return {{["y"] = 0, ["x"] = 0, ["name"] = "default:cobble", ["z"] = 5, ["meta"] = {["inventory"] = {}, ["fields"] = {}}, ["param2"] = 0, ["param1"] = 0}, {["y"] = 0, ["x"] = 0, ["name"] = "default:cobble", ["z"] = 6, ["meta"] = {["inventory"] = {}, ["fields"] = {}}, ["param2"] = 0, ["param1"] = 0}, {["y"] = 0, ["x"] = 0, ["name"] = "default:cobble", ["z"] = 7, ["meta"] = {["inventory"] = {}, ["fields"] = {}}, ["param2"] = 0, ["param1"] = 0}, {["y"] = 0, ["x"] = 0, ["name"] = "default:cobble", ["z"] = 8, ["meta"] = {["inventory"] = {}, ["fields"] = {}}, ["param2"] = 0, ["param1"] = 0}, {["y"] = 0, ["x"] = 0, ["name"] = "default:cobble", ["z"] = 9, ["meta"] = {["inventory"] = {}, ["fields"] = {}}, ["param2"] = 0, ["param1"] = 0}, {["y"] = 1, ["x"] = 0, ["name"] = "default:cobble", ["z"] = 5, ["meta"] = {["inventory"] = {}, ["fields"] = {}}, ["param2"] = 0, ["param1"] = 0}, {["y"] = 1, ["x"] = 0, ["name"] = "default:cobble", ["z"] = 6, ["meta"] = {["inventory"] = {}, ["fields"] = {}}, ["param2"] = 0, ["param1"] = 0}, {["y"] = 1, ["x"] = 0, ["name"] = "default:cobble", ["z"] = 7, ["meta"] = {["inventory"] = {}, ["fields"] = {}}, ["param2"] = 0, ["param1"] = 0}, {["y"] = 1, ["x"] = 0, ["name"] = "default:cobble", ["z"] = 8, ["meta"] = {["inventory"] = {}, ["fields"] = {}}, ["param2"] = 0, ["param1"] = 0}, {["y"] = 1, ["x"] = 0, ["name"] = "default:cobble", ["z"] = 9, ["meta"] = {["inventory"] = {}, ["fields"] = {}}, ["param2"] = 0, ["param1"] = 0}, {["y"] = 2, ["x"] = 0, ["name"] = "default:cobble", ["z"] = 5, ["meta"] = {["inventory"] = {}, ["fields"] = {}}, ["param2"] = 0, ["param1"] = 0}, {["y"] = 2, ["x"] = 0, ["name"] = "default:cobble", ["z"] = 6, ["meta"] = {["inventory"] = {}, ["fields"] = {}}, ["param2"] = 0, ["param1"] = 0}, {["y"] = 2, ["x"] = 0, ["name"] = "default:cobble", ["z"] = 7, ["meta"] = {["inventory"] = {}, ["fields"] = {}}, ["param2"] = 0, ["param1"] = 0}, {["y"] = 2, ["x"] = 0, ["name"] = "default:cobble", ["z"] = 8, ["meta"] = {["inventory"] = {}, ["fields"] = {}}, ["param2"] = 0, ["param1"] = 0}, {["y"] = 2, ["x"] = 0, ["name"] = "default:cobble", ["z"] = 9, ["meta"] = {["inventory"] = {}, ["fields"] = {}}, ["param2"] = 0, ["param1"] = 0}, {["y"] = 3, ["x"] = 0, ["name"] = "default:cobble", ["z"] = 5, ["meta"] = {["inventory"] = {}, ["fields"] = {}}, ["param2"] = 0, ["param1"] = 0}, {["y"] = 3, ["x"] = 0, ["name"] = "default:cobble", ["z"] = 6, ["meta"] = {["inventory"] = {}, ["fields"] = {}}, ["param2"] = 0, ["param1"] = 0}, {["y"] = 3, ["x"] = 0, ["name"] = "default:cobble", ["z"] = 7, ["meta"] = {["inventory"] = {}, ["fields"] = {}}, ["param2"] = 0, ["param1"] = 0}, {["y"] = 3, ["x"] = 0, ["name"] = "default:cobble", ["z"] = 8, ["meta"] = {["inventory"] = {}, ["fields"] = {}}, ["param2"] = 0, ["param1"] = 0}, {["y"] = 3, ["x"] = 0, ["name"] = "default:cobble", ["z"] = 9, ["meta"] = {["inventory"] = {}, ["fields"] = {}}, ["param2"] = 0, ["param1"] = 0}, {["y"] = 4, ["x"] = 0, ["name"] = "default:cobble", ["z"] = 5, ["meta"] = {["inventory"] = {}, ["fields"] = {}}, ["param2"] = 0, ["param1"] = 0}, {["y"] = 4, ["x"] = 0, ["name"] = "default:cobble", ["z"] = 6, ["meta"] = {["inventory"] = {}, ["fields"] = {}}, ["param2"] = 0, ["param1"] = 0}, {["y"] = 4, ["x"] = 0, ["name"] = "default:cobble", ["z"] = 7, ["meta"] = {["inventory"] = {}, ["fields"] = {}}, ["param2"] = 0, ["param1"] = 0}, {["y"] = 15, ["x"] = 0, ["name"] = "default:cobble", ["z"] = 8, ["meta"] = {["inventory"] = {}, ["fields"] = {}}, ["param2"] = 0, ["param1"] = 0}, {["y"] = 16, ["x"] = 0, ["name"] = "default:cobble", ["z"] = 8, ["meta"] = {["inventory"] = {}, ["fields"] = {}}, ["param2"] = 0, ["param1"] = 0}, {["y"] = 17, ["x"] = 0, ["name"] = "default:cobble", ["z"] = 7, ["meta"] = {["inventory"] = {}, ["fields"] = {}}, ["param2"] = 0, ["param1"] = 0}, {["y"] = 18, ["x"] = 0, ["name"] = "default:cobble", ["z"] = 7, ["meta"] = {["inventory"] = {}, ["fields"] = {}}, ["param2"] = 0, ["param1"] = 0}, {["y"] = 19, ["x"] = 0, ["name"] = "default:cobble", ["z"] = 7, ["meta"] = {["inventory"] = {}, ["fields"] = {}}, ["param2"] = 0, ["param1"] = 0}, {["y"] = 20, ["x"] = 0, ["name"] = "default:cobble", ["z"] = 6, ["meta"] = {["inventory"] = {}, ["fields"] = {}}, ["param2"] = 0, ["param1"] = 0}, {["y"] = 21, ["x"] = 0, ["name"] = "default:cobble", ["z"] = 6, ["meta"] = {["inventory"] = {}, ["fields"] = {}}, ["param2"] = 0, ["param1"] = 0}, {["y"] = 22, ["x"] = 0, ["name"] = "default:cobble", ["z"] = 6, ["meta"] = {["inventory"] = {}, ["fields"] = {}}, ["param2"] = 0, ["param1"] = 0}, {["y"] = 23, ["x"] = 0, ["name"] = "default:cobble", ["z"] = 6, ["meta"] = {["inventory"] = {}, ["fields"] = {}}, ["param2"] = 0, ["param1"] = 0}, {["y"] = 24, ["x"] = 0, ["name"] = "default:cobble", ["z"] = 5, ["meta"] = {["inventory"] = {}, ["fields"] = {}}, ["param2"] = 0, ["param1"] = 0}, {["y"] = 25, ["x"] = 0, ["name"] = "default:cobble", ["z"] = 5, ["meta"] = {["inventory"] = {}, ["fields"] = {}}, ["param2"] = 0, ["param1"] = 0}, {["y"] = 26, ["x"] = 0, ["name"] = "default:cobble", ["z"] = 5, ["meta"] = {["inventory"] = {}, ["fields"] = {}}, ["param2"] = 0, ["param1"] = 0}, {["y"] = 27, ["x"] = 0, ["name"] = "default:cobble", ["z"] = 5, ["meta"] = {["inventory"] = {}, ["fields"] = {}}, ["param2"] = 0, ["param1"] = 0}, {["y"] = 28, ["x"] = 0, ["name"] = "default:cobble", ["z"] = 5, ["meta"] = {["inventory"] = {}, ["fields"] = {}}, ["param2"] = 0, ["param1"] = 0}, {["y"] = 29, ["x"] = 0, ["name"] = "default:cobble", ["z"] = 5, ["meta"] = {["inventory"] = {}, ["fields"] = {}}, ["param2"] = 0, ["param1"] = 0}, {["y"] = 30, ["x"] = 0, ["name"] = "default:cobble", ["z"] = 5, ["meta"] = {["inventory"] = {}, ["fields"] = {}}, ["param2"] = 0, ["param1"] = 0}, {["y"] = 31, ["x"] = 0, ["name"] = "default:cobble", ["z"] = 5, ["meta"] = {["inventory"] = {}, ["fields"] = {}}, ["param2"] = 0, ["param1"] = 0}, {["y"] = 32, ["x"] = 0, ["name"] = "default:cobble", ["z"] = 5, ["meta"] = {["inventory"] = {}, ["fields"] = {}}, ["param2"] = 0, ["param1"] = 0}, {["y"] = 0, ["x"] = 1, ["name"] = "default:cobble", ["z"] = 3, ["meta"] = {["inventory"] = {}, ["fields"] = {}}, ["param2"] = 0, ["param1"] = 0}, {["y"] = 0, ["x"] = 1, ["name"] = "default:cobble", ["z"] = 4, ["meta"] = {["inventory"] = {}, ["fields"] = {}}, ["param2"] = 0, ["param1"] = 0}, {["y"] = 0, ["x"] = 1, ["name"] = "default:water_flowing", ["z"] = 5, ["meta"] = {["inventory"] = {}, ["fields"] = {}}, ["param2"] = 7, ["param1"] = 13}, {["y"] = 0, ["x"] = 1, ["name"] = "default:water_flowing", ["z"] = 6, ["meta"] = {["inventory"] = {}, ["fields"] = {}}, ["param2"] = 7, ["param1"] = 13}, {["y"] = 0, ["x"] = 1, ["name"] = "default:water_flowing", ["z"] = 7, ["meta"] = {["inventory"] = {}, ["fields"] = {}}, ["param2"] = 7, ["param1"] = 13}, {["y"] = 0, ["x"] = 1, ["name"] = "default:water_flowing", ["z"] = 8, ["meta"] = {["inventory"] = {}, ["fields"] = {}}, ["param2"] = 7, ["param1"] = 13}, {["y"] = 0, ["x"] = 1, ["name"] = "default:water_flowing", ["z"] = 9, ["meta"] = {["inventory"] = {}, ["fields"] = {}}, ["param2"] = 7, ["param1"] = 13}, {["y"] = 0, ["x"] = 1, ["name"] = "default:cobble", ["z"] = 10, ["meta"] = {["inventory"] = {}, ["fields"] = {}}, ["param2"] = 0, ["param1"] = 0}, {["y"] = 0, ["x"] = 1, ["name"] = "default:cobble", ["z"] = 11, ["meta"] = {["inventory"] = {}, ["fields"] = {}}, ["param2"] = 0, ["param1"] = 0}, {["y"] = 1, ["x"] = 1, ["name"] = "default:cobble", ["z"] = 3, ["meta"] = {["inventory"] = {}, ["fields"] = {}}, ["param2"] = 0, ["param1"] = 0}, {["y"] = 1, ["x"] = 1, ["name"] = "default:cobble", ["z"] = 4, ["meta"] = {["inventory"] = {}, ["fields"] = {}}, ["param2"] = 0, ["param1"] = 0}, {["y"] = 1, ["x"] = 1, ["name"] = "default:water_source", ["z"] = 5, ["meta"] = {["inventory"] = {}, ["fields"] = {}}, ["param2"] = 0, ["param1"] = 13}, {["y"] = 1, ["x"] = 1, ["name"] = "default:water_source", ["z"] = 6, ["meta"] = {["inventory"] = {}, ["fields"] = {}}, ["param2"] = 0, ["param1"] = 13}, {["y"] = 1, ["x"] = 1, ["name"] = "default:water_source", ["z"] = 7, ["meta"] = {["inventory"] = {}, ["fields"] = {}}, ["param2"] = 0, ["param1"] = 13}, {["y"] = 1, ["x"] = 1, ["name"] = "default:water_source", ["z"] = 8, ["meta"] = {["inventory"] = {}, ["fields"] = {}}, ["param2"] = 0, ["param1"] = 13}, {["y"] = 1, ["x"] = 1, ["name"] = "default:water_source", ["z"] = 9, ["meta"] = {["inventory"] = {}, ["fields"] = {}}, ["param2"] = 0, ["param1"] = 13}, {["y"] = 1, ["x"] = 1, ["name"] = "default:cobble", ["z"] = 10, ["meta"] = {["inventory"] = {}, ["fields"] = {}}, ["param2"] = 0, ["param1"] = 0}, {["y"] = 1, ["x"] = 1, ["name"] = "default:cobble", ["z"] = 11, ["meta"] = {["inventory"] = {}, ["fields"] = {}}, ["param2"] = 0, ["param1"] = 0}, {["y"] = 2, ["x"] = 1, ["name"] = "default:cobble", ["z"] = 3, ["meta"] = {["inventory"] = {}, ["fields"] = {}}, ["param2"] = 0, ["param1"] = 0}, {["y"] = 2, ["x"] = 1, ["name"] = "default:cobble", ["z"] = 4, ["meta"] = {["inventory"] = {}, ["fields"] = {}}, ["param2"] = 0, ["param1"] = 0}, {["y"] = 2, ["x"] = 1, ["name"] = "default:cobble", ["z"] = 10, ["meta"] = {["inventory"] = {}, ["fields"] = {}}, ["param2"] = 0, ["param1"] = 0}, {["y"] = 2, ["x"] = 1, ["name"] = "default:cobble", ["z"] = 11, ["meta"] = {["inventory"] = {}, ["fields"] = {}}, ["param2"] = 0, ["param1"] = 0}, {["y"] = 3, ["x"] = 1, ["name"] = "default:cobble", ["z"] = 3, ["meta"] = {["inventory"] = {}, ["fields"] = {}}, ["param2"] = 0, ["param1"] = 0}, {["y"] = 3, ["x"] = 1, ["name"] = "default:cobble", ["z"] = 4, ["meta"] = {["inventory"] = {}, ["fields"] = {}}, ["param2"] = 0, ["param1"] = 0}, {["y"] = 3, ["x"] = 1, ["name"] = "default:cobble", ["z"] = 10, ["meta"] = {["inventory"] = {}, ["fields"] = {}}, ["param2"] = 0, ["param1"] = 0}, {["y"] = 4, ["x"] = 1, ["name"] = "default:cobble", ["z"] = 3, ["meta"] = {["inventory"] = {}, ["fields"] = {}}, ["param2"] = 0, ["param1"] = 0}, {["y"] = 4, ["x"] = 1, ["name"] = "default:cobble", ["z"] = 4, ["meta"] = {["inventory"] = {}, ["fields"] = {}}, ["param2"] = 0, ["param1"] = 0}, {["y"] = 5, ["x"] = 1, ["name"] = "default:cobble", ["z"] = 3, ["meta"] = {["inventory"] = {}, ["fields"] = {}}, ["param2"] = 0, ["param1"] = 0}, {["y"] = 5, ["x"] = 1, ["name"] = "default:cobble", ["z"] = 4, ["meta"] = {["inventory"] = {}, ["fields"] = {}}, ["param2"] = 0, ["param1"] = 0}, {["y"] = 13, ["x"] = 1, ["name"] = "default:cobble", ["z"] = 10, ["meta"] = {["inventory"] = {}, ["fields"] = {}}, ["param2"] = 0, ["param1"] = 0}, {["y"] = 14, ["x"] = 1, ["name"] = "default:cobble", ["z"] = 9, ["meta"] = {["inventory"] = {}, ["fields"] = {}}, ["param2"] = 0, ["param1"] = 0}, {["y"] = 0, ["x"] = 2, ["name"] = "default:cobble", ["z"] = 2, ["meta"] = {["inventory"] = {}, ["fields"] = {}}, ["param2"] = 0, ["param1"] = 0}, {["y"] = 0, ["x"] = 2, ["name"] = "default:water_flowing", ["z"] = 3, ["meta"] = {["inventory"] = {}, ["fields"] = {}}, ["param2"] = 7, ["param1"] = 13}, {["y"] = 0, ["x"] = 2, ["name"] = "default:water_flowing", ["z"] = 4, ["meta"] = {["inventory"] = {}, ["fields"] = {}}, ["param2"] = 7, ["param1"] = 13}, {["y"] = 0, ["x"] = 2, ["name"] = "default:water_flowing", ["z"] = 5, ["meta"] = {["inventory"] = {}, ["fields"] = {}}, ["param2"] = 7, ["param1"] = 15}, {["y"] = 0, ["x"] = 2, ["name"] = "default:water_flowing", ["z"] = 6, ["meta"] = {["inventory"] = {}, ["fields"] = {}}, ["param2"] = 7, ["param1"] = 15}, {["y"] = 0, ["x"] = 2, ["name"] = "default:water_flowing", ["z"] = 7, ["meta"] = {["inventory"] = {}, ["fields"] = {}}, ["param2"] = 7, ["param1"] = 15}, {["y"] = 0, ["x"] = 2, ["name"] = "default:water_flowing", ["z"] = 8, ["meta"] = {["inventory"] = {}, ["fields"] = {}}, ["param2"] = 7, ["param1"] = 15}, {["y"] = 0, ["x"] = 2, ["name"] = "default:water_flowing", ["z"] = 9, ["meta"] = {["inventory"] = {}, ["fields"] = {}}, ["param2"] = 7, ["param1"] = 15}, {["y"] = 0, ["x"] = 2, ["name"] = "default:water_flowing", ["z"] = 10, ["meta"] = {["inventory"] = {}, ["fields"] = {}}, ["param2"] = 7, ["param1"] = 13}, {["y"] = 0, ["x"] = 2, ["name"] = "default:water_flowing", ["z"] = 11, ["meta"] = {["inventory"] = {}, ["fields"] = {}}, ["param2"] = 7, ["param1"] = 13}, {["y"] = 0, ["x"] = 2, ["name"] = "default:cobble", ["z"] = 12, ["meta"] = {["inventory"] = {}, ["fields"] = {}}, ["param2"] = 0, ["param1"] = 0}, {["y"] = 1, ["x"] = 2, ["name"] = "default:cobble", ["z"] = 2, ["meta"] = {["inventory"] = {}, ["fields"] = {}}, ["param2"] = 0, ["param1"] = 0}, {["y"] = 1, ["x"] = 2, ["name"] = "default:water_source", ["z"] = 3, ["meta"] = {["inventory"] = {}, ["fields"] = {}}, ["param2"] = 0, ["param1"] = 13}, {["y"] = 1, ["x"] = 2, ["name"] = "default:water_source", ["z"] = 4, ["meta"] = {["inventory"] = {}, ["fields"] = {}}, ["param2"] = 0, ["param1"] = 13}, {["y"] = 1, ["x"] = 2, ["name"] = "default:water_source", ["z"] = 5, ["meta"] = {["inventory"] = {}, ["fields"] = {}}, ["param2"] = 240, ["param1"] = 15}, {["y"] = 1, ["x"] = 2, ["name"] = "default:water_source", ["z"] = 6, ["meta"] = {["inventory"] = {}, ["fields"] = {}}, ["param2"] = 240, ["param1"] = 15}, {["y"] = 1, ["x"] = 2, ["name"] = "default:water_source", ["z"] = 7, ["meta"] = {["inventory"] = {}, ["fields"] = {}}, ["param2"] = 240, ["param1"] = 15}, {["y"] = 1, ["x"] = 2, ["name"] = "default:water_source", ["z"] = 8, ["meta"] = {["inventory"] = {}, ["fields"] = {}}, ["param2"] = 240, ["param1"] = 15}, {["y"] = 1, ["x"] = 2, ["name"] = "default:water_source", ["z"] = 9, ["meta"] = {["inventory"] = {}, ["fields"] = {}}, ["param2"] = 240, ["param1"] = 15}, {["y"] = 1, ["x"] = 2, ["name"] = "default:water_source", ["z"] = 10, ["meta"] = {["inventory"] = {}, ["fields"] = {}}, ["param2"] = 0, ["param1"] = 13}, {["y"] = 1, ["x"] = 2, ["name"] = "default:water_source", ["z"] = 11, ["meta"] = {["inventory"] = {}, ["fields"] = {}}, ["param2"] = 0, ["param1"] = 13}, {["y"] = 1, ["x"] = 2, ["name"] = "default:cobble", ["z"] = 12, ["meta"] = {["inventory"] = {}, ["fields"] = {}}, ["param2"] = 0, ["param1"] = 0}, {["y"] = 2, ["x"] = 2, ["name"] = "default:cobble", ["z"] = 2, ["meta"] = {["inventory"] = {}, ["fields"] = {}}, ["param2"] = 0, ["param1"] = 0}, {["y"] = 2, ["x"] = 2, ["name"] = "default:cobble", ["z"] = 12, ["meta"] = {["inventory"] = {}, ["fields"] = {}}, ["param2"] = 0, ["param1"] = 0}, {["y"] = 3, ["x"] = 2, ["name"] = "default:cobble", ["z"] = 2, ["meta"] = {["inventory"] = {}, ["fields"] = {}}, ["param2"] = 0, ["param1"] = 0}, {["y"] = 4, ["x"] = 2, ["name"] = "default:cobble", ["z"] = 2, ["meta"] = {["inventory"] = {}, ["fields"] = {}}, ["param2"] = 0, ["param1"] = 0}, {["y"] = 5, ["x"] = 2, ["name"] = "default:cobble", ["z"] = 2, ["meta"] = {["inventory"] = {}, ["fields"] = {}}, ["param2"] = 0, ["param1"] = 0}, {["y"] = 12, ["x"] = 2, ["name"] = "default:cobble", ["z"] = 11, ["meta"] = {["inventory"] = {}, ["fields"] = {}}, ["param2"] = 0, ["param1"] = 0}, {["y"] = 0, ["x"] = 3, ["name"] = "default:cobble", ["z"] = 1, ["meta"] = {["inventory"] = {}, ["fields"] = {}}, ["param2"] = 0, ["param1"] = 0}, {["y"] = 0, ["x"] = 3, ["name"] = "default:water_flowing", ["z"] = 2, ["meta"] = {["inventory"] = {}, ["fields"] = {}}, ["param2"] = 7, ["param1"] = 15}, {["y"] = 0, ["x"] = 3, ["name"] = "default:water_flowing", ["z"] = 3, ["meta"] = {["inventory"] = {}, ["fields"] = {}}, ["param2"] = 7, ["param1"] = 15}, {["y"] = 0, ["x"] = 3, ["name"] = "default:water_flowing", ["z"] = 4, ["meta"] = {["inventory"] = {}, ["fields"] = {}}, ["param2"] = 7, ["param1"] = 15}, {["y"] = 0, ["x"] = 3, ["name"] = "default:water_flowing", ["z"] = 5, ["meta"] = {["inventory"] = {}, ["fields"] = {}}, ["param2"] = 7, ["param1"] = 15}, {["y"] = 0, ["x"] = 3, ["name"] = "default:water_flowing", ["z"] = 6, ["meta"] = {["inventory"] = {}, ["fields"] = {}}, ["param2"] = 7, ["param1"] = 15}, {["y"] = 0, ["x"] = 3, ["name"] = "default:water_flowing", ["z"] = 7, ["meta"] = {["inventory"] = {}, ["fields"] = {}}, ["param2"] = 7, ["param1"] = 15}, {["y"] = 0, ["x"] = 3, ["name"] = "default:water_flowing", ["z"] = 8, ["meta"] = {["inventory"] = {}, ["fields"] = {}}, ["param2"] = 7, ["param1"] = 15}, {["y"] = 0, ["x"] = 3, ["name"] = "default:water_flowing", ["z"] = 9, ["meta"] = {["inventory"] = {}, ["fields"] = {}}, ["param2"] = 7, ["param1"] = 15}, {["y"] = 0, ["x"] = 3, ["name"] = "default:water_flowing", ["z"] = 10, ["meta"] = {["inventory"] = {}, ["fields"] = {}}, ["param2"] = 7, ["param1"] = 15}, {["y"] = 0, ["x"] = 3, ["name"] = "default:water_flowing", ["z"] = 11, ["meta"] = {["inventory"] = {}, ["fields"] = {}}, ["param2"] = 7, ["param1"] = 15}, {["y"] = 0, ["x"] = 3, ["name"] = "default:water_flowing", ["z"] = 12, ["meta"] = {["inventory"] = {}, ["fields"] = {}}, ["param2"] = 7, ["param1"] = 13}, {["y"] = 0, ["x"] = 3, ["name"] = "default:cobble", ["z"] = 13, ["meta"] = {["inventory"] = {}, ["fields"] = {}}, ["param2"] = 0, ["param1"] = 0}, {["y"] = 1, ["x"] = 3, ["name"] = "default:cobble", ["z"] = 1, ["meta"] = {["inventory"] = {}, ["fields"] = {}}, ["param2"] = 0, ["param1"] = 0}, {["y"] = 1, ["x"] = 3, ["name"] = "default:water_source", ["z"] = 2, ["meta"] = {["inventory"] = {}, ["fields"] = {}}, ["param2"] = 240, ["param1"] = 15}, {["y"] = 1, ["x"] = 3, ["name"] = "default:water_source", ["z"] = 3, ["meta"] = {["inventory"] = {}, ["fields"] = {}}, ["param2"] = 240, ["param1"] = 15}, {["y"] = 1, ["x"] = 3, ["name"] = "default:water_source", ["z"] = 4, ["meta"] = {["inventory"] = {}, ["fields"] = {}}, ["param2"] = 240, ["param1"] = 15}, {["y"] = 1, ["x"] = 3, ["name"] = "default:water_source", ["z"] = 5, ["meta"] = {["inventory"] = {}, ["fields"] = {}}, ["param2"] = 240, ["param1"] = 15}, {["y"] = 1, ["x"] = 3, ["name"] = "default:water_source", ["z"] = 6, ["meta"] = {["inventory"] = {}, ["fields"] = {}}, ["param2"] = 240, ["param1"] = 15}, {["y"] = 1, ["x"] = 3, ["name"] = "default:water_source", ["z"] = 7, ["meta"] = {["inventory"] = {}, ["fields"] = {}}, ["param2"] = 240, ["param1"] = 15}, {["y"] = 1, ["x"] = 3, ["name"] = "default:water_source", ["z"] = 8, ["meta"] = {["inventory"] = {}, ["fields"] = {}}, ["param2"] = 240, ["param1"] = 15}, {["y"] = 1, ["x"] = 3, ["name"] = "default:water_source", ["z"] = 9, ["meta"] = {["inventory"] = {}, ["fields"] = {}}, ["param2"] = 240, ["param1"] = 15}, {["y"] = 1, ["x"] = 3, ["name"] = "default:water_source", ["z"] = 10, ["meta"] = {["inventory"] = {}, ["fields"] = {}}, ["param2"] = 240, ["param1"] = 15}, {["y"] = 1, ["x"] = 3, ["name"] = "default:water_source", ["z"] = 11, ["meta"] = {["inventory"] = {}, ["fields"] = {}}, ["param2"] = 240, ["param1"] = 15}, {["y"] = 1, ["x"] = 3, ["name"] = "default:water_source", ["z"] = 12, ["meta"] = {["inventory"] = {}, ["fields"] = {}}, ["param2"] = 0, ["param1"] = 13}, {["y"] = 1, ["x"] = 3, ["name"] = "default:cobble", ["z"] = 13, ["meta"] = {["inventory"] = {}, ["fields"] = {}}, ["param2"] = 0, ["param1"] = 0}, {["y"] = 2, ["x"] = 3, ["name"] = "default:cobble", ["z"] = 1, ["meta"] = {["inventory"] = {}, ["fields"] = {}}, ["param2"] = 0, ["param1"] = 0}, {["y"] = 2, ["x"] = 3, ["name"] = "default:cobble", ["z"] = 13, ["meta"] = {["inventory"] = {}, ["fields"] = {}}, ["param2"] = 0, ["param1"] = 0}, {["y"] = 3, ["x"] = 3, ["name"] = "default:cobble", ["z"] = 1, ["meta"] = {["inventory"] = {}, ["fields"] = {}}, ["param2"] = 0, ["param1"] = 0}, {["y"] = 4, ["x"] = 3, ["name"] = "default:cobble", ["z"] = 1, ["meta"] = {["inventory"] = {}, ["fields"] = {}}, ["param2"] = 0, ["param1"] = 0}, {["y"] = 5, ["x"] = 3, ["name"] = "default:cobble", ["z"] = 1, ["meta"] = {["inventory"] = {}, ["fields"] = {}}, ["param2"] = 0, ["param1"] = 0}, {["y"] = 6, ["x"] = 3, ["name"] = "default:cobble", ["z"] = 1, ["meta"] = {["inventory"] = {}, ["fields"] = {}}, ["param2"] = 0, ["param1"] = 0}, {["y"] = 11, ["x"] = 3, ["name"] = "default:cobble", ["z"] = 12, ["meta"] = {["inventory"] = {}, ["fields"] = {}}, ["param2"] = 0, ["param1"] = 0}, {["y"] = 0, ["x"] = 4, ["name"] = "default:cobble", ["z"] = 1, ["meta"] = {["inventory"] = {}, ["fields"] = {}}, ["param2"] = 0, ["param1"] = 0}, {["y"] = 0, ["x"] = 4, ["name"] = "default:water_flowing", ["z"] = 2, ["meta"] = {["inventory"] = {}, ["fields"] = {}}, ["param2"] = 7, ["param1"] = 13}, {["y"] = 0, ["x"] = 4, ["name"] = "default:water_flowing", ["z"] = 3, ["meta"] = {["inventory"] = {}, ["fields"] = {}}, ["param2"] = 7, ["param1"] = 15}, {["y"] = 0, ["x"] = 4, ["name"] = "default:water_flowing", ["z"] = 4, ["meta"] = {["inventory"] = {}, ["fields"] = {}}, ["param2"] = 7, ["param1"] = 15}, {["y"] = 0, ["x"] = 4, ["name"] = "default:water_flowing", ["z"] = 5, ["meta"] = {["inventory"] = {}, ["fields"] = {}}, ["param2"] = 7, ["param1"] = 15}, {["y"] = 0, ["x"] = 4, ["name"] = "default:water_flowing", ["z"] = 6, ["meta"] = {["inventory"] = {}, ["fields"] = {}}, ["param2"] = 7, ["param1"] = 15}, {["y"] = 0, ["x"] = 4, ["name"] = "default:water_flowing", ["z"] = 7, ["meta"] = {["inventory"] = {}, ["fields"] = {}}, ["param2"] = 7, ["param1"] = 15}, {["y"] = 0, ["x"] = 4, ["name"] = "default:water_flowing", ["z"] = 8, ["meta"] = {["inventory"] = {}, ["fields"] = {}}, ["param2"] = 7, ["param1"] = 15}, {["y"] = 0, ["x"] = 4, ["name"] = "default:water_flowing", ["z"] = 9, ["meta"] = {["inventory"] = {}, ["fields"] = {}}, ["param2"] = 7, ["param1"] = 15}, {["y"] = 0, ["x"] = 4, ["name"] = "default:water_flowing", ["z"] = 10, ["meta"] = {["inventory"] = {}, ["fields"] = {}}, ["param2"] = 7, ["param1"] = 15}, {["y"] = 0, ["x"] = 4, ["name"] = "default:water_flowing", ["z"] = 11, ["meta"] = {["inventory"] = {}, ["fields"] = {}}, ["param2"] = 7, ["param1"] = 15}, {["y"] = 0, ["x"] = 4, ["name"] = "default:water_flowing", ["z"] = 12, ["meta"] = {["inventory"] = {}, ["fields"] = {}}, ["param2"] = 7, ["param1"] = 13}, {["y"] = 0, ["x"] = 4, ["name"] = "default:cobble", ["z"] = 13, ["meta"] = {["inventory"] = {}, ["fields"] = {}}, ["param2"] = 0, ["param1"] = 0}, {["y"] = 1, ["x"] = 4, ["name"] = "default:cobble", ["z"] = 1, ["meta"] = {["inventory"] = {}, ["fields"] = {}}, ["param2"] = 0, ["param1"] = 0}, {["y"] = 1, ["x"] = 4, ["name"] = "default:water_source", ["z"] = 2, ["meta"] = {["inventory"] = {}, ["fields"] = {}}, ["param2"] = 0, ["param1"] = 13}, {["y"] = 1, ["x"] = 4, ["name"] = "default:water_source", ["z"] = 3, ["meta"] = {["inventory"] = {}, ["fields"] = {}}, ["param2"] = 240, ["param1"] = 15}, {["y"] = 1, ["x"] = 4, ["name"] = "default:water_source", ["z"] = 4, ["meta"] = {["inventory"] = {}, ["fields"] = {}}, ["param2"] = 240, ["param1"] = 15}, {["y"] = 1, ["x"] = 4, ["name"] = "default:water_source", ["z"] = 5, ["meta"] = {["inventory"] = {}, ["fields"] = {}}, ["param2"] = 240, ["param1"] = 15}, {["y"] = 1, ["x"] = 4, ["name"] = "default:water_source", ["z"] = 6, ["meta"] = {["inventory"] = {}, ["fields"] = {}}, ["param2"] = 240, ["param1"] = 15}, {["y"] = 1, ["x"] = 4, ["name"] = "default:water_source", ["z"] = 7, ["meta"] = {["inventory"] = {}, ["fields"] = {}}, ["param2"] = 240, ["param1"] = 15}, {["y"] = 1, ["x"] = 4, ["name"] = "default:water_source", ["z"] = 8, ["meta"] = {["inventory"] = {}, ["fields"] = {}}, ["param2"] = 240, ["param1"] = 15}, {["y"] = 1, ["x"] = 4, ["name"] = "default:water_source", ["z"] = 9, ["meta"] = {["inventory"] = {}, ["fields"] = {}}, ["param2"] = 240, ["param1"] = 15}, {["y"] = 1, ["x"] = 4, ["name"] = "default:water_source", ["z"] = 10, ["meta"] = {["inventory"] = {}, ["fields"] = {}}, ["param2"] = 240, ["param1"] = 15}, {["y"] = 1, ["x"] = 4, ["name"] = "default:water_source", ["z"] = 11, ["meta"] = {["inventory"] = {}, ["fields"] = {}}, ["param2"] = 240, ["param1"] = 15}, {["y"] = 1, ["x"] = 4, ["name"] = "default:water_source", ["z"] = 12, ["meta"] = {["inventory"] = {}, ["fields"] = {}}, ["param2"] = 0, ["param1"] = 13}, {["y"] = 1, ["x"] = 4, ["name"] = "default:cobble", ["z"] = 13, ["meta"] = {["inventory"] = {}, ["fields"] = {}}, ["param2"] = 0, ["param1"] = 0}, {["y"] = 2, ["x"] = 4, ["name"] = "default:cobble", ["z"] = 1, ["meta"] = {["inventory"] = {}, ["fields"] = {}}, ["param2"] = 0, ["param1"] = 0}, {["y"] = 3, ["x"] = 4, ["name"] = "default:cobble", ["z"] = 1, ["meta"] = {["inventory"] = {}, ["fields"] = {}}, ["param2"] = 0, ["param1"] = 0}, {["y"] = 4, ["x"] = 4, ["name"] = "default:cobble", ["z"] = 1, ["meta"] = {["inventory"] = {}, ["fields"] = {}}, ["param2"] = 0, ["param1"] = 0}, {["y"] = 5, ["x"] = 4, ["name"] = "default:cobble", ["z"] = 1, ["meta"] = {["inventory"] = {}, ["fields"] = {}}, ["param2"] = 0, ["param1"] = 0}, {["y"] = 6, ["x"] = 4, ["name"] = "default:cobble", ["z"] = 1, ["meta"] = {["inventory"] = {}, ["fields"] = {}}, ["param2"] = 0, ["param1"] = 0}, {["y"] = 11, ["x"] = 4, ["name"] = "default:cobble", ["z"] = 12, ["meta"] = {["inventory"] = {}, ["fields"] = {}}, ["param2"] = 0, ["param1"] = 0}, {["y"] = 0, ["x"] = 5, ["name"] = "default:cobble", ["z"] = 0, ["meta"] = {["inventory"] = {}, ["fields"] = {}}, ["param2"] = 0, ["param1"] = 0}, {["y"] = 0, ["x"] = 5, ["name"] = "default:water_flowing", ["z"] = 1, ["meta"] = {["inventory"] = {}, ["fields"] = {}}, ["param2"] = 7, ["param1"] = 13}, {["y"] = 0, ["x"] = 5, ["name"] = "default:water_flowing", ["z"] = 2, ["meta"] = {["inventory"] = {}, ["fields"] = {}}, ["param2"] = 7, ["param1"] = 15}, {["y"] = 0, ["x"] = 5, ["name"] = "default:water_flowing", ["z"] = 3, ["meta"] = {["inventory"] = {}, ["fields"] = {}}, ["param2"] = 7, ["param1"] = 15}, {["y"] = 0, ["x"] = 5, ["name"] = "default:water_flowing", ["z"] = 4, ["meta"] = {["inventory"] = {}, ["fields"] = {}}, ["param2"] = 7, ["param1"] = 15}, {["y"] = 0, ["x"] = 5, ["name"] = "default:water_flowing", ["z"] = 5, ["meta"] = {["inventory"] = {}, ["fields"] = {}}, ["param2"] = 7, ["param1"] = 15}, {["y"] = 0, ["x"] = 5, ["name"] = "default:water_flowing", ["z"] = 6, ["meta"] = {["inventory"] = {}, ["fields"] = {}}, ["param2"] = 7, ["param1"] = 15}, {["y"] = 0, ["x"] = 5, ["name"] = "default:water_flowing", ["z"] = 7, ["meta"] = {["inventory"] = {}, ["fields"] = {}}, ["param2"] = 7, ["param1"] = 15}, {["y"] = 0, ["x"] = 5, ["name"] = "default:water_flowing", ["z"] = 8, ["meta"] = {["inventory"] = {}, ["fields"] = {}}, ["param2"] = 7, ["param1"] = 15}, {["y"] = 0, ["x"] = 5, ["name"] = "default:water_flowing", ["z"] = 9, ["meta"] = {["inventory"] = {}, ["fields"] = {}}, ["param2"] = 7, ["param1"] = 15}, {["y"] = 0, ["x"] = 5, ["name"] = "default:water_flowing", ["z"] = 10, ["meta"] = {["inventory"] = {}, ["fields"] = {}}, ["param2"] = 7, ["param1"] = 15}, {["y"] = 0, ["x"] = 5, ["name"] = "default:water_flowing", ["z"] = 11, ["meta"] = {["inventory"] = {}, ["fields"] = {}}, ["param2"] = 7, ["param1"] = 15}, {["y"] = 0, ["x"] = 5, ["name"] = "default:water_flowing", ["z"] = 12, ["meta"] = {["inventory"] = {}, ["fields"] = {}}, ["param2"] = 7, ["param1"] = 15}, {["y"] = 0, ["x"] = 5, ["name"] = "default:water_flowing", ["z"] = 13, ["meta"] = {["inventory"] = {}, ["fields"] = {}}, ["param2"] = 7, ["param1"] = 13}, {["y"] = 0, ["x"] = 5, ["name"] = "default:cobble", ["z"] = 14, ["meta"] = {["inventory"] = {}, ["fields"] = {}}, ["param2"] = 0, ["param1"] = 0}, {["y"] = 1, ["x"] = 5, ["name"] = "default:cobble", ["z"] = 0, ["meta"] = {["inventory"] = {}, ["fields"] = {}}, ["param2"] = 0, ["param1"] = 0}, {["y"] = 1, ["x"] = 5, ["name"] = "default:water_source", ["z"] = 1, ["meta"] = {["inventory"] = {}, ["fields"] = {}}, ["param2"] = 0, ["param1"] = 13}, {["y"] = 1, ["x"] = 5, ["name"] = "default:water_source", ["z"] = 2, ["meta"] = {["inventory"] = {}, ["fields"] = {}}, ["param2"] = 240, ["param1"] = 15}, {["y"] = 1, ["x"] = 5, ["name"] = "default:water_source", ["z"] = 3, ["meta"] = {["inventory"] = {}, ["fields"] = {}}, ["param2"] = 240, ["param1"] = 15}, {["y"] = 1, ["x"] = 5, ["name"] = "default:water_source", ["z"] = 4, ["meta"] = {["inventory"] = {}, ["fields"] = {}}, ["param2"] = 240, ["param1"] = 15}, {["y"] = 1, ["x"] = 5, ["name"] = "default:water_source", ["z"] = 5, ["meta"] = {["inventory"] = {}, ["fields"] = {}}, ["param2"] = 240, ["param1"] = 15}, {["y"] = 1, ["x"] = 5, ["name"] = "default:water_source", ["z"] = 6, ["meta"] = {["inventory"] = {}, ["fields"] = {}}, ["param2"] = 240, ["param1"] = 15}, {["y"] = 1, ["x"] = 5, ["name"] = "default:water_source", ["z"] = 7, ["meta"] = {["inventory"] = {}, ["fields"] = {}}, ["param2"] = 240, ["param1"] = 15}, {["y"] = 1, ["x"] = 5, ["name"] = "default:water_source", ["z"] = 8, ["meta"] = {["inventory"] = {}, ["fields"] = {}}, ["param2"] = 240, ["param1"] = 15}, {["y"] = 1, ["x"] = 5, ["name"] = "default:water_source", ["z"] = 9, ["meta"] = {["inventory"] = {}, ["fields"] = {}}, ["param2"] = 240, ["param1"] = 15}, {["y"] = 1, ["x"] = 5, ["name"] = "default:water_source", ["z"] = 10, ["meta"] = {["inventory"] = {}, ["fields"] = {}}, ["param2"] = 240, ["param1"] = 15}, {["y"] = 1, ["x"] = 5, ["name"] = "default:water_source", ["z"] = 11, ["meta"] = {["inventory"] = {}, ["fields"] = {}}, ["param2"] = 240, ["param1"] = 15}, {["y"] = 1, ["x"] = 5, ["name"] = "default:water_source", ["z"] = 12, ["meta"] = {["inventory"] = {}, ["fields"] = {}}, ["param2"] = 240, ["param1"] = 15}, {["y"] = 1, ["x"] = 5, ["name"] = "default:water_source", ["z"] = 13, ["meta"] = {["inventory"] = {}, ["fields"] = {}}, ["param2"] = 0, ["param1"] = 13}, {["y"] = 1, ["x"] = 5, ["name"] = "default:cobble", ["z"] = 14, ["meta"] = {["inventory"] = {}, ["fields"] = {}}, ["param2"] = 0, ["param1"] = 0}, {["y"] = 2, ["x"] = 5, ["name"] = "default:cobble", ["z"] = 0, ["meta"] = {["inventory"] = {}, ["fields"] = {}}, ["param2"] = 0, ["param1"] = 0}, {["y"] = 3, ["x"] = 5, ["name"] = "default:cobble", ["z"] = 0, ["meta"] = {["inventory"] = {}, ["fields"] = {}}, ["param2"] = 0, ["param1"] = 0}, {["y"] = 4, ["x"] = 5, ["name"] = "default:cobble", ["z"] = 0, ["meta"] = {["inventory"] = {}, ["fields"] = {}}, ["param2"] = 0, ["param1"] = 0}, {["y"] = 5, ["x"] = 5, ["name"] = "default:cobble", ["z"] = 0, ["meta"] = {["inventory"] = {}, ["fields"] = {}}, ["param2"] = 0, ["param1"] = 0}, {["y"] = 6, ["x"] = 5, ["name"] = "default:cobble", ["z"] = 0, ["meta"] = {["inventory"] = {}, ["fields"] = {}}, ["param2"] = 0, ["param1"] = 0}, {["y"] = 10, ["x"] = 5, ["name"] = "default:cobble", ["z"] = 13, ["meta"] = {["inventory"] = {}, ["fields"] = {}}, ["param2"] = 0, ["param1"] = 0}, {["y"] = 0, ["x"] = 6, ["name"] = "default:cobble", ["z"] = 0, ["meta"] = {["inventory"] = {}, ["fields"] = {}}, ["param2"] = 0, ["param1"] = 0}, {["y"] = 0, ["x"] = 6, ["name"] = "default:water_flowing", ["z"] = 1, ["meta"] = {["inventory"] = {}, ["fields"] = {}}, ["param2"] = 7, ["param1"] = 12}, {["y"] = 0, ["x"] = 6, ["name"] = "default:water_flowing", ["z"] = 2, ["meta"] = {["inventory"] = {}, ["fields"] = {}}, ["param2"] = 7, ["param1"] = 13}, {["y"] = 0, ["x"] = 6, ["name"] = "default:water_flowing", ["z"] = 3, ["meta"] = {["inventory"] = {}, ["fields"] = {}}, ["param2"] = 7, ["param1"] = 13}, {["y"] = 0, ["x"] = 6, ["name"] = "default:water_flowing", ["z"] = 4, ["meta"] = {["inventory"] = {}, ["fields"] = {}}, ["param2"] = 7, ["param1"] = 13}, {["y"] = 0, ["x"] = 6, ["name"] = "default:water_flowing", ["z"] = 5, ["meta"] = {["inventory"] = {}, ["fields"] = {}}, ["param2"] = 7, ["param1"] = 13}, {["y"] = 0, ["x"] = 6, ["name"] = "default:water_flowing", ["z"] = 6, ["meta"] = {["inventory"] = {}, ["fields"] = {}}, ["param2"] = 7, ["param1"] = 13}, {["y"] = 0, ["x"] = 6, ["name"] = "default:water_flowing", ["z"] = 7, ["meta"] = {["inventory"] = {}, ["fields"] = {}}, ["param2"] = 7, ["param1"] = 13}, {["y"] = 0, ["x"] = 6, ["name"] = "default:water_flowing", ["z"] = 8, ["meta"] = {["inventory"] = {}, ["fields"] = {}}, ["param2"] = 7, ["param1"] = 13}, {["y"] = 0, ["x"] = 6, ["name"] = "default:water_flowing", ["z"] = 9, ["meta"] = {["inventory"] = {}, ["fields"] = {}}, ["param2"] = 7, ["param1"] = 13}, {["y"] = 0, ["x"] = 6, ["name"] = "default:water_flowing", ["z"] = 10, ["meta"] = {["inventory"] = {}, ["fields"] = {}}, ["param2"] = 7, ["param1"] = 13}, {["y"] = 0, ["x"] = 6, ["name"] = "default:water_flowing", ["z"] = 11, ["meta"] = {["inventory"] = {}, ["fields"] = {}}, ["param2"] = 7, ["param1"] = 13}, {["y"] = 0, ["x"] = 6, ["name"] = "default:water_flowing", ["z"] = 12, ["meta"] = {["inventory"] = {}, ["fields"] = {}}, ["param2"] = 7, ["param1"] = 13}, {["y"] = 0, ["x"] = 6, ["name"] = "default:water_flowing", ["z"] = 13, ["meta"] = {["inventory"] = {}, ["fields"] = {}}, ["param2"] = 7, ["param1"] = 12}, {["y"] = 0, ["x"] = 6, ["name"] = "default:cobble", ["z"] = 14, ["meta"] = {["inventory"] = {}, ["fields"] = {}}, ["param2"] = 0, ["param1"] = 0}, {["y"] = 1, ["x"] = 6, ["name"] = "default:cobble", ["z"] = 0, ["meta"] = {["inventory"] = {}, ["fields"] = {}}, ["param2"] = 0, ["param1"] = 0}, {["y"] = 1, ["x"] = 6, ["name"] = "default:water_source", ["z"] = 1, ["meta"] = {["inventory"] = {}, ["fields"] = {}}, ["param2"] = 0, ["param1"] = 12}, {["y"] = 1, ["x"] = 6, ["name"] = "default:water_source", ["z"] = 2, ["meta"] = {["inventory"] = {}, ["fields"] = {}}, ["param2"] = 240, ["param1"] = 13}, {["y"] = 1, ["x"] = 6, ["name"] = "default:water_source", ["z"] = 3, ["meta"] = {["inventory"] = {}, ["fields"] = {}}, ["param2"] = 240, ["param1"] = 13}, {["y"] = 1, ["x"] = 6, ["name"] = "default:water_source", ["z"] = 4, ["meta"] = {["inventory"] = {}, ["fields"] = {}}, ["param2"] = 240, ["param1"] = 13}, {["y"] = 1, ["x"] = 6, ["name"] = "default:water_source", ["z"] = 5, ["meta"] = {["inventory"] = {}, ["fields"] = {}}, ["param2"] = 240, ["param1"] = 13}, {["y"] = 1, ["x"] = 6, ["name"] = "default:water_source", ["z"] = 6, ["meta"] = {["inventory"] = {}, ["fields"] = {}}, ["param2"] = 240, ["param1"] = 13}, {["y"] = 1, ["x"] = 6, ["name"] = "default:water_source", ["z"] = 7, ["meta"] = {["inventory"] = {}, ["fields"] = {}}, ["param2"] = 240, ["param1"] = 13}, {["y"] = 1, ["x"] = 6, ["name"] = "default:water_source", ["z"] = 8, ["meta"] = {["inventory"] = {}, ["fields"] = {}}, ["param2"] = 240, ["param1"] = 13}, {["y"] = 1, ["x"] = 6, ["name"] = "default:water_source", ["z"] = 9, ["meta"] = {["inventory"] = {}, ["fields"] = {}}, ["param2"] = 240, ["param1"] = 13}, {["y"] = 1, ["x"] = 6, ["name"] = "default:water_source", ["z"] = 10, ["meta"] = {["inventory"] = {}, ["fields"] = {}}, ["param2"] = 240, ["param1"] = 13}, {["y"] = 1, ["x"] = 6, ["name"] = "default:water_source", ["z"] = 11, ["meta"] = {["inventory"] = {}, ["fields"] = {}}, ["param2"] = 240, ["param1"] = 13}, {["y"] = 1, ["x"] = 6, ["name"] = "default:water_source", ["z"] = 12, ["meta"] = {["inventory"] = {}, ["fields"] = {}}, ["param2"] = 240, ["param1"] = 13}, {["y"] = 1, ["x"] = 6, ["name"] = "default:water_source", ["z"] = 13, ["meta"] = {["inventory"] = {}, ["fields"] = {}}, ["param2"] = 240, ["param1"] = 12}, {["y"] = 1, ["x"] = 6, ["name"] = "default:cobble", ["z"] = 14, ["meta"] = {["inventory"] = {}, ["fields"] = {}}, ["param2"] = 0, ["param1"] = 0}, {["y"] = 2, ["x"] = 6, ["name"] = "default:cobble", ["z"] = 0, ["meta"] = {["inventory"] = {}, ["fields"] = {}}, ["param2"] = 0, ["param1"] = 0}, {["y"] = 2, ["x"] = 6, ["name"] = "default:glass", ["z"] = 1, ["meta"] = {["inventory"] = {}, ["fields"] = {}}, ["param2"] = 0, ["param1"] = 13}, {["y"] = 2, ["x"] = 6, ["name"] = "default:glass", ["z"] = 2, ["meta"] = {["inventory"] = {}, ["fields"] = {}}, ["param2"] = 0, ["param1"] = 13}, {["y"] = 2, ["x"] = 6, ["name"] = "default:glass", ["z"] = 3, ["meta"] = {["inventory"] = {}, ["fields"] = {}}, ["param2"] = 0, ["param1"] = 13}, {["y"] = 2, ["x"] = 6, ["name"] = "default:glass", ["z"] = 4, ["meta"] = {["inventory"] = {}, ["fields"] = {}}, ["param2"] = 0, ["param1"] = 13}, {["y"] = 2, ["x"] = 6, ["name"] = "default:glass", ["z"] = 5, ["meta"] = {["inventory"] = {}, ["fields"] = {}}, ["param2"] = 0, ["param1"] = 13}, {["y"] = 2, ["x"] = 6, ["name"] = "default:glass", ["z"] = 6, ["meta"] = {["inventory"] = {}, ["fields"] = {}}, ["param2"] = 0, ["param1"] = 13}, {["y"] = 2, ["x"] = 6, ["name"] = "default:glass", ["z"] = 7, ["meta"] = {["inventory"] = {}, ["fields"] = {}}, ["param2"] = 0, ["param1"] = 13}, {["y"] = 2, ["x"] = 6, ["name"] = "default:glass", ["z"] = 8, ["meta"] = {["inventory"] = {}, ["fields"] = {}}, ["param2"] = 0, ["param1"] = 13}, {["y"] = 2, ["x"] = 6, ["name"] = "default:glass", ["z"] = 9, ["meta"] = {["inventory"] = {}, ["fields"] = {}}, ["param2"] = 0, ["param1"] = 13}, {["y"] = 2, ["x"] = 6, ["name"] = "default:glass", ["z"] = 10, ["meta"] = {["inventory"] = {}, ["fields"] = {}}, ["param2"] = 0, ["param1"] = 13}, {["y"] = 2, ["x"] = 6, ["name"] = "default:glass", ["z"] = 11, ["meta"] = {["inventory"] = {}, ["fields"] = {}}, ["param2"] = 0, ["param1"] = 13}, {["y"] = 2, ["x"] = 6, ["name"] = "default:glass", ["z"] = 12, ["meta"] = {["inventory"] = {}, ["fields"] = {}}, ["param2"] = 0, ["param1"] = 13}, {["y"] = 2, ["x"] = 6, ["name"] = "default:tree", ["z"] = 13, ["meta"] = {["inventory"] = {}, ["fields"] = {}}, ["param2"] = 7, ["param1"] = 0}, {["y"] = 3, ["x"] = 6, ["name"] = "default:cobble", ["z"] = 0, ["meta"] = {["inventory"] = {}, ["fields"] = {}}, ["param2"] = 0, ["param1"] = 0}, {["y"] = 3, ["x"] = 6, ["name"] = "default:glass", ["z"] = 1, ["meta"] = {["inventory"] = {}, ["fields"] = {}}, ["param2"] = 0, ["param1"] = 13}, {["y"] = 3, ["x"] = 6, ["name"] = "default:glass", ["z"] = 2, ["meta"] = {["inventory"] = {}, ["fields"] = {}}, ["param2"] = 0, ["param1"] = 13}, {["y"] = 3, ["x"] = 6, ["name"] = "default:glass", ["z"] = 3, ["meta"] = {["inventory"] = {}, ["fields"] = {}}, ["param2"] = 0, ["param1"] = 13}, {["y"] = 3, ["x"] = 6, ["name"] = "default:glass", ["z"] = 4, ["meta"] = {["inventory"] = {}, ["fields"] = {}}, ["param2"] = 0, ["param1"] = 13}, {["y"] = 3, ["x"] = 6, ["name"] = "default:glass", ["z"] = 5, ["meta"] = {["inventory"] = {}, ["fields"] = {}}, ["param2"] = 0, ["param1"] = 13}, {["y"] = 3, ["x"] = 6, ["name"] = "default:glass", ["z"] = 6, ["meta"] = {["inventory"] = {}, ["fields"] = {}}, ["param2"] = 0, ["param1"] = 13}, {["y"] = 3, ["x"] = 6, ["name"] = "default:glass", ["z"] = 7, ["meta"] = {["inventory"] = {}, ["fields"] = {}}, ["param2"] = 0, ["param1"] = 13}, {["y"] = 3, ["x"] = 6, ["name"] = "default:glass", ["z"] = 8, ["meta"] = {["inventory"] = {}, ["fields"] = {}}, ["param2"] = 0, ["param1"] = 13}, {["y"] = 3, ["x"] = 6, ["name"] = "default:glass", ["z"] = 9, ["meta"] = {["inventory"] = {}, ["fields"] = {}}, ["param2"] = 0, ["param1"] = 13}, {["y"] = 3, ["x"] = 6, ["name"] = "default:glass", ["z"] = 10, ["meta"] = {["inventory"] = {}, ["fields"] = {}}, ["param2"] = 0, ["param1"] = 13}, {["y"] = 3, ["x"] = 6, ["name"] = "default:tree", ["z"] = 11, ["meta"] = {["inventory"] = {}, ["fields"] = {}}, ["param2"] = 7, ["param1"] = 0}, {["y"] = 3, ["x"] = 6, ["name"] = "default:tree", ["z"] = 12, ["meta"] = {["inventory"] = {}, ["fields"] = {}}, ["param2"] = 7, ["param1"] = 0}, {["y"] = 4, ["x"] = 6, ["name"] = "default:cobble", ["z"] = 0, ["meta"] = {["inventory"] = {}, ["fields"] = {}}, ["param2"] = 0, ["param1"] = 0}, {["y"] = 4, ["x"] = 6, ["name"] = "default:glass", ["z"] = 1, ["meta"] = {["inventory"] = {}, ["fields"] = {}}, ["param2"] = 0, ["param1"] = 13}, {["y"] = 4, ["x"] = 6, ["name"] = "default:glass", ["z"] = 2, ["meta"] = {["inventory"] = {}, ["fields"] = {}}, ["param2"] = 0, ["param1"] = 13}, {["y"] = 4, ["x"] = 6, ["name"] = "default:glass", ["z"] = 3, ["meta"] = {["inventory"] = {}, ["fields"] = {}}, ["param2"] = 0, ["param1"] = 13}, {["y"] = 4, ["x"] = 6, ["name"] = "default:glass", ["z"] = 4, ["meta"] = {["inventory"] = {}, ["fields"] = {}}, ["param2"] = 0, ["param1"] = 13}, {["y"] = 4, ["x"] = 6, ["name"] = "default:glass", ["z"] = 5, ["meta"] = {["inventory"] = {}, ["fields"] = {}}, ["param2"] = 0, ["param1"] = 13}, {["y"] = 4, ["x"] = 6, ["name"] = "default:glass", ["z"] = 6, ["meta"] = {["inventory"] = {}, ["fields"] = {}}, ["param2"] = 0, ["param1"] = 13}, {["y"] = 4, ["x"] = 6, ["name"] = "default:glass", ["z"] = 7, ["meta"] = {["inventory"] = {}, ["fields"] = {}}, ["param2"] = 0, ["param1"] = 13}, {["y"] = 4, ["x"] = 6, ["name"] = "default:tree", ["z"] = 8, ["meta"] = {["inventory"] = {}, ["fields"] = {}}, ["param2"] = 7, ["param1"] = 0}, {["y"] = 4, ["x"] = 6, ["name"] = "default:tree", ["z"] = 9, ["meta"] = {["inventory"] = {}, ["fields"] = {}}, ["param2"] = 7, ["param1"] = 0}, {["y"] = 4, ["x"] = 6, ["name"] = "default:tree", ["z"] = 10, ["meta"] = {["inventory"] = {}, ["fields"] = {}}, ["param2"] = 7, ["param1"] = 0}, {["y"] = 5, ["x"] = 6, ["name"] = "default:cobble", ["z"] = 0, ["meta"] = {["inventory"] = {}, ["fields"] = {}}, ["param2"] = 0, ["param1"] = 0}, {["y"] = 5, ["x"] = 6, ["name"] = "default:tree", ["z"] = 1, ["meta"] = {["inventory"] = {}, ["fields"] = {}}, ["param2"] = 7, ["param1"] = 0}, {["y"] = 5, ["x"] = 6, ["name"] = "default:tree", ["z"] = 2, ["meta"] = {["inventory"] = {}, ["fields"] = {}}, ["param2"] = 7, ["param1"] = 0}, {["y"] = 5, ["x"] = 6, ["name"] = "default:tree", ["z"] = 3, ["meta"] = {["inventory"] = {}, ["fields"] = {}}, ["param2"] = 7, ["param1"] = 0}, {["y"] = 5, ["x"] = 6, ["name"] = "default:tree", ["z"] = 4, ["meta"] = {["inventory"] = {}, ["fields"] = {}}, ["param2"] = 7, ["param1"] = 0}, {["y"] = 5, ["x"] = 6, ["name"] = "default:tree", ["z"] = 5, ["meta"] = {["inventory"] = {}, ["fields"] = {}}, ["param2"] = 7, ["param1"] = 0}, {["y"] = 5, ["x"] = 6, ["name"] = "default:tree", ["z"] = 6, ["meta"] = {["inventory"] = {}, ["fields"] = {}}, ["param2"] = 7, ["param1"] = 0}, {["y"] = 5, ["x"] = 6, ["name"] = "default:tree", ["z"] = 7, ["meta"] = {["inventory"] = {}, ["fields"] = {}}, ["param2"] = 7, ["param1"] = 0}, {["y"] = 6, ["x"] = 6, ["name"] = "default:cobble", ["z"] = 0, ["meta"] = {["inventory"] = {}, ["fields"] = {}}, ["param2"] = 0, ["param1"] = 0}, {["y"] = 7, ["x"] = 6, ["name"] = "default:cobble", ["z"] = 0, ["meta"] = {["inventory"] = {}, ["fields"] = {}}, ["param2"] = 0, ["param1"] = 0}, {["y"] = 9, ["x"] = 6, ["name"] = "default:wood", ["z"] = 7, ["meta"] = {["inventory"] = {}, ["fields"] = {}}, ["param2"] = 0, ["param1"] = 0}, {["y"] = 10, ["x"] = 6, ["name"] = "default:wood", ["z"] = 6, ["meta"] = {["inventory"] = {}, ["fields"] = {}}, ["param2"] = 0, ["param1"] = 0}, {["y"] = 10, ["x"] = 6, ["name"] = "default:wood", ["z"] = 7, ["meta"] = {["inventory"] = {}, ["fields"] = {}}, ["param2"] = 0, ["param1"] = 0}, {["y"] = 10, ["x"] = 6, ["name"] = "default:wood", ["z"] = 8, ["meta"] = {["inventory"] = {}, ["fields"] = {}}, ["param2"] = 0, ["param1"] = 0}, {["y"] = 10, ["x"] = 6, ["name"] = "default:cobble", ["z"] = 13, ["meta"] = {["inventory"] = {}, ["fields"] = {}}, ["param2"] = 0, ["param1"] = 0}, {["y"] = 11, ["x"] = 6, ["name"] = "default:wood", ["z"] = 7, ["meta"] = {["inventory"] = {}, ["fields"] = {}}, ["param2"] = 0, ["param1"] = 0}, {["y"] = 0, ["x"] = 7, ["name"] = "default:cobble", ["z"] = 0, ["meta"] = {["inventory"] = {}, ["fields"] = {}}, ["param2"] = 0, ["param1"] = 0}, {["y"] = 0, ["x"] = 7, ["name"] = "default:water_flowing", ["z"] = 1, ["meta"] = {["inventory"] = {}, ["fields"] = {}}, ["param2"] = 7, ["param1"] = 11}, {["y"] = 0, ["x"] = 7, ["name"] = "default:water_flowing", ["z"] = 2, ["meta"] = {["inventory"] = {}, ["fields"] = {}}, ["param2"] = 7, ["param1"] = 12}, {["y"] = 0, ["x"] = 7, ["name"] = "default:water_flowing", ["z"] = 3, ["meta"] = {["inventory"] = {}, ["fields"] = {}}, ["param2"] = 7, ["param1"] = 12}, {["y"] = 0, ["x"] = 7, ["name"] = "default:water_flowing", ["z"] = 4, ["meta"] = {["inventory"] = {}, ["fields"] = {}}, ["param2"] = 7, ["param1"] = 12}, {["y"] = 0, ["x"] = 7, ["name"] = "default:water_flowing", ["z"] = 5, ["meta"] = {["inventory"] = {}, ["fields"] = {}}, ["param2"] = 7, ["param1"] = 12}, {["y"] = 0, ["x"] = 7, ["name"] = "default:water_flowing", ["z"] = 6, ["meta"] = {["inventory"] = {}, ["fields"] = {}}, ["param2"] = 7, ["param1"] = 12}, {["y"] = 0, ["x"] = 7, ["name"] = "default:water_flowing", ["z"] = 7, ["meta"] = {["inventory"] = {}, ["fields"] = {}}, ["param2"] = 7, ["param1"] = 12}, {["y"] = 0, ["x"] = 7, ["name"] = "default:water_flowing", ["z"] = 8, ["meta"] = {["inventory"] = {}, ["fields"] = {}}, ["param2"] = 7, ["param1"] = 12}, {["y"] = 0, ["x"] = 7, ["name"] = "default:water_flowing", ["z"] = 9, ["meta"] = {["inventory"] = {}, ["fields"] = {}}, ["param2"] = 7, ["param1"] = 12}, {["y"] = 0, ["x"] = 7, ["name"] = "default:water_flowing", ["z"] = 10, ["meta"] = {["inventory"] = {}, ["fields"] = {}}, ["param2"] = 7, ["param1"] = 12}, {["y"] = 0, ["x"] = 7, ["name"] = "default:water_flowing", ["z"] = 11, ["meta"] = {["inventory"] = {}, ["fields"] = {}}, ["param2"] = 7, ["param1"] = 12}, {["y"] = 0, ["x"] = 7, ["name"] = "default:water_flowing", ["z"] = 12, ["meta"] = {["inventory"] = {}, ["fields"] = {}}, ["param2"] = 7, ["param1"] = 12}, {["y"] = 0, ["x"] = 7, ["name"] = "default:water_flowing", ["z"] = 13, ["meta"] = {["inventory"] = {}, ["fields"] = {}}, ["param2"] = 7, ["param1"] = 11}, {["y"] = 0, ["x"] = 7, ["name"] = "default:cobble", ["z"] = 14, ["meta"] = {["inventory"] = {}, ["fields"] = {}}, ["param2"] = 0, ["param1"] = 0}, {["y"] = 0, ["x"] = 7, ["name"] = "default:tree", ["z"] = 15, ["meta"] = {["inventory"] = {}, ["fields"] = {}}, ["param2"] = 2, ["param1"] = 0}, {["y"] = 1, ["x"] = 7, ["name"] = "default:cobble", ["z"] = 0, ["meta"] = {["inventory"] = {}, ["fields"] = {}}, ["param2"] = 0, ["param1"] = 0}, {["y"] = 1, ["x"] = 7, ["name"] = "default:water_source", ["z"] = 1, ["meta"] = {["inventory"] = {}, ["fields"] = {}}, ["param2"] = 240, ["param1"] = 11}, {["y"] = 1, ["x"] = 7, ["name"] = "default:water_source", ["z"] = 2, ["meta"] = {["inventory"] = {}, ["fields"] = {}}, ["param2"] = 240, ["param1"] = 12}, {["y"] = 1, ["x"] = 7, ["name"] = "default:water_source", ["z"] = 3, ["meta"] = {["inventory"] = {}, ["fields"] = {}}, ["param2"] = 240, ["param1"] = 12}, {["y"] = 1, ["x"] = 7, ["name"] = "default:water_source", ["z"] = 4, ["meta"] = {["inventory"] = {}, ["fields"] = {}}, ["param2"] = 240, ["param1"] = 12}, {["y"] = 1, ["x"] = 7, ["name"] = "default:water_source", ["z"] = 5, ["meta"] = {["inventory"] = {}, ["fields"] = {}}, ["param2"] = 240, ["param1"] = 12}, {["y"] = 1, ["x"] = 7, ["name"] = "default:water_source", ["z"] = 6, ["meta"] = {["inventory"] = {}, ["fields"] = {}}, ["param2"] = 240, ["param1"] = 12}, {["y"] = 1, ["x"] = 7, ["name"] = "default:water_source", ["z"] = 7, ["meta"] = {["inventory"] = {}, ["fields"] = {}}, ["param2"] = 240, ["param1"] = 12}, {["y"] = 1, ["x"] = 7, ["name"] = "default:water_source", ["z"] = 8, ["meta"] = {["inventory"] = {}, ["fields"] = {}}, ["param2"] = 240, ["param1"] = 12}, {["y"] = 1, ["x"] = 7, ["name"] = "default:water_source", ["z"] = 9, ["meta"] = {["inventory"] = {}, ["fields"] = {}}, ["param2"] = 240, ["param1"] = 12}, {["y"] = 1, ["x"] = 7, ["name"] = "default:water_source", ["z"] = 10, ["meta"] = {["inventory"] = {}, ["fields"] = {}}, ["param2"] = 240, ["param1"] = 12}, {["y"] = 1, ["x"] = 7, ["name"] = "default:water_source", ["z"] = 11, ["meta"] = {["inventory"] = {}, ["fields"] = {}}, ["param2"] = 240, ["param1"] = 12}, {["y"] = 1, ["x"] = 7, ["name"] = "default:water_source", ["z"] = 12, ["meta"] = {["inventory"] = {}, ["fields"] = {}}, ["param2"] = 240, ["param1"] = 12}, {["y"] = 1, ["x"] = 7, ["name"] = "default:water_source", ["z"] = 13, ["meta"] = {["inventory"] = {}, ["fields"] = {}}, ["param2"] = 240, ["param1"] = 11}, {["y"] = 1, ["x"] = 7, ["name"] = "default:tree", ["z"] = 14, ["meta"] = {["inventory"] = {}, ["fields"] = {}}, ["param2"] = 22, ["param1"] = 0}, {["y"] = 2, ["x"] = 7, ["name"] = "default:cobble", ["z"] = 0, ["meta"] = {["inventory"] = {}, ["fields"] = {}}, ["param2"] = 0, ["param1"] = 0}, {["y"] = 2, ["x"] = 7, ["name"] = "default:water_source", ["z"] = 1, ["meta"] = {["inventory"] = {}, ["fields"] = {}}, ["param2"] = 240, ["param1"] = 12}, {["y"] = 2, ["x"] = 7, ["name"] = "default:water_source", ["z"] = 2, ["meta"] = {["inventory"] = {}, ["fields"] = {}}, ["param2"] = 240, ["param1"] = 12}, {["y"] = 2, ["x"] = 7, ["name"] = "default:water_source", ["z"] = 3, ["meta"] = {["inventory"] = {}, ["fields"] = {}}, ["param2"] = 240, ["param1"] = 12}, {["y"] = 2, ["x"] = 7, ["name"] = "default:water_source", ["z"] = 4, ["meta"] = {["inventory"] = {}, ["fields"] = {}}, ["param2"] = 240, ["param1"] = 12}, {["y"] = 2, ["x"] = 7, ["name"] = "default:water_source", ["z"] = 5, ["meta"] = {["inventory"] = {}, ["fields"] = {}}, ["param2"] = 240, ["param1"] = 12}, {["y"] = 2, ["x"] = 7, ["name"] = "default:water_source", ["z"] = 6, ["meta"] = {["inventory"] = {}, ["fields"] = {}}, ["param2"] = 240, ["param1"] = 12}, {["y"] = 2, ["x"] = 7, ["name"] = "default:water_source", ["z"] = 7, ["meta"] = {["inventory"] = {}, ["fields"] = {}}, ["param2"] = 240, ["param1"] = 12}, {["y"] = 2, ["x"] = 7, ["name"] = "default:water_source", ["z"] = 8, ["meta"] = {["inventory"] = {}, ["fields"] = {}}, ["param2"] = 240, ["param1"] = 12}, {["y"] = 2, ["x"] = 7, ["name"] = "default:water_source", ["z"] = 9, ["meta"] = {["inventory"] = {}, ["fields"] = {}}, ["param2"] = 240, ["param1"] = 12}, {["y"] = 2, ["x"] = 7, ["name"] = "default:water_source", ["z"] = 10, ["meta"] = {["inventory"] = {}, ["fields"] = {}}, ["param2"] = 240, ["param1"] = 12}, {["y"] = 2, ["x"] = 7, ["name"] = "default:water_source", ["z"] = 11, ["meta"] = {["inventory"] = {}, ["fields"] = {}}, ["param2"] = 240, ["param1"] = 12}, {["y"] = 2, ["x"] = 7, ["name"] = "default:water_source", ["z"] = 12, ["meta"] = {["inventory"] = {}, ["fields"] = {}}, ["param2"] = 240, ["param1"] = 12}, {["y"] = 2, ["x"] = 7, ["name"] = "default:water_source", ["z"] = 13, ["meta"] = {["inventory"] = {}, ["fields"] = {}}, ["param2"] = 0, ["param1"] = 11}, {["y"] = 2, ["x"] = 7, ["name"] = "default:tree", ["z"] = 14, ["meta"] = {["inventory"] = {}, ["fields"] = {}}, ["param2"] = 2, ["param1"] = 0}, {["y"] = 3, ["x"] = 7, ["name"] = "default:cobble", ["z"] = 0, ["meta"] = {["inventory"] = {}, ["fields"] = {}}, ["param2"] = 0, ["param1"] = 0}, {["y"] = 3, ["x"] = 7, ["name"] = "default:water_source", ["z"] = 1, ["meta"] = {["inventory"] = {}, ["fields"] = {}}, ["param2"] = 240, ["param1"] = 12}, {["y"] = 3, ["x"] = 7, ["name"] = "default:water_source", ["z"] = 2, ["meta"] = {["inventory"] = {}, ["fields"] = {}}, ["param2"] = 240, ["param1"] = 12}, {["y"] = 3, ["x"] = 7, ["name"] = "default:water_source", ["z"] = 3, ["meta"] = {["inventory"] = {}, ["fields"] = {}}, ["param2"] = 240, ["param1"] = 12}, {["y"] = 3, ["x"] = 7, ["name"] = "default:water_source", ["z"] = 4, ["meta"] = {["inventory"] = {}, ["fields"] = {}}, ["param2"] = 240, ["param1"] = 12}, {["y"] = 3, ["x"] = 7, ["name"] = "default:water_source", ["z"] = 5, ["meta"] = {["inventory"] = {}, ["fields"] = {}}, ["param2"] = 240, ["param1"] = 12}, {["y"] = 3, ["x"] = 7, ["name"] = "default:water_source", ["z"] = 6, ["meta"] = {["inventory"] = {}, ["fields"] = {}}, ["param2"] = 240, ["param1"] = 12}, {["y"] = 3, ["x"] = 7, ["name"] = "default:water_source", ["z"] = 7, ["meta"] = {["inventory"] = {}, ["fields"] = {}}, ["param2"] = 240, ["param1"] = 12}, {["y"] = 3, ["x"] = 7, ["name"] = "default:water_source", ["z"] = 8, ["meta"] = {["inventory"] = {}, ["fields"] = {}}, ["param2"] = 240, ["param1"] = 12}, {["y"] = 3, ["x"] = 7, ["name"] = "default:water_source", ["z"] = 9, ["meta"] = {["inventory"] = {}, ["fields"] = {}}, ["param2"] = 240, ["param1"] = 12}, {["y"] = 3, ["x"] = 7, ["name"] = "default:water_source", ["z"] = 10, ["meta"] = {["inventory"] = {}, ["fields"] = {}}, ["param2"] = 240, ["param1"] = 12}, {["y"] = 3, ["x"] = 7, ["name"] = "default:water_source", ["z"] = 11, ["meta"] = {["inventory"] = {}, ["fields"] = {}}, ["param2"] = 0, ["param1"] = 11}, {["y"] = 3, ["x"] = 7, ["name"] = "default:water_source", ["z"] = 12, ["meta"] = {["inventory"] = {}, ["fields"] = {}}, ["param2"] = 0, ["param1"] = 11}, {["y"] = 3, ["x"] = 7, ["name"] = "default:tree", ["z"] = 13, ["meta"] = {["inventory"] = {}, ["fields"] = {}}, ["param2"] = 7, ["param1"] = 0}, {["y"] = 4, ["x"] = 7, ["name"] = "default:cobble", ["z"] = 0, ["meta"] = {["inventory"] = {}, ["fields"] = {}}, ["param2"] = 0, ["param1"] = 0}, {["y"] = 4, ["x"] = 7, ["name"] = "default:water_source", ["z"] = 1, ["meta"] = {["inventory"] = {}, ["fields"] = {}}, ["param2"] = 240, ["param1"] = 12}, {["y"] = 4, ["x"] = 7, ["name"] = "default:water_source", ["z"] = 2, ["meta"] = {["inventory"] = {}, ["fields"] = {}}, ["param2"] = 240, ["param1"] = 12}, {["y"] = 4, ["x"] = 7, ["name"] = "default:water_source", ["z"] = 3, ["meta"] = {["inventory"] = {}, ["fields"] = {}}, ["param2"] = 240, ["param1"] = 12}, {["y"] = 4, ["x"] = 7, ["name"] = "default:water_source", ["z"] = 4, ["meta"] = {["inventory"] = {}, ["fields"] = {}}, ["param2"] = 240, ["param1"] = 12}, {["y"] = 4, ["x"] = 7, ["name"] = "default:water_source", ["z"] = 5, ["meta"] = {["inventory"] = {}, ["fields"] = {}}, ["param2"] = 240, ["param1"] = 12}, {["y"] = 4, ["x"] = 7, ["name"] = "default:water_source", ["z"] = 6, ["meta"] = {["inventory"] = {}, ["fields"] = {}}, ["param2"] = 240, ["param1"] = 12}, {["y"] = 4, ["x"] = 7, ["name"] = "default:water_source", ["z"] = 7, ["meta"] = {["inventory"] = {}, ["fields"] = {}}, ["param2"] = 240, ["param1"] = 12}, {["y"] = 4, ["x"] = 7, ["name"] = "default:water_source", ["z"] = 8, ["meta"] = {["inventory"] = {}, ["fields"] = {}}, ["param2"] = 0, ["param1"] = 11}, {["y"] = 4, ["x"] = 7, ["name"] = "default:water_source", ["z"] = 9, ["meta"] = {["inventory"] = {}, ["fields"] = {}}, ["param2"] = 0, ["param1"] = 11}, {["y"] = 4, ["x"] = 7, ["name"] = "default:water_source", ["z"] = 10, ["meta"] = {["inventory"] = {}, ["fields"] = {}}, ["param2"] = 0, ["param1"] = 11}, {["y"] = 4, ["x"] = 7, ["name"] = "default:tree", ["z"] = 11, ["meta"] = {["inventory"] = {}, ["fields"] = {}}, ["param2"] = 7, ["param1"] = 0}, {["y"] = 4, ["x"] = 7, ["name"] = "default:tree", ["z"] = 12, ["meta"] = {["inventory"] = {}, ["fields"] = {}}, ["param2"] = 7, ["param1"] = 0}, {["y"] = 5, ["x"] = 7, ["name"] = "default:cobble", ["z"] = 0, ["meta"] = {["inventory"] = {}, ["fields"] = {}}, ["param2"] = 0, ["param1"] = 0}, {["y"] = 5, ["x"] = 7, ["name"] = "default:water_source", ["z"] = 1, ["meta"] = {["inventory"] = {}, ["fields"] = {}}, ["param2"] = 0, ["param1"] = 11}, {["y"] = 5, ["x"] = 7, ["name"] = "default:water_source", ["z"] = 2, ["meta"] = {["inventory"] = {}, ["fields"] = {}}, ["param2"] = 0, ["param1"] = 11}, {["y"] = 5, ["x"] = 7, ["name"] = "default:water_source", ["z"] = 3, ["meta"] = {["inventory"] = {}, ["fields"] = {}}, ["param2"] = 0, ["param1"] = 11}, {["y"] = 5, ["x"] = 7, ["name"] = "default:water_source", ["z"] = 4, ["meta"] = {["inventory"] = {}, ["fields"] = {}}, ["param2"] = 0, ["param1"] = 11}, {["y"] = 5, ["x"] = 7, ["name"] = "default:water_source", ["z"] = 5, ["meta"] = {["inventory"] = {}, ["fields"] = {}}, ["param2"] = 0, ["param1"] = 11}, {["y"] = 5, ["x"] = 7, ["name"] = "default:water_source", ["z"] = 6, ["meta"] = {["inventory"] = {}, ["fields"] = {}}, ["param2"] = 0, ["param1"] = 11}, {["y"] = 5, ["x"] = 7, ["name"] = "default:water_source", ["z"] = 7, ["meta"] = {["inventory"] = {}, ["fields"] = {}}, ["param2"] = 0, ["param1"] = 11}, {["y"] = 5, ["x"] = 7, ["name"] = "default:tree", ["z"] = 8, ["meta"] = {["inventory"] = {}, ["fields"] = {}}, ["param2"] = 7, ["param1"] = 0}, {["y"] = 5, ["x"] = 7, ["name"] = "default:tree", ["z"] = 9, ["meta"] = {["inventory"] = {}, ["fields"] = {}}, ["param2"] = 7, ["param1"] = 0}, {["y"] = 5, ["x"] = 7, ["name"] = "default:tree", ["z"] = 10, ["meta"] = {["inventory"] = {}, ["fields"] = {}}, ["param2"] = 7, ["param1"] = 0}, {["y"] = 6, ["x"] = 7, ["name"] = "default:cobble", ["z"] = 0, ["meta"] = {["inventory"] = {}, ["fields"] = {}}, ["param2"] = 0, ["param1"] = 0}, {["y"] = 6, ["x"] = 7, ["name"] = "default:tree", ["z"] = 1, ["meta"] = {["inventory"] = {}, ["fields"] = {}}, ["param2"] = 7, ["param1"] = 0}, {["y"] = 6, ["x"] = 7, ["name"] = "default:tree", ["z"] = 2, ["meta"] = {["inventory"] = {}, ["fields"] = {}}, ["param2"] = 7, ["param1"] = 0}, {["y"] = 6, ["x"] = 7, ["name"] = "default:tree", ["z"] = 3, ["meta"] = {["inventory"] = {}, ["fields"] = {}}, ["param2"] = 7, ["param1"] = 0}, {["y"] = 6, ["x"] = 7, ["name"] = "default:tree", ["z"] = 4, ["meta"] = {["inventory"] = {}, ["fields"] = {}}, ["param2"] = 7, ["param1"] = 0}, {["y"] = 6, ["x"] = 7, ["name"] = "default:tree", ["z"] = 5, ["meta"] = {["inventory"] = {}, ["fields"] = {}}, ["param2"] = 7, ["param1"] = 0}, {["y"] = 6, ["x"] = 7, ["name"] = "default:tree", ["z"] = 6, ["meta"] = {["inventory"] = {}, ["fields"] = {}}, ["param2"] = 7, ["param1"] = 0}, {["y"] = 6, ["x"] = 7, ["name"] = "default:tree", ["z"] = 7, ["meta"] = {["inventory"] = {}, ["fields"] = {}}, ["param2"] = 7, ["param1"] = 0}, {["y"] = 7, ["x"] = 7, ["name"] = "default:cobble", ["z"] = 0, ["meta"] = {["inventory"] = {}, ["fields"] = {}}, ["param2"] = 0, ["param1"] = 0}, {["y"] = 8, ["x"] = 7, ["name"] = "default:wood", ["z"] = 7, ["meta"] = {["inventory"] = {}, ["fields"] = {}}, ["param2"] = 0, ["param1"] = 0}, {["y"] = 10, ["x"] = 7, ["name"] = "default:wood", ["z"] = 5, ["meta"] = {["inventory"] = {}, ["fields"] = {}}, ["param2"] = 0, ["param1"] = 0}, {["y"] = 10, ["x"] = 7, ["name"] = "default:wood", ["z"] = 9, ["meta"] = {["inventory"] = {}, ["fields"] = {}}, ["param2"] = 0, ["param1"] = 0}, {["y"] = 10, ["x"] = 7, ["name"] = "default:cobble", ["z"] = 13, ["meta"] = {["inventory"] = {}, ["fields"] = {}}, ["param2"] = 0, ["param1"] = 0}, {["y"] = 12, ["x"] = 7, ["name"] = "default:wood", ["z"] = 7, ["meta"] = {["inventory"] = {}, ["fields"] = {}}, ["param2"] = 0, ["param1"] = 0}, {["y"] = 0, ["x"] = 8, ["name"] = "default:cobble", ["z"] = 0, ["meta"] = {["inventory"] = {}, ["fields"] = {}}, ["param2"] = 0, ["param1"] = 0}, {["y"] = 0, ["x"] = 8, ["name"] = "default:glass", ["z"] = 1, ["meta"] = {["inventory"] = {}, ["fields"] = {}}, ["param2"] = 0, ["param1"] = 11}, {["y"] = 0, ["x"] = 8, ["name"] = "default:glass", ["z"] = 2, ["meta"] = {["inventory"] = {}, ["fields"] = {}}, ["param2"] = 0, ["param1"] = 12}, {["y"] = 0, ["x"] = 8, ["name"] = "default:glass", ["z"] = 3, ["meta"] = {["inventory"] = {}, ["fields"] = {}}, ["param2"] = 0, ["param1"] = 12}, {["y"] = 0, ["x"] = 8, ["name"] = "default:glass", ["z"] = 4, ["meta"] = {["inventory"] = {}, ["fields"] = {}}, ["param2"] = 0, ["param1"] = 11}, {["y"] = 0, ["x"] = 8, ["name"] = "default:glass", ["z"] = 5, ["meta"] = {["inventory"] = {}, ["fields"] = {}}, ["param2"] = 0, ["param1"] = 12}, {["y"] = 0, ["x"] = 8, ["name"] = "default:glass", ["z"] = 6, ["meta"] = {["inventory"] = {}, ["fields"] = {}}, ["param2"] = 0, ["param1"] = 12}, {["y"] = 0, ["x"] = 8, ["name"] = "default:glass", ["z"] = 7, ["meta"] = {["inventory"] = {}, ["fields"] = {}}, ["param2"] = 0, ["param1"] = 11}, {["y"] = 0, ["x"] = 8, ["name"] = "default:glass", ["z"] = 8, ["meta"] = {["inventory"] = {}, ["fields"] = {}}, ["param2"] = 0, ["param1"] = 12}, {["y"] = 0, ["x"] = 8, ["name"] = "default:glass", ["z"] = 9, ["meta"] = {["inventory"] = {}, ["fields"] = {}}, ["param2"] = 0, ["param1"] = 12}, {["y"] = 0, ["x"] = 8, ["name"] = "default:glass", ["z"] = 10, ["meta"] = {["inventory"] = {}, ["fields"] = {}}, ["param2"] = 0, ["param1"] = 11}, {["y"] = 0, ["x"] = 8, ["name"] = "default:glass", ["z"] = 11, ["meta"] = {["inventory"] = {}, ["fields"] = {}}, ["param2"] = 0, ["param1"] = 12}, {["y"] = 0, ["x"] = 8, ["name"] = "default:glass", ["z"] = 12, ["meta"] = {["inventory"] = {}, ["fields"] = {}}, ["param2"] = 0, ["param1"] = 11}, {["y"] = 0, ["x"] = 8, ["name"] = "default:glass", ["z"] = 13, ["meta"] = {["inventory"] = {}, ["fields"] = {}}, ["param2"] = 0, ["param1"] = 10}, {["y"] = 0, ["x"] = 8, ["name"] = "default:cobble", ["z"] = 14, ["meta"] = {["inventory"] = {}, ["fields"] = {}}, ["param2"] = 0, ["param1"] = 0}, {["y"] = 1, ["x"] = 8, ["name"] = "default:cobble", ["z"] = 0, ["meta"] = {["inventory"] = {}, ["fields"] = {}}, ["param2"] = 0, ["param1"] = 0}, {["y"] = 1, ["x"] = 8, ["name"] = "default:glass", ["z"] = 1, ["meta"] = {["inventory"] = {}, ["fields"] = {}}, ["param2"] = 0, ["param1"] = 11}, {["y"] = 1, ["x"] = 8, ["name"] = "default:glass", ["z"] = 2, ["meta"] = {["inventory"] = {}, ["fields"] = {}}, ["param2"] = 0, ["param1"] = 12}, {["y"] = 1, ["x"] = 8, ["name"] = "default:glass", ["z"] = 3, ["meta"] = {["inventory"] = {}, ["fields"] = {}}, ["param2"] = 0, ["param1"] = 12}, {["y"] = 1, ["x"] = 8, ["name"] = "default:glass", ["z"] = 4, ["meta"] = {["inventory"] = {}, ["fields"] = {}}, ["param2"] = 0, ["param1"] = 11}, {["y"] = 1, ["x"] = 8, ["name"] = "default:glass", ["z"] = 5, ["meta"] = {["inventory"] = {}, ["fields"] = {}}, ["param2"] = 0, ["param1"] = 12}, {["y"] = 1, ["x"] = 8, ["name"] = "default:glass", ["z"] = 6, ["meta"] = {["inventory"] = {}, ["fields"] = {}}, ["param2"] = 0, ["param1"] = 12}, {["y"] = 1, ["x"] = 8, ["name"] = "default:glass", ["z"] = 7, ["meta"] = {["inventory"] = {}, ["fields"] = {}}, ["param2"] = 0, ["param1"] = 11}, {["y"] = 1, ["x"] = 8, ["name"] = "default:glass", ["z"] = 8, ["meta"] = {["inventory"] = {}, ["fields"] = {}}, ["param2"] = 0, ["param1"] = 12}, {["y"] = 1, ["x"] = 8, ["name"] = "default:glass", ["z"] = 9, ["meta"] = {["inventory"] = {}, ["fields"] = {}}, ["param2"] = 0, ["param1"] = 12}, {["y"] = 1, ["x"] = 8, ["name"] = "default:glass", ["z"] = 10, ["meta"] = {["inventory"] = {}, ["fields"] = {}}, ["param2"] = 0, ["param1"] = 11}, {["y"] = 1, ["x"] = 8, ["name"] = "default:glass", ["z"] = 11, ["meta"] = {["inventory"] = {}, ["fields"] = {}}, ["param2"] = 0, ["param1"] = 12}, {["y"] = 1, ["x"] = 8, ["name"] = "default:glass", ["z"] = 12, ["meta"] = {["inventory"] = {}, ["fields"] = {}}, ["param2"] = 0, ["param1"] = 11}, {["y"] = 1, ["x"] = 8, ["name"] = "default:glass", ["z"] = 13, ["meta"] = {["inventory"] = {}, ["fields"] = {}}, ["param2"] = 0, ["param1"] = 11}, {["y"] = 1, ["x"] = 8, ["name"] = "default:tree", ["z"] = 14, ["meta"] = {["inventory"] = {}, ["fields"] = {}}, ["param2"] = 3, ["param1"] = 0}, {["y"] = 2, ["x"] = 8, ["name"] = "default:cobble", ["z"] = 0, ["meta"] = {["inventory"] = {}, ["fields"] = {}}, ["param2"] = 0, ["param1"] = 0}, {["y"] = 2, ["x"] = 8, ["name"] = "default:glass", ["z"] = 1, ["meta"] = {["inventory"] = {}, ["fields"] = {}}, ["param2"] = 0, ["param1"] = 11}, {["y"] = 2, ["x"] = 8, ["name"] = "default:glass", ["z"] = 2, ["meta"] = {["inventory"] = {}, ["fields"] = {}}, ["param2"] = 0, ["param1"] = 12}, {["y"] = 2, ["x"] = 8, ["name"] = "default:glass", ["z"] = 3, ["meta"] = {["inventory"] = {}, ["fields"] = {}}, ["param2"] = 0, ["param1"] = 12}, {["y"] = 2, ["x"] = 8, ["name"] = "default:glass", ["z"] = 4, ["meta"] = {["inventory"] = {}, ["fields"] = {}}, ["param2"] = 0, ["param1"] = 11}, {["y"] = 2, ["x"] = 8, ["name"] = "default:glass", ["z"] = 5, ["meta"] = {["inventory"] = {}, ["fields"] = {}}, ["param2"] = 0, ["param1"] = 12}, {["y"] = 2, ["x"] = 8, ["name"] = "default:glass", ["z"] = 6, ["meta"] = {["inventory"] = {}, ["fields"] = {}}, ["param2"] = 0, ["param1"] = 12}, {["y"] = 2, ["x"] = 8, ["name"] = "default:glass", ["z"] = 7, ["meta"] = {["inventory"] = {}, ["fields"] = {}}, ["param2"] = 0, ["param1"] = 11}, {["y"] = 2, ["x"] = 8, ["name"] = "default:glass", ["z"] = 8, ["meta"] = {["inventory"] = {}, ["fields"] = {}}, ["param2"] = 0, ["param1"] = 12}, {["y"] = 2, ["x"] = 8, ["name"] = "default:glass", ["z"] = 9, ["meta"] = {["inventory"] = {}, ["fields"] = {}}, ["param2"] = 0, ["param1"] = 12}, {["y"] = 2, ["x"] = 8, ["name"] = "default:glass", ["z"] = 10, ["meta"] = {["inventory"] = {}, ["fields"] = {}}, ["param2"] = 0, ["param1"] = 11}, {["y"] = 2, ["x"] = 8, ["name"] = "default:glass", ["z"] = 11, ["meta"] = {["inventory"] = {}, ["fields"] = {}}, ["param2"] = 0, ["param1"] = 12}, {["y"] = 2, ["x"] = 8, ["name"] = "default:glass", ["z"] = 12, ["meta"] = {["inventory"] = {}, ["fields"] = {}}, ["param2"] = 0, ["param1"] = 11}, {["y"] = 2, ["x"] = 8, ["name"] = "default:tree", ["z"] = 13, ["meta"] = {["inventory"] = {}, ["fields"] = {}}, ["param2"] = 7, ["param1"] = 0}, {["y"] = 3, ["x"] = 8, ["name"] = "default:cobble", ["z"] = 0, ["meta"] = {["inventory"] = {}, ["fields"] = {}}, ["param2"] = 0, ["param1"] = 0}, {["y"] = 3, ["x"] = 8, ["name"] = "default:glass", ["z"] = 1, ["meta"] = {["inventory"] = {}, ["fields"] = {}}, ["param2"] = 0, ["param1"] = 11}, {["y"] = 3, ["x"] = 8, ["name"] = "default:glass", ["z"] = 2, ["meta"] = {["inventory"] = {}, ["fields"] = {}}, ["param2"] = 0, ["param1"] = 12}, {["y"] = 3, ["x"] = 8, ["name"] = "default:glass", ["z"] = 3, ["meta"] = {["inventory"] = {}, ["fields"] = {}}, ["param2"] = 0, ["param1"] = 12}, {["y"] = 3, ["x"] = 8, ["name"] = "default:glass", ["z"] = 4, ["meta"] = {["inventory"] = {}, ["fields"] = {}}, ["param2"] = 0, ["param1"] = 11}, {["y"] = 3, ["x"] = 8, ["name"] = "default:glass", ["z"] = 5, ["meta"] = {["inventory"] = {}, ["fields"] = {}}, ["param2"] = 0, ["param1"] = 12}, {["y"] = 3, ["x"] = 8, ["name"] = "default:glass", ["z"] = 6, ["meta"] = {["inventory"] = {}, ["fields"] = {}}, ["param2"] = 0, ["param1"] = 12}, {["y"] = 3, ["x"] = 8, ["name"] = "default:glass", ["z"] = 7, ["meta"] = {["inventory"] = {}, ["fields"] = {}}, ["param2"] = 0, ["param1"] = 11}, {["y"] = 3, ["x"] = 8, ["name"] = "default:glass", ["z"] = 8, ["meta"] = {["inventory"] = {}, ["fields"] = {}}, ["param2"] = 0, ["param1"] = 12}, {["y"] = 3, ["x"] = 8, ["name"] = "default:glass", ["z"] = 9, ["meta"] = {["inventory"] = {}, ["fields"] = {}}, ["param2"] = 0, ["param1"] = 12}, {["y"] = 3, ["x"] = 8, ["name"] = "default:glass", ["z"] = 10, ["meta"] = {["inventory"] = {}, ["fields"] = {}}, ["param2"] = 0, ["param1"] = 11}, {["y"] = 3, ["x"] = 8, ["name"] = "default:tree", ["z"] = 11, ["meta"] = {["inventory"] = {}, ["fields"] = {}}, ["param2"] = 7, ["param1"] = 0}, {["y"] = 3, ["x"] = 8, ["name"] = "default:tree", ["z"] = 12, ["meta"] = {["inventory"] = {}, ["fields"] = {}}, ["param2"] = 7, ["param1"] = 0}, {["y"] = 4, ["x"] = 8, ["name"] = "default:cobble", ["z"] = 0, ["meta"] = {["inventory"] = {}, ["fields"] = {}}, ["param2"] = 0, ["param1"] = 0}, {["y"] = 4, ["x"] = 8, ["name"] = "default:glass", ["z"] = 1, ["meta"] = {["inventory"] = {}, ["fields"] = {}}, ["param2"] = 0, ["param1"] = 11}, {["y"] = 4, ["x"] = 8, ["name"] = "default:glass", ["z"] = 2, ["meta"] = {["inventory"] = {}, ["fields"] = {}}, ["param2"] = 0, ["param1"] = 12}, {["y"] = 4, ["x"] = 8, ["name"] = "default:glass", ["z"] = 3, ["meta"] = {["inventory"] = {}, ["fields"] = {}}, ["param2"] = 0, ["param1"] = 12}, {["y"] = 4, ["x"] = 8, ["name"] = "default:glass", ["z"] = 4, ["meta"] = {["inventory"] = {}, ["fields"] = {}}, ["param2"] = 0, ["param1"] = 11}, {["y"] = 4, ["x"] = 8, ["name"] = "default:glass", ["z"] = 5, ["meta"] = {["inventory"] = {}, ["fields"] = {}}, ["param2"] = 0, ["param1"] = 12}, {["y"] = 4, ["x"] = 8, ["name"] = "default:glass", ["z"] = 6, ["meta"] = {["inventory"] = {}, ["fields"] = {}}, ["param2"] = 0, ["param1"] = 12}, {["y"] = 4, ["x"] = 8, ["name"] = "default:glass", ["z"] = 7, ["meta"] = {["inventory"] = {}, ["fields"] = {}}, ["param2"] = 0, ["param1"] = 11}, {["y"] = 4, ["x"] = 8, ["name"] = "default:tree", ["z"] = 8, ["meta"] = {["inventory"] = {}, ["fields"] = {}}, ["param2"] = 7, ["param1"] = 0}, {["y"] = 4, ["x"] = 8, ["name"] = "default:tree", ["z"] = 9, ["meta"] = {["inventory"] = {}, ["fields"] = {}}, ["param2"] = 7, ["param1"] = 0}, {["y"] = 4, ["x"] = 8, ["name"] = "default:tree", ["z"] = 10, ["meta"] = {["inventory"] = {}, ["fields"] = {}}, ["param2"] = 7, ["param1"] = 0}, {["y"] = 5, ["x"] = 8, ["name"] = "default:cobble", ["z"] = 0, ["meta"] = {["inventory"] = {}, ["fields"] = {}}, ["param2"] = 0, ["param1"] = 0}, {["y"] = 5, ["x"] = 8, ["name"] = "default:tree", ["z"] = 1, ["meta"] = {["inventory"] = {}, ["fields"] = {}}, ["param2"] = 7, ["param1"] = 0}, {["y"] = 5, ["x"] = 8, ["name"] = "default:tree", ["z"] = 2, ["meta"] = {["inventory"] = {}, ["fields"] = {}}, ["param2"] = 7, ["param1"] = 0}, {["y"] = 5, ["x"] = 8, ["name"] = "default:tree", ["z"] = 3, ["meta"] = {["inventory"] = {}, ["fields"] = {}}, ["param2"] = 7, ["param1"] = 0}, {["y"] = 5, ["x"] = 8, ["name"] = "default:tree", ["z"] = 4, ["meta"] = {["inventory"] = {}, ["fields"] = {}}, ["param2"] = 7, ["param1"] = 0}, {["y"] = 5, ["x"] = 8, ["name"] = "default:tree", ["z"] = 5, ["meta"] = {["inventory"] = {}, ["fields"] = {}}, ["param2"] = 7, ["param1"] = 0}, {["y"] = 5, ["x"] = 8, ["name"] = "default:tree", ["z"] = 6, ["meta"] = {["inventory"] = {}, ["fields"] = {}}, ["param2"] = 7, ["param1"] = 0}, {["y"] = 5, ["x"] = 8, ["name"] = "default:tree", ["z"] = 7, ["meta"] = {["inventory"] = {}, ["fields"] = {}}, ["param2"] = 7, ["param1"] = 0}, {["y"] = 6, ["x"] = 8, ["name"] = "default:cobble", ["z"] = 0, ["meta"] = {["inventory"] = {}, ["fields"] = {}}, ["param2"] = 0, ["param1"] = 0}, {["y"] = 7, ["x"] = 8, ["name"] = "default:cobble", ["z"] = 0, ["meta"] = {["inventory"] = {}, ["fields"] = {}}, ["param2"] = 0, ["param1"] = 0}, {["y"] = 7, ["x"] = 8, ["name"] = "default:wood", ["z"] = 7, ["meta"] = {["inventory"] = {}, ["fields"] = {}}, ["param2"] = 0, ["param1"] = 0}, {["y"] = 9, ["x"] = 8, ["name"] = "default:cobble", ["z"] = 13, ["meta"] = {["inventory"] = {}, ["fields"] = {}}, ["param2"] = 0, ["param1"] = 0}, {["y"] = 10, ["x"] = 8, ["name"] = "default:wood", ["z"] = 4, ["meta"] = {["inventory"] = {}, ["fields"] = {}}, ["param2"] = 0, ["param1"] = 0}, {["y"] = 10, ["x"] = 8, ["name"] = "default:wood", ["z"] = 10, ["meta"] = {["inventory"] = {}, ["fields"] = {}}, ["param2"] = 0, ["param1"] = 0}, {["y"] = 10, ["x"] = 8, ["name"] = "default:cobble", ["z"] = 12, ["meta"] = {["inventory"] = {}, ["fields"] = {}}, ["param2"] = 0, ["param1"] = 0}, {["y"] = 10, ["x"] = 8, ["name"] = "default:cobble", ["z"] = 13, ["meta"] = {["inventory"] = {}, ["fields"] = {}}, ["param2"] = 0, ["param1"] = 0}, {["y"] = 10, ["x"] = 8, ["name"] = "default:cobble", ["z"] = 14, ["meta"] = {["inventory"] = {}, ["fields"] = {}}, ["param2"] = 0, ["param1"] = 0}, {["y"] = 11, ["x"] = 8, ["name"] = "default:cobble", ["z"] = 13, ["meta"] = {["inventory"] = {}, ["fields"] = {}}, ["param2"] = 0, ["param1"] = 0}, {["y"] = 13, ["x"] = 8, ["name"] = "default:wood", ["z"] = 7, ["meta"] = {["inventory"] = {}, ["fields"] = {}}, ["param2"] = 0, ["param1"] = 0}, {["y"] = 0, ["x"] = 9, ["name"] = "default:cobble", ["z"] = 0, ["meta"] = {["inventory"] = {}, ["fields"] = {}}, ["param2"] = 0, ["param1"] = 0}, {["y"] = 0, ["x"] = 9, ["name"] = "default:cobble", ["z"] = 14, ["meta"] = {["inventory"] = {}, ["fields"] = {}}, ["param2"] = 0, ["param1"] = 0}, {["y"] = 0, ["x"] = 9, ["name"] = "default:tree", ["z"] = 15, ["meta"] = {["inventory"] = {}, ["fields"] = {}}, ["param2"] = 2, ["param1"] = 0}, {["y"] = 1, ["x"] = 9, ["name"] = "default:cobble", ["z"] = 0, ["meta"] = {["inventory"] = {}, ["fields"] = {}}, ["param2"] = 0, ["param1"] = 0}, {["y"] = 2, ["x"] = 9, ["name"] = "default:cobble", ["z"] = 0, ["meta"] = {["inventory"] = {}, ["fields"] = {}}, ["param2"] = 0, ["param1"] = 0}, {["y"] = 3, ["x"] = 9, ["name"] = "default:cobble", ["z"] = 0, ["meta"] = {["inventory"] = {}, ["fields"] = {}}, ["param2"] = 0, ["param1"] = 0}, {["y"] = 4, ["x"] = 9, ["name"] = "default:cobble", ["z"] = 0, ["meta"] = {["inventory"] = {}, ["fields"] = {}}, ["param2"] = 0, ["param1"] = 0}, {["y"] = 5, ["x"] = 9, ["name"] = "default:cobble", ["z"] = 0, ["meta"] = {["inventory"] = {}, ["fields"] = {}}, ["param2"] = 0, ["param1"] = 0}, {["y"] = 6, ["x"] = 9, ["name"] = "default:cobble", ["z"] = 0, ["meta"] = {["inventory"] = {}, ["fields"] = {}}, ["param2"] = 0, ["param1"] = 0}, {["y"] = 7, ["x"] = 9, ["name"] = "default:cobble", ["z"] = 0, ["meta"] = {["inventory"] = {}, ["fields"] = {}}, ["param2"] = 0, ["param1"] = 0}, {["y"] = 7, ["x"] = 9, ["name"] = "default:wood", ["z"] = 6, ["meta"] = {["inventory"] = {}, ["fields"] = {}}, ["param2"] = 0, ["param1"] = 0}, {["y"] = 7, ["x"] = 9, ["name"] = "default:wood", ["z"] = 7, ["meta"] = {["inventory"] = {}, ["fields"] = {}}, ["param2"] = 0, ["param1"] = 0}, {["y"] = 7, ["x"] = 9, ["name"] = "default:wood", ["z"] = 8, ["meta"] = {["inventory"] = {}, ["fields"] = {}}, ["param2"] = 0, ["param1"] = 0}, {["y"] = 8, ["x"] = 9, ["name"] = "default:cobble", ["z"] = 0, ["meta"] = {["inventory"] = {}, ["fields"] = {}}, ["param2"] = 0, ["param1"] = 0}, {["y"] = 8, ["x"] = 9, ["name"] = "default:wood", ["z"] = 5, ["meta"] = {["inventory"] = {}, ["fields"] = {}}, ["param2"] = 0, ["param1"] = 0}, {["y"] = 8, ["x"] = 9, ["name"] = "default:wood", ["z"] = 9, ["meta"] = {["inventory"] = {}, ["fields"] = {}}, ["param2"] = 0, ["param1"] = 0}, {["y"] = 8, ["x"] = 9, ["name"] = "default:cobble", ["z"] = 13, ["meta"] = {["inventory"] = {}, ["fields"] = {}}, ["param2"] = 0, ["param1"] = 0}, {["y"] = 9, ["x"] = 9, ["name"] = "default:cobble", ["z"] = 1, ["meta"] = {["inventory"] = {}, ["fields"] = {}}, ["param2"] = 0, ["param1"] = 0}, {["y"] = 9, ["x"] = 9, ["name"] = "default:wood", ["z"] = 4, ["meta"] = {["inventory"] = {}, ["fields"] = {}}, ["param2"] = 0, ["param1"] = 0}, {["y"] = 9, ["x"] = 9, ["name"] = "default:wood", ["z"] = 10, ["meta"] = {["inventory"] = {}, ["fields"] = {}}, ["param2"] = 0, ["param1"] = 0}, {["y"] = 9, ["x"] = 9, ["name"] = "default:cobble", ["z"] = 12, ["meta"] = {["inventory"] = {}, ["fields"] = {}}, ["param2"] = 0, ["param1"] = 0}, {["y"] = 9, ["x"] = 9, ["name"] = "default:cobble", ["z"] = 13, ["meta"] = {["inventory"] = {}, ["fields"] = {}}, ["param2"] = 0, ["param1"] = 0}, {["y"] = 9, ["x"] = 9, ["name"] = "default:cobble", ["z"] = 14, ["meta"] = {["inventory"] = {}, ["fields"] = {}}, ["param2"] = 0, ["param1"] = 0}, {["y"] = 10, ["x"] = 9, ["name"] = "default:cobble", ["z"] = 2, ["meta"] = {["inventory"] = {}, ["fields"] = {}}, ["param2"] = 0, ["param1"] = 0}, {["y"] = 10, ["x"] = 9, ["name"] = "default:cobble", ["z"] = 3, ["meta"] = {["inventory"] = {}, ["fields"] = {}}, ["param2"] = 0, ["param1"] = 0}, {["y"] = 10, ["x"] = 9, ["name"] = "default:cobble", ["z"] = 4, ["meta"] = {["inventory"] = {}, ["fields"] = {}}, ["param2"] = 0, ["param1"] = 0}, {["y"] = 10, ["x"] = 9, ["name"] = "default:cobble", ["z"] = 5, ["meta"] = {["inventory"] = {}, ["fields"] = {}}, ["param2"] = 0, ["param1"] = 0}, {["y"] = 10, ["x"] = 9, ["name"] = "default:cobble", ["z"] = 6, ["meta"] = {["inventory"] = {}, ["fields"] = {}}, ["param2"] = 0, ["param1"] = 0}, {["y"] = 10, ["x"] = 9, ["name"] = "default:glass", ["z"] = 7, ["meta"] = {["inventory"] = {}, ["fields"] = {}}, ["param2"] = 0, ["param1"] = 12}, {["y"] = 10, ["x"] = 9, ["name"] = "default:cobble", ["z"] = 8, ["meta"] = {["inventory"] = {}, ["fields"] = {}}, ["param2"] = 0, ["param1"] = 0}, {["y"] = 10, ["x"] = 9, ["name"] = "default:cobble", ["z"] = 9, ["meta"] = {["inventory"] = {}, ["fields"] = {}}, ["param2"] = 0, ["param1"] = 0}, {["y"] = 10, ["x"] = 9, ["name"] = "default:cobble", ["z"] = 10, ["meta"] = {["inventory"] = {}, ["fields"] = {}}, ["param2"] = 0, ["param1"] = 0}, {["y"] = 10, ["x"] = 9, ["name"] = "default:cobble", ["z"] = 11, ["meta"] = {["inventory"] = {}, ["fields"] = {}}, ["param2"] = 0, ["param1"] = 0}, {["y"] = 10, ["x"] = 9, ["name"] = "default:cobble", ["z"] = 12, ["meta"] = {["inventory"] = {}, ["fields"] = {}}, ["param2"] = 0, ["param1"] = 0}, {["y"] = 10, ["x"] = 9, ["name"] = "default:cobble", ["z"] = 13, ["meta"] = {["inventory"] = {}, ["fields"] = {}}, ["param2"] = 0, ["param1"] = 0}, {["y"] = 10, ["x"] = 9, ["name"] = "default:cobble", ["z"] = 14, ["meta"] = {["inventory"] = {}, ["fields"] = {}}, ["param2"] = 0, ["param1"] = 0}, {["y"] = 11, ["x"] = 9, ["name"] = "default:wood", ["z"] = 4, ["meta"] = {["inventory"] = {}, ["fields"] = {}}, ["param2"] = 0, ["param1"] = 0}, {["y"] = 11, ["x"] = 9, ["name"] = "default:wood", ["z"] = 10, ["meta"] = {["inventory"] = {}, ["fields"] = {}}, ["param2"] = 0, ["param1"] = 0}, {["y"] = 11, ["x"] = 9, ["name"] = "default:cobble", ["z"] = 12, ["meta"] = {["inventory"] = {}, ["fields"] = {}}, ["param2"] = 0, ["param1"] = 0}, {["y"] = 11, ["x"] = 9, ["name"] = "default:cobble", ["z"] = 13, ["meta"] = {["inventory"] = {}, ["fields"] = {}}, ["param2"] = 0, ["param1"] = 0}, {["y"] = 11, ["x"] = 9, ["name"] = "default:cobble", ["z"] = 14, ["meta"] = {["inventory"] = {}, ["fields"] = {}}, ["param2"] = 0, ["param1"] = 0}, {["y"] = 12, ["x"] = 9, ["name"] = "default:wood", ["z"] = 5, ["meta"] = {["inventory"] = {}, ["fields"] = {}}, ["param2"] = 0, ["param1"] = 0}, {["y"] = 12, ["x"] = 9, ["name"] = "default:wood", ["z"] = 9, ["meta"] = {["inventory"] = {}, ["fields"] = {}}, ["param2"] = 0, ["param1"] = 0}, {["y"] = 13, ["x"] = 9, ["name"] = "default:wood", ["z"] = 6, ["meta"] = {["inventory"] = {}, ["fields"] = {}}, ["param2"] = 0, ["param1"] = 0}, {["y"] = 13, ["x"] = 9, ["name"] = "default:wood", ["z"] = 7, ["meta"] = {["inventory"] = {}, ["fields"] = {}}, ["param2"] = 0, ["param1"] = 0}, {["y"] = 13, ["x"] = 9, ["name"] = "default:wood", ["z"] = 8, ["meta"] = {["inventory"] = {}, ["fields"] = {}}, ["param2"] = 0, ["param1"] = 0}, {["y"] = 0, ["x"] = 10, ["name"] = "default:cobble", ["z"] = 1, ["meta"] = {["inventory"] = {}, ["fields"] = {}}, ["param2"] = 0, ["param1"] = 0}, {["y"] = 0, ["x"] = 10, ["name"] = "default:cobble", ["z"] = 13, ["meta"] = {["inventory"] = {}, ["fields"] = {}}, ["param2"] = 0, ["param1"] = 0}, {["y"] = 0, ["x"] = 10, ["name"] = "default:wood", ["z"] = 14, ["meta"] = {["inventory"] = {}, ["fields"] = {}}, ["param2"] = 0, ["param1"] = 0}, {["y"] = 0, ["x"] = 10, ["name"] = "default:water_flowing", ["z"] = 15, ["meta"] = {["inventory"] = {}, ["fields"] = {}}, ["param2"] = 4, ["param1"] = 15}, {["y"] = 0, ["x"] = 10, ["name"] = "default:wood", ["z"] = 16, ["meta"] = {["inventory"] = {}, ["fields"] = {}}, ["param2"] = 0, ["param1"] = 0}, {["y"] = 1, ["x"] = 10, ["name"] = "default:cobble", ["z"] = 1, ["meta"] = {["inventory"] = {}, ["fields"] = {}}, ["param2"] = 0, ["param1"] = 0}, {["y"] = 1, ["x"] = 10, ["name"] = "default:cobble", ["z"] = 13, ["meta"] = {["inventory"] = {}, ["fields"] = {}}, ["param2"] = 0, ["param1"] = 0}, {["y"] = 2, ["x"] = 10, ["name"] = "default:cobble", ["z"] = 1, ["meta"] = {["inventory"] = {}, ["fields"] = {}}, ["param2"] = 0, ["param1"] = 0}, {["y"] = 2, ["x"] = 10, ["name"] = "default:cobble", ["z"] = 13, ["meta"] = {["inventory"] = {}, ["fields"] = {}}, ["param2"] = 0, ["param1"] = 0}, {["y"] = 3, ["x"] = 10, ["name"] = "default:cobble", ["z"] = 1, ["meta"] = {["inventory"] = {}, ["fields"] = {}}, ["param2"] = 0, ["param1"] = 0}, {["y"] = 3, ["x"] = 10, ["name"] = "default:cobble", ["z"] = 13, ["meta"] = {["inventory"] = {}, ["fields"] = {}}, ["param2"] = 0, ["param1"] = 0}, {["y"] = 4, ["x"] = 10, ["name"] = "default:cobble", ["z"] = 1, ["meta"] = {["inventory"] = {}, ["fields"] = {}}, ["param2"] = 0, ["param1"] = 0}, {["y"] = 4, ["x"] = 10, ["name"] = "default:cobble", ["z"] = 13, ["meta"] = {["inventory"] = {}, ["fields"] = {}}, ["param2"] = 0, ["param1"] = 0}, {["y"] = 5, ["x"] = 10, ["name"] = "default:cobble", ["z"] = 1, ["meta"] = {["inventory"] = {}, ["fields"] = {}}, ["param2"] = 0, ["param1"] = 0}, {["y"] = 5, ["x"] = 10, ["name"] = "default:cobble", ["z"] = 13, ["meta"] = {["inventory"] = {}, ["fields"] = {}}, ["param2"] = 0, ["param1"] = 0}, {["y"] = 6, ["x"] = 10, ["name"] = "default:cobble", ["z"] = 1, ["meta"] = {["inventory"] = {}, ["fields"] = {}}, ["param2"] = 0, ["param1"] = 0}, {["y"] = 6, ["x"] = 10, ["name"] = "default:cobble", ["z"] = 13, ["meta"] = {["inventory"] = {}, ["fields"] = {}}, ["param2"] = 0, ["param1"] = 0}, {["y"] = 7, ["x"] = 10, ["name"] = "default:cobble", ["z"] = 1, ["meta"] = {["inventory"] = {}, ["fields"] = {}}, ["param2"] = 0, ["param1"] = 0}, {["y"] = 7, ["x"] = 10, ["name"] = "default:wood", ["z"] = 7, ["meta"] = {["inventory"] = {}, ["fields"] = {}}, ["param2"] = 0, ["param1"] = 0}, {["y"] = 7, ["x"] = 10, ["name"] = "default:cobble", ["z"] = 13, ["meta"] = {["inventory"] = {}, ["fields"] = {}}, ["param2"] = 0, ["param1"] = 0}, {["y"] = 8, ["x"] = 10, ["name"] = "default:cobble", ["z"] = 1, ["meta"] = {["inventory"] = {}, ["fields"] = {}}, ["param2"] = 0, ["param1"] = 0}, {["y"] = 8, ["x"] = 10, ["name"] = "default:cobble", ["z"] = 13, ["meta"] = {["inventory"] = {}, ["fields"] = {}}, ["param2"] = 0, ["param1"] = 0}, {["y"] = 9, ["x"] = 10, ["name"] = "default:cobble", ["z"] = 13, ["meta"] = {["inventory"] = {}, ["fields"] = {}}, ["param2"] = 0, ["param1"] = 0}, {["y"] = 10, ["x"] = 10, ["name"] = "default:wood", ["z"] = 4, ["meta"] = {["inventory"] = {}, ["fields"] = {}}, ["param2"] = 0, ["param1"] = 0}, {["y"] = 10, ["x"] = 10, ["name"] = "default:wood", ["z"] = 10, ["meta"] = {["inventory"] = {}, ["fields"] = {}}, ["param2"] = 0, ["param1"] = 0}, {["y"] = 10, ["x"] = 10, ["name"] = "default:cobble", ["z"] = 12, ["meta"] = {["inventory"] = {}, ["fields"] = {}}, ["param2"] = 0, ["param1"] = 0}, {["y"] = 10, ["x"] = 10, ["name"] = "default:cobble", ["z"] = 13, ["meta"] = {["inventory"] = {}, ["fields"] = {}}, ["param2"] = 0, ["param1"] = 0}, {["y"] = 10, ["x"] = 10, ["name"] = "default:cobble", ["z"] = 14, ["meta"] = {["inventory"] = {}, ["fields"] = {}}, ["param2"] = 0, ["param1"] = 0}, {["y"] = 11, ["x"] = 10, ["name"] = "default:cobble", ["z"] = 13, ["meta"] = {["inventory"] = {}, ["fields"] = {}}, ["param2"] = 0, ["param1"] = 0}, {["y"] = 12, ["x"] = 10, ["name"] = "default:cobble", ["z"] = 13, ["meta"] = {["inventory"] = {}, ["fields"] = {}}, ["param2"] = 0, ["param1"] = 0}, {["y"] = 13, ["x"] = 10, ["name"] = "default:wood", ["z"] = 7, ["meta"] = {["inventory"] = {}, ["fields"] = {}}, ["param2"] = 0, ["param1"] = 0}, {["y"] = 13, ["x"] = 10, ["name"] = "default:cobble", ["z"] = 13, ["meta"] = {["inventory"] = {}, ["fields"] = {}}, ["param2"] = 0, ["param1"] = 0}, {["y"] = 0, ["x"] = 11, ["name"] = "default:cobble", ["z"] = 1, ["meta"] = {["inventory"] = {}, ["fields"] = {}}, ["param2"] = 0, ["param1"] = 0}, {["y"] = 0, ["x"] = 11, ["name"] = "default:cobble", ["z"] = 13, ["meta"] = {["inventory"] = {}, ["fields"] = {}}, ["param2"] = 0, ["param1"] = 0}, {["y"] = 0, ["x"] = 11, ["name"] = "default:cobble", ["z"] = 14, ["meta"] = {["inventory"] = {}, ["fields"] = {}}, ["param2"] = 0, ["param1"] = 0}, {["y"] = 0, ["x"] = 11, ["name"] = "default:water_flowing", ["z"] = 15, ["meta"] = {["inventory"] = {}, ["fields"] = {}}, ["param2"] = 5, ["param1"] = 15}, {["y"] = 0, ["x"] = 11, ["name"] = "default:cobble", ["z"] = 16, ["meta"] = {["inventory"] = {}, ["fields"] = {}}, ["param2"] = 0, ["param1"] = 0}, {["y"] = 1, ["x"] = 11, ["name"] = "default:cobble", ["z"] = 1, ["meta"] = {["inventory"] = {}, ["fields"] = {}}, ["param2"] = 0, ["param1"] = 0}, {["y"] = 1, ["x"] = 11, ["name"] = "default:cobble", ["z"] = 13, ["meta"] = {["inventory"] = {}, ["fields"] = {}}, ["param2"] = 0, ["param1"] = 0}, {["y"] = 2, ["x"] = 11, ["name"] = "default:cobble", ["z"] = 1, ["meta"] = {["inventory"] = {}, ["fields"] = {}}, ["param2"] = 0, ["param1"] = 0}, {["y"] = 2, ["x"] = 11, ["name"] = "default:cobble", ["z"] = 13, ["meta"] = {["inventory"] = {}, ["fields"] = {}}, ["param2"] = 0, ["param1"] = 0}, {["y"] = 3, ["x"] = 11, ["name"] = "default:cobble", ["z"] = 1, ["meta"] = {["inventory"] = {}, ["fields"] = {}}, ["param2"] = 0, ["param1"] = 0}, {["y"] = 3, ["x"] = 11, ["name"] = "default:cobble", ["z"] = 13, ["meta"] = {["inventory"] = {}, ["fields"] = {}}, ["param2"] = 0, ["param1"] = 0}, {["y"] = 4, ["x"] = 11, ["name"] = "default:cobble", ["z"] = 1, ["meta"] = {["inventory"] = {}, ["fields"] = {}}, ["param2"] = 0, ["param1"] = 0}, {["y"] = 4, ["x"] = 11, ["name"] = "default:cobble", ["z"] = 13, ["meta"] = {["inventory"] = {}, ["fields"] = {}}, ["param2"] = 0, ["param1"] = 0}, {["y"] = 5, ["x"] = 11, ["name"] = "default:cobble", ["z"] = 1, ["meta"] = {["inventory"] = {}, ["fields"] = {}}, ["param2"] = 0, ["param1"] = 0}, {["y"] = 5, ["x"] = 11, ["name"] = "default:cobble", ["z"] = 13, ["meta"] = {["inventory"] = {}, ["fields"] = {}}, ["param2"] = 0, ["param1"] = 0}, {["y"] = 6, ["x"] = 11, ["name"] = "default:cobble", ["z"] = 1, ["meta"] = {["inventory"] = {}, ["fields"] = {}}, ["param2"] = 0, ["param1"] = 0}, {["y"] = 6, ["x"] = 11, ["name"] = "default:cobble", ["z"] = 13, ["meta"] = {["inventory"] = {}, ["fields"] = {}}, ["param2"] = 0, ["param1"] = 0}, {["y"] = 7, ["x"] = 11, ["name"] = "default:cobble", ["z"] = 1, ["meta"] = {["inventory"] = {}, ["fields"] = {}}, ["param2"] = 0, ["param1"] = 0}, {["y"] = 7, ["x"] = 11, ["name"] = "default:cobble", ["z"] = 13, ["meta"] = {["inventory"] = {}, ["fields"] = {}}, ["param2"] = 0, ["param1"] = 0}, {["y"] = 8, ["x"] = 11, ["name"] = "default:cobble", ["z"] = 1, ["meta"] = {["inventory"] = {}, ["fields"] = {}}, ["param2"] = 0, ["param1"] = 0}, {["y"] = 8, ["x"] = 11, ["name"] = "default:wood", ["z"] = 7, ["meta"] = {["inventory"] = {}, ["fields"] = {}}, ["param2"] = 0, ["param1"] = 0}, {["y"] = 8, ["x"] = 11, ["name"] = "default:cobble", ["z"] = 13, ["meta"] = {["inventory"] = {}, ["fields"] = {}}, ["param2"] = 0, ["param1"] = 0}, {["y"] = 9, ["x"] = 11, ["name"] = "default:cobble", ["z"] = 13, ["meta"] = {["inventory"] = {}, ["fields"] = {}}, ["param2"] = 0, ["param1"] = 0}, {["y"] = 10, ["x"] = 11, ["name"] = "default:wood", ["z"] = 5, ["meta"] = {["inventory"] = {}, ["fields"] = {}}, ["param2"] = 0, ["param1"] = 0}, {["y"] = 10, ["x"] = 11, ["name"] = "default:wood", ["z"] = 9, ["meta"] = {["inventory"] = {}, ["fields"] = {}}, ["param2"] = 0, ["param1"] = 0}, {["y"] = 10, ["x"] = 11, ["name"] = "default:cobble", ["z"] = 13, ["meta"] = {["inventory"] = {}, ["fields"] = {}}, ["param2"] = 0, ["param1"] = 0}, {["y"] = 11, ["x"] = 11, ["name"] = "default:cobble", ["z"] = 13, ["meta"] = {["inventory"] = {}, ["fields"] = {}}, ["param2"] = 0, ["param1"] = 0}, {["y"] = 12, ["x"] = 11, ["name"] = "default:wood", ["z"] = 7, ["meta"] = {["inventory"] = {}, ["fields"] = {}}, ["param2"] = 0, ["param1"] = 0}, {["y"] = 12, ["x"] = 11, ["name"] = "default:cobble", ["z"] = 13, ["meta"] = {["inventory"] = {}, ["fields"] = {}}, ["param2"] = 0, ["param1"] = 0}, {["y"] = 0, ["x"] = 12, ["name"] = "default:cobble", ["z"] = 2, ["meta"] = {["inventory"] = {}, ["fields"] = {}}, ["param2"] = 0, ["param1"] = 0}, {["y"] = 0, ["x"] = 12, ["name"] = "default:tree", ["z"] = 3, ["meta"] = {["inventory"] = {}, ["fields"] = {}}, ["param2"] = 9, ["param1"] = 0}, {["y"] = 0, ["x"] = 12, ["name"] = "default:tree", ["z"] = 4, ["meta"] = {["inventory"] = {}, ["fields"] = {}}, ["param2"] = 9, ["param1"] = 0}, {["y"] = 0, ["x"] = 12, ["name"] = "default:tree", ["z"] = 5, ["meta"] = {["inventory"] = {}, ["fields"] = {}}, ["param2"] = 9, ["param1"] = 0}, {["y"] = 0, ["x"] = 12, ["name"] = "default:tree", ["z"] = 6, ["meta"] = {["inventory"] = {}, ["fields"] = {}}, ["param2"] = 9, ["param1"] = 0}, {["y"] = 0, ["x"] = 12, ["name"] = "default:tree", ["z"] = 7, ["meta"] = {["inventory"] = {}, ["fields"] = {}}, ["param2"] = 9, ["param1"] = 0}, {["y"] = 0, ["x"] = 12, ["name"] = "default:tree", ["z"] = 8, ["meta"] = {["inventory"] = {}, ["fields"] = {}}, ["param2"] = 9, ["param1"] = 0}, {["y"] = 0, ["x"] = 12, ["name"] = "default:tree", ["z"] = 9, ["meta"] = {["inventory"] = {}, ["fields"] = {}}, ["param2"] = 9, ["param1"] = 0}, {["y"] = 0, ["x"] = 12, ["name"] = "default:tree", ["z"] = 10, ["meta"] = {["inventory"] = {}, ["fields"] = {}}, ["param2"] = 9, ["param1"] = 0}, {["y"] = 0, ["x"] = 12, ["name"] = "default:tree", ["z"] = 11, ["meta"] = {["inventory"] = {}, ["fields"] = {}}, ["param2"] = 9, ["param1"] = 0}, {["y"] = 0, ["x"] = 12, ["name"] = "default:cobble", ["z"] = 12, ["meta"] = {["inventory"] = {}, ["fields"] = {}}, ["param2"] = 0, ["param1"] = 0}, {["y"] = 0, ["x"] = 12, ["name"] = "default:wood", ["z"] = 13, ["meta"] = {["inventory"] = {}, ["fields"] = {}}, ["param2"] = 0, ["param1"] = 0}, {["y"] = 0, ["x"] = 12, ["name"] = "default:tree", ["z"] = 14, ["meta"] = {["inventory"] = {}, ["fields"] = {}}, ["param2"] = 3, ["param1"] = 0}, {["y"] = 0, ["x"] = 12, ["name"] = "default:water_flowing", ["z"] = 15, ["meta"] = {["inventory"] = {}, ["fields"] = {}}, ["param2"] = 6, ["param1"] = 13}, {["y"] = 0, ["x"] = 12, ["name"] = "default:tree", ["z"] = 16, ["meta"] = {["inventory"] = {}, ["fields"] = {}}, ["param2"] = 2, ["param1"] = 0}, {["y"] = 0, ["x"] = 12, ["name"] = "default:cobble", ["z"] = 17, ["meta"] = {["inventory"] = {}, ["fields"] = {}}, ["param2"] = 0, ["param1"] = 0}, {["y"] = 0, ["x"] = 12, ["name"] = "default:wood", ["z"] = 18, ["meta"] = {["inventory"] = {}, ["fields"] = {}}, ["param2"] = 0, ["param1"] = 0}, {["y"] = 1, ["x"] = 12, ["name"] = "default:cobble", ["z"] = 2, ["meta"] = {["inventory"] = {}, ["fields"] = {}}, ["param2"] = 0, ["param1"] = 0}, {["y"] = 1, ["x"] = 12, ["name"] = "default:glass", ["z"] = 3, ["meta"] = {["inventory"] = {}, ["fields"] = {}}, ["param2"] = 0, ["param1"] = 13}, {["y"] = 1, ["x"] = 12, ["name"] = "default:glass", ["z"] = 4, ["meta"] = {["inventory"] = {}, ["fields"] = {}}, ["param2"] = 0, ["param1"] = 13}, {["y"] = 1, ["x"] = 12, ["name"] = "default:glass", ["z"] = 5, ["meta"] = {["inventory"] = {}, ["fields"] = {}}, ["param2"] = 0, ["param1"] = 13}, {["y"] = 1, ["x"] = 12, ["name"] = "default:glass", ["z"] = 6, ["meta"] = {["inventory"] = {}, ["fields"] = {}}, ["param2"] = 0, ["param1"] = 13}, {["y"] = 1, ["x"] = 12, ["name"] = "default:glass", ["z"] = 7, ["meta"] = {["inventory"] = {}, ["fields"] = {}}, ["param2"] = 0, ["param1"] = 13}, {["y"] = 1, ["x"] = 12, ["name"] = "default:glass", ["z"] = 8, ["meta"] = {["inventory"] = {}, ["fields"] = {}}, ["param2"] = 0, ["param1"] = 13}, {["y"] = 1, ["x"] = 12, ["name"] = "default:glass", ["z"] = 9, ["meta"] = {["inventory"] = {}, ["fields"] = {}}, ["param2"] = 0, ["param1"] = 13}, {["y"] = 1, ["x"] = 12, ["name"] = "default:glass", ["z"] = 10, ["meta"] = {["inventory"] = {}, ["fields"] = {}}, ["param2"] = 0, ["param1"] = 13}, {["y"] = 1, ["x"] = 12, ["name"] = "default:glass", ["z"] = 11, ["meta"] = {["inventory"] = {}, ["fields"] = {}}, ["param2"] = 0, ["param1"] = 13}, {["y"] = 1, ["x"] = 12, ["name"] = "default:cobble", ["z"] = 12, ["meta"] = {["inventory"] = {}, ["fields"] = {}}, ["param2"] = 0, ["param1"] = 0}, {["y"] = 1, ["x"] = 12, ["name"] = "default:tree", ["z"] = 15, ["meta"] = {["inventory"] = {}, ["fields"] = {}}, ["param2"] = 3, ["param1"] = 0}, {["y"] = 2, ["x"] = 12, ["name"] = "default:cobble", ["z"] = 2, ["meta"] = {["inventory"] = {}, ["fields"] = {}}, ["param2"] = 0, ["param1"] = 0}, {["y"] = 2, ["x"] = 12, ["name"] = "default:tree", ["z"] = 3, ["meta"] = {["inventory"] = {}, ["fields"] = {}}, ["param2"] = 9, ["param1"] = 0}, {["y"] = 2, ["x"] = 12, ["name"] = "default:tree", ["z"] = 4, ["meta"] = {["inventory"] = {}, ["fields"] = {}}, ["param2"] = 9, ["param1"] = 0}, {["y"] = 2, ["x"] = 12, ["name"] = "default:tree", ["z"] = 5, ["meta"] = {["inventory"] = {}, ["fields"] = {}}, ["param2"] = 9, ["param1"] = 0}, {["y"] = 2, ["x"] = 12, ["name"] = "default:tree", ["z"] = 6, ["meta"] = {["inventory"] = {}, ["fields"] = {}}, ["param2"] = 9, ["param1"] = 0}, {["y"] = 2, ["x"] = 12, ["name"] = "default:tree", ["z"] = 7, ["meta"] = {["inventory"] = {}, ["fields"] = {}}, ["param2"] = 9, ["param1"] = 0}, {["y"] = 2, ["x"] = 12, ["name"] = "default:tree", ["z"] = 8, ["meta"] = {["inventory"] = {}, ["fields"] = {}}, ["param2"] = 9, ["param1"] = 0}, {["y"] = 2, ["x"] = 12, ["name"] = "default:tree", ["z"] = 9, ["meta"] = {["inventory"] = {}, ["fields"] = {}}, ["param2"] = 9, ["param1"] = 0}, {["y"] = 2, ["x"] = 12, ["name"] = "default:tree", ["z"] = 10, ["meta"] = {["inventory"] = {}, ["fields"] = {}}, ["param2"] = 9, ["param1"] = 0}, {["y"] = 2, ["x"] = 12, ["name"] = "default:tree", ["z"] = 11, ["meta"] = {["inventory"] = {}, ["fields"] = {}}, ["param2"] = 9, ["param1"] = 0}, {["y"] = 2, ["x"] = 12, ["name"] = "default:cobble", ["z"] = 12, ["meta"] = {["inventory"] = {}, ["fields"] = {}}, ["param2"] = 0, ["param1"] = 0}, {["y"] = 2, ["x"] = 12, ["name"] = "default:tree", ["z"] = 14, ["meta"] = {["inventory"] = {}, ["fields"] = {}}, ["param2"] = 2, ["param1"] = 0}, {["y"] = 2, ["x"] = 12, ["name"] = "default:tree", ["z"] = 16, ["meta"] = {["inventory"] = {}, ["fields"] = {}}, ["param2"] = 2, ["param1"] = 0}, {["y"] = 3, ["x"] = 12, ["name"] = "default:cobble", ["z"] = 2, ["meta"] = {["inventory"] = {}, ["fields"] = {}}, ["param2"] = 0, ["param1"] = 0}, {["y"] = 3, ["x"] = 12, ["name"] = "default:cobble", ["z"] = 12, ["meta"] = {["inventory"] = {}, ["fields"] = {}}, ["param2"] = 0, ["param1"] = 0}, {["y"] = 3, ["x"] = 12, ["name"] = "default:tree", ["z"] = 15, ["meta"] = {["inventory"] = {}, ["fields"] = {}}, ["param2"] = 3, ["param1"] = 0}, {["y"] = 4, ["x"] = 12, ["name"] = "default:cobble", ["z"] = 2, ["meta"] = {["inventory"] = {}, ["fields"] = {}}, ["param2"] = 0, ["param1"] = 0}, {["y"] = 4, ["x"] = 12, ["name"] = "default:cobble", ["z"] = 12, ["meta"] = {["inventory"] = {}, ["fields"] = {}}, ["param2"] = 0, ["param1"] = 0}, {["y"] = 4, ["x"] = 12, ["name"] = "default:tree", ["z"] = 14, ["meta"] = {["inventory"] = {}, ["fields"] = {}}, ["param2"] = 2, ["param1"] = 0}, {["y"] = 4, ["x"] = 12, ["name"] = "default:tree", ["z"] = 16, ["meta"] = {["inventory"] = {}, ["fields"] = {}}, ["param2"] = 2, ["param1"] = 0}, {["y"] = 5, ["x"] = 12, ["name"] = "default:cobble", ["z"] = 2, ["meta"] = {["inventory"] = {}, ["fields"] = {}}, ["param2"] = 0, ["param1"] = 0}, {["y"] = 5, ["x"] = 12, ["name"] = "default:cobble", ["z"] = 12, ["meta"] = {["inventory"] = {}, ["fields"] = {}}, ["param2"] = 0, ["param1"] = 0}, {["y"] = 5, ["x"] = 12, ["name"] = "default:tree", ["z"] = 15, ["meta"] = {["inventory"] = {}, ["fields"] = {}}, ["param2"] = 3, ["param1"] = 0}, {["y"] = 6, ["x"] = 12, ["name"] = "default:cobble", ["z"] = 2, ["meta"] = {["inventory"] = {}, ["fields"] = {}}, ["param2"] = 0, ["param1"] = 0}, {["y"] = 6, ["x"] = 12, ["name"] = "default:cobble", ["z"] = 12, ["meta"] = {["inventory"] = {}, ["fields"] = {}}, ["param2"] = 0, ["param1"] = 0}, {["y"] = 6, ["x"] = 12, ["name"] = "default:tree", ["z"] = 14, ["meta"] = {["inventory"] = {}, ["fields"] = {}}, ["param2"] = 2, ["param1"] = 0}, {["y"] = 6, ["x"] = 12, ["name"] = "default:tree", ["z"] = 16, ["meta"] = {["inventory"] = {}, ["fields"] = {}}, ["param2"] = 2, ["param1"] = 0}, {["y"] = 7, ["x"] = 12, ["name"] = "default:cobble", ["z"] = 2, ["meta"] = {["inventory"] = {}, ["fields"] = {}}, ["param2"] = 0, ["param1"] = 0}, {["y"] = 7, ["x"] = 12, ["name"] = "default:cobble", ["z"] = 12, ["meta"] = {["inventory"] = {}, ["fields"] = {}}, ["param2"] = 0, ["param1"] = 0}, {["y"] = 7, ["x"] = 12, ["name"] = "default:tree", ["z"] = 15, ["meta"] = {["inventory"] = {}, ["fields"] = {}}, ["param2"] = 3, ["param1"] = 0}, {["y"] = 8, ["x"] = 12, ["name"] = "default:cobble", ["z"] = 2, ["meta"] = {["inventory"] = {}, ["fields"] = {}}, ["param2"] = 0, ["param1"] = 0}, {["y"] = 8, ["x"] = 12, ["name"] = "default:cobble", ["z"] = 12, ["meta"] = {["inventory"] = {}, ["fields"] = {}}, ["param2"] = 0, ["param1"] = 0}, {["y"] = 8, ["x"] = 12, ["name"] = "default:glass", ["z"] = 15, ["meta"] = {["inventory"] = {}, ["fields"] = {}}, ["param2"] = 0, ["param1"] = 12}, {["y"] = 9, ["x"] = 12, ["name"] = "default:cobble", ["z"] = 2, ["meta"] = {["inventory"] = {}, ["fields"] = {}}, ["param2"] = 0, ["param1"] = 0}, {["y"] = 9, ["x"] = 12, ["name"] = "default:wood", ["z"] = 7, ["meta"] = {["inventory"] = {}, ["fields"] = {}}, ["param2"] = 0, ["param1"] = 0}, {["y"] = 9, ["x"] = 12, ["name"] = "default:cobble", ["z"] = 12, ["meta"] = {["inventory"] = {}, ["fields"] = {}}, ["param2"] = 0, ["param1"] = 0}, {["y"] = 9, ["x"] = 12, ["name"] = "default:glass", ["z"] = 15, ["meta"] = {["inventory"] = {}, ["fields"] = {}}, ["param2"] = 0, ["param1"] = 13}, {["y"] = 10, ["x"] = 12, ["name"] = "default:wood", ["z"] = 6, ["meta"] = {["inventory"] = {}, ["fields"] = {}}, ["param2"] = 0, ["param1"] = 0}, {["y"] = 10, ["x"] = 12, ["name"] = "default:wood", ["z"] = 7, ["meta"] = {["inventory"] = {}, ["fields"] = {}}, ["param2"] = 0, ["param1"] = 0}, {["y"] = 10, ["x"] = 12, ["name"] = "default:wood", ["z"] = 8, ["meta"] = {["inventory"] = {}, ["fields"] = {}}, ["param2"] = 0, ["param1"] = 0}, {["y"] = 10, ["x"] = 12, ["name"] = "default:cobble", ["z"] = 12, ["meta"] = {["inventory"] = {}, ["fields"] = {}}, ["param2"] = 0, ["param1"] = 0}, {["y"] = 10, ["x"] = 12, ["name"] = "default:glass", ["z"] = 15, ["meta"] = {["inventory"] = {}, ["fields"] = {}}, ["param2"] = 0, ["param1"] = 15}, {["y"] = 11, ["x"] = 12, ["name"] = "default:wood", ["z"] = 7, ["meta"] = {["inventory"] = {}, ["fields"] = {}}, ["param2"] = 0, ["param1"] = 0}, {["y"] = 11, ["x"] = 12, ["name"] = "default:cobble", ["z"] = 12, ["meta"] = {["inventory"] = {}, ["fields"] = {}}, ["param2"] = 0, ["param1"] = 0}, {["y"] = 11, ["x"] = 12, ["name"] = "default:glass", ["z"] = 14, ["meta"] = {["inventory"] = {}, ["fields"] = {}}, ["param2"] = 0, ["param1"] = 15}, {["y"] = 11, ["x"] = 12, ["name"] = "default:glass", ["z"] = 15, ["meta"] = {["inventory"] = {}, ["fields"] = {}}, ["param2"] = 0, ["param1"] = 15}, {["y"] = 12, ["x"] = 12, ["name"] = "default:glass", ["z"] = 10, ["meta"] = {["inventory"] = {}, ["fields"] = {}}, ["param2"] = 0, ["param1"] = 15}, {["y"] = 12, ["x"] = 12, ["name"] = "default:glass", ["z"] = 11, ["meta"] = {["inventory"] = {}, ["fields"] = {}}, ["param2"] = 0, ["param1"] = 15}, {["y"] = 12, ["x"] = 12, ["name"] = "default:cobble", ["z"] = 12, ["meta"] = {["inventory"] = {}, ["fields"] = {}}, ["param2"] = 0, ["param1"] = 0}, {["y"] = 12, ["x"] = 12, ["name"] = "default:glass", ["z"] = 13, ["meta"] = {["inventory"] = {}, ["fields"] = {}}, ["param2"] = 0, ["param1"] = 15}, {["y"] = 12, ["x"] = 12, ["name"] = "default:glass", ["z"] = 14, ["meta"] = {["inventory"] = {}, ["fields"] = {}}, ["param2"] = 0, ["param1"] = 15}, {["y"] = 0, ["x"] = 13, ["name"] = "default:cobble", ["z"] = 3, ["meta"] = {["inventory"] = {}, ["fields"] = {}}, ["param2"] = 0, ["param1"] = 0}, {["y"] = 0, ["x"] = 13, ["name"] = "default:cobble", ["z"] = 4, ["meta"] = {["inventory"] = {}, ["fields"] = {}}, ["param2"] = 0, ["param1"] = 0}, {["y"] = 0, ["x"] = 13, ["name"] = "default:water_source", ["z"] = 5, ["meta"] = {["inventory"] = {}, ["fields"] = {}}, ["param2"] = 0, ["param1"] = 13}, {["y"] = 0, ["x"] = 13, ["name"] = "default:water_source", ["z"] = 6, ["meta"] = {["inventory"] = {}, ["fields"] = {}}, ["param2"] = 0, ["param1"] = 13}, {["y"] = 0, ["x"] = 13, ["name"] = "default:water_source", ["z"] = 7, ["meta"] = {["inventory"] = {}, ["fields"] = {}}, ["param2"] = 0, ["param1"] = 13}, {["y"] = 0, ["x"] = 13, ["name"] = "default:water_source", ["z"] = 8, ["meta"] = {["inventory"] = {}, ["fields"] = {}}, ["param2"] = 0, ["param1"] = 13}, {["y"] = 0, ["x"] = 13, ["name"] = "default:water_flowing", ["z"] = 9, ["meta"] = {["inventory"] = {}, ["fields"] = {}}, ["param2"] = 7, ["param1"] = 15}, {["y"] = 0, ["x"] = 13, ["name"] = "default:cobble", ["z"] = 10, ["meta"] = {["inventory"] = {}, ["fields"] = {}}, ["param2"] = 0, ["param1"] = 0}, {["y"] = 0, ["x"] = 13, ["name"] = "default:cobble", ["z"] = 11, ["meta"] = {["inventory"] = {}, ["fields"] = {}}, ["param2"] = 0, ["param1"] = 0}, {["y"] = 0, ["x"] = 13, ["name"] = "default:water_flowing", ["z"] = 12, ["meta"] = {["inventory"] = {}, ["fields"] = {}}, ["param2"] = 4, ["param1"] = 13}, {["y"] = 0, ["x"] = 13, ["name"] = "default:water_flowing", ["z"] = 13, ["meta"] = {["inventory"] = {}, ["fields"] = {}}, ["param2"] = 5, ["param1"] = 15}, {["y"] = 0, ["x"] = 13, ["name"] = "default:water_flowing", ["z"] = 14, ["meta"] = {["inventory"] = {}, ["fields"] = {}}, ["param2"] = 6, ["param1"] = 13}, {["y"] = 0, ["x"] = 13, ["name"] = "default:water_flowing", ["z"] = 15, ["meta"] = {["inventory"] = {}, ["fields"] = {}}, ["param2"] = 7, ["param1"] = 15}, {["y"] = 0, ["x"] = 13, ["name"] = "default:water_flowing", ["z"] = 16, ["meta"] = {["inventory"] = {}, ["fields"] = {}}, ["param2"] = 6, ["param1"] = 13},