5:return {{["y"] = 3, ["x"] = 6, ["name"] = "default:glass", ["z"] = 9, ["meta"] = {["inventory"] = {}, ["fields"] = {}}, ["param1"] = 157}, {["y"] = 3, ["x"] = 6, ["name"] = "default:glass", ["z"] = 10, ["meta"] = {["inventory"] = {}, ["fields"] = {}}, ["param1"] = 173}, {["y"] = 3, ["x"] = 6, ["name"] = "default:glass", ["z"] = 11, ["meta"] = {["inventory"] = {}, ["fields"] = {}}, ["param1"] = 157}, {["y"] = 3, ["x"] = 6, ["name"] = "default:glass", ["z"] = 12, ["meta"] = {["inventory"] = {}, ["fields"] = {}}, ["param1"] = 141}, {["y"] = 3, ["x"] = 6, ["name"] = "default:glass", ["z"] = 13, ["meta"] = {["inventory"] = {}, ["fields"] = {}}, ["param1"] = 125}, {["y"] = 3, ["x"] = 6, ["name"] = "default:glass", ["z"] = 14, ["meta"] = {["inventory"] = {}, ["fields"] = {}}, ["param1"] = 109}, {["y"] = 3, ["x"] = 6, ["name"] = "default:glass", ["z"] = 15, ["meta"] = {["inventory"] = {}, ["fields"] = {}}, ["param1"] = 125}, {["y"] = 3, ["x"] = 6, ["name"] = "default:glass", ["z"] = 16, ["meta"] = {["inventory"] = {}, ["fields"] = {}}, ["param1"] = 141}, {["y"] = 3, ["x"] = 6, ["name"] = "default:glass", ["z"] = 17, ["meta"] = {["inventory"] = {}, ["fields"] = {}}, ["param1"] = 157}, {["y"] = 3, ["x"] = 6, ["name"] = "default:glass", ["z"] = 18, ["meta"] = {["inventory"] = {}, ["fields"] = {}}, ["param1"] = 141}, {["y"] = 3, ["x"] = 6, ["name"] = "default:glass", ["z"] = 19, ["meta"] = {["inventory"] = {}, ["fields"] = {}}, ["param1"] = 141}, {["y"] = 3, ["x"] = 6, ["name"] = "default:glass", ["z"] = 20, ["meta"] = {["inventory"] = {}, ["fields"] = {}}, ["param1"] = 157}, {["y"] = 3, ["x"] = 6, ["name"] = "default:glass", ["z"] = 21, ["meta"] = {["inventory"] = {}, ["fields"] = {}}, ["param1"] = 141}, {["y"] = 3, ["x"] = 6, ["name"] = "default:glass", ["z"] = 22, ["meta"] = {["inventory"] = {}, ["fields"] = {}}, ["param1"] = 125}, {["y"] = 3, ["x"] = 6, ["name"] = "default:glass", ["z"] = 23, ["meta"] = {["inventory"] = {}, ["fields"] = {}}, ["param1"] = 109}, {["y"] = 3, ["x"] = 6, ["name"] = "default:glass", ["z"] = 24, ["meta"] = {["inventory"] = {}, ["fields"] = {}}, ["param1"] = 109}, {["y"] = 3, ["x"] = 6, ["name"] = "default:glass", ["z"] = 25, ["meta"] = {["inventory"] = {}, ["fields"] = {}}, ["param1"] = 125}, {["y"] = 3, ["x"] = 6, ["name"] = "default:glass", ["z"] = 26, ["meta"] = {["inventory"] = {}, ["fields"] = {}}, ["param1"] = 141}, {["y"] = 3, ["x"] = 6, ["name"] = "default:glass", ["z"] = 27, ["meta"] = {["inventory"] = {}, ["fields"] = {}}, ["param1"] = 157}, {["y"] = 3, ["x"] = 6, ["name"] = "default:glass", ["z"] = 28, ["meta"] = {["inventory"] = {}, ["fields"] = {}}, ["param1"] = 173}, {["y"] = 3, ["x"] = 6, ["name"] = "default:glass", ["z"] = 29, ["meta"] = {["inventory"] = {}, ["fields"] = {}}, ["param1"] = 189}, {["y"] = 3, ["x"] = 6, ["name"] = "default:glass", ["z"] = 30, ["meta"] = {["inventory"] = {}, ["fields"] = {}}, ["param1"] = 205}, {["y"] = 3, ["x"] = 6, ["name"] = "default:glass", ["z"] = 31, ["meta"] = {["inventory"] = {}, ["fields"] = {}}, ["param1"] = 221}, {["y"] = 3, ["x"] = 6, ["name"] = "moreblocks:super_glow_glass", ["z"] = 32, ["meta"] = {["inventory"] = {}, ["fields"] = {}}}, {["y"] = 3, ["x"] = 6, ["name"] = "default:glass", ["z"] = 33, ["meta"] = {["inventory"] = {}, ["fields"] = {}}, ["param1"] = 221}, {["y"] = 3, ["x"] = 6, ["name"] = "default:glass", ["z"] = 34, ["meta"] = {["inventory"] = {}, ["fields"] = {}}, ["param1"] = 205}, {["y"] = 3, ["x"] = 6, ["name"] = "default:glass", ["z"] = 35, ["meta"] = {["inventory"] = {}, ["fields"] = {}}, ["param1"] = 189}, {["y"] = 3, ["x"] = 6, ["name"] = "default:glass", ["z"] = 36, ["meta"] = {["inventory"] = {}, ["fields"] = {}}, ["param1"] = 173}, {["y"] = 3, ["x"] = 6, ["name"] = "default:glass", ["z"] = 37, ["meta"] = {["inventory"] = {}, ["fields"] = {}}, ["param1"] = 157}, {["y"] = 3, ["x"] = 6, ["name"] = "default:glass", ["z"] = 38, ["meta"] = {["inventory"] = {}, ["fields"] = {}}, ["param1"] = 141}, {["y"] = 3, ["x"] = 6, ["name"] = "default:glass", ["z"] = 39, ["meta"] = {["inventory"] = {}, ["fields"] = {}}, ["param1"] = 125}, {["y"] = 3, ["x"] = 6, ["name"] = "default:glass", ["z"] = 40, ["meta"] = {["inventory"] = {}, ["fields"] = {}}, ["param1"] = 109}, {["y"] = 3, ["x"] = 6, ["name"] = "default:glass", ["z"] = 41, ["meta"] = {["inventory"] = {}, ["fields"] = {}}, ["param1"] = 93}, {["y"] = 3, ["x"] = 6, ["name"] = "default:glass", ["z"] = 42, ["meta"] = {["inventory"] = {}, ["fields"] = {}}, ["param1"] = 93}, {["y"] = 3, ["x"] = 6, ["name"] = "default:glass", ["z"] = 43, ["meta"] = {["inventory"] = {}, ["fields"] = {}}, ["param1"] = 109}, {["y"] = 3, ["x"] = 6, ["name"] = "default:glass", ["z"] = 44, ["meta"] = {["inventory"] = {}, ["fields"] = {}}, ["param1"] = 125}, {["y"] = 3, ["x"] = 6, ["name"] = "default:glass", ["z"] = 45, ["meta"] = {["inventory"] = {}, ["fields"] = {}}, ["param1"] = 109}, {["y"] = 3, ["x"] = 6, ["name"] = "default:glass", ["z"] = 46, ["meta"] = {["inventory"] = {}, ["fields"] = {}}, ["param1"] = 93}, {["y"] = 3, ["x"] = 6, ["name"] = "default:glass", ["z"] = 47, ["meta"] = {["inventory"] = {}, ["fields"] = {}}, ["param1"] = 77}, {["y"] = 3, ["x"] = 6, ["name"] = "default:glass", ["z"] = 48, ["meta"] = {["inventory"] = {}, ["fields"] = {}}, ["param1"] = 77}, {["y"] = 3, ["x"] = 6, ["name"] = "default:glass", ["z"] = 49, ["meta"] = {["inventory"] = {}, ["fields"] = {}}, ["param1"] = 93}, {["y"] = 3, ["x"] = 6, ["name"] = "default:glass", ["z"] = 50, ["meta"] = {["inventory"] = {}, ["fields"] = {}}, ["param1"] = 109}, {["y"] = 3, ["x"] = 6, ["name"] = "default:glass", ["z"] = 51, ["meta"] = {["inventory"] = {}, ["fields"] = {}}, ["param1"] = 93}, {["y"] = 3, ["x"] = 6, ["name"] = "default:glass", ["z"] = 52, ["meta"] = {["inventory"] = {}, ["fields"] = {}}, ["param1"] = 93}, {["y"] = 3, ["x"] = 6, ["name"] = "default:glass", ["z"] = 53, ["meta"] = {["inventory"] = {}, ["fields"] = {}}, ["param1"] = 77}, {["y"] = 4, ["x"] = 6, ["name"] = "default:cobble", ["z"] = 9, ["meta"] = {["inventory"] = {}, ["fields"] = {}}}, {["y"] = 4, ["x"] = 6, ["name"] = "default:cobble", ["z"] = 10, ["meta"] = {["inventory"] = {}, ["fields"] = {}}}, {["y"] = 4, ["x"] = 6, ["name"] = "default:cobble", ["z"] = 11, ["meta"] = {["inventory"] = {}, ["fields"] = {}}}, {["y"] = 4, ["x"] = 6, ["name"] = "default:cobble", ["z"] = 12, ["meta"] = {["inventory"] = {}, ["fields"] = {}}}, {["y"] = 4, ["x"] = 6, ["name"] = "default:cobble", ["z"] = 13, ["meta"] = {["inventory"] = {}, ["fields"] = {}}}, {["y"] = 4, ["x"] = 6, ["name"] = "default:cobble", ["z"] = 14, ["meta"] = {["inventory"] = {}, ["fields"] = {}}}, {["y"] = 4, ["x"] = 6, ["name"] = "default:cobble", ["z"] = 15, ["meta"] = {["inventory"] = {}, ["fields"] = {}}}, {["y"] = 4, ["x"] = 6, ["name"] = "default:cobble", ["z"] = 16, ["meta"] = {["inventory"] = {}, ["fields"] = {}}}, {["y"] = 4, ["x"] = 6, ["name"] = "default:cobble", ["z"] = 17, ["meta"] = {["inventory"] = {}, ["fields"] = {}}}, {["y"] = 4, ["x"] = 6, ["name"] = "default:cobble", ["z"] = 18, ["meta"] = {["inventory"] = {}, ["fields"] = {}}}, {["y"] = 4, ["x"] = 6, ["name"] = "default:cobble", ["z"] = 19, ["meta"] = {["inventory"] = {}, ["fields"] = {}}}, {["y"] = 4, ["x"] = 6, ["name"] = "default:cobble", ["z"] = 20, ["meta"] = {["inventory"] = {}, ["fields"] = {}}}, {["y"] = 4, ["x"] = 6, ["name"] = "default:cobble", ["z"] = 21, ["meta"] = {["inventory"] = {}, ["fields"] = {}}}, {["y"] = 4, ["x"] = 6, ["name"] = "default:cobble", ["z"] = 22, ["meta"] = {["inventory"] = {}, ["fields"] = {}}}, {["y"] = 4, ["x"] = 6, ["name"] = "default:cobble", ["z"] = 23, ["meta"] = {["inventory"] = {}, ["fields"] = {}}}, {["y"] = 4, ["x"] = 6, ["name"] = "default:cobble", ["z"] = 24, ["meta"] = {["inventory"] = {}, ["fields"] = {}}}, {["y"] = 4, ["x"] = 6, ["name"] = "default:cobble", ["z"] = 25, ["meta"] = {["inventory"] = {}, ["fields"] = {}}}, {["y"] = 4, ["x"] = 6, ["name"] = "default:cobble", ["z"] = 26, ["meta"] = {["inventory"] = {}, ["fields"] = {}}}, {["y"] = 4, ["x"] = 6, ["name"] = "default:cobble", ["z"] = 27, ["meta"] = {["inventory"] = {}, ["fields"] = {}}}, {["y"] = 4, ["x"] = 6, ["name"] = "default:cobble", ["z"] = 28, ["meta"] = {["inventory"] = {}, ["fields"] = {}}}, {["y"] = 4, ["x"] = 6, ["name"] = "default:cobble", ["z"] = 29, ["meta"] = {["inventory"] = {}, ["fields"] = {}}}, {["y"] = 4, ["x"] = 6, ["name"] = "default:cobble", ["z"] = 30, ["meta"] = {["inventory"] = {}, ["fields"] = {}}}, {["y"] = 4, ["x"] = 6, ["name"] = "default:cobble", ["z"] = 31, ["meta"] = {["inventory"] = {}, ["fields"] = {}}}, {["y"] = 4, ["x"] = 6, ["name"] = "default:cobble", ["z"] = 32, ["meta"] = {["inventory"] = {}, ["fields"] = {}}}, {["y"] = 4, ["x"] = 6, ["name"] = "default:cobble", ["z"] = 33, ["meta"] = {["inventory"] = {}, ["fields"] = {}}}, {["y"] = 4, ["x"] = 6, ["name"] = "default:cobble", ["z"] = 34, ["meta"] = {["inventory"] = {}, ["fields"] = {}}}, {["y"] = 4, ["x"] = 6, ["name"] = "default:cobble", ["z"] = 35, ["meta"] = {["inventory"] = {}, ["fields"] = {}}}, {["y"] = 4, ["x"] = 6, ["name"] = "default:cobble", ["z"] = 36, ["meta"] = {["inventory"] = {}, ["fields"] = {}}}, {["y"] = 4, ["x"] = 6, ["name"] = "default:cobble", ["z"] = 37, ["meta"] = {["inventory"] = {}, ["fields"] = {}}}, {["y"] = 4, ["x"] = 6, ["name"] = "default:cobble", ["z"] = 38, ["meta"] = {["inventory"] = {}, ["fields"] = {}}}, {["y"] = 4, ["x"] = 6, ["name"] = "default:cobble", ["z"] = 39, ["meta"] = {["inventory"] = {}, ["fields"] = {}}}, {["y"] = 4, ["x"] = 6, ["name"] = "default:cobble", ["z"] = 40, ["meta"] = {["inventory"] = {}, ["fields"] = {}}}, {["y"] = 4, ["x"] = 6, ["name"] = "default:cobble", ["z"] = 41, ["meta"] = {["inventory"] = {}, ["fields"] = {}}}, {["y"] = 4, ["x"] = 6, ["name"] = "default:cobble", ["z"] = 42, ["meta"] = {["inventory"] = {}, ["fields"] = {}}}, {["y"] = 4, ["x"] = 6, ["name"] = "default:cobble", ["z"] = 43, ["meta"] = {["inventory"] = {}, ["fields"] = {}}}, {["y"] = 4, ["x"] = 6, ["name"] = "default:cobble", ["z"] = 44, ["meta"] = {["inventory"] = {}, ["fields"] = {}}}, {["y"] = 4, ["x"] = 6, ["name"] = "default:cobble", ["z"] = 45, ["meta"] = {["inventory"] = {}, ["fields"] = {}}}, {["y"] = 4, ["x"] = 6, ["name"] = "default:cobble", ["z"] = 46, ["meta"] = {["inventory"] = {}, ["fields"] = {}}}, {["y"] = 4, ["x"] = 6, ["name"] = "default:cobble", ["z"] = 47, ["meta"] = {["inventory"] = {}, ["fields"] = {}}}, {["y"] = 4, ["x"] = 6, ["name"] = "default:cobble", ["z"] = 48, ["meta"] = {["inventory"] = {}, ["fields"] = {}}}, {["y"] = 4, ["x"] = 6, ["name"] = "default:cobble", ["z"] = 49, ["meta"] = {["inventory"] = {}, ["fields"] = {}}}, {["y"] = 4, ["x"] = 6, ["name"] = "default:cobble", ["z"] = 50, ["meta"] = {["inventory"] = {}, ["fields"] = {}}}, {["y"] = 4, ["x"] = 6, ["name"] = "default:cobble", ["z"] = 51, ["meta"] = {["inventory"] = {}, ["fields"] = {}}}, {["y"] = 4, ["x"] = 6, ["name"] = "default:cobble", ["z"] = 52, ["meta"] = {["inventory"] = {}, ["fields"] = {}}}, {["y"] = 4, ["x"] = 6, ["name"] = "default:cobble", ["z"] = 53, ["meta"] = {["inventory"] = {}, ["fields"] = {}}}, {["y"] = 5, ["x"] = 6, ["name"] = "default:cobble", ["z"] = 9, ["meta"] = {["inventory"] = {}, ["fields"] = {}}}, {["y"] = 5, ["x"] = 6, ["name"] = "default:cobble", ["z"] = 10, ["meta"] = {["inventory"] = {}, ["fields"] = {}}}, {["y"] = 5, ["x"] = 6, ["name"] = "default:cobble", ["z"] = 11, ["meta"] = {["inventory"] = {}, ["fields"] = {}}}, {["y"] = 5, ["x"] = 6, ["name"] = "default:cobble", ["z"] = 12, ["meta"] = {["inventory"] = {}, ["fields"] = {}}}, {["y"] = 5, ["x"] = 6, ["name"] = "default:cobble", ["z"] = 13, ["meta"] = {["inventory"] = {}, ["fields"] = {}}}, {["y"] = 5, ["x"] = 6, ["name"] = "default:cobble", ["z"] = 14, ["meta"] = {["inventory"] = {}, ["fields"] = {}}}, {["y"] = 5, ["x"] = 6, ["name"] = "default:cobble", ["z"] = 15, ["meta"] = {["inventory"] = {}, ["fields"] = {}}}, {["y"] = 5, ["x"] = 6, ["name"] = "default:cobble", ["z"] = 16, ["meta"] = {["inventory"] = {}, ["fields"] = {}}}, {["y"] = 5, ["x"] = 6, ["name"] = "default:cobble", ["z"] = 17, ["meta"] = {["inventory"] = {}, ["fields"] = {}}}, {["y"] = 5, ["x"] = 6, ["name"] = "default:cobble", ["z"] = 18, ["meta"] = {["inventory"] = {}, ["fields"] = {}}}, {["y"] = 5, ["x"] = 6, ["name"] = "default:cobble", ["z"] = 19, ["meta"] = {["inventory"] = {}, ["fields"] = {}}}, {["y"] = 5, ["x"] = 6, ["name"] = "default:cobble", ["z"] = 20, ["meta"] = {["inventory"] = {}, ["fields"] = {}}}, {["y"] = 5, ["x"] = 6, ["name"] = "default:cobble", ["z"] = 21, ["meta"] = {["inventory"] = {}, ["fields"] = {}}}, {["y"] = 5, ["x"] = 6, ["name"] = "default:cobble", ["z"] = 22, ["meta"] = {["inventory"] = {}, ["fields"] = {}}}, {["y"] = 5, ["x"] = 6, ["name"] = "default:cobble", ["z"] = 23, ["meta"] = {["inventory"] = {}, ["fields"] = {}}}, {["y"] = 5, ["x"] = 6, ["name"] = "default:cobble", ["z"] = 24, ["meta"] = {["inventory"] = {}, ["fields"] = {}}}, {["y"] = 5, ["x"] = 6, ["name"] = "default:cobble", ["z"] = 25, ["meta"] = {["inventory"] = {}, ["fields"] = {}}}, {["y"] = 5, ["x"] = 6, ["name"] = "default:cobble", ["z"] = 26, ["meta"] = {["inventory"] = {}, ["fields"] = {}}}, {["y"] = 5, ["x"] = 6, ["name"] = "default:cobble", ["z"] = 27, ["meta"] = {["inventory"] = {}, ["fields"] = {}}}, {["y"] = 5, ["x"] = 6, ["name"] = "default:cobble", ["z"] = 28, ["meta"] = {["inventory"] = {}, ["fields"] = {}}}, {["y"] = 5, ["x"] = 6, ["name"] = "default:cobble", ["z"] = 29, ["meta"] = {["inventory"] = {}, ["fields"] = {}}}, {["y"] = 5, ["x"] = 6, ["name"] = "default:cobble", ["z"] = 30, ["meta"] = {["inventory"] = {}, ["fields"] = {}}}, {["y"] = 5, ["x"] = 6, ["name"] = "default:cobble", ["z"] = 31, ["meta"] = {["inventory"] = {}, ["fields"] = {}}}, {["y"] = 5, ["x"] = 6, ["name"] = "default:cobble", ["z"] = 32, ["meta"] = {["inventory"] = {}, ["fields"] = {}}}, {["y"] = 5, ["x"] = 6, ["name"] = "default:cobble", ["z"] = 33, ["meta"] = {["inventory"] = {}, ["fields"] = {}}}, {["y"] = 5, ["x"] = 6, ["name"] = "default:cobble", ["z"] = 34, ["meta"] = {["inventory"] = {}, ["fields"] = {}}}, {["y"] = 5, ["x"] = 6, ["name"] = "default:cobble", ["z"] = 35, ["meta"] = {["inventory"] = {}, ["fields"] = {}}}, {["y"] = 5, ["x"] = 6, ["name"] = "default:cobble", ["z"] = 36, ["meta"] = {["inventory"] = {}, ["fields"] = {}}}, {["y"] = 5, ["x"] = 6, ["name"] = "default:cobble", ["z"] = 37, ["meta"] = {["inventory"] = {}, ["fields"] = {}}}, {["y"] = 5, ["x"] = 6, ["name"] = "default:cobble", ["z"] = 38, ["meta"] = {["inventory"] = {}, ["fields"] = {}}}, {["y"] = 5, ["x"] = 6, ["name"] = "default:cobble", ["z"] = 39, ["meta"] = {["inventory"] = {}, ["fields"] = {}}}, {["y"] = 5, ["x"] = 6, ["name"] = "default:cobble", ["z"] = 40, ["meta"] = {["inventory"] = {}, ["fields"] = {}}}, {["y"] = 5, ["x"] = 6, ["name"] = "default:cobble", ["z"] = 41, ["meta"] = {["inventory"] = {}, ["fields"] = {}}}, {["y"] = 5, ["x"] = 6, ["name"] = "default:cobble", ["z"] = 42, ["meta"] = {["inventory"] = {}, ["fields"] = {}}}, {["y"] = 5, ["x"] = 6, ["name"] = "default:cobble", ["z"] = 43, ["meta"] = {["inventory"] = {}, ["fields"] = {}}}, {["y"] = 5, ["x"] = 6, ["name"] = "default:cobble", ["z"] = 44, ["meta"] = {["inventory"] = {}, ["fields"] = {}}}, {["y"] = 5, ["x"] = 6, ["name"] = "default:cobble", ["z"] = 45, ["meta"] = {["inventory"] = {}, ["fields"] = {}}}, {["y"] = 5, ["x"] = 6, ["name"] = "default:cobble", ["z"] = 46, ["meta"] = {["inventory"] = {}, ["fields"] = {}}}, {["y"] = 5, ["x"] = 6, ["name"] = "default:cobble", ["z"] = 47, ["meta"] = {["inventory"] = {}, ["fields"] = {}}}, {["y"] = 5, ["x"] = 6, ["name"] = "default:cobble", ["z"] = 48, ["meta"] = {["inventory"] = {}, ["fields"] = {}}}, {["y"] = 5, ["x"] = 6, ["name"] = "default:cobble", ["z"] = 49, ["meta"] = {["inventory"] = {}, ["fields"] = {}}}, {["y"] = 5, ["x"] = 6, ["name"] = "default:cobble", ["z"] = 50, ["meta"] = {["inventory"] = {}, ["fields"] = {}}}, {["y"] = 5, ["x"] = 6, ["name"] = "default:cobble", ["z"] = 51, ["meta"] = {["inventory"] = {}, ["fields"] = {}}}, {["y"] = 5, ["x"] = 6, ["name"] = "default:cobble", ["z"] = 52, ["meta"] = {["inventory"] = {}, ["fields"] = {}}}, {["y"] = 5, ["x"] = 6, ["name"] = "default:cobble", ["z"] = 53, ["meta"] = {["inventory"] = {}, ["fields"] = {}}}, {["y"] = 6, ["x"] = 6, ["name"] = "default:glass", ["z"] = 9, ["meta"] = {["inventory"] = {}, ["fields"] = {}}, ["param1"] = 173}, {["y"] = 6, ["x"] = 6, ["name"] = "default:glass", ["z"] = 10, ["meta"] = {["inventory"] = {}, ["fields"] = {}}, ["param1"] = 189}, {["y"] = 6, ["x"] = 6, ["name"] = "default:glass", ["z"] = 11, ["meta"] = {["inventory"] = {}, ["fields"] = {}}, ["param1"] = 173}, {["y"] = 6, ["x"] = 6, ["name"] = "default:glass", ["z"] = 12, ["meta"] = {["inventory"] = {}, ["fields"] = {}}, ["param1"] = 157}, {["y"] = 6, ["x"] = 6, ["name"] = "default:glass", ["z"] = 13, ["meta"] = {["inventory"] = {}, ["fields"] = {}}, ["param1"] = 141}, {["y"] = 6, ["x"] = 6, ["name"] = "default:glass", ["z"] = 14, ["meta"] = {["inventory"] = {}, ["fields"] = {}}, ["param1"] = 141}, {["y"] = 6, ["x"] = 6, ["name"] = "default:glass", ["z"] = 15, ["meta"] = {["inventory"] = {}, ["fields"] = {}}, ["param1"] = 157}, {["y"] = 6, ["x"] = 6, ["name"] = "default:glass", ["z"] = 16, ["meta"] = {["inventory"] = {}, ["fields"] = {}}, ["param1"] = 157}, {["y"] = 6, ["x"] = 6, ["name"] = "default:glass", ["z"] = 17, ["meta"] = {["inventory"] = {}, ["fields"] = {}}, ["param1"] = 173}, {["y"] = 6, ["x"] = 6, ["name"] = "default:glass", ["z"] = 18, ["meta"] = {["inventory"] = {}, ["fields"] = {}}, ["param1"] = 157}, {["y"] = 6, ["x"] = 6, ["name"] = "default:glass", ["z"] = 19, ["meta"] = {["inventory"] = {}, ["fields"] = {}}, ["param1"] = 157}, {["y"] = 6, ["x"] = 6, ["name"] = "default:glass", ["z"] = 20, ["meta"] = {["inventory"] = {}, ["fields"] = {}}, ["param1"] = 173}, {["y"] = 6, ["x"] = 6, ["name"] = "default:glass", ["z"] = 21, ["meta"] = {["inventory"] = {}, ["fields"] = {}}, ["param1"] = 157}, {["y"] = 6, ["x"] = 6, ["name"] = "default:glass", ["z"] = 22, ["meta"] = {["inventory"] = {}, ["fields"] = {}}, ["param1"] = 141}, {["y"] = 6, ["x"] = 6, ["name"] = "default:glass", ["z"] = 23, ["meta"] = {["inventory"] = {}, ["fields"] = {}}, ["param1"] = 157}, {["y"] = 6, ["x"] = 6, ["name"] = "default:glass", ["z"] = 24, ["meta"] = {["inventory"] = {}, ["fields"] = {}}, ["param1"] = 141}, {["y"] = 6, ["x"] = 6, ["name"] = "default:glass", ["z"] = 25, ["meta"] = {["inventory"] = {}, ["fields"] = {}}, ["param1"] = 125}, {["y"] = 6, ["x"] = 6, ["name"] = "default:glass", ["z"] = 26, ["meta"] = {["inventory"] = {}, ["fields"] = {}}, ["param1"] = 141}, {["y"] = 6, ["x"] = 6, ["name"] = "default:glass", ["z"] = 27, ["meta"] = {["inventory"] = {}, ["fields"] = {}}, ["param1"] = 157}, {["y"] = 6, ["x"] = 6, ["name"] = "default:glass", ["z"] = 28, ["meta"] = {["inventory"] = {}, ["fields"] = {}}, ["param1"] = 173}, {["y"] = 6, ["x"] = 6, ["name"] = "default:glass", ["z"] = 29, ["meta"] = {["inventory"] = {}, ["fields"] = {}}, ["param1"] = 189}, {["y"] = 6, ["x"] = 6, ["name"] = "default:glass", ["z"] = 30, ["meta"] = {["inventory"] = {}, ["fields"] = {}}, ["param1"] = 205}, {["y"] = 6, ["x"] = 6, ["name"] = "default:glass", ["z"] = 31, ["meta"] = {["inventory"] = {}, ["fields"] = {}}, ["param1"] = 221}, {["y"] = 6, ["x"] = 6, ["name"] = "moreblocks:super_glow_glass", ["z"] = 32, ["meta"] = {["inventory"] = {}, ["fields"] = {}}}, {["y"] = 6, ["x"] = 6, ["name"] = "default:glass", ["z"] = 33, ["meta"] = {["inventory"] = {}, ["fields"] = {}}, ["param1"] = 221}, {["y"] = 6, ["x"] = 6, ["name"] = "default:glass", ["z"] = 34, ["meta"] = {["inventory"] = {}, ["fields"] = {}}, ["param1"] = 205}, {["y"] = 6, ["x"] = 6, ["name"] = "default:glass", ["z"] = 35, ["meta"] = {["inventory"] = {}, ["fields"] = {}}, ["param1"] = 189}, {["y"] = 6, ["x"] = 6, ["name"] = "default:glass", ["z"] = 36, ["meta"] = {["inventory"] = {}, ["fields"] = {}}, ["param1"] = 173}, {["y"] = 6, ["x"] = 6, ["name"] = "default:glass", ["z"] = 37, ["meta"] = {["inventory"] = {}, ["fields"] = {}}, ["param1"] = 173}, {["y"] = 6, ["x"] = 6, ["name"] = "default:glass", ["z"] = 38, ["meta"] = {["inventory"] = {}, ["fields"] = {}}, ["param1"] = 157}, {["y"] = 6, ["x"] = 6, ["name"] = "default:glass", ["z"] = 39, ["meta"] = {["inventory"] = {}, ["fields"] = {}}, ["param1"] = 141}, {["y"] = 6, ["x"] = 6, ["name"] = "default:glass", ["z"] = 40, ["meta"] = {["inventory"] = {}, ["fields"] = {}}, ["param1"] = 125}, {["y"] = 6, ["x"] = 6, ["name"] = "default:glass", ["z"] = 41, ["meta"] = {["inventory"] = {}, ["fields"] = {}}, ["param1"] = 109}, {["y"] = 6, ["x"] = 6, ["name"] = "default:glass", ["z"] = 42, ["meta"] = {["inventory"] = {}, ["fields"] = {}}, ["param1"] = 125}, {["y"] = 6, ["x"] = 6, ["name"] = "default:glass", ["z"] = 43, ["meta"] = {["inventory"] = {}, ["fields"] = {}}, ["param1"] = 141}, {["y"] = 6, ["x"] = 6, ["name"] = "default:glass", ["z"] = 44, ["meta"] = {["inventory"] = {}, ["fields"] = {}}, ["param1"] = 157}, {["y"] = 6, ["x"] = 6, ["name"] = "default:glass", ["z"] = 45, ["meta"] = {["inventory"] = {}, ["fields"] = {}}, ["param1"] = 141}, {["y"] = 6, ["x"] = 6, ["name"] = "default:glass", ["z"] = 46, ["meta"] = {["inventory"] = {}, ["fields"] = {}}, ["param1"] = 125}, {["y"] = 6, ["x"] = 6, ["name"] = "default:glass", ["z"] = 47, ["meta"] = {["inventory"] = {}, ["fields"] = {}}, ["param1"] = 109}, {["y"] = 6, ["x"] = 6, ["name"] = "default:glass", ["z"] = 48, ["meta"] = {["inventory"] = {}, ["fields"] = {}}, ["param1"] = 125}, {["y"] = 6, ["x"] = 6, ["name"] = "default:glass", ["z"] = 49, ["meta"] = {["inventory"] = {}, ["fields"] = {}}, ["param1"] = 141}, {["y"] = 6, ["x"] = 6, ["name"] = "default:glass", ["z"] = 50, ["meta"] = {["inventory"] = {}, ["fields"] = {}}, ["param1"] = 157}, {["y"] = 6, ["x"] = 6, ["name"] = "default:glass", ["z"] = 51, ["meta"] = {["inventory"] = {}, ["fields"] = {}}, ["param1"] = 141}, {["y"] = 6, ["x"] = 6, ["name"] = "default:glass", ["z"] = 52, ["meta"] = {["inventory"] = {}, ["fields"] = {}}, ["param1"] = 141}, {["y"] = 6, ["x"] = 6, ["name"] = "default:glass", ["z"] = 53, ["meta"] = {["inventory"] = {}, ["fields"] = {}}, ["param1"] = 125}, {["y"] = 7, ["x"] = 6, ["name"] = "default:cobble", ["z"] = 9, ["meta"] = {["inventory"] = {}, ["fields"] = {}}}, {["y"] = 7, ["x"] = 6, ["name"] = "default:cobble", ["z"] = 10, ["meta"] = {["inventory"] = {}, ["fields"] = {}}}, {["y"] = 7, ["x"] = 6, ["name"] = "default:cobble", ["z"] = 11, ["meta"] = {["inventory"] = {}, ["fields"] = {}}}, {["y"] = 7, ["x"] = 6, ["name"] = "default:cobble", ["z"] = 12, ["meta"] = {["inventory"] = {}, ["fields"] = {}}}, {["y"] = 7, ["x"] = 6, ["name"] = "default:cobble", ["z"] = 13, ["meta"] = {["inventory"] = {}, ["fields"] = {}}}, {["y"] = 7, ["x"] = 6, ["name"] = "default:cobble", ["z"] = 14, ["meta"] = {["inventory"] = {}, ["fields"] = {}}}, {["y"] = 7, ["x"] = 6, ["name"] = "default:cobble", ["z"] = 15, ["meta"] = {["inventory"] = {}, ["fields"] = {}}}, {["y"] = 7, ["x"] = 6, ["name"] = "default:cobble", ["z"] = 16, ["meta"] = {["inventory"] = {}, ["fields"] = {}}}, {["y"] = 7, ["x"] = 6, ["name"] = "default:cobble", ["z"] = 17, ["meta"] = {["inventory"] = {}, ["fields"] = {}}}, {["y"] = 7, ["x"] = 6, ["name"] = "default:cobble", ["z"] = 18, ["meta"] = {["inventory"] = {}, ["fields"] = {}}}, {["y"] = 7, ["x"] = 6, ["name"] = "default:cobble", ["z"] = 19, ["meta"] = {["inventory"] = {}, ["fields"] = {}}}, {["y"] = 7, ["x"] = 6, ["name"] = "default:cobble", ["z"] = 20, ["meta"] = {["inventory"] = {}, ["fields"] = {}}}, {["y"] = 7, ["x"] = 6, ["name"] = "default:cobble", ["z"] = 21, ["meta"] = {["inventory"] = {}, ["fields"] = {}}}, {["y"] = 7, ["x"] = 6, ["name"] = "default:cobble", ["z"] = 22, ["meta"] = {["inventory"] = {}, ["fields"] = {}}}, {["y"] = 7, ["x"] = 6, ["name"] = "default:cobble", ["z"] = 23, ["meta"] = {["inventory"] = {}, ["fields"] = {}}}, {["y"] = 7, ["x"] = 6, ["name"] = "default:cobble", ["z"] = 24, ["meta"] = {["inventory"] = {}, ["fields"] = {}}}, {["y"] = 7, ["x"] = 6, ["name"] = "default:cobble", ["z"] = 25, ["meta"] = {["inventory"] = {}, ["fields"] = {}}}, {["y"] = 7, ["x"] = 6, ["name"] = "default:cobble", ["z"] = 26, ["meta"] = {["inventory"] = {}, ["fields"] = {}}}, {["y"] = 7, ["x"] = 6, ["name"] = "default:cobble", ["z"] = 27, ["meta"] = {["inventory"] = {}, ["fields"] = {}}}, {["y"] = 7, ["x"] = 6, ["name"] = "default:cobble", ["z"] = 28, ["meta"] = {["inventory"] = {}, ["fields"] = {}}}, {["y"] = 7, ["x"] = 6, ["name"] = "default:cobble", ["z"] = 29, ["meta"] = {["inventory"] = {}, ["fields"] = {}}}, {["y"] = 7, ["x"] = 6, ["name"] = "default:cobble", ["z"] = 30, ["meta"] = {["inventory"] = {}, ["fields"] = {}}}, {["y"] = 7, ["x"] = 6, ["name"] = "default:cobble", ["z"] = 31, ["meta"] = {["inventory"] = {}, ["fields"] = {}}}, {["y"] = 7, ["x"] = 6, ["name"] = "default:cobble", ["z"] = 32, ["meta"] = {["inventory"] = {}, ["fields"] = {}}}, {["y"] = 7, ["x"] = 6, ["name"] = "default:cobble", ["z"] = 33, ["meta"] = {["inventory"] = {}, ["fields"] = {}}}, {["y"] = 7, ["x"] = 6, ["name"] = "default:cobble", ["z"] = 34, ["meta"] = {["inventory"] = {}, ["fields"] = {}}}, {["y"] = 7, ["x"] = 6, ["name"] = "default:cobble", ["z"] = 35, ["meta"] = {["inventory"] = {}, ["fields"] = {}}}, {["y"] = 7, ["x"] = 6, ["name"] = "default:cobble", ["z"] = 36, ["meta"] = {["inventory"] = {}, ["fields"] = {}}}, {["y"] = 7, ["x"] = 6, ["name"] = "default:cobble", ["z"] = 37, ["meta"] = {["inventory"] = {}, ["fields"] = {}}}, {["y"] = 7, ["x"] = 6, ["name"] = "default:cobble", ["z"] = 38, ["meta"] = {["inventory"] = {}, ["fields"] = {}}}, {["y"] = 7, ["x"] = 6, ["name"] = "default:cobble", ["z"] = 39, ["meta"] = {["inventory"] = {}, ["fields"] = {}}}, {["y"] = 7, ["x"] = 6, ["name"] = "default:cobble", ["z"] = 40, ["meta"] = {["inventory"] = {}, ["fields"] = {}}}, {["y"] = 7, ["x"] = 6, ["name"] = "default:cobble", ["z"] = 41, ["meta"] = {["inventory"] = {}, ["fields"] = {}}}, {["y"] = 7, ["x"] = 6, ["name"] = "default:cobble", ["z"] = 42, ["meta"] = {["inventory"] = {}, ["fields"] = {}}}, {["y"] = 7, ["x"] = 6, ["name"] = "default:cobble", ["z"] = 43, ["meta"] = {["inventory"] = {}, ["fields"] = {}}}, {["y"] = 7, ["x"] = 6, ["name"] = "default:cobble", ["z"] = 44, ["meta"] = {["inventory"] = {}, ["fields"] = {}}}, {["y"] = 7, ["x"] = 6, ["name"] = "default:cobble", ["z"] = 45, ["meta"] = {["inventory"] = {}, ["fields"] = {}}}, {["y"] = 7, ["x"] = 6, ["name"] = "default:cobble", ["z"] = 46, ["meta"] = {["inventory"] = {}, ["fields"] = {}}}, {["y"] = 7, ["x"] = 6, ["name"] = "default:cobble", ["z"] = 47, ["meta"] = {["inventory"] = {}, ["fields"] = {}}}, {["y"] = 7, ["x"] = 6, ["name"] = "default:cobble", ["z"] = 48, ["meta"] = {["inventory"] = {}, ["fields"] = {}}}, {["y"] = 7, ["x"] = 6, ["name"] = "default:cobble", ["z"] = 49, ["meta"] = {["inventory"] = {}, ["fields"] = {}}}, {["y"] = 7, ["x"] = 6, ["name"] = "default:cobble", ["z"] = 50, ["meta"] = {["inventory"] = {}, ["fields"] = {}}}, {["y"] = 7, ["x"] = 6, ["name"] = "default:cobble", ["z"] = 51, ["meta"] = {["inventory"] = {}, ["fields"] = {}}}, {["y"] = 7, ["x"] = 6, ["name"] = "default:cobble", ["z"] = 52, ["meta"] = {["inventory"] = {}, ["fields"] = {}}}, {["y"] = 7, ["x"] = 6, ["name"] = "default:cobble", ["z"] = 53, ["meta"] = {["inventory"] = {}, ["fields"] = {}}}, {["y"] = 8, ["x"] = 6, ["name"] = "default:cobble", ["z"] = 9, ["meta"] = {["inventory"] = {}, ["fields"] = {}}}, {["y"] = 8, ["x"] = 6, ["name"] = "default:cobble", ["z"] = 10, ["meta"] = {["inventory"] = {}, ["fields"] = {}}}, {["y"] = 8, ["x"] = 6, ["name"] = "default:cobble", ["z"] = 11, ["meta"] = {["inventory"] = {}, ["fields"] = {}}}, {["y"] = 8, ["x"] = 6, ["name"] = "default:cobble", ["z"] = 12, ["meta"] = {["inventory"] = {}, ["fields"] = {}}}, {["y"] = 8, ["x"] = 6, ["name"] = "default:cobble", ["z"] = 13, ["meta"] = {["inventory"] = {}, ["fields"] = {}}}, {["y"] = 8, ["x"] = 6, ["name"] = "default:cobble", ["z"] = 14, ["meta"] = {["inventory"] = {}, ["fields"] = {}}}, {["y"] = 8, ["x"] = 6, ["name"] = "default:cobble", ["z"] = 15, ["meta"] = {["inventory"] = {}, ["fields"] = {}}}, {["y"] = 8, ["x"] = 6, ["name"] = "default:cobble", ["z"] = 16, ["meta"] = {["inventory"] = {}, ["fields"] = {}}}, {["y"] = 8, ["x"] = 6, ["name"] = "default:cobble", ["z"] = 17, ["meta"] = {["inventory"] = {}, ["fields"] = {}}}, {["y"] = 8, ["x"] = 6, ["name"] = "default:cobble", ["z"] = 18, ["meta"] = {["inventory"] = {}, ["fields"] = {}}}, {["y"] = 8, ["x"] = 6, ["name"] = "default:cobble", ["z"] = 19, ["meta"] = {["inventory"] = {}, ["fields"] = {}}}, {["y"] = 8, ["x"] = 6, ["name"] = "default:cobble", ["z"] = 20, ["meta"] = {["inventory"] = {}, ["fields"] = {}}}, {["y"] = 8, ["x"] = 6, ["name"] = "default:cobble", ["z"] = 21, ["meta"] = {["inventory"] = {}, ["fields"] = {}}}, {["y"] = 8, ["x"] = 6, ["name"] = "default:cobble", ["z"] = 22, ["meta"] = {["inventory"] = {}, ["fields"] = {}}}, {["y"] = 8, ["x"] = 6, ["name"] = "default:cobble", ["z"] = 23, ["meta"] = {["inventory"] = {}, ["fields"] = {}}}, {["y"] = 8, ["x"] = 6, ["name"] = "default:cobble", ["z"] = 24, ["meta"] = {["inventory"] = {}, ["fields"] = {}}}, {["y"] = 8, ["x"] = 6, ["name"] = "default:cobble", ["z"] = 25, ["meta"] = {["inventory"] = {}, ["fields"] = {}}}, {["y"] = 8, ["x"] = 6, ["name"] = "default:cobble", ["z"] = 26, ["meta"] = {["inventory"] = {}, ["fields"] = {}}}, {["y"] = 8, ["x"] = 6, ["name"] = "default:cobble", ["z"] = 27, ["meta"] = {["inventory"] = {}, ["fields"] = {}}}, {["y"] = 8, ["x"] = 6, ["name"] = "default:cobble", ["z"] = 28, ["meta"] = {["inventory"] = {}, ["fields"] = {}}}, {["y"] = 8, ["x"] = 6, ["name"] = "default:cobble", ["z"] = 29, ["meta"] = {["inventory"] = {}, ["fields"] = {}}}, {["y"] = 8, ["x"] = 6, ["name"] = "default:cobble", ["z"] = 30, ["meta"] = {["inventory"] = {}, ["fields"] = {}}}, {["y"] = 8, ["x"] = 6, ["name"] = "default:cobble", ["z"] = 31, ["meta"] = {["inventory"] = {}, ["fields"] = {}}}, {["y"] = 8, ["x"] = 6, ["name"] = "default:cobble", ["z"] = 32, ["meta"] = {["inventory"] = {}, ["fields"] = {}}}, {["y"] = 8, ["x"] = 6, ["name"] = "default:cobble", ["z"] = 33, ["meta"] = {["inventory"] = {}, ["fields"] = {}}}, {["y"] = 8, ["x"] = 6, ["name"] = "default:cobble", ["z"] = 34, ["meta"] = {["inventory"] = {}, ["fields"] = {}}}, {["y"] = 8, ["x"] = 6, ["name"] = "default:cobble", ["z"] = 35, ["meta"] = {["inventory"] = {}, ["fields"] = {}}}, {["y"] = 8, ["x"] = 6, ["name"] = "default:cobble", ["z"] = 36, ["meta"] = {["inventory"] = {}, ["fields"] = {}}}, {["y"] = 8, ["x"] = 6, ["name"] = "default:cobble", ["z"] = 37, ["meta"] = {["inventory"] = {}, ["fields"] = {}}}, {["y"] = 8, ["x"] = 6, ["name"] = "default:cobble", ["z"] = 38, ["meta"] = {["inventory"] = {}, ["fields"] = {}}}, {["y"] = 8, ["x"] = 6, ["name"] = "default:cobble", ["z"] = 39, ["meta"] = {["inventory"] = {}, ["fields"] = {}}}, {["y"] = 8, ["x"] = 6, ["name"] = "default:cobble", ["z"] = 40, ["meta"] = {["inventory"] = {}, ["fields"] = {}}}, {["y"] = 8, ["x"] = 6, ["name"] = "default:cobble", ["z"] = 41, ["meta"] = {["inventory"] = {}, ["fields"] = {}}}, {["y"] = 8, ["x"] = 6, ["name"] = "default:cobble", ["z"] = 42, ["meta"] = {["inventory"] = {}, ["fields"] = {}}}, {["y"] = 8, ["x"] = 6, ["name"] = "default:cobble", ["z"] = 43, ["meta"] = {["inventory"] = {}, ["fields"] = {}}}, {["y"] = 8, ["x"] = 6, ["name"] = "default:cobble", ["z"] = 44, ["meta"] = {["inventory"] = {}, ["fields"] = {}}}, {["y"] = 8, ["x"] = 6, ["name"] = "default:cobble", ["z"] = 45, ["meta"] = {["inventory"] = {}, ["fields"] = {}}}, {["y"] = 8, ["x"] = 6, ["name"] = "default:cobble", ["z"] = 46, ["meta"] = {["inventory"] = {}, ["fields"] = {}}}, {["y"] = 8, ["x"] = 6, ["name"] = "default:cobble", ["z"] = 47, ["meta"] = {["inventory"] = {}, ["fields"] = {}}}, {["y"] = 8, ["x"] = 6, ["name"] = "default:cobble", ["z"] = 48, ["meta"] = {["inventory"] = {}, ["fields"] = {}}}, {["y"] = 8, ["x"] = 6, ["name"] = "default:cobble", ["z"] = 49, ["meta"] = {["inventory"] = {}, ["fields"] = {}}}, {["y"] = 8, ["x"] = 6, ["name"] = "default:cobble", ["z"] = 50, ["meta"] = {["inventory"] = {}, ["fields"] = {}}}, {["y"] = 8, ["x"] = 6, ["name"] = "default:cobble", ["z"] = 51, ["meta"] = {["inventory"] = {}, ["fields"] = {}}}, {["y"] = 8, ["x"] = 6, ["name"] = "default:cobble", ["z"] = 52, ["meta"] = {["inventory"] = {}, ["fields"] = {}}}, {["y"] = 8, ["x"] = 6, ["name"] = "default:cobble", ["z"] = 53, ["meta"] = {["inventory"] = {}, ["fields"] = {}}}, {["y"] = 9, ["x"] = 6, ["name"] = "default:glass", ["z"] = 9, ["meta"] = {["inventory"] = {}, ["fields"] = {}}, ["param1"] = 159}, {["y"] = 9, ["x"] = 6, ["name"] = "default:glass", ["z"] = 10, ["meta"] = {["inventory"] = {}, ["fields"] = {}}, ["param1"] = 175}, {["y"] = 9, ["x"] = 6, ["name"] = "default:glass", ["z"] = 11, ["meta"] = {["inventory"] = {}, ["fields"] = {}}, ["param1"] = 159}, {["y"] = 9, ["x"] = 6, ["name"] = "default:glass", ["z"] = 12, ["meta"] = {["inventory"] = {}, ["fields"] = {}}, ["param1"] = 143}, {["y"] = 9, ["x"] = 6, ["name"] = "default:glass", ["z"] = 13, ["meta"] = {["inventory"] = {}, ["fields"] = {}}, ["param1"] = 143}, {["y"] = 9, ["x"] = 6, ["name"] = "default:glass", ["z"] = 14, ["meta"] = {["inventory"] = {}, ["fields"] = {}}, ["param1"] = 159}, {["y"] = 9, ["x"] = 6, ["name"] = "default:glass", ["z"] = 15, ["meta"] = {["inventory"] = {}, ["fields"] = {}}, ["param1"] = 175}, {["y"] = 9, ["x"] = 6, ["name"] = "default:glass", ["z"] = 16, ["meta"] = {["inventory"] = {}, ["fields"] = {}}, ["param1"] = 159}, {["y"] = 9, ["x"] = 6, ["name"] = "default:glass", ["z"] = 17, ["meta"] = {["inventory"] = {}, ["fields"] = {}}, ["param1"] = 143}, {["y"] = 9, ["x"] = 6, ["name"] = "default:glass", ["z"] = 18, ["meta"] = {["inventory"] = {}, ["fields"] = {}}, ["param1"] = 143}, {["y"] = 9, ["x"] = 6, ["name"] = "default:glass", ["z"] = 19, ["meta"] = {["inventory"] = {}, ["fields"] = {}}, ["param1"] = 159}, {["y"] = 9, ["x"] = 6, ["name"] = "default:glass", ["z"] = 20, ["meta"] = {["inventory"] = {}, ["fields"] = {}}, ["param1"] = 143}, {["y"] = 9, ["x"] = 6, ["name"] = "default:glass", ["z"] = 21, ["meta"] = {["inventory"] = {}, ["fields"] = {}}, ["param1"] = 143}, {["y"] = 9, ["x"] = 6, ["name"] = "default:glass", ["z"] = 22, ["meta"] = {["inventory"] = {}, ["fields"] = {}}, ["param1"] = 159}, {["y"] = 9, ["x"] = 6, ["name"] = "default:glass", ["z"] = 23, ["meta"] = {["inventory"] = {}, ["fields"] = {}}, ["param1"] = 175}, {["y"] = 9, ["x"] = 6, ["name"] = "default:glass", ["z"] = 24, ["meta"] = {["inventory"] = {}, ["fields"] = {}}, ["param1"] = 159}, {["y"] = 9, ["x"] = 6, ["name"] = "default:glass", ["z"] = 25, ["meta"] = {["inventory"] = {}, ["fields"] = {}}, ["param1"] = 143}, {["y"] = 9, ["x"] = 6, ["name"] = "default:glass", ["z"] = 26, ["meta"] = {["inventory"] = {}, ["fields"] = {}}, ["param1"] = 127}, {["y"] = 9, ["x"] = 6, ["name"] = "default:glass", ["z"] = 27, ["meta"] = {["inventory"] = {}, ["fields"] = {}}, ["param1"] = 143}, {["y"] = 9, ["x"] = 6, ["name"] = "default:glass", ["z"] = 28, ["meta"] = {["inventory"] = {}, ["fields"] = {}}, ["param1"] = 159}, {["y"] = 9, ["x"] = 6, ["name"] = "default:glass", ["z"] = 29, ["meta"] = {["inventory"] = {}, ["fields"] = {}}, ["param1"] = 143}, {["y"] = 9, ["x"] = 6, ["name"] = "default:glass", ["z"] = 30, ["meta"] = {["inventory"] = {}, ["fields"] = {}}, ["param1"] = 143}, {["y"] = 9, ["x"] = 6, ["name"] = "default:glass", ["z"] = 31, ["meta"] = {["inventory"] = {}, ["fields"] = {}}, ["param1"] = 159}, {["y"] = 9, ["x"] = 6, ["name"] = "default:glass", ["z"] = 32, ["meta"] = {["inventory"] = {}, ["fields"] = {}}, ["param1"] = 159}, {["y"] = 9, ["x"] = 6, ["name"] = "default:glass", ["z"] = 33, ["meta"] = {["inventory"] = {}, ["fields"] = {}}, ["param1"] = 159}, {["y"] = 9, ["x"] = 6, ["name"] = "default:glass", ["z"] = 34, ["meta"] = {["inventory"] = {}, ["fields"] = {}}, ["param1"] = 159}, {["y"] = 9, ["x"] = 6, ["name"] = "default:glass", ["z"] = 35, ["meta"] = {["inventory"] = {}, ["fields"] = {}}, ["param1"] = 159}, {["y"] = 9, ["x"] = 6, ["name"] = "default:glass", ["z"] = 36, ["meta"] = {["inventory"] = {}, ["fields"] = {}}, ["param1"] = 175}, {["y"] = 9, ["x"] = 6, ["name"] = "default:glass", ["z"] = 37, ["meta"] = {["inventory"] = {}, ["fields"] = {}}, ["param1"] = 191}, {["y"] = 9, ["x"] = 6, ["name"] = "default:glass", ["z"] = 38, ["meta"] = {["inventory"] = {}, ["fields"] = {}}, ["param1"] = 175}, {["y"] = 9, ["x"] = 6, ["name"] = "default:glass", ["z"] = 39, ["meta"] = {["inventory"] = {}, ["fields"] = {}}, ["param1"] = 159}, {["y"] = 9, ["x"] = 6, ["name"] = "default:glass", ["z"] = 40, ["meta"] = {["inventory"] = {}, ["fields"] = {}}, ["param1"] = 143}, {["y"] = 9, ["x"] = 6, ["name"] = "default:glass", ["z"] = 41, ["meta"] = {["inventory"] = {}, ["fields"] = {}}, ["param1"] = 127}, {["y"] = 9, ["x"] = 6, ["name"] = "default:glass", ["z"] = 42, ["meta"] = {["inventory"] = {}, ["fields"] = {}}, ["param1"] = 143}, {["y"] = 9, ["x"] = 6, ["name"] = "default:glass", ["z"] = 43, ["meta"] = {["inventory"] = {}, ["fields"] = {}}, ["param1"] = 159}, {["y"] = 9, ["x"] = 6, ["name"] = "default:glass", ["z"] = 44, ["meta"] = {["inventory"] = {}, ["fields"] = {}}, ["param1"] = 175}, {["y"] = 9, ["x"] = 6, ["name"] = "default:glass", ["z"] = 45, ["meta"] = {["inventory"] = {}, ["fields"] = {}}, ["param1"] = 159}, {["y"] = 9, ["x"] = 6, ["name"] = "default:glass", ["z"] = 46, ["meta"] = {["inventory"] = {}, ["fields"] = {}}, ["param1"] = 143}, {["y"] = 9, ["x"] = 6, ["name"] = "default:glass", ["z"] = 47, ["meta"] = {["inventory"] = {}, ["fields"] = {}}, ["param1"] = 127}, {["y"] = 9, ["x"] = 6, ["name"] = "default:glass", ["z"] = 48, ["meta"] = {["inventory"] = {}, ["fields"] = {}}, ["param1"] = 143}, {["y"] = 9, ["x"] = 6, ["name"] = "default:glass", ["z"] = 49, ["meta"] = {["inventory"] = {}, ["fields"] = {}}, ["param1"] = 159}, {["y"] = 9, ["x"] = 6, ["name"] = "default:glass", ["z"] = 50, ["meta"] = {["inventory"] = {}, ["fields"] = {}}, ["param1"] = 175}, {["y"] = 9, ["x"] = 6, ["name"] = "default:glass", ["z"] = 51, ["meta"] = {["inventory"] = {}, ["fields"] = {}}, ["param1"] = 159}, {["y"] = 9, ["x"] = 6, ["name"] = "default:glass", ["z"] = 52, ["meta"] = {["inventory"] = {}, ["fields"] = {}}, ["param1"] = 159}, {["y"] = 9, ["x"] = 6, ["name"] = "default:glass", ["z"] = 53, ["meta"] = {["inventory"] = {}, ["fields"] = {}}, ["param1"] = 143}, {["y"] = 3, ["x"] = 7, ["name"] = "default:glass", ["z"] = 9, ["meta"] = {["inventory"] = {}, ["fields"] = {}}, ["param1"] = 173}, {["y"] = 3, ["x"] = 7, ["name"] = "default:glass", ["z"] = 10, ["meta"] = {["inventory"] = {}, ["fields"] = {}}, ["param1"] = 191}, {["y"] = 3, ["x"] = 7, ["name"] = "default:glass", ["z"] = 11, ["meta"] = {["inventory"] = {}, ["fields"] = {}}, ["param1"] = 175}, {["y"] = 3, ["x"] = 7, ["name"] = "default:glass", ["z"] = 12, ["meta"] = {["inventory"] = {}, ["fields"] = {}}, ["param1"] = 159}, {["y"] = 3, ["x"] = 7, ["name"] = "default:glass", ["z"] = 13, ["meta"] = {["inventory"] = {}, ["fields"] = {}}, ["param1"] = 143}, {["y"] = 3, ["x"] = 7, ["name"] = "default:glass", ["z"] = 14, ["meta"] = {["inventory"] = {}, ["fields"] = {}}, ["param1"] = 125}, {["y"] = 3, ["x"] = 7, ["name"] = "default:glass", ["z"] = 15, ["meta"] = {["inventory"] = {}, ["fields"] = {}}, ["param1"] = 143}, {["y"] = 3, ["x"] = 7, ["name"] = "default:glass", ["z"] = 16, ["meta"] = {["inventory"] = {}, ["fields"] = {}}, ["param1"] = 157}, {["y"] = 3, ["x"] = 7, ["name"] = "default:glass", ["z"] = 17, ["meta"] = {["inventory"] = {}, ["fields"] = {}}, ["param1"] = 175}, {["y"] = 3, ["x"] = 7, ["name"] = "default:glass", ["z"] = 18, ["meta"] = {["inventory"] = {}, ["fields"] = {}}, ["param1"] = 159}, {["y"] = 3, ["x"] = 7, ["name"] = "default:glass", ["z"] = 19, ["meta"] = {["inventory"] = {}, ["fields"] = {}}, ["param1"] = 159}, {["y"] = 3, ["x"] = 7, ["name"] = "default:glass", ["z"] = 20, ["meta"] = {["inventory"] = {}, ["fields"] = {}}, ["param1"] = 175}, {["y"] = 3, ["x"] = 7, ["name"] = "default:glass", ["z"] = 21, ["meta"] = {["inventory"] = {}, ["fields"] = {}}, ["param1"] = 159}, {["y"] = 3, ["x"] = 7, ["name"] = "default:glass", ["z"] = 22, ["meta"] = {["inventory"] = {}, ["fields"] = {}}, ["param1"] = 141}, {["y"] = 3, ["x"] = 7, ["name"] = "default:glass", ["z"] = 23, ["meta"] = {["inventory"] = {}, ["fields"] = {}}, ["param1"] = 125}, {["y"] = 3, ["x"] = 7, ["name"] = "default:glass", ["z"] = 24, ["meta"] = {["inventory"] = {}, ["fields"] = {}}, ["param1"] = 111}, {["y"] = 3, ["x"] = 7, ["name"] = "default:glass", ["z"] = 25, ["meta"] = {["inventory"] = {}, ["fields"] = {}}, ["param1"] = 127}, {["y"] = 3, ["x"] = 7, ["name"] = "default:glass", ["z"] = 26, ["meta"] = {["inventory"] = {}, ["fields"] = {}}, ["param1"] = 143}, {["y"] = 3, ["x"] = 7, ["name"] = "default:glass", ["z"] = 27, ["meta"] = {["inventory"] = {}, ["fields"] = {}}, ["param1"] = 157}, {["y"] = 3, ["x"] = 7, ["name"] = "default:glass", ["z"] = 28, ["meta"] = {["inventory"] = {}, ["fields"] = {}}, ["param1"] = 173}, {["y"] = 3, ["x"] = 7, ["name"] = "default:glass", ["z"] = 29, ["meta"] = {["inventory"] = {}, ["fields"] = {}}, ["param1"] = 191}, {["y"] = 3, ["x"] = 7, ["name"] = "default:glass", ["z"] = 30, ["meta"] = {["inventory"] = {}, ["fields"] = {}}, ["param1"] = 207}, {["y"] = 3, ["x"] = 7, ["name"] = "default:glass", ["z"] = 31, ["meta"] = {["inventory"] = {}, ["fields"] = {}}, ["param1"] = 223}, {["y"] = 3, ["x"] = 7, ["name"] = "moreblocks:super_glow_glass", ["z"] = 32, ["meta"] = {["inventory"] = {}, ["fields"] = {}}}, {["y"] = 3, ["x"] = 7, ["name"] = "default:glass", ["z"] = 33, ["meta"] = {["inventory"] = {}, ["fields"] = {}}, ["param1"] = 223}, {["y"] = 3, ["x"] = 7, ["name"] = "default:glass", ["z"] = 34, ["meta"] = {["inventory"] = {}, ["fields"] = {}}, ["param1"] = 207}, {["y"] = 3, ["x"] = 7, ["name"] = "default:glass", ["z"] = 35, ["meta"] = {["inventory"] = {}, ["fields"] = {}}, ["param1"] = 189}, {["y"] = 3, ["x"] = 7, ["name"] = "default:glass", ["z"] = 36, ["meta"] = {["inventory"] = {}, ["fields"] = {}}, ["param1"] = 175}, {["y"] = 3, ["x"] = 7, ["name"] = "default:glass", ["z"] = 37, ["meta"] = {["inventory"] = {}, ["fields"] = {}}, ["param1"] = 159}, {["y"] = 3, ["x"] = 7, ["name"] = "default:glass", ["z"] = 38, ["meta"] = {["inventory"] = {}, ["fields"] = {}}, ["param1"] = 141}, {["y"] = 3, ["x"] = 7, ["name"] = "default:glass", ["z"] = 39, ["meta"] = {["inventory"] = {}, ["fields"] = {}}, ["param1"] = 125}, {["y"] = 3, ["x"] = 7, ["name"] = "default:glass", ["z"] = 40, ["meta"] = {["inventory"] = {}, ["fields"] = {}}, ["param1"] = 109}, {["y"] = 3, ["x"] = 7, ["name"] = "default:glass", ["z"] = 41, ["meta"] = {["inventory"] = {}, ["fields"] = {}}, ["param1"] = 95}, {["y"] = 3, ["x"] = 7, ["name"] = "default:glass", ["z"] = 42, ["meta"] = {["inventory"] = {}, ["fields"] = {}}, ["param1"] = 111}, {["y"] = 3, ["x"] = 7, ["name"] = "default:glass", ["z"] = 43, ["meta"] = {["inventory"] = {}, ["fields"] = {}}, ["param1"] = 125}, {["y"] = 3, ["x"] = 7, ["name"] = "default:glass", ["z"] = 44, ["meta"] = {["inventory"] = {}, ["fields"] = {}}, ["param1"] = 141}, {["y"] = 3, ["x"] = 7, ["name"] = "default:glass", ["z"] = 45, ["meta"] = {["inventory"] = {}, ["fields"] = {}}, ["param1"] = 127}, {["y"] = 3, ["x"] = 7, ["name"] = "default:glass", ["z"] = 46, ["meta"] = {["inventory"] = {}, ["fields"] = {}}, ["param1"] = 109}, {["y"] = 3, ["x"] = 7, ["name"] = "default:glass", ["z"] = 47, ["meta"] = {["inventory"] = {}, ["fields"] = {}}, ["param1"] = 95}, {["y"] = 3, ["x"] = 7, ["name"] = "default:glass", ["z"] = 48, ["meta"] = {["inventory"] = {}, ["fields"] = {}}, ["param1"] = 93}, {["y"] = 3, ["x"] = 7, ["name"] = "default:glass", ["z"] = 49, ["meta"] = {["inventory"] = {}, ["fields"] = {}}, ["param1"] = 111}, {["y"] = 3, ["x"] = 7, ["name"] = "default:glass", ["z"] = 50, ["meta"] = {["inventory"] = {}, ["fields"] = {}}, ["param1"] = 127}, {["y"] = 3, ["x"] = 7, ["name"] = "default:glass", ["z"] = 51, ["meta"] = {["inventory"] = {}, ["fields"] = {}}, ["param1"] = 109}, {["y"] = 3, ["x"] = 7, ["name"] = "default:glass", ["z"] = 52, ["meta"] = {["inventory"] = {}, ["fields"] = {}}, ["param1"] = 108}, {["y"] = 3, ["x"] = 7, ["name"] = "default:glass", ["z"] = 53, ["meta"] = {["inventory"] = {}, ["fields"] = {}}, ["param1"] = 93}, {["y"] = 4, ["x"] = 7, ["name"] = "default:cobble", ["z"] = 9, ["meta"] = {["inventory"] = {}, ["fields"] = {}}}, {["y"] = 4, ["x"] = 7, ["name"] = "default:cobble", ["z"] = 16, ["meta"] = {["inventory"] = {}, ["fields"] = {}}}, {["y"] = 4, ["x"] = 7, ["name"] = "default:cobble", ["z"] = 23, ["meta"] = {["inventory"] = {}, ["fields"] = {}}}, {["y"] = 4, ["x"] = 7, ["name"] = "default:cobble", ["z"] = 35, ["meta"] = {["inventory"] = {}, ["fields"] = {}}}, {["y"] = 4, ["x"] = 7, ["name"] = "default:cobble", ["z"] = 38, ["meta"] = {["inventory"] = {}, ["fields"] = {}}}, {["y"] = 4, ["x"] = 7, ["name"] = "default:cobble", ["z"] = 39, ["meta"] = {["inventory"] = {}, ["fields"] = {}}}, {["y"] = 4, ["x"] = 7, ["name"] = "default:cobble", ["z"] = 43, ["meta"] = {["inventory"] = {}, ["fields"] = {}}}, {["y"] = 4, ["x"] = 7, ["name"] = "default:cobble", ["z"] = 48, ["meta"] = {["inventory"] = {}, ["fields"] = {}}}, {["y"] = 4, ["x"] = 7, ["name"] = "default:cobble", ["z"] = 53, ["meta"] = {["inventory"] = {}, ["fields"] = {}}}, {["y"] = 5, ["x"] = 7, ["name"] = "default:cobble", ["z"] = 9, ["meta"] = {["inventory"] = {}, ["fields"] = {}}}, {["y"] = 5, ["x"] = 7, ["name"] = "default:torch", ["z"] = 10, ["meta"] = {["inventory"] = {}, ["fields"] = {}}, ["param2"] = 6, ["param1"] = 15}, {["y"] = 5, ["x"] = 7, ["name"] = "default:cobble", ["z"] = 16, ["meta"] = {["inventory"] = {}, ["fields"] = {}}}, {["y"] = 5, ["x"] = 7, ["name"] = "default:cobble", ["z"] = 23, ["meta"] = {["inventory"] = {}, ["fields"] = {}}}, {["y"] = 5, ["x"] = 7, ["name"] = "default:cobble", ["z"] = 35, ["meta"] = {["inventory"] = {}, ["fields"] = {}}}, {["y"] = 5, ["x"] = 7, ["name"] = "default:cobble", ["z"] = 38, ["meta"] = {["inventory"] = {}, ["fields"] = {}}}, {["y"] = 5, ["x"] = 7, ["name"] = "default:cobble", ["z"] = 39, ["meta"] = {["inventory"] = {}, ["fields"] = {}}}, {["y"] = 5, ["x"] = 7, ["name"] = "default:cobble", ["z"] = 43, ["meta"] = {["inventory"] = {}, ["fields"] = {}}}, {["y"] = 5, ["x"] = 7, ["name"] = "default:cobble", ["z"] = 48, ["meta"] = {["inventory"] = {}, ["fields"] = {}}}, {["y"] = 5, ["x"] = 7, ["name"] = "default:cobble", ["z"] = 53, ["meta"] = {["inventory"] = {}, ["fields"] = {}}}, {["y"] = 6, ["x"] = 7, ["name"] = "default:glass", ["z"] = 9, ["meta"] = {["inventory"] = {}, ["fields"] = {}}, ["param1"] = 189}, {["y"] = 6, ["x"] = 7, ["name"] = "default:glass", ["z"] = 10, ["meta"] = {["inventory"] = {}, ["fields"] = {}}, ["param1"] = 207}, {["y"] = 6, ["x"] = 7, ["name"] = "default:glass", ["z"] = 11, ["meta"] = {["inventory"] = {}, ["fields"] = {}}, ["param1"] = 191}, {["y"] = 6, ["x"] = 7, ["name"] = "default:glass", ["z"] = 12, ["meta"] = {["inventory"] = {}, ["fields"] = {}}, ["param1"] = 175}, {["y"] = 6, ["x"] = 7, ["name"] = "default:glass", ["z"] = 13, ["meta"] = {["inventory"] = {}, ["fields"] = {}}, ["param1"] = 159}, {["y"] = 6, ["x"] = 7, ["name"] = "default:glass", ["z"] = 14, ["meta"] = {["inventory"] = {}, ["fields"] = {}}, ["param1"] = 157}, {["y"] = 6, ["x"] = 7, ["name"] = "default:glass", ["z"] = 15, ["meta"] = {["inventory"] = {}, ["fields"] = {}}, ["param1"] = 175}, {["y"] = 6, ["x"] = 7, ["name"] = "default:glass", ["z"] = 16, ["meta"] = {["inventory"] = {}, ["fields"] = {}}, ["param1"] = 173}, {["y"] = 6, ["x"] = 7, ["name"] = "default:glass", ["z"] = 17, ["meta"] = {["inventory"] = {}, ["fields"] = {}}, ["param1"] = 191}, {["y"] = 6, ["x"] = 7, ["name"] = "default:glass", ["z"] = 18, ["meta"] = {["inventory"] = {}, ["fields"] = {}}, ["param1"] = 175}, {["y"] = 6, ["x"] = 7, ["name"] = "default:glass", ["z"] = 19, ["meta"] = {["inventory"] = {}, ["fields"] = {}}, ["param1"] = 175}, {["y"] = 6, ["x"] = 7, ["name"] = "default:glass", ["z"] = 20, ["meta"] = {["inventory"] = {}, ["fields"] = {}}, ["param1"] = 191}, {["y"] = 6, ["x"] = 7, ["name"] = "default:glass", ["z"] = 21, ["meta"] = {["inventory"] = {}, ["fields"] = {}}, ["param1"] = 175}, {["y"] = 6, ["x"] = 7, ["name"] = "default:glass", ["z"] = 22, ["meta"] = {["inventory"] = {}, ["fields"] = {}}, ["param1"] = 157}, {["y"] = 6, ["x"] = 7, ["name"] = "default:glass", ["z"] = 23, ["meta"] = {["inventory"] = {}, ["fields"] = {}}, ["param1"] = 173}, {["y"] = 6, ["x"] = 7, ["name"] = "default:glass", ["z"] = 24, ["meta"] = {["inventory"] = {}, ["fields"] = {}}, ["param1"] = 159}, {["y"] = 6, ["x"] = 7, ["name"] = "default:glass", ["z"] = 25, ["meta"] = {["inventory"] = {}, ["fields"] = {}}, ["param1"] = 143}, {["y"] = 6, ["x"] = 7, ["name"] = "default:glass", ["z"] = 26, ["meta"] = {["inventory"] = {}, ["fields"] = {}}, ["param1"] = 143}, {["y"] = 6, ["x"] = 7, ["name"] = "default:glass", ["z"] = 27, ["meta"] = {["inventory"] = {}, ["fields"] = {}}, ["param1"] = 157}, {["y"] = 6, ["x"] = 7, ["name"] = "default:glass", ["z"] = 28, ["meta"] = {["inventory"] = {}, ["fields"] = {}}, ["param1"] = 173}, {["y"] = 6, ["x"] = 7, ["name"] = "default:glass", ["z"] = 29, ["meta"] = {["inventory"] = {}, ["fields"] = {}}, ["param1"] = 191}, {["y"] = 6, ["x"] = 7, ["name"] = "default:glass", ["z"] = 30, ["meta"] = {["inventory"] = {}, ["fields"] = {}}, ["param1"] = 207}, {["y"] = 6, ["x"] = 7, ["name"] = "default:glass", ["z"] = 31, ["meta"] = {["inventory"] = {}, ["fields"] = {}}, ["param1"] = 223}, {["y"] = 6, ["x"] = 7, ["name"] = "moreblocks:super_glow_glass", ["z"] = 32, ["meta"] = {["inventory"] = {}, ["fields"] = {}}}, {["y"] = 6, ["x"] = 7, ["name"] = "default:glass", ["z"] = 33, ["meta"] = {["inventory"] = {}, ["fields"] = {}}, ["param1"] = 223}, {["y"] = 6, ["x"] = 7, ["name"] = "default:glass", ["z"] = 34, ["meta"] = {["inventory"] = {}, ["fields"] = {}}, ["param1"] = 207}, {["y"] = 6, ["x"] = 7, ["name"] = "default:glass", ["z"] = 35, ["meta"] = {["inventory"] = {}, ["fields"] = {}}, ["param1"] = 191}, {["y"] = 6, ["x"] = 7, ["name"] = "default:glass", ["z"] = 36, ["meta"] = {["inventory"] = {}, ["fields"] = {}}, ["param1"] = 175}, {["y"] = 6, ["x"] = 7, ["name"] = "default:glass", ["z"] = 37, ["meta"] = {["inventory"] = {}, ["fields"] = {}}, ["param1"] = 191}, {["y"] = 6, ["x"] = 7, ["name"] = "default:glass", ["z"] = 38, ["meta"] = {["inventory"] = {}, ["fields"] = {}}, ["param1"] = 173}, {["y"] = 6, ["x"] = 7, ["name"] = "default:glass", ["z"] = 39, ["meta"] = {["inventory"] = {}, ["fields"] = {}}, ["param1"] = 159}, {["y"] = 6, ["x"] = 7, ["name"] = "default:glass", ["z"] = 40, ["meta"] = {["inventory"] = {}, ["fields"] = {}}, ["param1"] = 141}, {["y"] = 6, ["x"] = 7, ["name"] = "default:glass", ["z"] = 41, ["meta"] = {["inventory"] = {}, ["fields"] = {}}, ["param1"] = 127}, {["y"] = 6, ["x"] = 7, ["name"] = "default:glass", ["z"] = 42, ["meta"] = {["inventory"] = {}, ["fields"] = {}}, ["param1"] = 143}, {["y"] = 6, ["x"] = 7, ["name"] = "default:glass", ["z"] = 43, ["meta"] = {["inventory"] = {}, ["fields"] = {}}, ["param1"] = 159}, {["y"] = 6, ["x"] = 7, ["name"] = "default:glass", ["z"] = 44, ["meta"] = {["inventory"] = {}, ["fields"] = {}}, ["param1"] = 173}, {["y"] = 6, ["x"] = 7, ["name"] = "default:glass", ["z"] = 45, ["meta"] = {["inventory"] = {}, ["fields"] = {}}, ["param1"] = 159}, {["y"] = 6, ["x"] = 7, ["name"] = "default:glass", ["z"] = 46, ["meta"] = {["inventory"] = {}, ["fields"] = {}}, ["param1"] = 141}, {["y"] = 6, ["x"] = 7, ["name"] = "default:glass", ["z"] = 47, ["meta"] = {["inventory"] = {}, ["fields"] = {}}, ["param1"] = 127}, {["y"] = 6, ["x"] = 7, ["name"] = "default:glass", ["z"] = 48, ["meta"] = {["inventory"] = {}, ["fields"] = {}}, ["param1"] = 143}, {["y"] = 6, ["x"] = 7, ["name"] = "default:glass", ["z"] = 49, ["meta"] = {["inventory"] = {}, ["fields"] = {}}, ["param1"] = 159}, {["y"] = 6, ["x"] = 7, ["name"] = "default:glass", ["z"] = 50, ["meta"] = {["inventory"] = {}, ["fields"] = {}}, ["param1"] = 175}, {["y"] = 6, ["x"] = 7, ["name"] = "default:glass", ["z"] = 51, ["meta"] = {["inventory"] = {}, ["fields"] = {}}, ["param1"] = 157}, {["y"] = 6, ["x"] = 7, ["name"] = "default:glass", ["z"] = 52, ["meta"] = {["inventory"] = {}, ["fields"] = {}}, ["param1"] = 156}, {["y"] = 6, ["x"] = 7, ["name"] = "default:glass", ["z"] = 53, ["meta"] = {["inventory"] = {}, ["fields"] = {}}, ["param1"] = 141}, {["y"] = 7, ["x"] = 7, ["name"] = "default:cobble", ["z"] = 9, ["meta"] = {["inventory"] = {}, ["fields"] = {}}}, {["y"] = 7, ["x"] = 7, ["name"] = "default:cobble", ["z"] = 14, ["meta"] = {["inventory"] = {}, ["fields"] = {}}}, {["y"] = 7, ["x"] = 7, ["name"] = "default:cobble", ["z"] = 16, ["meta"] = {["inventory"] = {}, ["fields"] = {}}}, {["y"] = 7, ["x"] = 7, ["name"] = "default:cobble", ["z"] = 22, ["meta"] = {["inventory"] = {}, ["fields"] = {}}}, {["y"] = 7, ["x"] = 7, ["name"] = "default:cobble", ["z"] = 23, ["meta"] = {["inventory"] = {}, ["fields"] = {}}}, {["y"] = 7, ["x"] = 7, ["name"] = "default:cobble", ["z"] = 27, ["meta"] = {["inventory"] = {}, ["fields"] = {}}}, {["y"] = 7, ["x"] = 7, ["name"] = "default:cobble", ["z"] = 28, ["meta"] = {["inventory"] = {}, ["fields"] = {}}}, {["y"] = 7, ["x"] = 7, ["name"] = "default:cobble", ["z"] = 32, ["meta"] = {["inventory"] = {}, ["fields"] = {}}}, {["y"] = 7, ["x"] = 7, ["name"] = "default:cobble", ["z"] = 38, ["meta"] = {["inventory"] = {}, ["fields"] = {}}}, {["y"] = 7, ["x"] = 7, ["name"] = "default:cobble", ["z"] = 40, ["meta"] = {["inventory"] = {}, ["fields"] = {}}}, {["y"] = 7, ["x"] = 7, ["name"] = "default:cobble", ["z"] = 44, ["meta"] = {["inventory"] = {}, ["fields"] = {}}}, {["y"] = 7, ["x"] = 7, ["name"] = "default:cobble", ["z"] = 46, ["meta"] = {["inventory"] = {}, ["fields"] = {}}}, {["y"] = 7, ["x"] = 7, ["name"] = "default:cobble", ["z"] = 51, ["meta"] = {["inventory"] = {}, ["fields"] = {}}}, {["y"] = 7, ["x"] = 7, ["name"] = "default:cobble", ["z"] = 52, ["meta"] = {["inventory"] = {}, ["fields"] = {}}}, {["y"] = 7, ["x"] = 7, ["name"] = "default:cobble", ["z"] = 53, ["meta"] = {["inventory"] = {}, ["fields"] = {}}}, {["y"] = 8, ["x"] = 7, ["name"] = "default:cobble", ["z"] = 9, ["meta"] = {["inventory"] = {}, ["fields"] = {}}}, {["y"] = 8, ["x"] = 7, ["name"] = "default:cobble", ["z"] = 14, ["meta"] = {["inventory"] = {}, ["fields"] = {}}}, {["y"] = 8, ["x"] = 7, ["name"] = "default:cobble", ["z"] = 16, ["meta"] = {["inventory"] = {}, ["fields"] = {}}}, {["y"] = 8, ["x"] = 7, ["name"] = "default:cobble", ["z"] = 22, ["meta"] = {["inventory"] = {}, ["fields"] = {}}}, {["y"] = 8, ["x"] = 7, ["name"] = "default:cobble", ["z"] = 23, ["meta"] = {["inventory"] = {}, ["fields"] = {}}}, {["y"] = 8, ["x"] = 7, ["name"] = "default:cobble", ["z"] = 27, ["meta"] = {["inventory"] = {}, ["fields"] = {}}}, {["y"] = 8, ["x"] = 7, ["name"] = "default:cobble", ["z"] = 28, ["meta"] = {["inventory"] = {}, ["fields"] = {}}}, {["y"] = 8, ["x"] = 7, ["name"] = "default:cobble", ["z"] = 32, ["meta"] = {["inventory"] = {}, ["fields"] = {}}}, {["y"] = 8, ["x"] = 7, ["name"] = "default:torch", ["z"] = 37, ["meta"] = {["inventory"] = {}, ["fields"] = {}}, ["param2"] = 6, ["param1"] = 15}, {["y"] = 8, ["x"] = 7, ["name"] = "default:cobble", ["z"] = 38, ["meta"] = {["inventory"] = {}, ["fields"] = {}}}, {["y"] = 8, ["x"] = 7, ["name"] = "default:cobble", ["z"] = 40, ["meta"] = {["inventory"] = {}, ["fields"] = {}}}, {["y"] = 8, ["x"] = 7, ["name"] = "default:cobble", ["z"] = 44, ["meta"] = {["inventory"] = {}, ["fields"] = {}}}, {["y"] = 8, ["x"] = 7, ["name"] = "default:cobble", ["z"] = 46, ["meta"] = {["inventory"] = {}, ["fields"] = {}}}, {["y"] = 8, ["x"] = 7, ["name"] = "default:cobble", ["z"] = 51, ["meta"] = {["inventory"] = {}, ["fields"] = {}}}, {["y"] = 8, ["x"] = 7, ["name"] = "default:cobble", ["z"] = 52, ["meta"] = {["inventory"] = {}, ["fields"] = {}}}, {["y"] = 8, ["x"] = 7, ["name"] = "default:cobble", ["z"] = 53, ["meta"] = {["inventory"] = {}, ["fields"] = {}}}, {["y"] = 9, ["x"] = 7, ["name"] = "default:glass", ["z"] = 9, ["meta"] = {["inventory"] = {}, ["fields"] = {}}, ["param1"] = 175}, {["y"] = 9, ["x"] = 7, ["name"] = "default:glass", ["z"] = 10, ["meta"] = {["inventory"] = {}, ["fields"] = {}}, ["param1"] = 191}, {["y"] = 9, ["x"] = 7, ["name"] = "default:glass", ["z"] = 11, ["meta"] = {["inventory"] = {}, ["fields"] = {}}, ["param1"] = 175}, {["y"] = 9, ["x"] = 7, ["name"] = "default:glass", ["z"] = 12, ["meta"] = {["inventory"] = {}, ["fields"] = {}}, ["param1"] = 159}, {["y"] = 9, ["x"] = 7, ["name"] = "default:glass", ["z"] = 13, ["meta"] = {["inventory"] = {}, ["fields"] = {}}, ["param1"] = 159}, {["y"] = 9, ["x"] = 7, ["name"] = "default:glass", ["z"] = 14, ["meta"] = {["inventory"] = {}, ["fields"] = {}}, ["param1"] = 175}, {["y"] = 9, ["x"] = 7, ["name"] = "default:glass", ["z"] = 15, ["meta"] = {["inventory"] = {}, ["fields"] = {}}, ["param1"] = 191}, {["y"] = 9, ["x"] = 7, ["name"] = "default:glass", ["z"] = 16, ["meta"] = {["inventory"] = {}, ["fields"] = {}}, ["param1"] = 175}, {["y"] = 9, ["x"] = 7, ["name"] = "default:glass", ["z"] = 17, ["meta"] = {["inventory"] = {}, ["fields"] = {}}, ["param1"] = 159}, {["y"] = 9, ["x"] = 7, ["name"] = "default:glass", ["z"] = 18, ["meta"] = {["inventory"] = {}, ["fields"] = {}}, ["param1"] = 159}, {["y"] = 9, ["x"] = 7, ["name"] = "default:glass", ["z"] = 19, ["meta"] = {["inventory"] = {}, ["fields"] = {}}, ["param1"] = 175}, {["y"] = 9, ["x"] = 7, ["name"] = "default:glass", ["z"] = 20, ["meta"] = {["inventory"] = {}, ["fields"] = {}}, ["param1"] = 159}, {["y"] = 9, ["x"] = 7, ["name"] = "default:glass", ["z"] = 21, ["meta"] = {["inventory"] = {}, ["fields"] = {}}, ["param1"] = 159}, {["y"] = 9, ["x"] = 7, ["name"] = "default:glass", ["z"] = 22, ["meta"] = {["inventory"] = {}, ["fields"] = {}}, ["param1"] = 175}, {["y"] = 9, ["x"] = 7, ["name"] = "default:glass", ["z"] = 23, ["meta"] = {["inventory"] = {}, ["fields"] = {}}, ["param1"] = 191}, {["y"] = 9, ["x"] = 7, ["name"] = "default:glass", ["z"] = 24, ["meta"] = {["inventory"] = {}, ["fields"] = {}}, ["param1"] = 175}, {["y"] = 9, ["x"] = 7, ["name"] = "default:glass", ["z"] = 25, ["meta"] = {["inventory"] = {}, ["fields"] = {}}, ["param1"] = 159}, {["y"] = 9, ["x"] = 7, ["name"] = "default:glass", ["z"] = 26, ["meta"] = {["inventory"] = {}, ["fields"] = {}}, ["param1"] = 143}, {["y"] = 9, ["x"] = 7, ["name"] = "default:glass", ["z"] = 27, ["meta"] = {["inventory"] = {}, ["fields"] = {}}, ["param1"] = 159}, {["y"] = 9, ["x"] = 7, ["name"] = "default:glass", ["z"] = 28, ["meta"] = {["inventory"] = {}, ["fields"] = {}}, ["param1"] = 175}, {["y"] = 9, ["x"] = 7, ["name"] = "default:glass", ["z"] = 29, ["meta"] = {["inventory"] = {}, ["fields"] = {}}, ["param1"] = 159}, {["y"] = 9, ["x"] = 7, ["name"] = "default:glass", ["z"] = 30, ["meta"] = {["inventory"] = {}, ["fields"] = {}}, ["param1"] = 159}, {["y"] = 9, ["x"] = 7, ["name"] = "default:glass", ["z"] = 31, ["meta"] = {["inventory"] = {}, ["fields"] = {}}, ["param1"] = 175}, {["y"] = 9, ["x"] = 7, ["name"] = "default:glass", ["z"] = 32, ["meta"] = {["inventory"] = {}, ["fields"] = {}}, ["param1"] = 159}, {["y"] = 9, ["x"] = 7, ["name"] = "default:glass", ["z"] = 33, ["meta"] = {["inventory"] = {}, ["fields"] = {}}, ["param1"] = 175}, {["y"] = 9, ["x"] = 7, ["name"] = "default:glass", ["z"] = 34, ["meta"] = {["inventory"] = {}, ["fields"] = {}}, ["param1"] = 175}, {["y"] = 9, ["x"] = 7, ["name"] = "default:glass", ["z"] = 35, ["meta"] = {["inventory"] = {}, ["fields"] = {}}, ["param1"] = 175}, {["y"] = 9, ["x"] = 7, ["name"] = "default:glass", ["z"] = 36, ["meta"] = {["inventory"] = {}, ["fields"] = {}}, ["param1"] = 191}, {["y"] = 9, ["x"] = 7, ["name"] = "default:glass", ["z"] = 37, ["meta"] = {["inventory"] = {}, ["fields"] = {}}, ["param1"] = 207}, {["y"] = 9, ["x"] = 7, ["name"] = "default:glass", ["z"] = 38, ["meta"] = {["inventory"] = {}, ["fields"] = {}}, ["param1"] = 191}, {["y"] = 9, ["x"] = 7, ["name"] = "default:glass", ["z"] = 39, ["meta"] = {["inventory"] = {}, ["fields"] = {}}, ["param1"] = 175}, {["y"] = 9, ["x"] = 7, ["name"] = "default:glass", ["z"] = 40, ["meta"] = {["inventory"] = {}, ["fields"] = {}}, ["param1"] = 159}, {["y"] = 9, ["x"] = 7, ["name"] = "default:glass", ["z"] = 41, ["meta"] = {["inventory"] = {}, ["fields"] = {}}, ["param1"] = 143}, {["y"] = 9, ["x"] = 7, ["name"] = "default:glass", ["z"] = 42, ["meta"] = {["inventory"] = {}, ["fields"] = {}}, ["param1"] = 159}, {["y"] = 9, ["x"] = 7, ["name"] = "default:glass", ["z"] = 43, ["meta"] = {["inventory"] = {}, ["fields"] = {}}, ["param1"] = 175}, {["y"] = 9, ["x"] = 7, ["name"] = "default:glass", ["z"] = 44, ["meta"] = {["inventory"] = {}, ["fields"] = {}}, ["param1"] = 191}, {["y"] = 9, ["x"] = 7, ["name"] = "default:glass", ["z"] = 45, ["meta"] = {["inventory"] = {}, ["fields"] = {}}, ["param1"] = 175}, {["y"] = 9, ["x"] = 7, ["name"] = "default:glass", ["z"] = 46, ["meta"] = {["inventory"] = {}, ["fields"] = {}}, ["param1"] = 159}, {["y"] = 9, ["x"] = 7, ["name"] = "default:glass", ["z"] = 47, ["meta"] = {["inventory"] = {}, ["fields"] = {}}, ["param1"] = 143}, {["y"] = 9, ["x"] = 7, ["name"] = "default:glass", ["z"] = 48, ["meta"] = {["inventory"] = {}, ["fields"] = {}}, ["param1"] = 159}, {["y"] = 9, ["x"] = 7, ["name"] = "default:glass", ["z"] = 49, ["meta"] = {["inventory"] = {}, ["fields"] = {}}, ["param1"] = 175}, {["y"] = 9, ["x"] = 7, ["name"] = "default:glass", ["z"] = 50, ["meta"] = {["inventory"] = {}, ["fields"] = {}}, ["param1"] = 191}, {["y"] = 9, ["x"] = 7, ["name"] = "default:glass", ["z"] = 51, ["meta"] = {["inventory"] = {}, ["fields"] = {}}, ["param1"] = 175}, {["y"] = 9, ["x"] = 7, ["name"] = "default:glass", ["z"] = 52, ["meta"] = {["inventory"] = {}, ["fields"] = {}}, ["param1"] = 175}, {["y"] = 9, ["x"] = 7, ["name"] = "default:glass", ["z"] = 53, ["meta"] = {["inventory"] = {}, ["fields"] = {}}, ["param1"] = 159}, {["y"] = 3, ["x"] = 8, ["name"] = "default:glass", ["z"] = 9, ["meta"] = {["inventory"] = {}, ["fields"] = {}}, ["param1"] = 157}, {["y"] = 3, ["x"] = 8, ["name"] = "default:glass", ["z"] = 10, ["meta"] = {["inventory"] = {}, ["fields"] = {}}, ["param1"] = 175}, {["y"] = 3, ["x"] = 8, ["name"] = "default:glass", ["z"] = 11, ["meta"] = {["inventory"] = {}, ["fields"] = {}}, ["param1"] = 157}, {["y"] = 3, ["x"] = 8, ["name"] = "default:glass", ["z"] = 12, ["meta"] = {["inventory"] = {}, ["fields"] = {}}, ["param1"] = 141}, {["y"] = 3, ["x"] = 8, ["name"] = "default:glass", ["z"] = 13, ["meta"] = {["inventory"] = {}, ["fields"] = {}}, ["param1"] = 125}, {["y"] = 3, ["x"] = 8, ["name"] = "default:glass", ["z"] = 14, ["meta"] = {["inventory"] = {}, ["fields"] = {}}, ["param1"] = 141}, {["y"] = 3, ["x"] = 8, ["name"] = "default:glass", ["z"] = 15, ["meta"] = {["inventory"] = {}, ["fields"] = {}}, ["param1"] = 159}, {["y"] = 3, ["x"] = 8, ["name"] = "default:glass", ["z"] = 16, ["meta"] = {["inventory"] = {}, ["fields"] = {}}, ["param1"] = 173}, {["y"] = 3, ["x"] = 8, ["name"] = "default:glass", ["z"] = 17, ["meta"] = {["inventory"] = {}, ["fields"] = {}}, ["param1"] = 189}, {["y"] = 3, ["x"] = 8, ["name"] = "default:glass", ["z"] = 18, ["meta"] = {["inventory"] = {}, ["fields"] = {}}, ["param1"] = 173}, {["y"] = 3, ["x"] = 8, ["name"] = "default:glass", ["z"] = 19, ["meta"] = {["inventory"] = {}, ["fields"] = {}}, ["param1"] = 173}, {["y"] = 3, ["x"] = 8, ["name"] = "default:glass", ["z"] = 20, ["meta"] = {["inventory"] = {}, ["fields"] = {}}, ["param1"] = 189}, {["y"] = 3, ["x"] = 8, ["name"] = "default:glass", ["z"] = 21, ["meta"] = {["inventory"] = {}, ["fields"] = {}}, ["param1"] = 173}, {["y"] = 3, ["x"] = 8, ["name"] = "default:glass", ["z"] = 22, ["meta"] = {["inventory"] = {}, ["fields"] = {}}, ["param1"] = 159}, {["y"] = 3, ["x"] = 8, ["name"] = "default:glass", ["z"] = 23, ["meta"] = {["inventory"] = {}, ["fields"] = {}}, ["param1"] = 143}, {["y"] = 3, ["x"] = 8, ["name"] = "default:glass", ["z"] = 24, ["meta"] = {["inventory"] = {}, ["fields"] = {}}, ["param1"] = 127}, {["y"] = 3, ["x"] = 8, ["name"] = "default:glass", ["z"] = 25, ["meta"] = {["inventory"] = {}, ["fields"] = {}}, ["param1"] = 125}, {["y"] = 3, ["x"] = 8, ["name"] = "default:glass", ["z"] = 26, ["meta"] = {["inventory"] = {}, ["fields"] = {}}, ["param1"] = 141}, {["y"] = 3, ["x"] = 8, ["name"] = "default:glass", ["z"] = 27, ["meta"] = {["inventory"] = {}, ["fields"] = {}}, ["param1"] = 156}, {["y"] = 3, ["x"] = 8, ["name"] = "default:glass", ["z"] = 28, ["meta"] = {["inventory"] = {}, ["fields"] = {}}, ["param1"] = 173}, {["y"] = 3, ["x"] = 8, ["name"] = "default:glass", ["z"] = 29, ["meta"] = {["inventory"] = {}, ["fields"] = {}}, ["param1"] = 189}, {["y"] = 3, ["x"] = 8, ["name"] = "default:glass", ["z"] = 30, ["meta"] = {["inventory"] = {}, ["fields"] = {}}, ["param1"] = 205}, {["y"] = 3, ["x"] = 8, ["name"] = "default:glass", ["z"] = 31, ["meta"] = {["inventory"] = {}, ["fields"] = {}}, ["param1"] = 221}, {["y"] = 3, ["x"] = 8, ["name"] = "moreblocks:super_glow_glass", ["z"] = 32, ["meta"] = {["inventory"] = {}, ["fields"] = {}}}, {["y"] = 3, ["x"] = 8, ["name"] = "default:glass", ["z"] = 33, ["meta"] = {["inventory"] = {}, ["fields"] = {}}, ["param1"] = 221}, {["y"] = 3, ["x"] = 8, ["name"] = "default:glass", ["z"] = 34, ["meta"] = {["inventory"] = {}, ["fields"] = {}}, ["param1"] = 205}, {["y"] = 3, ["x"] = 8, ["name"] = "default:glass", ["z"] = 35, ["meta"] = {["inventory"] = {}, ["fields"] = {}}, ["param1"] = 188}, {["y"] = 3, ["x"] = 8, ["name"] = "default:glass", ["z"] = 36, ["meta"] = {["inventory"] = {}, ["fields"] = {}}, ["param1"] = 173}, {["y"] = 3, ["x"] = 8, ["name"] = "default:glass", ["z"] = 37, ["meta"] = {["inventory"] = {}, ["fields"] = {}}, ["param1"] = 159}, {["y"] = 3, ["x"] = 8, ["name"] = "default:glass", ["z"] = 38, ["meta"] = {["inventory"] = {}, ["fields"] = {}}, ["param1"] = 141}, {["y"] = 3, ["x"] = 8, ["name"] = "default:glass", ["z"] = 39, ["meta"] = {["inventory"] = {}, ["fields"] = {}}, ["param1"] = 127}, {["y"] = 3, ["x"] = 8, ["name"] = "default:glass", ["z"] = 40, ["meta"] = {["inventory"] = {}, ["fields"] = {}}, ["param1"] = 111}, {["y"] = 3, ["x"] = 8, ["name"] = "default:glass", ["z"] = 41, ["meta"] = {["inventory"] = {}, ["fields"] = {}}, ["param1"] = 109}, {["y"] = 3, ["x"] = 8, ["name"] = "default:glass", ["z"] = 42, ["meta"] = {["inventory"] = {}, ["fields"] = {}}, ["param1"] = 125}, {["y"] = 3, ["x"] = 8, ["name"] = "default:glass", ["z"] = 43, ["meta"] = {["inventory"] = {}, ["fields"] = {}}, ["param1"] = 141}, {["y"] = 3, ["x"] = 8, ["name"] = "default:glass", ["z"] = 44, ["meta"] = {["inventory"] = {}, ["fields"] = {}}, ["param1"] = 159}, {["y"] = 3, ["x"] = 8, ["name"] = "default:glass", ["z"] = 45, ["meta"] = {["inventory"] = {}, ["fields"] = {}}, ["param1"] = 141}, {["y"] = 3, ["x"] = 8, ["name"] = "default:glass", ["z"] = 46, ["meta"] = {["inventory"] = {}, ["fields"] = {}}, ["param1"] = 124}, {["y"] = 3, ["x"] = 8, ["name"] = "default:glass", ["z"] = 47, ["meta"] = {["inventory"] = {}, ["fields"] = {}}, ["param1"] = 109}, {["y"] = 3, ["x"] = 8, ["name"] = "default:glass", ["z"] = 48, ["meta"] = {["inventory"] = {}, ["fields"] = {}}, ["param1"] = 108}, {["y"] = 3, ["x"] = 8, ["name"] = "default:glass", ["z"] = 49, ["meta"] = {["inventory"] = {}, ["fields"] = {}}, ["param1"] = 125}, {["y"] = 3, ["x"] = 8, ["name"] = "default:glass", ["z"] = 50, ["meta"] = {["inventory"] = {}, ["fields"] = {}}, ["param1"] = 143}, {["y"] = 3, ["x"] = 8, ["name"] = "default:glass", ["z"] = 51, ["meta"] = {["inventory"] = {}, ["fields"] = {}}, ["param1"] = 125}, {["y"] = 3, ["x"] = 8, ["name"] = "default:glass", ["z"] = 52, ["meta"] = {["inventory"] = {}, ["fields"] = {}}, ["param1"] = 108}, {["y"] = 3, ["x"] = 8, ["name"] = "default:glass", ["z"] = 53, ["meta"] = {["inventory"] = {}, ["fields"] = {}}, ["param1"] = 93}, {["y"] = 4, ["x"] = 8, ["name"] = "default:cobble", ["z"] = 9, ["meta"] = {["inventory"] = {}, ["fields"] = {}}}, {["y"] = 4, ["x"] = 8, ["name"] = "default:cobble", ["z"] = 11, ["meta"] = {["inventory"] = {}, ["fields"] = {}}}, {["y"] = 4, ["x"] = 8, ["name"] = "default:cobble", ["z"] = 12, ["meta"] = {["inventory"] = {}, ["fields"] = {}}}, {["y"] = 4, ["x"] = 8, ["name"] = "default:cobble", ["z"] = 13, ["meta"] = {["inventory"] = {}, ["fields"] = {}}}, {["y"] = 4, ["x"] = 8, ["name"] = "default:cobble", ["z"] = 14, ["meta"] = {["inventory"] = {}, ["fields"] = {}}}, {["y"] = 4, ["x"] = 8, ["name"] = "default:ladder", ["z"] = 15, ["meta"] = {["inventory"] = {}, ["fields"] = {}}, ["param2"] = 4, ["param1"] = 159}, {["y"] = 4, ["x"] = 8, ["name"] = "default:cobble", ["z"] = 16, ["meta"] = {["inventory"] = {}, ["fields"] = {}}}, {["y"] = 4, ["x"] = 8, ["name"] = "default:cobble", ["z"] = 18, ["meta"] = {["inventory"] = {}, ["fields"] = {}}}, {["y"] = 4, ["x"] = 8, ["name"] = "default:cobble", ["z"] = 19, ["meta"] = {["inventory"] = {}, ["fields"] = {}}}, {["y"] = 4, ["x"] = 8, ["name"] = "default:cobble", ["z"] = 21, ["meta"] = {["inventory"] = {}, ["fields"] = {}}}, {["y"] = 4, ["x"] = 8, ["name"] = "default:ladder", ["z"] = 23, ["meta"] = {["inventory"] = {}, ["fields"] = {}}, ["param2"] = 2, ["param1"] = 159}, {["y"] = 4, ["x"] = 8, ["name"] = "default:cobble", ["z"] = 25, ["meta"] = {["inventory"] = {}, ["fields"] = {}}}, {["y"] = 4, ["x"] = 8, ["name"] = "default:cobble", ["z"] = 26, ["meta"] = {["inventory"] = {}, ["fields"] = {}}}, {["y"] = 4, ["x"] = 8, ["name"] = "default:cobble", ["z"] = 27, ["meta"] = {["inventory"] = {}, ["fields"] = {}}}, {["y"] = 4, ["x"] = 8, ["name"] = "default:cobble", ["z"] = 28, ["meta"] = {["inventory"] = {}, ["fields"] = {}}}, {["y"] = 4, ["x"] = 8, ["name"] = "default:cobble", ["z"] = 29, ["meta"] = {["inventory"] = {}, ["fields"] = {}}}, {["y"] = 4, ["x"] = 8, ["name"] = "default:cobble", ["z"] = 30, ["meta"] = {["inventory"] = {}, ["fields"] = {}}}, {["y"] = 4, ["x"] = 8, ["name"] = "default:cobble", ["z"] = 31, ["meta"] = {["inventory"] = {}, ["fields"] = {}}}, {["y"] = 4, ["x"] = 8, ["name"] = "default:cobble", ["z"] = 32, ["meta"] = {["inventory"] = {}, ["fields"] = {}}}, {["y"] = 4, ["x"] = 8, ["name"] = "default:cobble", ["z"] = 33, ["meta"] = {["inventory"] = {}, ["fields"] = {}}}, {["y"] = 4, ["x"] = 8, ["name"] = "default:cobble", ["z"] = 35, ["meta"] = {["inventory"] = {}, ["fields"] = {}}}, {["y"] = 4, ["x"] = 8, ["name"] = "default:cobble", ["z"] = 36, ["meta"] = {["inventory"] = {}, ["fields"] = {}}}, {["y"] = 4, ["x"] = 8, ["name"] = "default:cobble", ["z"] = 38, ["meta"] = {["inventory"] = {}, ["fields"] = {}}}, {["y"] = 4, ["x"] = 8, ["name"] = "default:cobble", ["z"] = 41, ["meta"] = {["inventory"] = {}, ["fields"] = {}}}, {["y"] = 4, ["x"] = 8, ["name"] = "default:cobble", ["z"] = 43, ["meta"] = {["inventory"] = {}, ["fields"] = {}}}, {["y"] = 4, ["x"] = 8, ["name"] = "default:ladder", ["z"] = 44, ["meta"] = {["inventory"] = {}, ["fields"] = {}}, ["param2"] = 4, ["param1"] = 159}, {["y"] = 4, ["x"] = 8, ["name"] = "default:cobble", ["z"] = 45, ["meta"] = {["inventory"] = {}, ["fields"] = {}}}, {["y"] = 4, ["x"] = 8, ["name"] = "default:cobble", ["z"] = 46, ["meta"] = {["inventory"] = {}, ["fields"] = {}}}, {["y"] = 4, ["x"] = 8, ["name"] = "default:cobble", ["z"] = 48, ["meta"] = {["inventory"] = {}, ["fields"] = {}}}, {["y"] = 4, ["x"] = 8, ["name"] = "default:cobble", ["z"] = 49, ["meta"] = {["inventory"] = {}, ["fields"] = {}}}, {["y"] = 4, ["x"] = 8, ["name"] = "default:ladder", ["z"] = 50, ["meta"] = {["inventory"] = {}, ["fields"] = {}}, ["param2"] = 4, ["param1"] = 159}, {["y"] = 4, ["x"] = 8, ["name"] = "default:cobble", ["z"] = 51, ["meta"] = {["inventory"] = {}, ["fields"] = {}}}, {["y"] = 4, ["x"] = 8, ["name"] = "default:cobble", ["z"] = 52, ["meta"] = {["inventory"] = {}, ["fields"] = {}}}, {["y"] = 4, ["x"] = 8, ["name"] = "default:cobble", ["z"] = 53, ["meta"] = {["inventory"] = {}, ["fields"] = {}}}, {["y"] = 5, ["x"] = 8, ["name"] = "default:cobble", ["z"] = 9, ["meta"] = {["inventory"] = {}, ["fields"] = {}}}, {["y"] = 5, ["x"] = 8, ["name"] = "default:cobble", ["z"] = 11, ["meta"] = {["inventory"] = {}, ["fields"] = {}}}, {["y"] = 5, ["x"] = 8, ["name"] = "default:cobble", ["z"] = 12, ["meta"] = {["inventory"] = {}, ["fields"] = {}}}, {["y"] = 5, ["x"] = 8, ["name"] = "default:cobble", ["z"] = 13, ["meta"] = {["inventory"] = {}, ["fields"] = {}}}, {["y"] = 5, ["x"] = 8, ["name"] = "default:cobble", ["z"] = 14, ["meta"] = {["inventory"] = {}, ["fields"] = {}}}, {["y"] = 5, ["x"] = 8, ["name"] = "default:ladder", ["z"] = 15, ["meta"] = {["inventory"] = {}, ["fields"] = {}}, ["param2"] = 4, ["param1"] = 175}, {["y"] = 5, ["x"] = 8, ["name"] = "default:cobble", ["z"] = 16, ["meta"] = {["inventory"] = {}, ["fields"] = {}}}, {["y"] = 5, ["x"] = 8, ["name"] = "default:torch", ["z"] = 17, ["meta"] = {["inventory"] = {}, ["fields"] = {}}, ["param2"] = 6}, {["y"] = 5, ["x"] = 8, ["name"] = "default:cobble", ["z"] = 18, ["meta"] = {["inventory"] = {}, ["fields"] = {}}}, {["y"] = 5, ["x"] = 8, ["name"] = "default:cobble", ["z"] = 19, ["meta"] = {["inventory"] = {}, ["fields"] = {}}}, {["y"] = 5, ["x"] = 8, ["name"] = "default:torch", ["z"] = 20, ["meta"] = {["inventory"] = {}, ["fields"] = {}}, ["param2"] = 6}, {["y"] = 5, ["x"] = 8, ["name"] = "default:cobble", ["z"] = 21, ["meta"] = {["inventory"] = {}, ["fields"] = {}}}, {["y"] = 5, ["x"] = 8, ["name"] = "default:ladder", ["z"] = 23, ["meta"] = {["inventory"] = {}, ["fields"] = {}}, ["param2"] = 2, ["param1"] = 175}, {["y"] = 5, ["x"] = 8, ["name"] = "default:cobble", ["z"] = 25, ["meta"] = {["inventory"] = {}, ["fields"] = {}}}, {["y"] = 5, ["x"] = 8, ["name"] = "default:cobble", ["z"] = 26, ["meta"] = {["inventory"] = {}, ["fields"] = {}}}, {["y"] = 5, ["x"] = 8, ["name"] = "default:cobble", ["z"] = 27, ["meta"] = {["inventory"] = {}, ["fields"] = {}}}, {["y"] = 5, ["x"] = 8, ["name"] = "default:cobble", ["z"] = 28, ["meta"] = {["inventory"] = {}, ["fields"] = {}}}, {["y"] = 5, ["x"] = 8, ["name"] = "default:cobble", ["z"] = 29, ["meta"] = {["inventory"] = {}, ["fields"] = {}}}, {["y"] = 5, ["x"] = 8, ["name"] = "default:cobble", ["z"] = 30, ["meta"] = {["inventory"] = {}, ["fields"] = {}}}, {["y"] = 5, ["x"] = 8, ["name"] = "default:cobble", ["z"] = 31, ["meta"] = {["inventory"] = {}, ["fields"] = {}}}, {["y"] = 5, ["x"] = 8, ["name"] = "default:cobble", ["z"] = 32, ["meta"] = {["inventory"] = {}, ["fields"] = {}}}, {["y"] = 5, ["x"] = 8, ["name"] = "default:cobble", ["z"] = 33, ["meta"] = {["inventory"] = {}, ["fields"] = {}}}, {["y"] = 5, ["x"] = 8, ["name"] = "default:cobble", ["z"] = 35, ["meta"] = {["inventory"] = {}, ["fields"] = {}}}, {["y"] = 5, ["x"] = 8, ["name"] = "default:cobble", ["z"] = 36, ["meta"] = {["inventory"] = {}, ["fields"] = {}}}, {["y"] = 5, ["x"] = 8, ["name"] = "default:cobble", ["z"] = 38, ["meta"] = {["inventory"] = {}, ["fields"] = {}}}, {["y"] = 5, ["x"] = 8, ["name"] = "default:cobble", ["z"] = 41, ["meta"] = {["inventory"] = {}, ["fields"] = {}}}, {["y"] = 5, ["x"] = 8, ["name"] = "default:cobble", ["z"] = 43, ["meta"] = {["inventory"] = {}, ["fields"] = {}}}, {["y"] = 5, ["x"] = 8, ["name"] = "default:ladder", ["z"] = 44, ["meta"] = {["inventory"] = {}, ["fields"] = {}}, ["param2"] = 4, ["param1"] = 175}, {["y"] = 5, ["x"] = 8, ["name"] = "default:cobble", ["z"] = 45, ["meta"] = {["inventory"] = {}, ["fields"] = {}}}, {["y"] = 5, ["x"] = 8, ["name"] = "default:cobble", ["z"] = 46, ["meta"] = {["inventory"] = {}, ["fields"] = {}}}, {["y"] = 5, ["x"] = 8, ["name"] = "default:cobble", ["z"] = 48, ["meta"] = {["inventory"] = {}, ["fields"] = {}}}, {["y"] = 5, ["x"] = 8, ["name"] = "default:cobble", ["z"] = 49, ["meta"] = {["inventory"] = {}, ["fields"] = {}}}, {["y"] = 5, ["x"] = 8, ["name"] = "default:ladder", ["z"] = 50, ["meta"] = {["inventory"] = {}, ["fields"] = {}}, ["param2"] = 4, ["param1"] = 175}, {["y"] = 5, ["x"] = 8, ["name"] = "default:cobble", ["z"] = 51, ["meta"] = {["inventory"] = {}, ["fields"] = {}}}, {["y"] = 5, ["x"] = 8, ["name"] = "default:cobble", ["z"] = 52, ["meta"] = {["inventory"] = {}, ["fields"] = {}}}, {["y"] = 5, ["x"] = 8, ["name"] = "default:cobble", ["z"] = 53, ["meta"] = {["inventory"] = {}, ["fields"] = {}}}, {["y"] = 6, ["x"] = 8, ["name"] = "default:glass", ["z"] = 9, ["meta"] = {["inventory"] = {}, ["fields"] = {}}, ["param1"] = 173}, {["y"] = 6, ["x"] = 8, ["name"] = "default:glass", ["z"] = 10, ["meta"] = {["inventory"] = {}, ["fields"] = {}}, ["param1"] = 191}, {["y"] = 6, ["x"] = 8, ["name"] = "default:glass", ["z"] = 11, ["meta"] = {["inventory"] = {}, ["fields"] = {}}, ["param1"] = 173}, {["y"] = 6, ["x"] = 8, ["name"] = "default:glass", ["z"] = 12, ["meta"] = {["inventory"] = {}, ["fields"] = {}}, ["param1"] = 157}, {["y"] = 6, ["x"] = 8, ["name"] = "default:glass", ["z"] = 13, ["meta"] = {["inventory"] = {}, ["fields"] = {}}, ["param1"] = 159}, {["y"] = 6, ["x"] = 8, ["name"] = "default:glass", ["z"] = 14, ["meta"] = {["inventory"] = {}, ["fields"] = {}}, ["param1"] = 173}, {["y"] = 6, ["x"] = 8, ["name"] = "default:ladder", ["z"] = 15, ["meta"] = {["inventory"] = {}, ["fields"] = {}}, ["param2"] = 4, ["param1"] = 191}, {["y"] = 6, ["x"] = 8, ["name"] = "default:glass", ["z"] = 16, ["meta"] = {["inventory"] = {}, ["fields"] = {}}, ["param1"] = 189}, {["y"] = 6, ["x"] = 8, ["name"] = "default:glass", ["z"] = 17, ["meta"] = {["inventory"] = {}, ["fields"] = {}}, ["param1"] = 205}, {["y"] = 6, ["x"] = 8, ["name"] = "default:glass", ["z"] = 18, ["meta"] = {["inventory"] = {}, ["fields"] = {}}, ["param1"] = 189}, {["y"] = 6, ["x"] = 8, ["name"] = "default:glass", ["z"] = 19, ["meta"] = {["inventory"] = {}, ["fields"] = {}}, ["param1"] = 189}, {["y"] = 6, ["x"] = 8, ["name"] = "default:glass", ["z"] = 20, ["meta"] = {["inventory"] = {}, ["fields"] = {}}, ["param1"] = 205}, {["y"] = 6, ["x"] = 8, ["name"] = "default:glass", ["z"] = 21, ["meta"] = {["inventory"] = {}, ["fields"] = {}}, ["param1"] = 191}, {["y"] = 6, ["x"] = 8, ["name"] = "default:glass", ["z"] = 22, ["meta"] = {["inventory"] = {}, ["fields"] = {}}, ["param1"] = 175}, {["y"] = 6, ["x"] = 8, ["name"] = "default:ladder", ["z"] = 23, ["meta"] = {["inventory"] = {}, ["fields"] = {}}, ["param2"] = 2, ["param1"] = 191}, {["y"] = 6, ["x"] = 8, ["name"] = "default:glass", ["z"] = 24, ["meta"] = {["inventory"] = {}, ["fields"] = {}}, ["param1"] = 175}, {["y"] = 6, ["x"] = 8, ["name"] = "default:glass", ["z"] = 25, ["meta"] = {["inventory"] = {}, ["fields"] = {}}, ["param1"] = 157}, {["y"] = 6, ["x"] = 8, ["name"] = "default:glass", ["z"] = 26, ["meta"] = {["inventory"] = {}, ["fields"] = {}}, ["param1"] = 143}, {["y"] = 6, ["x"] = 8, ["name"] = "default:glass", ["z"] = 27, ["meta"] = {["inventory"] = {}, ["fields"] = {}}, ["param1"] = 157}, {["y"] = 6, ["x"] = 8, ["name"] = "default:glass", ["z"] = 28, ["meta"] = {["inventory"] = {}, ["fields"] = {}}, ["param1"] = 175}, {["y"] = 6, ["x"] = 8, ["name"] = "default:glass", ["z"] = 29, ["meta"] = {["inventory"] = {}, ["fields"] = {}}, ["param1"] = 191}, {["y"] = 6, ["x"] = 8, ["name"] = "default:glass", ["z"] = 30, ["meta"] = {["inventory"] = {}, ["fields"] = {}}, ["param1"] = 205}, {["y"] = 6, ["x"] = 8, ["name"] = "default:glass", ["z"] = 31, ["meta"] = {["inventory"] = {}, ["fields"] = {}}, ["param1"] = 221}, {["y"] = 6, ["x"] = 8, ["name"] = "moreblocks:super_glow_glass", ["z"] = 32, ["meta"] = {["inventory"] = {}, ["fields"] = {}}}, {["y"] = 6, ["x"] = 8, ["name"] = "default:glass", ["z"] = 33, ["meta"] = {["inventory"] = {}, ["fields"] = {}}, ["param1"] = 221}, {["y"] = 6, ["x"] = 8, ["name"] = "default:glass", ["z"] = 34, ["meta"] = {["inventory"] = {}, ["fields"] = {}}, ["param1"] = 205}, {["y"] = 6, ["x"] = 8, ["name"] = "default:glass", ["z"] = 35, ["meta"] = {["inventory"] = {}, ["fields"] = {}}, ["param1"] = 189}, {["y"] = 6, ["x"] = 8, ["name"] = "default:glass", ["z"] = 36, ["meta"] = {["inventory"] = {}, ["fields"] = {}}, ["param1"] = 173}, {["y"] = 6, ["x"] = 8, ["name"] = "default:glass", ["z"] = 37, ["meta"] = {["inventory"] = {}, ["fields"] = {}}, ["param1"] = 175}, {["y"] = 6, ["x"] = 8, ["name"] = "default:glass", ["z"] = 38, ["meta"] = {["inventory"] = {}, ["fields"] = {}}, ["param1"] = 159}, {["y"] = 6, ["x"] = 8, ["name"] = "default:glass", ["z"] = 39, ["meta"] = {["inventory"] = {}, ["fields"] = {}}, ["param1"] = 143}, {["y"] = 6, ["x"] = 8, ["name"] = "default:glass", ["z"] = 40, ["meta"] = {["inventory"] = {}, ["fields"] = {}}, ["param1"] = 143}, {["y"] = 6, ["x"] = 8, ["name"] = "default:glass", ["z"] = 41, ["meta"] = {["inventory"] = {}, ["fields"] = {}}, ["param1"] = 143}, {["y"] = 6, ["x"] = 8, ["name"] = "default:glass", ["z"] = 42, ["meta"] = {["inventory"] = {}, ["fields"] = {}}, ["param1"] = 157}, {["y"] = 6, ["x"] = 8, ["name"] = "default:glass", ["z"] = 43, ["meta"] = {["inventory"] = {}, ["fields"] = {}}, ["param1"] = 175}, {["y"] = 6, ["x"] = 8, ["name"] = "default:ladder", ["z"] = 44, ["meta"] = {["inventory"] = {}, ["fields"] = {}}, ["param2"] = 4, ["param1"] = 191}, {["y"] = 6, ["x"] = 8, ["name"] = "default:glass", ["z"] = 45, ["meta"] = {["inventory"] = {}, ["fields"] = {}}, ["param1"] = 175}, {["y"] = 6, ["x"] = 8, ["name"] = "default:glass", ["z"] = 46, ["meta"] = {["inventory"] = {}, ["fields"] = {}}, ["param1"] = 157}, {["y"] = 6, ["x"] = 8, ["name"] = "default:glass", ["z"] = 47, ["meta"] = {["inventory"] = {}, ["fields"] = {}}, ["param1"] = 141}, {["y"] = 6, ["x"] = 8, ["name"] = "default:glass", ["z"] = 48, ["meta"] = {["inventory"] = {}, ["fields"] = {}}, ["param1"] = 159}, {["y"] = 6, ["x"] = 8, ["name"] = "default:glass", ["z"] = 49, ["meta"] = {["inventory"] = {}, ["fields"] = {}}, ["param1"] = 173}, {["y"] = 6, ["x"] = 8, ["name"] = "default:ladder", ["z"] = 50, ["meta"] = {["inventory"] = {}, ["fields"] = {}}, ["param2"] = 4, ["param1"] = 191}, {["y"] = 6, ["x"] = 8, ["name"] = "default:glass", ["z"] = 51, ["meta"] = {["inventory"] = {}, ["fields"] = {}}, ["param1"] = 175}, {["y"] = 6, ["x"] = 8, ["name"] = "default:glass", ["z"] = 52, ["meta"] = {["inventory"] = {}, ["fields"] = {}}, ["param1"] = 173}, {["y"] = 6, ["x"] = 8, ["name"] = "default:glass", ["z"] = 53, ["meta"] = {["inventory"] = {}, ["fields"] = {}}, ["param1"] = 157}, {["y"] = 7, ["x"] = 8, ["name"] = "default:cobble", ["z"] = 9, ["meta"] = {["inventory"] = {}, ["fields"] = {}}}, {["y"] = 7, ["x"] = 8, ["name"] = "default:cobble", ["z"] = 11, ["meta"] = {["inventory"] = {}, ["fields"] = {}}}, {["y"] = 7, ["x"] = 8, ["name"] = "default:cobble", ["z"] = 12, ["meta"] = {["inventory"] = {}, ["fields"] = {}}}, {["y"] = 7, ["x"] = 8, ["name"] = "default:cobble", ["z"] = 14, ["meta"] = {["inventory"] = {}, ["fields"] = {}}}, {["y"] = 7, ["x"] = 8, ["name"] = "default:cobble", ["z"] = 16, ["meta"] = {["inventory"] = {}, ["fields"] = {}}}, {["y"] = 7, ["x"] = 8, ["name"] = "default:cobble", ["z"] = 17, ["meta"] = {["inventory"] = {}, ["fields"] = {}}}, {["y"] = 7, ["x"] = 8, ["name"] = "default:cobble", ["z"] = 18, ["meta"] = {["inventory"] = {}, ["fields"] = {}}}, {["y"] = 7, ["x"] = 8, ["name"] = "default:cobble", ["z"] = 19, ["meta"] = {["inventory"] = {}, ["fields"] = {}}}, {["y"] = 7, ["x"] = 8, ["name"] = "default:cobble", ["z"] = 20, ["meta"] = {["inventory"] = {}, ["fields"] = {}}}, {["y"] = 7, ["x"] = 8, ["name"] = "default:cobble", ["z"] = 25, ["meta"] = {["inventory"] = {}, ["fields"] = {}}}, {["y"] = 7, ["x"] = 8, ["name"] = "default:cobble", ["z"] = 27, ["meta"] = {["inventory"] = {}, ["fields"] = {}}}, {["y"] = 7, ["x"] = 8, ["name"] = "default:cobble", ["z"] = 30, ["meta"] = {["inventory"] = {}, ["fields"] = {}}}, {["y"] = 7, ["x"] = 8, ["name"] = "default:cobble", ["z"] = 31, ["meta"] = {["inventory"] = {}, ["fields"] = {}}}, {["y"] = 7, ["x"] = 8, ["name"] = "default:cobble", ["z"] = 32, ["meta"] = {["inventory"] = {}, ["fields"] = {}}}, {["y"] = 7, ["x"] = 8, ["name"] = "default:cobble", ["z"] = 33, ["meta"] = {["inventory"] = {}, ["fields"] = {}}}, {["y"] = 7, ["x"] = 8, ["name"] = "default:cobble", ["z"] = 34, ["meta"] = {["inventory"] = {}, ["fields"] = {}}}, {["y"] = 7, ["x"] = 8, ["name"] = "default:cobble", ["z"] = 35, ["meta"] = {["inventory"] = {}, ["fields"] = {}}}, {["y"] = 7, ["x"] = 8, ["name"] = "default:cobble", ["z"] = 36, ["meta"] = {["inventory"] = {}, ["fields"] = {}}}, {["y"] = 7, ["x"] = 8, ["name"] = "default:cobble", ["z"] = 42, ["meta"] = {["inventory"] = {}, ["fields"] = {}}}, {["y"] = 7, ["x"] = 8, ["name"] = "default:cobble", ["z"] = 46, ["meta"] = {["inventory"] = {}, ["fields"] = {}}}, {["y"] = 7, ["x"] = 8, ["name"] = "default:cobble", ["z"] = 47, ["meta"] = {["inventory"] = {}, ["fields"] = {}}}, {["y"] = 7, ["x"] = 8, ["name"] = "default:cobble", ["z"] = 49, ["meta"] = {["inventory"] = {}, ["fields"] = {}}}, {["y"] = 7, ["x"] = 8, ["name"] = "default:cobble", ["z"] = 52, ["meta"] = {["inventory"] = {}, ["fields"] = {}}}, {["y"] = 7, ["x"] = 8, ["name"] = "default:cobble", ["z"] = 53, ["meta"] = {["inventory"] = {}, ["fields"] = {}}}, {["y"] = 8, ["x"] = 8, ["name"] = "default:cobble", ["z"] = 9, ["meta"] = {["inventory"] = {}, ["fields"] = {}}}, {["y"] = 8, ["x"] = 8, ["name"] = "default:torch", ["z"] = 10, ["meta"] = {["inventory"] = {}, ["fields"] = {}}, ["param2"] = 6, ["param1"] = 15}, {["y"] = 8, ["x"] = 8, ["name"] = "default:cobble", ["z"] = 11, ["meta"] = {["inventory"] = {}, ["fields"] = {}}}, {["y"] = 8, ["x"] = 8, ["name"] = "default:cobble", ["z"] = 12, ["meta"] = {["inventory"] = {}, ["fields"] = {}}}, {["y"] = 8, ["x"] = 8, ["name"] = "default:cobble", ["z"] = 14, ["meta"] = {["inventory"] = {}, ["fields"] = {}}}, {["y"] = 8, ["x"] = 8, ["name"] = "default:torch", ["z"] = 15, ["meta"] = {["inventory"] = {}, ["fields"] = {}}, ["param2"] = 4, ["param1"] = 15}, {["y"] = 8, ["x"] = 8, ["name"] = "default:cobble", ["z"] = 16, ["meta"] = {["inventory"] = {}, ["fields"] = {}}}, {["y"] = 8, ["x"] = 8, ["name"] = "default:cobble", ["z"] = 17, ["meta"] = {["inventory"] = {}, ["fields"] = {}}}, {["y"] = 8, ["x"] = 8, ["name"] = "default:cobble", ["z"] = 18, ["meta"] = {["inventory"] = {}, ["fields"] = {}}}, {["y"] = 8, ["x"] = 8, ["name"] = "default:cobble", ["z"] = 19, ["meta"] = {["inventory"] = {}, ["fields"] = {}}}, {["y"] = 8, ["x"] = 8, ["name"] = "default:cobble", ["z"] = 20, ["meta"] = {["inventory"] = {}, ["fields"] = {}}}, {["y"] = 8, ["x"] = 8, ["name"] = "default:torch", ["z"] = 23, ["meta"] = {["inventory"] = {}, ["fields"] = {}}, ["param2"] = 2, ["param1"] = 15}, {["y"] = 8, ["x"] = 8, ["name"] = "default:cobble", ["z"] = 25, ["meta"] = {["inventory"] = {}, ["fields"] = {}}}, {["y"] = 8, ["x"] = 8, ["name"] = "default:cobble", ["z"] = 27, ["meta"] = {["inventory"] = {}, ["fields"] = {}}}, {["y"] = 8, ["x"] = 8, ["name"] = "default:cobble", ["z"] = 30, ["meta"] = {["inventory"] = {}, ["fields"] = {}}}, {["y"] = 8, ["x"] = 8, ["name"] = "default:cobble", ["z"] = 31, ["meta"] = {["inventory"] = {}, ["fields"] = {}}}, {["y"] = 8, ["x"] = 8, ["name"] = "default:cobble", ["z"] = 32, ["meta"] = {["inventory"] = {}, ["fields"] = {}}}, {["y"] = 8, ["x"] = 8, ["name"] = "default:cobble", ["z"] = 33, ["meta"] = {["inventory"] = {}, ["fields"] = {}}}, {["y"] = 8, ["x"] = 8, ["name"] = "default:cobble", ["z"] = 34, ["meta"] = {["inventory"] = {}, ["fields"] = {}}}, {["y"] = 8, ["x"] = 8, ["name"] = "default:cobble", ["z"] = 35, ["meta"] = {["inventory"] = {}, ["fields"] = {}}}, {["y"] = 8, ["x"] = 8, ["name"] = "default:cobble", ["z"] = 36, ["meta"] = {["inventory"] = {}, ["fields"] = {}}}, {["y"] = 8, ["x"] = 8, ["name"] = "default:cobble", ["z"] = 42, ["meta"] = {["inventory"] = {}, ["fields"] = {}}}, {["y"] = 8, ["x"] = 8, ["name"] = "default:torch", ["z"] = 44, ["meta"] = {["inventory"] = {}, ["fields"] = {}}, ["param2"] = 2, ["param1"] = 15}, {["y"] = 8, ["x"] = 8, ["name"] = "default:cobble", ["z"] = 46, ["meta"] = {["inventory"] = {}, ["fields"] = {}}}, {["y"] = 8, ["x"] = 8, ["name"] = "default:cobble", ["z"] = 47, ["meta"] = {["inventory"] = {}, ["fields"] = {}}}, {["y"] = 8, ["x"] = 8, ["name"] = "default:cobble", ["z"] = 49, ["meta"] = {["inventory"] = {}, ["fields"] = {}}}, {["y"] = 8, ["x"] = 8, ["name"] = "default:torch", ["z"] = 50, ["meta"] = {["inventory"] = {}, ["fields"] = {}}, ["param2"] = 5, ["param1"] = 15}, {["y"] = 8, ["x"] = 8, ["name"] = "default:cobble", ["z"] = 52, ["meta"] = {["inventory"] = {}, ["fields"] = {}}}, {["y"] = 8, ["x"] = 8, ["name"] = "default:cobble", ["z"] = 53, ["meta"] = {["inventory"] = {}, ["fields"] = {}}}, {["y"] = 9, ["x"] = 8, ["name"] = "default:glass", ["z"] = 9, ["meta"] = {["inventory"] = {}, ["fields"] = {}}, ["param1"] = 191}, {["y"] = 9, ["x"] = 8, ["name"] = "default:glass", ["z"] = 10, ["meta"] = {["inventory"] = {}, ["fields"] = {}}, ["param1"] = 207}, {["y"] = 9, ["x"] = 8, ["name"] = "default:glass", ["z"] = 11, ["meta"] = {["inventory"] = {}, ["fields"] = {}}, ["param1"] = 191}, {["y"] = 9, ["x"] = 8, ["name"] = "default:glass", ["z"] = 12, ["meta"] = {["inventory"] = {}, ["fields"] = {}}, ["param1"] = 175}, {["y"] = 9, ["x"] = 8, ["name"] = "default:glass", ["z"] = 13, ["meta"] = {["inventory"] = {}, ["fields"] = {}}, ["param1"] = 175}, {["y"] = 9, ["x"] = 8, ["name"] = "default:glass", ["z"] = 14, ["meta"] = {["inventory"] = {}, ["fields"] = {}}, ["param1"] = 191}, {["y"] = 9, ["x"] = 8, ["name"] = "default:glass", ["z"] = 15, ["meta"] = {["inventory"] = {}, ["fields"] = {}}, ["param1"] = 207}, {["y"] = 9, ["x"] = 8, ["name"] = "default:glass", ["z"] = 16, ["meta"] = {["inventory"] = {}, ["fields"] = {}}, ["param1"] = 191}, {["y"] = 9, ["x"] = 8, ["name"] = "default:glass", ["z"] = 17, ["meta"] = {["inventory"] = {}, ["fields"] = {}}, ["param1"] = 175}, {["y"] = 9, ["x"] = 8, ["name"] = "default:glass", ["z"] = 18, ["meta"] = {["inventory"] = {}, ["fields"] = {}}, ["param1"] = 175}, {["y"] = 9, ["x"] = 8, ["name"] = "default:glass", ["z"] = 19, ["meta"] = {["inventory"] = {}, ["fields"] = {}}, ["param1"] = 191}, {["y"] = 9, ["x"] = 8, ["name"] = "default:glass", ["z"] = 20, ["meta"] = {["inventory"] = {}, ["fields"] = {}}, ["param1"] = 175}, {["y"] = 9, ["x"] = 8, ["name"] = "default:glass", ["z"] = 21, ["meta"] = {["inventory"] = {}, ["fields"] = {}}, ["param1"] = 175}, {["y"] = 9, ["x"] = 8, ["name"] = "default:glass", ["z"] = 22, ["meta"] = {["inventory"] = {}, ["fields"] = {}}, ["param1"] = 191}, {["y"] = 9, ["x"] = 8, ["name"] = "default:glass", ["z"] = 23, ["meta"] = {["inventory"] = {}, ["fields"] = {}}, ["param1"] = 207}, {["y"] = 9, ["x"] = 8, ["name"] = "default:glass", ["z"] = 24, ["meta"] = {["inventory"] = {}, ["fields"] = {}}, ["param1"] = 191}, {["y"] = 9, ["x"] = 8, ["name"] = "default:glass", ["z"] = 25, ["meta"] = {["inventory"] = {}, ["fields"] = {}}, ["param1"] = 175}, {["y"] = 9, ["x"] = 8, ["name"] = "default:glass", ["z"] = 26, ["meta"] = {["inventory"] = {}, ["fields"] = {}}, ["param1"] = 159}, {["y"] = 9, ["x"] = 8, ["name"] = "default:glass", ["z"] = 27, ["meta"] = {["inventory"] = {}, ["fields"] = {}}, ["param1"] = 175}, {["y"] = 9, ["x"] = 8, ["name"] = "default:glass", ["z"] = 28, ["meta"] = {["inventory"] = {}, ["fields"] = {}}, ["param1"] = 191}, {["y"] = 9, ["x"] = 8, ["name"] = "default:glass", ["z"] = 29, ["meta"] = {["inventory"] = {}, ["fields"] = {}}, ["param1"] = 175}, {["y"] = 9, ["x"] = 8, ["name"] = "default:glass", ["z"] = 30, ["meta"] = {["inventory"] = {}, ["fields"] = {}}, ["param1"] = 175}, {["y"] = 9, ["x"] = 8, ["name"] = "default:glass", ["z"] = 31, ["meta"] = {["inventory"] = {}, ["fields"] = {}}, ["param1"] = 191}, {["y"] = 9, ["x"] = 8, ["name"] = "default:glass", ["z"] = 32, ["meta"] = {["inventory"] = {}, ["fields"] = {}}, ["param1"] = 175}, {["y"] = 9, ["x"] = 8, ["name"] = "default:glass", ["z"] = 33, ["meta"] = {["inventory"] = {}, ["fields"] = {}}, ["param1"] = 175}, {["y"] = 9, ["x"] = 8, ["name"] = "default:glass", ["z"] = 34, ["meta"] = {["inventory"] = {}, ["fields"] = {}}, ["param1"] = 191}, {["y"] = 9, ["x"] = 8, ["name"] = "default:glass", ["z"] = 35, ["meta"] = {["inventory"] = {}, ["fields"] = {}}, ["param1"] = 175}, {["y"] = 9, ["x"] = 8, ["name"] = "default:glass", ["z"] = 36, ["meta"] = {["inventory"] = {}, ["fields"] = {}}, ["param1"] = 175}, {["y"] = 9, ["x"] = 8, ["name"] = "default:glass", ["z"] = 37, ["meta"] = {["inventory"] = {}, ["fields"] = {}}, ["param1"] = 191}, {["y"] = 9, ["x"] = 8, ["name"] = "default:glass", ["z"] = 38, ["meta"] = {["inventory"] = {}, ["fields"] = {}}, ["param1"] = 175}, {["y"] = 9, ["x"] = 8, ["name"] = "default:glass", ["z"] = 39, ["meta"] = {["inventory"] = {}, ["fields"] = {}}, ["param1"] = 159}, {["y"] = 9, ["x"] = 8, ["name"] = "default:glass", ["z"] = 40, ["meta"] = {["inventory"] = {}, ["fields"] = {}}, ["param1"] = 159}, {["y"] = 9, ["x"] = 8, ["name"] = "default:glass", ["z"] = 41, ["meta"] = {["inventory"] = {}, ["fields"] = {}}, ["param1"] = 159}, {["y"] = 9, ["x"] = 8, ["name"] = "default:glass", ["z"] = 42, ["meta"] = {["inventory"] = {}, ["fields"] = {}}, ["param1"] = 175}, {["y"] = 9, ["x"] = 8, ["name"] = "default:glass", ["z"] = 43, ["meta"] = {["inventory"] = {}, ["fields"] = {}}, ["param1"] = 191}, {["y"] = 9, ["x"] = 8, ["name"] = "default:glass", ["z"] = 44, ["meta"] = {["inventory"] = {}, ["fields"] = {}}, ["param1"] = 207}, {["y"] = 9, ["x"] = 8, ["name"] = "default:glass", ["z"] = 45, ["meta"] = {["inventory"] = {}, ["fields"] = {}}, ["param1"] = 191}, {["y"] = 9, ["x"] = 8, ["name"] = "default:glass", ["z"] = 46, ["meta"] = {["inventory"] = {}, ["fields"] = {}}, ["param1"] = 175}, {["y"] = 9, ["x"] = 8, ["name"] = "default:glass", ["z"] = 47, ["meta"] = {["inventory"] = {}, ["fields"] = {}}, ["param1"] = 159}, {["y"] = 9, ["x"] = 8, ["name"] = "default:glass", ["z"] = 48, ["meta"] = {["inventory"] = {}, ["fields"] = {}}, ["param1"] = 175}, {["y"] = 9, ["x"] = 8, ["name"] = "default:glass", ["z"] = 49, ["meta"] = {["inventory"] = {}, ["fields"] = {}}, ["param1"] = 191}, {["y"] = 9, ["x"] = 8, ["name"] = "default:glass", ["z"] = 50, ["meta"] = {["inventory"] = {}, ["fields"] = {}}, ["param1"] = 207}, {["y"] = 9, ["x"] = 8, ["name"] = "default:glass", ["z"] = 51, ["meta"] = {["inventory"] = {}, ["fields"] = {}}, ["param1"] = 191}, {["y"] = 9, ["x"] = 8, ["name"] = "default:glass", ["z"] = 52, ["meta"] = {["inventory"] = {}, ["fields"] = {}}, ["param1"] = 191}, {["y"] = 9, ["x"] = 8, ["name"] = "default:glass", ["z"] = 53, ["meta"] = {["inventory"] = {}, ["fields"] = {}}, ["param1"] = 175}, {["y"] = 3, ["x"] = 9, ["name"] = "default:glass", ["z"] = 9, ["meta"] = {["inventory"] = {}, ["fields"] = {}}, ["param1"] = 141}, {["y"] = 3, ["x"] = 9, ["name"] = "default:glass", ["z"] = 10, ["meta"] = {["inventory"] = {}, ["fields"] = {}}, ["param1"] = 159}, {["y"] = 3, ["x"] = 9, ["name"] = "default:glass", ["z"] = 11, ["meta"] = {["inventory"] = {}, ["fields"] = {}}, ["param1"] = 141}, {["y"] = 3, ["x"] = 9, ["name"] = "default:glass", ["z"] = 12, ["meta"] = {["inventory"] = {}, ["fields"] = {}}, ["param1"] = 125}, {["y"] = 3, ["x"] = 9, ["name"] = "default:glass", ["z"] = 13, ["meta"] = {["inventory"] = {}, ["fields"] = {}}, ["param1"] = 111}, {["y"] = 3, ["x"] = 9, ["name"] = "default:glass", ["z"] = 14, ["meta"] = {["inventory"] = {}, ["fields"] = {}}, ["param1"] = 125}, {["y"] = 3, ["x"] = 9, ["name"] = "default:glass", ["z"] = 15, ["meta"] = {["inventory"] = {}, ["fields"] = {}}, ["param1"] = 141}, {["y"] = 3, ["x"] = 9, ["name"] = "default:glass", ["z"] = 16, ["meta"] = {["inventory"] = {}, ["fields"] = {}}, ["param1"] = 156}, {["y"] = 3, ["x"] = 9, ["name"] = "default:glass", ["z"] = 17, ["meta"] = {["inventory"] = {}, ["fields"] = {}}, ["param1"] = 173}, {["y"] = 3, ["x"] = 9, ["name"] = "default:glass", ["z"] = 18, ["meta"] = {["inventory"] = {}, ["fields"] = {}}, ["param1"] = 157}, {["y"] = 3, ["x"] = 9, ["name"] = "default:glass", ["z"] = 19, ["meta"] = {["inventory"] = {}, ["fields"] = {}}, ["param1"] = 159}, {["y"] = 3, ["x"] = 9, ["name"] = "default:glass", ["z"] = 20, ["meta"] = {["inventory"] = {}, ["fields"] = {}}, ["param1"] = 173}, {["y"] = 3, ["x"] = 9, ["name"] = "default:glass", ["z"] = 21, ["meta"] = {["inventory"] = {}, ["fields"] = {}}, ["param1"] = 156}, {["y"] = 3, ["x"] = 9, ["name"] = "default:glass", ["z"] = 22, ["meta"] = {["inventory"] = {}, ["fields"] = {}}, ["param1"] = 141}, {["y"] = 3, ["x"] = 9, ["name"] = "default:glass", ["z"] = 23, ["meta"] = {["inventory"] = {}, ["fields"] = {}}, ["param1"] = 125}, {["y"] = 3, ["x"] = 9, ["name"] = "default:glass", ["z"] = 24, ["meta"] = {["inventory"] = {}, ["fields"] = {}}, ["param1"] = 109}, {["y"] = 3, ["x"] = 9, ["name"] = "default:glass", ["z"] = 25, ["meta"] = {["inventory"] = {}, ["fields"] = {}}, ["param1"] = 124}, {["y"] = 3, ["x"] = 9, ["name"] = "default:glass", ["z"] = 26, ["meta"] = {["inventory"] = {}, ["fields"] = {}}, ["param1"] = 141}, {["y"] = 3, ["x"] = 9, ["name"] = "default:glass", ["z"] = 27, ["meta"] = {["inventory"] = {}, ["fields"] = {}}, ["param1"] = 157}, {["y"] = 3, ["x"] = 9, ["name"] = "default:glass", ["z"] = 28, ["meta"] = {["inventory"] = {}, ["fields"] = {}}, ["param1"] = 175}, {["y"] = 3, ["x"] = 9, ["name"] = "default:glass", ["z"] = 29, ["meta"] = {["inventory"] = {}, ["fields"] = {}}, ["param1"] = 189}, {["y"] = 3, ["x"] = 9, ["name"] = "default:glass", ["z"] = 30, ["meta"] = {["inventory"] = {}, ["fields"] = {}}, ["param1"] = 205}, {["y"] = 3, ["x"] = 9, ["name"] = "default:glass", ["z"] = 31, ["meta"] = {["inventory"] = {}, ["fields"] = {}}, ["param1"] = 223}, {["y"] = 3, ["x"] = 9, ["name"] = "moreblocks:super_glow_glass", ["z"] = 32, ["meta"] = {["inventory"] = {}, ["fields"] = {}}}, {["y"] = 3, ["x"] = 9, ["name"] = "default:glass", ["z"] = 33, ["meta"] = {["inventory"] = {}, ["fields"] = {}}, ["param1"] = 223}, {["y"] = 3, ["x"] = 9, ["name"] = "default:glass", ["z"] = 34, ["meta"] = {["inventory"] = {}, ["fields"] = {}}, ["param1"] = 207}, {["y"] = 3, ["x"] = 9, ["name"] = "default:glass", ["z"] = 35, ["meta"] = {["inventory"] = {}, ["fields"] = {}}, ["param1"] = 189}, {["y"] = 3, ["x"] = 9, ["name"] = "default:glass", ["z"] = 36, ["meta"] = {["inventory"] = {}, ["fields"] = {}}, ["param1"] = 173}, {["y"] = 3, ["x"] = 9, ["name"] = "default:glass", ["z"] = 37, ["meta"] = {["inventory"] = {}, ["fields"] = {}}, ["param1"] = 157}, {["y"] = 3, ["x"] = 9, ["name"] = "default:glass", ["z"] = 38, ["meta"] = {["inventory"] = {}, ["fields"] = {}}, ["param1"] = 140}, {["y"] = 3, ["x"] = 9, ["name"] = "default:glass", ["z"] = 39, ["meta"] = {["inventory"] = {}, ["fields"] = {}}, ["param1"] = 125}, {["y"] = 3, ["x"] = 9, ["name"] = "default:glass", ["z"] = 40, ["meta"] = {["inventory"] = {}, ["fields"] = {}}, ["param1"] = 109}, {["y"] = 3, ["x"] = 9, ["name"] = "default:glass", ["z"] = 41, ["meta"] = {["inventory"] = {}, ["fields"] = {}}, ["param1"] = 124}, {["y"] = 3, ["x"] = 9, ["name"] = "default:glass", ["z"] = 42, ["meta"] = {["inventory"] = {}, ["fields"] = {}}, ["param1"] = 141}, {["y"] = 3, ["x"] = 9, ["name"] = "default:glass", ["z"] = 43, ["meta"] = {["inventory"] = {}, ["fields"] = {}}, ["param1"] = 156}, {["y"] = 3, ["x"] = 9, ["name"] = "default:glass", ["z"] = 44, ["meta"] = {["inventory"] = {}, ["fields"] = {}}, ["param1"] = 173}, {["y"] = 3, ["x"] = 9, ["name"] = "default:glass", ["z"] = 45, ["meta"] = {["inventory"] = {}, ["fields"] = {}}, ["param1"] = 156}, {["y"] = 3, ["x"] = 9, ["name"] = "default:glass", ["z"] = 46, ["meta"] = {["inventory"] = {}, ["fields"] = {}}, ["param1"] = 139}, {["y"] = 3, ["x"] = 9, ["name"] = "default:glass", ["z"] = 47, ["meta"] = {["inventory"] = {}, ["fields"] = {}}, ["param1"] = 124}, {["y"] = 3, ["x"] = 9, ["name"] = "default:glass", ["z"] = 48, ["meta"] = {["inventory"] = {}, ["fields"] = {}}, ["param1"] = 125}, {["y"] = 3, ["x"] = 9, ["name"] = "default:glass", ["z"] = 49, ["meta"] = {["inventory"] = {}, ["fields"] = {}},