return {{["y"] = 0, ["x"] = 0, ["name"] = "default:stone", ["z"] = 0, ["meta"] = {["inventory"] = {}, ["fields"] = {}}, ["param2"] = 0, ["param1"] = 0}, {["y"] = 0, ["x"] = 0, ["name"] = "default:stone", ["z"] = 1, ["meta"] = {["inventory"] = {}, ["fields"] = {}}, ["param2"] = 0, ["param1"] = 0}, {["y"] = 0, ["x"] = 0, ["name"] = "default:stone", ["z"] = 2, ["meta"] = {["inventory"] = {}, ["fields"] = {}}, ["param2"] = 0, ["param1"] = 0}, {["y"] = 1, ["x"] = 0, ["name"] = "default:desert_sand", ["z"] = 0, ["meta"] = {["inventory"] = {}, ["fields"] = {}}, ["param2"] = 0, ["param1"] = 0}, {["y"] = 1, ["x"] = 0, ["name"] = "default:desert_sand", ["z"] = 1, ["meta"] = {["inventory"] = {}, ["fields"] = {}}, ["param2"] = 0, ["param1"] = 0}, {["y"] = 1, ["x"] = 0, ["name"] = "default:desert_sand", ["z"] = 2, ["meta"] = {["inventory"] = {}, ["fields"] = {}}, ["param2"] = 0, ["param1"] = 0}, {["y"] = 2, ["x"] = 0, ["name"] = "default:desert_sand", ["z"] = 0, ["meta"] = {["inventory"] = {}, ["fields"] = {}}, ["param2"] = 0, ["param1"] = 0}, {["y"] = 2, ["x"] = 0, ["name"] = "default:desert_sand", ["z"] = 1, ["meta"] = {["inventory"] = {}, ["fields"] = {}}, ["param2"] = 0, ["param1"] = 0}, {["y"] = 2, ["x"] = 0, ["name"] = "default:desert_sand", ["z"] = 2, ["meta"] = {["inventory"] = {}, ["fields"] = {}}, ["param2"] = 0, ["param1"] = 0}, {["y"] = 3, ["x"] = 0, ["name"] = "default:desert_sand", ["z"] = 0, ["meta"] = {["inventory"] = {}, ["fields"] = {}}, ["param2"] = 0, ["param1"] = 0}, {["y"] = 3, ["x"] = 0, ["name"] = "default:desert_sand", ["z"] = 1, ["meta"] = {["inventory"] = {}, ["fields"] = {}}, ["param2"] = 0, ["param1"] = 0}, {["y"] = 3, ["x"] = 0, ["name"] = "default:desert_sand", ["z"] = 2, ["meta"] = {["inventory"] = {}, ["fields"] = {}}, ["param2"] = 0, ["param1"] = 0}, {["y"] = 0, ["x"] = 1, ["name"] = "default:stone", ["z"] = 0, ["meta"] = {["inventory"] = {}, ["fields"] = {}}, ["param2"] = 0, ["param1"] = 0}, {["y"] = 0, ["x"] = 1, ["name"] = "default:stone", ["z"] = 1, ["meta"] = {["inventory"] = {}, ["fields"] = {}}, ["param2"] = 0, ["param1"] = 0}, {["y"] = 0, ["x"] = 1, ["name"] = "default:stone", ["z"] = 2, ["meta"] = {["inventory"] = {}, ["fields"] = {}}, ["param2"] = 0, ["param1"] = 0}, {["y"] = 1, ["x"] = 1, ["name"] = "default:desert_sand", ["z"] = 0, ["meta"] = {["inventory"] = {}, ["fields"] = {}}, ["param2"] = 0, ["param1"] = 0}, {["y"] = 1, ["x"] = 1, ["name"] = "default:desert_sand", ["z"] = 1, ["meta"] = {["inventory"] = {}, ["fields"] = {}}, ["param2"] = 0, ["param1"] = 0}, {["y"] = 1, ["x"] = 1, ["name"] = "default:desert_sand", ["z"] = 2, ["meta"] = {["inventory"] = {}, ["fields"] = {}}, ["param2"] = 0, ["param1"] = 0}, {["y"] = 2, ["x"] = 1, ["name"] = "default:desert_sand", ["z"] = 0, ["meta"] = {["inventory"] = {}, ["fields"] = {}}, ["param2"] = 0, ["param1"] = 0}, {["y"] = 2, ["x"] = 1, ["name"] = "default:desert_sand", ["z"] = 1, ["meta"] = {["inventory"] = {}, ["fields"] = {}}, ["param2"] = 0, ["param1"] = 0}, {["y"] = 2, ["x"] = 1, ["name"] = "default:desert_sand", ["z"] = 2, ["meta"] = {["inventory"] = {}, ["fields"] = {}}, ["param2"] = 0, ["param1"] = 0}, {["y"] = 3, ["x"] = 1, ["name"] = "default:desert_sand", ["z"] = 0, ["meta"] = {["inventory"] = {}, ["fields"] = {}}, ["param2"] = 0, ["param1"] = 0}, {["y"] = 3, ["x"] = 1, ["name"] = "default:desert_sand", ["z"] = 1, ["meta"] = {["inventory"] = {}, ["fields"] = {}}, ["param2"] = 0, ["param1"] = 0}, {["y"] = 3, ["x"] = 1, ["name"] = "default:desert_sand", ["z"] = 2, ["meta"] = {["inventory"] = {}, ["fields"] = {}}, ["param2"] = 0, ["param1"] = 0}, {["y"] = 0, ["x"] = 2, ["name"] = "default:stone", ["z"] = 0, ["meta"] = {["inventory"] = {}, ["fields"] = {}}, ["param2"] = 0, ["param1"] = 0}, {["y"] = 0, ["x"] = 2, ["name"] = "default:stone", ["z"] = 1, ["meta"] = {["inventory"] = {}, ["fields"] = {}}, ["param2"] = 0, ["param1"] = 0}, {["y"] = 0, ["x"] = 2, ["name"] = "default:stone", ["z"] = 2, ["meta"] = {["inventory"] = {}, ["fields"] = {}}, ["param2"] = 0, ["param1"] = 0}, {["y"] = 1, ["x"] = 2, ["name"] = "default:desert_sand", ["z"] = 0, ["meta"] = {["inventory"] = {}, ["fields"] = {}}, ["param2"] = 0, ["param1"] = 0}, {["y"] = 1, ["x"] = 2, ["name"] = "default:desert_sand", ["z"] = 1, ["meta"] = {["inventory"] = {}, ["fields"] = {}}, ["param2"] = 0, ["param1"] = 0}, {["y"] = 1, ["x"] = 2, ["name"] = "default:desert_sand", ["z"] = 2, ["meta"] = {["inventory"] = {}, ["fields"] = {}}, ["param2"] = 0, ["param1"] = 0}, {["y"] = 2, ["x"] = 2, ["name"] = "default:desert_sand", ["z"] = 0, ["meta"] = {["inventory"] = {}, ["fields"] = {}}, ["param2"] = 0, ["param1"] = 0}, {["y"] = 2, ["x"] = 2, ["name"] = "default:desert_sand", ["z"] = 1, ["meta"] = {["inventory"] = {}, ["fields"] = {}}, ["param2"] = 0, ["param1"] = 0}, {["y"] = 2, ["x"] = 2, ["name"] = "default:desert_sand", ["z"] = 2, ["meta"] = {["inventory"] = {}, ["fields"] = {}}, ["param2"] = 0, ["param1"] = 0}, {["y"] = 3, ["x"] = 2, ["name"] = "default:desert_sand", ["z"] = 0, ["meta"] = {["inventory"] = {}, ["fields"] = {}}, ["param2"] = 0, ["param1"] = 0}, {["y"] = 3, ["x"] = 2, ["name"] = "default:desert_sand", ["z"] = 1, ["meta"] = {["inventory"] = {}, ["fields"] = {}}, ["param2"] = 0, ["param1"] = 0}, {["y"] = 3, ["x"] = 2, ["name"] = "default:desert_sand", ["z"] = 2, ["meta"] = {["inventory"] = {}, ["fields"] = {}}, ["param2"] = 0, ["param1"] = 0}, {["y"] = 4, ["x"] = 2, ["name"] = "default:chest_locked", ["z"] = 1, ["meta"] = {["inventory"] = {["main"] = {"farming:seed_wheat 53", "default:dirt 16", "moretrees:jungletree_leaves_green 28", "default:torch 40", "homedecor:plastic_sheeting", "", "homedecor:oil_extract", "default:cobble 20", "default:nyancat_rainbow 8", "default:nyancat", "", "", "pipeworks:tube_1 99", "mesecons:wire_00000000_off 80", "pipeworks:dispenser_off", "farming:wheat 14", "", "moretrees:beech_planks 8", "pipeworks:autocrafter", "trunks:twig_1 3", "", "pipeworks:tube_1 99", "pipeworks:sand_tube_1", "maptools:silver_coin", "carts:cart", "default:desert_sand 9", "", "maptools:copper_coin 24", "default:cobble 58", "", "default:mese_crystal", "default:mese_crystal_fragment 8"}}, ["fields"] = {["owner"] = "Cyberpangolin", ["infotext"] = "Locked Chest (owned by Cyberpangolin)", ["formspec"] = "size[8,9]listcolors[#606060AA;#808080;#101010;#202020;#FFF]list[nodemeta:-47,4,282;main;0,0.3;8,4;]list[current_player;main;0,4.85;8,4;]image[0,4.85;1,1;gui_hb_bg.png]image[1,4.85;1,1;gui_hb_bg.png]image[2,4.85;1,1;gui_hb_bg.png]image[3,4.85;1,1;gui_hb_bg.png]image[4,4.85;1,1;gui_hb_bg.png]image[5,4.85;1,1;gui_hb_bg.png]image[6,4.85;1,1;gui_hb_bg.png]image[7,4.85;1,1;gui_hb_bg.png]image[0,5.85;1,1;gui_hb_bg.png]image[1,5.85;1,1;gui_hb_bg.png]image[2,5.85;1,1;gui_hb_bg.png]image[3,5.85;1,1;gui_hb_bg.png]image[4,5.85;1,1;gui_hb_bg.png]image[5,5.85;1,1;gui_hb_bg.png]image[6,5.85;1,1;gui_hb_bg.png]image[7,5.85;1,1;gui_hb_bg.png]"}}, ["param2"] = 3, ["param1"] = 0}, {["y"] = 0, ["x"] = 3, ["name"] = "default:stone", ["z"] = 0, ["meta"] = {["inventory"] = {}, ["fields"] = {}}, ["param2"] = 0, ["param1"] = 0}, {["y"] = 0, ["x"] = 3, ["name"] = "default:stone", ["z"] = 1, ["meta"] = {["inventory"] = {}, ["fields"] = {}}, ["param2"] = 0, ["param1"] = 0}, {["y"] = 0, ["x"] = 3, ["name"] = "default:stone", ["z"] = 2, ["meta"] = {["inventory"] = {}, ["fields"] = {}}, ["param2"] = 0, ["param1"] = 0}, {["y"] = 1, ["x"] = 3, ["name"] = "default:desert_sand", ["z"] = 0, ["meta"] = {["inventory"] = {}, ["fields"] = {}}, ["param2"] = 0, ["param1"] = 0}, {["y"] = 1, ["x"] = 3, ["name"] = "default:desert_sand", ["z"] = 1, ["meta"] = {["inventory"] = {}, ["fields"] = {}}, ["param2"] = 0, ["param1"] = 0}, {["y"] = 1, ["x"] = 3, ["name"] = "default:desert_sand", ["z"] = 2, ["meta"] = {["inventory"] = {}, ["fields"] = {}}, ["param2"] = 0, ["param1"] = 0}, {["y"] = 2, ["x"] = 3, ["name"] = "default:desert_sand", ["z"] = 0, ["meta"] = {["inventory"] = {}, ["fields"] = {}}, ["param2"] = 0, ["param1"] = 0}, {["y"] = 2, ["x"] = 3, ["name"] = "default:desert_sand", ["z"] = 1, ["meta"] = {["inventory"] = {}, ["fields"] = {}}, ["param2"] = 0, ["param1"] = 0}, {["y"] = 2, ["x"] = 3, ["name"] = "default:desert_sand", ["z"] = 2, ["meta"] = {["inventory"] = {}, ["fields"] = {}}, ["param2"] = 0, ["param1"] = 0}, {["y"] = 3, ["x"] = 3, ["name"] = "default:desert_sand", ["z"] = 0, ["meta"] = {["inventory"] = {}, ["fields"] = {}}, ["param2"] = 0, ["param1"] = 0}, {["y"] = 3, ["x"] = 3, ["name"] = "default:desert_sand", ["z"] = 1, ["meta"] = {["inventory"] = {}, ["fields"] = {}}, ["param2"] = 0, ["param1"] = 0}, {["y"] = 3, ["x"] = 3, ["name"] = "default:desert_sand", ["z"] = 2, ["meta"] = {["inventory"] = {}, ["fields"] = {}}, ["param2"] = 0, ["param1"] = 0}}