5:return {{["y"] = 0, ["x"] = 0, ["name"] = "default:stone", ["z"] = 0, ["meta"] = {["inventory"] = {}, ["fields"] = {}}}, {["y"] = 0, ["x"] = 0, ["name"] = "default:stone", ["z"] = 1, ["meta"] = {["inventory"] = {}, ["fields"] = {}}}, {["y"] = 0, ["x"] = 0, ["name"] = "default:stone", ["z"] = 2, ["meta"] = {["inventory"] = {}, ["fields"] = {}}}, {["y"] = 0, ["x"] = 0, ["name"] = "default:stone", ["z"] = 3, ["meta"] = {["inventory"] = {}, ["fields"] = {}}}, {["y"] = 0, ["x"] = 0, ["name"] = "default:stone", ["z"] = 4, ["meta"] = {["inventory"] = {}, ["fields"] = {}}}, {["y"] = 0, ["x"] = 0, ["name"] = "default:stone", ["z"] = 5, ["meta"] = {["inventory"] = {}, ["fields"] = {}}}, {["y"] = 0, ["x"] = 0, ["name"] = "default:stone", ["z"] = 6, ["meta"] = {["inventory"] = {}, ["fields"] = {}}}, {["y"] = 0, ["x"] = 0, ["name"] = "default:stone", ["z"] = 7, ["meta"] = {["inventory"] = {}, ["fields"] = {}}}, {["y"] = 0, ["x"] = 0, ["name"] = "default:stone", ["z"] = 8, ["meta"] = {["inventory"] = {}, ["fields"] = {}}}, {["y"] = 0, ["x"] = 0, ["name"] = "default:stone", ["z"] = 9, ["meta"] = {["inventory"] = {}, ["fields"] = {}}}, {["y"] = 0, ["x"] = 0, ["name"] = "default:stone", ["z"] = 10, ["meta"] = {["inventory"] = {}, ["fields"] = {}}}, {["y"] = 0, ["x"] = 0, ["name"] = "default:stone", ["z"] = 11, ["meta"] = {["inventory"] = {}, ["fields"] = {}}}, {["y"] = 0, ["x"] = 0, ["name"] = "default:stone", ["z"] = 12, ["meta"] = {["inventory"] = {}, ["fields"] = {}}}, {["y"] = 0, ["x"] = 0, ["name"] = "default:stone", ["z"] = 13, ["meta"] = {["inventory"] = {}, ["fields"] = {}}}, {["y"] = 0, ["x"] = 0, ["name"] = "default:stone", ["z"] = 14, ["meta"] = {["inventory"] = {}, ["fields"] = {}}}, {["y"] = 0, ["x"] = 0, ["name"] = "default:stone", ["z"] = 15, ["meta"] = {["inventory"] = {}, ["fields"] = {}}}, {["y"] = 0, ["x"] = 0, ["name"] = "default:stone", ["z"] = 16, ["meta"] = {["inventory"] = {}, ["fields"] = {}}}, {["y"] = 0, ["x"] = 0, ["name"] = "default:stone", ["z"] = 17, ["meta"] = {["inventory"] = {}, ["fields"] = {}}}, {["y"] = 0, ["x"] = 0, ["name"] = "default:stone_with_coal", ["z"] = 18, ["meta"] = {["inventory"] = {}, ["fields"] = {}}}, {["y"] = 0, ["x"] = 0, ["name"] = "default:cobble", ["z"] = 19, ["meta"] = {["inventory"] = {}, ["fields"] = {}}}, {["y"] = 0, ["x"] = 0, ["name"] = "default:cobble", ["z"] = 20, ["meta"] = {["inventory"] = {}, ["fields"] = {}}}, {["y"] = 0, ["x"] = 0, ["name"] = "default:cobble", ["z"] = 21, ["meta"] = {["inventory"] = {}, ["fields"] = {}}}, {["y"] = 0, ["x"] = 0, ["name"] = "default:stone_with_coal", ["z"] = 22, ["meta"] = {["inventory"] = {}, ["fields"] = {}}}, {["y"] = 0, ["x"] = 0, ["name"] = "default:cobble", ["z"] = 23, ["meta"] = {["inventory"] = {}, ["fields"] = {}}}, {["y"] = 0, ["x"] = 0, ["name"] = "default:mossycobble", ["z"] = 24, ["meta"] = {["inventory"] = {}, ["fields"] = {}}}, {["y"] = 0, ["x"] = 0, ["name"] = "default:cobble", ["z"] = 25, ["meta"] = {["inventory"] = {}, ["fields"] = {}}}, {["y"] = 0, ["x"] = 0, ["name"] = "default:cobble", ["z"] = 26, ["meta"] = {["inventory"] = {}, ["fields"] = {}}}, {["y"] = 0, ["x"] = 0, ["name"] = "default:cobble", ["z"] = 27, ["meta"] = {["inventory"] = {}, ["fields"] = {}}}, {["y"] = 1, ["x"] = 0, ["name"] = "default:stone", ["z"] = 0, ["meta"] = {["inventory"] = {}, ["fields"] = {}}}, {["y"] = 1, ["x"] = 0, ["name"] = "default:stone", ["z"] = 1, ["meta"] = {["inventory"] = {}, ["fields"] = {}}}, {["y"] = 1, ["x"] = 0, ["name"] = "default:stone", ["z"] = 2, ["meta"] = {["inventory"] = {}, ["fields"] = {}}}, {["y"] = 1, ["x"] = 0, ["name"] = "default:sand", ["z"] = 3, ["meta"] = {["inventory"] = {}, ["fields"] = {}}}, {["y"] = 1, ["x"] = 0, ["name"] = "default:sand", ["z"] = 4, ["meta"] = {["inventory"] = {}, ["fields"] = {}}}, {["y"] = 1, ["x"] = 0, ["name"] = "default:sand", ["z"] = 5, ["meta"] = {["inventory"] = {}, ["fields"] = {}}}, {["y"] = 1, ["x"] = 0, ["name"] = "default:sand", ["z"] = 6, ["meta"] = {["inventory"] = {}, ["fields"] = {}}}, {["y"] = 1, ["x"] = 0, ["name"] = "default:sand", ["z"] = 7, ["meta"] = {["inventory"] = {}, ["fields"] = {}}}, {["y"] = 1, ["x"] = 0, ["name"] = "default:sand", ["z"] = 8, ["meta"] = {["inventory"] = {}, ["fields"] = {}}}, {["y"] = 1, ["x"] = 0, ["name"] = "default:sand", ["z"] = 9, ["meta"] = {["inventory"] = {}, ["fields"] = {}}}, {["y"] = 1, ["x"] = 0, ["name"] = "default:sand", ["z"] = 10, ["meta"] = {["inventory"] = {}, ["fields"] = {}}}, {["y"] = 1, ["x"] = 0, ["name"] = "default:sand", ["z"] = 11, ["meta"] = {["inventory"] = {}, ["fields"] = {}}}, {["y"] = 1, ["x"] = 0, ["name"] = "default:sand", ["z"] = 12, ["meta"] = {["inventory"] = {}, ["fields"] = {}}}, {["y"] = 1, ["x"] = 0, ["name"] = "default:sand", ["z"] = 13, ["meta"] = {["inventory"] = {}, ["fields"] = {}}}, {["y"] = 1, ["x"] = 0, ["name"] = "default:sand", ["z"] = 14, ["meta"] = {["inventory"] = {}, ["fields"] = {}}}, {["y"] = 1, ["x"] = 0, ["name"] = "default:sand", ["z"] = 15, ["meta"] = {["inventory"] = {}, ["fields"] = {}}}, {["y"] = 1, ["x"] = 0, ["name"] = "default:sand", ["z"] = 16, ["meta"] = {["inventory"] = {}, ["fields"] = {}}}, {["y"] = 1, ["x"] = 0, ["name"] = "default:sand", ["z"] = 17, ["meta"] = {["inventory"] = {}, ["fields"] = {}}}, {["y"] = 1, ["x"] = 0, ["name"] = "default:sand", ["z"] = 18, ["meta"] = {["inventory"] = {}, ["fields"] = {}}}, {["y"] = 1, ["x"] = 0, ["name"] = "default:sand", ["z"] = 19, ["meta"] = {["inventory"] = {}, ["fields"] = {}}}, {["y"] = 1, ["x"] = 0, ["name"] = "default:cobble", ["z"] = 20, ["meta"] = {["inventory"] = {}, ["fields"] = {}}}, {["y"] = 1, ["x"] = 0, ["name"] = "default:stone_with_coal", ["z"] = 21, ["meta"] = {["inventory"] = {}, ["fields"] = {}}}, {["y"] = 1, ["x"] = 0, ["name"] = "default:cobble", ["z"] = 22, ["meta"] = {["inventory"] = {}, ["fields"] = {}}}, {["y"] = 1, ["x"] = 0, ["name"] = "default:mossycobble", ["z"] = 23, ["meta"] = {["inventory"] = {}, ["fields"] = {}}}, {["y"] = 1, ["x"] = 0, ["name"] = "default:mossycobble", ["z"] = 24, ["meta"] = {["inventory"] = {}, ["fields"] = {}}}, {["y"] = 1, ["x"] = 0, ["name"] = "default:cobble", ["z"] = 25, ["meta"] = {["inventory"] = {}, ["fields"] = {}}}, {["y"] = 1, ["x"] = 0, ["name"] = "default:clay", ["z"] = 26, ["meta"] = {["inventory"] = {}, ["fields"] = {}}}, {["y"] = 1, ["x"] = 0, ["name"] = "default:sand", ["z"] = 27, ["meta"] = {["inventory"] = {}, ["fields"] = {}}}, {["y"] = 2, ["x"] = 0, ["name"] = "default:clay", ["z"] = 0, ["meta"] = {["inventory"] = {}, ["fields"] = {}}}, {["y"] = 2, ["x"] = 0, ["name"] = "default:clay", ["z"] = 1, ["meta"] = {["inventory"] = {}, ["fields"] = {}}}, {["y"] = 2, ["x"] = 0, ["name"] = "darkage:silt", ["z"] = 2, ["meta"] = {["inventory"] = {}, ["fields"] = {}}}, {["y"] = 2, ["x"] = 0, ["name"] = "darkage:silt", ["z"] = 3, ["meta"] = {["inventory"] = {}, ["fields"] = {}}}, {["y"] = 2, ["x"] = 0, ["name"] = "default:sand", ["z"] = 4, ["meta"] = {["inventory"] = {}, ["fields"] = {}}}, {["y"] = 2, ["x"] = 0, ["name"] = "default:sand", ["z"] = 5, ["meta"] = {["inventory"] = {}, ["fields"] = {}}}, {["y"] = 2, ["x"] = 0, ["name"] = "default:sand", ["z"] = 6, ["meta"] = {["inventory"] = {}, ["fields"] = {}}}, {["y"] = 2, ["x"] = 0, ["name"] = "default:sand", ["z"] = 7, ["meta"] = {["inventory"] = {}, ["fields"] = {}}}, {["y"] = 2, ["x"] = 0, ["name"] = "default:sand", ["z"] = 8, ["meta"] = {["inventory"] = {}, ["fields"] = {}}}, {["y"] = 2, ["x"] = 0, ["name"] = "default:sand", ["z"] = 9, ["meta"] = {["inventory"] = {}, ["fields"] = {}}}, {["y"] = 2, ["x"] = 0, ["name"] = "default:sand", ["z"] = 10, ["meta"] = {["inventory"] = {}, ["fields"] = {}}}, {["y"] = 2, ["x"] = 0, ["name"] = "default:sand", ["z"] = 11, ["meta"] = {["inventory"] = {}, ["fields"] = {}}}, {["y"] = 2, ["x"] = 0, ["name"] = "default:sand", ["z"] = 12, ["meta"] = {["inventory"] = {}, ["fields"] = {}}}, {["y"] = 2, ["x"] = 0, ["name"] = "default:sand", ["z"] = 13, ["meta"] = {["inventory"] = {}, ["fields"] = {}}}, {["y"] = 2, ["x"] = 0, ["name"] = "default:sand", ["z"] = 14, ["meta"] = {["inventory"] = {}, ["fields"] = {}}}, {["y"] = 2, ["x"] = 0, ["name"] = "default:sand", ["z"] = 15, ["meta"] = {["inventory"] = {}, ["fields"] = {}}}, {["y"] = 2, ["x"] = 0, ["name"] = "default:sand", ["z"] = 16, ["meta"] = {["inventory"] = {}, ["fields"] = {}}}, {["y"] = 2, ["x"] = 0, ["name"] = "default:sand", ["z"] = 17, ["meta"] = {["inventory"] = {}, ["fields"] = {}}}, {["y"] = 2, ["x"] = 0, ["name"] = "default:sand", ["z"] = 18, ["meta"] = {["inventory"] = {}, ["fields"] = {}}}, {["y"] = 2, ["x"] = 0, ["name"] = "default:sand", ["z"] = 19, ["meta"] = {["inventory"] = {}, ["fields"] = {}}}, {["y"] = 2, ["x"] = 0, ["name"] = "default:sand", ["z"] = 20, ["meta"] = {["inventory"] = {}, ["fields"] = {}}}, {["y"] = 2, ["x"] = 0, ["name"] = "default:sand", ["z"] = 21, ["meta"] = {["inventory"] = {}, ["fields"] = {}}}, {["y"] = 2, ["x"] = 0, ["name"] = "default:sand", ["z"] = 22, ["meta"] = {["inventory"] = {}, ["fields"] = {}}}, {["y"] = 2, ["x"] = 0, ["name"] = "default:sand", ["z"] = 23, ["meta"] = {["inventory"] = {}, ["fields"] = {}}}, {["y"] = 2, ["x"] = 0, ["name"] = "default:sand", ["z"] = 24, ["meta"] = {["inventory"] = {}, ["fields"] = {}}}, {["y"] = 2, ["x"] = 0, ["name"] = "default:sand", ["z"] = 25, ["meta"] = {["inventory"] = {}, ["fields"] = {}}}, {["y"] = 2, ["x"] = 0, ["name"] = "default:sand", ["z"] = 26, ["meta"] = {["inventory"] = {}, ["fields"] = {}}}, {["y"] = 2, ["x"] = 0, ["name"] = "default:sand", ["z"] = 27, ["meta"] = {["inventory"] = {}, ["fields"] = {}}}, {["y"] = 3, ["x"] = 0, ["name"] = "default:clay", ["z"] = 0, ["meta"] = {["inventory"] = {}, ["fields"] = {}}}, {["y"] = 3, ["x"] = 0, ["name"] = "default:clay", ["z"] = 1, ["meta"] = {["inventory"] = {}, ["fields"] = {}}}, {["y"] = 3, ["x"] = 0, ["name"] = "darkage:mud", ["z"] = 2, ["meta"] = {["inventory"] = {}, ["fields"] = {}}}, {["y"] = 3, ["x"] = 0, ["name"] = "colouredstonebricks:grey", ["z"] = 3, ["meta"] = {["inventory"] = {}, ["fields"] = {}}}, {["y"] = 3, ["x"] = 0, ["name"] = "default:water_source", ["z"] = 4, ["meta"] = {["inventory"] = {}, ["fields"] = {}}, ["param1"] = 45}, {["y"] = 3, ["x"] = 0, ["name"] = "default:water_source", ["z"] = 5, ["meta"] = {["inventory"] = {}, ["fields"] = {}}, ["param1"] = 61}, {["y"] = 3, ["x"] = 0, ["name"] = "default:water_source", ["z"] = 6, ["meta"] = {["inventory"] = {}, ["fields"] = {}}, ["param1"] = 76}, {["y"] = 3, ["x"] = 0, ["name"] = "default:water_source", ["z"] = 7, ["meta"] = {["inventory"] = {}, ["fields"] = {}}, ["param1"] = 93}, {["y"] = 3, ["x"] = 0, ["name"] = "default:water_source", ["z"] = 8, ["meta"] = {["inventory"] = {}, ["fields"] = {}}, ["param2"] = 240, ["param1"] = 109}, {["y"] = 3, ["x"] = 0, ["name"] = "default:water_source", ["z"] = 9, ["meta"] = {["inventory"] = {}, ["fields"] = {}}, ["param1"] = 125}, {["y"] = 3, ["x"] = 0, ["name"] = "default:water_source", ["z"] = 10, ["meta"] = {["inventory"] = {}, ["fields"] = {}}, ["param2"] = 240, ["param1"] = 109}, {["y"] = 3, ["x"] = 0, ["name"] = "default:water_source", ["z"] = 11, ["meta"] = {["inventory"] = {}, ["fields"] = {}}, ["param1"] = 93}, {["y"] = 3, ["x"] = 0, ["name"] = "default:water_source", ["z"] = 12, ["meta"] = {["inventory"] = {}, ["fields"] = {}}, ["param1"] = 77}, {["y"] = 3, ["x"] = 0, ["name"] = "default:water_source", ["z"] = 13, ["meta"] = {["inventory"] = {}, ["fields"] = {}}, ["param1"] = 61}, {["y"] = 3, ["x"] = 0, ["name"] = "default:water_source", ["z"] = 14, ["meta"] = {["inventory"] = {}, ["fields"] = {}}, ["param1"] = 44}, {["y"] = 3, ["x"] = 0, ["name"] = "default:water_source", ["z"] = 15, ["meta"] = {["inventory"] = {}, ["fields"] = {}}, ["param1"] = 27}, {["y"] = 3, ["x"] = 0, ["name"] = "default:water_source", ["z"] = 16, ["meta"] = {["inventory"] = {}, ["fields"] = {}}, ["param1"] = 26}, {["y"] = 3, ["x"] = 0, ["name"] = "default:water_source", ["z"] = 17, ["meta"] = {["inventory"] = {}, ["fields"] = {}}, ["param1"] = 43}, {["y"] = 3, ["x"] = 0, ["name"] = "default:water_source", ["z"] = 18, ["meta"] = {["inventory"] = {}, ["fields"] = {}}, ["param1"] = 60}, {["y"] = 3, ["x"] = 0, ["name"] = "default:water_source", ["z"] = 19, ["meta"] = {["inventory"] = {}, ["fields"] = {}}, ["param1"] = 77}, {["y"] = 3, ["x"] = 0, ["name"] = "default:water_source", ["z"] = 20, ["meta"] = {["inventory"] = {}, ["fields"] = {}}, ["param1"] = 61}, {["y"] = 3, ["x"] = 0, ["name"] = "default:water_source", ["z"] = 21, ["meta"] = {["inventory"] = {}, ["fields"] = {}}, ["param1"] = 45}, {["y"] = 3, ["x"] = 0, ["name"] = "default:water_source", ["z"] = 22, ["meta"] = {["inventory"] = {}, ["fields"] = {}}, ["param1"] = 29}, {["y"] = 3, ["x"] = 0, ["name"] = "default:water_source", ["z"] = 23, ["meta"] = {["inventory"] = {}, ["fields"] = {}}, ["param1"] = 13}, {["y"] = 3, ["x"] = 0, ["name"] = "default:water_source", ["z"] = 24, ["meta"] = {["inventory"] = {}, ["fields"] = {}}, ["param1"] = 29}, {["y"] = 3, ["x"] = 0, ["name"] = "default:water_source", ["z"] = 25, ["meta"] = {["inventory"] = {}, ["fields"] = {}}, ["param1"] = 45}, {["y"] = 3, ["x"] = 0, ["name"] = "default:water_source", ["z"] = 26, ["meta"] = {["inventory"] = {}, ["fields"] = {}}, ["param1"] = 61}, {["y"] = 3, ["x"] = 0, ["name"] = "default:water_source", ["z"] = 27, ["meta"] = {["inventory"] = {}, ["fields"] = {}}, ["param1"] = 77}, {["y"] = 4, ["x"] = 0, ["name"] = "default:sand", ["z"] = 0, ["meta"] = {["inventory"] = {}, ["fields"] = {}}}, {["y"] = 4, ["x"] = 0, ["name"] = "default:sand", ["z"] = 1, ["meta"] = {["inventory"] = {}, ["fields"] = {}}}, {["y"] = 4, ["x"] = 0, ["name"] = "default:sand", ["z"] = 2, ["meta"] = {["inventory"] = {}, ["fields"] = {}}}, {["y"] = 4, ["x"] = 0, ["name"] = "colouredstonebricks:grey", ["z"] = 3, ["meta"] = {["inventory"] = {}, ["fields"] = {}}}, {["y"] = 4, ["x"] = 0, ["name"] = "flowers:waterlily_s2", ["z"] = 4, ["meta"] = {["inventory"] = {}, ["fields"] = {}}, ["param2"] = 1, ["param1"] = 63}, {["y"] = 4, ["x"] = 0, ["name"] = "flowers:waterlily", ["z"] = 6, ["meta"] = {["inventory"] = {}, ["fields"] = {}}, ["param2"] = 1, ["param1"] = 93}, {["y"] = 4, ["x"] = 0, ["name"] = "flowers:waterlily_s3", ["z"] = 11, ["meta"] = {["inventory"] = {}, ["fields"] = {}}, ["param1"] = 111}, {["y"] = 4, ["x"] = 0, ["name"] = "colouredstonebricks:grey", ["z"] = 14, ["meta"] = {["inventory"] = {}, ["fields"] = {}}}, {["y"] = 4, ["x"] = 0, ["name"] = "colouredstonebricks:grey", ["z"] = 15, ["meta"] = {["inventory"] = {}, ["fields"] = {}}}, {["y"] = 4, ["x"] = 0, ["name"] = "colouredstonebricks:grey", ["z"] = 16, ["meta"] = {["inventory"] = {}, ["fields"] = {}}}, {["y"] = 4, ["x"] = 0, ["name"] = "colouredstonebricks:grey", ["z"] = 17, ["meta"] = {["inventory"] = {}, ["fields"] = {}}}, {["y"] = 4, ["x"] = 0, ["name"] = "colouredstonebricks:grey", ["z"] = 18, ["meta"] = {["inventory"] = {}, ["fields"] = {}}}, {["y"] = 4, ["x"] = 0, ["name"] = "flowers:waterlily_s4", ["z"] = 20, ["meta"] = {["inventory"] = {}, ["fields"] = {}}, ["param1"] = 79}, {["y"] = 4, ["x"] = 0, ["name"] = "flowers:waterlily_s4", ["z"] = 26, ["meta"] = {["inventory"] = {}, ["fields"] = {}}, ["param2"] = 3, ["param1"] = 79}, {["y"] = 5, ["x"] = 0, ["name"] = "dryplants:juncus_02", ["z"] = 1, ["meta"] = {["inventory"] = {}, ["fields"] = {}}, ["param1"] = 29}, {["y"] = 5, ["x"] = 0, ["name"] = "colouredstonebricks:grey", ["z"] = 3, ["meta"] = {["inventory"] = {}, ["fields"] = {}}}, {["y"] = 5, ["x"] = 0, ["name"] = "darkage:stone_brick", ["z"] = 14, ["meta"] = {["inventory"] = {}, ["fields"] = {}}}, {["y"] = 5, ["x"] = 0, ["name"] = "darkage:stone_brick", ["z"] = 18, ["meta"] = {["inventory"] = {}, ["fields"] = {}}}, {["y"] = 0, ["x"] = 1, ["name"] = "default:stone", ["z"] = 0, ["meta"] = {["inventory"] = {}, ["fields"] = {}}}, {["y"] = 0, ["x"] = 1, ["name"] = "default:stone", ["z"] = 1, ["meta"] = {["inventory"] = {}, ["fields"] = {}}}, {["y"] = 0, ["x"] = 1, ["name"] = "default:stone", ["z"] = 2, ["meta"] = {["inventory"] = {}, ["fields"] = {}}}, {["y"] = 0, ["x"] = 1, ["name"] = "default:stone", ["z"] = 3, ["meta"] = {["inventory"] = {}, ["fields"] = {}}}, {["y"] = 0, ["x"] = 1, ["name"] = "default:stone", ["z"] = 4, ["meta"] = {["inventory"] = {}, ["fields"] = {}}}, {["y"] = 0, ["x"] = 1, ["name"] = "default:stone", ["z"] = 5, ["meta"] = {["inventory"] = {}, ["fields"] = {}}}, {["y"] = 0, ["x"] = 1, ["name"] = "default:stone", ["z"] = 6, ["meta"] = {["inventory"] = {}, ["fields"] = {}}}, {["y"] = 0, ["x"] = 1, ["name"] = "default:stone", ["z"] = 7, ["meta"] = {["inventory"] = {}, ["fields"] = {}}}, {["y"] = 0, ["x"] = 1, ["name"] = "default:stone", ["z"] = 8, ["meta"] = {["inventory"] = {}, ["fields"] = {}}}, {["y"] = 0, ["x"] = 1, ["name"] = "default:stone", ["z"] = 9, ["meta"] = {["inventory"] = {}, ["fields"] = {}}}, {["y"] = 0, ["x"] = 1, ["name"] = "default:stone", ["z"] = 10, ["meta"] = {["inventory"] = {}, ["fields"] = {}}}, {["y"] = 0, ["x"] = 1, ["name"] = "default:stone", ["z"] = 11, ["meta"] = {["inventory"] = {}, ["fields"] = {}}}, {["y"] = 0, ["x"] = 1, ["name"] = "default:stone", ["z"] = 12, ["meta"] = {["inventory"] = {}, ["fields"] = {}}}, {["y"] = 0, ["x"] = 1, ["name"] = "default:stone", ["z"] = 13, ["meta"] = {["inventory"] = {}, ["fields"] = {}}}, {["y"] = 0, ["x"] = 1, ["name"] = "default:stone", ["z"] = 14, ["meta"] = {["inventory"] = {}, ["fields"] = {}}}, {["y"] = 0, ["x"] = 1, ["name"] = "default:stone", ["z"] = 15, ["meta"] = {["inventory"] = {}, ["fields"] = {}}}, {["y"] = 0, ["x"] = 1, ["name"] = "default:stone", ["z"] = 16, ["meta"] = {["inventory"] = {}, ["fields"] = {}}}, {["y"] = 0, ["x"] = 1, ["name"] = "default:stone", ["z"] = 17, ["meta"] = {["inventory"] = {}, ["fields"] = {}}}, {["y"] = 0, ["x"] = 1, ["name"] = "default:stone", ["z"] = 18, ["meta"] = {["inventory"] = {}, ["fields"] = {}}}, {["y"] = 0, ["x"] = 1, ["name"] = "default:cobble", ["z"] = 19, ["meta"] = {["inventory"] = {}, ["fields"] = {}}}, {["y"] = 0, ["x"] = 1, ["name"] = "default:cobble", ["z"] = 20, ["meta"] = {["inventory"] = {}, ["fields"] = {}}}, {["y"] = 0, ["x"] = 1, ["name"] = "default:cobble", ["z"] = 21, ["meta"] = {["inventory"] = {}, ["fields"] = {}}}, {["y"] = 0, ["x"] = 1, ["name"] = "default:mossycobble", ["z"] = 22, ["meta"] = {["inventory"] = {}, ["fields"] = {}}}, {["y"] = 0, ["x"] = 1, ["name"] = "default:mossycobble", ["z"] = 23, ["meta"] = {["inventory"] = {}, ["fields"] = {}}}, {["y"] = 0, ["x"] = 1, ["name"] = "default:cobble", ["z"] = 24, ["meta"] = {["inventory"] = {}, ["fields"] = {}}}, {["y"] = 0, ["x"] = 1, ["name"] = "default:cobble", ["z"] = 25, ["meta"] = {["inventory"] = {}, ["fields"] = {}}}, {["y"] = 0, ["x"] = 1, ["name"] = "default:cobble", ["z"] = 26, ["meta"] = {["inventory"] = {}, ["fields"] = {}}}, {["y"] = 0, ["x"] = 1, ["name"] = "default:cobble", ["z"] = 27, ["meta"] = {["inventory"] = {}, ["fields"] = {}}}, {["y"] = 1, ["x"] = 1, ["name"] = "default:stone", ["z"] = 0, ["meta"] = {["inventory"] = {}, ["fields"] = {}}}, {["y"] = 1, ["x"] = 1, ["name"] = "default:stone", ["z"] = 1, ["meta"] = {["inventory"] = {}, ["fields"] = {}}}, {["y"] = 1, ["x"] = 1, ["name"] = "default:stone", ["z"] = 2, ["meta"] = {["inventory"] = {}, ["fields"] = {}}}, {["y"] = 1, ["x"] = 1, ["name"] = "default:sand", ["z"] = 3, ["meta"] = {["inventory"] = {}, ["fields"] = {}}}, {["y"] = 1, ["x"] = 1, ["name"] = "default:sand", ["z"] = 4, ["meta"] = {["inventory"] = {}, ["fields"] = {}}}, {["y"] = 1, ["x"] = 1, ["name"] = "default:sand", ["z"] = 5, ["meta"] = {["inventory"] = {}, ["fields"] = {}}}, {["y"] = 1, ["x"] = 1, ["name"] = "default:sand", ["z"] = 6, ["meta"] = {["inventory"] = {}, ["fields"] = {}}}, {["y"] = 1, ["x"] = 1, ["name"] = "default:sand", ["z"] = 7, ["meta"] = {["inventory"] = {}, ["fields"] = {}}}, {["y"] = 1, ["x"] = 1, ["name"] = "default:sand", ["z"] = 8, ["meta"] = {["inventory"] = {}, ["fields"] = {}}}, {["y"] = 1, ["x"] = 1, ["name"] = "default:sand", ["z"] = 9, ["meta"] = {["inventory"] = {}, ["fields"] = {}}}, {["y"] = 1, ["x"] = 1, ["name"] = "default:sand", ["z"] = 10, ["meta"] = {["inventory"] = {}, ["fields"] = {}}}, {["y"] = 1, ["x"] = 1, ["name"] = "default:sand", ["z"] = 11, ["meta"] = {["inventory"] = {}, ["fields"] = {}}}, {["y"] = 1, ["x"] = 1, ["name"] = "default:sand", ["z"] = 12, ["meta"] = {["inventory"] = {}, ["fields"] = {}}}, {["y"] = 1, ["x"] = 1, ["name"] = "default:sand", ["z"] = 13, ["meta"] = {["inventory"] = {}, ["fields"] = {}}}, {["y"] = 1, ["x"] = 1, ["name"] = "default:sand", ["z"] = 14, ["meta"] = {["inventory"] = {}, ["fields"] = {}}}, {["y"] = 1, ["x"] = 1, ["name"] = "default:sand", ["z"] = 15, ["meta"] = {["inventory"] = {}, ["fields"] = {}}}, {["y"] = 1, ["x"] = 1, ["name"] = "default:sand", ["z"] = 16, ["meta"] = {["inventory"] = {}, ["fields"] = {}}}, {["y"] = 1, ["x"] = 1, ["name"] = "default:sand", ["z"] = 17, ["meta"] = {["inventory"] = {}, ["fields"] = {}}}, {["y"] = 1, ["x"] = 1, ["name"] = "default:sand", ["z"] = 18, ["meta"] = {["inventory"] = {}, ["fields"] = {}}}, {["y"] = 1, ["x"] = 1, ["name"] = "default:cobble", ["z"] = 19, ["meta"] = {["inventory"] = {}, ["fields"] = {}}}, {["y"] = 1, ["x"] = 1, ["name"] = "default:cobble", ["z"] = 20, ["meta"] = {["inventory"] = {}, ["fields"] = {}}}, {["y"] = 1, ["x"] = 1, ["name"] = "default:cobble", ["z"] = 21, ["meta"] = {["inventory"] = {}, ["fields"] = {}}}, {["y"] = 1, ["x"] = 1, ["name"] = "default:cobble", ["z"] = 22, ["meta"] = {["inventory"] = {}, ["fields"] = {}}}, {["y"] = 1, ["x"] = 1, ["name"] = "default:stone_with_coal", ["z"] = 23, ["meta"] = {["inventory"] = {}, ["fields"] = {}}}, {["y"] = 1, ["x"] = 1, ["name"] = "default:mossycobble", ["z"] = 24, ["meta"] = {["inventory"] = {}, ["fields"] = {}}}, {["y"] = 1, ["x"] = 1, ["name"] = "default:cobble", ["z"] = 25, ["meta"] = {["inventory"] = {}, ["fields"] = {}}}, {["y"] = 1, ["x"] = 1, ["name"] = "default:clay", ["z"] = 26, ["meta"] = {["inventory"] = {}, ["fields"] = {}}}, {["y"] = 1, ["x"] = 1, ["name"] = "default:sand", ["z"] = 27, ["meta"] = {["inventory"] = {}, ["fields"] = {}}}, {["y"] = 2, ["x"] = 1, ["name"] = "default:clay", ["z"] = 0, ["meta"] = {["inventory"] = {}, ["fields"] = {}}}, {["y"] = 2, ["x"] = 1, ["name"] = "default:clay", ["z"] = 1, ["meta"] = {["inventory"] = {}, ["fields"] = {}}}, {["y"] = 2, ["x"] = 1, ["name"] = "darkage:silt", ["z"] = 2, ["meta"] = {["inventory"] = {}, ["fields"] = {}}}, {["y"] = 2, ["x"] = 1, ["name"] = "darkage:silt", ["z"] = 3, ["meta"] = {["inventory"] = {}, ["fields"] = {}}}, {["y"] = 2, ["x"] = 1, ["name"] = "default:sand", ["z"] = 4, ["meta"] = {["inventory"] = {}, ["fields"] = {}}}, {["y"] = 2, ["x"] = 1, ["name"] = "default:sand", ["z"] = 5, ["meta"] = {["inventory"] = {}, ["fields"] = {}}}, {["y"] = 2, ["x"] = 1, ["name"] = "default:sand", ["z"] = 6, ["meta"] = {["inventory"] = {}, ["fields"] = {}}}, {["y"] = 2, ["x"] = 1, ["name"] = "default:sand", ["z"] = 7, ["meta"] = {["inventory"] = {}, ["fields"] = {}}}, {["y"] = 2, ["x"] = 1, ["name"] = "default:sand", ["z"] = 8, ["meta"] = {["inventory"] = {}, ["fields"] = {}}}, {["y"] = 2, ["x"] = 1, ["name"] = "default:sand", ["z"] = 9, ["meta"] = {["inventory"] = {}, ["fields"] = {}}}, {["y"] = 2, ["x"] = 1, ["name"] = "default:sand", ["z"] = 10, ["meta"] = {["inventory"] = {}, ["fields"] = {}}}, {["y"] = 2, ["x"] = 1, ["name"] = "default:sand", ["z"] = 11, ["meta"] = {["inventory"] = {}, ["fields"] = {}}}, {["y"] = 2, ["x"] = 1, ["name"] = "default:sand", ["z"] = 12, ["meta"] = {["inventory"] = {}, ["fields"] = {}}}, {["y"] = 2, ["x"] = 1, ["name"] = "default:sand", ["z"] = 13, ["meta"] = {["inventory"] = {}, ["fields"] = {}}}, {["y"] = 2, ["x"] = 1, ["name"] = "default:sand", ["z"] = 14, ["meta"] = {["inventory"] = {}, ["fields"] = {}}}, {["y"] = 2, ["x"] = 1, ["name"] = "default:sand", ["z"] = 15, ["meta"] = {["inventory"] = {}, ["fields"] = {}}}, {["y"] = 2, ["x"] = 1, ["name"] = "default:sand", ["z"] = 16, ["meta"] = {["inventory"] = {}, ["fields"] = {}}}, {["y"] = 2, ["x"] = 1, ["name"] = "default:sand", ["z"] = 17, ["meta"] = {["inventory"] = {}, ["fields"] = {}}}, {["y"] = 2, ["x"] = 1, ["name"] = "default:sand", ["z"] = 18, ["meta"] = {["inventory"] = {}, ["fields"] = {}}}, {["y"] = 2, ["x"] = 1, ["name"] = "default:sand", ["z"] = 19, ["meta"] = {["inventory"] = {}, ["fields"] = {}}}, {["y"] = 2, ["x"] = 1, ["name"] = "default:sand", ["z"] = 20, ["meta"] = {["inventory"] = {}, ["fields"] = {}}}, {["y"] = 2, ["x"] = 1, ["name"] = "default:sand", ["z"] = 21, ["meta"] = {["inventory"] = {}, ["fields"] = {}}}, {["y"] = 2, ["x"] = 1, ["name"] = "default:sand", ["z"] = 22, ["meta"] = {["inventory"] = {}, ["fields"] = {}}}, {["y"] = 2, ["x"] = 1, ["name"] = "default:sand", ["z"] = 23, ["meta"] = {["inventory"] = {}, ["fields"] = {}}}, {["y"] = 2, ["x"] = 1, ["name"] = "default:sand", ["z"] = 24, ["meta"] = {["inventory"] = {}, ["fields"] = {}}}, {["y"] = 2, ["x"] = 1, ["name"] = "default:sand", ["z"] = 25, ["meta"] = {["inventory"] = {}, ["fields"] = {}}}, {["y"] = 2, ["x"] = 1, ["name"] = "default:sand", ["z"] = 26, ["meta"] = {["inventory"] = {}, ["fields"] = {}}}, {["y"] = 2, ["x"] = 1, ["name"] = "default:sand", ["z"] = 27, ["meta"] = {["inventory"] = {}, ["fields"] = {}}}, {["y"] = 3, ["x"] = 1, ["name"] = "default:clay", ["z"] = 0, ["meta"] = {["inventory"] = {}, ["fields"] = {}}}, {["y"] = 3, ["x"] = 1, ["name"] = "default:clay", ["z"] = 1, ["meta"] = {["inventory"] = {}, ["fields"] = {}}}, {["y"] = 3, ["x"] = 1, ["name"] = "darkage:mud", ["z"] = 2, ["meta"] = {["inventory"] = {}, ["fields"] = {}}}, {["y"] = 3, ["x"] = 1, ["name"] = "colouredstonebricks:grey", ["z"] = 3, ["meta"] = {["inventory"] = {}, ["fields"] = {}}}, {["y"] = 3, ["x"] = 1, ["name"] = "default:water_source", ["z"] = 4, ["meta"] = {["inventory"] = {}, ["fields"] = {}}, ["param1"] = 29}, {["y"] = 3, ["x"] = 1, ["name"] = "default:water_source", ["z"] = 5, ["meta"] = {["inventory"] = {}, ["fields"] = {}}, ["param1"] = 45}, {["y"] = 3, ["x"] = 1, ["name"] = "default:water_source", ["z"] = 6, ["meta"] = {["inventory"] = {}, ["fields"] = {}}, ["param1"] = 61}, {["y"] = 3, ["x"] = 1, ["name"] = "default:water_source", ["z"] = 7, ["meta"] = {["inventory"] = {}, ["fields"] = {}}, ["param1"] = 77}, {["y"] = 3, ["x"] = 1, ["name"] = "default:water_source", ["z"] = 8, ["meta"] = {["inventory"] = {}, ["fields"] = {}}, ["param1"] = 93}, {["y"] = 3, ["x"] = 1, ["name"] = "default:water_source", ["z"] = 9, ["meta"] = {["inventory"] = {}, ["fields"] = {}}, ["param1"] = 109}, {["y"] = 3, ["x"] = 1, ["name"] = "default:water_source", ["z"] = 10, ["meta"] = {["inventory"] = {}, ["fields"] = {}}, ["param1"] = 93}, {["y"] = 3, ["x"] = 1, ["name"] = "default:water_source", ["z"] = 11, ["meta"] = {["inventory"] = {}, ["fields"] = {}}, ["param1"] = 77}, {["y"] = 3, ["x"] = 1, ["name"] = "default:water_source", ["z"] = 12, ["meta"] = {["inventory"] = {}, ["fields"] = {}}, ["param1"] = 61}, {["y"] = 3, ["x"] = 1, ["name"] = "default:water_source", ["z"] = 13, ["meta"] = {["inventory"] = {}, ["fields"] = {}}, ["param1"] = 45}, {["y"] = 3, ["x"] = 1, ["name"] = "default:water_source", ["z"] = 14, ["meta"] = {["inventory"] = {}, ["fields"] = {}}, ["param1"] = 28}, {["y"] = 3, ["x"] = 1, ["name"] = "default:water_source", ["z"] = 15, ["meta"] = {["inventory"] = {}, ["fields"] = {}}, ["param1"] = 11}, {["y"] = 3, ["x"] = 1, ["name"] = "default:water_source", ["z"] = 16, ["meta"] = {["inventory"] = {}, ["fields"] = {}}, ["param1"] = 10}, {["y"] = 3, ["x"] = 1, ["name"] = "default:water_source", ["z"] = 17, ["meta"] = {["inventory"] = {}, ["fields"] = {}}, ["param1"] = 27}, {["y"] = 3, ["x"] = 1, ["name"] = "default:water_source", ["z"] = 18, ["meta"] = {["inventory"] = {}, ["fields"] = {}}, ["param1"] = 44}, {["y"] = 3, ["x"] = 1, ["name"] = "default:water_source", ["z"] = 19, ["meta"] = {["inventory"] = {}, ["fields"] = {}}, ["param1"] = 61}, {["y"] = 3, ["x"] = 1, ["name"] = "default:water_source", ["z"] = 20, ["meta"] = {["inventory"] = {}, ["fields"] = {}}, ["param1"] = 45}, {["y"] = 3, ["x"] = 1, ["name"] = "default:water_source", ["z"] = 21, ["meta"] = {["inventory"] = {}, ["fields"] = {}}, ["param1"] = 29}, {["y"] = 3, ["x"] = 1, ["name"] = "default:water_source", ["z"] = 22, ["meta"] = {["inventory"] = {}, ["fields"] = {}}, ["param2"] = 240, ["param1"] = 13}, {["y"] = 3, ["x"] = 1, ["name"] = "default:water_source", ["z"] = 23, ["meta"] = {["inventory"] = {}, ["fields"] = {}}, ["param1"] = 13}, {["y"] = 3, ["x"] = 1, ["name"] = "default:water_source", ["z"] = 24, ["meta"] = {["inventory"] = {}, ["fields"] = {}}, ["param1"] = 13}, {["y"] = 3, ["x"] = 1, ["name"] = "default:water_source", ["z"] = 25, ["meta"] = {["inventory"] = {}, ["fields"] = {}}, ["param1"] = 29}, {["y"] = 3, ["x"] = 1, ["name"] = "default:water_source", ["z"] = 26, ["meta"] = {["inventory"] = {}, ["fields"] = {}}, ["param1"] = 45}, {["y"] = 3, ["x"] = 1, ["name"] = "default:water_source", ["z"] = 27, ["meta"] = {["inventory"] = {}, ["fields"] = {}}, ["param1"] = 61}, {["y"] = 4, ["x"] = 1, ["name"] = "default:sand", ["z"] = 0, ["meta"] = {["inventory"] = {}, ["fields"] = {}}}, {["y"] = 4, ["x"] = 1, ["name"] = "default:sand", ["z"] = 1, ["meta"] = {["inventory"] = {}, ["fields"] = {}}}, {["y"] = 4, ["x"] = 1, ["name"] = "default:sand", ["z"] = 2, ["meta"] = {["inventory"] = {}, ["fields"] = {}}}, {["y"] = 4, ["x"] = 1, ["name"] = "colouredstonebricks:grey", ["z"] = 3, ["meta"] = {["inventory"] = {}, ["fields"] = {}}}, {["y"] = 4, ["x"] = 1, ["name"] = "colouredstonebricks:grey", ["z"] = 14, ["meta"] = {["inventory"] = {}, ["fields"] = {}}}, {["y"] = 4, ["x"] = 1, ["name"] = "colouredstonebricks:grey", ["z"] = 15, ["meta"] = {["inventory"] = {}, ["fields"] = {}}}, {["y"] = 4, ["x"] = 1, ["name"] = "colouredstonebricks:grey", ["z"] = 16, ["meta"] = {["inventory"] = {}, ["fields"] = {}}}, {["y"] = 4, ["x"] = 1, ["name"] = "colouredstonebricks:grey", ["z"] = 17, ["meta"] = {["inventory"] = {}, ["fields"] = {}}}, {["y"] = 4, ["x"] = 1, ["name"] = "colouredstonebricks:grey", ["z"] = 18, ["meta"] = {["inventory"] = {}, ["fields"] = {}}}, {["y"] = 4, ["x"] = 1, ["name"] = "flowers:waterlily_675", ["z"] = 23, ["meta"] = {["inventory"] = {}, ["fields"] = {}}, ["param2"] = 3, ["param1"] = 15}, {["y"] = 5, ["x"] = 1, ["name"] = "colouredstonebricks:grey", ["z"] = 3, ["meta"] = {["inventory"] = {}, ["fields"] = {}}}, {["y"] = 5, ["x"] = 1, ["name"] = "darkage:stone_brick", ["z"] = 14, ["meta"] = {["inventory"] = {}, ["fields"] = {}}}, {["y"] = 5, ["x"] = 1, ["name"] = "dryplants:juncus", ["z"] = 15, ["meta"] = {["inventory"] = {}, ["fields"] = {}}, ["param1"] = 45}, {["y"] = 5, ["x"] = 1, ["name"] = "darkage:stone_brick", ["z"] = 18, ["meta"] = {["inventory"] = {}, ["fields"] = {}}}, {["y"] = 0, ["x"] = 2, ["name"] = "default:stone", ["z"] = 0, ["meta"] = {["inventory"] = {}, ["fields"] = {}}}, {["y"] = 0, ["x"] = 2, ["name"] = "default:stone", ["z"] = 1, ["meta"] = {["inventory"] = {}, ["fields"] = {}}}, {["y"] = 0, ["x"] = 2, ["name"] = "default:stone", ["z"] = 2, ["meta"] = {["inventory"] = {}, ["fields"] = {}}}, {["y"] = 0, ["x"] = 2, ["name"] = "default:stone", ["z"] = 3, ["meta"] = {["inventory"] = {}, ["fields"] = {}}}, {["y"] = 0, ["x"] = 2, ["name"] = "default:stone", ["z"] = 4, ["meta"] = {["inventory"] = {}, ["fields"] = {}}}, {["y"] = 0, ["x"] = 2, ["name"] = "default:stone", ["z"] = 5, ["meta"] = {["inventory"] = {}, ["fields"] = {}}}, {["y"] = 0, ["x"] = 2, ["name"] = "default:stone", ["z"] = 6, ["meta"] = {["inventory"] = {}, ["fields"] = {}}}, {["y"] = 0, ["x"] = 2, ["name"] = "default:stone", ["z"] = 7, ["meta"] = {["inventory"] = {}, ["fields"] = {}}}, {["y"] = 0, ["x"] = 2, ["name"] = "default:stone", ["z"] = 8, ["meta"] = {["inventory"] = {}, ["fields"] = {}}}, {["y"] = 0, ["x"] = 2, ["name"] = "moreores:mineral_tin", ["z"] = 9, ["meta"] = {["inventory"] = {}, ["fields"] = {}}}, {["y"] = 0, ["x"] = 2, ["name"] = "default:stone", ["z"] = 10, ["meta"] = {["inventory"] = {}, ["fields"] = {}}}, {["y"] = 0, ["x"] = 2, ["name"] = "default:stone", ["z"] = 11, ["meta"] = {["inventory"] = {}, ["fields"] = {}}}, {["y"] = 0, ["x"] = 2, ["name"] = "default:stone", ["z"] = 12, ["meta"] = {["inventory"] = {}, ["fields"] = {}}}, {["y"] = 0, ["x"] = 2, ["name"] = "default:stone", ["z"] = 13, ["meta"] = {["inventory"] = {}, ["fields"] = {}}}, {["y"] = 0, ["x"] = 2, ["name"] = "default:stone", ["z"] = 14, ["meta"] = {["inventory"] = {}, ["fields"] = {}}}, {["y"] = 0, ["x"] = 2, ["name"] = "default:stone", ["z"] = 15, ["meta"] = {["inventory"] = {}, ["fields"] = {}}}, {["y"] = 0, ["x"] = 2, ["name"] = "default:stone", ["z"] = 16, ["meta"] = {["inventory"] = {}, ["fields"] = {}}}, {["y"] = 0, ["x"] = 2, ["name"] = "default:stone", ["z"] = 17, ["meta"] = {["inventory"] = {}, ["fields"] = {}}}, {["y"] = 0, ["x"] = 2, ["name"] = "default:stone_with_coal", ["z"] = 18, ["meta"] = {["inventory"] = {}, ["fields"] = {}}}, {["y"] = 0, ["x"] = 2, ["name"] = "default:stone", ["z"] = 19, ["meta"] = {["inventory"] = {}, ["fields"] = {}}}, {["y"] = 0, ["x"] = 2, ["name"] = "default:stone", ["z"] = 20, ["meta"] = {["inventory"] = {}, ["fields"] = {}}}, {["y"] = 0, ["x"] = 2, ["name"] = "default:stone", ["z"] = 21, ["meta"] = {["inventory"] = {}, ["fields"] = {}}}, {["y"] = 0, ["x"] = 2, ["name"] = "default:stone", ["z"] = 22, ["meta"] = {["inventory"] = {}, ["fields"] = {}}}, {["y"] = 0, ["x"] = 2, ["name"] = "default:stone", ["z"] = 23, ["meta"] = {["inventory"] = {}, ["fields"] = {}}}, {["y"] = 0, ["x"] = 2, ["name"] = "default:stone", ["z"] = 24, ["meta"] = {["inventory"] = {}, ["fields"] = {}}}, {["y"] = 0, ["x"] = 2, ["name"] = "default:stone", ["z"] = 25, ["meta"] = {["inventory"] = {}, ["fields"] = {}}}, {["y"] = 0, ["x"] = 2, ["name"] = "default:stone", ["z"] = 26, ["meta"] = {["inventory"] = {}, ["fields"] = {}}}, {["y"] = 0, ["x"] = 2, ["name"] = "default:stone", ["z"] = 27, ["meta"] = {["inventory"] = {}, ["fields"] = {}}}, {["y"] = 1, ["x"] = 2, ["name"] = "default:stone", ["z"] = 0, ["meta"] = {["inventory"] = {}, ["fields"] = {}}}, {["y"] = 1, ["x"] = 2, ["name"] = "default:stone", ["z"] = 1, ["meta"] = {["inventory"] = {}, ["fields"] = {}}}, {["y"] = 1, ["x"] = 2, ["name"] = "default:stone", ["z"] = 2, ["meta"] = {["inventory"] = {}, ["fields"] = {}}}, {["y"] = 1, ["x"] = 2, ["name"] = "default:sand", ["z"] = 3, ["meta"] = {["inventory"] = {}, ["fields"] = {}}}, {["y"] = 1, ["x"] = 2, ["name"] = "default:sand", ["z"] = 4, ["meta"] = {["inventory"] = {}, ["fields"] = {}}}, {["y"] = 1, ["x"] = 2, ["name"] = "default:sand", ["z"] = 5, ["meta"] = {["inventory"] = {}, ["fields"] = {}}}, {["y"] = 1, ["x"] = 2, ["name"] = "default:sand", ["z"] = 6, ["meta"] = {["inventory"] = {}, ["fields"] = {}}}, {["y"] = 1, ["x"] = 2, ["name"] = "default:sand", ["z"] = 7, ["meta"] = {["inventory"] = {}, ["fields"] = {}}}, {["y"] = 1, ["x"] = 2, ["name"] = "default:sand", ["z"] = 8, ["meta"] = {["inventory"] = {}, ["fields"] = {}}}, {["y"] = 1, ["x"] = 2, ["name"] = "default:sand", ["z"] = 9, ["meta"] = {["inventory"] = {}, ["fields"] = {}}}, {["y"] = 1, ["x"] = 2, ["name"] = "default:sand", ["z"] = 10, ["meta"] = {["inventory"] = {}, ["fields"] = {}}}, {["y"] = 1, ["x"] = 2, ["name"] = "default:sand", ["z"] = 11, ["meta"] = {["inventory"] = {}, ["fields"] = {}}}, {["y"] = 1, ["x"] = 2, ["name"] = "default:sand", ["z"] = 12, ["meta"] = {["inventory"] = {}, ["fields"] = {}}}, {["y"] = 1, ["x"] = 2, ["name"] = "default:sand", ["z"] = 13, ["meta"] = {["inventory"] = {}, ["fields"] = {}}}, {["y"] = 1, ["x"] = 2, ["name"] = "default:sand", ["z"] = 14, ["meta"] = {["inventory"] = {}, ["fields"] = {}}}, {["y"] = 1, ["x"] = 2, ["name"] = "default:sand", ["z"] = 15, ["meta"] = {["inventory"] = {}, ["fields"] = {}}}, {["y"] = 1, ["x"] = 2, ["name"] = "default:sand", ["z"] = 16, ["meta"] = {["inventory"] = {}, ["fields"] = {}}}, {["y"] = 1, ["x"] = 2, ["name"] = "default:sand", ["z"] = 17, ["meta"] = {["inventory"] = {}, ["fields"] = {}}}, {["y"] = 1, ["x"] = 2, ["name"] = "default:stone", ["z"] = 18, ["meta"] = {["inventory"] = {}, ["fields"] = {}}}, {["y"] = 1, ["x"] = 2, ["name"] = "default:stone", ["z"] = 19, ["meta"] = {["inventory"] = {}, ["fields"] = {}}}, {["y"] = 1, ["x"] = 2, ["name"] = "default:stone", ["z"] = 20, ["meta"] = {["inventory"] = {}, ["fields"] = {}}}, {["y"] = 1, ["x"] = 2, ["name"] = "default:stone", ["z"] = 21, ["meta"] = {["inventory"] = {}, ["fields"] = {}}}, {["y"] = 1, ["x"] = 2, ["name"] = "default:stone", ["z"] = 22, ["meta"] = {["inventory"] = {}, ["fields"] = {}}}, {["y"] = 1, ["x"] = 2, ["name"] = "default:stone", ["z"] = 23, ["meta"] = {["inventory"] = {}, ["fields"] = {}}}, {["y"] = 1, ["x"] = 2, ["name"] = "default:stone", ["z"] = 24, ["meta"] = {["inventory"] = {}, ["fields"] = {}}}, {["y"] = 1, ["x"] = 2, ["name"] = "default:stone", ["z"] = 25, ["meta"] = {["inventory"] = {}, ["fields"] = {}}}, {["y"] = 1, ["x"] = 2, ["name"] = "default:stone", ["z"] = 26, ["meta"] = {["inventory"] = {}, ["fields"] = {}}}, {["y"] = 1, ["x"] = 2, ["name"] = "default:sand", ["z"] = 27, ["meta"] = {["inventory"] = {}, ["fields"] = {}}}, {["y"] = 2, ["x"] = 2, ["name"] = "default:clay", ["z"] = 0, ["meta"] = {["inventory"] = {}, ["fields"] = {}}}, {["y"] = 2, ["x"] = 2, ["name"] = "default:clay", ["z"] = 1, ["meta"] = {["inventory"] = {}, ["fields"] = {}}}, {["y"] = 2, ["x"] = 2, ["name"] = "darkage:silt", ["z"] = 2, ["meta"] = {["inventory"] = {}, ["fields"] = {}}}, {["y"] = 2, ["x"] = 2, ["name"] = "darkage:silt", ["z"] = 3, ["meta"] = {["inventory"] = {}, ["fields"] = {}}}, {["y"] = 2, ["x"] = 2, ["name"] = "default:sand", ["z"] = 4, ["meta"] = {["inventory"] = {}, ["fields"] = {}}}, {["y"] = 2, ["x"] = 2, ["name"] = "default:sand", ["z"] = 5, ["meta"] = {["inventory"] = {}, ["fields"] = {}}}, {["y"] = 2, ["x"] = 2, ["name"] = "default:sand", ["z"] = 6, ["meta"] = {["inventory"] = {}, ["fields"] = {}}}, {["y"] = 2, ["x"] = 2, ["name"] = "default:sand", ["z"] = 7, ["meta"] = {["inventory"] = {}, ["fields"] = {}}}, {["y"] = 2, ["x"] = 2, ["name"] = "default:sand", ["z"] = 8, ["meta"] = {["inventory"] = {}, ["fields"] = {}}}, {["y"] = 2, ["x"] = 2, ["name"] = "default:sand", ["z"] = 9, ["meta"] = {["inventory"] = {}, ["fields"] = {}}}, {["y"] = 2, ["x"] = 2, ["name"] = "default:sand", ["z"] = 10, ["meta"] = {["inventory"] = {}, ["fields"] = {}}}, {["y"] = 2, ["x"] = 2, ["name"] = "default:sand", ["z"] = 11, ["meta"] = {["inventory"] = {}, ["fields"] = {}}}, {["y"] = 2, ["x"] = 2, ["name"] = "default:sand", ["z"] = 12, ["meta"] = {["inventory"] = {}, ["fields"] = {}}}, {["y"] = 2, ["x"] = 2, ["name"] = "default:sand", ["z"] = 13, ["meta"] = {["inventory"] = {}, ["fields"] = {}}}, {["y"] = 2, ["x"] = 2, ["name"] = "default:sand", ["z"] = 14, ["meta"] = {["inventory"] = {}, ["fields"] = {}}}, {["y"] = 2, ["x"] = 2, ["name"] = "default:sand", ["z"] = 15, ["meta"] = {["inventory"] = {}, ["fields"] = {}}}, {["y"] = 2, ["x"] = 2, ["name"] = "default:sand", ["z"] = 16, ["meta"] = {["inventory"] = {}, ["fields"] = {}}}, {["y"] = 2, ["x"] = 2, ["name"] = "default:sand", ["z"] = 17, ["meta"] = {["inventory"] = {}, ["fields"] = {}}}, {["y"] = 2, ["x"] = 2, ["name"] = "default:sand", ["z"] = 18, ["meta"] = {["inventory"] = {}, ["fields"] = {}}}, {["y"] = 2, ["x"] = 2, ["name"] = "default:sand", ["z"] = 19, ["meta"] = {["inventory"] = {}, ["fields"] = {}}}, {["y"] = 2, ["x"] = 2, ["name"] = "default:sand", ["z"] = 20, ["meta"] = {["inventory"] = {}, ["fields"] = {}}}, {["y"] = 2, ["x"] = 2, ["name"] = "default:sand", ["z"] = 21, ["meta"] = {["inventory"] = {}, ["fields"] = {}}}, {["y"] = 2, ["x"] = 2, ["name"] = "default:sand", ["z"] = 22, ["meta"] = {["inventory"] = {}, ["fields"] = {}}}, {["y"] = 2, ["x"] = 2, ["name"] = "default:sand", ["z"] = 23, ["meta"] = {["inventory"] = {}, ["fields"] = {}}}, {["y"] = 2, ["x"] = 2, ["name"] = "default:sand", ["z"] = 24, ["meta"] = {["inventory"] = {}, ["fields"] = {}}}, {["y"] = 2, ["x"] = 2, ["name"] = "default:sand", ["z"] = 25, ["meta"] = {["inventory"] = {}, ["fields"] = {}}}, {["y"] = 2, ["x"] = 2, ["name"] = "default:sand", ["z"] = 26, ["meta"] = {["inventory"] = {}, ["fields"] = {}}}, {["y"] = 2, ["x"] = 2, ["name"] = "default:sand", ["z"] = 27, ["meta"] = {["inventory"] = {}, ["fields"] = {}}}, {["y"] = 3, ["x"] = 2, ["name"] = "default:clay", ["z"] = 0, ["meta"] = {["inventory"] = {}, ["fields"] = {}}}, {["y"] = 3, ["x"] = 2, ["name"] = "default:clay", ["z"] = 1, ["meta"] = {["inventory"] = {}, ["fields"] = {}}}, {["y"] = 3, ["x"] = 2, ["name"] = "darkage:mud", ["z"] = 2, ["meta"] = {["inventory"] = {}, ["fields"] = {}}}, {["y"] = 3, ["x"] = 2, ["name"] = "colouredstonebricks:grey", ["z"] = 3, ["meta"] = {["inventory"] = {}, ["fields"] = {}}}, {["y"] = 3, ["x"] = 2, ["name"] = "default:water_source", ["z"] = 4, ["meta"] = {["inventory"] = {}, ["fields"] = {}}, ["param1"] = 45}, {["y"] = 3, ["x"] = 2, ["name"] = "default:water_source", ["z"] = 5, ["meta"] = {["inventory"] = {}, ["fields"] = {}}, ["param2"] = 240, ["param1"] = 29}, {["y"] = 3, ["x"] = 2, ["name"] = "default:water_source", ["z"] = 6, ["meta"] = {["inventory"] = {}, ["fields"] = {}}, ["param1"] = 45}, {["y"] = 3, ["x"] = 2, ["name"] = "default:water_source", ["z"] = 7, ["meta"] = {["inventory"] = {}, ["fields"] = {}}, ["param1"] = 61}, {["y"] = 3, ["x"] = 2, ["name"] = "default:water_source", ["z"] = 8, ["meta"] = {["inventory"] = {}, ["fields"] = {}}, ["param1"] = 77}, {["y"] = 3, ["x"] = 2, ["name"] = "default:water_source", ["z"] = 9, ["meta"] = {["inventory"] = {}, ["fields"] = {}}, ["param1"] = 93}, {["y"] = 3, ["x"] = 2, ["name"] = "default:water_source", ["z"] = 10, ["meta"] = {["inventory"] = {}, ["fields"] = {}}, ["param1"] = 77}, {["y"] = 3, ["x"] = 2, ["name"] = "default:water_source", ["z"] = 11, ["meta"] = {["inventory"] = {}, ["fields"] = {}}, ["param1"] = 61}, {["y"] = 3, ["x"] = 2, ["name"] = "default:water_source", ["z"] = 12, ["meta"] = {["inventory"] = {}, ["fields"] = {}}, ["param1"] = 45}, {["y"] = 3, ["x"] = 2, ["name"] = "default:water_source", ["z"] = 13, ["meta"] = {["inventory"] = {}, ["fields"] = {}}, ["param1"] = 44}, {["y"] = 3, ["x"] = 2, ["name"] = "default:water_source", ["z"] = 14, ["meta"] = {["inventory"] = {}, ["fields"] = {}}, ["param1"] = 27}, {["y"] = 3, ["x"] = 2, ["name"] = "default:water_source", ["z"] = 15, ["meta"] = {["inventory"] = {}, ["fields"] = {}}, ["param1"] = 10}, {["y"] = 3, ["x"] = 2, ["name"] = "default:water_source", ["z"] = 16, ["meta"] = {["inventory"] = {}, ["fields"] = {}}, ["param1"] = 10}, {["y"] = 3, ["x"] = 2, ["name"] = "default:water_source", ["z"] = 17, ["meta"] = {["inventory"] = {}, ["fields"] = {}}, ["param1"] = 11}, {["y"] = 3, ["x"] = 2, ["name"] = "default:water_source", ["z"] = 18, ["meta"] = {["inventory"] = {}, ["fields"] = {}}, ["param1"] = 28}, {["y"] = 3, ["x"] = 2, ["name"] = "default:water_source", ["z"] = 19, ["meta"] = {["inventory"] = {}, ["fields"] = {}}, ["param1"] = 45}, {["y"] = 3, ["x"] = 2, ["name"] = "default:water_source", ["z"] = 20, ["meta"] = {["inventory"] = {}, ["fields"] = {}}, ["param1"] = 29}, {["y"] = 3, ["x"] = 2, ["name"] = "default:water_source", ["z"] = 21, ["meta"] = {["inventory"] = {}, ["fields"] = {}}, ["param1"] = 13}, {["y"] = 3, ["x"] = 2, ["name"] = "default:water_source", ["z"] = 22, ["meta"] = {["inventory"] = {}, ["fields"] = {}}, ["param1"] = 13}, {["y"] = 3, ["x"] = 2, ["name"] = "default:water_source", ["z"] = 23, ["meta"] = {["inventory"] = {}, ["fields"] = {}}, ["param1"] = 13}, {["y"] = 3, ["x"] = 2, ["name"] = "default:water_source", ["z"] = 24, ["meta"] = {["inventory"] = {}, ["fields"] = {}}, ["param2"] = 240, ["param1"] = 13}, {["y"] = 3, ["x"] = 2, ["name"] = "default:water_source", ["z"] = 25, ["meta"] = {["inventory"] = {}, ["fields"] = {}}, ["param1"] = 13}, {["y"] = 3, ["x"] = 2, ["name"] = "default:water_source", ["z"] = 26, ["meta"] = {["inventory"] = {}, ["fields"] = {}}, ["param1"] = 29}, {["y"] = 3, ["x"] = 2, ["name"] = "default:water_source", ["z"] = 27, ["meta"] = {["inventory"] = {}, ["fields"] = {}}, ["param1"] = 45}, {["y"] = 4, ["x"] = 2, ["name"] = "default:sand", ["z"] = 0, ["meta"] = {["inventory"] = {}, ["fields"] = {}}}, {["y"] = 4, ["x"] = 2, ["name"] = "default:sand", ["z"] = 1, ["meta"] = {["inventory"] = {}, ["fields"] = {}}}, {["y"] = 4, ["x"] = 2, ["name"] = "default:sand", ["z"] = 2, ["meta"] = {["inventory"] = {}, ["fields"] = {}}}, {["y"] = 4, ["x"] = 2, ["name"] = "colouredstonebricks:grey", ["z"] = 3, ["meta"] = {["inventory"] = {}, ["fields"] = {}}}, {["y"] = 4, ["x"] = 2, ["name"] = "flowers:waterlily_225", ["z"] = 6, ["meta"] = {["inventory"] = {}, ["fields"] = {}}, ["param2"] = 3, ["param1"] = 63}, {["y"] = 4, ["x"] = 2, ["name"] = "flowers:waterlily", ["z"] = 13, ["meta"] = {["inventory"] = {}, ["fields"] = {}}, ["param1"] = 61}, {["y"] = 4, ["x"] = 2, ["name"] = "colouredstonebricks:grey", ["z"] = 14, ["meta"] = {["inventory"] = {}, ["fields"] = {}}}, {["y"] = 4, ["x"] = 2, ["name"] = "colouredstonebricks:grey", ["z"] = 15, ["meta"] = {["inventory"] = {}, ["fields"] = {}}}, {["y"] = 4, ["x"] = 2, ["name"] = "colouredstonebricks:grey", ["z"] = 16, ["meta"] = {["inventory"] = {}, ["fields"] = {}}}, {["y"] = 4, ["x"] = 2, ["name"] = "colouredstonebricks:grey", ["z"] = 17, ["meta"] = {["inventory"] = {}, ["fields"] = {}}}, {["y"] = 4, ["x"] = 2, ["name"] = "colouredstonebricks:grey", ["z"] = 18, ["meta"] = {["inventory"] = {}, ["fields"] = {}}}, {["y"] = 4, ["x"] = 2, ["name"] = "flowers:waterlily_45", ["z"] = 27, ["meta"] = {["inventory"] = {}, ["fields"] = {}}, ["param2"] = 1, ["param1"] = 63}, {["y"] = 5, ["x"] = 2, ["name"] = "colouredstonebricks:grey", ["z"] = 3, ["meta"] = {["inventory"] = {}, ["fields"] = {}}}, {["y"] = 5, ["x"] = 2, ["name"] = "darkage:stone_brick", ["z"] = 14, ["meta"] = {["inventory"] = {}, ["fields"] = {}}}, {["y"] = 5, ["x"] = 2, ["name"] = "dryplants:juncus", ["z"] = 15, ["meta"] = {["inventory"] = {}, ["fields"] = {}}, ["param1"] = 45}, {["y"] = 5, ["x"] = 2, ["name"] = "dryplants:juncus_02", ["z"] = 16, ["meta"] = {["inventory"] = {}, ["fields"] = {}}, ["param1"] = 29}, {["y"] = 5, ["x"] = 2, ["name"] = "darkage:stone_brick", ["z"] = 18, ["meta"] = {["inventory"] = {}, ["fields"] = {}}}, {["y"] = 6, ["x"] = 2, ["name"] = "darkage:stone_brick", ["z"] = 14, ["meta"] = {["inventory"] = {}, ["fields"] = {}}}, {["y"] = 6, ["x"] = 2, ["name"] = "darkage:stone_brick", ["z"] = 18, ["meta"] = {["inventory"] = {}, ["fields"] = {}}}, {["y"] = 0, ["x"] = 3, ["name"] = "default:stone", ["z"] = 0, ["meta"] = {["inventory"] = {}, ["fields"] = {}}}, {["y"] = 0, ["x"] = 3, ["name"] = "default:stone", ["z"] = 1, ["meta"] = {["inventory"] = {}, ["fields"] = {}}}, {["y"] = 0, ["x"] = 3, ["name"] = "default:stone", ["z"] = 2, ["meta"] = {["inventory"] = {}, ["fields"] = {}}}, {["y"] = 0, ["x"] = 3, ["name"] = "default:stone", ["z"] = 3, ["meta"] = {["inventory"] = {}, ["fields"] = {}}}, {["y"] = 0, ["x"] = 3, ["name"] = "default:stone", ["z"] = 4, ["meta"] = {["inventory"] = {}, ["fields"] = {}}}, {["y"] = 0, ["x"] = 3, ["name"] = "default:stone", ["z"] = 5, ["meta"] = {["inventory"] = {}, ["fields"] = {}}}, {["y"] = 0, ["x"] = 3, ["name"] = "default:stone", ["z"] = 6, ["meta"] = {["inventory"] = {}, ["fields"] = {}}}, {["y"] = 0, ["x"] = 3, ["name"] = "default:stone", ["z"] = 7, ["meta"] = {["inventory"] = {}, ["fields"] = {}}}, {["y"] = 0, ["x"] = 3, ["name"] = "default:stone", ["z"] = 8, ["meta"] = {["inventory"] = {}, ["fields"] = {}}}, {["y"] = 0, ["x"] = 3, ["name"] = "default:stone", ["z"] = 9, ["meta"] = {["inventory"] = {}, ["fields"] = {}}}, {["y"] = 0, ["x"] = 3, ["name"] = "default:stone", ["z"] = 10, ["meta"] = {["inventory"] = {}, ["fields"] = {}}}, {["y"] = 0, ["x"] = 3, ["name"] = "default:stone", ["z"] = 11, ["meta"] = {["inventory"] = {}, ["fields"] = {}}}, {["y"] = 0, ["x"] = 3, ["name"] = "default:stone", ["z"] = 12, ["meta"] = {["inventory"] = {}, ["fields"] = {}}}, {["y"] = 0, ["x"] = 3, ["name"] = "default:stone", ["z"] = 13, ["meta"] = {["inventory"] = {}, ["fields"] = {}}}, {["y"] = 0, ["x"] = 3, ["name"] = "default:stone", ["z"] = 14, ["meta"] = {["inventory"] = {}, ["fields"] = {}}}, {["y"] = 0, ["x"] = 3, ["name"] = "default:stone", ["z"] = 15, ["meta"] = {["inventory"] = {}, ["fields"] = {}}}, {["y"] = 0, ["x"] = 3, ["name"] = "default:stone", ["z"] = 16, ["meta"] = {["inventory"] = {}, ["fields"] = {}}}, {["y"] = 0, ["x"] = 3, ["name"] = "default:stone", ["z"] = 17, ["meta"] = {["inventory"] = {}, ["fields"] = {}}}, {["y"] = 0, ["x"] = 3, ["name"] = "default:stone", ["z"] = 18, ["meta"] = {["inventory"] = {}, ["fields"] = {}}}, {["y"] = 0, ["x"] = 3, ["name"] = "default:stone", ["z"] = 19, ["meta"] = {["inventory"] = {}, ["fields"] = {}}}, {["y"] = 0, ["x"] = 3, ["name"] = "default:stone", ["z"] = 20, ["meta"] = {["inventory"] = {}, ["fields"] = {}}}, {["y"] = 0, ["x"] = 3, ["name"] = "default:stone", ["z"] = 21, ["meta"] = {["inventory"] = {}, ["fields"] = {}}}, {["y"] = 0, ["x"] = 3, ["name"] = "default:stone", ["z"] = 22, ["meta"] = {["inventory"] = {}, ["fields"] = {}}}, {["y"] = 0, ["x"] = 3, ["name"] = "default:stone", ["z"] = 23, ["meta"] = {["inventory"] = {}, ["fields"] = {}}}, {["y"] = 0, ["x"] = 3, ["name"] = "default:stone", ["z"] = 24, ["meta"] = {["inventory"] = {}, ["fields"] = {}}}, {["y"] = 0, ["x"] = 3, ["name"] = "default:stone", ["z"] = 25, ["meta"] = {["inventory"] = {}, ["fields"] = {}}}, {["y"] = 0, ["x"] = 3, ["name"] = "default:stone", ["z"] = 26, ["meta"] = {["inventory"] = {}, ["fields"] = {}}}, {["y"] = 0, ["x"] = 3, ["name"] = "default:stone", ["z"] = 27, ["meta"] = {["inventory"] = {}, ["fields"] = {}}}, {["y"] = 1, ["x"] = 3, ["name"] = "default:stone", ["z"] = 0, ["meta"] = {["inventory"] = {}, ["fields"] = {}}}, {["y"] = 1, ["x"] = 3, ["name"] = "default:stone", ["z"] = 1, ["meta"] = {["inventory"] = {}, ["fields"] = {}}}, {["y"] = 1, ["x"] = 3, ["name"] = "default:stone", ["z"] = 2, ["meta"] = {["inventory"] = {}, ["fields"] = {}}}, {["y"] = 1, ["x"] = 3, ["name"] = "default:sand", ["z"] = 3, ["meta"] = {["inventory"] = {}, ["fields"] = {}}}, {["y"] = 1, ["x"] = 3, ["name"] = "default:sand", ["z"] = 4, ["meta"] = {["inventory"] = {}, ["fields"] = {}}}, {["y"] = 1, ["x"] = 3, ["name"] = "default:sand", ["z"] = 5, ["meta"] = {["inventory"] = {}, ["fields"] = {}}}, {["y"] = 1, ["x"] = 3, ["name"] = "default:sand", ["z"] = 6, ["meta"] = {["inventory"] = {}, ["fields"] = {}}}, {["y"] = 1, ["x"] = 3, ["name"] = "default:sand", ["z"] = 7, ["meta"] = {["inventory"] = {}, ["fields"] = {}}}, {["y"] = 1, ["x"] = 3, ["name"] = "default:sand", ["z"] = 8, ["meta"] = {["inventory"] = {}, ["fields"] = {}}}, {["y"] = 1, ["x"] = 3, ["name"] = "default:sand", ["z"] = 9, ["meta"] = {["inventory"] = {}, ["fields"] = {}}}, {["y"] = 1, ["x"] = 3, ["name"] = "default:sand", ["z"] = 10, ["meta"] = {["inventory"] = {}, ["fields"] = {}}}, {["y"] = 1, ["x"] = 3, ["name"] = "default:sand", ["z"] = 11, ["meta"] = {["inventory"] = {}, ["fields"] = {}}}, {["y"] = 1, ["x"] = 3, ["name"] = "default:sand", ["z"] = 12, ["meta"] = {["inventory"] = {}, ["fields"] = {}}}, {["y"] = 1, ["x"] = 3, ["name"] = "default:sand", ["z"] = 13, ["meta"] = {["inventory"] = {}, ["fields"] = {}}}, {["y"] = 1, ["x"] = 3, ["name"] = "default:sand", ["z"] = 14, ["meta"] = {["inventory"] = {}, ["fields"] = {}}}, {["y"] = 1, ["x"] = 3, ["name"] = "default:sand", ["z"] = 15, ["meta"] = {["inventory"] = {}, ["fields"] = {}}}, {["y"] = 1, ["x"] = 3, ["name"] = "default:sand", ["z"] = 16, ["meta"] = {["inventory"] = {}, ["fields"] = {}}}, {["y"] = 1, ["x"] = 3, ["name"] = "default:sand", ["z"] = 17, ["meta"] = {["inventory"] = {}, ["fields"] = {}}}, {["y"] = 1, ["x"] = 3, ["name"] = "default:stone", ["z"] = 18, ["meta"] = {["inventory"] = {}, ["fields"] = {}}}, {["y"] = 1, ["x"] = 3, ["name"] = "default:stone", ["z"] = 19, ["meta"] = {["inventory"] = {}, ["fields"] = {}}}, {["y"] = 1, ["x"] = 3, ["name"] = "default:stone", ["z"] = 20, ["meta"] = {["inventory"] = {}, ["fields"] = {}}}, {["y"] = 1, ["x"] = 3, ["name"] = "default:stone", ["z"] = 21, ["meta"] = {["inventory"] = {}, ["fields"] = {}}}, {["y"] = 1, ["x"] = 3, ["name"] = "default:stone", ["z"] = 22, ["meta"] = {["inventory"] = {}, ["fields"] = {}}}, {["y"] = 1, ["x"] = 3, ["name"] = "default:stone_with_coal", ["z"] = 23, ["meta"] = {["inventory"] = {}, ["fields"] = {}}}, {["y"] = 1, ["x"] = 3, ["name"] = "default:stone", ["z"] = 24, ["meta"] = {["inventory"] = {}, ["fields"] = {}}}, {["y"] = 1, ["x"] = 3, ["name"] = "default:stone", ["z"] = 25, ["meta"] = {["inventory"] = {}, ["fields"] = {}}}, {["y"] = 1, ["x"] = 3, ["name"] = "default:stone", ["z"] = 26, ["meta"] = {["inventory"] = {}, ["fields"] = {}}}, {["y"] = 1, ["x"] = 3, ["name"] = "default:sand", ["z"] = 27, ["meta"] = {["inventory"] = {}, ["fields"] = {}}}, {["y"] = 2, ["x"] = 3, ["name"] = "darkage:silt", ["z"] = 0, ["meta"] = {["inventory"] = {}, ["fields"] = {}}}, {["y"] = 2, ["x"] = 3, ["name"] = "darkage:silt", ["z"] = 1, ["meta"] = {["inventory"] = {}, ["fields"] = {}}}, {["y"] = 2, ["x"] = 3, ["name"] = "darkage:silt", ["z"] = 2, ["meta"] = {["inventory"] = {}, ["fields"] = {}}}, {["y"] = 2, ["x"] = 3, ["name"] = "darkage:silt", ["z"] = 3, ["meta"] = {["inventory"] = {}, ["fields"] = {}}}, {["y"] = 2, ["x"] = 3, ["name"] = "default:sand", ["z"] = 4, ["meta"] = {["inventory"] = {}, ["fields"] = {}}}, {["y"] = 2, ["x"] = 3, ["name"] = "default:sand", ["z"] = 5, ["meta"] = {["inventory"] = {}, ["fields"] = {}}}, {["y"] = 2, ["x"] = 3, ["name"] = "default:sand", ["z"] = 6, ["meta"] = {["inventory"] = {}, ["fields"] = {}}}, {["y"] = 2, ["x"] = 3, ["name"] = "default:sand", ["z"] = 7, ["meta"] = {["inventory"] = {}, ["fields"] = {}}}, {["y"] = 2, ["x"] = 3, ["name"] = "default:sand", ["z"] = 8, ["meta"] = {["inventory"] = {}, ["fields"] = {}}}, {["y"] = 2, ["x"] = 3, ["name"] = "default:sand", ["z"] = 9, ["meta"] = {["inventory"] = {}, ["fields"] = {}}}, {["y"] = 2, ["x"] = 3, ["name"] = "default:sand", ["z"] = 10, ["meta"] = {["inventory"] = {}, ["fields"] = {}}}, {["y"] = 2, ["x"] = 3, ["name"] = "default:sand", ["z"] = 11, ["meta"] = {["inventory"] = {}, ["fields"] = {}}}, {["y"] = 2, ["x"] = 3, ["name"] = "default:sand", ["z"] = 12, ["meta"] = {["inventory"] = {}, ["fields"] = {}}}, {["y"] = 2, ["x"] = 3, ["name"] = "default:sand", ["z"] = 13, ["meta"] = {["inventory"] = {}, ["fields"] = {}}}, {["y"] = 2, ["x"] = 3, ["name"] = "default:sand", ["z"] = 14, ["meta"] = {["inventory"] = {}, ["fields"] = {}}}, {["y"] = 2, ["x"] = 3, ["name"] = "default:sand", ["z"] = 15, ["meta"] = {["inventory"] = {}, ["fields"] = {}}}, {["y"] = 2, ["x"] = 3, ["name"] = "default:sand", ["z"] = 16, ["meta"] = {["inventory"] = {}, ["fields"] = {}}}, {["y"] = 2, ["x"] = 3, ["name"] = "default:sand", ["z"] = 17, ["meta"] = {["inventory"] = {}, ["fields"] = {}}}, {["y"] = 2, ["x"] = 3, ["name"] = "default:sand", ["z"] = 18, ["meta"] = {["inventory"] = {}, ["fields"] = {}}}, {["y"] = 2, ["x"] = 3, ["name"] = "default:sand", ["z"] = 19, ["meta"] = {["inventory"] = {}, ["fields"] = {}}}, {["y"] = 2, ["x"] = 3, ["name"] = "default:sand", ["z"] = 20, ["meta"] = {["inventory"] = {}, ["fields"] = {}}}, {["y"] = 2, ["x"] = 3, ["name"] = "default:sand", ["z"] = 21, ["meta"] = {["inventory"] = {}, ["fields"] = {}}}, {["y"] = 2, ["x"] = 3, ["name"] = "default:sand", ["z"] = 22, ["meta"] = {["inventory"] = {}, ["fields"] = {}}}, {["y"] = 2, ["x"] = 3, ["name"] = "default:sand", ["z"] = 23, ["meta"] = {["inventory"] = {}, ["fields"] = {}}}, {["y"] = 2, ["x"] = 3, ["name"] = "default:sand", ["z"] = 24, ["meta"] = {["inventory"] = {}, ["fields"] = {}}}, {["y"] = 2, ["x"] = 3, ["name"] = "default:sand", ["z"] = 25, ["meta"] = {["inventory"] = {}, ["fields"] = {}}}, {["y"] = 2, ["x"] = 3, ["name"] = "default:sand", ["z"] = 26, ["meta"] = {["inventory"] = {}, ["fields"] = {}}}, {["y"] = 2, ["x"] = 3, ["name"] = "default:sand", ["z"] = 27, ["meta"] = {["inventory"] = {}, ["fields"] = {}}}, {["y"] = 3, ["x"] = 3, ["name"] = "darkage:mud", ["z"] = 0, ["meta"] = {["inventory"] = {}, ["fields"] = {}}}, {["y"] = 3, ["x"] = 3, ["name"] = "darkage:mud", ["z"] = 1, ["meta"] = {["inventory"] = {}, ["fields"] = {}}}, {["y"] = 3, ["x"] = 3, ["name"] = "darkage:mud", ["z"] = 2, ["meta"] = {["inventory"] = {}, ["fields"] = {}}}, {["y"] = 3, ["x"] = 3, ["name"] = "colouredstonebricks:grey", ["z"] = 3, ["meta"] = {["inventory"] = {}, ["fields"] = {}}}, {["y"] = 3, ["x"] = 3, ["name"] = "default:water_source", ["z"] = 4, ["meta"] = {["inventory"] = {}, ["fields"] = {}}, ["param1"] = 61}, {["y"] = 3, ["x"] = 3, ["name"] = "default:water_source", ["z"] = 5, ["meta"] = {["inventory"] = {}, ["fields"] = {}}, ["param1"] = 45}, {["y"] = 3, ["x"] = 3, ["name"] = "default:water_source", ["z"] = 6, ["meta"] = {["inventory"] = {}, ["fields"] = {}}, ["param1"] = 29}, {["y"] = 3, ["x"] = 3, ["name"] = "default:water_source", ["z"] = 7, ["meta"] = {["inventory"] = {}, ["fields"] = {}}, ["param1"] = 45}, {["y"] = 3, ["x"] = 3, ["name"] = "default:water_source", ["z"] = 8, ["meta"] = {["inventory"] = {}, ["fields"] = {}}, ["param1"] = 61}, {["y"] = 3, ["x"] = 3, ["name"] = "default:water_source", ["z"] = 9, ["meta"] = {["inventory"] = {}, ["fields"] = {}}, ["param1"] = 77}, {["y"] = 3, ["x"] = 3, ["name"] = "default:water_source", ["z"] = 10, ["meta"] = {["inventory"] = {}, ["fields"] = {}}, ["param1"] = 61}, {["y"] = 3, ["x"] = 3, ["name"] = "default:water_source", ["z"] = 11, ["meta"] = {["inventory"] = {}, ["fields"] = {}}, ["param1"] = 45}, {["y"] = 3, ["x"] = 3, ["name"] = "default:water_source", ["z"] = 12, ["meta"] = {["inventory"] = {}, ["fields"] = {}}, ["param1"] = 45}, {["y"] = 3, ["x"] = 3, ["name"] = "default:water_source", ["z"] = 13, ["meta"] = {["inventory"] = {}, ["fields"] = {}}, ["param1"] = 61}, {["y"] = 3, ["x"] = 3, ["name"] = "default:water_source", ["z"] = 14, ["meta"] = {["inventory"] = {}, ["fields"] = {}}, ["param1"] = 44}, {["y"] = 3, ["x"] = 3, ["name"] = "default:water_source", ["z"] = 15, ["meta"] = {["inventory"] = {}, ["fields"] = {}}, ["param1"] = 27}, {["y"] = 3, ["x"] = 3, ["name"] = "default:water_source", ["z"] = 16, ["meta"] = {["inventory"] = {}, ["fields"] = {}}, ["param2"] = 240, ["param1"] = 10}, {["y"] = 3, ["x"] = 3, ["name"] = "default:water_source", ["z"] = 17, ["meta"] = {["inventory"] = {}, ["fields"] = {}}, ["param1"] = 27}, {["y"] = 3, ["x"] = 3, ["name"] = "default:water_source", ["z"] = 18, ["meta"] = {["inventory"] = {}, ["fields"] = {}}, ["param2"] = 240, ["param1"] = 44}, {["y"] = 3, ["x"] = 3, ["name"] = "default:water_source", ["z"] = 19, ["meta"] = {["inventory"] = {}, ["fields"] = {}}, ["param1"] = 61}, {["y"] = 3, ["x"] = 3, ["name"] = "default:water_source", ["z"] = 20, ["meta"] = {["inventory"] = {}, ["fields"] = {}}, ["param1"] = 45}, {["y"] = 3, ["x"] = 3, ["name"] = "default:water_source", ["z"] = 21, ["meta"] = {["inventory"] = {}, ["fields"] = {}}, ["param1"] = 29}, {["y"] = 3, ["x"] = 3, ["name"] = "default:water_source", ["z"] = 22, ["meta"] = {["inventory"] = {}, ["fields"] = {}}, ["param1"] = 13}, {["y"] = 3, ["x"] = 3, ["name"] = "default:water_source", ["z"] = 23, ["meta"] = {["inventory"] = {}, ["fields"] = {}}, ["param1"] = 13}, {["y"] = 3, ["x"] = 3, ["name"] = "default:water_source", ["z"] = 24, ["meta"] = {["inventory"] = {}, ["fields"] = {}}, ["param2"] = 240, ["param1"] = 13}, {["y"] = 3, ["x"] = 3, ["name"] = "default:water_source", ["z"] = 25, ["meta"] = {["inventory"] = {}, ["fields"] = {}}, ["param1"] = 29}, {["y"] = 3, ["x"] = 3, ["name"] = "default:water_source", ["z"] = 26, ["meta"] = {["inventory"] = {}, ["fields"] = {}}, ["param1"] = 45}, {["y"] = 3, ["x"] = 3, ["name"] = "default:water_source", ["z"] = 27, ["meta"] = {["inventory"] = {}, ["fields"] = {}}, ["param1"] = 61}, {["y"] = 4, ["x"] = 3, ["name"] = "default:sand", ["z"] = 0, ["meta"] = {["inventory"] = {}, ["fields"] = {}}}, {["y"] = 4, ["x"] = 3, ["name"] = "default:sand", ["z"] = 1, ["meta"] = {["inventory"] = {}, ["fields"] = {}}}, {["y"] = 4, ["x"] = 3, ["name"] = "default:sand", ["z"] = 2, ["meta"] = {["inventory"] = {}, ["fields"] = {}}}, {["y"] = 4, ["x"] = 3, ["name"] = "colouredstonebricks:grey", ["z"] = 3, ["meta"] = {["inventory"] = {}, ["fields"] = {}}}, {["y"] = 4, ["x"] = 3, ["name"] = "flowers:waterlily_s4", ["z"] = 4, ["meta"] = {["inventory"] = {}, ["fields"] = {}}, ["param2"] = 1, ["param1"] = 79}, {["y"] = 4, ["x"] = 3, ["name"] = "flowers:waterlily_45", ["z"] = 10, ["meta"] = {["inventory"] = {}, ["fields"] = {}}, ["param1"] = 79}, {["y"] = 4, ["x"] = 3, ["name"] = "colouredstonebricks:grey", ["z"] = 14, ["meta"] = {["inventory"] = {}, ["fields"] = {}}}, {["y"] = 4, ["x"] = 3, ["name"] = "colouredstonebricks:grey", ["z"] = 15, ["meta"] = {["inventory"] = {}, ["fields"] = {}}}, {["y"] = 4, ["x"] = 3, ["name"] = "colouredstonebricks:grey", ["z"] = 16, ["meta"] = {["inventory"] = {}, ["fields"] = {}}}, {["y"] = 4, ["x"] = 3, ["name"] = "colouredstonebricks:grey", ["z"] = 17, ["meta"] = {["inventory"] = {}, ["fields"] = {}}}, {["y"] = 4, ["x"] = 3, ["name"] = "colouredstonebricks:grey", ["z"] = 18, ["meta"] = {["inventory"] = {}, ["fields"] = {}}}, {["y"] = 4, ["x"] = 3, ["name"] = "flowers:waterlily_675", ["z"] = 19, ["meta"] = {["inventory"] = {}, ["fields"] = {}}, ["param1"] = 79}, {["y"] = 4, ["x"] = 3, ["name"] = "flowers:waterlily_s3", ["z"] = 21, ["meta"] = {["inventory"] = {}, ["fields"] = {}}, ["param1"] = 47}, {["y"] = 4, ["x"] = 3, ["name"] = "flowers:waterlily_s1", ["z"] = 23, ["meta"] = {["inventory"] = {}, ["fields"] = {}}, ["param2"] = 3, ["param1"] = 15}, {["y"] = 5, ["x"] = 3, ["name"] = "colouredstonebricks:grey", ["z"] = 3, ["meta"] = {["inventory"] = {}, ["fields"] = {}}}, {["y"] = 5, ["x"] = 3, ["name"] = "darkage:stone_brick", ["z"] = 14, ["meta"] = {["inventory"] = {}, ["fields"] = {}}}, {["y"] = 5, ["x"] = 3, ["name"] = "dryplants:juncus_02", ["z"] = 16, ["meta"] = {["inventory"] = {}, ["fields"] = {}}, ["param1"] = 45}, {["y"] = 5, ["x"] = 3, ["name"] = "darkage:stone_brick", ["z"] = 18, ["meta"] = {["inventory"] = {}, ["fields"] = {}}}, {["y"] = 0, ["x"] = 4, ["name"] = "default:stone", ["z"] = 0, ["meta"] = {["inventory"] = {}, ["fields"] = {}}}, {["y"] = 0, ["x"] = 4, ["name"] = "default:stone", ["z"] = 1, ["meta"] = {["inventory"] = {}, ["fields"] = {}}}, {["y"] = 0, ["x"] = 4, ["name"] = "default:stone", ["z"] = 2, ["meta"] = {["inventory"] = {}, ["fields"] = {}}}, {["y"] = 0, ["x"] = 4, ["name"] = "default:stone", ["z"] = 3, ["meta"] = {["inventory"] = {}, ["fields"] = {}}}, {["y"] = 0, ["x"] = 4, ["name"] = "default:stone", ["z"] = 4, ["meta"] = {["inventory"] = {}, ["fields"] = {}}}, {["y"] = 0, ["x"] = 4, ["name"] = "default:stone", ["z"] = 5, ["meta"] = {["inventory"] = {}, ["fields"] = {}}}, {["y"] = 0, ["x"] = 4, ["name"] = "default:stone", ["z"] = 6, ["meta"] = {["inventory"] = {}, ["fields"] = {}}}, {["y"] = 0, ["x"] = 4, ["name"] = "default:stone", ["z"] = 7, ["meta"] = {["inventory"] = {}, ["fields"] = {}}}, {["y"] = 0, ["x"] = 4, ["name"] = "default:stone", ["z"] = 8, ["meta"] = {["inventory"] = {}, ["fields"] = {}}}, {["y"] = 0, ["x"] = 4, ["name"] = "default:stone", ["z"] = 9, ["meta"] = {["inventory"] = {}, ["fields"] = {}}}, {["y"] = 0, ["x"] = 4, ["name"] = "default:stone", ["z"] = 10, ["meta"] = {["inventory"] = {}, ["fields"] = {}}}, {["y"] = 0, ["x"] = 4, ["name"] = "default:stone", ["z"] = 11, ["meta"] = {["inventory"] = {}, ["fields"] = {}}}, {["y"] = 0, ["x"] = 4, ["name"] = "default:stone", ["z"] = 12, ["meta"] = {["inventory"] = {}, ["fields"] = {}}}, {["y"] = 0, ["x"] = 4, ["name"] = "default:stone", ["z"] = 13, ["meta"] = {["inventory"] = {}, ["fields"] = {}}}, {["y"] = 0, ["x"] = 4, ["name"] = "default:stone", ["z"] = 14, ["meta"] = {["inventory"] = {}, ["fields"] = {}}}, {["y"] = 0, ["x"] = 4, ["name"] = "default:stone", ["z"] = 15, ["meta"] = {["inventory"] = {}, ["fields"] = {}}}, {["y"] = 0, ["x"] = 4, ["name"] = "default:stone", ["z"] = 16, ["meta"] = {["inventory"] = {}, ["fields"] = {}}}, {["y"] = 0, ["x"] = 4, ["name"] = "default:stone", ["z"] = 17, ["meta"] = {["inventory"] = {}, ["fields"] = {}}}, {["y"] = 0, ["x"] = 4, ["name"] = "default:stone", ["z"] = 18, ["meta"] = {["inventory"] = {}, ["fields"] = {}}}, {["y"] = 0, ["x"] = 4, ["name"] = "default:stone_with_coal", ["z"] = 19, ["meta"] = {["inventory"] = {}, ["fields"] = {}}}, {["y"] = 0, ["x"] = 4, ["name"] = "default:stone", ["z"] = 20, ["meta"] = {["inventory"] = {}, ["fields"] = {}}}, {["y"] = 0, ["x"] = 4, ["name"] = "default:stone_with_coal", ["z"] = 21, ["meta"] = {["inventory"] = {}, ["fields"] = {}}}, {["y"] = 0, ["x"] = 4, ["name"] = "default:stone", ["z"] = 22, ["meta"] = {["inventory"] = {}, ["fields"] = {}}}, {["y"] = 0, ["x"] = 4, ["name"] = "default:stone", ["z"] = 23, ["meta"] = {["inventory"] = {}, ["fields"] = {}}}, {["y"] = 0, ["x"] = 4, ["name"] = "moreores:mineral_tin", ["z"] = 24, ["meta"] = {["inventory"] = {}, ["fields"] = {}}}, {["y"] = 0, ["x"] = 4, ["name"] = "default:stone", ["z"] = 25, ["meta"] = {["inventory"] = {}, ["fields"] = {}}}, {["y"] = 0, ["x"] = 4, ["name"] = "default:stone", ["z"] = 26, ["meta"] = {["inventory"] = {}, ["fields"] = {}}}, {["y"] = 0, ["x"] = 4, ["name"] = "default:stone", ["z"] = 27, ["meta"] = {["inventory"] = {}, ["fields"] = {}}}, {["y"] = 1, ["x"] = 4, ["name"] = "default:stone", ["z"] = 0, ["meta"] = {["inventory"] = {}, ["fields"] = {}}}, {["y"] = 1, ["x"] = 4, ["name"] = "default:stone", ["z"] = 1, ["meta"] = {["inventory"] = {}, ["fields"] = {}}}, {["y"] = 1, ["x"] = 4, ["name"] = "default:stone", ["z"] = 2, ["meta"] = {["inventory"] = {}, ["fields"] = {}}}, {["y"] = 1, ["x"] = 4, ["name"] = "default:sand", ["z"] = 3, ["meta"] = {["inventory"] = {}, ["fields"] = {}}}, {["y"] = 1, ["x"] = 4, ["name"] = "default:sand", ["z"] = 4, ["meta"] = {["inventory"] = {}, ["fields"] = {}}}, {["y"] = 1, ["x"] = 4, ["name"] = "default:sand", ["z"] = 5, ["meta"] = {["inventory"] = {}, ["fields"] = {}}}, {["y"] = 1, ["x"] = 4, ["name"] = "default:sand", ["z"] = 6, ["meta"] = {["inventory"] = {}, ["fields"] = {}}}, {["y"] = 1, ["x"] = 4, ["name"] = "default:sand", ["z"] = 7, ["meta"] = {["inventory"] = {}, ["fields"] = {}}}, {["y"] = 1, ["x"] = 4, ["name"] = "default:sand", ["z"] = 8, ["meta"] = {["inventory"] = {}, ["fields"] = {}}}, {["y"] = 1, ["x"] = 4, ["name"] = "default:sand", ["z"] = 9, ["meta"] = {["inventory"] = {}, ["fields"] = {}}}, {["y"] = 1, ["x"] = 4, ["name"] = "default:sand", ["z"] = 10, ["meta"] = {["inventory"] = {}, ["fields"] = {}}}, {["y"] = 1, ["x"] = 4, ["name"] = "default:sand", ["z"] = 11, ["meta"] = {["inventory"] = {}, ["fields"] = {}}}, {["y"] = 1, ["x"] = 4, ["name"] = "default:sand", ["z"] = 12, ["meta"] = {["inventory"] = {}, ["fields"] = {}}}, {["y"] = 1, ["x"] = 4, ["name"] = "default:sand", ["z"] = 13, ["meta"] = {["inventory"] = {}, ["fields"] = {}}}, {["y"] = 1, ["x"] = 4, ["name"] = "default:sand", ["z"] = 14, ["meta"] = {["inventory"] = {}, ["fields"] = {}}}, {["y"] = 1, ["x"] = 4, ["name"] = "default:sand", ["z"] = 15, ["meta"] = {["inventory"] = {}, ["fields"] = {}}}, {["y"] = 1, ["x"] = 4, ["name"] = "default:sand", ["z"] = 16, ["meta"] = {["inventory"] = {}, ["fields"] = {}}}, {["y"] = 1, ["x"] = 4, ["name"] = "default:stone", ["z"] = 17, ["meta"] = {["inventory"] = {}, ["fields"] = {}}}, {["y"] = 1, ["x"] = 4, ["name"] = "default:stone", ["z"] = 18, ["meta"] = {["inventory"] = {}, ["fields"] = {}}}, {["y"] = 1, ["x"] = 4, ["name"] = "default:stone", ["z"] = 19, ["meta"] = {["inventory"] = {}, ["fields"] = {}}}, {["y"] = 1, ["x"] = 4, ["name"] = "default:stone", ["z"] = 20, ["meta"] = {["inventory"] = {}, ["fields"] = {}}}, {["y"] = 1, ["x"] = 4, ["name"] = "default:stone", ["z"] = 21, ["meta"] = {["inventory"] = {}, ["fields"] = {}}}, {["y"] = 1, ["x"] = 4, ["name"] = "default:stone", ["z"] = 22, ["meta"] = {["inventory"] = {}, ["fields"] = {}}}, {["y"] = 1, ["x"] = 4, ["name"] = "default:stone", ["z"] = 23, ["meta"] = {["inventory"] = {}, ["fields"] = {}}}, {["y"] = 1, ["x"] = 4, ["name"] = "default:stone", ["z"] = 24, ["meta"] = {["inventory"] = {}, ["fields"] = {}}}, {["y"] = 1, ["x"] = 4, ["name"] = "default:stone", ["z"] = 25, ["meta"] = {["inventory"] = {}, ["fields"] = {}}}, {["y"] = 1, ["x"] = 4, ["name"] = "default:stone", ["z"] = 26, ["meta"] = {["inventory"] = {}, ["fields"] = {}}}, {["y"] = 1, ["x"] = 4, ["name"] = "default:stone", ["z"] = 27, ["meta"] = {["inventory"] = {}, ["fields"] = {}}}, {["y"] = 2, ["x"] = 4, ["name"] = "darkage:silt", ["z"] = 0, ["meta"] = {["inventory"] = {}, ["fields"] = {}}}, {["y"] = 2, ["x"] = 4, ["name"] = "darkage:silt", ["z"] = 1, ["meta"] = {["inventory"] = {}, ["fields"] = {}}}, {["y"] = 2, ["x"] = 4, ["name"] = "darkage:silt", ["z"] = 2, ["meta"] = {["inventory"] = {}, ["fields"] = {}}}, {["y"] = 2, ["x"] = 4, ["name"] = "darkage:silt", ["z"] = 3, ["meta"] = {["inventory"] = {}, ["fields"] = {}}}, {["y"] = 2, ["x"] = 4, ["name"] = "default:sand", ["z"] = 4, ["meta"] = {["inventory"] = {}, ["fields"] = {}}}, {["y"] = 2, ["x"] = 4, ["name"] = "default:sand", ["z"] = 5, ["meta"] = {["inventory"] = {}, ["fields"] = {}}}, {["y"] = 2, ["x"] = 4, ["name"] = "default:sand", ["z"] = 6, ["meta"] = {["inventory"] = {}, ["fields"] = {}}}, {["y"] = 2, ["x"] = 4, ["name"] = "default:sand", ["z"] = 7, ["meta"] = {["inventory"] = {}, ["fields"] = {}}}, {["y"] = 2, ["x"] = 4, ["name"] = "default:sand", ["z"] = 8, ["meta"] = {["inventory"] = {}, ["fields"] = {}}}, {["y"] = 2, ["x"] = 4, ["name"] = "default:sand", ["z"] = 9, ["meta"] = {["inventory"] = {}, ["fields"] = {}}}, {["y"] = 2, ["x"] = 4, ["name"] = "default:sand", ["z"] = 10, ["meta"] = {["inventory"] = {}, ["fields"] = {}}}, {["y"] = 2, ["x"] = 4, ["name"] = "default:sand", ["z"] = 11, ["meta"] = {["inventory"] = {}, ["fields"] = {}}}, {["y"] = 2, ["x"] = 4, ["name"] = "default:sand", ["z"] = 12, ["meta"] = {["inventory"] = {}, ["fields"] = {}}}, {["y"] = 2, ["x"] = 4, ["name"] = "default:sand", ["z"] = 13, ["meta"] = {["inventory"] = {}, ["fields"] = {}}}, {["y"] = 2, ["x"] = 4, ["name"] = "default:sand", ["z"] = 14, ["meta"] = {["inventory"] = {}, ["fields"] = {}}}, {["y"] = 2, ["x"] = 4, ["name"] = "default:sand", ["z"] = 15, ["meta"] = {["inventory"] = {}, ["fields"] = {}}}, {["y"] = 2, ["x"] = 4, ["name"] = "default:sand", ["z"] = 16, ["meta"] = {["inventory"] = {}, ["fields"] = {}}}, {["y"] = 2, ["x"] = 4, ["name"] = "default:sand", ["z"] = 17, ["meta"] = {["inventory"] = {}, ["fields"] = {}}}, {["y"] = 2, ["x"] = 4, ["name"] = "default:sand", ["z"] = 18, ["meta"] = {["inventory"] = {}, ["fields"] = {}}}, {["y"] = 2, ["x"] = 4, ["name"] = "default:sand", ["z"] = 19, ["meta"] = {["inventory"] = {}, ["fields"] = {}}}, {["y"] = 2, ["x"] = 4, ["name"] = "default:sand", ["z"] = 20, ["meta"] = {["inventory"] = {}, ["fields"] = {}}}, {["y"] = 2, ["x"] = 4, ["name"] = "default:sand", ["z"] = 21, ["meta"] = {["inventory"] = {}, ["fields"] = {}}}, {["y"] = 2, ["x"] = 4, ["name"] = "default:sand", ["z"] = 22, ["meta"] = {["inventory"] = {}, ["fields"] = {}}}, {["y"] = 2, ["x"] = 4, ["name"] = "default:sand", ["z"] = 23, ["meta"] = {["inventory"] = {}, ["fields"] = {}}}, {["y"] = 2, ["x"] = 4, ["name"] = "default:sand", ["z"] = 24, ["meta"] = {["inventory"] = {}, ["fields"] = {}}}, {["y"] = 2, ["x"] = 4, ["name"] = "default:sand", ["z"] = 25, ["meta"] = {["inventory"] = {}, ["fields"] = {}}}, {["y"] = 2, ["x"] = 4, ["name"] = "default:sand", ["z"] = 26, ["meta"] = {["inventory"] = {}, ["fields"] = {}}}, {["y"] = 2, ["x"] = 4, ["name"] = "default:sand", ["z"] = 27, ["meta"] = {["inventory"] = {}, ["fields"] = {}}}, {["y"] = 3, ["x"] = 4, ["name"] = "darkage:mud", ["z"] = 0, ["meta"] = {["inventory"] = {}, ["fields"] = {}}}, {["y"] = 3, ["x"] = 4, ["name"] = "darkage:mud", ["z"] = 1, ["meta"] = {["inventory"] = {}, ["fields"] = {}}}, {["y"] = 3, ["x"] = 4, ["name"] = "darkage:mud", ["z"] = 2, ["meta"] = {["inventory"] = {}, ["fields"] = {}}}, {["y"] = 3, ["x"] = 4, ["name"] = "colouredstonebricks:grey", ["z"] = 3, ["meta"] = {["inventory"] = {}, ["fields"] = {}}}, {["y"] = 3, ["x"] = 4, ["name"] = "default:water_source", ["z"] = 4, ["meta"] = {["inventory"] = {}, ["fields"] = {}}, ["param1"] = 77}, {["y"] = 3, ["x"] = 4, ["name"] = "default:water_source", ["z"] = 5, ["meta"] = {["inventory"] = {}, ["fields"] = {}}, ["param1"] = 61}, {["y"] = 3, ["x"] = 4, ["name"] = "default:water_source", ["z"] = 6, ["meta"] = {["inventory"] = {}, ["fields"] = {}}, ["param1"] = 45}, {["y"] = 3, ["x"] = 4, ["name"] = "default:water_source", ["z"] = 7, ["meta"] = {["inventory"] = {}, ["fields"] = {}}, ["param1"] = 29}, {["y"] = 3, ["x"] = 4, ["name"] = "default:water_source", ["z"] = 8, ["meta"] = {["inventory"] = {}, ["fields"] = {}}, ["param1"] = 45}, {["y"] = 3, ["x"] = 4, ["name"] = "default:water_source", ["z"] = 9, ["meta"] = {["inventory"] = {}, ["fields"] = {}}, ["param1"] = 61}, {["y"] = 3, ["x"] = 4, ["name"] = "default:water_source", ["z"] = 10, ["meta"] = {["inventory"] = {}, ["fields"] = {}}, ["param1"] = 45}, {["y"] = 3, ["x"] = 4, ["name"] = "default:water_source", ["z"] = 11, ["meta"] = {["inventory"] = {}, ["fields"] = {}}, ["param1"] = 45}, {["y"] = 3, ["x"] = 4, ["name"] = "default:water_source", ["z"] = 12, ["meta"] = {["inventory"] = {}, ["fields"] = {}}, ["param1"] = 61}, {["y"] = 3, ["x"] = 4, ["name"] = "default:water_source", ["z"] = 13, ["meta"] = {["inventory"] = {}, ["fields"] = {}}, ["param1"] = 77}, {["y"] = 3, ["x"] = 4, ["name"] = "default:water_source", ["z"] = 14, ["meta"] = {["inventory"] = {}, ["fields"] = {}}, ["param2"] = 240, ["param1"] = 60}, {["y"] = 3, ["x"] = 4, ["name"] = "default:water_source", ["z"] = 15, ["meta"] = {["inventory"] = {}, ["fields"] = {}}, ["param1"] = 43}, {["y"] = 3, ["x"] = 4, ["name"] = "default:water_source", ["z"] = 16, ["meta"] = {["inventory"] = {}, ["fields"] = {}}, ["param1"] = 26}, {["y"] = 3, ["x"] = 4, ["name"] = "default:water_source", ["z"] = 17, ["meta"] = {["inventory"] = {}, ["fields"] = {}}, ["param1"] = 43}, {["y"] = 3, ["x"] = 4, ["name"] = "default:water_source", ["z"] = 18, ["meta"] = {["inventory"] = {}, ["fields"] = {}}, ["param1"] = 60}, {["y"] = 3, ["x"] = 4, ["name"] = "default:water_source", ["z"] = 19, ["meta"] = {["inventory"] = {}, ["fields"] = {}}, ["param1"] = 77}, {["y"] = 3, ["x"] = 4, ["name"] = "default:water_source", ["z"] = 20, ["meta"] = {["inventory"] = {}, ["fields"] = {}}, ["param1"] = 61}, {["y"] = 3, ["x"] = 4, ["name"] = "default:water_source", ["z"] = 21, ["meta"] = {["inventory"] = {}, ["fields"] = {}}, ["param1"] = 45}, {["y"] = 3, ["x"] = 4, ["name"] = "default:water_source", ["z"] = 22, ["meta"] = {["inventory"] = {}, ["fields"] = {}}, ["param1"] = 29}, {["y"] = 3, ["x"] = 4, ["name"] = "default:water_source", ["z"] = 23, ["meta"] = {["inventory"] = {}, ["fields"] = {}}, ["param1"] = 13}, {["y"] = 3, ["x"] = 4, ["name"] = "default:water_source", ["z"] = 24, ["meta"] = {["inventory"] = {}, ["fields"] = {}}, ["param1"] = 29}, {["y"] = 3, ["x"] = 4, ["name"] = "default:water_source", ["z"] = 25, ["meta"] = {["inventory"] = {}, ["fields"] = {}}, ["param2"] = 240, ["param1"] = 45}, {["y"] = 3, ["x"] = 4, ["name"] = "default:water_source", ["z"] = 26, ["meta"] = {["inventory"] = {}, ["fields"] = {}}, ["param1"] = 61}, {["y"] = 3, ["x"] = 4, ["name"] = "default:water_source", ["z"] = 27, ["meta"] = {["inventory"] = {}, ["fields"] = {}}, ["param1"] = 77}, {["y"] = 4, ["x"] = 4, ["name"] = "default:sand", ["z"] = 0, ["meta"] = {["inventory"] = {}, ["fields"] = {}}}, {["y"] = 4, ["x"] = 4, ["name"] = "default:sand", ["z"] = 1, ["meta"] = {["inventory"] = {}, ["fields"] = {}}}, {["y"] = 4, ["x"] = 4, ["name"] = "default:sand", ["z"] = 2, ["meta"] = {["inventory"] = {}, ["fields"] = {}}}, {["y"] = 4, ["x"] = 4, ["name"] = "colouredstonebricks:grey", ["z"] = 3, ["meta"] = {["inventory"] = {}, ["fields"] = {}}}, {["y"] = 4, ["x"] = 4, ["name"] = "flowers:waterlily_s4", ["z"] = 8, ["meta"] = {["inventory"] = {}, ["fields"] = {}}, ["param2"] = 2, ["param1"] = 63}, {["y"] = 4, ["x"] = 4, ["name"] = "colouredstonebricks:grey", ["z"] = 14, ["meta"] = {["inventory"] = {}, ["fields"] = {}}}, {["y"] = 4, ["x"] = 4, ["name"] = "colouredstonebricks:grey", ["z"] = 15, ["meta"] = {["inventory"] = {}, ["fields"] = {}}}, {["y"] = 4, ["x"] = 4, ["name"] = "colouredstonebricks:grey", ["z"] = 16, ["meta"] = {["inventory"] = {}, ["fields"] = {}}}, {["y"] = 4, ["x"] = 4, ["name"] = "colouredstonebricks:grey", ["z"] = 17, ["meta"] = {["inventory"] = {}, ["fields"] = {}}}, {["y"] = 4, ["x"] = 4, ["name"] = "colouredstonebricks:grey", ["z"] = 18, ["meta"] = {["inventory"] = {}, ["fields"] = {}}}, {["y"] = 5, ["x"] = 4, ["name"] = "dryplants:juncus_02", ["z"] = 1, ["meta"] = {["inventory"] = {}, ["fields"] = {}}, ["param1"] = 61}, {["y"] = 5, ["x"] = 4, ["name"] = "colouredstonebricks:grey", ["z"] = 3, ["meta"] = {["inventory"] = {}, ["fields"] = {}}}, {["y"] = 5, ["x"] = 4, ["name"] = "darkage:stone_brick", ["z"] = 14, ["meta"] = {["inventory"] = {}, ["fields"] = {}}}, {["y"] = 5, ["x"] = 4, ["name"] = "darkage:stone_brick", ["z"] = 18, ["meta"] = {["inventory"] = {}, ["fields"] = {}}}, {["y"] = 6, ["x"] = 4, ["name"] = "dryplants:juncus", ["z"] = 1, ["meta"] = {["inventory"] = {}, ["fields"] = {}}, ["param1"] = 77}, {["y"] = 6, ["x"] = 4, ["name"] = "dryplants:juncus", ["z"] = 14, ["meta"] = {["inventory"] = {}, ["fields"] = {}}, ["param1"] = 109}, {["y"] = 0, ["x"] = 5, ["name"] = "default:stone", ["z"] = 0, ["meta"] = {["inventory"] = {}, ["fields"] = {}}}, {["y"] = 0, ["x"] = 5, ["name"] = "default:stone", ["z"] = 1, ["meta"] = {["inventory"] = {}, ["fields"] = {}}}, {["y"] = 0, ["x"] = 5, ["name"] = "default:stone", ["z"] = 2, ["meta"] = {["inventory"] = {}, ["fields"] = {}}}, {["y"] = 0, ["x"] = 5, ["name"] = "default:stone", ["z"] = 3, ["meta"] = {["inventory"] = {}, ["fields"] = {}}}, {["y"] = 0, ["x"] = 5, ["name"] = "default:stone", ["z"] = 4, ["meta"] = {["inventory"] = {}, ["fields"] = {}}}, {["y"] = 0, ["x"] = 5, ["name"] = "default:stone", ["z"] = 5, ["meta"] = {["inventory"] = {}, ["fields"] = {}}}, {["y"] = 0, ["x"] = 5, ["name"] = "default:sand", ["z"] = 6, ["meta"] = {["inventory"] = {}, ["fields"] = {}}}, {["y"] = 0, ["x"] = 5, ["name"] = "default:stone", ["z"] = 7, ["meta"] = {["inventory"] = {}, ["fields"] = {}}}, {["y"] = 0, ["x"] = 5, ["name"] = "default:stone", ["z"] = 8, ["meta"] = {["inventory"] = {}, ["fields"] = {}}}, {["y"] = 0, ["x"] = 5, ["name"] = "default:stone", ["z"] = 9, ["meta"] = {["inventory"] = {}, ["fields"] = {}}}, {["y"] = 0, ["x"] = 5, ["name"] = "default:stone", ["z"] = 10, ["meta"] = {["inventory"] = {}, ["fields"] = {}}}, {["y"] = 0, ["x"] = 5, ["name"] = "default:stone", ["z"] = 11, ["meta"] = {["inventory"] = {}, ["fields"] = {}}}, {["y"] = 0, ["x"] = 5, ["name"] = "default:stone", ["z"] = 12, ["meta"] = {["inventory"] = {}, ["fields"] = {}}}, {["y"] = 0, ["x"] = 5, ["name"] = "default:stone", ["z"] = 13, ["meta"] = {["inventory"] = {}, ["fields"] = {}}}, {["y"] = 0, ["x"] = 5, ["name"] = "default:stone", ["z"] = 14, ["meta"] = {["inventory"] = {}, ["fields"] = {}}}, {["y"] = 0, ["x"] = 5, ["name"] = "default:stone", ["z"] = 15, ["meta"] = {["inventory"] = {}, ["fields"] = {}}}, {["y"] = 0, ["x"] = 5, ["name"] = "default:stone", ["z"] = 16, ["meta"] = {["inventory"] = {}, ["fields"] = {}}}, {["y"] = 0, ["x"] = 5, ["name"] = "default:stone", ["z"] = 17, ["meta"] = {["inventory"] = {}, ["fields"] = {}}}, {["y"] = 0, ["x"] = 5, ["name"] = "default:stone", ["z"] = 18, ["meta"] = {["inventory"] = {}, ["fields"] = {}}}, {["y"] = 0, ["x"] = 5, ["name"] = "default:stone", ["z"] = 19, ["meta"] = {["inventory"] = {}, ["fields"] = {}}}, {["y"] = 0, ["x"] = 5, ["name"] = "default:stone", ["z"] = 20, ["meta"] = {["inventory"] = {}, ["fields"] = {}}}, {["y"] = 0, ["x"] = 5, ["name"] = "default:stone", ["z"] = 21, ["meta"] = {["inventory"] = {}, ["fields"] = {}}}, {["y"] = 0, ["x"] = 5, ["name"] = "default:stone", ["z"] = 22, ["meta"] = {["inventory"] = {}, ["fields"] = {}}}, {["y"] = 0, ["x"] = 5, ["name"] = "default:stone", ["z"] = 23, ["meta"] = {["inventory"] = {}, ["fields"] = {}}}, {["y"] = 0, ["x"] = 5, ["name"] = "default:stone", ["z"] = 24, ["meta"] = {["inventory"] = {}, ["fields"] = {}}}, {["y"] = 0, ["x"] = 5, ["name"] = "default:stone", ["z"] = 25, ["meta"] = {["inventory"] = {}, ["fields"] = {}}}, {["y"] = 0, ["x"] = 5, ["name"] = "default:stone", ["z"] = 26, ["meta"] = {["inventory"] = {}, ["fields"] = {}}}, {["y"] = 0, ["x"] = 5, ["name"] = "default:stone", ["z"] = 27, ["meta"] = {["inventory"] = {}, ["fields"] = {}}}, {["y"] = 1, ["x"] = 5, ["name"] = "default:stone", ["z"] = 0, ["meta"] = {["inventory"] = {}, ["fields"] = {}}}, {["y"] = 1, ["x"] = 5, ["name"] = "default:stone", ["z"] = 1, ["meta"] = {["inventory"] = {}, ["fields"] = {}}}, {["y"] = 1, ["x"] = 5, ["name"] = "default:stone", ["z"] = 2, ["meta"] = {["inventory"] = {}, ["fields"] = {}}}, {["y"] = 1, ["x"] = 5, ["name"] = "default:sand", ["z"] = 3, ["meta"] = {["inventory"] = {}, ["fields"] = {}}}, {["y"] = 1, ["x"] = 5, ["name"] = "default:sand", ["z"] = 4, ["meta"] = {["inventory"] = {}, ["fields"] = {}}}, {["y"] = 1, ["x"] = 5, ["name"] = "default:sand", ["z"] = 5, ["meta"] = {["inventory"] = {}, ["fields"] = {}}}, {["y"] = 1, ["x"] = 5, ["name"] = "default:sand", ["z"] = 6, ["meta"] = {["inventory"] = {}, ["fields"] = {}}}, {["y"] = 1, ["x"] = 5, ["name"] = "default:sand", ["z"] = 7, ["meta"] = {["inventory"] = {}, ["fields"] = {}}}, {["y"] = 1, ["x"] = 5, ["name"] = "default:sand", ["z"] = 8, ["meta"] = {["inventory"] = {}, ["fields"] = {}}}, {["y"] = 1, ["x"] = 5, ["name"] = "default:sand", ["z"] = 9, ["meta"] = {["inventory"] = {}, ["fields"] = {}}}, {["y"] = 1, ["x"] = 5, ["name"] = "default:sand", ["z"] = 10, ["meta"] = {["inventory"] = {}, ["fields"] = {}}}, {["y"] = 1, ["x"] = 5, ["name"] = "default:sand", ["z"] = 11, ["meta"] = {["inventory"] = {}, ["fields"] = {}}}, {["y"] = 1, ["x"] = 5, ["name"] = "default:sand", ["z"] = 12, ["meta"] = {["inventory"] = {}, ["fields"] = {}}}, {["y"] = 1, ["x"] = 5, ["name"] = "default:sand", ["z"] = 13, ["meta"] = {["inventory"] = {}, ["fields"] = {}}}, {["y"] = 1, ["x"] = 5, ["name"] = "default:sand", ["z"] = 14, ["meta"] = {["inventory"] = {}, ["fields"] = {}}}, {["y"] = 1, ["x"] = 5, ["name"] = "default:sand", ["z"] = 15, ["meta"] = {["inventory"] = {}, ["fields"] = {}}}, {["y"] = 1, ["x"] = 5, ["name"] = "default:sand", ["z"] = 16, ["meta"] = {["inventory"] = {}, ["fields"] = {}}}, {["y"] = 1, ["x"] = 5, ["name"] = "default:stone", ["z"] = 17, ["meta"] = {["inventory"] = {}, ["fields"] = {}}}, {["y"] = 1, ["x"] = 5, ["name"] = "default:stone", ["z"] = 18, ["meta"] = {["inventory"] = {}, ["fields"] = {}}}, {["y"] = 1, ["x"] = 5, ["name"] = "default:stone", ["z"] = 19, ["meta"] = {["inventory"] = {}, ["fields"] = {}}}, {["y"] = 1, ["x"] = 5, ["name"] = "default:stone", ["z"] = 20, ["meta"] = {["inventory"] = {}, ["fields"] = {}}}, {["y"] = 1, ["x"] = 5, ["name"] = "default:stone", ["z"] = 21, ["meta"] = {["inventory"] = {}, ["fields"] = {}}}, {["y"] = 1, ["x"] = 5, ["name"] = "default:stone", ["z"] = 22, ["meta"] = {["inventory"] = {}, ["fields"] = {}}}, {["y"] = 1, ["x"] = 5, ["name"] = "default:stone", ["z"] = 23, ["meta"] = {["inventory"] = {}, ["fields"] = {}}}, {["y"] = 1, ["x"] = 5, ["name"] = "default:stone", ["z"] = 24, ["meta"] = {["inventory"] = {}, ["fields"] = {}}}, {["y"] = 1, ["x"] = 5, ["name"] = "default:stone", ["z"] = 25, ["meta"] = {["inventory"] = {}, ["fields"] = {}}}, {["y"] = 1, ["x"] = 5, ["name"] = "default:stone", ["z"] = 26, ["meta"] = {["inventory"] = {}, ["fields"] = {}}}, {["y"] = 1, ["x"] = 5, ["name"] = "default:stone", ["z"] = 27, ["meta"] = {["inventory"] = {}, ["fields"] = {}}}, {["y"] = 2, ["x"] = 5, ["name"] = "darkage:silt", ["z"] = 0, ["meta"] = {["inventory"] = {}, ["fields"] = {}}}, {["y"] = 2, ["x"] = 5, ["name"] = "darkage:silt", ["z"] = 1, ["meta"] = {["inventory"] = {}, ["fields"] = {}}}, {["y"] = 2, ["x"] = 5, ["name"] = "darkage:silt", ["z"] = 2, ["meta"] = {["inventory"] = {}, ["fields"] = {}}}, {["y"] = 2, ["x"] = 5, ["name"] = "darkage:silt", ["z"] = 3, ["meta"] = {["inventory"] = {}, ["fields"] = {}}}, {["y"] = 2, ["x"] = 5, ["name"] = "default:sand", ["z"] = 4, ["meta"] = {["inventory"] = {}, ["fields"] = {}}}, {["y"] = 2, ["x"] = 5, ["name"] = "default:sand", ["z"] = 5, ["meta"] = {["inventory"] = {}, ["fields"] = {}}}, {["y"] = 2, ["x"] = 5, ["name"] = "default:sand", ["z"] = 6, ["meta"] = {["inventory"] = {}, ["fields"] = {}}}, {["y"] = 2, ["x"] = 5, ["name"] = "default:sand", ["z"] = 7, ["meta"] = {["inventory"] = {}, ["fields"] = {}}}, {["y"] = 2, ["x"] = 5, ["name"] = "default:sand", ["z"] = 8, ["meta"] = {["inventory"] = {}, ["fields"] = {}}}, {["y"] = 2, ["x"] = 5, ["name"] = "default:sand", ["z"] = 9, ["meta"] = {["inventory"] = {}, ["fields"] = {}}}, {["y"] = 2, ["x"] = 5, ["name"] = "default:sand", ["z"] = 10, ["meta"] = {["inventory"] = {}, ["fields"] = {}}}, {["y"] = 2, ["x"] = 5, ["name"] = "default:sand", ["z"] = 11, ["meta"] = {["inventory"] = {}, ["fields"] = {}}}, {["y"] = 2, ["x"] = 5, ["name"] = "default:sand", ["z"] = 12, ["meta"] = {["inventory"] = {}, ["fields"] = {}}}, {["y"] = 2, ["x"] = 5, ["name"] = "default:sand", ["z"] = 13, ["meta"] = {["inventory"] = {}, ["fields"] = {}}}, {["y"] = 2, ["x"] = 5, ["name"] = "default:sand", ["z"] = 14, ["meta"] = {["inventory"] = {}, ["fields"] = {}}}, {["y"] = 2, ["x"] = 5, ["name"] = "default:sand", ["z"] = 15, ["meta"] = {["inventory"] = {}, ["fields"] = {}}}, {["y"] = 2, ["x"] = 5, ["name"] = "default:sand", ["z"] = 16, ["meta"] = {["inventory"] = {}, ["fields"] = {}}}, {["y"] = 2, ["x"] = 5, ["name"] = "default:sand", ["z"] = 17, ["meta"] = {["inventory"] = {}, ["fields"] = {}}}, {["y"] = 2, ["x"] = 5, ["name"] = "default:sand", ["z"] = 18, ["meta"] = {["inventory"] = {}, ["fields"] = {}}}, {["y"] = 2, ["x"] = 5, ["name"] = "default:sand", ["z"] = 19, ["meta"] = {["inventory"] = {}, ["fields"] = {}}}, {["y"] = 2, ["x"] = 5, ["name"] = "default:sand", ["z"] = 20, ["meta"] = {["inventory"] = {}, ["fields"] = {}}}, {["y"] = 2, ["x"] = 5, ["name"] = "default:sand", ["z"] = 21, ["meta"] = {["inventory"] = {}, ["fields"] = {}}}, {["y"] = 2, ["x"] = 5, ["name"] = "default:sand", ["z"] = 22, ["meta"] = {["inventory"] = {}, ["fields"] = {}}}, {["y"] = 2, ["x"] = 5, ["name"] = "default:sand", ["z"] = 23, ["meta"] = {["inventory"] = {}, ["fields"] = {}}}, {["y"] = 2, ["x"] = 5, ["name"] = "default:sand", ["z"] = 24, ["meta"] = {["inventory"] = {}, ["fields"] = {}}}, {["y"] = 2, ["x"] = 5, ["name"] = "default:sand", ["z"] = 25, ["meta"] = {["inventory"] = {}, ["fields"] = {}}}, {["y"] = 2, ["x"] = 5, ["name"] = "default:sand", ["z"] = 26, ["meta"] = {["inventory"] = {}, ["fields"] = {}}}, {["y"] = 2, ["x"] = 5, ["name"] = "default:sand", ["z"] = 27, ["meta"] = {["inventory"] = {}, ["fields"] = {}}}, {["y"] = 3, ["x"] = 5, ["name"] = "darkage:mud", ["z"] = 0, ["meta"] = {["inventory"] = {}, ["fields"] = {}}}, {["y"] = 3, ["x"] = 5, ["name"] = "darkage:mud", ["z"] = 1, ["meta"] = {["inventory"] = {}, ["fields"] = {}}}, {["y"] = 3, ["x"] = 5, ["name"] = "darkage:mud", ["z"] = 2, ["meta"] = {["inventory"] = {}, ["fields"] = {}}}, {["y"] = 3, ["x"] = 5, ["name"] = "colouredstonebricks:grey", ["z"] = 3, ["meta"] = {["inventory"] = {}, ["fields"] = {}}}, {["y"] = 3, ["x"] = 5, ["name"] = "default:water_source", ["z"] = 4, ["meta"] = {["inventory"] = {}, ["fields"] = {}}, ["param2"] = 240, ["param1"] = 93}, {["y"] = 3, ["x"] = 5, ["name"] = "default:water_source", ["z"] = 5, ["meta"] = {["inventory"] = {}, ["fields"] = {}}, ["param1"] = 77}, {["y"] = 3, ["x"] = 5, ["name"] = "default:water_source", ["z"] = 6, ["meta"] = {["inventory"] = {}, ["fields"] = {}}, ["param1"] = 61}, {["y"] = 3, ["x"] = 5, ["name"] = "default:water_source", ["z"] = 7, ["meta"] = {["inventory"] = {}, ["fields"] = {}}, ["param1"] = 45}, {["y"] = 3, ["x"] = 5, ["name"] = "default:water_source", ["z"] = 8, ["meta"] = {["inventory"] = {}, ["fields"] = {}}, ["param1"] = 29}, {["y"] = 3, ["x"] = 5, ["name"] = "default:water_source", ["z"] = 9, ["meta"] = {["inventory"] = {}, ["fields"] = {}}, ["param1"] = 45}, {["y"] = 3, ["x"] = 5, ["name"] = "default:water_source", ["z"] = 10, ["meta"] = {["inventory"] = {}, ["fields"] = {}}, ["param1"] = 45}, {["y"] = 3, ["x"] = 5, ["name"] = "default:water_source", ["z"] = 11, ["meta"] = {["inventory"] = {}, ["fields"] = {}}, ["param1"] = 61}, {["y"] = 3, ["x"] = 5, ["name"] = "default:water_source", ["z"] = 12, ["meta"] = {["inventory"] = {}, ["fields"] = {}}, ["param1"] = 77}, {["y"] = 3, ["x"] = 5, ["name"] = "default:water_source", ["z"] = 13, ["meta"] = {["inventory"] = {}, ["fields"] = {}}, ["param1"] = 93}, {["y"] = 3, ["x"] = 5, ["name"] = "default:water_source", ["z"] = 14, ["meta"] = {["inventory"] = {}, ["fields"] = {}}, ["param1"] = 76}, {["y"] = 3, ["x"] = 5, ["name"] = "default:water_source", ["z"] = 15, ["meta"] = {["inventory"] = {}, ["fields"] = {}}, ["param1"] = 59}, {["y"] = 3, ["x"] = 5, ["name"] = "default:water_source", ["z"] = 16, ["meta"] = {["inventory"] = {}, ["fields"] = {}}, ["param1"] = 42}, {["y"] = 3, ["x"] = 5, ["name"] = "default:water_source", ["z"] = 17, ["meta"] = {["inventory"] = {}, ["fields"] = {}}, ["param1"] = 59}, {["y"] = 3, ["x"] = 5, ["name"] = "default:water_source", ["z"] = 18, ["meta"] = {["inventory"] = {}, ["fields"] = {}}, ["param1"] = 76}, {["y"] = 3, ["x"] = 5, ["name"] = "default:water_source", ["z"] = 19, ["meta"] = {["inventory"] = {}, ["fields"] = {}}, ["param1"] = 93}, {["y"] = 3, ["x"] = 5, ["name"] = "default:water_source", ["z"] = 20, ["meta"] = {["inventory"] = {}, ["fields"] = {}}, ["param1"] = 77}, {["y"] = 3, ["x"] = 5, ["name"] = "default:water_source", ["z"] = 21, ["meta"] = {["inventory"] = {}, ["fields"] = {}}, ["param1"] = 61}, {["y"] = 3, ["x"] = 5, ["name"] = "default:water_source", ["z"] = 22, ["meta"] = {["inventory"] = {}, ["fields"] = {}}, ["param1"] = 45}, {["y"] = 3, ["x"] = 5, ["name"] = "default:water_source", ["z"] = 23, ["meta"] = {["inventory"] = {}, ["fields"] = {}}, ["param1"] = 29}, {["y"] = 3, ["x"] = 5, ["name"] = "default:water_source", ["z"] = 24, ["meta"] = {["inventory"] = {}, ["fields"] = {}}, ["param1"] = 29}, {["y"] = 3, ["x"] = 5, ["name"] = "default:water_source", ["z"] = 25, ["meta"] = {["inventory"] = {}, ["fields"] = {}}, ["param1"] = 45}, {["y"] = 3, ["x"] = 5, ["name"] = "default:water_source", ["z"] = 26, ["meta"] = {["inventory"] = {}, ["fields"] = {}}, ["param1"] = 61}, {["y"] = 3, ["x"] = 5, ["name"] = "default:water_source", ["z"] = 27, ["meta"] = {["inventory"] = {}, ["fields"] = {}}, ["param1"] = 77}, {["y"] = 4, ["x"] = 5, ["name"] = "default:sand", ["z"] = 0, ["meta"] = {["inventory"] = {}, ["fields"] = {}}}, {["y"] = 4, ["x"] = 5, ["name"] = "default:sand", ["z"] = 1, ["meta"] = {["inventory"] = {}, ["fields"] = {}}}, {["y"] = 4, ["x"] = 5, ["name"] = "default:sand", ["z"] = 2, ["meta"] = {["inventory"] = {}, ["fields"] = {}}}, {["y"] = 4, ["x"] = 5, ["name"] = "colouredstonebricks:grey", ["z"] = 3, ["meta"] = {["inventory"] = {}, ["fields"] = {}}}, {["y"] = 4, ["x"] = 5, ["name"] = "flowers:waterlily_s2", ["z"] = 9, ["meta"] = {["inventory"] = {}, ["fields"] = {}}, ["param1"] = 63}, {["y"] = 4, ["x"] = 5, ["name"] = "flowers:waterlily_s4", ["z"] = 13, ["meta"] = {["inventory"] = {}, ["fields"] = {}}, ["param2"] = 1, ["param1"] = 111}, {["y"] = 4, ["x"] = 5, ["name"] = "colouredstonebricks:grey", ["z"] = 14, ["meta"] = {["inventory"] = {}, ["fields"] = {}}}, {["y"] = 4, ["x"] = 5, ["name"] = "colouredstonebricks:grey", ["z"] = 15, ["meta"] = {["inventory"] = {}, ["fields"] = {}}}, {["y"] = 4, ["x"] = 5, ["name"] = "colouredstonebricks:grey", ["z"] = 16, ["meta"] = {["inventory"] = {}, ["fields"] = {}}}, {["y"] = 4, ["x"] = 5, ["name"] = "colouredstonebricks:grey", ["z"] = 17, ["meta"] = {["inventory"] = {}, ["fields"] = {}}}, {["y"] = 4, ["x"] = 5, ["name"] = "colouredstonebricks:grey", ["z"] = 18, ["meta"] = {["inventory"] = {}, ["fields"] = {}}}, {["y"] = 4, ["x"] = 5, ["name"] = "flowers:waterlily_s1", ["z"] = 20, ["meta"] = {["inventory"] = {}, ["fields"] = {}}, ["param1"] = 95}, {["y"] = 4, ["x"] = 5, ["name"] = "flowers:waterlily_675", ["z"] = 22, ["meta"] = {["inventory"] = {}, ["fields"] = {}}, ["param2"] = 1, ["param1"] = 63}, {["y"] = 4, ["x"] = 5, ["name"] = "flowers:waterlily_s3", ["z"] = 26, ["meta"] = {["inventory"] = {}, ["fields"] = {}}, ["param1"] = 79}, {["y"] = 5, ["x"] = 5, ["name"] = "colouredstonebricks:grey", ["z"] = 3, ["meta"] = {["inventory"] = {}, ["fields"] = {}}}, {["y"] = 5, ["x"] = 5, ["name"] = "darkage:stone_brick", ["z"] = 14, ["meta"] = {["inventory"] = {}, ["fields"] = {}}}, {["y"] = 5, ["x"] = 5, ["name"] = "dryplants:juncus", ["z"] = 15, ["meta"] = {["inventory"] = {}, ["fields"] = {}}, ["param1"] = 93}, {["y"] = 5, ["x"] = 5, ["name"] = "darkage:stone_brick", ["z"] = 18, ["meta"] = {["inventory"] = {}, ["fields"] = {}}}, {["y"] = 6, ["x"] = 5, ["name"] = "dryplants:juncus", ["z"] = 15, ["meta"] = {["inventory"] = {}, ["fields"] = {}}, ["param1"] = 109}, {["y"] = 22, ["x"] = 5, ["name"] = "coloredwood:wood_dark_orange_s50", ["z"] = 0, ["meta"] = {["inventory"] = {}, ["fields"] = {}}, ["param1"] = 156}, {["y"] = 23, ["x"] = 5, ["name"] = "colouredstonebricks:white", ["z"] = 0, ["meta"] = {["inventory"] = {}, ["fields"] = {}}}, {["y"] = 24, ["x"] = 5, ["name"] = "colouredstonebricks:white", ["z"] = 0, ["meta"] = {["inventory"] = {}, ["fields"] = {}}}, {["y"] = 25, ["x"] = 5, ["name"] = "colouredstonebricks:white", ["z"] = 0, ["meta"] = {["inventory"] = {}, ["fields"] = {}}}, {["y"] = 0, ["x"] = 6, ["name"] = "default:stone", ["z"] = 0, ["meta"] = {["inventory"] = {}, ["fields"] = {}}}, {["y"] = 0, ["x"] = 6, ["name"] = "default:stone", ["z"] = 1, ["meta"] = {["inventory"] = {}, ["fields"] = {}}}, {["y"] = 0, ["x"] = 6, ["name"] = "default:stone", ["z"] = 2, ["meta"] = {["inventory"] = {}, ["fields"] = {}}}, {["y"] = 0, ["x"] = 6, ["name"] = "default:stone", ["z"] = 3, ["meta"] = {["inventory"] = {}, ["fields"] = {}}}, {["y"] = 0, ["x"] = 6, ["name"] = "default:stone", ["z"] = 4, ["meta"] = {["inventory"] = {}, ["fields"] = {}}}, {["y"] = 0, ["x"] = 6, ["name"] = "default:stone", ["z"] = 5, ["meta"] = {["inventory"] = {}, ["fields"] = {}}}, {["y"] = 0, ["x"] = 6, ["name"] = "default:stone", ["z"] = 6, ["meta"] = {["inventory"] = {}, ["fields"] = {}}}, {["y"] = 0, ["x"] = 6, ["name"] = "default:stone", ["z"] = 7, ["meta"] = {["inventory"] = {}, ["fields"] = {}}}, {["y"] = 0, ["x"] = 6, ["name"] = "default:stone", ["z"] = 8, ["meta"] = {["inventory"] = {}, ["fields"] = {}}}, {["y"] = 0, ["x"] = 6, ["name"] = "default:stone", ["z"] = 9, ["meta"] = {["inventory"] = {}, ["fields"] = {}}}, {["y"] = 0, ["x"] = 6, ["name"] = "default:stone", ["z"] = 10, ["meta"] = {["inventory"] = {}, ["fields"] = {}}}, {["y"] = 0, ["x"] = 6, ["name"] = "default:stone", ["z"] = 11, ["meta"] = {["inventory"] = {}, ["fields"] = {}}}, {["y"] = 0, ["x"] = 6, ["name"] = "default:stone", ["z"] = 12, ["meta"] = {["inventory"] = {}, ["fields"] = {}}}, {["y"] = 0, ["x"] = 6, ["name"] = "default:stone", ["z"] = 13, ["meta"] = {["inventory"] = {}, ["fields"] = {}}}, {["y"] = 0, ["x"] = 6, ["name"] = "default:stone", ["z"] = 14, ["meta"] = {["inventory"] = {}, ["fields"] = {}}}, {["y"] = 0, ["x"] = 6, ["name"] = "default:stone", ["z"] = 15, ["meta"] = {["inventory"] = {}, ["fields"] = {}}}, {["y"] = 0, ["x"] = 6, ["name"] = "default:stone", ["z"] = 16, ["meta"] = {["inventory"] = {}, ["fields"] = {}}}, {["y"] = 0, ["x"] = 6, ["name"] = "default:stone", ["z"] = 17, ["meta"] = {["inventory"] = {}, ["fields"] = {}}}, {["y"] = 0, ["x"] = 6, ["name"] = "default:stone", ["z"] = 18, ["meta"] = {["inventory"] = {}, ["fields"] = {}}}, {["y"] = 0, ["x"] = 6, ["name"] = "default:stone", ["z"] = 19, ["meta"] = {["inventory"] = {}, ["fields"] = {}}}, {["y"] = 0, ["x"] = 6, ["name"] = "default:stone", ["z"] = 20, ["meta"] = {["inventory"] = {}, ["fields"] = {}}}, {["y"] = 0, ["x"] = 6, ["name"] = "default:stone", ["z"] = 21, ["meta"] = {["inventory"] = {}, ["fields"] = {}}}, {["y"] = 0, ["x"] = 6, ["name"] = "default:stone", ["z"] = 22, ["meta"] = {["inventory"] = {}, ["fields"] = {}}}, {["y"] = 0, ["x"] = 6, ["name"] = "default:stone", ["z"] = 23, ["meta"] = {["inventory"] = {}, ["fields"] = {}}}, {["y"] = 0, ["x"] = 6, ["name"] = "default:stone", ["z"] = 24, ["meta"] = {["inventory"] = {}, ["fields"] = {}}}, {["y"] = 0, ["x"] = 6, ["name"] = "default:stone", ["z"] = 25, ["meta"] = {["inventory"] = {}, ["fields"] = {}}}, {["y"] = 0, ["x"] = 6, ["name"] = "default:stone", ["z"] = 26, ["meta"] = {["inventory"] = {}, ["fields"] = {}}}, {["y"] = 0, ["x"] = 6, ["name"] = "default:stone", ["z"] = 27, ["meta"] = {["inventory"] = {}, ["fields"] = {}}}, {["y"] = 1, ["x"] = 6, ["name"] = "default:stone", ["z"] = 0, ["meta"] = {["inventory"] = {}, ["fields"] = {}}}, {["y"] = 1, ["x"] = 6, ["name"] = "default:stone", ["z"] = 1, ["meta"] = {["inventory"] = {}, ["fields"] = {}}}, {["y"] = 1, ["x"] = 6, ["name"] = "default:sand", ["z"] = 2, ["meta"] = {["inventory"] = {}, ["fields"] = {}}}, {["y"] = 1, ["x"] = 6, ["name"] = "default:sand", ["z"] = 3, ["meta"] = {["inventory"] = {}, ["fields"] = {}}}, {["y"] = 1, ["x"] = 6, ["name"] = "default:sand", ["z"] = 4, ["meta"] = {["inventory"] = {}, ["fields"] = {}}}, {["y"] = 1, ["x"] = 6, ["name"] = "default:sand", ["z"] = 5, ["meta"] = {["inventory"] = {}, ["fields"] = {}}}, {["y"] = 1, ["x"] = 6, ["name"] = "default:sand", ["z"] = 6, ["meta"] = {["inventory"] = {}, ["fields"] = {}}}, {["y"] = 1, ["x"] = 6, ["name"] = "default:sand", ["z"] = 7, ["meta"] = {["inventory"] = {}, ["fields"] = {}}}, {["y"] = 1, ["x"] = 6, ["name"] = "default:sand", ["z"] = 8, ["meta"] = {["inventory"] = {}, ["fields"] = {}}}, {["y"] = 1, ["x"] = 6, ["name"] = "default:sand", ["z"] = 9, ["meta"] = {["inventory"] = {}, ["fields"] = {}}}, {["y"] = 1, ["x"] = 6, ["name"] = "default:sand", ["z"] = 10, ["meta"] = {["inventory"] = {}, ["fields"] = {}}}, {["y"] = 1, ["x"] = 6, ["name"] = "default:sand", ["z"] = 11, ["meta"] = {["inventory"] = {}, ["fields"] = {}}}, {["y"] = 1, ["x"] = 6, ["name"] = "default:sand", ["z"] = 12, ["meta"] = {["inventory"] = {}, ["fields"] = {}}}, {["y"] = 1, ["x"] = 6, ["name"] = "default:sand", ["z"] = 13, ["meta"] = {["inventory"] = {}, ["fields"] = {}}}, {["y"] = 1, ["x"] = 6, ["name"] = "default:sand", ["z"] = 14, ["meta"] = {["inventory"] = {}, ["fields"] = {}}}, {["y"] = 1, ["x"] = 6, ["name"] = "default:sand", ["z"] = 15, ["meta"] = {["inventory"] = {}, ["fields"] = {}}}, {["y"] = 1, ["x"] = 6, ["name"] = "default:stone", ["z"] = 16, ["meta"] = {["inventory"] = {}, ["fields"] = {}}}, {["y"] = 1, ["x"] = 6, ["name"] = "default:stone", ["z"] = 17, ["meta"] = {["inventory"] = {}, ["fields"] = {}}}, {["y"] = 1, ["x"] = 6, ["name"] = "default:stone", ["z"] = 18, ["meta"] = {["inventory"] = {}, ["fields"] = {}}}, {["y"] = 1, ["x"] = 6, ["name"] = "default:stone", ["z"] = 19, ["meta"] = {["inventory"] = {}, ["fields"] = {}}}, {["y"] = 1, ["x"] = 6, ["name"] = "default:stone", ["z"] = 20, ["meta"] = {["inventory"] = {}, ["fields"] = {}}}, {["y"] = 1, ["x"] = 6, ["name"] = "default:stone", ["z"] = 21, ["meta"] = {["inventory"] = {}, ["fields"] = {}}}, {["y"] = 1, ["x"] = 6, ["name"] = "default:stone", ["z"] = 22, ["meta"] = {["inventory"] = {}, ["fields"] = {}}}, {["y"] = 1, ["x"] = 6, ["name"] = "default:stone", ["z"] = 23, ["meta"] = {["inventory"] = {}, ["fields"] = {}}}, {["y"] = 1, ["x"] = 6, ["name"] = "default:stone", ["z"] = 24, ["meta"] = {["inventory"] = {}, ["fields"] = {}}}, {["y"] = 1, ["x"] = 6, ["name"] = "default:stone", ["z"] = 25, ["meta"] = {["inventory"] = {}, ["fields"] = {}}}, {["y"] = 1, ["x"] = 6, ["name"] = "default:stone", ["z"] = 26, ["meta"] = {["inventory"] = {}, ["fields"] = {}}},