return { { ["y"] = 0, ["x"] = 0, ["name"] = "default:water_flowing", ["z"] = 0, ["meta"] = { ["inventory"] = {  }, ["fields"] = {  } }, ["param2"] = 7, ["param1"] = 111 }, { ["y"] = 0, ["x"] = 0, ["name"] = "default:stone", ["z"] = 1, ["meta"] = { ["inventory"] = {  }, ["fields"] = {  } }, ["param2"] = 0, ["param1"] = 0 }, { ["y"] = 0, ["x"] = 0, ["name"] = "default:stone", ["z"] = 2, ["meta"] = { ["inventory"] = {  }, ["fields"] = {  } }, ["param2"] = 0, ["param1"] = 0 }, { ["y"] = 0, ["x"] = 0, ["name"] = "default:sand", ["z"] = 3, ["meta"] = { ["inventory"] = {  }, ["fields"] = {  } }, ["param2"] = 0, ["param1"] = 0 }, { ["y"] = 0, ["x"] = 0, ["name"] = "default:sand", ["z"] = 4, ["meta"] = { ["inventory"] = {  }, ["fields"] = {  } }, ["param2"] = 0, ["param1"] = 0 }, { ["y"] = 0, ["x"] = 0, ["name"] = "default:sand", ["z"] = 5, ["meta"] = { ["inventory"] = {  }, ["fields"] = {  } }, ["param2"] = 0, ["param1"] = 0 }, { ["y"] = 0, ["x"] = 0, ["name"] = "default:sand", ["z"] = 6, ["meta"] = { ["inventory"] = {  }, ["fields"] = {  } }, ["param2"] = 0, ["param1"] = 0 }, { ["y"] = 0, ["x"] = 0, ["name"] = "default:sand", ["z"] = 7, ["meta"] = { ["inventory"] = {  }, ["fields"] = {  } }, ["param2"] = 0, ["param1"] = 0 }, { ["y"] = 0, ["x"] = 0, ["name"] = "default:sand", ["z"] = 8, ["meta"] = { ["inventory"] = {  }, ["fields"] = {  } }, ["param2"] = 0, ["param1"] = 0 }, { ["y"] = 0, ["x"] = 0, ["name"] = "default:sand", ["z"] = 9, ["meta"] = { ["inventory"] = {  }, ["fields"] = {  } }, ["param2"] = 0, ["param1"] = 0 }, { ["y"] = 0, ["x"] = 0, ["name"] = "default:sand", ["z"] = 10, ["meta"] = { ["inventory"] = {  }, ["fields"] = {  } }, ["param2"] = 0, ["param1"] = 0 }, { ["y"] = 0, ["x"] = 0, ["name"] = "default:sand", ["z"] = 11, ["meta"] = { ["inventory"] = {  }, ["fields"] = {  } }, ["param2"] = 0, ["param1"] = 0 }, { ["y"] = 0, ["x"] = 0, ["name"] = "default:sand", ["z"] = 12, ["meta"] = { ["inventory"] = {  }, ["fields"] = {  } }, ["param2"] = 0, ["param1"] = 0 }, { ["y"] = 0, ["x"] = 0, ["name"] = "default:sand", ["z"] = 13, ["meta"] = { ["inventory"] = {  }, ["fields"] = {  } }, ["param2"] = 0, ["param1"] = 0 }, { ["y"] = 0, ["x"] = 0, ["name"] = "default:sand", ["z"] = 14, ["meta"] = { ["inventory"] = {  }, ["fields"] = {  } }, ["param2"] = 0, ["param1"] = 0 }, { ["y"] = 0, ["x"] = 0, ["name"] = "default:sand", ["z"] = 15, ["meta"] = { ["inventory"] = {  }, ["fields"] = {  } }, ["param2"] = 0, ["param1"] = 0 }, { ["y"] = 0, ["x"] = 0, ["name"] = "default:sand", ["z"] = 16, ["meta"] = { ["inventory"] = {  }, ["fields"] = {  } }, ["param2"] = 0, ["param1"] = 0 }, { ["y"] = 1, ["x"] = 0, ["name"] = "default:water_flowing", ["z"] = 0, ["meta"] = { ["inventory"] = {  }, ["fields"] = {  } }, ["param2"] = 15, ["param1"] = 127 }, { ["y"] = 1, ["x"] = 0, ["name"] = "default:sand", ["z"] = 1, ["meta"] = { ["inventory"] = {  }, ["fields"] = {  } }, ["param2"] = 0, ["param1"] = 0 }, { ["y"] = 1, ["x"] = 0, ["name"] = "default:sand", ["z"] = 2, ["meta"] = { ["inventory"] = {  }, ["fields"] = {  } }, ["param2"] = 0, ["param1"] = 0 }, { ["y"] = 1, ["x"] = 0, ["name"] = "default:sand", ["z"] = 3, ["meta"] = { ["inventory"] = {  }, ["fields"] = {  } }, ["param2"] = 0, ["param1"] = 0 }, { ["y"] = 1, ["x"] = 0, ["name"] = "default:sand", ["z"] = 4, ["meta"] = { ["inventory"] = {  }, ["fields"] = {  } }, ["param2"] = 0, ["param1"] = 0 }, { ["y"] = 1, ["x"] = 0, ["name"] = "default:sand", ["z"] = 5, ["meta"] = { ["inventory"] = {  }, ["fields"] = {  } }, ["param2"] = 0, ["param1"] = 0 }, { ["y"] = 1, ["x"] = 0, ["name"] = "default:sand", ["z"] = 6, ["meta"] = { ["inventory"] = {  }, ["fields"] = {  } }, ["param2"] = 0, ["param1"] = 0 }, { ["y"] = 1, ["x"] = 0, ["name"] = "default:sand", ["z"] = 7, ["meta"] = { ["inventory"] = {  }, ["fields"] = {  } }, ["param2"] = 0, ["param1"] = 0 }, { ["y"] = 1, ["x"] = 0, ["name"] = "default:sand", ["z"] = 8, ["meta"] = { ["inventory"] = {  }, ["fields"] = {  } }, ["param2"] = 0, ["param1"] = 0 }, { ["y"] = 1, ["x"] = 0, ["name"] = "default:sand", ["z"] = 9, ["meta"] = { ["inventory"] = {  }, ["fields"] = {  } }, ["param2"] = 0, ["param1"] = 0 }, { ["y"] = 1, ["x"] = 0, ["name"] = "default:sand", ["z"] = 10, ["meta"] = { ["inventory"] = {  }, ["fields"] = {  } }, ["param2"] = 0, ["param1"] = 0 }, { ["y"] = 1, ["x"] = 0, ["name"] = "default:sand", ["z"] = 11, ["meta"] = { ["inventory"] = {  }, ["fields"] = {  } }, ["param2"] = 0, ["param1"] = 0 }, { ["y"] = 1, ["x"] = 0, ["name"] = "default:sand", ["z"] = 12, ["meta"] = { ["inventory"] = {  }, ["fields"] = {  } }, ["param2"] = 0, ["param1"] = 0 }, { ["y"] = 1, ["x"] = 0, ["name"] = "default:sand", ["z"] = 13, ["meta"] = { ["inventory"] = {  }, ["fields"] = {  } }, ["param2"] = 0, ["param1"] = 0 }, { ["y"] = 1, ["x"] = 0, ["name"] = "default:sand", ["z"] = 14, ["meta"] = { ["inventory"] = {  }, ["fields"] = {  } }, ["param2"] = 0, ["param1"] = 0 }, { ["y"] = 1, ["x"] = 0, ["name"] = "default:sand", ["z"] = 15, ["meta"] = { ["inventory"] = {  }, ["fields"] = {  } }, ["param2"] = 0, ["param1"] = 0 }, { ["y"] = 1, ["x"] = 0, ["name"] = "default:sand", ["z"] = 16, ["meta"] = { ["inventory"] = {  }, ["fields"] = {  } }, ["param2"] = 0, ["param1"] = 0 }, { ["y"] = 2, ["x"] = 0, ["name"] = "default:water_flowing", ["z"] = 0, ["meta"] = { ["inventory"] = {  }, ["fields"] = {  } }, ["param2"] = 15, ["param1"] = 143 }, { ["y"] = 2, ["x"] = 0, ["name"] = "default:sand", ["z"] = 1, ["meta"] = { ["inventory"] = {  }, ["fields"] = {  } }, ["param2"] = 0, ["param1"] = 0 }, { ["y"] = 2, ["x"] = 0, ["name"] = "default:sand", ["z"] = 2, ["meta"] = { ["inventory"] = {  }, ["fields"] = {  } }, ["param2"] = 0, ["param1"] = 0 }, { ["y"] = 2, ["x"] = 0, ["name"] = "default:sand", ["z"] = 3, ["meta"] = { ["inventory"] = {  }, ["fields"] = {  } }, ["param2"] = 0, ["param1"] = 0 }, { ["y"] = 2, ["x"] = 0, ["name"] = "default:sand", ["z"] = 4, ["meta"] = { ["inventory"] = {  }, ["fields"] = {  } }, ["param2"] = 0, ["param1"] = 0 }, { ["y"] = 2, ["x"] = 0, ["name"] = "default:sand", ["z"] = 5, ["meta"] = { ["inventory"] = {  }, ["fields"] = {  } }, ["param2"] = 0, ["param1"] = 0 }, { ["y"] = 2, ["x"] = 0, ["name"] = "default:sand", ["z"] = 6, ["meta"] = { ["inventory"] = {  }, ["fields"] = {  } }, ["param2"] = 0, ["param1"] = 0 }, { ["y"] = 2, ["x"] = 0, ["name"] = "default:sand", ["z"] = 7, ["meta"] = { ["inventory"] = {  }, ["fields"] = {  } }, ["param2"] = 0, ["param1"] = 0 }, { ["y"] = 2, ["x"] = 0, ["name"] = "default:sand", ["z"] = 8, ["meta"] = { ["inventory"] = {  }, ["fields"] = {  } }, ["param2"] = 0, ["param1"] = 0 }, { ["y"] = 2, ["x"] = 0, ["name"] = "default:sand", ["z"] = 9, ["meta"] = { ["inventory"] = {  }, ["fields"] = {  } }, ["param2"] = 0, ["param1"] = 0 }, { ["y"] = 2, ["x"] = 0, ["name"] = "default:sand", ["z"] = 10, ["meta"] = { ["inventory"] = {  }, ["fields"] = {  } }, ["param2"] = 0, ["param1"] = 0 }, { ["y"] = 2, ["x"] = 0, ["name"] = "default:water_source", ["z"] = 11, ["meta"] = { ["inventory"] = {  }, ["fields"] = {  } }, ["param2"] = 240, ["param1"] = 124 }, { ["y"] = 2, ["x"] = 0, ["name"] = "default:water_source", ["z"] = 12, ["meta"] = { ["inventory"] = {  }, ["fields"] = {  } }, ["param2"] = 0, ["param1"] = 108 }, { ["y"] = 2, ["x"] = 0, ["name"] = "default:water_source", ["z"] = 13, ["meta"] = { ["inventory"] = {  }, ["fields"] = {  } }, ["param2"] = 0, ["param1"] = 124 }, { ["y"] = 2, ["x"] = 0, ["name"] = "default:water_source", ["z"] = 14, ["meta"] = { ["inventory"] = {  }, ["fields"] = {  } }, ["param2"] = 0, ["param1"] = 141 }, { ["y"] = 2, ["x"] = 0, ["name"] = "default:water_source", ["z"] = 15, ["meta"] = { ["inventory"] = {  }, ["fields"] = {  } }, ["param2"] = 0, ["param1"] = 156 }, { ["y"] = 2, ["x"] = 0, ["name"] = "default:sand", ["z"] = 16, ["meta"] = { ["inventory"] = {  }, ["fields"] = {  } }, ["param2"] = 0, ["param1"] = 0 }, { ["y"] = 3, ["x"] = 0, ["name"] = "flowers:waterlily_s1", ["z"] = 12, ["meta"] = { ["inventory"] = {  }, ["fields"] = {  } }, ["param2"] = 2, ["param1"] = 125 }, { ["y"] = 0, ["x"] = 1, ["name"] = "default:sand", ["z"] = 0, ["meta"] = { ["inventory"] = {  }, ["fields"] = {  } }, ["param2"] = 0, ["param1"] = 0 }, { ["y"] = 0, ["x"] = 1, ["name"] = "default:sand", ["z"] = 1, ["meta"] = { ["inventory"] = {  }, ["fields"] = {  } }, ["param2"] = 0, ["param1"] = 0 }, { ["y"] = 0, ["x"] = 1, ["name"] = "default:stone", ["z"] = 2, ["meta"] = { ["inventory"] = {  }, ["fields"] = {  } }, ["param2"] = 0, ["param1"] = 0 }, { ["y"] = 0, ["x"] = 1, ["name"] = "default:sand", ["z"] = 3, ["meta"] = { ["inventory"] = {  }, ["fields"] = {  } }, ["param2"] = 0, ["param1"] = 0 }, { ["y"] = 0, ["x"] = 1, ["name"] = "default:sand", ["z"] = 4, ["meta"] = { ["inventory"] = {  }, ["fields"] = {  } }, ["param2"] = 0, ["param1"] = 0 }, { ["y"] = 0, ["x"] = 1, ["name"] = "default:sand", ["z"] = 5, ["meta"] = { ["inventory"] = {  }, ["fields"] = {  } }, ["param2"] = 0, ["param1"] = 0 }, { ["y"] = 0, ["x"] = 1, ["name"] = "default:sand", ["z"] = 6, ["meta"] = { ["inventory"] = {  }, ["fields"] = {  } }, ["param2"] = 0, ["param1"] = 0 }, { ["y"] = 0, ["x"] = 1, ["name"] = "default:sand", ["z"] = 7, ["meta"] = { ["inventory"] = {  }, ["fields"] = {  } }, ["param2"] = 0, ["param1"] = 0 }, { ["y"] = 0, ["x"] = 1, ["name"] = "default:sand", ["z"] = 8, ["meta"] = { ["inventory"] = {  }, ["fields"] = {  } }, ["param2"] = 0, ["param1"] = 0 }, { ["y"] = 0, ["x"] = 1, ["name"] = "default:sand", ["z"] = 9, ["meta"] = { ["inventory"] = {  }, ["fields"] = {  } }, ["param2"] = 0, ["param1"] = 0 }, { ["y"] = 0, ["x"] = 1, ["name"] = "default:sand", ["z"] = 10, ["meta"] = { ["inventory"] = {  }, ["fields"] = {  } }, ["param2"] = 0, ["param1"] = 0 }, { ["y"] = 0, ["x"] = 1, ["name"] = "default:sand", ["z"] = 11, ["meta"] = { ["inventory"] = {  }, ["fields"] = {  } }, ["param2"] = 0, ["param1"] = 0 }, { ["y"] = 0, ["x"] = 1, ["name"] = "default:sand", ["z"] = 12, ["meta"] = { ["inventory"] = {  }, ["fields"] = {  } }, ["param2"] = 0, ["param1"] = 0 }, { ["y"] = 0, ["x"] = 1, ["name"] = "default:sand", ["z"] = 13, ["meta"] = { ["inventory"] = {  }, ["fields"] = {  } }, ["param2"] = 0, ["param1"] = 0 }, { ["y"] = 0, ["x"] = 1, ["name"] = "default:sand", ["z"] = 14, ["meta"] = { ["inventory"] = {  }, ["fields"] = {  } }, ["param2"] = 0, ["param1"] = 0 }, { ["y"] = 0, ["x"] = 1, ["name"] = "default:sand", ["z"] = 15, ["meta"] = { ["inventory"] = {  }, ["fields"] = {  } }, ["param2"] = 0, ["param1"] = 0 }, { ["y"] = 0, ["x"] = 1, ["name"] = "default:sand", ["z"] = 16, ["meta"] = { ["inventory"] = {  }, ["fields"] = {  } }, ["param2"] = 0, ["param1"] = 0 }, { ["y"] = 1, ["x"] = 1, ["name"] = "default:water_source", ["z"] = 0, ["meta"] = { ["inventory"] = {  }, ["fields"] = {  } }, ["param2"] = 240, ["param1"] = 141 }, { ["y"] = 1, ["x"] = 1, ["name"] = "default:water_flowing", ["z"] = 1, ["meta"] = { ["inventory"] = {  }, ["fields"] = {  } }, ["param2"] = 7, ["param1"] = 124 }, { ["y"] = 1, ["x"] = 1, ["name"] = "default:stonebrick", ["z"] = 2, ["meta"] = { ["inventory"] = {  }, ["fields"] = {  } }, ["param2"] = 0, ["param1"] = 0 }, { ["y"] = 1, ["x"] = 1, ["name"] = "default:stonebrick", ["z"] = 3, ["meta"] = { ["inventory"] = {  }, ["fields"] = {  } }, ["param2"] = 0, ["param1"] = 0 }, { ["y"] = 1, ["x"] = 1, ["name"] = "default:sand", ["z"] = 4, ["meta"] = { ["inventory"] = {  }, ["fields"] = {  } }, ["param2"] = 0, ["param1"] = 0 }, { ["y"] = 1, ["x"] = 1, ["name"] = "default:sand", ["z"] = 5, ["meta"] = { ["inventory"] = {  }, ["fields"] = {  } }, ["param2"] = 0, ["param1"] = 0 }, { ["y"] = 1, ["x"] = 1, ["name"] = "default:sand", ["z"] = 6, ["meta"] = { ["inventory"] = {  }, ["fields"] = {  } }, ["param2"] = 0, ["param1"] = 0 }, { ["y"] = 1, ["x"] = 1, ["name"] = "default:sand", ["z"] = 7, ["meta"] = { ["inventory"] = {  }, ["fields"] = {  } }, ["param2"] = 0, ["param1"] = 0 }, { ["y"] = 1, ["x"] = 1, ["name"] = "default:sand", ["z"] = 8, ["meta"] = { ["inventory"] = {  }, ["fields"] = {  } }, ["param2"] = 0, ["param1"] = 0 }, { ["y"] = 1, ["x"] = 1, ["name"] = "default:sand", ["z"] = 9, ["meta"] = { ["inventory"] = {  }, ["fields"] = {  } }, ["param2"] = 0, ["param1"] = 0 }, { ["y"] = 1, ["x"] = 1, ["name"] = "default:sand", ["z"] = 10, ["meta"] = { ["inventory"] = {  }, ["fields"] = {  } }, ["param2"] = 0, ["param1"] = 0 }, { ["y"] = 1, ["x"] = 1, ["name"] = "default:sand", ["z"] = 11, ["meta"] = { ["inventory"] = {  }, ["fields"] = {  } }, ["param2"] = 0, ["param1"] = 0 }, { ["y"] = 1, ["x"] = 1, ["name"] = "default:sand", ["z"] = 12, ["meta"] = { ["inventory"] = {  }, ["fields"] = {  } }, ["param2"] = 0, ["param1"] = 0 }, { ["y"] = 1, ["x"] = 1, ["name"] = "default:sand", ["z"] = 13, ["meta"] = { ["inventory"] = {  }, ["fields"] = {  } }, ["param2"] = 0, ["param1"] = 0 }, { ["y"] = 1, ["x"] = 1, ["name"] = "default:sand", ["z"] = 14, ["meta"] = { ["inventory"] = {  }, ["fields"] = {  } }, ["param2"] = 0, ["param1"] = 0 }, { ["y"] = 1, ["x"] = 1, ["name"] = "default:sand", ["z"] = 15, ["meta"] = { ["inventory"] = {  }, ["fields"] = {  } }, ["param2"] = 0, ["param1"] = 0 }, { ["y"] = 1, ["x"] = 1, ["name"] = "default:sand", ["z"] = 16, ["meta"] = { ["inventory"] = {  }, ["fields"] = {  } }, ["param2"] = 0, ["param1"] = 0 }, { ["y"] = 2, ["x"] = 1, ["name"] = "default:water_source", ["z"] = 0, ["meta"] = { ["inventory"] = {  }, ["fields"] = {  } }, ["param2"] = 0, ["param1"] = 157 }, { ["y"] = 2, ["x"] = 1, ["name"] = "framedglass:steel_framed_obsidian_glass", ["z"] = 1, ["meta"] = { ["inventory"] = {  }, ["fields"] = {  } }, ["param2"] = 0, ["param1"] = 140 }, { ["y"] = 2, ["x"] = 1, ["name"] = "default:stonebrick", ["z"] = 2, ["meta"] = { ["inventory"] = {  }, ["fields"] = {  } }, ["param2"] = 0, ["param1"] = 0 }, { ["y"] = 2, ["x"] = 1, ["name"] = "default:stonebrick", ["z"] = 3, ["meta"] = { ["inventory"] = {  }, ["fields"] = {  } }, ["param2"] = 0, ["param1"] = 0 }, { ["y"] = 2, ["x"] = 1, ["name"] = "default:stonebrick", ["z"] = 4, ["meta"] = { ["inventory"] = {  }, ["fields"] = {  } }, ["param2"] = 0, ["param1"] = 0 }, { ["y"] = 2, ["x"] = 1, ["name"] = "default:stonebrick", ["z"] = 5, ["meta"] = { ["inventory"] = {  }, ["fields"] = {  } }, ["param2"] = 0, ["param1"] = 0 }, { ["y"] = 2, ["x"] = 1, ["name"] = "default:stonebrick", ["z"] = 6, ["meta"] = { ["inventory"] = {  }, ["fields"] = {  } }, ["param2"] = 0, ["param1"] = 0 }, { ["y"] = 2, ["x"] = 1, ["name"] = "default:sand", ["z"] = 7, ["meta"] = { ["inventory"] = {  }, ["fields"] = {  } }, ["param2"] = 0, ["param1"] = 0 }, { ["y"] = 2, ["x"] = 1, ["name"] = "default:sand", ["z"] = 8, ["meta"] = { ["inventory"] = {  }, ["fields"] = {  } }, ["param2"] = 0, ["param1"] = 0 }, { ["y"] = 2, ["x"] = 1, ["name"] = "default:sand", ["z"] = 9, ["meta"] = { ["inventory"] = {  }, ["fields"] = {  } }, ["param2"] = 0, ["param1"] = 0 }, { ["y"] = 2, ["x"] = 1, ["name"] = "default:sand", ["z"] = 10, ["meta"] = { ["inventory"] = {  }, ["fields"] = {  } }, ["param2"] = 0, ["param1"] = 0 }, { ["y"] = 2, ["x"] = 1, ["name"] = "default:sand", ["z"] = 11, ["meta"] = { ["inventory"] = {  }, ["fields"] = {  } }, ["param2"] = 0, ["param1"] = 0 }, { ["y"] = 2, ["x"] = 1, ["name"] = "default:sand", ["z"] = 12, ["meta"] = { ["inventory"] = {  }, ["fields"] = {  } }, ["param2"] = 0, ["param1"] = 0 }, { ["y"] = 2, ["x"] = 1, ["name"] = "default:water_source", ["z"] = 13, ["meta"] = { ["inventory"] = {  }, ["fields"] = {  } }, ["param2"] = 0, ["param1"] = 140 }, { ["y"] = 2, ["x"] = 1, ["name"] = "default:water_source", ["z"] = 14, ["meta"] = { ["inventory"] = {  }, ["fields"] = {  } }, ["param2"] = 0, ["param1"] = 157 }, { ["y"] = 2, ["x"] = 1, ["name"] = "default:sand", ["z"] = 15, ["meta"] = { ["inventory"] = {  }, ["fields"] = {  } }, ["param2"] = 0, ["param1"] = 0 }, { ["y"] = 2, ["x"] = 1, ["name"] = "default:sand", ["z"] = 16, ["meta"] = { ["inventory"] = {  }, ["fields"] = {  } }, ["param2"] = 0, ["param1"] = 0 }, { ["y"] = 3, ["x"] = 1, ["name"] = "framedglass:steel_framed_obsidian_glass", ["z"] = 1, ["meta"] = { ["inventory"] = {  }, ["fields"] = {  } }, ["param2"] = 0, ["param1"] = 157 }, { ["y"] = 3, ["x"] = 1, ["name"] = "framedglass:steel_framed_obsidian_glass", ["z"] = 2, ["meta"] = { ["inventory"] = {  }, ["fields"] = {  } }, ["param2"] = 0, ["param1"] = 173 }, { ["y"] = 3, ["x"] = 1, ["name"] = "wiki:wiki", ["z"] = 3, ["meta"] = { ["inventory"] = {  }, ["fields"] = { ["infotext"] = "Wiki" } }, ["param2"] = 0, ["param1"] = 0 }, { ["y"] = 3, ["x"] = 1, ["name"] = "framedglass:steel_framed_obsidian_glass", ["z"] = 4, ["meta"] = { ["inventory"] = {  }, ["fields"] = {  } }, ["param2"] = 0, ["param1"] = 173 }, { ["y"] = 3, ["x"] = 1, ["name"] = "framedglass:steel_framed_obsidian_glass", ["z"] = 5, ["meta"] = { ["inventory"] = {  }, ["fields"] = {  } }, ["param2"] = 0, ["param1"] = 173 }, { ["y"] = 3, ["x"] = 1, ["name"] = "framedglass:steel_framed_obsidian_glass", ["z"] = 6, ["meta"] = { ["inventory"] = {  }, ["fields"] = {  } }, ["param2"] = 0, ["param1"] = 173 }, { ["y"] = 3, ["x"] = 1, ["name"] = "framedglass:steel_framed_obsidian_glass", ["z"] = 7, ["meta"] = { ["inventory"] = {  }, ["fields"] = {  } }, ["param2"] = 0, ["param1"] = 191 }, { ["y"] = 3, ["x"] = 1, ["name"] = "framedglass:steel_framed_obsidian_glass", ["z"] = 8, ["meta"] = { ["inventory"] = {  }, ["fields"] = {  } }, ["param2"] = 0, ["param1"] = 207 }, { ["y"] = 3, ["x"] = 1, ["name"] = "framedglass:steel_framed_obsidian_glass", ["z"] = 9, ["meta"] = { ["inventory"] = {  }, ["fields"] = {  } }, ["param2"] = 0, ["param1"] = 191 }, { ["y"] = 3, ["x"] = 1, ["name"] = "flowers:waterlily_s2", ["z"] = 14, ["meta"] = { ["inventory"] = {  }, ["fields"] = {  } }, ["param2"] = 0, ["param1"] = 175 }, { ["y"] = 4, ["x"] = 1, ["name"] = "building_blocks:hardwood", ["z"] = 1, ["meta"] = { ["inventory"] = {  }, ["fields"] = {  } }, ["param2"] = 0, ["param1"] = 0 }, { ["y"] = 4, ["x"] = 1, ["name"] = "building_blocks:hardwood", ["z"] = 2, ["meta"] = { ["inventory"] = {  }, ["fields"] = {  } }, ["param2"] = 0, ["param1"] = 0 }, { ["y"] = 4, ["x"] = 1, ["name"] = "building_blocks:hardwood", ["z"] = 3, ["meta"] = { ["inventory"] = {  }, ["fields"] = {  } }, ["param2"] = 0, ["param1"] = 0 }, { ["y"] = 4, ["x"] = 1, ["name"] = "building_blocks:hardwood", ["z"] = 4, ["meta"] = { ["inventory"] = {  }, ["fields"] = {  } }, ["param2"] = 0, ["param1"] = 0 }, { ["y"] = 4, ["x"] = 1, ["name"] = "building_blocks:hardwood", ["z"] = 5, ["meta"] = { ["inventory"] = {  }, ["fields"] = {  } }, ["param2"] = 0, ["param1"] = 0 }, { ["y"] = 4, ["x"] = 1, ["name"] = "building_blocks:hardwood", ["z"] = 6, ["meta"] = { ["inventory"] = {  }, ["fields"] = {  } }, ["param2"] = 0, ["param1"] = 0 }, { ["y"] = 4, ["x"] = 1, ["name"] = "framedglass:steel_framed_obsidian_glass", ["z"] = 7, ["meta"] = { ["inventory"] = {  }, ["fields"] = {  } }, ["param2"] = 0, ["param1"] = 207 }, { ["y"] = 4, ["x"] = 1, ["name"] = "framedglass:steel_framed_obsidian_glass", ["z"] = 8, ["meta"] = { ["inventory"] = {  }, ["fields"] = {  } }, ["param2"] = 0, ["param1"] = 223 }, { ["y"] = 4, ["x"] = 1, ["name"] = "framedglass:steel_framed_obsidian_glass", ["z"] = 9, ["meta"] = { ["inventory"] = {  }, ["fields"] = {  } }, ["param2"] = 0, ["param1"] = 207 }, { ["y"] = 5, ["x"] = 1, ["name"] = "darkage:glass", ["z"] = 1, ["meta"] = { ["inventory"] = {  }, ["fields"] = {  } }, ["param2"] = 0, ["param1"] = 223 }, { ["y"] = 5, ["x"] = 1, ["name"] = "moreblocks:super_glow_glass", ["z"] = 2, ["meta"] = { ["inventory"] = {  }, ["fields"] = {  } }, ["param2"] = 0, ["param1"] = 0 }, { ["y"] = 5, ["x"] = 1, ["name"] = "darkage:glass", ["z"] = 3, ["meta"] = { ["inventory"] = {  }, ["fields"] = {  } }, ["param2"] = 0, ["param1"] = 221 }, { ["y"] = 5, ["x"] = 1, ["name"] = "moreblocks:super_glow_glass", ["z"] = 4, ["meta"] = { ["inventory"] = {  }, ["fields"] = {  } }, ["param2"] = 0, ["param1"] = 0 }, { ["y"] = 5, ["x"] = 1, ["name"] = "darkage:glass", ["z"] = 5, ["meta"] = { ["inventory"] = {  }, ["fields"] = {  } }, ["param2"] = 0, ["param1"] = 221 }, { ["y"] = 5, ["x"] = 1, ["name"] = "moreblocks:super_glow_glass", ["z"] = 6, ["meta"] = { ["inventory"] = {  }, ["fields"] = {  } }, ["param2"] = 0, ["param1"] = 0 }, { ["y"] = 5, ["x"] = 1, ["name"] = "framedglass:steel_framed_obsidian_glass", ["z"] = 7, ["meta"] = { ["inventory"] = {  }, ["fields"] = {  } }, ["param2"] = 0, ["param1"] = 223 }, { ["y"] = 5, ["x"] = 1, ["name"] = "framedglass:steel_framed_obsidian_glass", ["z"] = 8, ["meta"] = { ["inventory"] = {  }, ["fields"] = {  } }, ["param2"] = 0, ["param1"] = 207 }, { ["y"] = 5, ["x"] = 1, ["name"] = "framedglass:steel_framed_obsidian_glass", ["z"] = 9, ["meta"] = { ["inventory"] = {  }, ["fields"] = {  } }, ["param2"] = 0, ["param1"] = 191 }, { ["y"] = 5, ["x"] = 1, ["name"] = "columnia:rusty_block", ["z"] = 10, ["meta"] = { ["inventory"] = {  }, ["fields"] = {  } }, ["param2"] = 0, ["param1"] = 0 }, { ["y"] = 6, ["x"] = 1, ["name"] = "building_blocks:smoothglass", ["z"] = 1, ["meta"] = { ["inventory"] = {  }, ["fields"] = {  } }, ["param2"] = 0, ["param1"] = 207 }, { ["y"] = 6, ["x"] = 1, ["name"] = "default:junglewood", ["z"] = 2, ["meta"] = { ["inventory"] = {  }, ["fields"] = {  } }, ["param2"] = 0, ["param1"] = 0 }, { ["y"] = 6, ["x"] = 1, ["name"] = "default:junglewood", ["z"] = 3, ["meta"] = { ["inventory"] = {  }, ["fields"] = {  } }, ["param2"] = 0, ["param1"] = 0 }, { ["y"] = 6, ["x"] = 1, ["name"] = "default:junglewood", ["z"] = 4, ["meta"] = { ["inventory"] = {  }, ["fields"] = {  } }, ["param2"] = 0, ["param1"] = 0 }, { ["y"] = 6, ["x"] = 1, ["name"] = "default:junglewood", ["z"] = 5, ["meta"] = { ["inventory"] = {  }, ["fields"] = {  } }, ["param2"] = 0, ["param1"] = 0 }, { ["y"] = 6, ["x"] = 1, ["name"] = "default:junglewood", ["z"] = 6, ["meta"] = { ["inventory"] = {  }, ["fields"] = {  } }, ["param2"] = 0, ["param1"] = 0 }, { ["y"] = 0, ["x"] = 2, ["name"] = "default:water_source", ["z"] = 0, ["meta"] = { ["inventory"] = {  }, ["fields"] = {  } }, ["param2"] = 240, ["param1"] = 139 }, { ["y"] = 0, ["x"] = 2, ["name"] = "default:sand", ["z"] = 1, ["meta"] = { ["inventory"] = {  }, ["fields"] = {  } }, ["param2"] = 0, ["param1"] = 0 }, { ["y"] = 0, ["x"] = 2, ["name"] = "default:sand", ["z"] = 2, ["meta"] = { ["inventory"] = {  }, ["fields"] = {  } }, ["param2"] = 0, ["param1"] = 0 }, { ["y"] = 0, ["x"] = 2, ["name"] = "default:sand", ["z"] = 3, ["meta"] = { ["inventory"] = {  }, ["fields"] = {  } }, ["param2"] = 0, ["param1"] = 0 }, { ["y"] = 0, ["x"] = 2, ["name"] = "default:sand", ["z"] = 4, ["meta"] = { ["inventory"] = {  }, ["fields"] = {  } }, ["param2"] = 0, ["param1"] = 0 }, { ["y"] = 0, ["x"] = 2, ["name"] = "default:sand", ["z"] = 5, ["meta"] = { ["inventory"] = {  }, ["fields"] = {  } }, ["param2"] = 0, ["param1"] = 0 }, { ["y"] = 0, ["x"] = 2, ["name"] = "default:sand", ["z"] = 6, ["meta"] = { ["inventory"] = {  }, ["fields"] = {  } }, ["param2"] = 0, ["param1"] = 0 }, { ["y"] = 0, ["x"] = 2, ["name"] = "default:sand", ["z"] = 7, ["meta"] = { ["inventory"] = {  }, ["fields"] = {  } }, ["param2"] = 0, ["param1"] = 0 }, { ["y"] = 0, ["x"] = 2, ["name"] = "default:sand", ["z"] = 8, ["meta"] = { ["inventory"] = {  }, ["fields"] = {  } }, ["param2"] = 0, ["param1"] = 0 }, { ["y"] = 0, ["x"] = 2, ["name"] = "default:sand", ["z"] = 9, ["meta"] = { ["inventory"] = {  }, ["fields"] = {  } }, ["param2"] = 0, ["param1"] = 0 }, { ["y"] = 0, ["x"] = 2, ["name"] = "default:sand", ["z"] = 10, ["meta"] = { ["inventory"] = {  }, ["fields"] = {  } }, ["param2"] = 0, ["param1"] = 0 }, { ["y"] = 0, ["x"] = 2, ["name"] = "default:sand", ["z"] = 11, ["meta"] = { ["inventory"] = {  }, ["fields"] = {  } }, ["param2"] = 0, ["param1"] = 0 }, { ["y"] = 0, ["x"] = 2, ["name"] = "default:sand", ["z"] = 12, ["meta"] = { ["inventory"] = {  }, ["fields"] = {  } }, ["param2"] = 0, ["param1"] = 0 }, { ["y"] = 0, ["x"] = 2, ["name"] = "default:sand", ["z"] = 13, ["meta"] = { ["inventory"] = {  }, ["fields"] = {  } }, ["param2"] = 0, ["param1"] = 0 }, { ["y"] = 0, ["x"] = 2, ["name"] = "default:sand", ["z"] = 14, ["meta"] = { ["inventory"] = {  }, ["fields"] = {  } }, ["param2"] = 0, ["param1"] = 0 }, { ["y"] = 0, ["x"] = 2, ["name"] = "default:sand", ["z"] = 15, ["meta"] = { ["inventory"] = {  }, ["fields"] = {  } }, ["param2"] = 0, ["param1"] = 0 }, { ["y"] = 0, ["x"] = 2, ["name"] = "default:sand", ["z"] = 16, ["meta"] = { ["inventory"] = {  }, ["fields"] = {  } }, ["param2"] = 0, ["param1"] = 0 }, { ["y"] = 1, ["x"] = 2, ["name"] = "default:water_source", ["z"] = 0, ["meta"] = { ["inventory"] = {  }, ["fields"] = {  } }, ["param2"] = 240, ["param1"] = 156 }, { ["y"] = 1, ["x"] = 2, ["name"] = "default:water_flowing", ["z"] = 1, ["meta"] = { ["inventory"] = {  }, ["fields"] = {  } }, ["param2"] = 7, ["param1"] = 140 }, { ["y"] = 1, ["x"] = 2, ["name"] = "default:diamondblock", ["z"] = 2, ["meta"] = { ["inventory"] = {  }, ["fields"] = {  } }, ["param2"] = 0, ["param1"] = 0 }, { ["y"] = 1, ["x"] = 2, ["name"] = "default:diamondblock", ["z"] = 3, ["meta"] = { ["inventory"] = {  }, ["fields"] = {  } }, ["param2"] = 0, ["param1"] = 0 }, { ["y"] = 1, ["x"] = 2, ["name"] = "default:wood", ["z"] = 4, ["meta"] = { ["inventory"] = {  }, ["fields"] = {  } }, ["param2"] = 0, ["param1"] = 0 }, { ["y"] = 1, ["x"] = 2, ["name"] = "default:sand", ["z"] = 5, ["meta"] = { ["inventory"] = {  }, ["fields"] = {  } }, ["param2"] = 0, ["param1"] = 0 }, { ["y"] = 1, ["x"] = 2, ["name"] = "default:sand", ["z"] = 6, ["meta"] = { ["inventory"] = {  }, ["fields"] = {  } }, ["param2"] = 0, ["param1"] = 0 }, { ["y"] = 1, ["x"] = 2, ["name"] = "default:sand", ["z"] = 7, ["meta"] = { ["inventory"] = {  }, ["fields"] = {  } }, ["param2"] = 0, ["param1"] = 0 }, { ["y"] = 1, ["x"] = 2, ["name"] = "default:sand", ["z"] = 8, ["meta"] = { ["inventory"] = {  }, ["fields"] = {  } }, ["param2"] = 0, ["param1"] = 0 }, { ["y"] = 1, ["x"] = 2, ["name"] = "default:sand", ["z"] = 9, ["meta"] = { ["inventory"] = {  }, ["fields"] = {  } }, ["param2"] = 0, ["param1"] = 0 }, { ["y"] = 1, ["x"] = 2, ["name"] = "default:sand", ["z"] = 10, ["meta"] = { ["inventory"] = {  }, ["fields"] = {  } }, ["param2"] = 0, ["param1"] = 0 }, { ["y"] = 1, ["x"] = 2, ["name"] = "default:sand", ["z"] = 11, ["meta"] = { ["inventory"] = {  }, ["fields"] = {  } }, ["param2"] = 0, ["param1"] = 0 }, { ["y"] = 1, ["x"] = 2, ["name"] = "default:sand", ["z"] = 12, ["meta"] = { ["inventory"] = {  }, ["fields"] = {  } }, ["param2"] = 0, ["param1"] = 0 }, { ["y"] = 1, ["x"] = 2, ["name"] = "default:sand", ["z"] = 13, ["meta"] = { ["inventory"] = {  }, ["fields"] = {  } }, ["param2"] = 0, ["param1"] = 0 }, { ["y"] = 1, ["x"] = 2, ["name"] = "default:sand", ["z"] = 14, ["meta"] = { ["inventory"] = {  }, ["fields"] = {  } }, ["param2"] = 0, ["param1"] = 0 }, { ["y"] = 1, ["x"] = 2, ["name"] = "default:sand", ["z"] = 15, ["meta"] = { ["inventory"] = {  }, ["fields"] = {  } }, ["param2"] = 0, ["param1"] = 0 }, { ["y"] = 1, ["x"] = 2, ["name"] = "default:sand", ["z"] = 16, ["meta"] = { ["inventory"] = {  }, ["fields"] = {  } }, ["param2"] = 0, ["param1"] = 0 }, { ["y"] = 2, ["x"] = 2, ["name"] = "default:water_source", ["z"] = 0, ["meta"] = { ["inventory"] = {  }, ["fields"] = {  } }, ["param2"] = 0, ["param1"] = 173 }, { ["y"] = 2, ["x"] = 2, ["name"] = "framedglass:steel_framed_obsidian_glass", ["z"] = 1, ["meta"] = { ["inventory"] = {  }, ["fields"] = {  } }, ["param2"] = 0, ["param1"] = 157 }, { ["y"] = 2, ["x"] = 2, ["name"] = "moreblocks:stair_wood", ["z"] = 4, ["meta"] = { ["inventory"] = {  }, ["fields"] = {  } }, ["param2"] = 10, ["param1"] = 175 }, { ["y"] = 2, ["x"] = 2, ["name"] = "default:wood", ["z"] = 5, ["meta"] = { ["inventory"] = {  }, ["fields"] = {  } }, ["param2"] = 0, ["param1"] = 0 }, { ["y"] = 2, ["x"] = 2, ["name"] = "default:stonebrick", ["z"] = 6, ["meta"] = { ["inventory"] = {  }, ["fields"] = {  } }, ["param2"] = 0, ["param1"] = 0 }, { ["y"] = 2, ["x"] = 2, ["name"] = "default:sand", ["z"] = 7, ["meta"] = { ["inventory"] = {  }, ["fields"] = {  } }, ["param2"] = 0, ["param1"] = 0 }, { ["y"] = 2, ["x"] = 2, ["name"] = "default:sand", ["z"] = 8, ["meta"] = { ["inventory"] = {  }, ["fields"] = {  } }, ["param2"] = 0, ["param1"] = 0 }, { ["y"] = 2, ["x"] = 2, ["name"] = "default:sand", ["z"] = 9, ["meta"] = { ["inventory"] = {  }, ["fields"] = {  } }, ["param2"] = 0, ["param1"] = 0 }, { ["y"] = 2, ["x"] = 2, ["name"] = "default:sand", ["z"] = 10, ["meta"] = { ["inventory"] = {  }, ["fields"] = {  } }, ["param2"] = 0, ["param1"] = 0 }, { ["y"] = 2, ["x"] = 2, ["name"] = "default:sand", ["z"] = 11, ["meta"] = { ["inventory"] = {  }, ["fields"] = {  } }, ["param2"] = 0, ["param1"] = 0 }, { ["y"] = 2, ["x"] = 2, ["name"] = "default:sand", ["z"] = 12, ["meta"] = { ["inventory"] = {  }, ["fields"] = {  } }, ["param2"] = 0, ["param1"] = 0 }, { ["y"] = 2, ["x"] = 2, ["name"] = "default:sand", ["z"] = 13, ["meta"] = { ["inventory"] = {  }, ["fields"] = {  } }, ["param2"] = 0, ["param1"] = 0 }, { ["y"] = 2, ["x"] = 2, ["name"] = "default:sand", ["z"] = 14, ["meta"] = { ["inventory"] = {  }, ["fields"] = {  } }, ["param2"] = 0, ["param1"] = 0 }, { ["y"] = 2, ["x"] = 2, ["name"] = "default:sand", ["z"] = 15, ["meta"] = { ["inventory"] = {  }, ["fields"] = {  } }, ["param2"] = 0, ["param1"] = 0 }, { ["y"] = 2, ["x"] = 2, ["name"] = "default:sand", ["z"] = 16, ["meta"] = { ["inventory"] = {  }, ["fields"] = {  } }, ["param2"] = 0, ["param1"] = 0 }, { ["y"] = 3, ["x"] = 2, ["name"] = "framedglass:steel_framed_obsidian_glass", ["z"] = 1, ["meta"] = { ["inventory"] = {  }, ["fields"] = {  } }, ["param2"] = 0, ["param1"] = 173 }, { ["y"] = 3, ["x"] = 2, ["name"] = "signs:sign_wall_green", ["z"] = 2, ["meta"] = { ["inventory"] = {  }, ["fields"] = { ["infotext"] = "Mod U_skins :\
Permet de changer l'apparence\
de son avatar depuis l'icone en\
bas a droite de votre inventaire. ", ["text"] = "Mod U_skins :\
Permet de changer l'apparence\
de son avatar depuis l'icone en\
bas a droite de votre inventaire.", ["formspec"] = "size[6,4]textarea[0,-0.3;6.5,3;text;;${text}]button_exit[2,3.4;2,1;ok;Write]background[-0.5,-0.5;7,5;bg_signs_lib.jpg]", ["__signslib_new_format"] = "1" } }, ["param2"] = 3, ["param1"] = 191 }, { ["y"] = 3, ["x"] = 2, ["name"] = "framedglass:steel_framed_obsidian_glass", ["z"] = 9, ["meta"] = { ["inventory"] = {  }, ["fields"] = {  } }, ["param2"] = 0, ["param1"] = 207 }, { ["y"] = 3, ["x"] = 2, ["name"] = "columnia:column_bottom_rusty_block", ["z"] = 10, ["meta"] = { ["inventory"] = {  }, ["fields"] = {  } }, ["param2"] = 2, ["param1"] = 189 }, { ["y"] = 4, ["x"] = 2, ["name"] = "building_blocks:hardwood", ["z"] = 1, ["meta"] = { ["inventory"] = {  }, ["fields"] = {  } }, ["param2"] = 0, ["param1"] = 0 }, { ["y"] = 4, ["x"] = 2, ["name"] = "signs:sign_wall_green", ["z"] = 2, ["meta"] = { ["inventory"] = {  }, ["fields"] = { ["infotext"] = "Mod Factions :\
Permet de creer des groupes de joueurs. (guildes)\
/factions => infos sur vos factions actuels\
/factions list => affiche une liste des factions\
/factions info <factionname> => affiche la description d'une faction\
/factions join <factionname> => rejoindre une faction\
/factions leave <factionname> => quitter une faction\r ", ["text"] = "Mod Factions :\
Permet de creer des groupes de joueurs. (guildes)\
/factions => infos sur vos factions actuels\
/factions list => affiche une liste des factions\
/factions info <factionname> => affiche la description d'une faction\
/factions join <factionname> => rejoindre une faction\
/factions leave <factionname> => quitter une faction\r", ["formspec"] = "size[6,4]textarea[0,0;6.5,3;text;;${text}]button_exit[2,3;2,1;ok;Write]background[-0.5,-0.5;7,5;bg_signs_lib.jpg]", ["__signslib_new_format"] = "1" } }, ["param2"] = 2, ["param1"] = 207 }, { ["y"] = 4, ["x"] = 2, ["name"] = "signs:sign_wall_green", ["z"] = 3, ["meta"] = { ["inventory"] = {  }, ["fields"] = { ["infotext"] = "\
Wiki publique du serveur\
O\
O\
O\
V ", ["text"] = "  \
Wiki publique du serveur\
O\
O\
O\
V", ["formspec"] = "size[6,4]textarea[0,0;6.5,3;text;;${text}]button_exit[2,3;2,1;ok;Write]background[-0.5,-0.5;7,5;bg_signs_lib.jpg]", ["__signslib_new_format"] = "1" } }, ["param2"] = 3, ["param1"] = 191 }, { ["y"] = 4, ["x"] = 2, ["name"] = "default:sign_wall", ["z"] = 4, ["meta"] = { ["inventory"] = {  }, ["fields"] = { ["infotext"] = "\
Aucune forme d'insulte ou\
de racisme n'est admise.\
 ", ["text"] = "  \
Aucune forme d'insulte ou\
de racisme n'est admise.\
  ", ["formspec"] = "size[6,4]textarea[0,0;6.5,3;text;;${text}]button_exit[2,3;2,1;ok;Write]background[-0.5,-0.5;7,5;bg_signs_lib.jpg]", ["__signslib_new_format"] = "1" } }, ["param2"] = 3, ["param1"] = 207 }, { ["y"] = 4, ["x"] = 2, ["name"] = "default:sign_wall", ["z"] = 5, ["meta"] = { ["inventory"] = {  }, ["fields"] = { ["infotext"] = "   \
Merci de ne pas spammer ou \
flooder. ", ["text"] = "   \
Merci de ne pas spammer ou \
flooder.", ["formspec"] = "size[6,4]textarea[0,0;6.5,3;text;;${text}]button_exit[2,3;2,1;ok;Write]background[-0.5,-0.5;7,5;bg_signs_lib.jpg]", ["__signslib_new_format"] = "1" } }, ["param2"] = 3, ["param1"] = 207 }, { ["y"] = 4, ["x"] = 2, ["name"] = "default:sign_wall", ["z"] = 6, ["meta"] = { ["inventory"] = {  }, ["fields"] = { ["infotext"] = "La triche n'est pas toleree \
sur le serveur.\
Soyez fair-play et apprenez\
a jouer dans les regles. ", ["text"] = "La triche n'est pas toleree \
sur le serveur.\
Soyez fair-play et apprenez\
a jouer dans les regles.", ["formspec"] = "size[6,4]textarea[0,0;6.5,3;text;;${text}]button_exit[2,3;2,1;ok;Write]background[-0.5,-0.5;7,5;bg_signs_lib.jpg]", ["__signslib_new_format"] = "1" } }, ["param2"] = 3, ["param1"] = 205 }, { ["y"] = 4, ["x"] = 2, ["name"] = "homedecor:torch_wall", ["z"] = 8, ["meta"] = { ["inventory"] = {  }, ["fields"] = {  } }, ["param2"] = 0, ["param1"] = 15 }, { ["y"] = 4, ["x"] = 2, ["name"] = "framedglass:steel_framed_obsidian_glass", ["z"] = 9, ["meta"] = { ["inventory"] = {  }, ["fields"] = {  } }, ["param2"] = 0, ["param1"] = 223 }, { ["y"] = 4, ["x"] = 2, ["name"] = "columnia:column_top_rusty_block", ["z"] = 10, ["meta"] = { ["inventory"] = {  }, ["fields"] = {  } }, ["param2"] = 3, ["param1"] = 205 }, { ["y"] = 5, ["x"] = 2, ["name"] = "moreblocks:super_glow_glass", ["z"] = 1, ["meta"] = { ["inventory"] = {  }, ["fields"] = {  } }, ["param2"] = 0, ["param1"] = 0 }, { ["y"] = 5, ["x"] = 2, ["name"] = "signs:sign_wall_green", ["z"] = 2, ["meta"] = { ["inventory"] = {  }, ["fields"] = { ["infotext"] = "Mod Wiki :\
Craftez le bloc \"Wiki\"\
pour avoir acces au Wiki\
du serveur en jeu ", ["text"] = "Mod Wiki :\
Craftez le bloc \"Wiki\"\
pour avoir acces au Wiki\
du serveur en jeu", ["formspec"] = "size[6,4]textarea[0,0;6.5,3;text;;${text}]button_exit[2,3;2,1;ok;Write]background[-0.5,-0.5;7,5;bg_signs_lib.jpg]", ["__signslib_new_format"] = "1" } }, ["param2"] = 2, ["param1"] = 223 }, { ["y"] = 5, ["x"] = 2, ["name"] = "signs:sign_hanging", ["z"] = 6, ["meta"] = { ["inventory"] = {  }, ["fields"] = { ["infotext"] = "\
Aucune atteinte intentionnelle\
au bon fonctionnement du\
serveur ne sera admise. (lag,\
crash, exploit de bug, etc...) ", ["text"] = "   \
Aucune atteinte intentionnelle\
au bon fonctionnement du \
serveur ne sera admise. (lag,\
crash, exploit de bug, etc...)", ["formspec"] = "size[6,4]textarea[0,0;6.5,3;text;;${text}]button_exit[2,3;2,1;ok;Write]background[-0.5,-0.5;7,5;bg_signs_lib.jpg]", ["__signslib_new_format"] = "1" } }, ["param2"] = 0, ["param1"] = 221 }, { ["y"] = 5, ["x"] = 2, ["name"] = "framedglass:steel_framed_obsidian_glass", ["z"] = 9, ["meta"] = { ["inventory"] = {  }, ["fields"] = {  } }, ["param2"] = 0, ["param1"] = 207 }, { ["y"] = 5, ["x"] = 2, ["name"] = "columnia:rusty_block", ["z"] = 10, ["meta"] = { ["inventory"] = {  }, ["fields"] = {  } }, ["param2"] = 0, ["param1"] = 0 }, { ["y"] = 5, ["x"] = 2, ["name"] = "columnia:rusty_block", ["z"] = 11, ["meta"] = { ["inventory"] = {  }, ["fields"] = {  } }, ["param2"] = 0, ["param1"] = 0 }, { ["y"] = 5, ["x"] = 2, ["name"] = "columnia:rusty_block", ["z"] = 12, ["meta"] = { ["inventory"] = {  }, ["fields"] = {  } }, ["param2"] = 0, ["param1"] = 0 }, { ["y"] = 6, ["x"] = 2, ["name"] = "building_blocks:smoothglass", ["z"] = 1, ["meta"] = { ["inventory"] = {  }, ["fields"] = {  } }, ["param2"] = 0, ["param1"] = 223 }, { ["y"] = 6, ["x"] = 2, ["name"] = "homedecor:torch_wall", ["z"] = 5, ["meta"] = { ["inventory"] = {  }, ["fields"] = {  } }, ["param2"] = 0, ["param1"] = 15 }, { ["y"] = 6, ["x"] = 2, ["name"] = "default:junglewood", ["z"] = 6, ["meta"] = { ["inventory"] = {  }, ["fields"] = {  } }, ["param2"] = 0, ["param1"] = 0 }, { ["y"] = 6, ["x"] = 2, ["name"] = "default:junglewood", ["z"] = 7, ["meta"] = { ["inventory"] = {  }, ["fields"] = {  } }, ["param2"] = 0, ["param1"] = 0 }, { ["y"] = 6, ["x"] = 2, ["name"] = "framedglass:steel_framed_obsidian_glass", ["z"] = 8, ["meta"] = { ["inventory"] = {  }, ["fields"] = {  } }, ["param2"] = 0, ["param1"] = 207 }, { ["y"] = 7, ["x"] = 2, ["name"] = "building_blocks:smoothglass", ["z"] = 2, ["meta"] = { ["inventory"] = {  }, ["fields"] = {  } }, ["param2"] = 0, ["param1"] = 191 }, { ["y"] = 7, ["x"] = 2, ["name"] = "building_blocks:smoothglass", ["z"] = 3, ["meta"] = { ["inventory"] = {  }, ["fields"] = {  } }, ["param2"] = 0, ["param1"] = 191 }, { ["y"] = 7, ["x"] = 2, ["name"] = "building_blocks:smoothglass", ["z"] = 4, ["meta"] = { ["inventory"] = {  }, ["fields"] = {  } }, ["param2"] = 0, ["param1"] = 207 }, { ["y"] = 7, ["x"] = 2, ["name"] = "building_blocks:smoothglass", ["z"] = 5, ["meta"] = { ["inventory"] = {  }, ["fields"] = {  } }, ["param2"] = 0, ["param1"] = 223 }, { ["y"] = 0, ["x"] = 3, ["name"] = "default:water_source", ["z"] = 0, ["meta"] = { ["inventory"] = {  }, ["fields"] = {  } }, ["param2"] = 240, ["param1"] = 123 }, { ["y"] = 0, ["x"] = 3, ["name"] = "default:water_flowing", ["z"] = 1, ["meta"] = { ["inventory"] = {  }, ["fields"] = {  } }, ["param2"] = 7, ["param1"] = 107 }, { ["y"] = 0, ["x"] = 3, ["name"] = "default:sand", ["z"] = 2, ["meta"] = { ["inventory"] = {  }, ["fields"] = {  } }, ["param2"] = 0, ["param1"] = 0 }, { ["y"] = 0, ["x"] = 3, ["name"] = "default:sand", ["z"] = 3, ["meta"] = { ["inventory"] = {  }, ["fields"] = {  } }, ["param2"] = 0, ["param1"] = 0 }, { ["y"] = 0, ["x"] = 3, ["name"] = "default:sand", ["z"] = 4, ["meta"] = { ["inventory"] = {  }, ["fields"] = {  } }, ["param2"] = 0, ["param1"] = 0 }, { ["y"] = 0, ["x"] = 3, ["name"] = "default:sand", ["z"] = 5, ["meta"] = { ["inventory"] = {  }, ["fields"] = {  } }, ["param2"] = 0, ["param1"] = 0 }, { ["y"] = 0, ["x"] = 3, ["name"] = "default:sand", ["z"] = 6, ["meta"] = { ["inventory"] = {  }, ["fields"] = {  } }, ["param2"] = 0, ["param1"] = 0 }, { ["y"] = 0, ["x"] = 3, ["name"] = "default:sand", ["z"] = 7, ["meta"] = { ["inventory"] = {  }, ["fields"] = {  } }, ["param2"] = 0, ["param1"] = 0 }, { ["y"] = 0, ["x"] = 3, ["name"] = "default:sand", ["z"] = 8, ["meta"] = { ["inventory"] = {  }, ["fields"] = {  } }, ["param2"] = 0, ["param1"] = 0 }, { ["y"] = 0, ["x"] = 3, ["name"] = "default:sand", ["z"] = 9, ["meta"] = { ["inventory"] = {  }, ["fields"] = {  } }, ["param2"] = 0, ["param1"] = 0 }, { ["y"] = 0, ["x"] = 3, ["name"] = "default:sand", ["z"] = 10, ["meta"] = { ["inventory"] = {  }, ["fields"] = {  } }, ["param2"] = 0, ["param1"] = 0 }, { ["y"] = 0, ["x"] = 3, ["name"] = "default:sand", ["z"] = 11, ["meta"] = { ["inventory"] = {  }, ["fields"] = {  } }, ["param2"] = 0, ["param1"] = 0 }, { ["y"] = 0, ["x"] = 3, ["name"] = "default:sand", ["z"] = 12, ["meta"] = { ["inventory"] = {  }, ["fields"] = {  } }, ["param2"] = 0, ["param1"] = 0 }, { ["y"] = 0, ["x"] = 3, ["name"] = "default:sand", ["z"] = 13, ["meta"] = { ["inventory"] = {  }, ["fields"] = {  } }, ["param2"] = 0, ["param1"] = 0 }, { ["y"] = 0, ["x"] = 3, ["name"] = "default:sand", ["z"] = 14, ["meta"] = { ["inventory"] = {  }, ["fields"] = {  } }, ["param2"] = 0, ["param1"] = 0 }, { ["y"] = 0, ["x"] = 3, ["name"] = "default:sand", ["z"] = 15, ["meta"] = { ["inventory"] = {  }, ["fields"] = {  } }, ["param2"] = 0, ["param1"] = 0 }, { ["y"] = 0, ["x"] = 3, ["name"] = "default:stone", ["z"] = 16, ["meta"] = { ["inventory"] = {  }, ["fields"] = {  } }, ["param2"] = 0, ["param1"] = 0 }, { ["y"] = 1, ["x"] = 3, ["name"] = "default:water_source", ["z"] = 0, ["meta"] = { ["inventory"] = {  }, ["fields"] = {  } }, ["param2"] = 240, ["param1"] = 140 }, { ["y"] = 1, ["x"] = 3, ["name"] = "default:water_flowing", ["z"] = 1, ["meta"] = { ["inventory"] = {  }, ["fields"] = {  } }, ["param2"] = 15, ["param1"] = 124 }, { ["y"] = 1, ["x"] = 3, ["name"] = "default:diamondblock", ["z"] = 2, ["meta"] = { ["inventory"] = {  }, ["fields"] = {  } }, ["param2"] = 0, ["param1"] = 0 }, { ["y"] = 1, ["x"] = 3, ["name"] = "default:diamondblock", ["z"] = 3, ["meta"] = { ["inventory"] = {  }, ["fields"] = {  } }, ["param2"] = 0, ["param1"] = 0 }, { ["y"] = 1, ["x"] = 3, ["name"] = "building_blocks:hardwood", ["z"] = 4, ["meta"] = { ["inventory"] = {  }, ["fields"] = {  } }, ["param2"] = 0, ["param1"] = 0 }, { ["y"] = 1, ["x"] = 3, ["name"] = "default:sand", ["z"] = 5, ["meta"] = { ["inventory"] = {  }, ["fields"] = {  } }, ["param2"] = 0, ["param1"] = 0 }, { ["y"] = 1, ["x"] = 3, ["name"] = "default:sand", ["z"] = 6, ["meta"] = { ["inventory"] = {  }, ["fields"] = {  } }, ["param2"] = 0, ["param1"] = 0 }, { ["y"] = 1, ["x"] = 3, ["name"] = "default:sand", ["z"] = 7, ["meta"] = { ["inventory"] = {  }, ["fields"] = {  } }, ["param2"] = 0, ["param1"] = 0 }, { ["y"] = 1, ["x"] = 3, ["name"] = "default:sand", ["z"] = 8, ["meta"] = { ["inventory"] = {  }, ["fields"] = {  } }, ["param2"] = 0, ["param1"] = 0 }, { ["y"] = 1, ["x"] = 3, ["name"] = "default:sand", ["z"] = 9, ["meta"] = { ["inventory"] = {  }, ["fields"] = {  } }, ["param2"] = 0, ["param1"] = 0 }, { ["y"] = 1, ["x"] = 3, ["name"] = "default:sand", ["z"] = 10, ["meta"] = { ["inventory"] = {  }, ["fields"] = {  } }, ["param2"] = 0, ["param1"] = 0 }, { ["y"] = 1, ["x"] = 3, ["name"] = "default:sand", ["z"] = 11, ["meta"] = { ["inventory"] = {  }, ["fields"] = {  } }, ["param2"] = 0, ["param1"] = 0 }, { ["y"] = 1, ["x"] = 3, ["name"] = "default:sand", ["z"] = 12, ["meta"] = { ["inventory"] = {  }, ["fields"] = {  } }, ["param2"] = 0, ["param1"] = 0 }, { ["y"] = 1, ["x"] = 3, ["name"] = "default:sand", ["z"] = 13, ["meta"] = { ["inventory"] = {  }, ["fields"] = {  } }, ["param2"] = 0, ["param1"] = 0 }, { ["y"] = 1, ["x"] = 3, ["name"] = "default:sand", ["z"] = 14, ["meta"] = { ["inventory"] = {  }, ["fields"] = {  } }, ["param2"] = 0, ["param1"] = 0 }, { ["y"] = 1, ["x"] = 3, ["name"] = "default:sand", ["z"] = 15, ["meta"] = { ["inventory"] = {  }, ["fields"] = {  } }, ["param2"] = 0, ["param1"] = 0 }, { ["y"] = 1, ["x"] = 3, ["name"] = "default:sand", ["z"] = 16, ["meta"] = { ["inventory"] = {  }, ["fields"] = {  } }, ["param2"] = 0, ["param1"] = 0 }, { ["y"] = 2, ["x"] = 3, ["name"] = "default:water_source", ["z"] = 0, ["meta"] = { ["inventory"] = {  }, ["fields"] = {  } }, ["param2"] = 240, ["param1"] = 157 }, { ["y"] = 2, ["x"] = 3, ["name"] = "framedglass:steel_framed_obsidian_glass", ["z"] = 1, ["meta"] = { ["inventory"] = {  }, ["fields"] = {  } }, ["param2"] = 0, ["param1"] = 141 }, { ["y"] = 2, ["x"] = 3, ["name"] = "building_blocks:stair_hardwood", ["z"] = 4, ["meta"] = { ["inventory"] = {  }, ["fields"] = {  } }, ["param2"] = 10, ["param1"] = 157 }, { ["y"] = 2, ["x"] = 3, ["name"] = "building_blocks:hardwood", ["z"] = 5, ["meta"] = { ["inventory"] = {  }, ["fields"] = {  } }, ["param2"] = 0, ["param1"] = 0 }, { ["y"] = 2, ["x"] = 3, ["name"] = "default:stonebrick", ["z"] = 6, ["meta"] = { ["inventory"] = {  }, ["fields"] = {  } }, ["param2"] = 0, ["param1"] = 0 }, { ["y"] = 2, ["x"] = 3, ["name"] = "default:stonebrick", ["z"] = 7, ["meta"] = { ["inventory"] = {  }, ["fields"] = {  } }, ["param2"] = 0, ["param1"] = 0 }, { ["y"] = 2, ["x"] = 3, ["name"] = "default:sand", ["z"] = 8, ["meta"] = { ["inventory"] = {  }, ["fields"] = {  } }, ["param2"] = 0, ["param1"] = 0 }, { ["y"] = 2, ["x"] = 3, ["name"] = "default:sand", ["z"] = 9, ["meta"] = { ["inventory"] = {  }, ["fields"] = {  } }, ["param2"] = 0, ["param1"] = 0 }, { ["y"] = 2, ["x"] = 3, ["name"] = "default:sand", ["z"] = 10, ["meta"] = { ["inventory"] = {  }, ["fields"] = {  } }, ["param2"] = 0, ["param1"] = 0 }, { ["y"] = 2, ["x"] = 3, ["name"] = "default:sand", ["z"] = 11, ["meta"] = { ["inventory"] = {  }, ["fields"] = {  } }, ["param2"] = 0, ["param1"] = 0 }, { ["y"] = 2, ["x"] = 3, ["name"] = "default:sand", ["z"] = 12, ["meta"] = { ["inventory"] = {  }, ["fields"] = {  } }, ["param2"] = 0, ["param1"] = 0 }, { ["y"] = 2, ["x"] = 3, ["name"] = "default:sand", ["z"] = 13, ["meta"] = { ["inventory"] = {  }, ["fields"] = {  } }, ["param2"] = 0, ["param1"] = 0 }, { ["y"] = 2, ["x"] = 3, ["name"] = "default:sand", ["z"] = 14, ["meta"] = { ["inventory"] = {  }, ["fields"] = {  } }, ["param2"] = 0, ["param1"] = 0 }, { ["y"] = 2, ["x"] = 3, ["name"] = "default:sand", ["z"] = 15, ["meta"] = { ["inventory"] = {  }, ["fields"] = {  } }, ["param2"] = 0, ["param1"] = 0 }, { ["y"] = 2, ["x"] = 3, ["name"] = "default:sand", ["z"] = 16, ["meta"] = { ["inventory"] = {  }, ["fields"] = {  } }, ["param2"] = 0, ["param1"] = 0 }, { ["y"] = 3, ["x"] = 3, ["name"] = "framedglass:steel_framed_obsidian_glass", ["z"] = 1, ["meta"] = { ["inventory"] = {  }, ["fields"] = {  } }, ["param2"] = 0, ["param1"] = 157 }, { ["y"] = 3, ["x"] = 3, ["name"] = "framedglass:steel_framed_obsidian_glassblue", ["z"] = 9, ["meta"] = { ["inventory"] = {  }, ["fields"] = {  } }, ["param2"] = 0, ["param1"] = 191 }, { ["y"] = 3, ["x"] = 3, ["name"] = "columnia:column_bottom_rusty_block", ["z"] = 14, ["meta"] = { ["inventory"] = {  }, ["fields"] = {  } }, ["param2"] = 0, ["param1"] = 205 }, { ["y"] = 3, ["x"] = 3, ["name"] = "homedecor:torch_wall", ["z"] = 16, ["meta"] = { ["inventory"] = {  }, ["fields"] = {  } }, ["param2"] = 1, ["param1"] = 0 }, { ["y"] = 4, ["x"] = 3, ["name"] = "building_blocks:hardwood", ["z"] = 1, ["meta"] = { ["inventory"] = {  }, ["fields"] = {  } }, ["param2"] = 0, ["param1"] = 0 }, { ["y"] = 4, ["x"] = 3, ["name"] = "signs:sign_wall_green", ["z"] = 2, ["meta"] = { ["inventory"] = {  }, ["fields"] = { ["infotext"] = "Mod Areas et Markers :\
Permet de proteger ses constructions\
- Placer 4 \"marker\" en carre/rectangle\
- Placer le \"boundary marker\" dans la zone dessinee\
- Remplissez les informations demandes puis cliquer sur \"Buy area\"\
(Pour pouvoir beneficier de ce mod il vous faut demander le privilege \"areas\") ", ["text"] = "Mod Areas et Markers :\
Permet de proteger ses constructions\
- Placer 4 \"marker\" en carre/rectangle\
- Placer le \"boundary marker\" dans la zone dessinee\
- Remplissez les informations demandes puis cliquer sur \"Buy area\"\
(Pour pouvoir beneficier de ce mod il vous faut demander le privilege \"areas\")", ["formspec"] = "size[6,4]textarea[0,0;6.5,3;text;;${text}]button_exit[2,3;2,1;ok;Write]background[-0.5,-0.5;7,5;bg_signs_lib.jpg]", ["__signslib_new_format"] = "1" } }, ["param2"] = 2, ["param1"] = 191 }, { ["y"] = 4, ["x"] = 3, ["name"] = "framedglass:steel_framed_obsidian_glassred", ["z"] = 9, ["meta"] = { ["inventory"] = {  }, ["fields"] = {  } }, ["param2"] = 0, ["param1"] = 207 }, { ["y"] = 4, ["x"] = 3, ["name"] = "columnia:column_top_rusty_block", ["z"] = 14, ["meta"] = { ["inventory"] = {  }, ["fields"] = {  } }, ["param2"] = 0, ["param1"] = 189 }, { ["y"] = 5, ["x"] = 3, ["name"] = "darkage:glass", ["z"] = 1, ["meta"] = { ["inventory"] = {  }, ["fields"] = {  } }, ["param2"] = 0, ["param1"] = 223 }, { ["y"] = 5, ["x"] = 3, ["name"] = "signs:sign_wall_green", ["z"] = 2, ["meta"] = { ["inventory"] = {  }, ["fields"] = { ["infotext"] = "Mod Spawn :\
Si vous voulez retourner\
instantannement a cet\
endroit, tapez /spawn ", ["text"] = "Mod Spawn :\
Si vous voulez retourner\
instantannement a cet\
endroit, tapez /spawn", ["formspec"] = "size[6,4]textarea[0,0;6.5,3;text;;${text}]button_exit[2,3;2,1;ok;Write]background[-0.5,-0.5;7,5;bg_signs_lib.jpg]", ["__signslib_new_format"] = "1" } }, ["param2"] = 2, ["param1"] = 207 }, { ["y"] = 5, ["x"] = 3, ["name"] = "framedglass:steel_framed_obsidian_glassyellow", ["z"] = 9, ["meta"] = { ["inventory"] = {  }, ["fields"] = {  } }, ["param2"] = 0, ["param1"] = 191 }, { ["y"] = 5, ["x"] = 3, ["name"] = "columnia:rusty_block", ["z"] = 10, ["meta"] = { ["inventory"] = {  }, ["fields"] = {  } }, ["param2"] = 0, ["param1"] = 0 }, { ["y"] = 5, ["x"] = 3, ["name"] = "columnia:rusty_block", ["z"] = 11, ["meta"] = { ["inventory"] = {  }, ["fields"] = {  } }, ["param2"] = 0, ["param1"] = 0 }, { ["y"] = 5, ["x"] = 3, ["name"] = "columnia:rusty_block", ["z"] = 12, ["meta"] = { ["inventory"] = {  }, ["fields"] = {  } }, ["param2"] = 0, ["param1"] = 0 }, { ["y"] = 5, ["x"] = 3, ["name"] = "columnia:rusty_block", ["z"] = 13, ["meta"] = { ["inventory"] = {  }, ["fields"] = {  } }, ["param2"] = 0, ["param1"] = 0 }, { ["y"] = 5, ["x"] = 3, ["name"] = "columnia:rusty_block", ["z"] = 14, ["meta"] = { ["inventory"] = {  }, ["fields"] = {  } }, ["param2"] = 0, ["param1"] = 0 }, { ["y"] = 6, ["x"] = 3, ["name"] = "building_blocks:smoothglass", ["z"] = 1, ["meta"] = { ["inventory"] = {  }, ["fields"] = {  } }, ["param2"] = 0, ["param1"] = 207 }, { ["y"] = 6, ["x"] = 3, ["name"] = "building_blocks:smoothglass", ["z"] = 8, ["meta"] = { ["inventory"] = {  }, ["fields"] = {  } }, ["param2"] = 0, ["param1"] = 191 }, { ["y"] = 6, ["x"] = 3, ["name"] = "framedglass:steel_framed_obsidian_glass", ["z"] = 9, ["meta"] = { ["inventory"] = {  }, ["fields"] = {  } }, ["param2"] = 0, ["param1"] = 175 }, { ["y"] = 6, ["x"] = 3, ["name"] = "columnia:rusty_block", ["z"] = 10, ["meta"] = { ["inventory"] = {  }, ["fields"] = {  } }, ["param2"] = 0, ["param1"] = 0 }, { ["y"] = 6, ["x"] = 3, ["name"] = "columnia:rusty_block", ["z"] = 11, ["meta"] = { ["inventory"] = {  }, ["fields"] = {  } }, ["param2"] = 0, ["param1"] = 0 }, { ["y"] = 7, ["x"] = 3, ["name"] = "building_blocks:smoothglass", ["z"] = 2, ["meta"] = { ["inventory"] = {  }, ["fields"] = {  } }, ["param2"] = 0, ["param1"] = 175 }, { ["y"] = 7, ["x"] = 3, ["name"] = "building_blocks:smoothglass", ["z"] = 5, ["meta"] = { ["inventory"] = {  }, ["fields"] = {  } }, ["param2"] = 0, ["param1"] = 207 }, { ["y"] = 7, ["x"] = 3, ["name"] = "building_blocks:smoothglass", ["z"] = 6, ["meta"] = { ["inventory"] = {  }, ["fields"] = {  } }, ["param2"] = 0, ["param1"] = 191 }, { ["y"] = 7, ["x"] = 3, ["name"] = "building_blocks:smoothglass", ["z"] = 7, ["meta"] = { ["inventory"] = {  }, ["fields"] = {  } }, ["param2"] = 0, ["param1"] = 175 }, { ["y"] = 8, ["x"] = 3, ["name"] = "building_blocks:smoothglass", ["z"] = 3, ["meta"] = { ["inventory"] = {  }, ["fields"] = {  } }, ["param2"] = 0, ["param1"] = 159 }, { ["y"] = 8, ["x"] = 3, ["name"] = "building_blocks:smoothglass", ["z"] = 4, ["meta"] = { ["inventory"] = {  }, ["fields"] = {  } }, ["param2"] = 0, ["param1"] = 175 }, { ["y"] = 0, ["x"] = 4, ["name"] = "default:water_source", ["z"] = 0, ["meta"] = { ["inventory"] = {  }, ["fields"] = {  } }, ["param2"] = 240, ["param1"] = 139 }, { ["y"] = 0, ["x"] = 4, ["name"] = "default:water_flowing", ["z"] = 1, ["meta"] = { ["inventory"] = {  }, ["fields"] = {  } }, ["param2"] = 7, ["param1"] = 123 }, { ["y"] = 0, ["x"] = 4, ["name"] = "default:sand", ["z"] = 2, ["meta"] = { ["inventory"] = {  }, ["fields"] = {  } }, ["param2"] = 0, ["param1"] = 0 }, { ["y"] = 0, ["x"] = 4, ["name"] = "default:stone", ["z"] = 3, ["meta"] = { ["inventory"] = {  }, ["fields"] = {  } }, ["param2"] = 0, ["param1"] = 0 }, { ["y"] = 0, ["x"] = 4, ["name"] = "default:sand", ["z"] = 4, ["meta"] = { ["inventory"] = {  }, ["fields"] = {  } }, ["param2"] = 0, ["param1"] = 0 }, { ["y"] = 0, ["x"] = 4, ["name"] = "default:sand", ["z"] = 5, ["meta"] = { ["inventory"] = {  }, ["fields"] = {  } }, ["param2"] = 0, ["param1"] = 0 }, { ["y"] = 0, ["x"] = 4, ["name"] = "default:sand", ["z"] = 6, ["meta"] = { ["inventory"] = {  }, ["fields"] = {  } }, ["param2"] = 0, ["param1"] = 0 }, { ["y"] = 0, ["x"] = 4, ["name"] = "default:sand", ["z"] = 7, ["meta"] = { ["inventory"] = {  }, ["fields"] = {  } }, ["param2"] = 0, ["param1"] = 0 }, { ["y"] = 0, ["x"] = 4, ["name"] = "default:sand", ["z"] = 8, ["meta"] = { ["inventory"] = {  }, ["fields"] = {  } }, ["param2"] = 0, ["param1"] = 0 }, { ["y"] = 0, ["x"] = 4, ["name"] = "default:sand", ["z"] = 9, ["meta"] = { ["inventory"] = {  }, ["fields"] = {  } }, ["param2"] = 0, ["param1"] = 0 }, { ["y"] = 0, ["x"] = 4, ["name"] = "default:sand", ["z"] = 10, ["meta"] = { ["inventory"] = {  }, ["fields"] = {  } }, ["param2"] = 0, ["param1"] = 0 }, { ["y"] = 0, ["x"] = 4, ["name"] = "default:sand", ["z"] = 11, ["meta"] = { ["inventory"] = {  }, ["fields"] = {  } }, ["param2"] = 0, ["param1"] = 0 }, { ["y"] = 0, ["x"] = 4, ["name"] = "default:sand", ["z"] = 12, ["meta"] = { ["inventory"] = {  }, ["fields"] = {  } }, ["param2"] = 0, ["param1"] = 0 }, { ["y"] = 0, ["x"] = 4, ["name"] = "default:sand", ["z"] = 13, ["meta"] = { ["inventory"] = {  }, ["fields"] = {  } }, ["param2"] = 0, ["param1"] = 0 }, { ["y"] = 0, ["x"] = 4, ["name"] = "default:stone", ["z"] = 14, ["meta"] = { ["inventory"] = {  }, ["fields"] = {  } }, ["param2"] = 0, ["param1"] = 0 }, { ["y"] = 0, ["x"] = 4, ["name"] = "default:stone", ["z"] = 15, ["meta"] = { ["inventory"] = {  }, ["fields"] = {  } }, ["param2"] = 0, ["param1"] = 0 }, { ["y"] = 0, ["x"] = 4, ["name"] = "default:stone", ["z"] = 16, ["meta"] = { ["inventory"] = {  }, ["fields"] = {  } }, ["param2"] = 0, ["param1"] = 0 }, { ["y"] = 1, ["x"] = 4, ["name"] = "default:water_source", ["z"] = 0, ["meta"] = { ["inventory"] = {  }, ["fields"] = {  } }, ["param2"] = 240, ["param1"] = 156 }, { ["y"] = 1, ["x"] = 4, ["name"] = "default:water_flowing", ["z"] = 1, ["meta"] = { ["inventory"] = {  }, ["fields"] = {  } }, ["param2"] = 15, ["param1"] = 140 }, { ["y"] = 1, ["x"] = 4, ["name"] = "moreblocks:circle_stone_bricks", ["z"] = 2, ["meta"] = { ["inventory"] = {  }, ["fields"] = {  } }, ["param2"] = 0, ["param1"] = 0 }, { ["y"] = 1, ["x"] = 4, ["name"] = "default:stonebrick", ["z"] = 3, ["meta"] = { ["inventory"] = {  }, ["fields"] = {  } }, ["param2"] = 0, ["param1"] = 0 }, { ["y"] = 1, ["x"] = 4, ["name"] = "default:sand", ["z"] = 4, ["meta"] = { ["inventory"] = {  }, ["fields"] = {  } }, ["param2"] = 0, ["param1"] = 0 }, { ["y"] = 1, ["x"] = 4, ["name"] = "default:sand", ["z"] = 5, ["meta"] = { ["inventory"] = {  }, ["fields"] = {  } }, ["param2"] = 0, ["param1"] = 0 }, { ["y"] = 1, ["x"] = 4, ["name"] = "default:sand", ["z"] = 6, ["meta"] = { ["inventory"] = {  }, ["fields"] = {  } }, ["param2"] = 0, ["param1"] = 0 }, { ["y"] = 1, ["x"] = 4, ["name"] = "default:sand", ["z"] = 7, ["meta"] = { ["inventory"] = {  }, ["fields"] = {  } }, ["param2"] = 0, ["param1"] = 0 }, { ["y"] = 1, ["x"] = 4, ["name"] = "default:sand", ["z"] = 8, ["meta"] = { ["inventory"] = {  }, ["fields"] = {  } }, ["param2"] = 0, ["param1"] = 0 }, { ["y"] = 1, ["x"] = 4, ["name"] = "default:sand", ["z"] = 9, ["meta"] = { ["inventory"] = {  }, ["fields"] = {  } }, ["param2"] = 0, ["param1"] = 0 }, { ["y"] = 1, ["x"] = 4, ["name"] = "default:sand", ["z"] = 10, ["meta"] = { ["inventory"] = {  }, ["fields"] = {  } }, ["param2"] = 0, ["param1"] = 0 }, { ["y"] = 1, ["x"] = 4, ["name"] = "default:sand", ["z"] = 11, ["meta"] = { ["inventory"] = {  }, ["fields"] = {  } }, ["param2"] = 0, ["param1"] = 0 }, { ["y"] = 1, ["x"] = 4, ["name"] = "default:sand", ["z"] = 12, ["meta"] = { ["inventory"] = {  }, ["fields"] = {  } }, ["param2"] = 0, ["param1"] = 0 }, { ["y"] = 1, ["x"] = 4, ["name"] = "default:sand", ["z"] = 13, ["meta"] = { ["inventory"] = {  }, ["fields"] = {  } }, ["param2"] = 0, ["param1"] = 0 }, { ["y"] = 1, ["x"] = 4, ["name"] = "default:sand", ["z"] = 14, ["meta"] = { ["inventory"] = {  }, ["fields"] = {  } }, ["param2"] = 0, ["param1"] = 0 }, { ["y"] = 1, ["x"] = 4, ["name"] = "default:sand", ["z"] = 15, ["meta"] = { ["inventory"] = {  }, ["fields"] = {  } }, ["param2"] = 0, ["param1"] = 0 }, { ["y"] = 1, ["x"] = 4, ["name"] = "default:sand", ["z"] = 16, ["meta"] = { ["inventory"] = {  }, ["fields"] = {  } }, ["param2"] = 0, ["param1"] = 0 }, { ["y"] = 2, ["x"] = 4, ["name"] = "default:water_source", ["z"] = 0, ["meta"] = { ["inventory"] = {  }, ["fields"] = {  } }, ["param2"] = 240, ["param1"] = 173 }, { ["y"] = 2, ["x"] = 4, ["name"] = "framedglass:steel_framed_obsidian_glass", ["z"] = 1, ["meta"] = { ["inventory"] = {  }, ["fields"] = {  } }, ["param2"] = 0, ["param1"] = 157 }, { ["y"] = 2, ["x"] = 4, ["name"] = "moreblocks:stair_stonebrick", ["z"] = 4, ["meta"] = { ["inventory"] = {  }, ["fields"] = {  } }, ["param2"] = 0, ["param1"] = 143 }, { ["y"] = 2, ["x"] = 4, ["name"] = "default:stonebrick", ["z"] = 5, ["meta"] = { ["inventory"] = {  }, ["fields"] = {  } }, ["param2"] = 0, ["param1"] = 0 }, { ["y"] = 2, ["x"] = 4, ["name"] = "default:stonebrick", ["z"] = 6, ["meta"] = { ["inventory"] = {  }, ["fields"] = {  } }, ["param2"] = 0, ["param1"] = 0 }, { ["y"] = 2, ["x"] = 4, ["name"] = "default:stonebrick", ["z"] = 7, ["meta"] = { ["inventory"] = {  }, ["fields"] = {  } }, ["param2"] = 0, ["param1"] = 0 }, { ["y"] = 2, ["x"] = 4, ["name"] = "default:stonebrick", ["z"] = 8, ["meta"] = { ["inventory"] = {  }, ["fields"] = {  } }, ["param2"] = 0, ["param1"] = 0 }, { ["y"] = 2, ["x"] = 4, ["name"] = "default:sand", ["z"] = 9, ["meta"] = { ["inventory"] = {  }, ["fields"] = {  } }, ["param2"] = 0, ["param1"] = 0 }, { ["y"] = 2, ["x"] = 4, ["name"] = "default:sand", ["z"] = 10, ["meta"] = { ["inventory"] = {  }, ["fields"] = {  } }, ["param2"] = 0, ["param1"] = 0 }, { ["y"] = 2, ["x"] = 4, ["name"] = "default:sand", ["z"] = 11, ["meta"] = { ["inventory"] = {  }, ["fields"] = {  } }, ["param2"] = 0, ["param1"] = 0 }, { ["y"] = 2, ["x"] = 4, ["name"] = "default:sand", ["z"] = 12, ["meta"] = { ["inventory"] = {  }, ["fields"] = {  } }, ["param2"] = 0, ["param1"] = 0 }, { ["y"] = 2, ["x"] = 4, ["name"] = "default:sand", ["z"] = 13, ["meta"] = { ["inventory"] = {  }, ["fields"] = {  } }, ["param2"] = 0, ["param1"] = 0 }, { ["y"] = 2, ["x"] = 4, ["name"] = "default:sand", ["z"] = 14, ["meta"] = { ["inventory"] = {  }, ["fields"] = {  } }, ["param2"] = 0, ["param1"] = 0 }, { ["y"] = 2, ["x"] = 4, ["name"] = "default:sand", ["z"] = 15, ["meta"] = { ["inventory"] = {  }, ["fields"] = {  } }, ["param2"] = 0, ["param1"] = 0 }, { ["y"] = 2, ["x"] = 4, ["name"] = "default:sand", ["z"] = 16, ["meta"] = { ["inventory"] = {  }, ["fields"] = {  } }, ["param2"] = 0, ["param1"] = 0 }, { ["y"] = 3, ["x"] = 4, ["name"] = "flowers:waterlily_225", ["z"] = 0, ["meta"] = { ["inventory"] = {  }, ["fields"] = {  } }, ["param2"] = 2, ["param1"] = 191 }, { ["y"] = 3, ["x"] = 4, ["name"] = "framedglass:steel_framed_obsidian_glass", ["z"] = 1, ["meta"] = { ["inventory"] = {  }, ["fields"] = {  } }, ["param2"] = 0, ["param1"] = 173 }, { ["y"] = 3, ["x"] = 4, ["name"] = "doors:door_steel_b_1", ["z"] = 9, ["meta"] = { ["inventory"] = {  }, ["fields"] = { ["doors_owner"] = "Darcidride", ["infotext"] = "Owned by Darcidride" } }, ["param2"] = 0, ["param1"] = 173 }, { ["y"] = 3, ["x"] = 4, ["name"] = "framedglass:steel_framed_obsidian_glassbrown", ["z"] = 16, ["meta"] = { ["inventory"] = {  }, ["fields"] = {  } }, ["param2"] = 0, ["param1"] = 221 }, { ["y"] = 4, ["x"] = 4, ["name"] = "building_blocks:hardwood", ["z"] = 1, ["meta"] = { ["inventory"] = {  }, ["fields"] = {  } }, ["param2"] = 0, ["param1"] = 0 }, { ["y"] = 4, ["x"] = 4, ["name"] = "signs:sign_wall_green", ["z"] = 2, ["meta"] = { ["inventory"] = {  }, ["fields"] = { ["infotext"] = "Mod Rules :\
Pour pouvoir commencer a\
construire et modifier le serveur, vous devez lire puis accepter les regles du serveur, pour ce faire, tapez /rules ", ["text"] = "Mod Rules :\
Pour pouvoir commencer a\
construire et modifier le serveur, vous devez lire puis accepter les regles du serveur, pour ce faire, tapez /rules", ["formspec"] = "size[6,4]textarea[0,0;6.5,3;text;;${text}]button_exit[2,3;2,1;ok;Write]background[-0.5,-0.5;7,5;bg_signs_lib.jpg]", ["__signslib_new_format"] = "1" } }, ["param2"] = 2, ["param1"] = 207 }, { ["y"] = 4, ["x"] = 4, ["name"] = "doors:door_steel_t_1", ["z"] = 9, ["meta"] = { ["inventory"] = {  }, ["fields"] = { ["doors_owner"] = "Darcidride", ["infotext"] = "Owned by Darcidride" } }, ["param2"] = 0, ["param1"] = 189 }, { ["y"] = 4, ["x"] = 4, ["name"] = "signs:sign_yard", ["z"] = 16, ["meta"] = { ["inventory"] = {  }, ["fields"] = { ["infotext"] = "Merci d'avoir lu le reglement du serveur, l'equipe de MinetestForFun vous souhaite bon jeu et surtout, amusez vous bien ! ", ["text"] = "Merci d'avoir lu le reglement du serveur, l'equipe de MinetestForFun vous souhaite bon jeu et surtout, amusez vous bien !", ["formspec"] = "size[6,4]textarea[0,-0.3;6.5,3;text;;${text}]button_exit[2,3.4;2,1;ok;Write]background[-0.5,-0.5;7,5;bg_signs_lib.jpg]", ["__signslib_new_format"] = "1" } }, ["param2"] = 0, ["param1"] = 205 }, { ["y"] = 5, ["x"] = 4, ["name"] = "moreblocks:super_glow_glass", ["z"] = 1, ["meta"] = { ["inventory"] = {  }, ["fields"] = {  } }, ["param2"] = 0, ["param1"] = 0 }, { ["y"] = 5, ["x"] = 4, ["name"] = "signs:sign_wall_white_red", ["z"] = 2, ["meta"] = { ["inventory"] = {  }, ["fields"] = { ["infotext"] = "Bienvenue,\
Amusez vous bien sur \
FR - MinetestForFun (Survival) !\
(nous vous recommandons\
de lire les panneaux) ", ["text"] = "Bienvenue,\
Amusez vous bien sur \
FR - MinetestForFun (Survival) !\
(nous vous recommandons\
de lire les panneaux)", ["formspec"] = "size[6,4]textarea[0,0;6.5,3;text;;${text}]button_exit[2,3;2,1;ok;Write]background[-0.5,-0.5;7,5;bg_signs_lib.jpg]", ["__signslib_new_format"] = "1" } }, ["param2"] = 2, ["param1"] = 223 }, { ["y"] = 5, ["x"] = 4, ["name"] = "framedglass:steel_framed_obsidian_glasscyan", ["z"] = 9, ["meta"] = { ["inventory"] = {  }, ["fields"] = {  } }, ["param2"] = 0, ["param1"] = 175 }, { ["y"] = 5, ["x"] = 4, ["name"] = "columnia:rusty_block", ["z"] = 10, ["meta"] = { ["inventory"] = {  }, ["fields"] = {  } }, ["param2"] = 0, ["param1"] = 0 }, { ["y"] = 5, ["x"] = 4, ["name"] = "columnia:rusty_block", ["z"] = 11, ["meta"] = { ["inventory"] = {  }, ["fields"] = {  } }, ["param2"] = 0, ["param1"] = 0 }, { ["y"] = 5, ["x"] = 4, ["name"] = "columnia:rusty_block", ["z"] = 12, ["meta"] = { ["inventory"] = {  }, ["fields"] = {  } }, ["param2"] = 0, ["param1"] = 0 }, { ["y"] = 5, ["x"] = 4, ["name"] = "columnia:rusty_block", ["z"] = 13, ["meta"] = { ["inventory"] = {  }, ["fields"] = {  } }, ["param2"] = 0, ["param1"] = 0 }, { ["y"] = 5, ["x"] = 4, ["name"] = "columnia:rusty_block", ["z"] = 14, ["meta"] = { ["inventory"] = {  }, ["fields"] = {  } }, ["param2"] = 0, ["param1"] = 0 }, { ["y"] = 6, ["x"] = 4, ["name"] = "building_blocks:smoothglass", ["z"] = 1, ["meta"] = { ["inventory"] = {  }, ["fields"] = {  } }, ["param2"] = 0, ["param1"] = 223 }, { ["y"] = 6, ["x"] = 4, ["name"] = "chains:chandelier_brass", ["z"] = 4, ["meta"] = { ["inventory"] = {  }, ["fields"] = {  } }, ["param2"] = 0, ["param1"] = 15 }, { ["y"] = 6, ["x"] = 4, ["name"] = "building_blocks:smoothglass", ["z"] = 8, ["meta"] = { ["inventory"] = {  }, ["fields"] = {  } }, ["param2"] = 0, ["param1"] = 175 }, { ["y"] = 6, ["x"] = 4, ["name"] = "framedglass:steel_framed_obsidian_glass", ["z"] = 9, ["meta"] = { ["inventory"] = {  }, ["fields"] = {  } }, ["param2"] = 0, ["param1"] = 159 }, { ["y"] = 6, ["x"] = 4, ["name"] = "columnia:rusty_block", ["z"] = 10, ["meta"] = { ["inventory"] = {  }, ["fields"] = {  } }, ["param2"] = 0, ["param1"] = 0 }, { ["y"] = 6, ["x"] = 4, ["name"] = "columnia:rusty_block", ["z"] = 11, ["meta"] = { ["inventory"] = {  }, ["fields"] = {  } }, ["param2"] = 0, ["param1"] = 0 }, { ["y"] = 6, ["x"] = 4, ["name"] = "columnia:rusty_block", ["z"] = 12, ["meta"] = { ["inventory"] = {  }, ["fields"] = {  } }, ["param2"] = 0, ["param1"] = 0 }, { ["y"] = 6, ["x"] = 4, ["name"] = "columnia:rusty_block", ["z"] = 13, ["meta"] = { ["inventory"] = {  }, ["fields"] = {  } }, ["param2"] = 0, ["param1"] = 0 }, { ["y"] = 7, ["x"] = 4, ["name"] = "building_blocks:smoothglass", ["z"] = 2, ["meta"] = { ["inventory"] = {  }, ["fields"] = {  } }, ["param2"] = 0, ["param1"] = 191 }, { ["y"] = 7, ["x"] = 4, ["name"] = "chains:chain_brass", ["z"] = 4, ["meta"] = { ["inventory"] = {  }, ["fields"] = {  } }, ["param2"] = 0, ["param1"] = 191 }, { ["y"] = 7, ["x"] = 4, ["name"] = "building_blocks:smoothglass", ["z"] = 7, ["meta"] = { ["inventory"] = {  }, ["fields"] = {  } }, ["param2"] = 0, ["param1"] = 159 }, { ["y"] = 8, ["x"] = 4, ["name"] = "building_blocks:smoothglass", ["z"] = 3, ["meta"] = { ["inventory"] = {  }, ["fields"] = {  } }, ["param2"] = 0, ["param1"] = 159 }, { ["y"] = 8, ["x"] = 4, ["name"] = "building_blocks:smoothglass", ["z"] = 4, ["meta"] = { ["inventory"] = {  }, ["fields"] = {  } }, ["param2"] = 0, ["param1"] = 175 }, { ["y"] = 8, ["x"] = 4, ["name"] = "building_blocks:smoothglass", ["z"] = 5, ["meta"] = { ["inventory"] = {  }, ["fields"] = {  } }, ["param2"] = 0, ["param1"] = 175 }, { ["y"] = 8, ["x"] = 4, ["name"] = "building_blocks:smoothglass", ["z"] = 6, ["meta"] = { ["inventory"] = {  }, ["fields"] = {  } }, ["param2"] = 0, ["param1"] = 159 }, { ["y"] = 0, ["x"] = 5, ["name"] = "default:water_source", ["z"] = 0, ["meta"] = { ["inventory"] = {  }, ["fields"] = {  } }, ["param2"] = 240, ["param1"] = 122 }, { ["y"] = 0, ["x"] = 5, ["name"] = "default:water_flowing", ["z"] = 1, ["meta"] = { ["inventory"] = {  }, ["fields"] = {  } }, ["param2"] = 7, ["param1"] = 107 }, { ["y"] = 0, ["x"] = 5, ["name"] = "default:sand", ["z"] = 2, ["meta"] = { ["inventory"] = {  }, ["fields"] = {  } }, ["param2"] = 0, ["param1"] = 0 }, { ["y"] = 0, ["x"] = 5, ["name"] = "default:stone", ["z"] = 3, ["meta"] = { ["inventory"] = {  }, ["fields"] = {  } }, ["param2"] = 0, ["param1"] = 0 }, { ["y"] = 0, ["x"] = 5, ["name"] = "default:stone", ["z"] = 4, ["meta"] = { ["inventory"] = {  }, ["fields"] = {  } }, ["param2"] = 0, ["param1"] = 0 }, { ["y"] = 0, ["x"] = 5, ["name"] = "default:stone", ["z"] = 5, ["meta"] = { ["inventory"] = {  }, ["fields"] = {  } }, ["param2"] = 0, ["param1"] = 0 }, { ["y"] = 0, ["x"] = 5, ["name"] = "default:sand", ["z"] = 6, ["meta"] = { ["inventory"] = {  }, ["fields"] = {  } }, ["param2"] = 0, ["param1"] = 0 }, { ["y"] = 0, ["x"] = 5, ["name"] = "default:sand", ["z"] = 7, ["meta"] = { ["inventory"] = {  }, ["fields"] = {  } }, ["param2"] = 0, ["param1"] = 0 }, { ["y"] = 0, ["x"] = 5, ["name"] = "default:sand", ["z"] = 8, ["meta"] = { ["inventory"] = {  }, ["fields"] = {  } }, ["param2"] = 0, ["param1"] = 0 }, { ["y"] = 0, ["x"] = 5, ["name"] = "default:sand", ["z"] = 9, ["meta"] = { ["inventory"] = {  }, ["fields"] = {  } }, ["param2"] = 0, ["param1"] = 0 }, { ["y"] = 0, ["x"] = 5, ["name"] = "default:stone", ["z"] = 10, ["meta"] = { ["inventory"] = {  }, ["fields"] = {  } }, ["param2"] = 0, ["param1"] = 0 }, { ["y"] = 0, ["x"] = 5, ["name"] = "default:stone", ["z"] = 11, ["meta"] = { ["inventory"] = {  }, ["fields"] = {  } }, ["param2"] = 0, ["param1"] = 0 }, { ["y"] = 0, ["x"] = 5, ["name"] = "default:stone", ["z"] = 12, ["meta"] = { ["inventory"] = {  }, ["fields"] = {  } }, ["param2"] = 0, ["param1"] = 0 }, { ["y"] = 0, ["x"] = 5, ["name"] = "default:stone", ["z"] = 13, ["meta"] = { ["inventory"] = {  }, ["fields"] = {  } }, ["param2"] = 0, ["param1"] = 0 }, { ["y"] = 0, ["x"] = 5, ["name"] = "default:stone", ["z"] = 14, ["meta"] = { ["inventory"] = {  }, ["fields"] = {  } }, ["param2"] = 0, ["param1"] = 0 }, { ["y"] = 0, ["x"] = 5, ["name"] = "default:stone", ["z"] = 15, ["meta"] = { ["inventory"] = {  }, ["fields"] = {  } }, ["param2"] = 0, ["param1"] = 0 }, { ["y"] = 0, ["x"] = 5, ["name"] = "default:stone", ["z"] = 16, ["meta"] = { ["inventory"] = {  }, ["fields"] = {  } }, ["param2"] = 0, ["param1"] = 0 }, { ["y"] = 1, ["x"] = 5, ["name"] = "default:water_source", ["z"] = 0, ["meta"] = { ["inventory"] = {  }, ["fields"] = {  } }, ["param2"] = 240, ["param1"] = 139 }, { ["y"] = 1, ["x"] = 5, ["name"] = "default:water_flowing", ["z"] = 1, ["meta"] = { ["inventory"] = {  }, ["fields"] = {  } }, ["param2"] = 15, ["param1"] = 124 }, { ["y"] = 1, ["x"] = 5, ["name"] = "default:diamondblock", ["z"] = 2, ["meta"] = { ["inventory"] = {  }, ["fields"] = {  } }, ["param2"] = 0, ["param1"] = 0 }, { ["y"] = 1, ["x"] = 5, ["name"] = "default:diamondblock", ["z"] = 3, ["meta"] = { ["inventory"] = {  }, ["fields"] = {  } }, ["param2"] = 0, ["param1"] = 0 }, { ["y"] = 1, ["x"] = 5, ["name"] = "building_blocks:hardwood", ["z"] = 4, ["meta"] = { ["inventory"] = {  }, ["fields"] = {  } }, ["param2"] = 0, ["param1"] = 0 }, { ["y"] = 1, ["x"] = 5, ["name"] = "default:sand", ["z"] = 5, ["meta"] = { ["inventory"] = {  }, ["fields"] = {  } }, ["param2"] = 0, ["param1"] = 0 }, { ["y"] = 1, ["x"] = 5, ["name"] = "default:sand", ["z"] = 6, ["meta"] = { ["inventory"] = {  }, ["fields"] = {  } }, ["param2"] = 0, ["param1"] = 0 }, { ["y"] = 1, ["x"] = 5, ["name"] = "default:sand", ["z"] = 7, ["meta"] = { ["inventory"] = {  }, ["fields"] = {  } }, ["param2"] = 0, ["param1"] = 0 }, { ["y"] = 1, ["x"] = 5, ["name"] = "default:sand", ["z"] = 8, ["meta"] = { ["inventory"] = {  }, ["fields"] = {  } }, ["param2"] = 0, ["param1"] = 0 }, { ["y"] = 1, ["x"] = 5, ["name"] = "default:sand", ["z"] = 9, ["meta"] = { ["inventory"] = {  }, ["fields"] = {  } }, ["param2"] = 0, ["param1"] = 0 }, { ["y"] = 1, ["x"] = 5, ["name"] = "default:sand", ["z"] = 10, ["meta"] = { ["inventory"] = {  }, ["fields"] = {  } }, ["param2"] = 0, ["param1"] = 0 }, { ["y"] = 1, ["x"] = 5, ["name"] = "default:sand", ["z"] = 11, ["meta"] = { ["inventory"] = {  }, ["fields"] = {  } }, ["param2"] = 0, ["param1"] = 0 }, { ["y"] = 1, ["x"] = 5, ["name"] = "default:sand", ["z"] = 12, ["meta"] = { ["inventory"] = {  }, ["fields"] = {  } }, ["param2"] = 0, ["param1"] = 0 }, { ["y"] = 1, ["x"] = 5, ["name"] = "default:sand", ["z"] = 13, ["meta"] = { ["inventory"] = {  }, ["fields"] = {  } }, ["param2"] = 0, ["param1"] = 0 }, { ["y"] = 1, ["x"] = 5, ["name"] = "default:sand", ["z"] = 14, ["meta"] = { ["inventory"] = {  }, ["fields"] = {  } }, ["param2"] = 0, ["param1"] = 0 }, { ["y"] = 1, ["x"] = 5, ["name"] = "default:sand", ["z"] = 15, ["meta"] = { ["inventory"] = {  }, ["fields"] = {  } }, ["param2"] = 0, ["param1"] = 0 }, { ["y"] = 1, ["x"] = 5, ["name"] = "default:sand", ["z"] = 16, ["meta"] = { ["inventory"] = {  }, ["fields"] = {  } }, ["param2"] = 0, ["param1"] = 0 }, { ["y"] = 2, ["x"] = 5, ["name"] = "default:water_source", ["z"] = 0, ["meta"] = { ["inventory"] = {  }, ["fields"] = {  } }, ["param2"] = 240, ["param1"] = 156 }, { ["y"] = 2, ["x"] = 5, ["name"] = "framedglass:steel_framed_obsidian_glass", ["z"] = 1, ["meta"] = { ["inventory"] = {  }, ["fields"] = {  } }, ["param2"] = 0, ["param1"] = 141 }, { ["y"] = 2, ["x"] = 5, ["name"] = "building_blocks:stair_hardwood", ["z"] = 4, ["meta"] = { ["inventory"] = {  }, ["fields"] = {  } }, ["param2"] = 0, ["param1"] = 157 }, { ["y"] = 2, ["x"] = 5, ["name"] = "building_blocks:hardwood", ["z"] = 5, ["meta"] = { ["inventory"] = {  }, ["fields"] = {  } }, ["param2"] = 0, ["param1"] = 0 }, { ["y"] = 2, ["x"] = 5, ["name"] = "default:stonebrick", ["z"] = 6, ["meta"] = { ["inventory"] = {  }, ["fields"] = {  } }, ["param2"] = 0, ["param1"] = 0 }, { ["y"] = 2, ["x"] = 5, ["name"] = "default:stonebrick", ["z"] = 7, ["meta"] = { ["inventory"] = {  }, ["fields"] = {  } }, ["param2"] = 0, ["param1"] = 0 }, { ["y"] = 2, ["x"] = 5, ["name"] = "default:sand", ["z"] = 8, ["meta"] = { ["inventory"] = {  }, ["fields"] = {  } }, ["param2"] = 0, ["param1"] = 0 }, { ["y"] = 2, ["x"] = 5, ["name"] = "default:sand", ["z"] = 9, ["meta"] = { ["inventory"] = {  }, ["fields"] = {  } }, ["param2"] = 0, ["param1"] = 0 }, { ["y"] = 2, ["x"] = 5, ["name"] = "default:sand", ["z"] = 10, ["meta"] = { ["inventory"] = {  }, ["fields"] = {  } }, ["param2"] = 0, ["param1"] = 0 }, { ["y"] = 2, ["x"] = 5, ["name"] = "default:sand", ["z"] = 11, ["meta"] = { ["inventory"] = {  }, ["fields"] = {  } }, ["param2"] = 0, ["param1"] = 0 }, { ["y"] = 2, ["x"] = 5, ["name"] = "default:sand", ["z"] = 12, ["meta"] = { ["inventory"] = {  }, ["fields"] = {  } }, ["param2"] = 0, ["param1"] = 0 }, { ["y"] = 2, ["x"] = 5, ["name"] = "default:sand", ["z"] = 13, ["meta"] = { ["inventory"] = {  }, ["fields"] = {  } }, ["param2"] = 0, ["param1"] = 0 }, { ["y"] = 2, ["x"] = 5, ["name"] = "default:sand", ["z"] = 14, ["meta"] = { ["inventory"] = {  }, ["fields"] = {  } }, ["param2"] = 0, ["param1"] = 0 }, { ["y"] = 2, ["x"] = 5, ["name"] = "default:sand", ["z"] = 15, ["meta"] = { ["inventory"] = {  }, ["fields"] = {  } }, ["param2"] = 0, ["param1"] = 0 }, { ["y"] = 2, ["x"] = 5, ["name"] = "default:sand", ["z"] = 16, ["meta"] = { ["inventory"] = {  }, ["fields"] = {  } }, ["param2"] = 0, ["param1"] = 0 }, { ["y"] = 3, ["x"] = 5, ["name"] = "framedglass:steel_framed_obsidian_glass", ["z"] = 1, ["meta"] = { ["inventory"] = {  }, ["fields"] = {  } }, ["param2"] = 0, ["param1"] = 157 }, { ["y"] = 3, ["x"] = 5, ["name"] = "mesecons_button:button_off", ["z"] = 8, ["meta"] = { ["inventory"] = {  }, ["fields"] = {  } }, ["param2"] = 0, ["param1"] = 207 }, { ["y"] = 3, ["x"] = 5, ["name"] = "default:mese", ["z"] = 9, ["meta"] = { ["inventory"] = {  }, ["fields"] = {  } }, ["param2"] = 0, ["param1"] = 0 }, { ["y"] = 3, ["x"] = 5, ["name"] = "columnia:column_bottom_rusty_block", ["z"] = 14, ["meta"] = { ["inventory"] = {  }, ["fields"] = {  } }, ["param2"] = 0, ["param1"] = 205 }, { ["y"] = 3, ["x"] = 5, ["name"] = "homedecor:torch_wall", ["z"] = 16, ["meta"] = { ["inventory"] = {  }, ["fields"] = {  } }, ["param2"] = 3, ["param1"] = 15 }, { ["y"] = 4, ["x"] = 5, ["name"] = "building_blocks:hardwood", ["z"] = 1, ["meta"] = { ["inventory"] = {  }, ["fields"] = {  } }, ["param2"] = 0, ["param1"] = 0 }, { ["y"] = 4, ["x"] = 5, ["name"] = "signs:sign_wall_green", ["z"] = 2, ["meta"] = { ["inventory"] = {  }, ["fields"] = { ["infotext"] = "Mod Inbox :\
Permet d'avoir une messagerie personnelle\
/mail <name> <msg> => envoyer un message (connecter ou deconnecter)\r/inbox => ouvrir votre messagerie\r/inbox clear => nettoyer votre messagerie\
/ignore <name> => ignorer un joueur\r/unignore <name> => ne plus ignorer un joueur ", ["text"] = "Mod Inbox :\
Permet d'avoir une messagerie personnelle\
/mail <name> <msg> => envoyer un message (connecter ou deconnecter)\r/inbox => ouvrir votre messagerie\r/inbox clear => nettoyer votre messagerie\
/ignore <name> => ignorer un joueur\r/unignore <name> => ne plus ignorer un joueur", ["formspec"] = "size[6,4]textarea[0,0;6.5,3;text;;${text}]button_exit[2,3;2,1;ok;Write]background[-0.5,-0.5;7,5;bg_signs_lib.jpg]", ["__signslib_new_format"] = "1" } }, ["param2"] = 2, ["param1"] = 191 }, { ["y"] = 4, ["x"] = 5, ["name"] = "signs:sign_wall_yellow", ["z"] = 8, ["meta"] = { ["inventory"] = {  }, ["fields"] = { ["infotext"] = "Il te faut le droit \"interact\" pour sortir de cette salle.\
Si tu ne l'as toujours pas, c'est que tu n'as pas lu les panneaux/regles du serveur, tu sais ce qu'il te reste a faire ! ", ["text"] = "Il te faut le droit \"interact\" pour sortir de cette salle. \
Si tu ne l'as toujours pas, c'est que tu n'as pas lu les panneaux/regles du serveur, tu sais ce qu'il te reste a faire !", ["formspec"] = "size[6,4]textarea[0,-0.3;6.5,3;text;;${text}]button_exit[2,3.4;2,1;ok;Write]background[-0.5,-0.5;7,5;bg_signs_lib.jpg]", ["__signslib_new_format"] = "1" } }, ["param2"] = 0, ["param1"] = 223 }, { ["y"] = 4, ["x"] = 5, ["name"] = "framedglass:steel_framed_obsidian_glassviolet", ["z"] = 9, ["meta"] = { ["inventory"] = {  }, ["fields"] = {  } }, ["param2"] = 0, ["param1"] = 207 }, { ["y"] = 4, ["x"] = 5, ["name"] = "columnia:column_top_rusty_block", ["z"] = 14, ["meta"] = { ["inventory"] = {  }, ["fields"] = {  } }, ["param2"] = 3, ["param1"] = 189 }, { ["y"] = 5, ["x"] = 5, ["name"] = "darkage:glass", ["z"] = 1, ["meta"] = { ["inventory"] = {  }, ["fields"] = {  } }, ["param2"] = 0, ["param1"] = 223 }, { ["y"] = 5, ["x"] = 5, ["name"] = "signs:sign_wall_green", ["z"] = 2, ["meta"] = { ["inventory"] = {  }, ["fields"] = { ["infotext"] = "Mod News :\
A chaque connexion \
une fenetre s'ouvrira pour\
vous informer des nouveautes\
(tapez /news pour la re-ouvrir) ", ["text"] = "Mod News :\
A chaque connexion \
une fenetre s'ouvrira pour\
vous informer des nouveautes\
(tapez /news pour la re-ouvrir)", ["formspec"] = "size[6,4]textarea[0,0;6.5,3;text;;${text}]button_exit[2,3;2,1;ok;Write]background[-0.5,-0.5;7,5;bg_signs_lib.jpg]", ["__signslib_new_format"] = "1" } }, ["param2"] = 2, ["param1"] = 207 }, { ["y"] = 5, ["x"] = 5, ["name"] = "framedglass:steel_framed_obsidian_glasspink", ["z"] = 9, ["meta"] = { ["inventory"] = {  }, ["fields"] = {  } }, ["param2"] = 0, ["param1"] = 191 }, { ["y"] = 5, ["x"] = 5, ["name"] = "columnia:rusty_block", ["z"] = 10, ["meta"] = { ["inventory"] = {  }, ["fields"] = {  } }, ["param2"] = 0, ["param1"] = 0 }, { ["y"] = 5, ["x"] = 5, ["name"] = "columnia:rusty_block", ["z"] = 11, ["meta"] = { ["inventory"] = {  }, ["fields"] = {  } }, ["param2"] = 0, ["param1"] = 0 }, { ["y"] = 5, ["x"] = 5, ["name"] = "columnia:rusty_block", ["z"] = 12, ["meta"] = { ["inventory"] = {  }, ["fields"] = {  } }, ["param2"] = 0, ["param1"] = 0 }, { ["y"] = 5, ["x"] = 5, ["name"] = "columnia:rusty_block", ["z"] = 13, ["meta"] = { ["inventory"] = {  }, ["fields"] = {  } }, ["param2"] = 0, ["param1"] = 0 }, { ["y"] = 5, ["x"] = 5, ["name"] = "columnia:rusty_block", ["z"] = 14, ["meta"] = { ["inventory"] = {  }, ["fields"] = {  } }, ["param2"] = 0, ["param1"] = 0 }, { ["y"] = 6, ["x"] = 5, ["name"] = "building_blocks:smoothglass", ["z"] = 1, ["meta"] = { ["inventory"] = {  }, ["fields"] = {  } }, ["param2"] = 0, ["param1"] = 207 }, { ["y"] = 6, ["x"] = 5, ["name"] = "building_blocks:smoothglass", ["z"] = 8, ["meta"] = { ["inventory"] = {  }, ["fields"] = {  } }, ["param2"] = 0, ["param1"] = 191 }, { ["y"] = 6, ["x"] = 5, ["name"] = "framedglass:steel_framed_obsidian_glass", ["z"] = 9, ["meta"] = { ["inventory"] = {  }, ["fields"] = {  } }, ["param2"] = 0, ["param1"] = 175 }, { ["y"] = 6, ["x"] = 5, ["name"] = "columnia:rusty_block", ["z"] = 10, ["meta"] = { ["inventory"] = {  }, ["fields"] = {  } }, ["param2"] = 0, ["param1"] = 0 }, { ["y"] = 6, ["x"] = 5, ["name"] = "columnia:rusty_block", ["z"] = 11, ["meta"] = { ["inventory"] = {  }, ["fields"] = {  } }, ["param2"] = 0, ["param1"] = 0 }, { ["y"] = 7, ["x"] = 5, ["name"] = "building_blocks:smoothglass", ["z"] = 2, ["meta"] = { ["inventory"] = {  }, ["fields"] = {  } }, ["param2"] = 0, ["param1"] = 175 }, { ["y"] = 7, ["x"] = 5, ["name"] = "building_blocks:smoothglass", ["z"] = 5, ["meta"] = { ["inventory"] = {  }, ["fields"] = {  } }, ["param2"] = 0, ["param1"] = 207 }, { ["y"] = 7, ["x"] = 5, ["name"] = "building_blocks:smoothglass", ["z"] = 6, ["meta"] = { ["inventory"] = {  }, ["fields"] = {  } }, ["param2"] = 0, ["param1"] = 191 }, { ["y"] = 7, ["x"] = 5, ["name"] = "building_blocks:smoothglass", ["z"] = 7, ["meta"] = { ["inventory"] = {  }, ["fields"] = {  } }, ["param2"] = 0, ["param1"] = 175 }, { ["y"] = 8, ["x"] = 5, ["name"] = "building_blocks:smoothglass", ["z"] = 3, ["meta"] = { ["inventory"] = {  }, ["fields"] = {  } }, ["param2"] = 0, ["param1"] = 159 }, { ["y"] = 8, ["x"] = 5, ["name"] = "building_blocks:smoothglass", ["z"] = 4, ["meta"] = { ["inventory"] = {  }, ["fields"] = {  } }, ["param2"] = 0, ["param1"] = 175 }, { ["y"] = 0, ["x"] = 6, ["name"] = "default:sand", ["z"] = 0, ["meta"] = { ["inventory"] = {  }, ["fields"] = {  } }, ["param2"] = 0, ["param1"] = 0 }, { ["y"] = 0, ["x"] = 6, ["name"] = "default:water_flowing", ["z"] = 1, ["meta"] = { ["inventory"] = {  }, ["fields"] = {  } }, ["param2"] = 7, ["param1"] = 123 }, { ["y"] = 0, ["x"] = 6, ["name"] = "default:sand", ["z"] = 2, ["meta"] = { ["inventory"] = {  }, ["fields"] = {  } }, ["param2"] = 0, ["param1"] = 0 }, { ["y"] = 0, ["x"] = 6, ["name"] = "default:stone", ["z"] = 3, ["meta"] = { ["inventory"] = {  }, ["fields"] = {  } }, ["param2"] = 0, ["param1"] = 0 }, { ["y"] = 0, ["x"] = 6, ["name"] = "default:stone", ["z"] = 4, ["meta"] = { ["inventory"] = {  }, ["fields"] = {  } }, ["param2"] = 0, ["param1"] = 0 }, { ["y"] = 0, ["x"] = 6, ["name"] = "default:stone", ["z"] = 5, ["meta"] = { ["inventory"] = {  }, ["fields"] = {  } }, ["param2"] = 0, ["param1"] = 0 }, { ["y"] = 0, ["x"] = 6, ["name"] = "default:stone", ["z"] = 6, ["meta"] = { ["inventory"] = {  }, ["fields"] = {  } }, ["param2"] = 0, ["param1"] = 0 }, { ["y"] = 0, ["x"] = 6, ["name"] = "default:stone", ["z"] = 7, ["meta"] = { ["inventory"] = {  }, ["fields"] = {  } }, ["param2"] = 0, ["param1"] = 0 }, { ["y"] = 0, ["x"] = 6, ["name"] = "default:stone", ["z"] = 8, ["meta"] = { ["inventory"] = {  }, ["fields"] = {  } }, ["param2"] = 0, ["param1"] = 0 }, { ["y"] = 0, ["x"] = 6, ["name"] = "default:stone", ["z"] = 9, ["meta"] = { ["inventory"] = {  }, ["fields"] = {  } }, ["param2"] = 0, ["param1"] = 0 }, { ["y"] = 0, ["x"] = 6, ["name"] = "default:stone", ["z"] = 10, ["meta"] = { ["inventory"] = {  }, ["fields"] = {  } }, ["param2"] = 0, ["param1"] = 0 }, { ["y"] = 0, ["x"] = 6, ["name"] = "default:stone", ["z"] = 11, ["meta"] = { ["inventory"] = {  }, ["fields"] = {  } }, ["param2"] = 0, ["param1"] = 0 }, { ["y"] = 0, ["x"] = 6, ["name"] = "default:stone", ["z"] = 12, ["meta"] = { ["inventory"] = {  }, ["fields"] = {  } }, ["param2"] = 0, ["param1"] = 0 }, { ["y"] = 0, ["x"] = 6, ["name"] = "default:stone", ["z"] = 13, ["meta"] = { ["inventory"] = {  }, ["fields"] = {  } }, ["param2"] = 0, ["param1"] = 0 }, { ["y"] = 0, ["x"] = 6, ["name"] = "default:stone", ["z"] = 14, ["meta"] = { ["inventory"] = {  }, ["fields"] = {  } }, ["param2"] = 0, ["param1"] = 0 }, { ["y"] = 0, ["x"] = 6, ["name"] = "default:stone", ["z"] = 15, ["meta"] = { ["inventory"] = {  }, ["fields"] = {  } }, ["param2"] = 0, ["param1"] = 0 }, { ["y"] = 0, ["x"] = 6, ["name"] = "default:stone", ["z"] = 16, ["meta"] = { ["inventory"] = {  }, ["fields"] = {  } }, ["param2"] = 0, ["param1"] = 0 }, { ["y"] = 1, ["x"] = 6, ["name"] = "default:water_source", ["z"] = 0, ["meta"] = { ["inventory"] = {  }, ["fields"] = {  } }, ["param2"] = 240, ["param1"] = 155 }, { ["y"] = 1, ["x"] = 6, ["name"] = "default:water_flowing", ["z"] = 1, ["meta"] = { ["inventory"] = {  }, ["fields"] = {  } }, ["param2"] = 15, ["param1"] = 140 }, { ["y"] = 1, ["x"] = 6, ["name"] = "default:diamondblock", ["z"] = 2, ["meta"] = { ["inventory"] = {  }, ["fields"] = {  } }, ["param2"] = 0, ["param1"] = 0 }, { ["y"] = 1, ["x"] = 6, ["name"] = "default:diamondblock", ["z"] = 3, ["meta"] = { ["inventory"] = {  }, ["fields"] = {  } }, ["param2"] = 0, ["param1"] = 0 }, { ["y"] = 1, ["x"] = 6, ["name"] = "default:wood", ["z"] = 4, ["meta"] = { ["inventory"] = {  }, ["fields"] = {  } }, ["param2"] = 0, ["param1"] = 0 }, { ["y"] = 1, ["x"] = 6, ["name"] = "default:sand", ["z"] = 5, ["meta"] = { ["inventory"] = {  }, ["fields"] = {  } }, ["param2"] = 0, ["param1"] = 0 }, { ["y"] = 1, ["x"] = 6, ["name"] = "default:sand", ["z"] = 6, ["meta"] = { ["inventory"] = {  }, ["fields"] = {  } }, ["param2"] = 0, ["param1"] = 0 }, { ["y"] = 1, ["x"] = 6, ["name"] = "default:sand", ["z"] = 7, ["meta"] = { ["inventory"] = {  }, ["fields"] = {  } }, ["param2"] = 0, ["param1"] = 0 }, { ["y"] = 1, ["x"] = 6, ["name"] = "default:sand", ["z"] = 8, ["meta"] = { ["inventory"] = {  }, ["fields"] = {  } }, ["param2"] = 0, ["param1"] = 0 }, { ["y"] = 1, ["x"] = 6, ["name"] = "default:sand", ["z"] = 9, ["meta"] = { ["inventory"] = {  }, ["fields"] = {  } }, ["param2"] = 0, ["param1"] = 0 }, { ["y"] = 1, ["x"] = 6, ["name"] = "default:sand", ["z"] = 10, ["meta"] = { ["inventory"] = {  }, ["fields"] = {  } }, ["param2"] = 0, ["param1"] = 0 }, { ["y"] = 1, ["x"] = 6, ["name"] = "default:sand", ["z"] = 11, ["meta"] = { ["inventory"] = {  }, ["fields"] = {  } }, ["param2"] = 0, ["param1"] = 0 }, { ["y"] = 1, ["x"] = 6, ["name"] = "default:sand", ["z"] = 12, ["meta"] = { ["inventory"] = {  }, ["fields"] = {  } }, ["param2"] = 0, ["param1"] = 0 }, { ["y"] = 1, ["x"] = 6, ["name"] = "default:sand", ["z"] = 13, ["meta"] = { ["inventory"] = {  }, ["fields"] = {  } }, ["param2"] = 0, ["param1"] = 0 }, { ["y"] = 1, ["x"] = 6, ["name"] = "default:sand", ["z"] = 14, ["meta"] = { ["inventory"] = {  }, ["fields"] = {  } }, ["param2"] = 0, ["param1"] = 0 }, { ["y"] = 1, ["x"] = 6, ["name"] = "default:sand", ["z"] = 15, ["meta"] = { ["inventory"] = {  }, ["fields"] = {  } }, ["param2"] = 0, ["param1"] = 0 }, { ["y"] = 1, ["x"] = 6, ["name"] = "default:sand", ["z"] = 16, ["meta"] = { ["inventory"] = {  }, ["fields"] = {  } }, ["param2"] = 0, ["param1"] = 0 }, { ["y"] = 2, ["x"] = 6, ["name"] = "default:water_source", ["z"] = 0, ["meta"] = { ["inventory"] = {  }, ["fields"] = {  } }, ["param2"] = 240, ["param1"] = 172 }, { ["y"] = 2, ["x"] = 6, ["name"] = "framedglass:steel_framed_obsidian_glass", ["z"] = 1, ["meta"] = { ["inventory"] = {  }, ["fields"] = {  } }, ["param2"] = 0, ["param1"] = 157 }, { ["y"] = 2, ["x"] = 6, ["name"] = "moreblocks:stair_wood", ["z"] = 4, ["meta"] = { ["inventory"] = {  }, ["fields"] = {  } }, ["param2"] = 10, ["param1"] = 175 }, { ["y"] = 2, ["x"] = 6, ["name"] = "default:wood", ["z"] = 5, ["meta"] = { ["inventory"] = {  }, ["fields"] = {  } }, ["param2"] = 0, ["param1"] = 0 }, { ["y"] = 2, ["x"] = 6, ["name"] = "default:stonebrick", ["z"] = 6, ["meta"] = { ["inventory"] = {  }, ["fields"] = {  } }, ["param2"] = 0, ["param1"] = 0 }, { ["y"] = 2, ["x"] = 6, ["name"] = "default:sand", ["z"] = 7, ["meta"] = { ["inventory"] = {  }, ["fields"] = {  } }, ["param2"] = 0, ["param1"] = 0 }, { ["y"] = 2, ["x"] = 6, ["name"] = "default:sand", ["z"] = 8, ["meta"] = { ["inventory"] = {  }, ["fields"] = {  } }, ["param2"] = 0, ["param1"] = 0 }, { ["y"] = 2, ["x"] = 6, ["name"] = "default:sand", ["z"] = 9, ["meta"] = { ["inventory"] = {  }, ["fields"] = {  } }, ["param2"] = 0, ["param1"] = 0 }, { ["y"] = 2, ["x"] = 6, ["name"] = "default:sand", ["z"] = 10, ["meta"] = { ["inventory"] = {  }, ["fields"] = {  } }, ["param2"] = 0, ["param1"] = 0 }, { ["y"] = 2, ["x"] = 6, ["name"] = "default:sand", ["z"] = 11, ["meta"] = { ["inventory"] = {  }, ["fields"] = {  } }, ["param2"] = 0, ["param1"] = 0 }, { ["y"] = 2, ["x"] = 6, ["name"] = "default:sand", ["z"] = 12, ["meta"] = { ["inventory"] = {  }, ["fields"] = {  } }, ["param2"] = 0, ["param1"] = 0 }, { ["y"] = 2, ["x"] = 6, ["name"] = "default:sand", ["z"] = 13, ["meta"] = { ["inventory"] = {  }, ["fields"] = {  } }, ["param2"] = 0, ["param1"] = 0 }, { ["y"] = 2, ["x"] = 6, ["name"] = "default:sand", ["z"] = 14, ["meta"] = { ["inventory"] = {  }, ["fields"] = {  } }, ["param2"] = 0, ["param1"] = 0 }, { ["y"] = 2, ["x"] = 6, ["name"] = "default:sand", ["z"] = 15, ["meta"] = { ["inventory"] = {  }, ["fields"] = {  } }, ["param2"] = 0, ["param1"] = 0 }, { ["y"] = 2, ["x"] = 6, ["name"] = "default:sand", ["z"] = 16, ["meta"] = { ["inventory"] = {  }, ["fields"] = {  } }, ["param2"] = 0, ["param1"] = 0 }, { ["y"] = 3, ["x"] = 6, ["name"] = "flowers:waterlily_225", ["z"] = 0, ["meta"] = { ["inventory"] = {  }, ["fields"] = {  } }, ["param2"] = 2, ["param1"] = 188 }, { ["y"] = 3, ["x"] = 6, ["name"] = "framedglass:steel_framed_obsidian_glass", ["z"] = 1, ["meta"] = { ["inventory"] = {  }, ["fields"] = {  } }, ["param2"] = 0, ["param1"] = 173 }, { ["y"] = 3, ["x"] = 6, ["name"] = "signs:sign_wall_green", ["z"] = 2, ["meta"] = { ["inventory"] = {  }, ["fields"] = { ["infotext"] = "Mod Craft_guide :\
En bas a gauche de votre inventaire ce trouve un bouton nomme \"craft guide\", utile si vous ne connaissez pas encore par coeur la fabrication d'un objet ! ", ["text"] = "Mod Craft_guide :\
En bas a gauche de votre inventaire ce trouve un bouton nomme \"craft guide\", utile si vous ne connaissez pas encore par coeur la fabrication d'un objet !", ["formspec"] = "size[6,4]textarea[0,-0.3;6.5,3;text;;${text}]button_exit[2,3.4;2,1;ok;Write]background[-0.5,-0.5;7,5;bg_signs_lib.jpg]", ["__signslib_new_format"] = "1" } }, ["param2"] = 1, ["param1"] = 191 }, { ["y"] = 3, ["x"] = 6, ["name"] = "signs:sign_wall_green", ["z"] = 3, ["meta"] = { ["inventory"] = {  }, ["fields"] = { ["infotext"] = "Mod Sprint :\
Ce mod permet de sprinter, pour ce faire, appuyez deux fois rapidement sur votre touche \"avancer\" (Z par defaut en clavier AZERTY) ", ["text"] = "Mod Sprint :\
Ce mod permet de sprinter, pour ce faire, appuyez deux fois rapidement sur votre touche \"avancer\" (Z par defaut en clavier AZERTY)", ["formspec"] = "size[6,4]textarea[0,-0.3;6.5,3;text;;${text}]button_exit[2,3.4;2,1;ok;Write]background[-0.5,-0.5;7,5;bg_signs_lib.jpg]", ["__signslib_new_format"] = "1" } }, ["param2"] = 1, ["param1"] = 175 }, { ["y"] = 3, ["x"] = 6, ["name"] = "framedglass:steel_framed_obsidian_glass", ["z"] = 9, ["meta"] = { ["inventory"] = {  }, ["fields"] = {  } }, ["param2"] = 0, ["param1"] = 207 }, { ["y"] = 3, ["x"] = 6, ["name"] = "columnia:column_bottom_rusty_block", ["z"] = 10, ["meta"] = { ["inventory"] = {  }, ["fields"] = {  } }, ["param2"] = 2, ["param1"] = 189 }, { ["y"] = 4, ["x"] = 6, ["name"] = "building_blocks:hardwood", ["z"] = 1, ["meta"] = { ["inventory"] = {  }, ["fields"] = {  } }, ["param2"] = 0, ["param1"] = 0 }, { ["y"] = 4, ["x"] = 6, ["name"] = "signs:sign_wall_green", ["z"] = 2, ["meta"] = { ["inventory"] = {  }, ["fields"] = { ["infotext"] = "Mod Awards :\
Permet d'accomplir des objectifs divers et varies\
/awards => pour aller au panneau des objectifs accomplies et restants/secrets ", ["text"] = "Mod Awards :\
Permet d'accomplir des objectifs divers et varies\
/awards => pour aller au panneau des objectifs accomplies et restants/secrets", ["formspec"] = "size[6,4]textarea[0,0;6.5,3;text;;${text}]button_exit[2,3;2,1;ok;Write]background[-0.5,-0.5;7,5;bg_signs_lib.jpg]", ["__signslib_new_format"] = "1" } }, ["param2"] = 2, ["param1"] = 207 }, { ["y"] = 4, ["x"] = 6, ["name"] = "signs:sign_wall_green", ["z"] = 3, ["meta"] = { ["inventory"] = {  }, ["fields"] = { ["infotext"] = "Mod chest :\
Poser deux coffres normaux l'un a cote de l'autre les feront ce fusionner en un grand ayant la capacite des deux coffres initiaux ", ["text"] = "Mod chest :\
Poser deux coffres normaux l'un a cote de l'autre les feront ce fusionner en un grand ayant la capacite des deux coffres initiaux", ["formspec"] = "size[6,4]textarea[0,-0.3;6.5,3;text;;${text}]button_exit[2,3.4;2,1;ok;Write]background[-0.5,-0.5;7,5;bg_signs_lib.jpg]", ["__signslib_new_format"] = "1" } }, ["param2"] = 1, ["param1"] = 191 }, { ["y"] = 4, ["x"] = 6, ["name"] = "default:sign_wall", ["z"] = 4, ["meta"] = { ["inventory"] = {  }, ["fields"] = { ["infotext"] = "  \
Aucune forme de triche n'est \
autorise. (hack, client modifie, \
etc...) ", ["text"] = "  \
Aucune forme de triche n'est \
autorise. (hack, client modifie, \
etc...)", ["formspec"] = "size[6,4]textarea[0,0;6.5,3;text;;${text}]button_exit[2,3;2,1;ok;Write]background[-0.5,-0.5;7,5;bg_signs_lib.jpg]", ["__signslib_new_format"] = "1" } }, ["param2"] = 1, ["param1"] = 207 }, { ["y"] = 4, ["x"] = 6, ["name"] = "default:sign_wall", ["z"] = 5, ["meta"] = { ["inventory"] = {  }, ["fields"] = { ["infotext"] = "Chaque joueur a l'entiere responsabilite de son compte, nous ne sommes en aucun cas responsable d'une utilisation frauduleuse de votre compte dans le jeu. ", ["text"] = "Chaque joueur a l'entiere responsabilite de son compte, nous ne sommes en aucun cas responsable d'une utilisation frauduleuse de votre compte dans le jeu.", ["formspec"] = "size[6,4]textarea[0,0;6.5,3;text;;${text}]button_exit[2,3;2,1;ok;Write]background[-0.5,-0.5;7,5;bg_signs_lib.jpg]", ["__signslib_new_format"] = "1" } }, ["param2"] = 1, ["param1"] = 207 }, { ["y"] = 4, ["x"] = 6, ["name"] = "default:sign_wall", ["z"] = 6, ["meta"] = { ["inventory"] = {  }, ["fields"] = { ["infotext"] = "Sur le serveur,\
le PVP est autorise, le\
vole/grief est aussi autorise.\
(pensez au mod areas pour \
proteger vos biens) ", ["text"] = "Sur le serveur,\
le PVP est autorise, le\
vole/grief est aussi autorise.\
(pensez au mod areas pour \
proteger vos biens)\
", ["formspec"] = "size[6,4]textarea[0,0;6.5,3;text;;${text}]button_exit[2,3;2,1;ok;Write]background[-0.5,-0.5;7,5;bg_signs_lib.jpg]", ["__signslib_new_format"] = "1" } }, ["param2"] = 1, ["param1"] = 205 }, { ["y"] = 4, ["x"] = 6, ["name"] = "homedecor:torch_wall", ["z"] = 8, ["meta"] = { ["inventory"] = {  }, ["fields"] = {  } }, ["param2"] = 0, ["param1"] = 15 }, { ["y"] = 4, ["x"] = 6, ["name"] = "framedglass:steel_framed_obsidian_glass", ["z"] = 9, ["meta"] = { ["inventory"] = {  }, ["fields"] = {  } }, ["param2"] = 0, ["param1"] = 223 }, { ["y"] = 4, ["x"] = 6, ["name"] = "columnia:column_top_rusty_block", ["z"] = 10, ["meta"] = { ["inventory"] = {  }, ["fields"] = {  } }, ["param2"] = 2, ["param1"] = 205 }, { ["y"] = 5, ["x"] = 6, ["name"] = "moreblocks:super_glow_glass", ["z"] = 1, ["meta"] = { ["inventory"] = {  }, ["fields"] = {  } }, ["param2"] = 0, ["param1"] = 0 }, { ["y"] = 5, ["x"] = 6, ["name"] = "signs:sign_wall_green", ["z"] = 2, ["meta"] = { ["inventory"] = {  }, ["fields"] = { ["infotext"] = "Mod Player_notes :\
Tapez /notes pour creer,\
supprimer et modifier vos notes\
personelles ", ["text"] = "Mod Player_notes :\
Tapez /notes pour creer,\
supprimer et modifier vos notes\
personelles", ["formspec"] = "size[6,4]textarea[0,0;6.5,3;text;;${text}]button_exit[2,3;2,1;ok;Write]background[-0.5,-0.5;7,5;bg_signs_lib.jpg]", ["__signslib_new_format"] = "1" } }, ["param2"] = 2, ["param1"] = 223 }, { ["y"] = 5, ["x"] = 6, ["name"] = "signs:sign_hanging", ["z"] = 6, ["meta"] = { ["inventory"] = {  }, ["fields"] = { ["infotext"] = "   \
     \
Ne demandez pas a etre \
membre de l'equipe du serveur. ", ["text"] = "   \
     \
Ne demandez pas a etre \
