return { { ["y"] = 33, ["x"] = 1, ["name"] = "framedglass:steel_framed_obsidian_glass", ["z"] = 1, ["meta"] = { ["inventory"] = {  }, ["fields"] = {  } }, ["param2"] = 0, ["param1"] = 127 }, { ["y"] = 33, ["x"] = 1, ["name"] = "framedglass:steel_framed_obsidian_glass", ["z"] = 2, ["meta"] = { ["inventory"] = {  }, ["fields"] = {  } }, ["param2"] = 0, ["param1"] = 111 }, { ["y"] = 33, ["x"] = 1, ["name"] = "framedglass:steel_framed_obsidian_glass", ["z"] = 3, ["meta"] = { ["inventory"] = {  }, ["fields"] = {  } }, ["param2"] = 0, ["param1"] = 95 }, { ["y"] = 33, ["x"] = 1, ["name"] = "framedglass:steel_framed_obsidian_glass", ["z"] = 4, ["meta"] = { ["inventory"] = {  }, ["fields"] = {  } }, ["param2"] = 0, ["param1"] = 111 }, { ["y"] = 33, ["x"] = 1, ["name"] = "framedglass:steel_framed_obsidian_glass", ["z"] = 5, ["meta"] = { ["inventory"] = {  }, ["fields"] = {  } }, ["param2"] = 0, ["param1"] = 127 }, { ["y"] = 33, ["x"] = 1, ["name"] = "framedglass:steel_framed_obsidian_glass", ["z"] = 6, ["meta"] = { ["inventory"] = {  }, ["fields"] = {  } }, ["param2"] = 0, ["param1"] = 143 }, { ["y"] = 33, ["x"] = 1, ["name"] = "framedglass:steel_framed_obsidian_glass", ["z"] = 7, ["meta"] = { ["inventory"] = {  }, ["fields"] = {  } }, ["param2"] = 0, ["param1"] = 127 }, { ["y"] = 33, ["x"] = 1, ["name"] = "framedglass:steel_framed_obsidian_glass", ["z"] = 8, ["meta"] = { ["inventory"] = {  }, ["fields"] = {  } }, ["param2"] = 0, ["param1"] = 143 }, { ["y"] = 33, ["x"] = 1, ["name"] = "framedglass:steel_framed_obsidian_glass", ["z"] = 9, ["meta"] = { ["inventory"] = {  }, ["fields"] = {  } }, ["param2"] = 0, ["param1"] = 127 }, { ["y"] = 33, ["x"] = 1, ["name"] = "framedglass:steel_framed_obsidian_glass", ["z"] = 10, ["meta"] = { ["inventory"] = {  }, ["fields"] = {  } }, ["param2"] = 0, ["param1"] = 143 }, { ["y"] = 33, ["x"] = 1, ["name"] = "framedglass:steel_framed_obsidian_glass", ["z"] = 11, ["meta"] = { ["inventory"] = {  }, ["fields"] = {  } }, ["param2"] = 0, ["param1"] = 127 }, { ["y"] = 33, ["x"] = 1, ["name"] = "framedglass:steel_framed_obsidian_glass", ["z"] = 12, ["meta"] = { ["inventory"] = {  }, ["fields"] = {  } }, ["param2"] = 0, ["param1"] = 143 }, { ["y"] = 33, ["x"] = 1, ["name"] = "framedglass:steel_framed_obsidian_glass", ["z"] = 13, ["meta"] = { ["inventory"] = {  }, ["fields"] = {  } }, ["param2"] = 0, ["param1"] = 127 }, { ["y"] = 33, ["x"] = 1, ["name"] = "framedglass:steel_framed_obsidian_glass", ["z"] = 14, ["meta"] = { ["inventory"] = {  }, ["fields"] = {  } }, ["param2"] = 0, ["param1"] = 111 }, { ["y"] = 33, ["x"] = 1, ["name"] = "framedglass:steel_framed_obsidian_glass", ["z"] = 15, ["meta"] = { ["inventory"] = {  }, ["fields"] = {  } }, ["param2"] = 0, ["param1"] = 95 }, { ["y"] = 33, ["x"] = 1, ["name"] = "framedglass:steel_framed_obsidian_glass", ["z"] = 16, ["meta"] = { ["inventory"] = {  }, ["fields"] = {  } }, ["param2"] = 0, ["param1"] = 79 }, { ["y"] = 33, ["x"] = 1, ["name"] = "framedglass:steel_framed_obsidian_glass", ["z"] = 17, ["meta"] = { ["inventory"] = {  }, ["fields"] = {  } }, ["param2"] = 0, ["param1"] = 79 }, { ["y"] = 33, ["x"] = 1, ["name"] = "framedglass:steel_framed_obsidian_glass", ["z"] = 18, ["meta"] = { ["inventory"] = {  }, ["fields"] = {  } }, ["param2"] = 0, ["param1"] = 95 }, { ["y"] = 33, ["x"] = 1, ["name"] = "framedglass:steel_framed_obsidian_glass", ["z"] = 19, ["meta"] = { ["inventory"] = {  }, ["fields"] = {  } }, ["param2"] = 0, ["param1"] = 111 }, { ["y"] = 33, ["x"] = 1, ["name"] = "framedglass:steel_framed_obsidian_glass", ["z"] = 20, ["meta"] = { ["inventory"] = {  }, ["fields"] = {  } }, ["param2"] = 0, ["param1"] = 95 }, { ["y"] = 33, ["x"] = 1, ["name"] = "framedglass:steel_framed_obsidian_glass", ["z"] = 21, ["meta"] = { ["inventory"] = {  }, ["fields"] = {  } }, ["param2"] = 0, ["param1"] = 79 }, { ["y"] = 33, ["x"] = 1, ["name"] = "framedglass:steel_framed_obsidian_glass", ["z"] = 22, ["meta"] = { ["inventory"] = {  }, ["fields"] = {  } }, ["param2"] = 0, ["param1"] = 63 }, { ["y"] = 34, ["x"] = 1, ["name"] = "framedglass:steel_framed_obsidian_glass", ["z"] = 1, ["meta"] = { ["inventory"] = {  }, ["fields"] = {  } }, ["param2"] = 0, ["param1"] = 143 }, { ["y"] = 34, ["x"] = 1, ["name"] = "framedglass:steel_framed_obsidian_glass", ["z"] = 2, ["meta"] = { ["inventory"] = {  }, ["fields"] = {  } }, ["param2"] = 0, ["param1"] = 127 }, { ["y"] = 34, ["x"] = 1, ["name"] = "framedglass:steel_framed_obsidian_glass", ["z"] = 3, ["meta"] = { ["inventory"] = {  }, ["fields"] = {  } }, ["param2"] = 0, ["param1"] = 111 }, { ["y"] = 34, ["x"] = 1, ["name"] = "framedglass:steel_framed_obsidian_glass", ["z"] = 4, ["meta"] = { ["inventory"] = {  }, ["fields"] = {  } }, ["param2"] = 0, ["param1"] = 127 }, { ["y"] = 34, ["x"] = 1, ["name"] = "framedglass:steel_framed_obsidian_glass", ["z"] = 5, ["meta"] = { ["inventory"] = {  }, ["fields"] = {  } }, ["param2"] = 0, ["param1"] = 143 }, { ["y"] = 34, ["x"] = 1, ["name"] = "framedglass:steel_framed_obsidian_glass", ["z"] = 6, ["meta"] = { ["inventory"] = {  }, ["fields"] = {  } }, ["param2"] = 0, ["param1"] = 159 }, { ["y"] = 34, ["x"] = 1, ["name"] = "framedglass:steel_framed_obsidian_glass", ["z"] = 7, ["meta"] = { ["inventory"] = {  }, ["fields"] = {  } }, ["param2"] = 0, ["param1"] = 143 }, { ["y"] = 34, ["x"] = 1, ["name"] = "framedglass:steel_framed_obsidian_glass", ["z"] = 8, ["meta"] = { ["inventory"] = {  }, ["fields"] = {  } }, ["param2"] = 0, ["param1"] = 159 }, { ["y"] = 34, ["x"] = 1, ["name"] = "framedglass:steel_framed_obsidian_glass", ["z"] = 9, ["meta"] = { ["inventory"] = {  }, ["fields"] = {  } }, ["param2"] = 0, ["param1"] = 143 }, { ["y"] = 34, ["x"] = 1, ["name"] = "framedglass:steel_framed_obsidian_glass", ["z"] = 10, ["meta"] = { ["inventory"] = {  }, ["fields"] = {  } }, ["param2"] = 0, ["param1"] = 159 }, { ["y"] = 34, ["x"] = 1, ["name"] = "framedglass:steel_framed_obsidian_glass", ["z"] = 11, ["meta"] = { ["inventory"] = {  }, ["fields"] = {  } }, ["param2"] = 0, ["param1"] = 143 }, { ["y"] = 34, ["x"] = 1, ["name"] = "framedglass:steel_framed_obsidian_glass", ["z"] = 12, ["meta"] = { ["inventory"] = {  }, ["fields"] = {  } }, ["param2"] = 0, ["param1"] = 159 }, { ["y"] = 34, ["x"] = 1, ["name"] = "framedglass:steel_framed_obsidian_glass", ["z"] = 13, ["meta"] = { ["inventory"] = {  }, ["fields"] = {  } }, ["param2"] = 0, ["param1"] = 143 }, { ["y"] = 34, ["x"] = 1, ["name"] = "framedglass:steel_framed_obsidian_glass", ["z"] = 14, ["meta"] = { ["inventory"] = {  }, ["fields"] = {  } }, ["param2"] = 0, ["param1"] = 127 }, { ["y"] = 34, ["x"] = 1, ["name"] = "framedglass:steel_framed_obsidian_glass", ["z"] = 15, ["meta"] = { ["inventory"] = {  }, ["fields"] = {  } }, ["param2"] = 0, ["param1"] = 111 }, { ["y"] = 34, ["x"] = 1, ["name"] = "framedglass:steel_framed_obsidian_glass", ["z"] = 16, ["meta"] = { ["inventory"] = {  }, ["fields"] = {  } }, ["param2"] = 0, ["param1"] = 95 }, { ["y"] = 34, ["x"] = 1, ["name"] = "framedglass:steel_framed_obsidian_glass", ["z"] = 17, ["meta"] = { ["inventory"] = {  }, ["fields"] = {  } }, ["param2"] = 0, ["param1"] = 95 }, { ["y"] = 34, ["x"] = 1, ["name"] = "framedglass:steel_framed_obsidian_glass", ["z"] = 18, ["meta"] = { ["inventory"] = {  }, ["fields"] = {  } }, ["param2"] = 0, ["param1"] = 111 }, { ["y"] = 34, ["x"] = 1, ["name"] = "framedglass:steel_framed_obsidian_glass", ["z"] = 19, ["meta"] = { ["inventory"] = {  }, ["fields"] = {  } }, ["param2"] = 0, ["param1"] = 127 }, { ["y"] = 34, ["x"] = 1, ["name"] = "framedglass:steel_framed_obsidian_glass", ["z"] = 20, ["meta"] = { ["inventory"] = {  }, ["fields"] = {  } }, ["param2"] = 0, ["param1"] = 111 }, { ["y"] = 34, ["x"] = 1, ["name"] = "framedglass:steel_framed_obsidian_glass", ["z"] = 21, ["meta"] = { ["inventory"] = {  }, ["fields"] = {  } }, ["param2"] = 0, ["param1"] = 95 }, { ["y"] = 34, ["x"] = 1, ["name"] = "framedglass:steel_framed_obsidian_glass", ["z"] = 22, ["meta"] = { ["inventory"] = {  }, ["fields"] = {  } }, ["param2"] = 0, ["param1"] = 79 }, { ["y"] = 35, ["x"] = 1, ["name"] = "framedglass:steel_framed_obsidian_glass", ["z"] = 1, ["meta"] = { ["inventory"] = {  }, ["fields"] = {  } }, ["param2"] = 0, ["param1"] = 159 }, { ["y"] = 35, ["x"] = 1, ["name"] = "framedglass:steel_framed_obsidian_glass", ["z"] = 2, ["meta"] = { ["inventory"] = {  }, ["fields"] = {  } }, ["param2"] = 0, ["param1"] = 143 }, { ["y"] = 35, ["x"] = 1, ["name"] = "framedglass:steel_framed_obsidian_glass", ["z"] = 3, ["meta"] = { ["inventory"] = {  }, ["fields"] = {  } }, ["param2"] = 0, ["param1"] = 127 }, { ["y"] = 35, ["x"] = 1, ["name"] = "framedglass:steel_framed_obsidian_glass", ["z"] = 4, ["meta"] = { ["inventory"] = {  }, ["fields"] = {  } }, ["param2"] = 0, ["param1"] = 143 }, { ["y"] = 35, ["x"] = 1, ["name"] = "framedglass:steel_framed_obsidian_glass", ["z"] = 5, ["meta"] = { ["inventory"] = {  }, ["fields"] = {  } }, ["param2"] = 0, ["param1"] = 159 }, { ["y"] = 35, ["x"] = 1, ["name"] = "framedglass:steel_framed_obsidian_glass", ["z"] = 6, ["meta"] = { ["inventory"] = {  }, ["fields"] = {  } }, ["param2"] = 0, ["param1"] = 175 }, { ["y"] = 35, ["x"] = 1, ["name"] = "framedglass:steel_framed_obsidian_glass", ["z"] = 7, ["meta"] = { ["inventory"] = {  }, ["fields"] = {  } }, ["param2"] = 0, ["param1"] = 159 }, { ["y"] = 35, ["x"] = 1, ["name"] = "framedglass:steel_framed_obsidian_glass", ["z"] = 8, ["meta"] = { ["inventory"] = {  }, ["fields"] = {  } }, ["param2"] = 0, ["param1"] = 175 }, { ["y"] = 35, ["x"] = 1, ["name"] = "framedglass:steel_framed_obsidian_glass", ["z"] = 9, ["meta"] = { ["inventory"] = {  }, ["fields"] = {  } }, ["param2"] = 0, ["param1"] = 159 }, { ["y"] = 35, ["x"] = 1, ["name"] = "framedglass:steel_framed_obsidian_glass", ["z"] = 10, ["meta"] = { ["inventory"] = {  }, ["fields"] = {  } }, ["param2"] = 0, ["param1"] = 175 }, { ["y"] = 35, ["x"] = 1, ["name"] = "framedglass:steel_framed_obsidian_glass", ["z"] = 11, ["meta"] = { ["inventory"] = {  }, ["fields"] = {  } }, ["param2"] = 0, ["param1"] = 159 }, { ["y"] = 35, ["x"] = 1, ["name"] = "framedglass:steel_framed_obsidian_glass", ["z"] = 12, ["meta"] = { ["inventory"] = {  }, ["fields"] = {  } }, ["param2"] = 0, ["param1"] = 175 }, { ["y"] = 35, ["x"] = 1, ["name"] = "framedglass:steel_framed_obsidian_glass", ["z"] = 13, ["meta"] = { ["inventory"] = {  }, ["fields"] = {  } }, ["param2"] = 0, ["param1"] = 159 }, { ["y"] = 35, ["x"] = 1, ["name"] = "framedglass:steel_framed_obsidian_glass", ["z"] = 14, ["meta"] = { ["inventory"] = {  }, ["fields"] = {  } }, ["param2"] = 0, ["param1"] = 143 }, { ["y"] = 35, ["x"] = 1, ["name"] = "framedglass:steel_framed_obsidian_glass", ["z"] = 15, ["meta"] = { ["inventory"] = {  }, ["fields"] = {  } }, ["param2"] = 0, ["param1"] = 127 }, { ["y"] = 35, ["x"] = 1, ["name"] = "framedglass:steel_framed_obsidian_glass", ["z"] = 16, ["meta"] = { ["inventory"] = {  }, ["fields"] = {  } }, ["param2"] = 0, ["param1"] = 111 }, { ["y"] = 35, ["x"] = 1, ["name"] = "framedglass:steel_framed_obsidian_glass", ["z"] = 17, ["meta"] = { ["inventory"] = {  }, ["fields"] = {  } }, ["param2"] = 0, ["param1"] = 111 }, { ["y"] = 35, ["x"] = 1, ["name"] = "framedglass:steel_framed_obsidian_glass", ["z"] = 18, ["meta"] = { ["inventory"] = {  }, ["fields"] = {  } }, ["param2"] = 0, ["param1"] = 127 }, { ["y"] = 35, ["x"] = 1, ["name"] = "framedglass:steel_framed_obsidian_glass", ["z"] = 19, ["meta"] = { ["inventory"] = {  }, ["fields"] = {  } }, ["param2"] = 0, ["param1"] = 143 }, { ["y"] = 35, ["x"] = 1, ["name"] = "framedglass:steel_framed_obsidian_glass", ["z"] = 20, ["meta"] = { ["inventory"] = {  }, ["fields"] = {  } }, ["param2"] = 0, ["param1"] = 127 }, { ["y"] = 35, ["x"] = 1, ["name"] = "framedglass:steel_framed_obsidian_glass", ["z"] = 21, ["meta"] = { ["inventory"] = {  }, ["fields"] = {  } }, ["param2"] = 0, ["param1"] = 111 }, { ["y"] = 35, ["x"] = 1, ["name"] = "framedglass:steel_framed_obsidian_glass", ["z"] = 22, ["meta"] = { ["inventory"] = {  }, ["fields"] = {  } }, ["param2"] = 0, ["param1"] = 95 }, { ["y"] = 36, ["x"] = 1, ["name"] = "framedglass:steel_framed_obsidian_glass", ["z"] = 1, ["meta"] = { ["inventory"] = {  }, ["fields"] = {  } }, ["param2"] = 0, ["param1"] = 175 }, { ["y"] = 36, ["x"] = 1, ["name"] = "framedglass:steel_framed_obsidian_glass", ["z"] = 2, ["meta"] = { ["inventory"] = {  }, ["fields"] = {  } }, ["param2"] = 0, ["param1"] = 159 }, { ["y"] = 36, ["x"] = 1, ["name"] = "framedglass:steel_framed_obsidian_glass", ["z"] = 3, ["meta"] = { ["inventory"] = {  }, ["fields"] = {  } }, ["param2"] = 0, ["param1"] = 143 }, { ["y"] = 36, ["x"] = 1, ["name"] = "framedglass:steel_framed_obsidian_glass", ["z"] = 4, ["meta"] = { ["inventory"] = {  }, ["fields"] = {  } }, ["param2"] = 0, ["param1"] = 159 }, { ["y"] = 36, ["x"] = 1, ["name"] = "framedglass:steel_framed_obsidian_glass", ["z"] = 5, ["meta"] = { ["inventory"] = {  }, ["fields"] = {  } }, ["param2"] = 0, ["param1"] = 175 }, { ["y"] = 36, ["x"] = 1, ["name"] = "framedglass:steel_framed_obsidian_glass", ["z"] = 6, ["meta"] = { ["inventory"] = {  }, ["fields"] = {  } }, ["param2"] = 0, ["param1"] = 191 }, { ["y"] = 36, ["x"] = 1, ["name"] = "framedglass:steel_framed_obsidian_glass", ["z"] = 7, ["meta"] = { ["inventory"] = {  }, ["fields"] = {  } }, ["param2"] = 0, ["param1"] = 175 }, { ["y"] = 36, ["x"] = 1, ["name"] = "framedglass:steel_framed_obsidian_glass", ["z"] = 8, ["meta"] = { ["inventory"] = {  }, ["fields"] = {  } }, ["param2"] = 0, ["param1"] = 191 }, { ["y"] = 36, ["x"] = 1, ["name"] = "framedglass:steel_framed_obsidian_glass", ["z"] = 9, ["meta"] = { ["inventory"] = {  }, ["fields"] = {  } }, ["param2"] = 0, ["param1"] = 175 }, { ["y"] = 36, ["x"] = 1, ["name"] = "framedglass:steel_framed_obsidian_glass", ["z"] = 10, ["meta"] = { ["inventory"] = {  }, ["fields"] = {  } }, ["param2"] = 0, ["param1"] = 191 }, { ["y"] = 36, ["x"] = 1, ["name"] = "framedglass:steel_framed_obsidian_glass", ["z"] = 11, ["meta"] = { ["inventory"] = {  }, ["fields"] = {  } }, ["param2"] = 0, ["param1"] = 175 }, { ["y"] = 36, ["x"] = 1, ["name"] = "framedglass:steel_framed_obsidian_glass", ["z"] = 12, ["meta"] = { ["inventory"] = {  }, ["fields"] = {  } }, ["param2"] = 0, ["param1"] = 159 }, { ["y"] = 36, ["x"] = 1, ["name"] = "framedglass:steel_framed_obsidian_glass", ["z"] = 13, ["meta"] = { ["inventory"] = {  }, ["fields"] = {  } }, ["param2"] = 0, ["param1"] = 143 }, { ["y"] = 36, ["x"] = 1, ["name"] = "framedglass:steel_framed_obsidian_glass", ["z"] = 14, ["meta"] = { ["inventory"] = {  }, ["fields"] = {  } }, ["param2"] = 0, ["param1"] = 127 }, { ["y"] = 36, ["x"] = 1, ["name"] = "framedglass:steel_framed_obsidian_glass", ["z"] = 15, ["meta"] = { ["inventory"] = {  }, ["fields"] = {  } }, ["param2"] = 0, ["param1"] = 143 }, { ["y"] = 36, ["x"] = 1, ["name"] = "framedglass:steel_framed_obsidian_glass", ["z"] = 16, ["meta"] = { ["inventory"] = {  }, ["fields"] = {  } }, ["param2"] = 0, ["param1"] = 127 }, { ["y"] = 36, ["x"] = 1, ["name"] = "framedglass:steel_framed_obsidian_glass", ["z"] = 17, ["meta"] = { ["inventory"] = {  }, ["fields"] = {  } }, ["param2"] = 0, ["param1"] = 127 }, { ["y"] = 36, ["x"] = 1, ["name"] = "framedglass:steel_framed_obsidian_glass", ["z"] = 18, ["meta"] = { ["inventory"] = {  }, ["fields"] = {  } }, ["param2"] = 0, ["param1"] = 143 }, { ["y"] = 36, ["x"] = 1, ["name"] = "framedglass:steel_framed_obsidian_glass", ["z"] = 19, ["meta"] = { ["inventory"] = {  }, ["fields"] = {  } }, ["param2"] = 0, ["param1"] = 159 }, { ["y"] = 36, ["x"] = 1, ["name"] = "framedglass:steel_framed_obsidian_glass", ["z"] = 20, ["meta"] = { ["inventory"] = {  }, ["fields"] = {  } }, ["param2"] = 0, ["param1"] = 143 }, { ["y"] = 36, ["x"] = 1, ["name"] = "framedglass:steel_framed_obsidian_glass", ["z"] = 21, ["meta"] = { ["inventory"] = {  }, ["fields"] = {  } }, ["param2"] = 0, ["param1"] = 127 }, { ["y"] = 36, ["x"] = 1, ["name"] = "framedglass:steel_framed_obsidian_glass", ["z"] = 22, ["meta"] = { ["inventory"] = {  }, ["fields"] = {  } }, ["param2"] = 0, ["param1"] = 111 }, { ["y"] = 37, ["x"] = 1, ["name"] = "framedglass:steel_framed_obsidian_glass", ["z"] = 1, ["meta"] = { ["inventory"] = {  }, ["fields"] = {  } }, ["param2"] = 0, ["param1"] = 159 }, { ["y"] = 37, ["x"] = 1, ["name"] = "framedglass:steel_framed_obsidian_glass", ["z"] = 2, ["meta"] = { ["inventory"] = {  }, ["fields"] = {  } }, ["param2"] = 0, ["param1"] = 143 }, { ["y"] = 37, ["x"] = 1, ["name"] = "framedglass:steel_framed_obsidian_glass", ["z"] = 3, ["meta"] = { ["inventory"] = {  }, ["fields"] = {  } }, ["param2"] = 0, ["param1"] = 127 }, { ["y"] = 37, ["x"] = 1, ["name"] = "framedglass:steel_framed_obsidian_glass", ["z"] = 4, ["meta"] = { ["inventory"] = {  }, ["fields"] = {  } }, ["param2"] = 0, ["param1"] = 143 }, { ["y"] = 37, ["x"] = 1, ["name"] = "framedglass:steel_framed_obsidian_glass", ["z"] = 5, ["meta"] = { ["inventory"] = {  }, ["fields"] = {  } }, ["param2"] = 0, ["param1"] = 159 }, { ["y"] = 37, ["x"] = 1, ["name"] = "framedglass:steel_framed_obsidian_glass", ["z"] = 6, ["meta"] = { ["inventory"] = {  }, ["fields"] = {  } }, ["param2"] = 0, ["param1"] = 175 }, { ["y"] = 37, ["x"] = 1, ["name"] = "framedglass:steel_framed_obsidian_glass", ["z"] = 7, ["meta"] = { ["inventory"] = {  }, ["fields"] = {  } }, ["param2"] = 0, ["param1"] = 159 }, { ["y"] = 37, ["x"] = 1, ["name"] = "framedglass:steel_framed_obsidian_glass", ["z"] = 8, ["meta"] = { ["inventory"] = {  }, ["fields"] = {  } }, ["param2"] = 0, ["param1"] = 175 }, { ["y"] = 37, ["x"] = 1, ["name"] = "framedglass:steel_framed_obsidian_glass", ["z"] = 9, ["meta"] = { ["inventory"] = {  }, ["fields"] = {  } }, ["param2"] = 0, ["param1"] = 159 }, { ["y"] = 37, ["x"] = 1, ["name"] = "framedglass:steel_framed_obsidian_glass", ["z"] = 10, ["meta"] = { ["inventory"] = {  }, ["fields"] = {  } }, ["param2"] = 0, ["param1"] = 175 }, { ["y"] = 37, ["x"] = 1, ["name"] = "framedglass:steel_framed_obsidian_glass", ["z"] = 11, ["meta"] = { ["inventory"] = {  }, ["fields"] = {  } }, ["param2"] = 0, ["param1"] = 159 }, { ["y"] = 37, ["x"] = 1, ["name"] = "framedglass:steel_framed_obsidian_glass", ["z"] = 12, ["meta"] = { ["inventory"] = {  }, ["fields"] = {  } }, ["param2"] = 0, ["param1"] = 143 }, { ["y"] = 37, ["x"] = 1, ["name"] = "framedglass:steel_framed_obsidian_glass", ["z"] = 13, ["meta"] = { ["inventory"] = {  }, ["fields"] = {  } }, ["param2"] = 0, ["param1"] = 127 }, { ["y"] = 37, ["x"] = 1, ["name"] = "framedglass:steel_framed_obsidian_glass", ["z"] = 14, ["meta"] = { ["inventory"] = {  }, ["fields"] = {  } }, ["param2"] = 0, ["param1"] = 143 }, { ["y"] = 37, ["x"] = 1, ["name"] = "framedglass:steel_framed_obsidian_glass", ["z"] = 15, ["meta"] = { ["inventory"] = {  }, ["fields"] = {  } }, ["param2"] = 0, ["param1"] = 159 }, { ["y"] = 37, ["x"] = 1, ["name"] = "framedglass:steel_framed_obsidian_glass", ["z"] = 16, ["meta"] = { ["inventory"] = {  }, ["fields"] = {  } }, ["param2"] = 0, ["param1"] = 143 }, { ["y"] = 37, ["x"] = 1, ["name"] = "framedglass:steel_framed_obsidian_glass", ["z"] = 17, ["meta"] = { ["inventory"] = {  }, ["fields"] = {  } }, ["param2"] = 0, ["param1"] = 127 }, { ["y"] = 37, ["x"] = 1, ["name"] = "framedglass:steel_framed_obsidian_glass", ["z"] = 18, ["meta"] = { ["inventory"] = {  }, ["fields"] = {  } }, ["param2"] = 0, ["param1"] = 127 }, { ["y"] = 37, ["x"] = 1, ["name"] = "framedglass:steel_framed_obsidian_glass", ["z"] = 19, ["meta"] = { ["inventory"] = {  }, ["fields"] = {  } }, ["param2"] = 0, ["param1"] = 143 }, { ["y"] = 37, ["x"] = 1, ["name"] = "framedglass:steel_framed_obsidian_glass", ["z"] = 20, ["meta"] = { ["inventory"] = {  }, ["fields"] = {  } }, ["param2"] = 0, ["param1"] = 127 }, { ["y"] = 37, ["x"] = 1, ["name"] = "framedglass:steel_framed_obsidian_glass", ["z"] = 21, ["meta"] = { ["inventory"] = {  }, ["fields"] = {  } }, ["param2"] = 0, ["param1"] = 111 }, { ["y"] = 37, ["x"] = 1, ["name"] = "framedglass:steel_framed_obsidian_glass", ["z"] = 22, ["meta"] = { ["inventory"] = {  }, ["fields"] = {  } }, ["param2"] = 0, ["param1"] = 95 }, { ["y"] = 38, ["x"] = 1, ["name"] = "framedglass:steel_framed_obsidian_glass", ["z"] = 1, ["meta"] = { ["inventory"] = {  }, ["fields"] = {  } }, ["param2"] = 0, ["param1"] = 143 }, { ["y"] = 38, ["x"] = 1, ["name"] = "framedglass:steel_framed_obsidian_glass", ["z"] = 2, ["meta"] = { ["inventory"] = {  }, ["fields"] = {  } }, ["param2"] = 0, ["param1"] = 127 }, { ["y"] = 38, ["x"] = 1, ["name"] = "framedglass:steel_framed_obsidian_glass", ["z"] = 3, ["meta"] = { ["inventory"] = {  }, ["fields"] = {  } }, ["param2"] = 0, ["param1"] = 111 }, { ["y"] = 38, ["x"] = 1, ["name"] = "framedglass:steel_framed_obsidian_glass", ["z"] = 4, ["meta"] = { ["inventory"] = {  }, ["fields"] = {  } }, ["param2"] = 0, ["param1"] = 127 }, { ["y"] = 38, ["x"] = 1, ["name"] = "framedglass:steel_framed_obsidian_glass", ["z"] = 5, ["meta"] = { ["inventory"] = {  }, ["fields"] = {  } }, ["param2"] = 0, ["param1"] = 143 }, { ["y"] = 38, ["x"] = 1, ["name"] = "framedglass:steel_framed_obsidian_glass", ["z"] = 6, ["meta"] = { ["inventory"] = {  }, ["fields"] = {  } }, ["param2"] = 0, ["param1"] = 159 }, { ["y"] = 38, ["x"] = 1, ["name"] = "framedglass:steel_framed_obsidian_glass", ["z"] = 7, ["meta"] = { ["inventory"] = {  }, ["fields"] = {  } }, ["param2"] = 0, ["param1"] = 143 }, { ["y"] = 38, ["x"] = 1, ["name"] = "framedglass:steel_framed_obsidian_glass", ["z"] = 8, ["meta"] = { ["inventory"] = {  }, ["fields"] = {  } }, ["param2"] = 0, ["param1"] = 159 }, { ["y"] = 38, ["x"] = 1, ["name"] = "framedglass:steel_framed_obsidian_glass", ["z"] = 9, ["meta"] = { ["inventory"] = {  }, ["fields"] = {  } }, ["param2"] = 0, ["param1"] = 159 }, { ["y"] = 38, ["x"] = 1, ["name"] = "framedglass:steel_framed_obsidian_glass", ["z"] = 10, ["meta"] = { ["inventory"] = {  }, ["fields"] = {  } }, ["param2"] = 0, ["param1"] = 159 }, { ["y"] = 38, ["x"] = 1, ["name"] = "framedglass:steel_framed_obsidian_glass", ["z"] = 11, ["meta"] = { ["inventory"] = {  }, ["fields"] = {  } }, ["param2"] = 0, ["param1"] = 143 }, { ["y"] = 38, ["x"] = 1, ["name"] = "framedglass:steel_framed_obsidian_glass", ["z"] = 12, ["meta"] = { ["inventory"] = {  }, ["fields"] = {  } }, ["param2"] = 0, ["param1"] = 127 }, { ["y"] = 38, ["x"] = 1, ["name"] = "framedglass:steel_framed_obsidian_glass", ["z"] = 13, ["meta"] = { ["inventory"] = {  }, ["fields"] = {  } }, ["param2"] = 0, ["param1"] = 111 }, { ["y"] = 38, ["x"] = 1, ["name"] = "framedglass:steel_framed_obsidian_glass", ["z"] = 14, ["meta"] = { ["inventory"] = {  }, ["fields"] = {  } }, ["param2"] = 0, ["param1"] = 127 }, { ["y"] = 38, ["x"] = 1, ["name"] = "framedglass:steel_framed_obsidian_glass", ["z"] = 15, ["meta"] = { ["inventory"] = {  }, ["fields"] = {  } }, ["param2"] = 0, ["param1"] = 143 }, { ["y"] = 38, ["x"] = 1, ["name"] = "framedglass:steel_framed_obsidian_glass", ["z"] = 16, ["meta"] = { ["inventory"] = {  }, ["fields"] = {  } }, ["param2"] = 0, ["param1"] = 127 }, { ["y"] = 38, ["x"] = 1, ["name"] = "framedglass:steel_framed_obsidian_glass", ["z"] = 17, ["meta"] = { ["inventory"] = {  }, ["fields"] = {  } }, ["param2"] = 0, ["param1"] = 111 }, { ["y"] = 38, ["x"] = 1, ["name"] = "framedglass:steel_framed_obsidian_glass", ["z"] = 18, ["meta"] = { ["inventory"] = {  }, ["fields"] = {  } }, ["param2"] = 0, ["param1"] = 111 }, { ["y"] = 38, ["x"] = 1, ["name"] = "framedglass:steel_framed_obsidian_glass", ["z"] = 19, ["meta"] = { ["inventory"] = {  }, ["fields"] = {  } }, ["param2"] = 0, ["param1"] = 127 }, { ["y"] = 38, ["x"] = 1, ["name"] = "framedglass:steel_framed_obsidian_glass", ["z"] = 20, ["meta"] = { ["inventory"] = {  }, ["fields"] = {  } }, ["param2"] = 0, ["param1"] = 111 }, { ["y"] = 38, ["x"] = 1, ["name"] = "framedglass:steel_framed_obsidian_glass", ["z"] = 21, ["meta"] = { ["inventory"] = {  }, ["fields"] = {  } }, ["param2"] = 0, ["param1"] = 95 }, { ["y"] = 38, ["x"] = 1, ["name"] = "framedglass:steel_framed_obsidian_glass", ["z"] = 22, ["meta"] = { ["inventory"] = {  }, ["fields"] = {  } }, ["param2"] = 0, ["param1"] = 79 }, { ["y"] = 39, ["x"] = 1, ["name"] = "framedglass:steel_framed_obsidian_glass", ["z"] = 1, ["meta"] = { ["inventory"] = {  }, ["fields"] = {  } }, ["param2"] = 0, ["param1"] = 127 }, { ["y"] = 39, ["x"] = 1, ["name"] = "framedglass:steel_framed_obsidian_glass", ["z"] = 2, ["meta"] = { ["inventory"] = {  }, ["fields"] = {  } }, ["param2"] = 0, ["param1"] = 111 }, { ["y"] = 39, ["x"] = 1, ["name"] = "framedglass:steel_framed_obsidian_glass", ["z"] = 3, ["meta"] = { ["inventory"] = {  }, ["fields"] = {  } }, ["param2"] = 0, ["param1"] = 95 }, { ["y"] = 39, ["x"] = 1, ["name"] = "framedglass:steel_framed_obsidian_glass", ["z"] = 4, ["meta"] = { ["inventory"] = {  }, ["fields"] = {  } }, ["param2"] = 0, ["param1"] = 111 }, { ["y"] = 39, ["x"] = 1, ["name"] = "framedglass:steel_framed_obsidian_glass", ["z"] = 5, ["meta"] = { ["inventory"] = {  }, ["fields"] = {  } }, ["param2"] = 0, ["param1"] = 127 }, { ["y"] = 39, ["x"] = 1, ["name"] = "framedglass:steel_framed_obsidian_glass", ["z"] = 6, ["meta"] = { ["inventory"] = {  }, ["fields"] = {  } }, ["param2"] = 0, ["param1"] = 143 }, { ["y"] = 39, ["x"] = 1, ["name"] = "framedglass:steel_framed_obsidian_glass", ["z"] = 7, ["meta"] = { ["inventory"] = {  }, ["fields"] = {  } }, ["param2"] = 0, ["param1"] = 127 }, { ["y"] = 39, ["x"] = 1, ["name"] = "framedglass:steel_framed_obsidian_glass", ["z"] = 8, ["meta"] = { ["inventory"] = {  }, ["fields"] = {  } }, ["param2"] = 0, ["param1"] = 143 }, { ["y"] = 39, ["x"] = 1, ["name"] = "framedglass:steel_framed_obsidian_glass", ["z"] = 9, ["meta"] = { ["inventory"] = {  }, ["fields"] = {  } }, ["param2"] = 0, ["param1"] = 143 }, { ["y"] = 39, ["x"] = 1, ["name"] = "framedglass:steel_framed_obsidian_glass", ["z"] = 10, ["meta"] = { ["inventory"] = {  }, ["fields"] = {  } }, ["param2"] = 0, ["param1"] = 143 }, { ["y"] = 39, ["x"] = 1, ["name"] = "framedglass:steel_framed_obsidian_glass", ["z"] = 11, ["meta"] = { ["inventory"] = {  }, ["fields"] = {  } }, ["param2"] = 0, ["param1"] = 127 }, { ["y"] = 39, ["x"] = 1, ["name"] = "framedglass:steel_framed_obsidian_glass", ["z"] = 12, ["meta"] = { ["inventory"] = {  }, ["fields"] = {  } }, ["param2"] = 0, ["param1"] = 111 }, { ["y"] = 39, ["x"] = 1, ["name"] = "framedglass:steel_framed_obsidian_glass", ["z"] = 13, ["meta"] = { ["inventory"] = {  }, ["fields"] = {  } }, ["param2"] = 0, ["param1"] = 95 }, { ["y"] = 39, ["x"] = 1, ["name"] = "framedglass:steel_framed_obsidian_glass", ["z"] = 14, ["meta"] = { ["inventory"] = {  }, ["fields"] = {  } }, ["param2"] = 0, ["param1"] = 111 }, { ["y"] = 39, ["x"] = 1, ["name"] = "framedglass:steel_framed_obsidian_glass", ["z"] = 15, ["meta"] = { ["inventory"] = {  }, ["fields"] = {  } }, ["param2"] = 0, ["param1"] = 127 }, { ["y"] = 39, ["x"] = 1, ["name"] = "framedglass:steel_framed_obsidian_glass", ["z"] = 16, ["meta"] = { ["inventory"] = {  }, ["fields"] = {  } }, ["param2"] = 0, ["param1"] = 111 }, { ["y"] = 39, ["x"] = 1, ["name"] = "framedglass:steel_framed_obsidian_glass", ["z"] = 17, ["meta"] = { ["inventory"] = {  }, ["fields"] = {  } }, ["param2"] = 0, ["param1"] = 95 }, { ["y"] = 39, ["x"] = 1, ["name"] = "framedglass:steel_framed_obsidian_glass", ["z"] = 18, ["meta"] = { ["inventory"] = {  }, ["fields"] = {  } }, ["param2"] = 0, ["param1"] = 95 }, { ["y"] = 39, ["x"] = 1, ["name"] = "framedglass:steel_framed_obsidian_glass", ["z"] = 19, ["meta"] = { ["inventory"] = {  }, ["fields"] = {  } }, ["param2"] = 0, ["param1"] = 111 }, { ["y"] = 39, ["x"] = 1, ["name"] = "framedglass:steel_framed_obsidian_glass", ["z"] = 20, ["meta"] = { ["inventory"] = {  }, ["fields"] = {  } }, ["param2"] = 0, ["param1"] = 95 }, { ["y"] = 39, ["x"] = 1, ["name"] = "framedglass:steel_framed_obsidian_glass", ["z"] = 21, ["meta"] = { ["inventory"] = {  }, ["fields"] = {  } }, ["param2"] = 0, ["param1"] = 79 }, { ["y"] = 39, ["x"] = 1, ["name"] = "framedglass:steel_framed_obsidian_glass", ["z"] = 22, ["meta"] = { ["inventory"] = {  }, ["fields"] = {  } }, ["param2"] = 0, ["param1"] = 63 }, { ["y"] = 40, ["x"] = 1, ["name"] = "framedglass:steel_framed_obsidian_glass", ["z"] = 1, ["meta"] = { ["inventory"] = {  }, ["fields"] = {  } }, ["param2"] = 0, ["param1"] = 111 }, { ["y"] = 40, ["x"] = 1, ["name"] = "framedglass:steel_framed_obsidian_glass", ["z"] = 2, ["meta"] = { ["inventory"] = {  }, ["fields"] = {  } }, ["param2"] = 0, ["param1"] = 95 }, { ["y"] = 40, ["x"] = 1, ["name"] = "framedglass:steel_framed_obsidian_glass", ["z"] = 3, ["meta"] = { ["inventory"] = {  }, ["fields"] = {  } }, ["param2"] = 0, ["param1"] = 79 }, { ["y"] = 40, ["x"] = 1, ["name"] = "framedglass:steel_framed_obsidian_glass", ["z"] = 4, ["meta"] = { ["inventory"] = {  }, ["fields"] = {  } }, ["param2"] = 0, ["param1"] = 95 }, { ["y"] = 40, ["x"] = 1, ["name"] = "framedglass:steel_framed_obsidian_glass", ["z"] = 5, ["meta"] = { ["inventory"] = {  }, ["fields"] = {  } }, ["param2"] = 0, ["param1"] = 111 }, { ["y"] = 40, ["x"] = 1, ["name"] = "framedglass:steel_framed_obsidian_glass", ["z"] = 6, ["meta"] = { ["inventory"] = {  }, ["fields"] = {  } }, ["param2"] = 0, ["param1"] = 127 }, { ["y"] = 40, ["x"] = 1, ["name"] = "framedglass:steel_framed_obsidian_glass", ["z"] = 7, ["meta"] = { ["inventory"] = {  }, ["fields"] = {  } }, ["param2"] = 0, ["param1"] = 111 }, { ["y"] = 40, ["x"] = 1, ["name"] = "framedglass:steel_framed_obsidian_glass", ["z"] = 8, ["meta"] = { ["inventory"] = {  }, ["fields"] = {  } }, ["param2"] = 0, ["param1"] = 127 }, { ["y"] = 40, ["x"] = 1, ["name"] = "framedglass:steel_framed_obsidian_glass", ["z"] = 9, ["meta"] = { ["inventory"] = {  }, ["fields"] = {  } }, ["param2"] = 0, ["param1"] = 127 }, { ["y"] = 40, ["x"] = 1, ["name"] = "framedglass:steel_framed_obsidian_glass", ["z"] = 10, ["meta"] = { ["inventory"] = {  }, ["fields"] = {  } }, ["param2"] = 0, ["param1"] = 127 }, { ["y"] = 40, ["x"] = 1, ["name"] = "framedglass:steel_framed_obsidian_glass", ["z"] = 11, ["meta"] = { ["inventory"] = {  }, ["fields"] = {  } }, ["param2"] = 0, ["param1"] = 111 }, { ["y"] = 40, ["x"] = 1, ["name"] = "framedglass:steel_framed_obsidian_glass", ["z"] = 12, ["meta"] = { ["inventory"] = {  }, ["fields"] = {  } }, ["param2"] = 0, ["param1"] = 95 }, { ["y"] = 40, ["x"] = 1, ["name"] = "framedglass:steel_framed_obsidian_glass", ["z"] = 13, ["meta"] = { ["inventory"] = {  }, ["fields"] = {  } }, ["param2"] = 0, ["param1"] = 79 }, { ["y"] = 40, ["x"] = 1, ["name"] = "framedglass:steel_framed_obsidian_glass", ["z"] = 14, ["meta"] = { ["inventory"] = {  }, ["fields"] = {  } }, ["param2"] = 0, ["param1"] = 95 }, { ["y"] = 40, ["x"] = 1, ["name"] = "framedglass:steel_framed_obsidian_glass", ["z"] = 15, ["meta"] = { ["inventory"] = {  }, ["fields"] = {  } }, ["param2"] = 0, ["param1"] = 111 }, { ["y"] = 40, ["x"] = 1, ["name"] = "framedglass:steel_framed_obsidian_glass", ["z"] = 16, ["meta"] = { ["inventory"] = {  }, ["fields"] = {  } }, ["param2"] = 0, ["param1"] = 95 }, { ["y"] = 40, ["x"] = 1, ["name"] = "framedglass:steel_framed_obsidian_glass", ["z"] = 17, ["meta"] = { ["inventory"] = {  }, ["fields"] = {  } }, ["param2"] = 0, ["param1"] = 79 }, { ["y"] = 40, ["x"] = 1, ["name"] = "framedglass:steel_framed_obsidian_glass", ["z"] = 18, ["meta"] = { ["inventory"] = {  }, ["fields"] = {  } }, ["param2"] = 0, ["param1"] = 79 }, { ["y"] = 40, ["x"] = 1, ["name"] = "framedglass:steel_framed_obsidian_glass", ["z"] = 19, ["meta"] = { ["inventory"] = {  }, ["fields"] = {  } }, ["param2"] = 0, ["param1"] = 95 }, { ["y"] = 40, ["x"] = 1, ["name"] = "framedglass:steel_framed_obsidian_glass", ["z"] = 20, ["meta"] = { ["inventory"] = {  }, ["fields"] = {  } }, ["param2"] = 0, ["param1"] = 79 }, { ["y"] = 40, ["x"] = 1, ["name"] = "framedglass:steel_framed_obsidian_glass", ["z"] = 21, ["meta"] = { ["inventory"] = {  }, ["fields"] = {  } }, ["param2"] = 0, ["param1"] = 63 }, { ["y"] = 40, ["x"] = 1, ["name"] = "framedglass:steel_framed_obsidian_glass", ["z"] = 22, ["meta"] = { ["inventory"] = {  }, ["fields"] = {  } }, ["param2"] = 0, ["param1"] = 47 }, { ["y"] = 41, ["x"] = 1, ["name"] = "framedglass:steel_framed_obsidian_glass", ["z"] = 1, ["meta"] = { ["inventory"] = {  }, ["fields"] = {  } }, ["param2"] = 0, ["param1"] = 95 }, { ["y"] = 41, ["x"] = 1, ["name"] = "framedglass:steel_framed_obsidian_glass", ["z"] = 2, ["meta"] = { ["inventory"] = {  }, ["fields"] = {  } }, ["param2"] = 0, ["param1"] = 79 }, { ["y"] = 41, ["x"] = 1, ["name"] = "framedglass:steel_framed_obsidian_glass", ["z"] = 3, ["meta"] = { ["inventory"] = {  }, ["fields"] = {  } }, ["param2"] = 0, ["param1"] = 63 }, { ["y"] = 41, ["x"] = 1, ["name"] = "framedglass:steel_framed_obsidian_glass", ["z"] = 4, ["meta"] = { ["inventory"] = {  }, ["fields"] = {  } }, ["param2"] = 0, ["param1"] = 79 }, { ["y"] = 41, ["x"] = 1, ["name"] = "framedglass:steel_framed_obsidian_glass", ["z"] = 5, ["meta"] = { ["inventory"] = {  }, ["fields"] = {  } }, ["param2"] = 0, ["param1"] = 95 }, { ["y"] = 41, ["x"] = 1, ["name"] = "framedglass:steel_framed_obsidian_glass", ["z"] = 6, ["meta"] = { ["inventory"] = {  }, ["fields"] = {  } }, ["param2"] = 0, ["param1"] = 111 }, { ["y"] = 41, ["x"] = 1, ["name"] = "framedglass:steel_framed_obsidian_glass", ["z"] = 7, ["meta"] = { ["inventory"] = {  }, ["fields"] = {  } }, ["param2"] = 0, ["param1"] = 95 }, { ["y"] = 41, ["x"] = 1, ["name"] = "framedglass:steel_framed_obsidian_glass", ["z"] = 8, ["meta"] = { ["inventory"] = {  }, ["fields"] = {  } }, ["param2"] = 0, ["param1"] = 111 }, { ["y"] = 41, ["x"] = 1, ["name"] = "framedglass:steel_framed_obsidian_glass", ["z"] = 9, ["meta"] = { ["inventory"] = {  }, ["fields"] = {  } }, ["param2"] = 0, ["param1"] = 111 }, { ["y"] = 41, ["x"] = 1, ["name"] = "framedglass:steel_framed_obsidian_glass", ["z"] = 10, ["meta"] = { ["inventory"] = {  }, ["fields"] = {  } }, ["param2"] = 0, ["param1"] = 111 }, { ["y"] = 41, ["x"] = 1, ["name"] = "framedglass:steel_framed_obsidian_glass", ["z"] = 11, ["meta"] = { ["inventory"] = {  }, ["fields"] = {  } }, ["param2"] = 0, ["param1"] = 95 }, { ["y"] = 41, ["x"] = 1, ["name"] = "framedglass:steel_framed_obsidian_glass", ["z"] = 12, ["meta"] = { ["inventory"] = {  }, ["fields"] = {  } }, ["param2"] = 0, ["param1"] = 79 }, { ["y"] = 41, ["x"] = 1, ["name"] = "framedglass:steel_framed_obsidian_glass", ["z"] = 13, ["meta"] = { ["inventory"] = {  }, ["fields"] = {  } }, ["param2"] = 0, ["param1"] = 63 }, { ["y"] = 41, ["x"] = 1, ["name"] = "framedglass:steel_framed_obsidian_glass", ["z"] = 14, ["meta"] = { ["inventory"] = {  }, ["fields"] = {  } }, ["param2"] = 0, ["param1"] = 79 }, { ["y"] = 41, ["x"] = 1, ["name"] = "framedglass:steel_framed_obsidian_glass", ["z"] = 15, ["meta"] = { ["inventory"] = {  }, ["fields"] = {  } }, ["param2"] = 0, ["param1"] = 95 }, { ["y"] = 41, ["x"] = 1, ["name"] = "framedglass:steel_framed_obsidian_glass", ["z"] = 16, ["meta"] = { ["inventory"] = {  }, ["fields"] = {  } }, ["param2"] = 0, ["param1"] = 79 }, { ["y"] = 41, ["x"] = 1, ["name"] = "framedglass:steel_framed_obsidian_glass", ["z"] = 17, ["meta"] = { ["inventory"] = {  }, ["fields"] = {  } }, ["param2"] = 0, ["param1"] = 63 }, { ["y"] = 41, ["x"] = 1, ["name"] = "framedglass:steel_framed_obsidian_glass", ["z"] = 18, ["meta"] = { ["inventory"] = {  }, ["fields"] = {  } }, ["param2"] = 0, ["param1"] = 63 }, { ["y"] = 41, ["x"] = 1, ["name"] = "framedglass:steel_framed_obsidian_glass", ["z"] = 19, ["meta"] = { ["inventory"] = {  }, ["fields"] = {  } }, ["param2"] = 0, ["param1"] = 79 }, { ["y"] = 41, ["x"] = 1, ["name"] = "framedglass:steel_framed_obsidian_glass", ["z"] = 20, ["meta"] = { ["inventory"] = {  }, ["fields"] = {  } }, ["param2"] = 0, ["param1"] = 63 }, { ["y"] = 41, ["x"] = 1, ["name"] = "framedglass:steel_framed_obsidian_glass", ["z"] = 21, ["meta"] = { ["inventory"] = {  }, ["fields"] = {  } }, ["param2"] = 0, ["param1"] = 47 }, { ["y"] = 41, ["x"] = 1, ["name"] = "framedglass:steel_framed_obsidian_glass", ["z"] = 22, ["meta"] = { ["inventory"] = {  }, ["fields"] = {  } }, ["param2"] = 0, ["param1"] = 31 }, { ["y"] = 42, ["x"] = 1, ["name"] = "framedglass:steel_framed_obsidian_glass", ["z"] = 1, ["meta"] = { ["inventory"] = {  }, ["fields"] = {  } }, ["param2"] = 0, ["param1"] = 79 }, { ["y"] = 42, ["x"] = 1, ["name"] = "framedglass:steel_framed_obsidian_glass", ["z"] = 2, ["meta"] = { ["inventory"] = {  }, ["fields"] = {  } }, ["param2"] = 0, ["param1"] = 63 }, { ["y"] = 42, ["x"] = 1, ["name"] = "framedglass:steel_framed_obsidian_glass", ["z"] = 3, ["meta"] = { ["inventory"] = {  }, ["fields"] = {  } }, ["param2"] = 0, ["param1"] = 47 }, { ["y"] = 42, ["x"] = 1, ["name"] = "framedglass:steel_framed_obsidian_glass", ["z"] = 4, ["meta"] = { ["inventory"] = {  }, ["fields"] = {  } }, ["param2"] = 0, ["param1"] = 63 }, { ["y"] = 42, ["x"] = 1, ["name"] = "framedglass:steel_framed_obsidian_glass", ["z"] = 5, ["meta"] = { ["inventory"] = {  }, ["fields"] = {  } }, ["param2"] = 0, ["param1"] = 79 }, { ["y"] = 42, ["x"] = 1, ["name"] = "framedglass:steel_framed_obsidian_glass", ["z"] = 6, ["meta"] = { ["inventory"] = {  }, ["fields"] = {  } }, ["param2"] = 0, ["param1"] = 95 }, { ["y"] = 42, ["x"] = 1, ["name"] = "framedglass:steel_framed_obsidian_glass", ["z"] = 7, ["meta"] = { ["inventory"] = {  }, ["fields"] = {  } }, ["param2"] = 0, ["param1"] = 79 }, { ["y"] = 42, ["x"] = 1, ["name"] = "framedglass:steel_framed_obsidian_glass", ["z"] = 8, ["meta"] = { ["inventory"] = {  }, ["fields"] = {  } }, ["param2"] = 0, ["param1"] = 95 }, { ["y"] = 42, ["x"] = 1, ["name"] = "framedglass:steel_framed_obsidian_glass", ["z"] = 9, ["meta"] = { ["inventory"] = {  }, ["fields"] = {  } }, ["param2"] = 0, ["param1"] = 95 }, { ["y"] = 42, ["x"] = 1, ["name"] = "framedglass:steel_framed_obsidian_glass", ["z"] = 10, ["meta"] = { ["inventory"] = {  }, ["fields"] = {  } }, ["param2"] = 0, ["param1"] = 95 }, { ["y"] = 42, ["x"] = 1, ["name"] = "framedglass:steel_framed_obsidian_glass", ["z"] = 11, ["meta"] = { ["inventory"] = {  }, ["fields"] = {  } }, ["param2"] = 0, ["param1"] = 79 }, { ["y"] = 42, ["x"] = 1, ["name"] = "framedglass:steel_framed_obsidian_glass", ["z"] = 12, ["meta"] = { ["inventory"] = {  }, ["fields"] = {  } }, ["param2"] = 0, ["param1"] = 63 }, { ["y"] = 42, ["x"] = 1, ["name"] = "framedglass:steel_framed_obsidian_glass", ["z"] = 13, ["meta"] = { ["inventory"] = {  }, ["fields"] = {  } }, ["param2"] = 0, ["param1"] = 47 }, { ["y"] = 42, ["x"] = 1, ["name"] = "framedglass:steel_framed_obsidian_glass", ["z"] = 14, ["meta"] = { ["inventory"] = {  }, ["fields"] = {  } }, ["param2"] = 0, ["param1"] = 63 }, { ["y"] = 42, ["x"] = 1, ["name"] = "framedglass:steel_framed_obsidian_glass", ["z"] = 15, ["meta"] = { ["inventory"] = {  }, ["fields"] = {  } }, ["param2"] = 0, ["param1"] = 79 }, { ["y"] = 42, ["x"] = 1, ["name"] = "framedglass:steel_framed_obsidian_glass", ["z"] = 16, ["meta"] = { ["inventory"] = {  }, ["fields"] = {  } }, ["param2"] = 0, ["param1"] = 63 }, { ["y"] = 42, ["x"] = 1, ["name"] = "framedglass:steel_framed_obsidian_glass", ["z"] = 17, ["meta"] = { ["inventory"] = {  }, ["fields"] = {  } }, ["param2"] = 0, ["param1"] = 47 }, { ["y"] = 42, ["x"] = 1, ["name"] = "framedglass:steel_framed_obsidian_glass", ["z"] = 18, ["meta"] = { ["inventory"] = {  }, ["fields"] = {  } }, ["param2"] = 0, ["param1"] = 47 }, { ["y"] = 42, ["x"] = 1, ["name"] = "framedglass:steel_framed_obsidian_glass", ["z"] = 19, ["meta"] = { ["inventory"] = {  }, ["fields"] = {  } }, ["param2"] = 0, ["param1"] = 63 }, { ["y"] = 42, ["x"] = 1, ["name"] = "framedglass:steel_framed_obsidian_glass", ["z"] = 20, ["meta"] = { ["inventory"] = {  }, ["fields"] = {  } }, ["param2"] = 0, ["param1"] = 47 }, { ["y"] = 42, ["x"] = 1, ["name"] = "framedglass:steel_framed_obsidian_glass", ["z"] = 21, ["meta"] = { ["inventory"] = {  }, ["fields"] = {  } }, ["param2"] = 0, ["param1"] = 31 }, { ["y"] = 42, ["x"] = 1, ["name"] = "framedglass:steel_framed_obsidian_glass", ["z"] = 22, ["meta"] = { ["inventory"] = {  }, ["fields"] = {  } }, ["param2"] = 0, ["param1"] = 15 }, { ["y"] = 0, ["x"] = 2, ["name"] = "moreblocks:clean_glass", ["z"] = 5, ["meta"] = { ["inventory"] = {  }, ["fields"] = {  } }, ["param2"] = 0, ["param1"] = 13 }, { ["y"] = 0, ["x"] = 2, ["name"] = "moreblocks:clean_glass", ["z"] = 6, ["meta"] = { ["inventory"] = {  }, ["fields"] = {  } }, ["param2"] = 0, ["param1"] = 13 }, { ["y"] = 1, ["x"] = 2, ["name"] = "moreblocks:clean_glass", ["z"] = 5, ["meta"] = { ["inventory"] = {  }, ["fields"] = {  } }, ["param2"] = 0, ["param1"] = 13 }, { ["y"] = 1, ["x"] = 2, ["name"] = "moreblocks:clean_glass", ["z"] = 6, ["meta"] = { ["inventory"] = {  }, ["fields"] = {  } }, ["param2"] = 0, ["param1"] = 13 }, { ["y"] = 2, ["x"] = 2, ["name"] = "moreblocks:clean_glass", ["z"] = 5, ["meta"] = { ["inventory"] = {  }, ["fields"] = {  } }, ["param2"] = 0, ["param1"] = 13 }, { ["y"] = 2, ["x"] = 2, ["name"] = "moreblocks:clean_glass", ["z"] = 6, ["meta"] = { ["inventory"] = {  }, ["fields"] = {  } }, ["param2"] = 0, ["param1"] = 13 }, { ["y"] = 3, ["x"] = 2, ["name"] = "moreblocks:clean_glass", ["z"] = 5, ["meta"] = { ["inventory"] = {  }, ["fields"] = {  } }, ["param2"] = 0, ["param1"] = 13 }, { ["y"] = 3, ["x"] = 2, ["name"] = "moreblocks:clean_glass", ["z"] = 6, ["meta"] = { ["inventory"] = {  }, ["fields"] = {  } }, ["param2"] = 0, ["param1"] = 13 }, { ["y"] = 4, ["x"] = 2, ["name"] = "moreblocks:clean_glass", ["z"] = 5, ["meta"] = { ["inventory"] = {  }, ["fields"] = {  } }, ["param2"] = 0, ["param1"] = 13 }, { ["y"] = 4, ["x"] = 2, ["name"] = "moreblocks:clean_glass", ["z"] = 6, ["meta"] = { ["inventory"] = {  }, ["fields"] = {  } }, ["param2"] = 0, ["param1"] = 13 }, { ["y"] = 5, ["x"] = 2, ["name"] = "moreblocks:clean_glass", ["z"] = 5, ["meta"] = { ["inventory"] = {  }, ["fields"] = {  } }, ["param2"] = 0, ["param1"] = 13 }, { ["y"] = 5, ["x"] = 2, ["name"] = "moreblocks:clean_glass", ["z"] = 6, ["meta"] = { ["inventory"] = {  }, ["fields"] = {  } }, ["param2"] = 0, ["param1"] = 13 }, { ["y"] = 6, ["x"] = 2, ["name"] = "moreblocks:clean_glass", ["z"] = 5, ["meta"] = { ["inventory"] = {  }, ["fields"] = {  } }, ["param2"] = 0, ["param1"] = 13 }, { ["y"] = 6, ["x"] = 2, ["name"] = "moreblocks:clean_glass", ["z"] = 6, ["meta"] = { ["inventory"] = {  }, ["fields"] = {  } }, ["param2"] = 0, ["param1"] = 13 }, { ["y"] = 7, ["x"] = 2, ["name"] = "moreblocks:clean_glass", ["z"] = 5, ["meta"] = { ["inventory"] = {  }, ["fields"] = {  } }, ["param2"] = 0, ["param1"] = 13 }, { ["y"] = 7, ["x"] = 2, ["name"] = "moreblocks:clean_glass", ["z"] = 6, ["meta"] = { ["inventory"] = {  }, ["fields"] = {  } }, ["param2"] = 0, ["param1"] = 13 }, { ["y"] = 8, ["x"] = 2, ["name"] = "moreblocks:clean_glass", ["z"] = 5, ["meta"] = { ["inventory"] = {  }, ["fields"] = {  } }, ["param2"] = 0, ["param1"] = 13 }, { ["y"] = 8, ["x"] = 2, ["name"] = "moreblocks:clean_glass", ["z"] = 6, ["meta"] = { ["inventory"] = {  }, ["fields"] = {  } }, ["param2"] = 0, ["param1"] = 13 }, { ["y"] = 9, ["x"] = 2, ["name"] = "moreblocks:clean_glass", ["z"] = 5, ["meta"] = { ["inventory"] = {  }, ["fields"] = {  } }, ["param2"] = 0, ["param1"] = 13 }, { ["y"] = 9, ["x"] = 2, ["name"] = "moreblocks:clean_glass", ["z"] = 6, ["meta"] = { ["inventory"] = {  }, ["fields"] = {  } }, ["param2"] = 0, ["param1"] = 13 }, { ["y"] = 10, ["x"] = 2, ["name"] = "moreblocks:clean_glass", ["z"] = 5, ["meta"] = { ["inventory"] = {  }, ["fields"] = {  } }, ["param2"] = 0, ["param1"] = 13 }, { ["y"] = 10, ["x"] = 2, ["name"] = "moreblocks:clean_glass", ["z"] = 6, ["meta"] = { ["inventory"] = {  }, ["fields"] = {  } }, ["param2"] = 0, ["param1"] = 13 }, { ["y"] = 11, ["x"] = 2, ["name"] = "moreblocks:clean_glass", ["z"] = 5, ["meta"] = { ["inventory"] = {  }, ["fields"] = {  } }, ["param2"] = 0, ["param1"] = 13 }, { ["y"] = 11, ["x"] = 2, ["name"] = "moreblocks:clean_glass", ["z"] = 6, ["meta"] = { ["inventory"] = {  }, ["fields"] = {  } }, ["param2"] = 0, ["param1"] = 13 }, { ["y"] = 12, ["x"] = 2, ["name"] = "moreblocks:clean_glass", ["z"] = 5, ["meta"] = { ["inventory"] = {  }, ["fields"] = {  } }, ["param2"] = 0, ["param1"] = 13 }, { ["y"] = 12, ["x"] = 2, ["name"] = "moreblocks:clean_glass", ["z"] = 6, ["meta"] = { ["inventory"] = {  }, ["fields"] = {  } }, ["param2"] = 0, ["param1"] = 13 }, { ["y"] = 13, ["x"] = 2, ["name"] = "moreblocks:clean_glass", ["z"] = 5, ["meta"] = { ["inventory"] = {  }, ["fields"] = {  } }, ["param2"] = 0, ["param1"] = 13 }, { ["y"] = 13, ["x"] = 2, ["name"] = "moreblocks:clean_glass", ["z"] = 6, ["meta"] = { ["inventory"] = {  }, ["fields"] = {  } }, ["param2"] = 0, ["param1"] = 13 }, { ["y"] = 14, ["x"] = 2, ["name"] = "moreblocks:clean_glass", ["z"] = 5, ["meta"] = { ["inventory"] = {  }, ["fields"] = {  } }, ["param2"] = 0, ["param1"] = 13 }, { ["y"] = 14, ["x"] = 2, ["name"] = "moreblocks:clean_glass", ["z"] = 6, ["meta"] = { ["inventory"] = {  }, ["fields"] = {  } }, ["param2"] = 0, ["param1"] = 13 }, { ["y"] = 15, ["x"] = 2, ["name"] = "moreblocks:clean_glass", ["z"] = 5, ["meta"] = { ["inventory"] = {  }, ["fields"] = {  } }, ["param2"] = 0, ["param1"] = 13 }, { ["y"] = 15, ["x"] = 2, ["name"] = "moreblocks:clean_glass", ["z"] = 6, ["meta"] = { ["inventory"] = {  }, ["fields"] = {  } }, ["param2"] = 0, ["param1"] = 13 }, { ["y"] = 16, ["x"] = 2, ["name"] = "moreblocks:clean_glass", ["z"] = 5, ["meta"] = { ["inventory"] = {  }, ["fields"] = {  } }, ["param2"] = 0, ["param1"] = 13 }, { ["y"] = 16, ["x"] = 2, ["name"] = "moreblocks:clean_glass", ["z"] = 6, ["meta"] = { ["inventory"] = {  }, ["fields"] = {  } }, ["param2"] = 0, ["param1"] = 13 }, { ["y"] = 17, ["x"] = 2, ["name"] = "moreblocks:clean_glass", ["z"] = 5, ["meta"] = { ["inventory"] = {  }, ["fields"] = {  } }, ["param2"] = 0, ["param1"] = 13 }, { ["y"] = 17, ["x"] = 2, ["name"] = "moreblocks:clean_glass", ["z"] = 6, ["meta"] = { ["inventory"] = {  }, ["fields"] = {  } }, ["param2"] = 0, ["param1"] = 13 }, { ["y"] = 18, ["x"] = 2, ["name"] = "moreblocks:clean_glass", ["z"] = 5, ["meta"] = { ["inventory"] = {  }, ["fields"] = {  } }, ["param2"] = 0, ["param1"] = 13 }, { ["y"] = 18, ["x"] = 2, ["name"] = "moreblocks:clean_glass", ["z"] = 6, ["meta"] = { ["inventory"] = {  }, ["fields"] = {  } }, ["param2"] = 0, ["param1"] = 13 }, { ["y"] = 19, ["x"] = 2, ["name"] = "moreblocks:clean_glass", ["z"] = 5, ["meta"] = { ["inventory"] = {  }, ["fields"] = {  } }, ["param2"] = 0, ["param1"] = 13 }, { ["y"] = 19, ["x"] = 2, ["name"] = "moreblocks:clean_glass", ["z"] = 6, ["meta"] = { ["inventory"] = {  }, ["fields"] = {  } }, ["param2"] = 0, ["param1"] = 13 }, { ["y"] = 20, ["x"] = 2, ["name"] = "moreblocks:clean_glass", ["z"] = 5, ["meta"] = { ["inventory"] = {  }, ["fields"] = {  } }, ["param2"] = 0, ["param1"] = 13 }, { ["y"] = 20, ["x"] = 2, ["name"] = "moreblocks:clean_glass", ["z"] = 6, ["meta"] = { ["inventory"] = {  }, ["fields"] = {  } }, ["param2"] = 0, ["param1"] = 13 }, { ["y"] = 21, ["x"] = 2, ["name"] = "moreblocks:clean_glass", ["z"] = 5, ["meta"] = { ["inventory"] = {  }, ["fields"] = {  } }, ["param2"] = 0, ["param1"] = 13 }, { ["y"] = 21, ["x"] = 2, ["name"] = "moreblocks:clean_glass", ["z"] = 6, ["meta"] = { ["inventory"] = {  }, ["fields"] = {  } }, ["param2"] = 0, ["param1"] = 13 }, { ["y"] = 22, ["x"] = 2, ["name"] = "moreblocks:clean_glass", ["z"] = 5, ["meta"] = { ["inventory"] = {  }, ["fields"] = {  } }, ["param2"] = 0, ["param1"] = 13 }, { ["y"] = 22, ["x"] = 2, ["name"] = "moreblocks:clean_glass", ["z"] = 6, ["meta"] = { ["inventory"] = {  }, ["fields"] = {  } }, ["param2"] = 0, ["param1"] = 13 }, { ["y"] = 23, ["x"] = 2, ["name"] = "moreblocks:clean_glass", ["z"] = 5, ["meta"] = { ["inventory"] = {  }, ["fields"] = {  } }, ["param2"] = 0, ["param1"] = 13 }, { ["y"] = 23, ["x"] = 2, ["name"] = "moreblocks:clean_glass", ["z"] = 6, ["meta"] = { ["inventory"] = {  }, ["fields"] = {  } }, ["param2"] = 0, ["param1"] = 13 }, { ["y"] = 24, ["x"] = 2, ["name"] = "moreblocks:clean_glass", ["z"] = 5, ["meta"] = { ["inventory"] = {  }, ["fields"] = {  } }, ["param2"] = 0, ["param1"] = 13 }, { ["y"] = 24, ["x"] = 2, ["name"] = "moreblocks:clean_glass", ["z"] = 6, ["meta"] = { ["inventory"] = {  }, ["fields"] = {  } }, ["param2"] = 0, ["param1"] = 13 }, { ["y"] = 25, ["x"] = 2, ["name"] = "moreblocks:clean_glass", ["z"] = 5, ["meta"] = { ["inventory"] = {  }, ["fields"] = {  } }, ["param2"] = 0, ["param1"] = 13 }, { ["y"] = 25, ["x"] = 2, ["name"] = "moreblocks:clean_glass", ["z"] = 6, ["meta"] = { ["inventory"] = {  }, ["fields"] = {  } }, ["param2"] = 0, ["param1"] = 13 }, { ["y"] = 26, ["x"] = 2, ["name"] = "moreblocks:clean_glass", ["z"] = 5, ["meta"] = { ["inventory"] = {  }, ["fields"] = {  } }, ["param2"] = 0, ["param1"] = 13 }, { ["y"] = 26, ["x"] = 2, ["name"] = "moreblocks:clean_glass", ["z"] = 6, ["meta"] = { ["inventory"] = {  }, ["fields"] = {  } }, ["param2"] = 0, ["param1"] = 13 }, { ["y"] = 27, ["x"] = 2, ["name"] = "moreblocks:clean_glass", ["z"] = 5, ["meta"] = { ["inventory"] = {  }, ["fields"] = {  } }, ["param2"] = 0, ["param1"] = 13 }, { ["y"] = 27, ["x"] = 2, ["name"] = "moreblocks:clean_glass", ["z"] = 6, ["meta"] = { ["inventory"] = {  }, ["fields"] = {  } }, ["param2"] = 0, ["param1"] = 29 }, { ["y"] = 28, ["x"] = 2, ["name"] = "moreblocks:clean_glass", ["z"] = 5, ["meta"] = { ["inventory"] = {  }, ["fields"] = {  } }, ["param2"] = 0, ["param1"] = 29 }, { ["y"] = 28, ["x"] = 2, ["name"] = "moreblocks:clean_glass", ["z"] = 6, ["meta"] = { ["inventory"] = {  }, ["fields"] = {  } }, ["param2"] = 0, ["param1"] = 45 }, { ["y"] = 29, ["x"] = 2, ["name"] = "moreblocks:clean_glass", ["z"] = 5, ["meta"] = { ["inventory"] = {  }, ["fields"] = {  } }, ["param2"] = 0, ["param1"] = 45 }, { ["y"] = 29, ["x"] = 2, ["name"] = "moreblocks:clean_glass", ["z"] = 6, ["meta"] = { ["inventory"] = {  }, ["fields"] = {  } }, ["param2"] = 0, ["param1"] = 61 }, { ["y"] = 31, ["x"] = 2, ["name"] = "default:cobble", ["z"] = 3, ["meta"] = { ["inventory"] = {  }, ["fields"] = {  } }, ["param2"] = 0, ["param1"] = 0 }, { ["y"] = 31, ["x"] = 2, ["name"] = "default:cobble", ["z"] = 4, ["meta"] = { ["inventory"] = {  }, ["fields"] = {  } }, ["param2"] = 0, ["param1"] = 0 }, { ["y"] = 31, ["x"] = 2, ["name"] = "default:cobble", ["z"] = 5, ["meta"] = { ["inventory"] = {  }, ["fields"] = {  } }, ["param2"] = 0, ["param1"] = 0 }, { ["y"] = 31, ["x"] = 2, ["name"] = "default:cobble", ["z"] = 6, ["meta"] = { ["inventory"] = {  }, ["fields"] = {  } }, ["param2"] = 0, ["param1"] = 0 }, { ["y"] = 31, ["x"] = 2, ["name"] = "default:cobble", ["z"] = 7, ["meta"] = { ["inventory"] = {  }, ["fields"] = {  } }, ["param2"] = 0, ["param1"] = 0 }, { ["y"] = 31, ["x"] = 2, ["name"] = "default:cobble", ["z"] = 8, ["meta"] = { ["inventory"] = {  }, ["fields"] = {  } }, ["param2"] = 0, ["param1"] = 0 }, { ["y"] = 31, ["x"] = 2, ["name"] = "default:cobble", ["z"] = 9, ["meta"] = { ["inventory"] = {  }, ["fields"] = {  } }, ["param2"] = 0, ["param1"] = 0 }, { ["y"] = 31, ["x"] = 2, ["name"] = "default:cobble", ["z"] = 10, ["meta"] = { ["inventory"] = {  }, ["fields"] = {  } }, ["param2"] = 0, ["param1"] = 0 }, { ["y"] = 31, ["x"] = 2, ["name"] = "default:cobble", ["z"] = 11, ["meta"] = { ["inventory"] = {  }, ["fields"] = {  } }, ["param2"] = 0, ["param1"] = 0 }, { ["y"] = 31, ["x"] = 2, ["name"] = "default:cobble", ["z"] = 12, ["meta"] = { ["inventory"] = {  }, ["fields"] = {  } }, ["param2"] = 0, ["param1"] = 0 }, { ["y"] = 31, ["x"] = 2, ["name"] = "default:cobble", ["z"] = 13, ["meta"] = { ["inventory"] = {  }, ["fields"] = {  } }, ["param2"] = 0, ["param1"] = 0 }, { ["y"] = 31, ["x"] = 2, ["name"] = "default:cobble", ["z"] = 14, ["meta"] = { ["inventory"] = {  }, ["fields"] = {  } }, ["param2"] = 0, ["param1"] = 0 }, { ["y"] = 31, ["x"] = 2, ["name"] = "default:cobble", ["z"] = 15, ["meta"] = { ["inventory"] = {  }, ["fields"] = {  } }, ["param2"] = 0, ["param1"] = 0 }, { ["y"] = 31, ["x"] = 2, ["name"] = "default:cobble", ["z"] = 16, ["meta"] = { ["inventory"] = {  }, ["fields"] = {  } }, ["param2"] = 0, ["param1"] = 0 }, { ["y"] = 31, ["x"] = 2, ["name"] = "default:cobble", ["z"] = 17, ["meta"] = { ["inventory"] = {  }, ["fields"] = {  } }, ["param2"] = 0, ["param1"] = 0 }, { ["y"] = 31, ["x"] = 2, ["name"] = "default:cobble", ["z"] = 18, ["meta"] = { ["inventory"] = {  }, ["fields"] = {  } }, ["param2"] = 0, ["param1"] = 0 }, { ["y"] = 31, ["x"] = 2, ["name"] = "default:cobble", ["z"] = 19, ["meta"] = { ["inventory"] = {  }, ["fields"] = {  } }, ["param2"] = 0, ["param1"] = 0 }, { ["y"] = 31, ["x"] = 2, ["name"] = "default:cobble", ["z"] = 20, ["meta"] = { ["inventory"] = {  }, ["fields"] = {  } }, ["param2"] = 0, ["param1"] = 0 }, { ["y"] = 31, ["x"] = 2, ["name"] = "default:cobble", ["z"] = 21, ["meta"] = { ["inventory"] = {  }, ["fields"] = {  } }, ["param2"] = 0, ["param1"] = 0 }, { ["y"] = 32, ["x"] = 2, ["name"] = "default:cobble", ["z"] = 2, ["meta"] = { ["inventory"] = {  }, ["fields"] = {  } }, ["param2"] = 0, ["param1"] = 0 }, { ["y"] = 32, ["x"] = 2, ["name"] = "default:cobble", ["z"] = 3, ["meta"] = { ["inventory"] = {  }, ["fields"] = {  } }, ["param2"] = 0, ["param1"] = 0 }, { ["y"] = 32, ["x"] = 2, ["name"] = "default:cobble", ["z"] = 4, ["meta"] = { ["inventory"] = {  }, ["fields"] = {  } }, ["param2"] = 0, ["param1"] = 0 }, { ["y"] = 32, ["x"] = 2, ["name"] = "default:sand", ["z"] = 5, ["meta"] = { ["inventory"] = {  }, ["fields"] = {  } }, ["param2"] = 0, ["param1"] = 0 }, { ["y"] = 32, ["x"] = 2, ["name"] = "default:sand", ["z"] = 6, ["meta"] = { ["inventory"] = {  }, ["fields"] = {  } }, ["param2"] = 0, ["param1"] = 0 }, { ["y"] = 32, ["x"] = 2, ["name"] = "default:sand", ["z"] = 7, ["meta"] = { ["inventory"] = {  }, ["fields"] = {  } }, ["param2"] = 0, ["param1"] = 0 }, { ["y"] = 32, ["x"] = 2, ["name"] = "default:sand", ["z"] = 8, ["meta"] = { ["inventory"] = {  }, ["fields"] = {  } }, ["param2"] = 0, ["param1"] = 0 }, { ["y"] = 32, ["x"] = 2, ["name"] = "default:sand", ["z"] = 9, ["meta"] = { ["inventory"] = {  }, ["fields"] = {  } }, ["param2"] = 0, ["param1"] = 0 }, { ["y"] = 32, ["x"] = 2, ["name"] = "default:sand", ["z"] = 10, ["meta"] = { ["inventory"] = {  }, ["fields"] = {  } }, ["param2"] = 0, ["param1"] = 0 }, { ["y"] = 32, ["x"] = 2, ["name"] = "default:sand", ["z"] = 11, ["meta"] = { ["inventory"] = {  }, ["fields"] = {  } }, ["param2"] = 0, ["param1"] = 0 }, { ["y"] = 32, ["x"] = 2, ["name"] = "default:sand", ["z"] = 12, ["meta"] = { ["inventory"] = {  }, ["fields"] = {  } }, ["param2"] = 0, ["param1"] = 0 }, { ["y"] = 32, ["x"] = 2, ["name"] = "default:sand", ["z"] = 13, ["meta"] = { ["inventory"] = {  }, ["fields"] = {  } }, ["param2"] = 0, ["param1"] = 0 }, { ["y"] = 32, ["x"] = 2, ["name"] = "default:sand", ["z"] = 14, ["meta"] = { ["inventory"] = {  }, ["fields"] = {  } }, ["param2"] = 0, ["param1"] = 0 }, { ["y"] = 32, ["x"] = 2, ["name"] = "default:sand", ["z"] = 15, ["meta"] = { ["inventory"] = {  }, ["fields"] = {  } }, ["param2"] = 0, ["param1"] = 0 }, { ["y"] = 32, ["x"] = 2, ["name"] = "default:sand", ["z"] = 16, ["meta"] = { ["inventory"] = {  }, ["fields"] = {  } }, ["param2"] = 0, ["param1"] = 0 }, { ["y"] = 32, ["x"] = 2, ["name"] = "default:sand", ["z"] = 17, ["meta"] = { ["inventory"] = {  }, ["fields"] = {  } }, ["param2"] = 0, ["param1"] = 0 }, { ["y"] = 32, ["x"] = 2, ["name"] = "default:sand", ["z"] = 18, ["meta"] = { ["inventory"] = {  }, ["fields"] = {  } }, ["param2"] = 0, ["param1"] = 0 }, { ["y"] = 32, ["x"] = 2, ["name"] = "default:sand", ["z"] = 19, ["meta"] = { ["inventory"] = {  }, ["fields"] = {  } }, ["param2"] = 0, ["param1"] = 0 }, { ["y"] = 32, ["x"] = 2, ["name"] = "framedglass:steel_framed_obsidian_glass", ["z"] = 20, ["meta"] = { ["inventory"] = {  }, ["fields"] = {  } }, ["param2"] = 0, ["param1"] = 95 }, { ["y"] = 32, ["x"] = 2, ["name"] = "framedglass:steel_framed_obsidian_glass", ["z"] = 21, ["meta"] = { ["inventory"] = {  }, ["fields"] = {  } }, ["param2"] = 0, ["param1"] = 79 }, { ["y"] = 33, ["x"] = 2, ["name"] = "framedglass:steel_framed_obsidian_glass", ["z"] = 1, ["meta"] = { ["inventory"] = {  }, ["fields"] = {  } }, ["param2"] = 0, ["param1"] = 143 }, { ["y"] = 33, ["x"] = 2, ["name"] = "default:cobble", ["z"] = 2, ["meta"] = { ["inventory"] = {  }, ["fields"] = {  } }, ["param2"] = 0, ["param1"] = 0 }, { ["y"] = 33, ["x"] = 2, ["name"] = "default:cobble", ["z"] = 3, ["meta"] = { ["inventory"] = {  }, ["fields"] = {  } }, ["param2"] = 0, ["param1"] = 0 }, { ["y"] = 33, ["x"] = 2, ["name"] = "default:cobble", ["z"] = 4, ["meta"] = { ["inventory"] = {  }, ["fields"] = {  } }, ["param2"] = 0, ["param1"] = 0 }, { ["y"] = 33, ["x"] = 2, ["name"] = "default:sand", ["z"] = 5, ["meta"] = { ["inventory"] = {  }, ["fields"] = {  } }, ["param2"] = 0, ["param1"] = 0 }, { ["y"] = 33, ["x"] = 2, ["name"] = "default:sand", ["z"] = 6, ["meta"] = { ["inventory"] = {  }, ["fields"] = {  } }, ["param2"] = 0, ["param1"] = 0 }, { ["y"] = 33, ["x"] = 2, ["name"] = "default:sand", ["z"] = 7, ["meta"] = { ["inventory"] = {  }, ["fields"] = {  } }, ["param2"] = 0, ["param1"] = 0 }, { ["y"] = 33, ["x"] = 2, ["name"] = "default:sand", ["z"] = 8, ["meta"] = { ["inventory"] = {  }, ["fields"] = {  } }, ["param2"] = 0, ["param1"] = 0 }, { ["y"] = 33, ["x"] = 2, ["name"] = "default:sand", ["z"] = 9, ["meta"] = { ["inventory"] = {  }, ["fields"] = {  } }, ["param2"] = 0, ["param1"] = 0 }, { ["y"] = 33, ["x"] = 2, ["name"] = "default:sand", ["z"] = 10, ["meta"] = { ["inventory"] = {  }, ["fields"] = {  } }, ["param2"] = 0, ["param1"] = 0 }, { ["y"] = 33, ["x"] = 2, ["name"] = "default:sand", ["z"] = 11, ["meta"] = { ["inventory"] = {  }, ["fields"] = {  } }, ["param2"] = 0, ["param1"] = 0 }, { ["y"] = 33, ["x"] = 2, ["name"] = "default:sand", ["z"] = 12, ["meta"] = { ["inventory"] = {  }, ["fields"] = {  } }, ["param2"] = 0, ["param1"] = 0 }, { ["y"] = 33, ["x"] = 2, ["name"] = "default:sand", ["z"] = 13, ["meta"] = { ["inventory"] = {  }, ["fields"] = {  } }, ["param2"] = 0, ["param1"] = 0 }, { ["y"] = 33, ["x"] = 2, ["name"] = "default:sand", ["z"] = 14, ["meta"] = { ["inventory"] = {  }, ["fields"] = {  } }, ["param2"] = 0, ["param1"] = 0 }, { ["y"] = 33, ["x"] = 2, ["name"] = "default:sand", ["z"] = 15, ["meta"] = { ["inventory"] = {  }, ["fields"] = {  } }, ["param2"] = 0, ["param1"] = 0 }, { ["y"] = 33, ["x"] = 2, ["name"] = "default:sand", ["z"] = 16, ["meta"] = { ["inventory"] = {  }, ["fields"] = {  } }, ["param2"] = 0, ["param1"] = 0 }, { ["y"] = 33, ["x"] = 2, ["name"] = "default:sand", ["z"] = 17, ["meta"] = { ["inventory"] = {  }, ["fields"] = {  } }, ["param2"] = 0, ["param1"] = 0 }, { ["y"] = 33, ["x"] = 2, ["name"] = "default:sand", ["z"] = 18, ["meta"] = { ["inventory"] = {  }, ["fields"] = {  } }, ["param2"] = 0, ["param1"] = 0 }, { ["y"] = 33, ["x"] = 2, ["name"] = "framedglass:steel_framed_obsidian_glass", ["z"] = 19, ["meta"] = { ["inventory"] = {  }, ["fields"] = {  } }, ["param2"] = 0, ["param1"] = 127 }, { ["y"] = 33, ["x"] = 2, ["name"] = "framedglass:steel_framed_obsidian_glass", ["z"] = 20, ["meta"] = { ["inventory"] = {  }, ["fields"] = {  } }, ["param2"] = 0, ["param1"] = 111 }, { ["y"] = 33, ["x"] = 2, ["name"] = "framedglass:steel_framed_obsidian_glass", ["z"] = 21, ["meta"] = { ["inventory"] = {  }, ["fields"] = {  } }, ["param2"] = 0, ["param1"] = 95 }, { ["y"] = 33, ["x"] = 2, ["name"] = "framedglass:steel_framed_obsidian_glass", ["z"] = 22, ["meta"] = { ["inventory"] = {  }, ["fields"] = {  } }, ["param2"] = 0, ["param1"] = 79 }, { ["y"] = 34, ["x"] = 2, ["name"] = "framedglass:steel_framed_obsidian_glass", ["z"] = 1, ["meta"] = { ["inventory"] = {  }, ["fields"] = {  } }, ["param2"] = 0, ["param1"] = 159 }, { ["y"] = 34, ["x"] = 2, ["name"] = "framedglass:steel_framed_obsidian_glass", ["z"] = 22, ["meta"] = { ["inventory"] = {  }, ["fields"] = {  } }, ["param2"] = 0, ["param1"] = 95 }, { ["y"] = 35, ["x"] = 2, ["name"] = "framedglass:steel_framed_obsidian_glass", ["z"] = 1, ["meta"] = { ["inventory"] = {  }, ["fields"] = {  } }, ["param2"] = 0, ["param1"] = 175 }, { ["y"] = 35, ["x"] = 2, ["name"] = "framedglass:steel_framed_obsidian_glass", ["z"] = 22, ["meta"] = { ["inventory"] = {  }, ["fields"] = {  } }, ["param2"] = 0, ["param1"] = 111 }, { ["y"] = 36, ["x"] = 2, ["name"] = "framedglass:steel_framed_obsidian_glass", ["z"] = 1, ["meta"] = { ["inventory"] = {  }, ["fields"] = {  } }, ["param2"] = 0, ["param1"] = 191 }, { ["y"] = 36, ["x"] = 2, ["name"] = "arrow_signs:wall", ["z"] = 9, ["meta"] = { ["inventory"] = {  }, ["fields"] = { ["text"] = "Sortie", ["infotext"] = "\"Sortie\"", ["formspec"] = "field[text;Sign text:;${text}]" } }, ["param2"] = 7, ["param1"] = 191 }, { ["y"] = 36, ["x"] = 2, ["name"] = "framedglass:steel_framed_obsidian_glass", ["z"] = 22, ["meta"] = { ["inventory"] = {  }, ["fields"] = {  } }, ["param2"] = 0, ["param1"] = 127 }, { ["y"] = 37, ["x"] = 2, ["name"] = "framedglass:steel_framed_obsidian_glass", ["z"] = 1, ["meta"] = { ["inventory"] = {  }, ["fields"] = {  } }, ["param2"] = 0, ["param1"] = 175 }, { ["y"] = 37, ["x"] = 2, ["name"] = "framedglass:steel_framed_obsidian_glass", ["z"] = 22, ["meta"] = { ["inventory"] = {  }, ["fields"] = {  } }, ["param2"] = 0, ["param1"] = 111 }, { ["y"] = 38, ["x"] = 2, ["name"] = "framedglass:steel_framed_obsidian_glass", ["z"] = 1, ["meta"] = { ["inventory"] = {  }, ["fields"] = {  } }, ["param2"] = 0, ["param1"] = 159 }, { ["y"] = 38, ["x"] = 2, ["name"] = "framedglass:steel_framed_obsidian_glass", ["z"] = 22, ["meta"] = { ["inventory"] = {  }, ["fields"] = {  } }, ["param2"] = 0, ["param1"] = 95 }, { ["y"] = 39, ["x"] = 2, ["name"] = "framedglass:steel_framed_obsidian_glass", ["z"] = 1, ["meta"] = { ["inventory"] = {  }, ["fields"] = {  } }, ["param2"] = 0, ["param1"] = 143 }, { ["y"] = 39, ["x"] = 2, ["name"] = "framedglass:steel_framed_obsidian_glass", ["z"] = 22, ["meta"] = { ["inventory"] = {  }, ["fields"] = {  } }, ["param2"] = 0, ["param1"] = 79 }, { ["y"] = 40, ["x"] = 2, ["name"] = "framedglass:steel_framed_obsidian_glass", ["z"] = 1, ["meta"] = { ["inventory"] = {  }, ["fields"] = {  } }, ["param2"] = 0, ["param1"] = 127 }, { ["y"] = 40, ["x"] = 2, ["name"] = "framedglass:steel_framed_obsidian_glass", ["z"] = 22, ["meta"] = { ["inventory"] = {  }, ["fields"] = {  } }, ["param2"] = 0, ["param1"] = 63 }, { ["y"] = 41, ["x"] = 2, ["name"] = "framedglass:steel_framed_obsidian_glass", ["z"] = 1, ["meta"] = { ["inventory"] = {  }, ["fields"] = {  } }, ["param2"] = 0, ["param1"] = 111 }, { ["y"] = 41, ["x"] = 2, ["name"] = "framedglass:steel_framed_obsidian_glass", ["z"] = 22, ["meta"] = { ["inventory"] = {  }, ["fields"] = {  } }, ["param2"] = 0, ["param1"] = 47 }, { ["y"] = 42, ["x"] = 2, ["name"] = "framedglass:steel_framed_obsidian_glass", ["z"] = 1, ["meta"] = { ["inventory"] = {  }, ["fields"] = {  } }, ["param2"] = 0, ["param1"] = 95 }, { ["y"] = 42, ["x"] = 2, ["name"] = "framedglass:steel_framed_obsidian_glass", ["z"] = 2, ["meta"] = { ["inventory"] = {  }, ["fields"] = {  } }, ["param2"] = 0, ["param1"] = 79 }, { ["y"] = 42, ["x"] = 2, ["name"] = "framedglass:steel_framed_obsidian_glass", ["z"] = 3, ["meta"] = { ["inventory"] = {  }, ["fields"] = {  } }, ["param2"] = 0, ["param1"] = 63 }, { ["y"] = 42, ["x"] = 2, ["name"] = "framedglass:steel_framed_obsidian_glass", ["z"] = 4, ["meta"] = { ["inventory"] = {  }, ["fields"] = {  } }, ["param2"] = 0, ["param1"] = 79 }, { ["y"] = 42, ["x"] = 2, ["name"] = "framedglass:steel_framed_obsidian_glass", ["z"] = 5, ["meta"] = { ["inventory"] = {  }, ["fields"] = {  } }, ["param2"] = 0, ["param1"] = 95 }, { ["y"] = 42, ["x"] = 2, ["name"] = "framedglass:steel_framed_obsidian_glass", ["z"] = 6, ["meta"] = { ["inventory"] = {  }, ["fields"] = {  } }, ["param2"] = 0, ["param1"] = 111 }, { ["y"] = 42, ["x"] = 2, ["name"] = "framedglass:steel_framed_obsidian_glass", ["z"] = 7, ["meta"] = { ["inventory"] = {  }, ["fields"] = {  } }, ["param2"] = 0, ["param1"] = 95 }, { ["y"] = 42, ["x"] = 2, ["name"] = "framedglass:steel_framed_obsidian_glass", ["z"] = 8, ["meta"] = { ["inventory"] = {  }, ["fields"] = {  } }, ["param2"] = 0, ["param1"] = 111 }, { ["y"] = 42, ["x"] = 2, ["name"] = "framedglass:steel_framed_obsidian_glass", ["z"] = 9, ["meta"] = { ["inventory"] = {  }, ["fields"] = {  } }, ["param2"] = 0, ["param1"] = 111 }, { ["y"] = 42, ["x"] = 2, ["name"] = "framedglass:steel_framed_obsidian_glass", ["z"] = 10, ["meta"] = { ["inventory"] = {  }, ["fields"] = {  } }, ["param2"] = 0, ["param1"] = 111 }, { ["y"] = 42, ["x"] = 2, ["name"] = "framedglass:steel_framed_obsidian_glass", ["z"] = 11, ["meta"] = { ["inventory"] = {  }, ["fields"] = {  } }, ["param2"] = 0, ["param1"] = 95 }, { ["y"] = 42, ["x"] = 2, ["name"] = "framedglass:steel_framed_obsidian_glass", ["z"] = 12, ["meta"] = { ["inventory"] = {  }, ["fields"] = {  } }, ["param2"] = 0, ["param1"] = 79 }, { ["y"] = 42, ["x"] = 2, ["name"] = "framedglass:steel_framed_obsidian_glass", ["z"] = 13, ["meta"] = { ["inventory"] = {  }, ["fields"] = {  } }, ["param2"] = 0, ["param1"] = 63 }, { ["y"] = 42, ["x"] = 2, ["name"] = "framedglass:steel_framed_obsidian_glass", ["z"] = 14, ["meta"] = { ["inventory"] = {  }, ["fields"] = {  } }, ["param2"] = 0, ["param1"] = 79 }, { ["y"] = 42, ["x"] = 2, ["name"] = "framedglass:steel_framed_obsidian_glass", ["z"] = 15, ["meta"] = { ["inventory"] = {  }, ["fields"] = {  } }, ["param2"] = 0, ["param1"] = 95 }, { ["y"] = 42, ["x"] = 2, ["name"] = "framedglass:steel_framed_obsidian_glass", ["z"] = 16, ["meta"] = { ["inventory"] = {  }, ["fields"] = {  } }, ["param2"] = 0, ["param1"] = 79 }, { ["y"] = 42, ["x"] = 2, ["name"] = "framedglass:steel_framed_obsidian_glass", ["z"] = 17, ["meta"] = { ["inventory"] = {  }, ["fields"] = {  } }, ["param2"] = 0, ["param1"] = 63 }, { ["y"] = 42, ["x"] = 2, ["name"] = "framedglass:steel_framed_obsidian_glass", ["z"] = 18, ["meta"] = { ["inventory"] = {  }, ["fields"] = {  } }, ["param2"] = 0, ["param1"] = 63 }, { ["y"] = 42, ["x"] = 2, ["name"] = "framedglass:steel_framed_obsidian_glass", ["z"] = 19, ["meta"] = { ["inventory"] = {  }, ["fields"] = {  } }, ["param2"] = 0, ["param1"] = 79 }, { ["y"] = 42, ["x"] = 2, ["name"] = "framedglass:steel_framed_obsidian_glass", ["z"] = 20, ["meta"] = { ["inventory"] = {  }, ["fields"] = {  } }, ["param2"] = 0, ["param1"] = 63 }, { ["y"] = 42, ["x"] = 2, ["name"] = "framedglass:steel_framed_obsidian_glass", ["z"] = 21, ["meta"] = { ["inventory"] = {  }, ["fields"] = {  } }, ["param2"] = 0, ["param1"] = 47 }, { ["y"] = 42, ["x"] = 2, ["name"] = "framedglass:steel_framed_obsidian_glass", ["z"] = 22, ["meta"] = { ["inventory"] = {  }, ["fields"] = {  } }, ["param2"] = 0, ["param1"] = 31 }, { ["y"] = 0, ["x"] = 3, ["name"] = "default:sand", ["z"] = 4, ["meta"] = { ["inventory"] = {  }, ["fields"] = {  } }, ["param2"] = 0, ["param1"] = 0 }, { ["y"] = 0, ["x"] = 3, ["name"] = "default:sand", ["z"] = 5, ["meta"] = { ["inventory"] = {  }, ["fields"] = {  } }, ["param2"] = 0, ["param1"] = 0 }, { ["y"] = 0, ["x"] = 3, ["name"] = "moreblocks:clean_glass", ["z"] = 6, ["meta"] = { ["inventory"] = {  }, ["fields"] = {  } }, ["param2"] = 0, ["param1"] = 12 }, { ["y"] = 0, ["x"] = 3, ["name"] = "columnia:column_crosslink_stonebrick", ["z"] = 7, ["meta"] = { ["inventory"] = {  }, ["fields"] = {  } }, ["param2"] = 20, ["param1"] = 12 }, { ["y"] = 0, ["x"] = 3, ["name"] = "columnia:column_crosslink_stonebrick", ["z"] = 20, ["meta"] = { ["inventory"] = {  }, ["fields"] = {  } }, ["param2"] = 20, ["param1"] = 12 }, { ["y"] = 1, ["x"] = 3, ["name"] = "default:sand", ["z"] = 4, ["meta"] = { ["inventory"] = {  }, ["fields"] = {  } }, ["param2"] = 0, ["param1"] = 0 }, { ["y"] = 1, ["x"] = 3, ["name"] = "default:sand", ["z"] = 5, ["meta"] = { ["inventory"] = {  }, ["fields"] = {  } }, ["param2"] = 0, ["param1"] = 0 }, { ["y"] = 1, ["x"] = 3, ["name"] = "moreblocks:clean_glass", ["z"] = 6, ["meta"] = { ["inventory"] = {  }, ["fields"] = {  } }, ["param2"] = 0, ["param1"] = 12 }, { ["y"] = 1, ["x"] = 3, ["name"] = "columnia:column_mid_stonebrick", ["z"] = 7, ["meta"] = { ["inventory"] = {  }, ["fields"] = {  } }, ["param2"] = 2, ["param1"] = 12 }, { ["y"] = 1, ["x"] = 3, ["name"] = "columnia:column_mid_stonebrick", ["z"] = 20, ["meta"] = { ["inventory"] = {  }, ["fields"] = {  } }, ["param2"] = 3, ["param1"] = 12 }, { ["y"] = 2, ["x"] = 3, ["name"] = "default:sand", ["z"] = 4, ["meta"] = { ["inventory"] = {  }, ["fields"] = {  } }, ["param2"] = 0, ["param1"] = 0 }, { ["y"] = 2, ["x"] = 3, ["name"] = "default:sand", ["z"] = 5, ["meta"] = { ["inventory"] = {  }, ["fields"] = {  } }, ["param2"] = 0, ["param1"] = 0 }, { ["y"] = 2, ["x"] = 3, ["name"] = "moreblocks:clean_glass", ["z"] = 6, ["meta"] = { ["inventory"] = {  }, ["fields"] = {  } }, ["param2"] = 0, ["param1"] = 12 }, { ["y"] = 2, ["x"] = 3, ["name"] = "columnia:column_mid_stonebrick", ["z"] = 7, ["meta"] = { ["inventory"] = {  }, ["fields"] = {  } }, ["param2"] = 22, ["param1"] = 12 }, { ["y"] = 2, ["x"] = 3, ["name"] = "columnia:column_mid_stonebrick", ["z"] = 20, ["meta"] = { ["inventory"] = {  }, ["fields"] = {  } }, ["param2"] = 3, ["param1"] = 12 }, { ["y"] = 3, ["x"] = 3, ["name"] = "default:sand", ["z"] = 4, ["meta"] = { ["inventory"] = {  }, ["fields"] = {  } }, ["param2"] = 0, ["param1"] = 0 }, { ["y"] = 3, ["x"] = 3, ["name"] = "default:sand", ["z"] = 5, ["meta"] = { ["inventory"] = {  }, ["fields"] = {  } }, ["param2"] = 0, ["param1"] = 0 }, { ["y"] = 3, ["x"] = 3, ["name"] = "moreblocks:clean_glass", ["z"] = 6, ["meta"] = { ["inventory"] = {  }, ["fields"] = {  } }, ["param2"] = 0, ["param1"] = 12 }, { ["y"] = 3, ["x"] = 3, ["name"] = "columnia:column_mid_stonebrick", ["z"] = 7, ["meta"] = { ["inventory"] = {  }, ["fields"] = {  } }, ["param2"] = 22, ["param1"] = 12 }, { ["y"] = 3, ["x"] = 3, ["name"] = "columnia:column_mid_stonebrick", ["z"] = 20, ["meta"] = { ["inventory"] = {  }, ["fields"] = {  } }, ["param2"] = 21, ["param1"] = 12 }, { ["y"] = 4, ["x"] = 3, ["name"] = "default:sand", ["z"] = 4, ["meta"] = { ["inventory"] = {  }, ["fields"] = {  } }, ["param2"] = 0, ["param1"] = 0 }, { ["y"] = 4, ["x"] = 3, ["name"] = "default:sand", ["z"] = 5, ["meta"] = { ["inventory"] = {  }, ["fields"] = {  } }, ["param2"] = 0, ["param1"] = 0 }, { ["y"] = 4, ["x"] = 3, ["name"] = "moreblocks:clean_glass", ["z"] = 6, ["meta"] = { ["inventory"] = {  }, ["fields"] = {  } }, ["param2"] = 0, ["param1"] = 12 }, { ["y"] = 4, ["x"] = 3, ["name"] = "columnia:column_mid_stonebrick", ["z"] = 7, ["meta"] = { ["inventory"] = {  }, ["fields"] = {  } }, ["param2"] = 22, ["param1"] = 12 }, { ["y"] = 4, ["x"] = 3, ["name"] = "columnia:column_mid_stonebrick", ["z"] = 20, ["meta"] = { ["inventory"] = {  }, ["fields"] = {  } }, ["param2"] = 21, ["param1"] = 12 }, { ["y"] = 5, ["x"] = 3, ["name"] = "default:sand", ["z"] = 4, ["meta"] = { ["inventory"] = {  }, ["fields"] = {  } }, ["param2"] = 0, ["param1"] = 0 }, { ["y"] = 5, ["x"] = 3, ["name"] = "default:sand", ["z"] = 5, ["meta"] = { ["inventory"] = {  }, ["fields"] = {  } }, ["param2"] = 0, ["param1"] = 0 }, { ["y"] = 5, ["x"] = 3, ["name"] = "moreblocks:clean_glass", ["z"] = 6, ["meta"] = { ["inventory"] = {  }, ["fields"] = {  } }, ["param2"] = 0, ["param1"] = 12 }, { ["y"] = 5, ["x"] = 3, ["name"] = "columnia:column_mid_stonebrick", ["z"] = 7, ["meta"] = { ["inventory"] = {  }, ["fields"] = {  } }, ["param2"] = 22, ["param1"] = 12 }, { ["y"] = 5, ["x"] = 3, ["name"] = "columnia:column_mid_stonebrick", ["z"] = 20, ["meta"] = { ["inventory"] = {  }, ["fields"] = {  } }, ["param2"] = 21, ["param1"] = 12 }, { ["y"] = 6, ["x"] = 3, ["name"] = "default:sand", ["z"] = 4, ["meta"] = { ["inventory"] = {  }, ["fields"] = {  } }, ["param2"] = 0, ["param1"] = 0 }, { ["y"] = 6, ["x"] = 3, ["name"] = "default:sand", ["z"] = 5, ["meta"] = { ["inventory"] = {  }, ["fields"] = {  } }, ["param2"] = 0, ["param1"] = 0 }, { ["y"] = 6, ["x"] = 3, ["name"] = "moreblocks:clean_glass", ["z"] = 6, ["meta"] = { ["inventory"] = {  }, ["fields"] = {  } }, ["param2"] = 0, ["param1"] = 12 }, { ["y"] = 6, ["x"] = 3, ["name"] = "columnia:column_mid_stonebrick", ["z"] = 7, ["meta"] = { ["inventory"] = {  }, ["fields"] = {  } }, ["param2"] = 22, ["param1"] = 12 }, { ["y"] = 6, ["x"] = 3, ["name"] = "columnia:column_mid_stonebrick", ["z"] = 20, ["meta"] = { ["inventory"] = {  }, ["fields"] = {  } }, ["param2"] = 21, ["param1"] = 12 }, { ["y"] = 7, ["x"] = 3, ["name"] = "default:sand", ["z"] = 4, ["meta"] = { ["inventory"] = {  }, ["fields"] = {  } }, ["param2"] = 0, ["param1"] = 0 }, { ["y"] = 7, ["x"] = 3, ["name"] = "default:sand", ["z"] = 5, ["meta"] = { ["inventory"] = {  }, ["fields"] = {  } }, ["param2"] = 0, ["param1"] = 0 }, { ["y"] = 7, ["x"] = 3, ["name"] = "moreblocks:clean_glass", ["z"] = 6, ["meta"] = { ["inventory"] = {  }, ["fields"] = {  } }, ["param2"] = 0, ["param1"] = 12 }, { ["y"] = 7, ["x"] = 3, ["name"] = "columnia:column_mid_stonebrick", ["z"] = 7, ["meta"] = { ["inventory"] = {  }, ["fields"] = {  } }, ["param2"] = 22, ["param1"] = 12 }, { ["y"] = 7, ["x"] = 3, ["name"] = "columnia:column_mid_stonebrick", ["z"] = 20, ["meta"] = { ["inventory"] = {  }, ["fields"] = {  } }, ["param2"] = 21, ["param1"] = 12 }, { ["y"] = 8, ["x"] = 3, ["name"] = "default:sand", ["z"] = 4, ["meta"] = { ["inventory"] = {  }, ["fields"] = {  } }, ["param2"] = 0, ["param1"] = 0 }, { ["y"] = 8, ["x"] = 3, ["name"] = "default:sand", ["z"] = 5, ["meta"] = { ["inventory"] = {  }, ["fields"] = {  } }, ["param2"] = 0, ["param1"] = 0 }, { ["y"] = 8, ["x"] = 3, ["name"] = "moreblocks:clean_glass", ["z"] = 6, ["meta"] = { ["inventory"] = {  }, ["fields"] = {  } }, ["param2"] = 0, ["param1"] = 12 }, { ["y"] = 8, ["x"] = 3, ["name"] = "columnia:column_mid_stonebrick", ["z"] = 7, ["meta"] = { ["inventory"] = {  }, ["fields"] = {  } }, ["param2"] = 22, ["param1"] = 12 }, { ["y"] = 8, ["x"] = 3, ["name"] = "columnia:column_mid_stonebrick", ["z"] = 20, ["meta"] = { ["inventory"] = {  }, ["fields"] = {  } }, ["param2"] = 21, ["param1"] = 12 }, { ["y"] = 9, ["x"] = 3, ["name"] = "default:sand", ["z"] = 4, ["meta"] = { ["inventory"] = {  }, ["fields"] = {  } }, ["param2"] = 0, ["param1"] = 0 }, { ["y"] = 9, ["x"] = 3, ["name"] = "default:sand", ["z"] = 5, ["meta"] = { ["inventory"] = {  }, ["fields"] = {  } }, ["param2"] = 0, ["param1"] = 0 }, { ["y"] = 9, ["x"] = 3, ["name"] = "moreblocks:clean_glass", ["z"] = 6, ["meta"] = { ["inventory"] = {  }, ["fields"] = {  } }, ["param2"] = 0, ["param1"] = 12 }, { ["y"] = 9, ["x"] = 3, ["name"] = "columnia:column_mid_stonebrick", ["z"] = 7, ["meta"] = { ["inventory"] = {  }, ["fields"] = {  } }, ["param2"] = 22, ["param1"] = 12 }, { ["y"] = 9, ["x"] = 3, ["name"] = "columnia:column_mid_stonebrick", ["z"] = 20, ["meta"] = { ["inventory"] = {  }, ["fields"] = {  } }, ["param2"] = 21, ["param1"] = 12 }, { ["y"] = 10, ["x"] = 3, ["name"] = "default:sand", ["z"] = 4, ["meta"] = { ["inventory"] = {  }, ["fields"] = {  } }, ["param2"] = 0, ["param1"] = 0 }, { ["y"] = 10, ["x"] = 3, ["name"] = "default:sand", ["z"] = 5, ["meta"] = { ["inventory"] = {  }, ["fields"] = {  } }, ["param2"] = 0, ["param1"] = 0 }, { ["y"] = 10, ["x"] = 3, ["name"] = "moreblocks:clean_glass", ["z"] = 6, ["meta"] = { ["inventory"] = {  }, ["fields"] = {  } }, ["param2"] = 0, ["param1"] = 12 }, { ["y"] = 10, ["x"] = 3, ["name"] = "columnia:column_mid_stonebrick", ["z"] = 7, ["meta"] = { ["inventory"] = {  }, ["fields"] = {  } }, ["param2"] = 22, ["param1"] = 12 }, { ["y"] = 10, ["x"] = 3, ["name"] = "columnia:column_mid_stonebrick", ["z"] = 20, ["meta"] = { ["inventory"] = {  }, ["fields"] = {  } }, ["param2"] = 21, ["param1"] = 12 }, { ["y"] = 11, ["x"] = 3, ["name"] = "default:sand", ["z"] = 4, ["meta"] = { ["inventory"] = {  }, ["fields"] = {  } }, ["param2"] = 0, ["param1"] = 0 }, { ["y"] = 11, ["x"] = 3, ["name"] = "default:sand", ["z"] = 5, ["meta"] = { ["inventory"] = {  }, ["fields"] = {  } }, ["param2"] = 0, ["param1"] = 0 }, { ["y"] = 11, ["x"] = 3, ["name"] = "moreblocks:clean_glass", ["z"] = 6, ["meta"] = { ["inventory"] = {  }, ["fields"] = {  } }, ["param2"] = 0, ["param1"] = 12 }, { ["y"] = 11, ["x"] = 3, ["name"] = "columnia:column_mid_stonebrick", ["z"] = 7, ["meta"] = { ["inventory"] = {  }, ["fields"] = {  } }, ["param2"] = 22, ["param1"] = 12 }, { ["y"] = 11, ["x"] = 3, ["name"] = "columnia:column_mid_stonebrick", ["z"] = 20, ["meta"] = { ["inventory"] = {  }, ["fields"] = {  } }, ["param2"] = 21, ["param1"] = 12 }, { ["y"] = 12, ["x"] = 3, ["name"] = "default:sand", ["z"] = 4, ["meta"] = { ["inventory"] = {  }, ["fields"] = {  } }, ["param2"] = 0, ["param1"] = 0 }, { ["y"] = 12, ["x"] = 3, ["name"] = "default:sand", ["z"] = 5, ["meta"] = { ["inventory"] = {  }, ["fields"] = {  } }, ["param2"] = 0, ["param1"] = 0 }, { ["y"] = 12, ["x"] = 3, ["name"] = "moreblocks:clean_glass", ["z"] = 6, ["meta"] = { ["inventory"] = {  }, ["fields"] = {  } }, ["param2"] = 0, ["param1"] = 12 }, { ["y"] = 12, ["x"] = 3, ["name"] = "columnia:column_mid_stonebrick", ["z"] = 7, ["meta"] = { ["inventory"] = {  }, ["fields"] = {  } }, ["param2"] = 22, ["param1"] = 12 }, { ["y"] = 12, ["x"] = 3, ["name"] = "columnia:column_mid_stonebrick", ["z"] = 20, ["meta"] = { ["inventory"] = {  }, ["fields"] = {  } }, ["param2"] = 21, ["param1"] = 12 }, { ["y"] = 13, ["x"] = 3, ["name"] = "default:sand", ["z"] = 4, ["meta"] = { ["inventory"] = {  }, ["fields"] = {  } }, ["param2"] = 0, ["param1"] = 0 }, { ["y"] = 13, ["x"] = 3, ["name"] = "default:sand", ["z"] = 5, ["meta"] = { ["inventory"] = {  }, ["fields"] = {  } }, ["param2"] = 0, ["param1"] = 0 }, { ["y"] = 13, ["x"] = 3, ["name"] = "moreblocks:clean_glass", ["z"] = 6, ["meta"] = { ["inventory"] = {  }, ["fields"] = {  } }, ["param2"] = 0, ["param1"] = 12 }, { ["y"] = 13, ["x"] = 3, ["name"] = "columnia:column_mid_stonebrick", ["z"] = 7, ["meta"] = { ["inventory"] = {  }, ["fields"] = {  } }, ["param2"] = 22, ["param1"] = 12 }, { ["y"] = 13, ["x"] = 3, ["name"] = "columnia:column_mid_stonebrick", ["z"] = 20, ["meta"] = { ["inventory"] = {  }, ["fields"] = {  } }, ["param2"] = 21, ["param1"] = 12 }, { ["y"] = 14, ["x"] = 3, ["name"] = "default:sand", ["z"] = 4, ["meta"] = { ["inventory"] = {  }, ["fields"] = {  } }, ["param2"] = 0, ["param1"] = 0 }, { ["y"] = 14, ["x"] = 3, ["name"] = "default:sand", ["z"] = 5, ["meta"] = { ["inventory"] = {  }, ["fields"] = {  } }, ["param2"] = 0, ["param1"] = 0 }, { ["y"] = 14, ["x"] = 3, ["name"] = "moreblocks:clean_glass", ["z"] = 6, ["meta"] = { ["inventory"] = {  }, ["fields"] = {  } }, ["param2"] = 0, ["param1"] = 12 }, { ["y"] = 14, ["x"] = 3, ["name"] = "columnia:column_mid_stonebrick", ["z"] = 7, ["meta"] = { ["inventory"] = {  }, ["fields"] = {  } }, ["param2"] = 22, ["param1"] = 12 }, { ["y"] = 14, ["x"] = 3, ["name"] = "columnia:column_mid_stonebrick", ["z"] = 20, ["meta"] = { ["inventory"] = {  }, ["fields"] = {  } }, ["param2"] = 21, ["param1"] = 12 }, { ["y"] = 15, ["x"] = 3, ["name"] = "default:sand", ["z"] = 4, ["meta"] = { ["inventory"] = {  }, ["fields"] = {  } }, ["param2"] = 0, ["param1"] = 0 }, { ["y"] = 15, ["x"] = 3, ["name"] = "default:sand", ["z"] = 5, ["meta"] = { ["inventory"] = {  }, ["fields"] = {  } }, ["param2"] = 0, ["param1"] = 0 }, { ["y"] = 15, ["x"] = 3, ["name"] = "moreblocks:clean_glass", ["z"] = 6, ["meta"] = { ["inventory"] = {  }, ["fields"] = {  } }, ["param2"] = 0, ["param1"] = 12 }, { ["y"] = 15, ["x"] = 3, ["name"] = "columnia:column_mid_stonebrick", ["z"] = 7, ["meta"] = { ["inventory"] = {  }, ["fields"] = {  } }, ["param2"] = 22, ["param1"] = 12 }, { ["y"] = 15, ["x"] = 3, ["name"] = "columnia:column_mid_stonebrick", ["z"] = 20, ["meta"] = { ["inventory"] = {  }, ["fields"] = {  } }, ["param2"] = 21, ["param1"] = 12 }, { ["y"] = 16, ["x"] = 3, ["name"] = "default:sand", ["z"] = 4, ["meta"] = { ["inventory"] = {  }, ["fields"] = {  } }, ["param2"] = 0, ["param1"] = 0 }, { ["y"] = 16, ["x"] = 3, ["name"] = "default:sand", ["z"] = 5, ["meta"] = { ["inventory"] = {  }, ["fields"] = {  } }, ["param2"] = 0, ["param1"] = 0 }, { ["y"] = 16, ["x"] = 3, ["name"] = "moreblocks:clean_glass", ["z"] = 6, ["meta"] = { ["inventory"] = {  }, ["fields"] = {  } }, ["param2"] = 0, ["param1"] = 12 }, { ["y"] = 16, ["x"] = 3, ["name"] = "columnia:column_mid_stonebrick", ["z"] = 7, ["meta"] = { ["inventory"] = {  }, ["fields"] = {  } }, ["param2"] = 22, ["param1"] = 12 }, { ["y"] = 16, ["x"] = 3, ["name"] = "columnia:column_mid_stonebrick", ["z"] = 20, ["meta"] = { ["inventory"] = {  }, ["fields"] = {  } }, ["param2"] = 21, ["param1"] = 12 }, { ["y"] = 17, ["x"] = 3, ["name"] = "default:sand", ["z"] = 4, ["meta"] = { ["inventory"] = {  }, ["fields"] = {  } }, ["param2"] = 0, ["param1"] = 0 }, { ["y"] = 17, ["x"] = 3, ["name"] = "default:sand", ["z"] = 5, ["meta"] = { ["inventory"] = {  }, ["fields"] = {  } }, ["param2"] = 0, ["param1"] = 0 }, { ["y"] = 17, ["x"] = 3, ["name"] = "moreblocks:clean_glass", ["z"] = 6, ["meta"] = { ["inventory"] = {  }, ["fields"] = {  } }, ["param2"] = 0, ["param1"] = 12 }, { ["y"] = 17, ["x"] = 3, ["name"] = "columnia:column_mid_stonebrick", ["z"] = 7, ["meta"] = { ["inventory"] = {  }, ["fields"] = {  } }, ["param2"] = 22, ["param1"] = 12 }, { ["y"] = 17, ["x"] = 3, ["name"] = "columnia:column_mid_stonebrick", ["z"] = 20, ["meta"] = { ["inventory"] = {  }, ["fields"] = {  } }, ["param2"] = 21, ["param1"] = 12 }, { ["y"] = 18, ["x"] = 3, ["name"] = "default:sand", ["z"] = 4, ["meta"] = { ["inventory"] = {  }, ["fields"] = {  } }, ["param2"] = 0, ["param1"] = 0 }, { ["y"] = 18, ["x"] = 3, ["name"] = "default:sand", ["z"] = 5, ["meta"] = { ["inventory"] = {  }, ["fields"] = {  } }, ["param2"] = 0, ["param1"] = 0 }, { ["y"] = 18, ["x"] = 3, ["name"] = "moreblocks:clean_glass", ["z"] = 6, ["meta"] = { ["inventory"] = {  }, ["fields"] = {  } }, ["param2"] = 0, ["param1"] = 12 }, { ["y"] = 18, ["x"] = 3, ["name"] = "columnia:column_mid_stonebrick", ["z"] = 7, ["meta"] = { ["inventory"] = {  }, ["fields"] = {  } }, ["param2"] = 22, ["param1"] = 12 }, { ["y"] = 18, ["x"] = 3, ["name"] = "columnia:column_mid_stonebrick", ["z"] = 20, ["meta"] = { ["inventory"] = {  }, ["fields"] = {  } }, ["param2"] = 20, ["param1"] = 12 }, { ["y"] = 19, ["x"] = 3, ["name"] = "default:sand", ["z"] = 4, ["meta"] = { ["inventory"] = {  }, ["fields"] = {  } }, ["param2"] = 0, ["param1"] = 0 }, { ["y"] = 19, ["x"] = 3, ["name"] = "default:sand", ["z"] = 5, ["meta"] = { ["inventory"] = {  }, ["fields"] = {  } }, ["param2"] = 0, ["param1"] = 0 }, { ["y"] = 19, ["x"] = 3, ["name"] = "moreblocks:clean_glass", ["z"] = 6, ["meta"] = { ["inventory"] = {  }, ["fields"] = {  } }, ["param2"] = 0, ["param1"] = 12 }, { ["y"] = 19, ["x"] = 3, ["name"] = "columnia:column_mid_stonebrick", ["z"] = 7, ["meta"] = { ["inventory"] = {  }, ["fields"] = {  } }, ["param2"] = 22, ["param1"] = 12 }, { ["y"] = 19, ["x"] = 3, ["name"] = "columnia:column_mid_stonebrick", ["z"] = 20, ["meta"] = { ["inventory"] = {  }, ["fields"] = {  } }, ["param2"] = 20, ["param1"] = 12 }, { ["y"] = 20, ["x"] = 3, ["name"] = "default:sand", ["z"] = 4, ["meta"] = { ["inventory"] = {  }, ["fields"] = {  } }, ["param2"] = 0, ["param1"] = 0 }, { ["y"] = 20, ["x"] = 3, ["name"] = "default:sand", ["z"] = 5, ["meta"] = { ["inventory"] = {  }, ["fields"] = {  } }, ["param2"] = 0, ["param1"] = 0 }, { ["y"] = 20, ["x"] = 3, ["name"] = "moreblocks:clean_glass", ["z"] = 6, ["meta"] = { ["inventory"] = {  }, ["fields"] = {  } }, ["param2"] = 0, ["param1"] = 12 }, { ["y"] = 20, ["x"] = 3, ["name"] = "columnia:column_mid_stonebrick", ["z"] = 7, ["meta"] = { ["inventory"] = {  }, ["fields"] = {  } }, ["param2"] = 22, ["param1"] = 12 }, { ["y"] = 20, ["x"] = 3, ["name"] = "columnia:column_mid_stonebrick", ["z"] = 20, ["meta"] = { ["inventory"] = {  }, ["fields"] = {  } }, ["param2"] = 20, ["param1"] = 12 }, { ["y"] = 21, ["x"] = 3, ["name"] = "default:sand", ["z"] = 4, ["meta"] = { ["inventory"] = {  }, ["fields"] = {  } }, ["param2"] = 0, ["param1"] = 0 }, { ["y"] = 21, ["x"] = 3, ["name"] = "default:sand", ["z"] = 5, ["meta"] = { ["inventory"] = {  }, ["fields"] = {  } }, ["param2"] = 0, ["param1"] = 0 }, { ["y"] = 21, ["x"] = 3, ["name"] = "moreblocks:clean_glass", ["z"] = 6, ["meta"] = { ["inventory"] = {  }, ["fields"] = {  } }, ["param2"] = 0, ["param1"] = 12 }, { ["y"] = 21, ["x"] = 3, ["name"] = "columnia:column_mid_stonebrick", ["z"] = 7, ["meta"] = { ["inventory"] = {  }, ["fields"] = {  } }, ["param2"] = 22, ["param1"] = 12 }, { ["y"] = 21, ["x"] = 3, ["name"] = "columnia:column_mid_stonebrick", ["z"] = 20, ["meta"] = { ["inventory"] = {  }, ["fields"] = {  } }, ["param2"] = 20, ["param1"] = 12 }, { ["y"] = 22, ["x"] = 3, ["name"] = "default:sand", ["z"] = 4, ["meta"] = { ["inventory"] = {  }, ["fields"] = {  } }, ["param2"] = 0, ["param1"] = 0 }, { ["y"] = 22, ["x"] = 3, ["name"] = "default:sand", ["z"] = 5, ["meta"] = { ["inventory"] = {  }, ["fields"] = {  } }, ["param2"] = 0, ["param1"] = 0 }, { ["y"] = 22, ["x"] = 3, ["name"] = "moreblocks:clean_glass", ["z"] = 6, ["meta"] = { ["inventory"] = {  }, ["fields"] = {  } }, ["param2"] = 0, ["param1"] = 12 }, { ["y"] = 22, ["x"] = 3, ["name"] = "columnia:column_mid_stonebrick", ["z"] = 7, ["meta"] = { ["inventory"] = {  }, ["fields"] = {  } }, ["param2"] = 22, ["param1"] = 12 }, { ["y"] = 22, ["x"] = 3, ["name"] = "columnia:column_mid_stonebrick", ["z"] = 20, ["meta"] = { ["inventory"] = {  }, ["fields"] = {  } }, ["param2"] = 20, ["param1"] = 12 }, { ["y"] = 23, ["x"] = 3, ["name"] = "default:sand", ["z"] = 4, ["meta"] = { ["inventory"] = {  }, ["fields"] = {  } }, ["param2"] = 0, ["param1"] = 0 }, { ["y"] = 23, ["x"] = 3, ["name"] = "default:sand", ["z"] = 5, ["meta"] = { ["inventory"] = {  }, ["fields"] = {  } }, ["param2"] = 0, ["param1"] = 0 }, { ["y"] = 23, ["x"] = 3, ["name"] = "moreblocks:clean_glass", ["z"] = 6, ["meta"] = { ["inventory"] = {  }, ["fields"] = {  } }, ["param2"] = 0, ["param1"] = 12 }, { ["y"] = 23, ["x"] = 3, ["name"] = "columnia:column_mid_stonebrick", ["z"] = 7, ["meta"] = { ["inventory"] = {  }, ["fields"] = {  } }, ["param2"] = 22, ["param1"] = 12 }, { ["y"] = 23, ["x"] = 3, ["name"] = "columnia:column_mid_stonebrick", ["z"] = 20, ["meta"] = { ["inventory"] = {  }, ["fields"] = {  } }, ["param2"] = 20, ["param1"] = 12 }, { ["y"] = 24, ["x"] = 3, ["name"] = "default:sand", ["z"] = 4, ["meta"] = { ["inventory"] = {  }, ["fields"] = {  } }, ["param2"] = 0, ["param1"] = 0 }, { ["y"] = 24, ["x"] = 3, ["name"] = "default:sand", ["z"] = 5, ["meta"] = { ["inventory"] = {  }, ["fields"] = {  } }, ["param2"] = 0, ["param1"] = 0 }, { ["y"] = 24, ["x"] = 3, ["name"] = "moreblocks:clean_glass", ["z"] = 6, ["meta"] = { ["inventory"] = {  }, ["fields"] = {  } }, ["param2"] = 0, ["param1"] = 12 }, { ["y"] = 24, ["x"] = 3, ["name"] = "columnia:column_mid_stonebrick", ["z"] = 7, ["meta"] = { ["inventory"] = {  }, ["fields"] = {  } }, ["param2"] = 22, ["param1"] = 12 }, { ["y"] = 24, ["x"] = 3, ["name"] = "columnia:column_mid_stonebrick", ["z"] = 20, ["meta"] = { ["inventory"] = {  }, ["fields"] = {  } }, ["param2"] = 20, ["param1"] = 12 }, { ["y"] = 25, ["x"] = 3, ["name"] = "default:sand", ["z"] = 4, ["meta"] = { ["inventory"] = {  }, ["fields"] = {  } }, ["param2"] = 0, ["param1"] = 0 }, { ["y"] = 25, ["x"] = 3, ["name"] = "default:sand", ["z"] = 5, ["meta"] = { ["inventory"] = {  }, ["fields"] = {  } }, ["param2"] = 0, ["param1"] = 0 }, { ["y"] = 25, ["x"] = 3, ["name"] = "moreblocks:clean_glass", ["z"] = 6, ["meta"] = { ["inventory"] = {  }, ["fields"] = {  } }, ["param2"] = 0, ["param1"] = 12 }, { ["y"] = 25, ["x"] = 3, ["name"] = "columnia:column_mid_stonebrick", ["z"] = 7, ["meta"] = { ["inventory"] = {  }, ["fields"] = {  } }, ["param2"] = 22, ["param1"] = 12 }, { ["y"] = 25, ["x"] = 3, ["name"] = "columnia:column_mid_stonebrick", ["z"] = 20, ["meta"] = { ["inventory"] = {  }, ["fields"] = {  } }, ["param2"] = 20, ["param1"] = 12 }, { ["y"] = 26, ["x"] = 3, ["name"] = "default:sand", ["z"] = 4, ["meta"] = { ["inventory"] = {  }, ["fields"] = {  } }, ["param2"] = 0, ["param1"] = 0 }, { ["y"] = 26, ["x"] = 3, ["name"] = "default:sand", ["z"] = 5, ["meta"] = { ["inventory"] = {  }, ["fields"] = {  } }, ["param2"] = 0, ["param1"] = 0 }, { ["y"] = 26, ["x"] = 3, ["name"] = "moreblocks:clean_glass", ["z"] = 6, ["meta"] = { ["inventory"] = {  }, ["fields"] = {  } }, ["param2"] = 0, ["param1"] = 12 }, { ["y"] = 26, ["x"] = 3, ["name"] = "columnia:column_mid_stonebrick", ["z"] = 7, ["meta"] = { ["inventory"] = {  }, ["fields"] = {  } }, ["param2"] = 22, ["param1"] = 12 }, { ["y"] = 26, ["x"] = 3, ["name"] = "columnia:column_mid_stonebrick", ["z"] = 20, ["meta"] = { ["inventory"] = {  }, ["fields"] = {  } }, ["param2"] = 20, ["param1"] = 12 }, { ["y"] = 27, ["x"] = 3, ["name"] = "default:sand", ["z"] = 4, ["meta"] = { ["inventory"] = {  }, ["fields"] = {  } }, ["param2"] = 0, ["param1"] = 0 }, { ["y"] = 27, ["x"] = 3, ["name"] = "default:sand", ["z"] = 5, ["meta"] = { ["inventory"] = {  }, ["fields"] = {  } }, ["param2"] = 0, ["param1"] = 0 }, { ["y"] = 27, ["x"] = 3, ["name"] = "moreblocks:clean_glass", ["z"] = 6, ["meta"] = { ["inventory"] = {  }, ["fields"] = {  } }, ["param2"] = 0, ["param1"] = 12 }, { ["y"] = 27, ["x"] = 3, ["name"] = "columnia:column_mid_stonebrick", ["z"] = 7, ["meta"] = { ["inventory"] = {  }, ["fields"] = {  } }, ["param2"] = 22, ["param1"] = 12 }, { ["y"] = 27, ["x"] = 3, ["name"] = "columnia:column_mid_stonebrick", ["z"] = 20, ["meta"] = { ["inventory"] = {  }, ["fields"] = {  } }, ["param2"] = 20, ["param1"] = 12 }, { ["y"] = 28, ["x"] = 3, ["name"] = "default:sand", ["z"] = 4, ["meta"] = { ["inventory"] = {  }, ["fields"] = {  } }, ["param2"] = 0, ["param1"] = 0 }, { ["y"] = 28, ["x"] = 3, ["name"] = "default:sand", ["z"] = 5, ["meta"] = { ["inventory"] = {  }, ["fields"] = {  } }, ["param2"] = 0, ["param1"] = 0 }, { ["y"] = 28, ["x"] = 3, ["name"] = "moreblocks:clean_glass", ["z"] = 6, ["meta"] = { ["inventory"] = {  }, ["fields"] = {  } }, ["param2"] = 0, ["param1"] = 28 }, { ["y"] = 28, ["x"] = 3, ["name"] = "columnia:column_crosslink_stonebrick", ["z"] = 7, ["meta"] = { ["inventory"] = {  }, ["fields"] = {  } }, ["param2"] = 0, ["param1"] = 12 }, { ["y"] = 28, ["x"] = 3, ["name"] = "columnia:column_crosslink_stonebrick", ["z"] = 20, ["meta"] = { ["inventory"] = {  }, ["fields"] = {  } }, ["param2"] = 0, ["param1"] = 12 }, { ["y"] = 29, ["x"] = 3, ["name"] = "default:sand", ["z"] = 4, ["meta"] = { ["inventory"] = {  }, ["fields"] = {  } }, ["param2"] = 0, ["param1"] = 0 }, { ["y"] = 29, ["x"] = 3, ["name"] = "default:sand", ["z"] = 5, ["meta"] = { ["inventory"] = {  }, ["fields"] = {  } }, ["param2"] = 0, ["param1"] = 0 }, { ["y"] = 29, ["x"] = 3, ["name"] = "moreblocks:clean_glass", ["z"] = 6, ["meta"] = { ["inventory"] = {  }, ["fields"] = {  } }, ["param2"] = 0, ["param1"] = 44 }, { ["y"] = 29, ["x"] = 3, ["name"] = "default:cobble", ["z"] = 7, ["meta"] = { ["inventory"] = {  }, ["fields"] = {  } }, ["param2"] = 0, ["param1"] = 0 }, { ["y"] = 29, ["x"] = 3, ["name"] = "default:cobble", ["z"] = 8, ["meta"] = { ["inventory"] = {  }, ["fields"] = {  } }, ["param2"] = 0, ["param1"] = 0 }, { ["y"] = 29, ["x"] = 3, ["name"] = "default:cobble", ["z"] = 9, ["meta"] = { ["inventory"] = {  }, ["fields"] = {  } }, ["param2"] = 0, ["param1"] = 0 }, { ["y"] = 29, ["x"] = 3, ["name"] = "default:cobble", ["z"] = 10, ["meta"] = { ["inventory"] = {  }, ["fields"] = {  } }, ["param2"] = 0, ["param1"] = 0 }, { ["y"] = 29, ["x"] = 3, ["name"] = "default:cobble", ["z"] = 11, ["meta"] = { ["inventory"] = {  }, ["fields"] = {  } }, ["param2"] = 0, ["param1"] = 0 }, { ["y"] = 29, ["x"] = 3, ["name"] = "default:cobble", ["z"] = 12, ["meta"] = { ["inventory"] = {  }, ["fields"] = {  } }, ["param2"] = 0, ["param1"] = 0 }, { ["y"] = 29, ["x"] = 3, ["name"] = "default:cobble", ["z"] = 13, ["meta"] = { ["inventory"] = {  }, ["fields"] = {  } }, ["param2"] = 0, ["param1"] = 0 }, { ["y"] = 29, ["x"] = 3, ["name"] = "default:cobble", ["z"] = 14, ["meta"] = { ["inventory"] = {  }, ["fields"] = {  } }, ["param2"] = 0, ["param1"] = 0 }, { ["y"] = 29, ["x"] = 3, ["name"] = "default:cobble", ["z"] = 15, ["meta"] = { ["inventory"] = {  }, ["fields"] = {  } }, ["param2"] = 0, ["param1"] = 0 }, { ["y"] = 29, ["x"] = 3, ["name"] = "default:cobble", ["z"] = 16, ["meta"] = { ["inventory"] = {  }, ["fields"] = {  } }, ["param2"] = 0, ["param1"] = 0 }, { ["y"] = 29, ["x"] = 3, ["name"] = "default:cobble", ["z"] = 17, ["meta"] = { ["inventory"] = {  }, ["fields"] = {  } }, ["param2"] = 0, ["param1"] = 0 }, { ["y"] = 29, ["x"] = 3, ["name"] = "default:cobble", ["z"] = 18, ["meta"] = { ["inventory"] = {  }, ["fields"] = {  } }, ["param2"] = 0, ["param1"] = 0 }, { ["y"] = 29, ["x"] = 3, ["name"] = "default:cobble", ["z"] = 19, ["meta"] = { ["inventory"] = {  }, ["fields"] = {  } }, ["param2"] = 0, ["param1"] = 0 }, { ["y"] = 29, ["x"] = 3, ["name"] = "default:cobble", ["z"] = 20, ["meta"] = { ["inventory"] = {  }, ["fields"] = {  } }, ["param2"] = 0, ["param1"] = 0 }, { ["y"] = 30, ["x"] = 3, ["name"] = "default:cobble", ["z"] = 3, ["meta"] = { ["inventory"] = {  }, ["fields"] = {  } }, ["param2"] = 0, ["param1"] = 0 }, { ["y"] = 30, ["x"] = 3, ["name"] = "default:cobble", ["z"] = 4, ["meta"] = { ["inventory"] = {  }, ["fields"] = {  } }, ["param2"] = 0, ["param1"] = 0 }, { ["y"] = 30, ["x"] = 3, ["name"] = "default:cobble", ["z"] = 5, ["meta"] = { ["inventory"] = {  }, ["fields"] = {  } }, ["param2"] = 0, ["param1"] = 0 }, { ["y"] = 30, ["x"] = 3, ["name"] = "default:cobble", ["z"] = 6, ["meta"] = { ["inventory"] = {  }, ["fields"] = {  } }, ["param2"] = 0, ["param1"] = 0 }, { ["y"] = 30, ["x"] = 3, ["name"] = "default:cobble", ["z"] = 7, ["meta"] = { ["inventory"] = {  }, ["fields"] = {  } }, ["param2"] = 0, ["param1"] = 0 }, { ["y"] = 30, ["x"] = 3, ["name"] = "default:cobble", ["z"] = 8, ["meta"] = { ["inventory"] = {  }, ["fields"] = {  } }, ["param2"] = 0, ["param1"] = 0 }, { ["y"] = 30, ["x"] = 3, ["name"] = "default:cobble", ["z"] = 9, ["meta"] = { ["inventory"] = {  }, ["fields"] = {  } }, ["param2"] = 0, ["param1"] = 0 }, { ["y"] = 30, ["x"] = 3, ["name"] = "default:cobble", ["z"] = 10, ["meta"] = { ["inventory"] = {  }, ["fields"] = {  } }, ["param2"] = 0, ["param1"] = 0 }, { ["y"] = 30, ["x"] = 3, ["name"] = "default:cobble", ["z"] = 11, ["meta"] = { ["inventory"] = {  }, ["fields"] = {  } }, ["param2"] = 0, ["param1"] = 0 }, { ["y"] = 30, ["x"] = 3, ["name"] = "default:cobble", ["z"] = 12, ["meta"] = { ["inventory"] = {  }, ["fields"] = {  } }, ["param2"] = 0, ["param1"] = 0 }, { ["y"] = 30, ["x"] = 3, ["name"] = "default:cobble", ["z"] = 13, ["meta"] = { ["inventory"] = {  }, ["fields"] = {  } }, ["param2"] = 0, ["param1"] = 0 }, { ["y"] = 30, ["x"] = 3, ["name"] = "default:cobble", ["z"] = 14, ["meta"] = { ["inventory"] = {  }, ["fields"] = {  } }, ["param2"] = 0, ["param1"] = 0 }, { ["y"] = 30, ["x"] = 3, ["name"] = "default:cobble", ["z"] = 15, ["meta"] = { ["inventory"] = {  }, ["fields"] = {  } }, ["param2"] = 0, ["param1"] = 0 }, { ["y"] = 30, ["x"] = 3, ["name"] = "default:cobble", ["z"] = 16, ["meta"] = { ["inventory"] = {  }, ["fields"] = {  } }, ["param2"] = 0, ["param1"] = 0 }, { ["y"] = 30, ["x"] = 3, ["name"] = "default:cobble", ["z"] = 17, ["meta"] = { ["inventory"] = {  }, ["fields"] = {  } }, ["param2"] = 0, ["param1"] = 0 }, { ["y"] = 30, ["x"] = 3, ["name"] = "default:cobble", ["z"] = 18, ["meta"] = { ["inventory"] = {  }, ["fields"] = {  } }, ["param2"] = 0, ["param1"] = 0 }, { ["y"] = 30, ["x"] = 3, ["name"] = "default:cobble", ["z"] = 19, ["meta"] = { ["inventory"] = {  }, ["fields"] = {  } }, ["param2"] = 0, ["param1"] = 0 }, { ["y"] = 30, ["x"] = 3, ["name"] = "default:cobble", ["z"] = 20, ["meta"] = { ["inventory"] = {  }, ["fields"] = {  } }, ["param2"] = 0, ["param1"] = 0 }, { ["y"] = 31, ["x"] = 3, ["name"] = "default:cobble", ["z"] = 2, ["meta"] = { ["inventory"] = {  }, ["fields"] = {  } }, ["param2"] = 0, ["param1"] = 0 }, { ["y"] = 31, ["x"] = 3, ["name"] = "default:cobble", ["z"] = 3, ["meta"] = { ["inventory"] = {  }, ["fields"] = {  } }, ["param2"] = 0, ["param1"] = 0 }, { ["y"] = 31, ["x"] = 3, ["name"] = "default:cobble", ["z"] = 4, ["meta"] = { ["inventory"] = {  }, ["fields"] = {  } }, ["param2"] = 0, ["param1"] = 0 }, { ["y"] = 31, ["x"] = 3, ["name"] = "default:cobble", ["z"] = 5, ["meta"] = { ["inventory"] = {  }, ["fields"] = {  } }, ["param2"] = 0, ["param1"] = 0 }, { ["y"] = 31, ["x"] = 3, ["name"] = "default:cobble", ["z"] = 6, ["meta"] = { ["inventory"] = {  }, ["fields"] = {  } }, ["param2"] = 0, ["param1"] = 0 }, { ["y"] = 31, ["x"] = 3, ["name"] = "default:cobble", ["z"] = 7, ["meta"] = { ["inventory"] = {  }, ["fields"] = {  } }, ["param2"] = 0, ["param1"] = 0 }, { ["y"] = 31, ["x"] = 3, ["name"] = "default:cobble", ["z"] = 8, ["meta"] = { ["inventory"] = {  }, ["fields"] = {  } }, ["param2"] = 0, ["param1"] = 0 }, { ["y"] = 31, ["x"] = 3, ["name"] = "default:cobble", ["z"] = 9, ["meta"] = { ["inventory"] = {  }, ["fields"] = {  } }, ["param2"] = 0, ["param1"] = 0 }, { ["y"] = 31, ["x"] = 3, ["name"] = "default:cobble", ["z"] = 10, ["meta"] = { ["inventory"] = {  }, ["fields"] = {  } }, ["param2"] = 0, ["param1"] = 0 }, { ["y"] = 31, ["x"] = 3, ["name"] = "default:cobble", ["z"] = 11, ["meta"] = { ["inventory"] = {  }, ["fields"] = {  } }, ["param2"] = 0, ["param1"] = 0 }, { ["y"] = 31, ["x"] = 3, ["name"] = "default:cobble", ["z"] = 12, ["meta"] = { ["inventory"] = {  }, ["fields"] = {  } }, ["param2"] = 0, ["param1"] = 0 }, { ["y"] = 31, ["x"] = 3, ["name"] = "default:cobble", ["z"] = 13, ["meta"] = { ["inventory"] = {  }, ["fields"] = {  } }, ["param2"] = 0, ["param1"] = 0 }, { ["y"] = 31, ["x"] = 3, ["name"] = "default:cobble", ["z"] = 14, ["meta"] = { ["inventory"] = {  }, ["fields"] = {  } }, ["param2"] = 0, ["param1"] = 0 }, { ["y"] = 31, ["x"] = 3, ["name"] = "default:cobble", ["z"] = 15, ["meta"] = { ["inventory"] = {  }, ["fields"] = {  } }, ["param2"] = 0, ["param1"] = 0 }, { ["y"] = 31, ["x"] = 3, ["name"] = "default:cobble", ["z"] = 16, ["meta"] = { ["inventory"] = {  }, ["fields"] = {  } }, ["param2"] = 0, ["param1"] = 0 }, { ["y"] = 31, ["x"] = 3, ["name"] = "default:cobble", ["z"] = 17, ["meta"] = { ["inventory"] = {  }, ["fields"] = {  } }, ["param2"] = 0, ["param1"] = 0 }, { ["y"] = 31, ["x"] = 3, ["name"] = "default:cobble", ["z"] = 18, ["meta"] = { ["inventory"] = {  }, ["fields"] = {  } }, ["param2"] = 0, ["param1"] = 0 }, { ["y"] = 31, ["x"] = 3, ["name"] = "default:cobble", ["z"] = 19, ["meta"] = { ["inventory"] = {  }, ["fields"] = {  } }, ["param2"] = 0, ["param1"] = 0 }, { ["y"] = 31, ["x"] = 3, ["name"] = "default:cobble", ["z"] = 20, ["meta"] = { ["inventory"] = {  }, ["fields"] = {  } }, ["param2"] = 0, ["param1"] = 0 }, { ["y"] = 31, ["x"] = 3, ["name"] = "default:cobble", ["z"] = 21, ["meta"] = { ["inventory"] = {  }, ["fields"] = {  } }, ["param2"] = 0, ["param1"] = 0 }, { ["y"] = 32, ["x"] = 3, ["name"] = "default:cobble", ["z"] = 2, ["meta"] = { ["inventory"] = {  }, ["fields"] = {  } }, ["param2"] = 0, ["param1"] = 0 }, { ["y"] = 32, ["x"] = 3, ["name"] = "default:cobble", ["z"] = 3, ["meta"] = { ["inventory"] = {  }, ["fields"] = {  } }, ["param2"] = 0, ["param1"] = 0 }, { ["y"] = 32, ["x"] = 3, ["name"] = "default:cobble", ["z"] = 4, ["meta"] = { ["inventory"] = {  }, ["fields"] = {  } }, ["param2"] = 0, ["param1"] = 0 }, { ["y"] = 32, ["x"] = 3, ["name"] = "default:cobble", ["z"] = 5, ["meta"] = { ["inventory"] = {  }, ["fields"] = {  } }, ["param2"] = 0, ["param1"] = 0 }, { ["y"] = 32, ["x"] = 3, ["name"] = "default:cobble", ["z"] = 6, ["meta"] = { ["inventory"] = {  }, ["fields"] = {  } }, ["param2"] = 0, ["param1"] = 0 }, { ["y"] = 32, ["x"] = 3, ["name"] = "default:cobble", ["z"] = 7, ["meta"] = { ["inventory"] = {  }, ["fields"] = {  } }, ["param2"] = 0, ["param1"] = 0 }, { ["y"] = 32, ["x"] = 3, ["name"] = "default:sand", ["z"] = 8, ["meta"] = { ["inventory"] = {  }, ["fields"] = {  } },