return { { ["y"] = 0, ["x"] = 0, ["name"] = "default:water_source", ["z"] = 0, ["meta"] = { ["inventory"] = {  }, ["fields"] = {  } }, ["param2"] = 0, ["param1"] = 12 }, { ["y"] = 0, ["x"] = 0, ["name"] = "default:water_source", ["z"] = 1, ["meta"] = { ["inventory"] = {  }, ["fields"] = {  } }, ["param2"] = 0, ["param1"] = 12 }, { ["y"] = 0, ["x"] = 0, ["name"] = "default:water_source", ["z"] = 2, ["meta"] = { ["inventory"] = {  }, ["fields"] = {  } }, ["param2"] = 0, ["param1"] = 12 }, { ["y"] = 0, ["x"] = 0, ["name"] = "default:water_source", ["z"] = 3, ["meta"] = { ["inventory"] = {  }, ["fields"] = {  } }, ["param2"] = 0, ["param1"] = 11 }, { ["y"] = 0, ["x"] = 0, ["name"] = "default:water_source", ["z"] = 4, ["meta"] = { ["inventory"] = {  }, ["fields"] = {  } }, ["param2"] = 0, ["param1"] = 28 }, { ["y"] = 0, ["x"] = 0, ["name"] = "default:sand", ["z"] = 5, ["meta"] = { ["inventory"] = {  }, ["fields"] = {  } }, ["param2"] = 0, ["param1"] = 0 }, { ["y"] = 0, ["x"] = 0, ["name"] = "default:sand", ["z"] = 6, ["meta"] = { ["inventory"] = {  }, ["fields"] = {  } }, ["param2"] = 0, ["param1"] = 0 }, { ["y"] = 0, ["x"] = 0, ["name"] = "default:sand", ["z"] = 7, ["meta"] = { ["inventory"] = {  }, ["fields"] = {  } }, ["param2"] = 0, ["param1"] = 0 }, { ["y"] = 0, ["x"] = 0, ["name"] = "default:sand", ["z"] = 8, ["meta"] = { ["inventory"] = {  }, ["fields"] = {  } }, ["param2"] = 0, ["param1"] = 0 }, { ["y"] = 0, ["x"] = 0, ["name"] = "default:sand", ["z"] = 9, ["meta"] = { ["inventory"] = {  }, ["fields"] = {  } }, ["param2"] = 0, ["param1"] = 0 }, { ["y"] = 0, ["x"] = 0, ["name"] = "default:sand", ["z"] = 10, ["meta"] = { ["inventory"] = {  }, ["fields"] = {  } }, ["param2"] = 0, ["param1"] = 0 }, { ["y"] = 0, ["x"] = 0, ["name"] = "default:sand", ["z"] = 11, ["meta"] = { ["inventory"] = {  }, ["fields"] = {  } }, ["param2"] = 0, ["param1"] = 0 }, { ["y"] = 0, ["x"] = 0, ["name"] = "default:sand", ["z"] = 12, ["meta"] = { ["inventory"] = {  }, ["fields"] = {  } }, ["param2"] = 0, ["param1"] = 0 }, { ["y"] = 0, ["x"] = 0, ["name"] = "default:sand", ["z"] = 13, ["meta"] = { ["inventory"] = {  }, ["fields"] = {  } }, ["param2"] = 0, ["param1"] = 0 }, { ["y"] = 0, ["x"] = 0, ["name"] = "default:sand", ["z"] = 14, ["meta"] = { ["inventory"] = {  }, ["fields"] = {  } }, ["param2"] = 0, ["param1"] = 0 }, { ["y"] = 0, ["x"] = 0, ["name"] = "default:sand", ["z"] = 15, ["meta"] = { ["inventory"] = {  }, ["fields"] = {  } }, ["param2"] = 0, ["param1"] = 0 }, { ["y"] = 0, ["x"] = 0, ["name"] = "default:sand", ["z"] = 16, ["meta"] = { ["inventory"] = {  }, ["fields"] = {  } }, ["param2"] = 0, ["param1"] = 0 }, { ["y"] = 0, ["x"] = 0, ["name"] = "default:water_source", ["z"] = 17, ["meta"] = { ["inventory"] = {  }, ["fields"] = {  } }, ["param2"] = 0, ["param1"] = 12 }, { ["y"] = 0, ["x"] = 0, ["name"] = "default:water_source", ["z"] = 18, ["meta"] = { ["inventory"] = {  }, ["fields"] = {  } }, ["param2"] = 0, ["param1"] = 12 }, { ["y"] = 0, ["x"] = 0, ["name"] = "default:water_source", ["z"] = 19, ["meta"] = { ["inventory"] = {  }, ["fields"] = {  } }, ["param2"] = 0, ["param1"] = 11 }, { ["y"] = 1, ["x"] = 0, ["name"] = "default:water_source", ["z"] = 0, ["meta"] = { ["inventory"] = {  }, ["fields"] = {  } }, ["param2"] = 0, ["param1"] = 13 }, { ["y"] = 1, ["x"] = 0, ["name"] = "default:water_source", ["z"] = 1, ["meta"] = { ["inventory"] = {  }, ["fields"] = {  } }, ["param2"] = 0, ["param1"] = 13 }, { ["y"] = 1, ["x"] = 0, ["name"] = "default:water_source", ["z"] = 2, ["meta"] = { ["inventory"] = {  }, ["fields"] = {  } }, ["param2"] = 0, ["param1"] = 13 }, { ["y"] = 1, ["x"] = 0, ["name"] = "default:water_source", ["z"] = 3, ["meta"] = { ["inventory"] = {  }, ["fields"] = {  } }, ["param2"] = 0, ["param1"] = 28 }, { ["y"] = 1, ["x"] = 0, ["name"] = "default:water_source", ["z"] = 4, ["meta"] = { ["inventory"] = {  }, ["fields"] = {  } }, ["param2"] = 0, ["param1"] = 45 }, { ["y"] = 1, ["x"] = 0, ["name"] = "default:water_source", ["z"] = 5, ["meta"] = { ["inventory"] = {  }, ["fields"] = {  } }, ["param2"] = 0, ["param1"] = 61 }, { ["y"] = 1, ["x"] = 0, ["name"] = "default:water_source", ["z"] = 6, ["meta"] = { ["inventory"] = {  }, ["fields"] = {  } }, ["param2"] = 0, ["param1"] = 77 }, { ["y"] = 1, ["x"] = 0, ["name"] = "default:sand", ["z"] = 7, ["meta"] = { ["inventory"] = {  }, ["fields"] = {  } }, ["param2"] = 0, ["param1"] = 0 }, { ["y"] = 1, ["x"] = 0, ["name"] = "default:sand", ["z"] = 8, ["meta"] = { ["inventory"] = {  }, ["fields"] = {  } }, ["param2"] = 0, ["param1"] = 0 }, { ["y"] = 1, ["x"] = 0, ["name"] = "default:sand", ["z"] = 9, ["meta"] = { ["inventory"] = {  }, ["fields"] = {  } }, ["param2"] = 0, ["param1"] = 0 }, { ["y"] = 1, ["x"] = 0, ["name"] = "default:sand", ["z"] = 10, ["meta"] = { ["inventory"] = {  }, ["fields"] = {  } }, ["param2"] = 0, ["param1"] = 0 }, { ["y"] = 1, ["x"] = 0, ["name"] = "default:sand", ["z"] = 11, ["meta"] = { ["inventory"] = {  }, ["fields"] = {  } }, ["param2"] = 0, ["param1"] = 0 }, { ["y"] = 1, ["x"] = 0, ["name"] = "default:sand", ["z"] = 12, ["meta"] = { ["inventory"] = {  }, ["fields"] = {  } }, ["param2"] = 0, ["param1"] = 0 }, { ["y"] = 1, ["x"] = 0, ["name"] = "default:sand", ["z"] = 13, ["meta"] = { ["inventory"] = {  }, ["fields"] = {  } }, ["param2"] = 0, ["param1"] = 0 }, { ["y"] = 1, ["x"] = 0, ["name"] = "default:water_source", ["z"] = 14, ["meta"] = { ["inventory"] = {  }, ["fields"] = {  } }, ["param2"] = 0, ["param1"] = 13 }, { ["y"] = 1, ["x"] = 0, ["name"] = "default:water_source", ["z"] = 15, ["meta"] = { ["inventory"] = {  }, ["fields"] = {  } }, ["param2"] = 0, ["param1"] = 13 }, { ["y"] = 1, ["x"] = 0, ["name"] = "default:water_source", ["z"] = 16, ["meta"] = { ["inventory"] = {  }, ["fields"] = {  } }, ["param2"] = 0, ["param1"] = 13 }, { ["y"] = 1, ["x"] = 0, ["name"] = "default:water_source", ["z"] = 17, ["meta"] = { ["inventory"] = {  }, ["fields"] = {  } }, ["param2"] = 0, ["param1"] = 13 }, { ["y"] = 1, ["x"] = 0, ["name"] = "default:water_source", ["z"] = 18, ["meta"] = { ["inventory"] = {  }, ["fields"] = {  } }, ["param2"] = 0, ["param1"] = 13 }, { ["y"] = 1, ["x"] = 0, ["name"] = "default:water_source", ["z"] = 19, ["meta"] = { ["inventory"] = {  }, ["fields"] = {  } }, ["param2"] = 0, ["param1"] = 12 }, { ["y"] = 6, ["x"] = 0, ["name"] = "moretrees:palm_leaves", ["z"] = 3, ["meta"] = { ["inventory"] = {  }, ["fields"] = {  } }, ["param2"] = 0, ["param1"] = 13 }, { ["y"] = 9, ["x"] = 0, ["name"] = "moretrees:palm_leaves", ["z"] = 19, ["meta"] = { ["inventory"] = {  }, ["fields"] = {  } }, ["param2"] = 0, ["param1"] = 13 }, { ["y"] = 10, ["x"] = 0, ["name"] = "moretrees:palm_leaves", ["z"] = 19, ["meta"] = { ["inventory"] = {  }, ["fields"] = {  } }, ["param2"] = 0, ["param1"] = 13 }, { ["y"] = 11, ["x"] = 0, ["name"] = "moretrees:palm_leaves", ["z"] = 19, ["meta"] = { ["inventory"] = {  }, ["fields"] = {  } }, ["param2"] = 0, ["param1"] = 13 }, { ["y"] = 0, ["x"] = 1, ["name"] = "default:water_source", ["z"] = 0, ["meta"] = { ["inventory"] = {  }, ["fields"] = {  } }, ["param2"] = 0, ["param1"] = 12 }, { ["y"] = 0, ["x"] = 1, ["name"] = "default:water_source", ["z"] = 1, ["meta"] = { ["inventory"] = {  }, ["fields"] = {  } }, ["param2"] = 0, ["param1"] = 12 }, { ["y"] = 0, ["x"] = 1, ["name"] = "default:water_source", ["z"] = 2, ["meta"] = { ["inventory"] = {  }, ["fields"] = {  } }, ["param2"] = 0, ["param1"] = 12 }, { ["y"] = 0, ["x"] = 1, ["name"] = "default:water_source", ["z"] = 3, ["meta"] = { ["inventory"] = {  }, ["fields"] = {  } }, ["param2"] = 0, ["param1"] = 28 }, { ["y"] = 0, ["x"] = 1, ["name"] = "default:water_source", ["z"] = 4, ["meta"] = { ["inventory"] = {  }, ["fields"] = {  } }, ["param2"] = 0, ["param1"] = 44 }, { ["y"] = 0, ["x"] = 1, ["name"] = "default:sand", ["z"] = 5, ["meta"] = { ["inventory"] = {  }, ["fields"] = {  } }, ["param2"] = 0, ["param1"] = 0 }, { ["y"] = 0, ["x"] = 1, ["name"] = "default:sand", ["z"] = 6, ["meta"] = { ["inventory"] = {  }, ["fields"] = {  } }, ["param2"] = 0, ["param1"] = 0 }, { ["y"] = 0, ["x"] = 1, ["name"] = "default:sand", ["z"] = 7, ["meta"] = { ["inventory"] = {  }, ["fields"] = {  } }, ["param2"] = 0, ["param1"] = 0 }, { ["y"] = 0, ["x"] = 1, ["name"] = "default:sand", ["z"] = 8, ["meta"] = { ["inventory"] = {  }, ["fields"] = {  } }, ["param2"] = 0, ["param1"] = 0 }, { ["y"] = 0, ["x"] = 1, ["name"] = "default:sand", ["z"] = 9, ["meta"] = { ["inventory"] = {  }, ["fields"] = {  } }, ["param2"] = 0, ["param1"] = 0 }, { ["y"] = 0, ["x"] = 1, ["name"] = "default:sand", ["z"] = 10, ["meta"] = { ["inventory"] = {  }, ["fields"] = {  } }, ["param2"] = 0, ["param1"] = 0 }, { ["y"] = 0, ["x"] = 1, ["name"] = "default:sand", ["z"] = 11, ["meta"] = { ["inventory"] = {  }, ["fields"] = {  } }, ["param2"] = 0, ["param1"] = 0 }, { ["y"] = 0, ["x"] = 1, ["name"] = "default:sand", ["z"] = 12, ["meta"] = { ["inventory"] = {  }, ["fields"] = {  } }, ["param2"] = 0, ["param1"] = 0 }, { ["y"] = 0, ["x"] = 1, ["name"] = "default:sand", ["z"] = 13, ["meta"] = { ["inventory"] = {  }, ["fields"] = {  } }, ["param2"] = 0, ["param1"] = 0 }, { ["y"] = 0, ["x"] = 1, ["name"] = "default:sand", ["z"] = 14, ["meta"] = { ["inventory"] = {  }, ["fields"] = {  } }, ["param2"] = 0, ["param1"] = 0 }, { ["y"] = 0, ["x"] = 1, ["name"] = "default:sand", ["z"] = 15, ["meta"] = { ["inventory"] = {  }, ["fields"] = {  } }, ["param2"] = 0, ["param1"] = 0 }, { ["y"] = 0, ["x"] = 1, ["name"] = "default:sand", ["z"] = 16, ["meta"] = { ["inventory"] = {  }, ["fields"] = {  } }, ["param2"] = 0, ["param1"] = 0 }, { ["y"] = 0, ["x"] = 1, ["name"] = "default:water_source", ["z"] = 17, ["meta"] = { ["inventory"] = {  }, ["fields"] = {  } }, ["param2"] = 0, ["param1"] = 12 }, { ["y"] = 0, ["x"] = 1, ["name"] = "default:water_source", ["z"] = 18, ["meta"] = { ["inventory"] = {  }, ["fields"] = {  } }, ["param2"] = 0, ["param1"] = 12 }, { ["y"] = 0, ["x"] = 1, ["name"] = "default:water_source", ["z"] = 19, ["meta"] = { ["inventory"] = {  }, ["fields"] = {  } }, ["param2"] = 0, ["param1"] = 11 }, { ["y"] = 1, ["x"] = 1, ["name"] = "default:water_source", ["z"] = 0, ["meta"] = { ["inventory"] = {  }, ["fields"] = {  } }, ["param2"] = 0, ["param1"] = 13 }, { ["y"] = 1, ["x"] = 1, ["name"] = "default:water_source", ["z"] = 1, ["meta"] = { ["inventory"] = {  }, ["fields"] = {  } }, ["param2"] = 0, ["param1"] = 13 }, { ["y"] = 1, ["x"] = 1, ["name"] = "default:water_source", ["z"] = 2, ["meta"] = { ["inventory"] = {  }, ["fields"] = {  } }, ["param2"] = 0, ["param1"] = 29 }, { ["y"] = 1, ["x"] = 1, ["name"] = "default:water_source", ["z"] = 3, ["meta"] = { ["inventory"] = {  }, ["fields"] = {  } }, ["param2"] = 0, ["param1"] = 45 }, { ["y"] = 1, ["x"] = 1, ["name"] = "default:water_source", ["z"] = 4, ["meta"] = { ["inventory"] = {  }, ["fields"] = {  } }, ["param2"] = 0, ["param1"] = 61 }, { ["y"] = 1, ["x"] = 1, ["name"] = "default:water_source", ["z"] = 5, ["meta"] = { ["inventory"] = {  }, ["fields"] = {  } }, ["param2"] = 0, ["param1"] = 77 }, { ["y"] = 1, ["x"] = 1, ["name"] = "default:water_source", ["z"] = 6, ["meta"] = { ["inventory"] = {  }, ["fields"] = {  } }, ["param2"] = 0, ["param1"] = 93 }, { ["y"] = 1, ["x"] = 1, ["name"] = "default:sand", ["z"] = 7, ["meta"] = { ["inventory"] = {  }, ["fields"] = {  } }, ["param2"] = 0, ["param1"] = 0 }, { ["y"] = 1, ["x"] = 1, ["name"] = "default:sand", ["z"] = 8, ["meta"] = { ["inventory"] = {  }, ["fields"] = {  } }, ["param2"] = 0, ["param1"] = 0 }, { ["y"] = 1, ["x"] = 1, ["name"] = "default:sand", ["z"] = 9, ["meta"] = { ["inventory"] = {  }, ["fields"] = {  } }, ["param2"] = 0, ["param1"] = 0 }, { ["y"] = 1, ["x"] = 1, ["name"] = "default:sand", ["z"] = 10, ["meta"] = { ["inventory"] = {  }, ["fields"] = {  } }, ["param2"] = 0, ["param1"] = 0 }, { ["y"] = 1, ["x"] = 1, ["name"] = "default:sand", ["z"] = 11, ["meta"] = { ["inventory"] = {  }, ["fields"] = {  } }, ["param2"] = 0, ["param1"] = 0 }, { ["y"] = 1, ["x"] = 1, ["name"] = "default:sand", ["z"] = 12, ["meta"] = { ["inventory"] = {  }, ["fields"] = {  } }, ["param2"] = 0, ["param1"] = 0 }, { ["y"] = 1, ["x"] = 1, ["name"] = "default:water_source", ["z"] = 13, ["meta"] = { ["inventory"] = {  }, ["fields"] = {  } }, ["param2"] = 0, ["param1"] = 29 }, { ["y"] = 1, ["x"] = 1, ["name"] = "default:water_source", ["z"] = 14, ["meta"] = { ["inventory"] = {  }, ["fields"] = {  } }, ["param2"] = 0, ["param1"] = 13 }, { ["y"] = 1, ["x"] = 1, ["name"] = "default:water_source", ["z"] = 15, ["meta"] = { ["inventory"] = {  }, ["fields"] = {  } }, ["param2"] = 0, ["param1"] = 13 }, { ["y"] = 1, ["x"] = 1, ["name"] = "default:water_source", ["z"] = 16, ["meta"] = { ["inventory"] = {  }, ["fields"] = {  } }, ["param2"] = 0, ["param1"] = 13 }, { ["y"] = 1, ["x"] = 1, ["name"] = "default:water_source", ["z"] = 17, ["meta"] = { ["inventory"] = {  }, ["fields"] = {  } }, ["param2"] = 0, ["param1"] = 13 }, { ["y"] = 1, ["x"] = 1, ["name"] = "default:water_source", ["z"] = 18, ["meta"] = { ["inventory"] = {  }, ["fields"] = {  } }, ["param2"] = 0, ["param1"] = 13 }, { ["y"] = 1, ["x"] = 1, ["name"] = "default:water_source", ["z"] = 19, ["meta"] = { ["inventory"] = {  }, ["fields"] = {  } }, ["param2"] = 0, ["param1"] = 12 }, { ["y"] = 10, ["x"] = 1, ["name"] = "moretrees:palm_leaves", ["z"] = 19, ["meta"] = { ["inventory"] = {  }, ["fields"] = {  } }, ["param2"] = 0, ["param1"] = 13 }, { ["y"] = 0, ["x"] = 2, ["name"] = "default:water_source", ["z"] = 0, ["meta"] = { ["inventory"] = {  }, ["fields"] = {  } }, ["param2"] = 0, ["param1"] = 12 }, { ["y"] = 0, ["x"] = 2, ["name"] = "default:water_source", ["z"] = 1, ["meta"] = { ["inventory"] = {  }, ["fields"] = {  } }, ["param2"] = 0, ["param1"] = 12 }, { ["y"] = 0, ["x"] = 2, ["name"] = "default:water_source", ["z"] = 2, ["meta"] = { ["inventory"] = {  }, ["fields"] = {  } }, ["param2"] = 0, ["param1"] = 28 }, { ["y"] = 0, ["x"] = 2, ["name"] = "default:water_source", ["z"] = 3, ["meta"] = { ["inventory"] = {  }, ["fields"] = {  } }, ["param2"] = 0, ["param1"] = 44 }, { ["y"] = 0, ["x"] = 2, ["name"] = "default:water_source", ["z"] = 4, ["meta"] = { ["inventory"] = {  }, ["fields"] = {  } }, ["param2"] = 0, ["param1"] = 60 }, { ["y"] = 0, ["x"] = 2, ["name"] = "default:sand", ["z"] = 5, ["meta"] = { ["inventory"] = {  }, ["fields"] = {  } }, ["param2"] = 0, ["param1"] = 0 }, { ["y"] = 0, ["x"] = 2, ["name"] = "default:sand", ["z"] = 6, ["meta"] = { ["inventory"] = {  }, ["fields"] = {  } }, ["param2"] = 0, ["param1"] = 0 }, { ["y"] = 0, ["x"] = 2, ["name"] = "default:sand", ["z"] = 7, ["meta"] = { ["inventory"] = {  }, ["fields"] = {  } }, ["param2"] = 0, ["param1"] = 0 }, { ["y"] = 0, ["x"] = 2, ["name"] = "default:sand", ["z"] = 8, ["meta"] = { ["inventory"] = {  }, ["fields"] = {  } }, ["param2"] = 0, ["param1"] = 0 }, { ["y"] = 0, ["x"] = 2, ["name"] = "default:sand", ["z"] = 9, ["meta"] = { ["inventory"] = {  }, ["fields"] = {  } }, ["param2"] = 0, ["param1"] = 0 }, { ["y"] = 0, ["x"] = 2, ["name"] = "default:sand", ["z"] = 10, ["meta"] = { ["inventory"] = {  }, ["fields"] = {  } }, ["param2"] = 0, ["param1"] = 0 }, { ["y"] = 0, ["x"] = 2, ["name"] = "default:sand", ["z"] = 11, ["meta"] = { ["inventory"] = {  }, ["fields"] = {  } }, ["param2"] = 0, ["param1"] = 0 }, { ["y"] = 0, ["x"] = 2, ["name"] = "default:sand", ["z"] = 12, ["meta"] = { ["inventory"] = {  }, ["fields"] = {  } }, ["param2"] = 0, ["param1"] = 0 }, { ["y"] = 0, ["x"] = 2, ["name"] = "default:sand", ["z"] = 13, ["meta"] = { ["inventory"] = {  }, ["fields"] = {  } }, ["param2"] = 0, ["param1"] = 0 }, { ["y"] = 0, ["x"] = 2, ["name"] = "default:sand", ["z"] = 14, ["meta"] = { ["inventory"] = {  }, ["fields"] = {  } }, ["param2"] = 0, ["param1"] = 0 }, { ["y"] = 0, ["x"] = 2, ["name"] = "default:sand", ["z"] = 15, ["meta"] = { ["inventory"] = {  }, ["fields"] = {  } }, ["param2"] = 0, ["param1"] = 0 }, { ["y"] = 0, ["x"] = 2, ["name"] = "default:sand", ["z"] = 16, ["meta"] = { ["inventory"] = {  }, ["fields"] = {  } }, ["param2"] = 0, ["param1"] = 0 }, { ["y"] = 0, ["x"] = 2, ["name"] = "default:water_source", ["z"] = 17, ["meta"] = { ["inventory"] = {  }, ["fields"] = {  } }, ["param2"] = 0, ["param1"] = 12 }, { ["y"] = 0, ["x"] = 2, ["name"] = "default:water_source", ["z"] = 18, ["meta"] = { ["inventory"] = {  }, ["fields"] = {  } }, ["param2"] = 0, ["param1"] = 12 }, { ["y"] = 0, ["x"] = 2, ["name"] = "default:water_source", ["z"] = 19, ["meta"] = { ["inventory"] = {  }, ["fields"] = {  } }, ["param2"] = 0, ["param1"] = 12 }, { ["y"] = 1, ["x"] = 2, ["name"] = "default:water_source", ["z"] = 0, ["meta"] = { ["inventory"] = {  }, ["fields"] = {  } }, ["param2"] = 0, ["param1"] = 13 }, { ["y"] = 1, ["x"] = 2, ["name"] = "default:water_source", ["z"] = 1, ["meta"] = { ["inventory"] = {  }, ["fields"] = {  } }, ["param2"] = 0, ["param1"] = 29 }, { ["y"] = 1, ["x"] = 2, ["name"] = "default:water_source", ["z"] = 2, ["meta"] = { ["inventory"] = {  }, ["fields"] = {  } }, ["param2"] = 0, ["param1"] = 45 }, { ["y"] = 1, ["x"] = 2, ["name"] = "default:water_source", ["z"] = 3, ["meta"] = { ["inventory"] = {  }, ["fields"] = {  } }, ["param2"] = 0, ["param1"] = 61 }, { ["y"] = 1, ["x"] = 2, ["name"] = "default:water_source", ["z"] = 4, ["meta"] = { ["inventory"] = {  }, ["fields"] = {  } }, ["param2"] = 0, ["param1"] = 77 }, { ["y"] = 1, ["x"] = 2, ["name"] = "default:water_source", ["z"] = 5, ["meta"] = { ["inventory"] = {  }, ["fields"] = {  } }, ["param2"] = 240, ["param1"] = 93 }, { ["y"] = 1, ["x"] = 2, ["name"] = "default:water_source", ["z"] = 6, ["meta"] = { ["inventory"] = {  }, ["fields"] = {  } }, ["param2"] = 0, ["param1"] = 109 }, { ["y"] = 1, ["x"] = 2, ["name"] = "default:sand", ["z"] = 7, ["meta"] = { ["inventory"] = {  }, ["fields"] = {  } }, ["param2"] = 0, ["param1"] = 0 }, { ["y"] = 1, ["x"] = 2, ["name"] = "default:sand", ["z"] = 8, ["meta"] = { ["inventory"] = {  }, ["fields"] = {  } }, ["param2"] = 0, ["param1"] = 0 }, { ["y"] = 1, ["x"] = 2, ["name"] = "default:sand", ["z"] = 9, ["meta"] = { ["inventory"] = {  }, ["fields"] = {  } }, ["param2"] = 0, ["param1"] = 0 }, { ["y"] = 1, ["x"] = 2, ["name"] = "default:sand", ["z"] = 10, ["meta"] = { ["inventory"] = {  }, ["fields"] = {  } }, ["param2"] = 0, ["param1"] = 0 }, { ["y"] = 1, ["x"] = 2, ["name"] = "default:sand", ["z"] = 11, ["meta"] = { ["inventory"] = {  }, ["fields"] = {  } }, ["param2"] = 0, ["param1"] = 0 }, { ["y"] = 1, ["x"] = 2, ["name"] = "default:sand", ["z"] = 12, ["meta"] = { ["inventory"] = {  }, ["fields"] = {  } }, ["param2"] = 0, ["param1"] = 0 }, { ["y"] = 1, ["x"] = 2, ["name"] = "default:water_source", ["z"] = 13, ["meta"] = { ["inventory"] = {  }, ["fields"] = {  } }, ["param2"] = 0, ["param1"] = 45 }, { ["y"] = 1, ["x"] = 2, ["name"] = "default:water_source", ["z"] = 14, ["meta"] = { ["inventory"] = {  }, ["fields"] = {  } }, ["param2"] = 0, ["param1"] = 29 }, { ["y"] = 1, ["x"] = 2, ["name"] = "default:water_source", ["z"] = 15, ["meta"] = { ["inventory"] = {  }, ["fields"] = {  } }, ["param2"] = 0, ["param1"] = 13 }, { ["y"] = 1, ["x"] = 2, ["name"] = "default:water_source", ["z"] = 16, ["meta"] = { ["inventory"] = {  }, ["fields"] = {  } }, ["param2"] = 0, ["param1"] = 13 }, { ["y"] = 1, ["x"] = 2, ["name"] = "default:water_source", ["z"] = 17, ["meta"] = { ["inventory"] = {  }, ["fields"] = {  } }, ["param2"] = 0, ["param1"] = 13 }, { ["y"] = 1, ["x"] = 2, ["name"] = "default:water_source", ["z"] = 18, ["meta"] = { ["inventory"] = {  }, ["fields"] = {  } }, ["param2"] = 0, ["param1"] = 13 }, { ["y"] = 1, ["x"] = 2, ["name"] = "default:water_source", ["z"] = 19, ["meta"] = { ["inventory"] = {  }, ["fields"] = {  } }, ["param2"] = 0, ["param1"] = 13 }, { ["y"] = 2, ["x"] = 2, ["name"] = "ferns:horsetail_03", ["z"] = 8, ["meta"] = { ["inventory"] = {  }, ["fields"] = {  } }, ["param2"] = 0, ["param1"] = 125 }, { ["y"] = 2, ["x"] = 2, ["name"] = "ferns:horsetail_02", ["z"] = 10, ["meta"] = { ["inventory"] = {  }, ["fields"] = {  } }, ["param2"] = 0, ["param1"] = 109 }, { ["y"] = 0, ["x"] = 3, ["name"] = "default:water_source", ["z"] = 0, ["meta"] = { ["inventory"] = {  }, ["fields"] = {  } }, ["param2"] = 0, ["param1"] = 12 }, { ["y"] = 0, ["x"] = 3, ["name"] = "default:water_source", ["z"] = 1, ["meta"] = { ["inventory"] = {  }, ["fields"] = {  } }, ["param2"] = 0, ["param1"] = 28 }, { ["y"] = 0, ["x"] = 3, ["name"] = "default:water_source", ["z"] = 2, ["meta"] = { ["inventory"] = {  }, ["fields"] = {  } }, ["param2"] = 0, ["param1"] = 44 }, { ["y"] = 0, ["x"] = 3, ["name"] = "default:water_source", ["z"] = 3, ["meta"] = { ["inventory"] = {  }, ["fields"] = {  } }, ["param2"] = 0, ["param1"] = 60 }, { ["y"] = 0, ["x"] = 3, ["name"] = "default:water_source", ["z"] = 4, ["meta"] = { ["inventory"] = {  }, ["fields"] = {  } }, ["param2"] = 240, ["param1"] = 76 }, { ["y"] = 0, ["x"] = 3, ["name"] = "default:sand", ["z"] = 5, ["meta"] = { ["inventory"] = {  }, ["fields"] = {  } }, ["param2"] = 0, ["param1"] = 0 }, { ["y"] = 0, ["x"] = 3, ["name"] = "default:sand", ["z"] = 6, ["meta"] = { ["inventory"] = {  }, ["fields"] = {  } }, ["param2"] = 0, ["param1"] = 0 }, { ["y"] = 0, ["x"] = 3, ["name"] = "default:sand", ["z"] = 7, ["meta"] = { ["inventory"] = {  }, ["fields"] = {  } }, ["param2"] = 0, ["param1"] = 0 }, { ["y"] = 0, ["x"] = 3, ["name"] = "default:sand", ["z"] = 8, ["meta"] = { ["inventory"] = {  }, ["fields"] = {  } }, ["param2"] = 0, ["param1"] = 0 }, { ["y"] = 0, ["x"] = 3, ["name"] = "default:sand", ["z"] = 9, ["meta"] = { ["inventory"] = {  }, ["fields"] = {  } }, ["param2"] = 0, ["param1"] = 0 }, { ["y"] = 0, ["x"] = 3, ["name"] = "default:sand", ["z"] = 10, ["meta"] = { ["inventory"] = {  }, ["fields"] = {  } }, ["param2"] = 0, ["param1"] = 0 }, { ["y"] = 0, ["x"] = 3, ["name"] = "default:sand", ["z"] = 11, ["meta"] = { ["inventory"] = {  }, ["fields"] = {  } }, ["param2"] = 0, ["param1"] = 0 }, { ["y"] = 0, ["x"] = 3, ["name"] = "default:sand", ["z"] = 12, ["meta"] = { ["inventory"] = {  }, ["fields"] = {  } }, ["param2"] = 0, ["param1"] = 0 }, { ["y"] = 0, ["x"] = 3, ["name"] = "default:sand", ["z"] = 13, ["meta"] = { ["inventory"] = {  }, ["fields"] = {  } }, ["param2"] = 0, ["param1"] = 0 }, { ["y"] = 0, ["x"] = 3, ["name"] = "default:sand", ["z"] = 14, ["meta"] = { ["inventory"] = {  }, ["fields"] = {  } }, ["param2"] = 0, ["param1"] = 0 }, { ["y"] = 0, ["x"] = 3, ["name"] = "default:sand", ["z"] = 15, ["meta"] = { ["inventory"] = {  }, ["fields"] = {  } }, ["param2"] = 0, ["param1"] = 0 }, { ["y"] = 0, ["x"] = 3, ["name"] = "default:water_source", ["z"] = 16, ["meta"] = { ["inventory"] = {  }, ["fields"] = {  } }, ["param2"] = 0, ["param1"] = 12 }, { ["y"] = 0, ["x"] = 3, ["name"] = "default:water_source", ["z"] = 17, ["meta"] = { ["inventory"] = {  }, ["fields"] = {  } }, ["param2"] = 0, ["param1"] = 12 }, { ["y"] = 0, ["x"] = 3, ["name"] = "default:water_source", ["z"] = 18, ["meta"] = { ["inventory"] = {  }, ["fields"] = {  } }, ["param2"] = 0, ["param1"] = 12 }, { ["y"] = 0, ["x"] = 3, ["name"] = "default:water_source", ["z"] = 19, ["meta"] = { ["inventory"] = {  }, ["fields"] = {  } }, ["param2"] = 0, ["param1"] = 12 }, { ["y"] = 1, ["x"] = 3, ["name"] = "default:water_source", ["z"] = 0, ["meta"] = { ["inventory"] = {  }, ["fields"] = {  } }, ["param2"] = 0, ["param1"] = 29 }, { ["y"] = 1, ["x"] = 3, ["name"] = "default:water_source", ["z"] = 1, ["meta"] = { ["inventory"] = {  }, ["fields"] = {  } }, ["param2"] = 0, ["param1"] = 45 }, { ["y"] = 1, ["x"] = 3, ["name"] = "default:water_source", ["z"] = 2, ["meta"] = { ["inventory"] = {  }, ["fields"] = {  } }, ["param2"] = 0, ["param1"] = 61 }, { ["y"] = 1, ["x"] = 3, ["name"] = "default:water_source", ["z"] = 3, ["meta"] = { ["inventory"] = {  }, ["fields"] = {  } }, ["param2"] = 0, ["param1"] = 77 }, { ["y"] = 1, ["x"] = 3, ["name"] = "default:water_source", ["z"] = 4, ["meta"] = { ["inventory"] = {  }, ["fields"] = {  } }, ["param2"] = 0, ["param1"] = 93 }, { ["y"] = 1, ["x"] = 3, ["name"] = "default:water_source", ["z"] = 5, ["meta"] = { ["inventory"] = {  }, ["fields"] = {  } }, ["param2"] = 0, ["param1"] = 108 }, { ["y"] = 1, ["x"] = 3, ["name"] = "default:water_source", ["z"] = 6, ["meta"] = { ["inventory"] = {  }, ["fields"] = {  } }, ["param2"] = 0, ["param1"] = 124 }, { ["y"] = 1, ["x"] = 3, ["name"] = "default:sand", ["z"] = 7, ["meta"] = { ["inventory"] = {  }, ["fields"] = {  } }, ["param2"] = 0, ["param1"] = 0 }, { ["y"] = 1, ["x"] = 3, ["name"] = "default:sand", ["z"] = 8, ["meta"] = { ["inventory"] = {  }, ["fields"] = {  } }, ["param2"] = 0, ["param1"] = 0 }, { ["y"] = 1, ["x"] = 3, ["name"] = "default:sand", ["z"] = 9, ["meta"] = { ["inventory"] = {  }, ["fields"] = {  } }, ["param2"] = 0, ["param1"] = 0 }, { ["y"] = 1, ["x"] = 3, ["name"] = "default:sand", ["z"] = 10, ["meta"] = { ["inventory"] = {  }, ["fields"] = {  } }, ["param2"] = 0, ["param1"] = 0 }, { ["y"] = 1, ["x"] = 3, ["name"] = "default:sand", ["z"] = 11, ["meta"] = { ["inventory"] = {  }, ["fields"] = {  } }, ["param2"] = 0, ["param1"] = 0 }, { ["y"] = 1, ["x"] = 3, ["name"] = "default:sand", ["z"] = 12, ["meta"] = { ["inventory"] = {  }, ["fields"] = {  } }, ["param2"] = 0, ["param1"] = 0 }, { ["y"] = 1, ["x"] = 3, ["name"] = "default:water_source", ["z"] = 13, ["meta"] = { ["inventory"] = {  }, ["fields"] = {  } }, ["param2"] = 0, ["param1"] = 61 }, { ["y"] = 1, ["x"] = 3, ["name"] = "default:water_source", ["z"] = 14, ["meta"] = { ["inventory"] = {  }, ["fields"] = {  } }, ["param2"] = 0, ["param1"] = 45 }, { ["y"] = 1, ["x"] = 3, ["name"] = "default:water_source", ["z"] = 15, ["meta"] = { ["inventory"] = {  }, ["fields"] = {  } }, ["param2"] = 0, ["param1"] = 29 }, { ["y"] = 1, ["x"] = 3, ["name"] = "default:water_source", ["z"] = 16, ["meta"] = { ["inventory"] = {  }, ["fields"] = {  } }, ["param2"] = 0, ["param1"] = 13 }, { ["y"] = 1, ["x"] = 3, ["name"] = "default:water_source", ["z"] = 17, ["meta"] = { ["inventory"] = {  }, ["fields"] = {  } }, ["param2"] = 0, ["param1"] = 13 }, { ["y"] = 1, ["x"] = 3, ["name"] = "default:water_source", ["z"] = 18, ["meta"] = { ["inventory"] = {  }, ["fields"] = {  } }, ["param2"] = 0, ["param1"] = 13 }, { ["y"] = 1, ["x"] = 3, ["name"] = "default:water_source", ["z"] = 19, ["meta"] = { ["inventory"] = {  }, ["fields"] = {  } }, ["param2"] = 0, ["param1"] = 13 }, { ["y"] = 2, ["x"] = 3, ["name"] = "ferns:fern_trunk", ["z"] = 8, ["meta"] = { ["inventory"] = {  }, ["fields"] = {  } }, ["param2"] = 0, ["param1"] = 141 }, { ["y"] = 2, ["x"] = 3, ["name"] = "ferns:fern_trunk", ["z"] = 10, ["meta"] = { ["inventory"] = {  }, ["fields"] = {  } }, ["param2"] = 0, ["param1"] = 125 }, { ["y"] = 3, ["x"] = 3, ["name"] = "ferns:fern_trunk", ["z"] = 8, ["meta"] = { ["inventory"] = {  }, ["fields"] = {  } }, ["param2"] = 0, ["param1"] = 157 }, { ["y"] = 3, ["x"] = 3, ["name"] = "ferns:fern_trunk", ["z"] = 10, ["meta"] = { ["inventory"] = {  }, ["fields"] = {  } }, ["param2"] = 0, ["param1"] = 141 }, { ["y"] = 4, ["x"] = 3, ["name"] = "ferns:fern_trunk", ["z"] = 8, ["meta"] = { ["inventory"] = {  }, ["fields"] = {  } }, ["param2"] = 0, ["param1"] = 157 }, { ["y"] = 4, ["x"] = 3, ["name"] = "ferns:fern_trunk", ["z"] = 10, ["meta"] = { ["inventory"] = {  }, ["fields"] = {  } }, ["param2"] = 0, ["param1"] = 157 }, { ["y"] = 5, ["x"] = 3, ["name"] = "default:leaves", ["z"] = 5, ["meta"] = { ["inventory"] = {  }, ["fields"] = {  } }, ["param2"] = 0, ["param1"] = 109 }, { ["y"] = 5, ["x"] = 3, ["name"] = "default:leaves", ["z"] = 6, ["meta"] = { ["inventory"] = {  }, ["fields"] = {  } }, ["param2"] = 0, ["param1"] = 125 }, { ["y"] = 5, ["x"] = 3, ["name"] = "ferns:tree_fern_leaves", ["z"] = 8, ["meta"] = { ["inventory"] = {  }, ["fields"] = {  } }, ["param2"] = 2, ["param1"] = 141 }, { ["y"] = 5, ["x"] = 3, ["name"] = "ferns:tree_fern_leaves", ["z"] = 10, ["meta"] = { ["inventory"] = {  }, ["fields"] = {  } }, ["param2"] = 2, ["param1"] = 141 }, { ["y"] = 6, ["x"] = 3, ["name"] = "default:leaves", ["z"] = 5, ["meta"] = { ["inventory"] = {  }, ["fields"] = {  } }, ["param2"] = 0, ["param1"] = 93 }, { ["y"] = 6, ["x"] = 3, ["name"] = "default:leaves", ["z"] = 6, ["meta"] = { ["inventory"] = {  }, ["fields"] = {  } }, ["param2"] = 0, ["param1"] = 109 }, { ["y"] = 7, ["x"] = 3, ["name"] = "default:leaves", ["z"] = 5, ["meta"] = { ["inventory"] = {  }, ["fields"] = {  } }, ["param2"] = 0, ["param1"] = 77 }, { ["y"] = 7, ["x"] = 3, ["name"] = "default:leaves", ["z"] = 6, ["meta"] = { ["inventory"] = {  }, ["fields"] = {  } }, ["param2"] = 0, ["param1"] = 93 }, { ["y"] = 8, ["x"] = 3, ["name"] = "default:leaves", ["z"] = 5, ["meta"] = { ["inventory"] = {  }, ["fields"] = {  } }, ["param2"] = 0, ["param1"] = 61 }, { ["y"] = 8, ["x"] = 3, ["name"] = "default:leaves", ["z"] = 6, ["meta"] = { ["inventory"] = {  }, ["fields"] = {  } }, ["param2"] = 0, ["param1"] = 77 }, { ["y"] = 0, ["x"] = 4, ["name"] = "default:water_source", ["z"] = 0, ["meta"] = { ["inventory"] = {  }, ["fields"] = {  } }, ["param2"] = 0, ["param1"] = 28 }, { ["y"] = 0, ["x"] = 4, ["name"] = "default:water_source", ["z"] = 1, ["meta"] = { ["inventory"] = {  }, ["fields"] = {  } }, ["param2"] = 0, ["param1"] = 44 }, { ["y"] = 0, ["x"] = 4, ["name"] = "default:water_source", ["z"] = 2, ["meta"] = { ["inventory"] = {  }, ["fields"] = {  } }, ["param2"] = 0, ["param1"] = 60 }, { ["y"] = 0, ["x"] = 4, ["name"] = "default:water_source", ["z"] = 3, ["meta"] = { ["inventory"] = {  }, ["fields"] = {  } }, ["param2"] = 0, ["param1"] = 76 }, { ["y"] = 0, ["x"] = 4, ["name"] = "default:sand", ["z"] = 4, ["meta"] = { ["inventory"] = {  }, ["fields"] = {  } }, ["param2"] = 0, ["param1"] = 0 }, { ["y"] = 0, ["x"] = 4, ["name"] = "default:sand", ["z"] = 5, ["meta"] = { ["inventory"] = {  }, ["fields"] = {  } }, ["param2"] = 0, ["param1"] = 0 }, { ["y"] = 0, ["x"] = 4, ["name"] = "default:sand", ["z"] = 6, ["meta"] = { ["inventory"] = {  }, ["fields"] = {  } }, ["param2"] = 0, ["param1"] = 0 }, { ["y"] = 0, ["x"] = 4, ["name"] = "default:water_flowing", ["z"] = 7, ["meta"] = { ["inventory"] = {  }, ["fields"] = {  } }, ["param2"] = 1, ["param1"] = 2 }, { ["y"] = 0, ["x"] = 4, ["name"] = "default:water_flowing", ["z"] = 8, ["meta"] = { ["inventory"] = {  }, ["fields"] = {  } }, ["param2"] = 2, ["param1"] = 3 }, { ["y"] = 0, ["x"] = 4, ["name"] = "default:water_flowing", ["z"] = 9, ["meta"] = { ["inventory"] = {  }, ["fields"] = {  } }, ["param2"] = 3, ["param1"] = 4 }, { ["y"] = 0, ["x"] = 4, ["name"] = "default:water_flowing", ["z"] = 10, ["meta"] = { ["inventory"] = {  }, ["fields"] = {  } }, ["param2"] = 4, ["param1"] = 5 }, { ["y"] = 0, ["x"] = 4, ["name"] = "default:water_flowing", ["z"] = 11, ["meta"] = { ["inventory"] = {  }, ["fields"] = {  } }, ["param2"] = 5, ["param1"] = 6 }, { ["y"] = 0, ["x"] = 4, ["name"] = "default:water_flowing", ["z"] = 12, ["meta"] = { ["inventory"] = {  }, ["fields"] = {  } }, ["param2"] = 6, ["param1"] = 7 }, { ["y"] = 0, ["x"] = 4, ["name"] = "default:water_flowing", ["z"] = 13, ["meta"] = { ["inventory"] = {  }, ["fields"] = {  } }, ["param2"] = 7, ["param1"] = 8 }, { ["y"] = 0, ["x"] = 4, ["name"] = "default:water_source", ["z"] = 14, ["meta"] = { ["inventory"] = {  }, ["fields"] = {  } }, ["param2"] = 240, ["param1"] = 9 }, { ["y"] = 0, ["x"] = 4, ["name"] = "default:water_source", ["z"] = 15, ["meta"] = { ["inventory"] = {  }, ["fields"] = {  } }, ["param2"] = 240, ["param1"] = 10 }, { ["y"] = 0, ["x"] = 4, ["name"] = "default:water_source", ["z"] = 16, ["meta"] = { ["inventory"] = {  }, ["fields"] = {  } }, ["param2"] = 0, ["param1"] = 11 }, { ["y"] = 0, ["x"] = 4, ["name"] = "default:water_source", ["z"] = 17, ["meta"] = { ["inventory"] = {  }, ["fields"] = {  } }, ["param2"] = 0, ["param1"] = 11 }, { ["y"] = 0, ["x"] = 4, ["name"] = "default:water_source", ["z"] = 18, ["meta"] = { ["inventory"] = {  }, ["fields"] = {  } }, ["param2"] = 0, ["param1"] = 12 }, { ["y"] = 0, ["x"] = 4, ["name"] = "default:water_source", ["z"] = 19, ["meta"] = { ["inventory"] = {  }, ["fields"] = {  } }, ["param2"] = 0, ["param1"] = 12 }, { ["y"] = 1, ["x"] = 4, ["name"] = "default:water_source", ["z"] = 0, ["meta"] = { ["inventory"] = {  }, ["fields"] = {  } }, ["param2"] = 0, ["param1"] = 45 }, { ["y"] = 1, ["x"] = 4, ["name"] = "default:water_source", ["z"] = 1, ["meta"] = { ["inventory"] = {  }, ["fields"] = {  } }, ["param2"] = 0, ["param1"] = 61 }, { ["y"] = 1, ["x"] = 4, ["name"] = "default:water_source", ["z"] = 2, ["meta"] = { ["inventory"] = {  }, ["fields"] = {  } }, ["param2"] = 0, ["param1"] = 77 }, { ["y"] = 1, ["x"] = 4, ["name"] = "default:water_source", ["z"] = 3, ["meta"] = { ["inventory"] = {  }, ["fields"] = {  } }, ["param2"] = 0, ["param1"] = 93 }, { ["y"] = 1, ["x"] = 4, ["name"] = "default:water_source", ["z"] = 4, ["meta"] = { ["inventory"] = {  }, ["fields"] = {  } }, ["param2"] = 0, ["param1"] = 109 }, { ["y"] = 1, ["x"] = 4, ["name"] = "default:wood", ["z"] = 5, ["meta"] = { ["inventory"] = {  }, ["fields"] = {  } }, ["param2"] = 0, ["param1"] = 0 }, { ["y"] = 1, ["x"] = 4, ["name"] = "default:wood", ["z"] = 6, ["meta"] = { ["inventory"] = {  }, ["fields"] = {  } }, ["param2"] = 0, ["param1"] = 0 }, { ["y"] = 1, ["x"] = 4, ["name"] = "default:dirt_with_grass", ["z"] = 7, ["meta"] = { ["inventory"] = {  }, ["fields"] = {  } }, ["param2"] = 0, ["param1"] = 0 }, { ["y"] = 1, ["x"] = 4, ["name"] = "default:dirt_with_grass", ["z"] = 8, ["meta"] = { ["inventory"] = {  }, ["fields"] = {  } }, ["param2"] = 0, ["param1"] = 0 }, { ["y"] = 1, ["x"] = 4, ["name"] = "default:dirt_with_grass", ["z"] = 9, ["meta"] = { ["inventory"] = {  }, ["fields"] = {  } }, ["param2"] = 0, ["param1"] = 0 }, { ["y"] = 1, ["x"] = 4, ["name"] = "default:dirt_with_grass", ["z"] = 10, ["meta"] = { ["inventory"] = {  }, ["fields"] = {  } }, ["param2"] = 0, ["param1"] = 0 }, { ["y"] = 1, ["x"] = 4, ["name"] = "default:dirt_with_grass", ["z"] = 11, ["meta"] = { ["inventory"] = {  }, ["fields"] = {  } }, ["param2"] = 0, ["param1"] = 0 }, { ["y"] = 1, ["x"] = 4, ["name"] = "farming:soil_wet", ["z"] = 12, ["meta"] = { ["inventory"] = {  }, ["fields"] = {  } }, ["param2"] = 0, ["param1"] = 0 }, { ["y"] = 1, ["x"] = 4, ["name"] = "farming:soil_wet", ["z"] = 13, ["meta"] = { ["inventory"] = {  }, ["fields"] = {  } }, ["param2"] = 0, ["param1"] = 0 }, { ["y"] = 1, ["x"] = 4, ["name"] = "farming:soil_wet", ["z"] = 14, ["meta"] = { ["inventory"] = {  }, ["fields"] = {  } }, ["param2"] = 0, ["param1"] = 0 }, { ["y"] = 1, ["x"] = 4, ["name"] = "farming:soil_wet", ["z"] = 15, ["meta"] = { ["inventory"] = {  }, ["fields"] = {  } }, ["param2"] = 0, ["param1"] = 0 }, { ["y"] = 1, ["x"] = 4, ["name"] = "farming:soil_wet", ["z"] = 16, ["meta"] = { ["inventory"] = {  }, ["fields"] = {  } }, ["param2"] = 0, ["param1"] = 0 }, { ["y"] = 1, ["x"] = 4, ["name"] = "farming:soil_wet", ["z"] = 17, ["meta"] = { ["inventory"] = {  }, ["fields"] = {  } }, ["param2"] = 0, ["param1"] = 0 }, { ["y"] = 1, ["x"] = 4, ["name"] = "default:water_source", ["z"] = 18, ["meta"] = { ["inventory"] = {  }, ["fields"] = {  } }, ["param2"] = 0, ["param1"] = 13 }, { ["y"] = 1, ["x"] = 4, ["name"] = "default:water_source", ["z"] = 19, ["meta"] = { ["inventory"] = {  }, ["fields"] = {  } }, ["param2"] = 240, ["param1"] = 13 }, { ["y"] = 2, ["x"] = 4, ["name"] = "bushes:fruitless_bush", ["z"] = 8, ["meta"] = { ["inventory"] = {  }, ["fields"] = { ["bush_type"] = "strawberry" } }, ["param2"] = 0, ["param1"] = 156 }, { ["y"] = 2, ["x"] = 4, ["name"] = "bushes:blackberry_bush", ["z"] = 10, ["meta"] = { ["inventory"] = {  }, ["fields"] = {  } }, ["param2"] = 0, ["param1"] = 143 }, { ["y"] = 2, ["x"] = 4, ["name"] = "default:papyrus", ["z"] = 11, ["meta"] = { ["inventory"] = {  }, ["fields"] = {  } }, ["param2"] = 0, ["param1"] = 127 }, { ["y"] = 2, ["x"] = 4, ["name"] = "farming:tomato_8", ["z"] = 12, ["meta"] = { ["inventory"] = {  }, ["fields"] = {  } }, ["param2"] = 0, ["param1"] = 109 }, { ["y"] = 2, ["x"] = 4, ["name"] = "farming:wheat_8", ["z"] = 13, ["meta"] = { ["inventory"] = {  }, ["fields"] = {  } }, ["param2"] = 0, ["param1"] = 93 }, { ["y"] = 2, ["x"] = 4, ["name"] = "default:grass_2", ["z"] = 14, ["meta"] = { ["inventory"] = {  }, ["fields"] = {  } }, ["param2"] = 0, ["param1"] = 79 }, { ["y"] = 2, ["x"] = 4, ["name"] = "farming:rhubarb_3", ["z"] = 15, ["meta"] = { ["inventory"] = {  }, ["fields"] = {  } }, ["param2"] = 0, ["param1"] = 61 }, { ["y"] = 2, ["x"] = 4, ["name"] = "farming:cotton_8", ["z"] = 16, ["meta"] = { ["inventory"] = {  }, ["fields"] = {  } }, ["param2"] = 0, ["param1"] = 45 }, { ["y"] = 2, ["x"] = 4, ["name"] = "farming:cotton_8", ["z"] = 17, ["meta"] = { ["inventory"] = {  }, ["fields"] = {  } }, ["param2"] = 0, ["param1"] = 29 }, { ["y"] = 3, ["x"] = 4, ["name"] = "default:papyrus", ["z"] = 11, ["meta"] = { ["inventory"] = {  }, ["fields"] = {  } }, ["param2"] = 0, ["param1"] = 143 }, { ["y"] = 4, ["x"] = 4, ["name"] = "default:papyrus", ["z"] = 11, ["meta"] = { ["inventory"] = {  }, ["fields"] = {  } }, ["param2"] = 0, ["param1"] = 159 }, { ["y"] = 5, ["x"] = 4, ["name"] = "default:leaves", ["z"] = 5, ["meta"] = { ["inventory"] = {  }, ["fields"] = {  } }, ["param2"] = 0, ["param1"] = 125 }, { ["y"] = 5, ["x"] = 4, ["name"] = "default:leaves", ["z"] = 6, ["meta"] = { ["inventory"] = {  }, ["fields"] = {  } }, ["param2"] = 0, ["param1"] = 140 }, { ["y"] = 5, ["x"] = 4, ["name"] = "default:leaves", ["z"] = 7, ["meta"] = { ["inventory"] = {  }, ["fields"] = {  } }, ["param2"] = 0, ["param1"] = 141 }, { ["y"] = 5, ["x"] = 4, ["name"] = "default:leaves", ["z"] = 8, ["meta"] = { ["inventory"] = {  }, ["fields"] = {  } }, ["param2"] = 0, ["param1"] = 156 }, { ["y"] = 5, ["x"] = 4, ["name"] = "default:papyrus", ["z"] = 11, ["meta"] = { ["inventory"] = {  }, ["fields"] = {  } }, ["param2"] = 0, ["param1"] = 143 }, { ["y"] = 6, ["x"] = 4, ["name"] = "default:leaves", ["z"] = 5, ["meta"] = { ["inventory"] = {  }, ["fields"] = {  } }, ["param2"] = 0, ["param1"] = 109 }, { ["y"] = 6, ["x"] = 4, ["name"] = "default:leaves", ["z"] = 6, ["meta"] = { ["inventory"] = {  }, ["fields"] = {  } }, ["param2"] = 0, ["param1"] = 124 }, { ["y"] = 6, ["x"] = 4, ["name"] = "default:leaves", ["z"] = 7, ["meta"] = { ["inventory"] = {  }, ["fields"] = {  } }, ["param2"] = 0, ["param1"] = 125 }, { ["y"] = 7, ["x"] = 4, ["name"] = "default:leaves", ["z"] = 6, ["meta"] = { ["inventory"] = {  }, ["fields"] = {  } }, ["param2"] = 0, ["param1"] = 109 }, { ["y"] = 7, ["x"] = 4, ["name"] = "default:leaves", ["z"] = 8, ["meta"] = { ["inventory"] = {  }, ["fields"] = {  } }, ["param2"] = 0, ["param1"] = 125 }, { ["y"] = 7, ["x"] = 4, ["name"] = "default:leaves", ["z"] = 9, ["meta"] = { ["inventory"] = {  }, ["fields"] = {  } }, ["param2"] = 0, ["param1"] = 141 }, { ["y"] = 8, ["x"] = 4, ["name"] = "default:leaves", ["z"] = 5, ["meta"] = { ["inventory"] = {  }, ["fields"] = {  } }, ["param2"] = 0, ["param1"] = 77 }, { ["y"] = 8, ["x"] = 4, ["name"] = "default:leaves", ["z"] = 7, ["meta"] = { ["inventory"] = {  }, ["fields"] = {  } }, ["param2"] = 0, ["param1"] = 109 }, { ["y"] = 0, ["x"] = 5, ["name"] = "default:water_source", ["z"] = 0, ["meta"] = { ["inventory"] = {  }, ["fields"] = {  } }, ["param2"] = 0, ["param1"] = 44 }, { ["y"] = 0, ["x"] = 5, ["name"] = "default:water_source", ["z"] = 1, ["meta"] = { ["inventory"] = {  }, ["fields"] = {  } }, ["param2"] = 0, ["param1"] = 60 }, { ["y"] = 0, ["x"] = 5, ["name"] = "default:water_source", ["z"] = 2, ["meta"] = { ["inventory"] = {  }, ["fields"] = {  } }, ["param2"] = 0, ["param1"] = 76 }, { ["y"] = 0, ["x"] = 5, ["name"] = "default:water_source", ["z"] = 3, ["meta"] = { ["inventory"] = {  }, ["fields"] = {  } }, ["param2"] = 0, ["param1"] = 92 }, { ["y"] = 0, ["x"] = 5, ["name"] = "default:sand", ["z"] = 4, ["meta"] = { ["inventory"] = {  }, ["fields"] = {  } }, ["param2"] = 0, ["param1"] = 0 }, { ["y"] = 0, ["x"] = 5, ["name"] = "default:sand", ["z"] = 5, ["meta"] = { ["inventory"] = {  }, ["fields"] = {  } }, ["param2"] = 0, ["param1"] = 0 }, { ["y"] = 0, ["x"] = 5, ["name"] = "default:water_flowing", ["z"] = 7, ["meta"] = { ["inventory"] = {  }, ["fields"] = {  } }, ["param2"] = 0, ["param1"] = 1 }, { ["y"] = 0, ["x"] = 5, ["name"] = "default:water_flowing", ["z"] = 8, ["meta"] = { ["inventory"] = {  }, ["fields"] = {  } }, ["param2"] = 1, ["param1"] = 2 }, { ["y"] = 0, ["x"] = 5, ["name"] = "default:water_flowing", ["z"] = 9, ["meta"] = { ["inventory"] = {  }, ["fields"] = {  } }, ["param2"] = 2, ["param1"] = 3 }, { ["y"] = 0, ["x"] = 5, ["name"] = "default:water_flowing", ["z"] = 10, ["meta"] = { ["inventory"] = {  }, ["fields"] = {  } }, ["param2"] = 3, ["param1"] = 4 }, { ["y"] = 0, ["x"] = 5, ["name"] = "default:desert_sand", ["z"] = 11, ["meta"] = { ["inventory"] = {  }, ["fields"] = {  } }, ["param2"] = 0, ["param1"] = 0 }, { ["y"] = 0, ["x"] = 5, ["name"] = "default:water_flowing", ["z"] = 12, ["meta"] = { ["inventory"] = {  }, ["fields"] = {  } }, ["param2"] = 6, ["param1"] = 6 }, { ["y"] = 0, ["x"] = 5, ["name"] = "default:water_flowing", ["z"] = 13, ["meta"] = { ["inventory"] = {  }, ["fields"] = {  } }, ["param2"] = 7, ["param1"] = 7 }, { ["y"] = 0, ["x"] = 5, ["name"] = "default:water_source", ["z"] = 14, ["meta"] = { ["inventory"] = {  }, ["fields"] = {  } }, ["param2"] = 240, ["param1"] = 8 }, { ["y"] = 0, ["x"] = 5, ["name"] = "default:water_source", ["z"] = 15, ["meta"] = { ["inventory"] = {  }, ["fields"] = {  } }, ["param2"] = 0, ["param1"] = 9 }, { ["y"] = 0, ["x"] = 5, ["name"] = "default:water_source", ["z"] = 16, ["meta"] = { ["inventory"] = {  }, ["fields"] = {  } }, ["param2"] = 0, ["param1"] = 10 }, { ["y"] = 0, ["x"] = 5, ["name"] = "default:water_source", ["z"] = 17, ["meta"] = { ["inventory"] = {  }, ["fields"] = {  } }, ["param2"] = 0, ["param1"] = 11 }, { ["y"] = 0, ["x"] = 5, ["name"] = "default:water_source", ["z"] = 18, ["meta"] = { ["inventory"] = {  }, ["fields"] = {  } }, ["param2"] = 0, ["param1"] = 12 }, { ["y"] = 0, ["x"] = 5, ["name"] = "default:water_source", ["z"] = 19, ["meta"] = { ["inventory"] = {  }, ["fields"] = {  } }, ["param2"] = 0, ["param1"] = 12 }, { ["y"] = 1, ["x"] = 5, ["name"] = "default:water_source", ["z"] = 0, ["meta"] = { ["inventory"] = {  }, ["fields"] = {  } }, ["param2"] = 0, ["param1"] = 61 }, { ["y"] = 1, ["x"] = 5, ["name"] = "default:water_source", ["z"] = 1, ["meta"] = { ["inventory"] = {  }, ["fields"] = {  } }, ["param2"] = 0, ["param1"] = 77 }, { ["y"] = 1, ["x"] = 5, ["name"] = "default:water_source", ["z"] = 2, ["meta"] = { ["inventory"] = {  }, ["fields"] = {  } }, ["param2"] = 0, ["param1"] = 93 }, { ["y"] = 1, ["x"] = 5, ["name"] = "default:water_source", ["z"] = 3, ["meta"] = { ["inventory"] = {  }, ["fields"] = {  } }, ["param2"] = 240, ["param1"] = 109 }, { ["y"] = 1, ["x"] = 5, ["name"] = "default:water_source", ["z"] = 4, ["meta"] = { ["inventory"] = {  }, ["fields"] = {  } }, ["param2"] = 0, ["param1"] = 125 }, { ["y"] = 1, ["x"] = 5, ["name"] = "default:wood", ["z"] = 5, ["meta"] = { ["inventory"] = {  }, ["fields"] = {  } }, ["param2"] = 0, ["param1"] = 0 }, { ["y"] = 1, ["x"] = 5, ["name"] = "default:wood", ["z"] = 6, ["meta"] = { ["inventory"] = {  }, ["fields"] = {  } }, ["param2"] = 0, ["param1"] = 0 }, { ["y"] = 1, ["x"] = 5, ["name"] = "default:dirt", ["z"] = 7, ["meta"] = { ["inventory"] = {  }, ["fields"] = {  } }, ["param2"] = 0, ["param1"] = 0 }, { ["y"] = 1, ["x"] = 5, ["name"] = "default:dirt_with_grass", ["z"] = 8, ["meta"] = { ["inventory"] = {  }, ["fields"] = {  } }, ["param2"] = 0, ["param1"] = 0 }, { ["y"] = 1, ["x"] = 5, ["name"] = "default:dirt_with_grass", ["z"] = 9, ["meta"] = { ["inventory"] = {  }, ["fields"] = {  } }, ["param2"] = 0, ["param1"] = 0 }, { ["y"] = 1, ["x"] = 5, ["name"] = "default:dirt_with_grass", ["z"] = 10, ["meta"] = { ["inventory"] = {  }, ["fields"] = {  } }, ["param2"] = 0, ["param1"] = 0 }, { ["y"] = 1, ["x"] = 5, ["name"] = "default:desert_sand", ["z"] = 11, ["meta"] = { ["inventory"] = {  }, ["fields"] = {  } }, ["param2"] = 0, ["param1"] = 0 }, { ["y"] = 1, ["x"] = 5, ["name"] = "farming:soil_wet", ["z"] = 12, ["meta"] = { ["inventory"] = {  }, ["fields"] = {  } }, ["param2"] = 0, ["param1"] = 0 }, { ["y"] = 1, ["x"] = 5, ["name"] = "farming:soil_wet", ["z"] = 13, ["meta"] = { ["inventory"] = {  }, ["fields"] = {  } }, ["param2"] = 0, ["param1"] = 0 }, { ["y"] = 1, ["x"] = 5, ["name"] = "farming:soil_wet", ["z"] = 14, ["meta"] = { ["inventory"] = {  }, ["fields"] = {  } }, ["param2"] = 0, ["param1"] = 0 }, { ["y"] = 1, ["x"] = 5, ["name"] = "farming:soil_wet", ["z"] = 15, ["meta"] = { ["inventory"] = {  }, ["fields"] = {  } }, ["param2"] = 0, ["param1"] = 0 }, { ["y"] = 1, ["x"] = 5, ["name"] = "farming:soil_wet", ["z"] = 16, ["meta"] = { ["inventory"] = {  }, ["fields"] = {  } }, ["param2"] = 0, ["param1"] = 0 }, { ["y"] = 1, ["x"] = 5, ["name"] = "farming:soil_wet", ["z"] = 17, ["meta"] = { ["inventory"] = {  }, ["fields"] = {  } }, ["param2"] = 0, ["param1"] = 0 }, { ["y"] = 1, ["x"] = 5, ["name"] = "default:water_source", ["z"] = 18, ["meta"] = { ["inventory"] = {  }, ["fields"] = {  } }, ["param2"] = 0, ["param1"] = 13 }, { ["y"] = 1, ["x"] = 5, ["name"] = "default:water_source", ["z"] = 19, ["meta"] = { ["inventory"] = {  }, ["fields"] = {  } }, ["param2"] = 240, ["param1"] = 13 }, { ["y"] = 2, ["x"] = 5, ["name"] = "homedecor:welcome_mat_green", ["z"] = 5, ["meta"] = { ["inventory"] = {  }, ["fields"] = {  } }, ["param2"] = 1, ["param1"] = 157 }, { ["y"] = 2, ["x"] = 5, ["name"] = "default:tree", ["z"] = 7, ["meta"] = { ["inventory"] = {  }, ["fields"] = {  } }, ["param2"] = 1, ["param1"] = 0 }, { ["y"] = 2, ["x"] = 5, ["name"] = "bushes:raspberry_bush", ["z"] = 10, ["meta"] = { ["inventory"] = {  }, ["fields"] = {  } }, ["param2"] = 0, ["param1"] = 159 }, { ["y"] = 2, ["x"] = 5, ["name"] = "default:cactus", ["z"] = 11, ["meta"] = { ["inventory"] = {  }, ["fields"] = {  } }, ["param2"] = 0, ["param1"] = 0 }, { ["y"] = 2, ["x"] = 5, ["name"] = "farming:raspberry_4", ["z"] = 12, ["meta"] = { ["inventory"] = {  }, ["fields"] = {  } }, ["param2"] = 0, ["param1"] = 125 }, { ["y"] = 2, ["x"] = 5, ["name"] = "farming:cotton_8", ["z"] = 13, ["meta"] = { ["inventory"] = {  }, ["fields"] = {  } }, ["param2"] = 0, ["param1"] = 109 }, { ["y"] = 2, ["x"] = 5, ["name"] = "farming:carrot_8", ["z"] = 14, ["meta"] = { ["inventory"] = {  }, ["fields"] = {  } }, ["param2"] = 0, ["param1"] = 93 }, { ["y"] = 2, ["x"] = 5, ["name"] = "farming:tomato_8", ["z"] = 15, ["meta"] = { ["inventory"] = {  }, ["fields"] = {  } }, ["param2"] = 0, ["param1"] = 77 }, { ["y"] = 2, ["x"] = 5, ["name"] = "farming:cotton_8", ["z"] = 16, ["meta"] = { ["inventory"] = {  }, ["fields"] = {  } }, ["param2"] = 0, ["param1"] = 61 }, { ["y"] = 2, ["x"] = 5, ["name"] = "farming:cotton_8", ["z"] = 17, ["meta"] = { ["inventory"] = {  }, ["fields"] = {  } }, ["param2"] = 0, ["param1"] = 45 }, { ["y"] = 3, ["x"] = 5, ["name"] = "default:tree", ["z"] = 7, ["meta"] = { ["inventory"] = {  }, ["fields"] = {  } }, ["param2"] = 20, ["param1"] = 0 }, { ["y"] = 3, ["x"] = 5, ["name"] = "default:cactus", ["z"] = 11, ["meta"] = { ["inventory"] = {  }, ["fields"] = {  } }, ["param2"] = 0, ["param1"] = 0 }, { ["y"] = 4, ["x"] = 5, ["name"] = "default:tree", ["z"] = 7, ["meta"] = { ["inventory"] = {  }, ["fields"] = {  } }, ["param2"] = 0, ["param1"] = 207 }, { ["y"] = 4, ["x"] = 5, ["name"] = "default:cactus", ["z"] = 11, ["meta"] = { ["inventory"] = {  }, ["fields"] = {  } }, ["param2"] = 0, ["param1"] = 0 }, { ["y"] = 5, ["x"] = 5, ["name"] = "default:leaves", ["z"] = 6, ["meta"] = { ["inventory"] = {  }, ["fields"] = {  } }, ["param2"] = 0, ["param1"] = 157 }, { ["y"] = 5, ["x"] = 5, ["name"] = "default:tree", ["z"] = 7, ["meta"] = { ["inventory"] = {  }, ["fields"] = {  } }, ["param2"] = 0, ["param1"] = 191 }, { ["y"] = 5, ["x"] = 5, ["name"] = "default:leaves", ["z"] = 8, ["meta"] = { ["inventory"] = {  }, ["fields"] = {  } }, ["param2"] = 0, ["param1"] = 172 }, { ["y"] = 5, ["x"] = 5, ["name"] = "default:cactus", ["z"] = 11, ["meta"] = { ["inventory"] = {  }, ["fields"] = {  } }, ["param2"] = 0, ["param1"] = 0 }, { ["y"] = 6, ["x"] = 5, ["name"] = "default:leaves", ["z"] = 6, ["meta"] = { ["inventory"] = {  }, ["fields"] = {  } }, ["param2"] = 0, ["param1"] = 141 }, { ["y"] = 6, ["x"] = 5, ["name"] = "default:tree", ["z"] = 7, ["meta"] = { ["inventory"] = {  }, ["fields"] = {  } }, ["param2"] = 0, ["param1"] = 175 }, { ["y"] = 6, ["x"] = 5, ["name"] = "default:leaves", ["z"] = 8, ["meta"] = { ["inventory"] = {  }, ["fields"] = {  } }, ["param2"] = 0, ["param1"] = 156 }, { ["y"] = 6, ["x"] = 5, ["name"] = "default:leaves", ["z"] = 9, ["meta"] = { ["inventory"] = {  }, ["fields"] = {  } }, ["param2"] = 0, ["param1"] = 173 }, { ["y"] = 7, ["x"] = 5, ["name"] = "default:leaves", ["z"] = 6, ["meta"] = { ["inventory"] = {  }, ["fields"] = {  } }, ["param2"] = 0, ["param1"] = 125 }, { ["y"] = 7, ["x"] = 5, ["name"] = "default:leaves", ["z"] = 7, ["meta"] = { ["inventory"] = {  }, ["fields"] = {  } }, ["param2"] = 0, ["param1"] = 140 }, { ["y"] = 7, ["x"] = 5, ["name"] = "default:leaves", ["z"] = 8, ["meta"] = { ["inventory"] = {  }, ["fields"] = {  } }, ["param2"] = 0, ["param1"] = 140 }, { ["y"] = 7, ["x"] = 5, ["name"] = "default:leaves", ["z"] = 9, ["meta"] = { ["inventory"] = {  }, ["fields"] = {  } }, ["param2"] = 0, ["param1"] = 157 }, { ["y"] = 8, ["x"] = 5, ["name"] = "default:leaves", ["z"] = 6, ["meta"] = { ["inventory"] = {  }, ["fields"] = {  } }, ["param2"] = 0, ["param1"] = 109 }, { ["y"] = 8, ["x"] = 5, ["name"] = "default:leaves", ["z"] = 7, ["meta"] = { ["inventory"] = {  }, ["fields"] = {  } }, ["param2"] = 0, ["param1"] = 125 }, { ["y"] = 8, ["x"] = 5, ["name"] = "default:leaves", ["z"] = 8, ["meta"] = { ["inventory"] = {  }, ["fields"] = {  } }, ["param2"] = 0, ["param1"] = 125 }, { ["y"] = 8, ["x"] = 5, ["name"] = "default:leaves", ["z"] = 9, ["meta"] = { ["inventory"] = {  }, ["fields"] = {  } }, ["param2"] = 0, ["param1"] = 141 }, { ["y"] = 0, ["x"] = 6, ["name"] = "default:water_source", ["z"] = 0, ["meta"] = { ["inventory"] = {  }, ["fields"] = {  } }, ["param2"] = 0, ["param1"] = 60 }, { ["y"] = 0, ["x"] = 6, ["name"] = "default:water_source", ["z"] = 1, ["meta"] = { ["inventory"] = {  }, ["fields"] = {  } }, ["param2"] = 0, ["param1"] = 76 }, { ["y"] = 0, ["x"] = 6, ["name"] = "default:water_source", ["z"] = 2, ["meta"] = { ["inventory"] = {  }, ["fields"] = {  } }, ["param2"] = 0, ["param1"] = 92 }, { ["y"] = 0, ["x"] = 6, ["name"] = "default:sand", ["z"] = 3, ["meta"] = { ["inventory"] = {  }, ["fields"] = {  } }, ["param2"] = 0, ["param1"] = 0 }, { ["y"] = 0, ["x"] = 6, ["name"] = "default:sand", ["z"] = 4, ["meta"] = { ["inventory"] = {  }, ["fields"] = {  } }, ["param2"] = 0, ["param1"] = 0 }, { ["y"] = 0, ["x"] = 6, ["name"] = "default:sand", ["z"] = 5, ["meta"] = { ["inventory"] = {  }, ["fields"] = {  } }, ["param2"] = 0, ["param1"] = 0 }, { ["y"] = 0, ["x"] = 6, ["name"] = "default:water_flowing", ["z"] = 6, ["meta"] = { ["inventory"] = {  }, ["fields"] = {  } }, ["param2"] = 8, ["param1"] = 0 }, { ["y"] = 0, ["x"] = 6, ["name"] = "default:water_flowing", ["z"] = 7, ["meta"] = { ["inventory"] = {  }, ["fields"] = {  } }, ["param2"] = 1, ["param1"] = 1 }, { ["y"] = 0, ["x"] = 6, ["name"] = "default:water_flowing", ["z"] = 8, ["meta"] = { ["inventory"] = {  }, ["fields"] = {  } }, ["param2"] = 2, ["param1"] = 2 }, { ["y"] = 0, ["x"] = 6, ["name"] = "default:water_flowing", ["z"] = 9, ["meta"] = { ["inventory"] = {  }, ["fields"] = {  } }, ["param2"] = 3, ["param1"] = 3 }, { ["y"] = 0, ["x"] = 6, ["name"] = "default:water_flowing", ["z"] = 10, ["meta"] = { ["inventory"] = {  }, ["fields"] = {  } }, ["param2"] = 4, ["param1"] = 4 }, { ["y"] = 0, ["x"] = 6, ["name"] = "default:water_flowing", ["z"] = 11, ["meta"] = { ["inventory"] = {  }, ["fields"] = {  } }, ["param2"] = 5, ["param1"] = 5 }, { ["y"] = 0, ["x"] = 6, ["name"] = "default:water_flowing", ["z"] = 12, ["meta"] = { ["inventory"] = {  }, ["fields"] = {  } }, ["param2"] = 6, ["param1"] = 6 }, { ["y"] = 0, ["x"] = 6, ["name"] = "default:water_flowing", ["z"] = 13, ["meta"] = { ["inventory"] = {  }, ["fields"] = {  } }, ["param2"] = 7, ["param1"] = 7 }, { ["y"] = 0, ["x"] = 6, ["name"] = "default:water_source", ["z"] = 14, ["meta"] = { ["inventory"] = {  }, ["fields"] = {  } }, ["param2"] = 0, ["param1"] = 8 }, { ["y"] = 0, ["x"] = 6, ["name"] = "default:water_source", ["z"] = 15, ["meta"] = { ["inventory"] = {  }, ["fields"] = {  } }, ["param2"] = 0, ["param1"] = 9 }, { ["y"] = 0, ["x"] = 6, ["name"] = "default:water_source", ["z"] = 16, ["meta"] = { ["inventory"] = {  }, ["fields"] = {  } }, ["param2"] = 0, ["param1"] = 10 }, { ["y"] = 0, ["x"] = 6, ["name"] = "default:water_source", ["z"] = 17, ["meta"] = { ["inventory"] = {  }, ["fields"] = {  } }, ["param2"] = 0, ["param1"] = 11 }, { ["y"] = 0, ["x"] = 6, ["name"] = "default:water_source", ["z"] = 18, ["meta"] = { ["inventory"] = {  }, ["fields"] = {  } }, ["param2"] = 0, ["param1"] = 12 }, { ["y"] = 0, ["x"] = 6, ["name"] = "default:water_source", ["z"] = 19, ["meta"] = { ["inventory"] = {  }, ["fields"] = {  } }, ["param2"] = 0, ["param1"] = 12 }, { ["y"] = 1, ["x"] = 6, ["name"] = "default:water_source", ["z"] = 0, ["meta"] = { ["inventory"] = {  }, ["fields"] = {  } }, ["param2"] = 0, ["param1"] = 77 }, { ["y"] = 1, ["x"] = 6, ["name"] = "default:water_source", ["z"] = 1, ["meta"] = { ["inventory"] = {  }, ["fields"] = {  } }, ["param2"] = 0, ["param1"] = 93 }, { ["y"] = 1, ["x"] = 6, ["name"] = "default:water_source", ["z"] = 2, ["meta"] = { ["inventory"] = {  }, ["fields"] = {  } }, ["param2"] = 240, ["param1"] = 109 }, { ["y"] = 1, ["x"] = 6, ["name"] = "default:water_source", ["z"] = 3, ["meta"] = { ["inventory"] = {  }, ["fields"] = {  } }, ["param2"] = 0, ["param1"] = 125 }, { ["y"] = 1, ["x"] = 6, ["name"] = "default:water_source", ["z"] = 4, ["meta"] = { ["inventory"] = {  }, ["fields"] = {  } }, ["param2"] = 0, ["param1"] = 141 }, { ["y"] = 1, ["x"] = 6, ["name"] = "default:wood", ["z"] = 5, ["meta"] = { ["inventory"] = {  }, ["fields"] = {  } }, ["param2"] = 0, ["param1"] = 0 }, { ["y"] = 1, ["x"] = 6, ["name"] = "default:wood", ["z"] = 6, ["meta"] = { ["inventory"] = {  }, ["fields"] = {  } }, ["param2"] = 0, ["param1"] = 0 }, { ["y"] = 1, ["x"] = 6, ["name"] = "default:dirt_with_grass", ["z"] = 7, ["meta"] = { ["inventory"] = {  }, ["fields"] = {  } }, ["param2"] = 0, ["param1"] = 0 }, { ["y"] = 1, ["x"] = 6, ["name"] = "default:dirt_with_grass", ["z"] = 8, ["meta"] = { ["inventory"] = {  }, ["fields"] = {  } }, ["param2"] = 0, ["param1"] = 0 }, { ["y"] = 1, ["x"] = 6, ["name"] = "default:dirt_with_grass", ["z"] = 9, ["meta"] = { ["inventory"] = {  }, ["fields"] = {  } }, ["param2"] = 0, ["param1"] = 0 }, { ["y"] = 1, ["x"] = 6, ["name"] = "default:dirt_with_grass", ["z"] = 10, ["meta"] = { ["inventory"] = {  }, ["fields"] = {  } }, ["param2"] = 0, ["param1"] = 0 }, { ["y"] = 1, ["x"] = 6, ["name"] = "default:dirt_with_grass", ["z"] = 11, ["meta"] = { ["inventory"] = {  }, ["fields"] = {  } }, ["param2"] = 0, ["param1"] = 0 }, { ["y"] = 1, ["x"] = 6, ["name"] = "farming:soil_wet", ["z"] = 12, ["meta"] = { ["inventory"] = {  }, ["fields"] = {  } }, ["param2"] = 0, ["param1"] = 0 }, { ["y"] = 1, ["x"] = 6, ["name"] = "farming:soil_wet", ["z"] = 13, ["meta"] = { ["inventory"] = {  }, ["fields"] = {  } }, ["param2"] = 0, ["param1"] = 0 }, { ["y"] = 1, ["x"] = 6, ["name"] = "farming:soil_wet", ["z"] = 14, ["meta"] = { ["inventory"] = {  }, ["fields"] = {  } }, ["param2"] = 0, ["param1"] = 0 }, { ["y"] = 1, ["x"] = 6, ["name"] = "farming:soil_wet", ["z"] = 15, ["meta"] = { ["inventory"] = {  }, ["fields"] = {  } }, ["param2"] = 0, ["param1"] = 0 }, { ["y"] = 1, ["x"] = 6, ["name"] = "farming:soil_wet", ["z"] = 16, ["meta"] = { ["inventory"] = {  }, ["fields"] = {  } }, ["param2"] = 0, ["param1"] = 0 }, { ["y"] = 1, ["x"] = 6, ["name"] = "farming:soil_wet", ["z"] = 17, ["meta"] = { ["inventory"] = {  }, ["fields"] = {  } }, ["param2"] = 0, ["param1"] = 0 }, { ["y"] = 1, ["x"] = 6, ["name"] = "default:water_source", ["z"] = 18, ["meta"] = { ["inventory"] = {  }, ["fields"] = {  } }, ["param2"] = 240, ["param1"] = 29 }, { ["y"] = 1, ["x"] = 6, ["name"] = "default:water_source", ["z"] = 19, ["meta"] = { ["inventory"] = {  }, ["fields"] = {  } }, ["param2"] = 240, ["param1"] = 13 }, { ["y"] = 2, ["x"] = 6, ["name"] = "homedecor:doghouse_base", ["z"] = 5, ["meta"] = { ["inventory"] = {  }, ["fields"] = {  } }, ["param2"] = 1, ["param1"] = 173 }, { ["y"] = 2, ["x"] = 6, ["name"] = "bushes:raspberry_bush", ["z"] = 8, ["meta"] = { ["inventory"] = {  }, ["fields"] = {  } }, ["param2"] = 0, ["param1"] = 188 }, { ["y"] = 2, ["x"] = 6, ["name"] = "homedecor:welcome_mat_green", ["z"] = 9, ["meta"] = { ["inventory"] = {  }, ["fields"] = {  } }, ["param2"] = 1, ["param1"] = 189 }, { ["y"] = 2, ["x"] = 6, ["name"] = "bushes:gooseberry_bush", ["z"] = 10, ["meta"] = { ["inventory"] = {  }, ["fields"] = {  } }, ["param2"] = 0, ["param1"] = 175 }, { ["y"] = 2, ["x"] = 6, ["name"] = "default:papyrus", ["z"] = 11, ["meta"] = { ["inventory"] = {  }, ["fields"] = {  } }, ["param2"] = 0, ["param1"] = 159 }, { ["y"] = 2, ["x"] = 6, ["name"] = "farming:pumpkin", ["z"] = 12, ["meta"] = { ["inventory"] = {  }, ["fields"] = {  } }, ["param2"] = 0, ["param1"] = 0 }, { ["y"] = 2, ["x"] = 6, ["name"] = "farming:carrot_8", ["z"] = 13, ["meta"] = { ["inventory"] = {  }, ["fields"] = {  } }, ["param2"] = 0, ["param1"] = 125 }, { ["y"] = 2, ["x"] = 6, ["name"] = "farming:raspberry_4", ["z"] = 14, ["meta"] = { ["inventory"] = {  }, ["fields"] = {  } }, ["param2"] = 0, ["param1"] = 109 }, { ["y"] = 2, ["x"] = 6, ["name"] = "farming:tomato_8", ["z"] = 15, ["meta"] = { ["inventory"] = {  }, ["fields"] = {  } }, ["param2"] = 0, ["param1"] = 93 }, { ["y"] = 2, ["x"] = 6, ["name"] = "farming:cotton_8", ["z"] = 16, ["meta"] = { ["inventory"] = {  }, ["fields"] = {  } }, ["param2"] = 0, ["param1"] = 77 }, { ["y"] = 2, ["x"] = 6, ["name"] = "farming:raspberry_4", ["z"] = 17, ["meta"] = { ["inventory"] = {  }, ["fields"] = {  } }, ["param2"] = 0, ["param1"] = 61 }, { ["y"] = 3, ["x"] = 6, ["name"] = "homedecor:doghouse_roof", ["z"] = 5, ["meta"] = { ["inventory"] = {  }, ["fields"] = {  } }, ["param2"] = 1, ["param1"] = 189 }, { ["y"] = 3, ["x"] = 6, ["name"] = "default:sign_wall", ["z"] = 6, ["meta"] = { ["inventory"] = {  }, ["fields"] = { ["infotext"] = " ---< chez bernard, chien gentil >---\
PS : ne lui donnez pas a manger, surtout  du poissons !!\
 >< ((( °> ", ["text"] = " ---< chez bernard, chien gentil >---\
PS : ne lui donnez pas a manger, surtout  du poissons !!\
 >< ((( °>", ["formspec"] = "size[6,4]textarea[0,0;6.5,3;text;;${text}]button_exit[2,3;2,1;ok;Write]background[-0.5,-0.5;7,5;bg_signs_lib.jpg]", ["__signslib_new_format"] = "1" } }, ["param2"] = 1, ["param1"] = 204 }, { ["y"] = 3, ["x"] = 6, ["name"] = "torches:wand", ["z"] = 7, ["meta"] = { ["inventory"] = {  }, ["fields"] = {  } }, ["param2"] = 1, ["param1"] = 0 }, { ["y"] = 3, ["x"] = 6, ["name"] = "default:sign_wall", ["z"] = 10, ["meta"] = { ["inventory"] = {  }, ["fields"] = { ["infotext"] = " ---=== chez lapotte ===--- ", ["text"] = " ---=== chez lapotte ===---", ["formspec"] = "size[6,4]textarea[0,0;6.5,3;text;;${text}]button_exit[2,3;2,1;ok;Write]background[-0.5,-0.5;7,5;bg_signs_lib.jpg]", ["__signslib_new_format"] = "1" } }, ["param2"] = 1, ["param1"] = 191 }, { ["y"] = 3, ["x"] = 6, ["name"] = "default:papyrus", ["z"] = 11, ["meta"] = { ["inventory"] = {  }, ["fields"] = {  } }, ["param2"] = 0, ["param1"] = 175 }, { ["y"] = 4, ["x"] = 6, ["name"] = "default:papyrus", ["z"] = 11, ["meta"] = { ["inventory"] = {  }, ["fields"] = {  } }, ["param2"] = 0, ["param1"] = 191 }, { ["y"] = 4, ["x"] = 6, ["name"] = "default:sign_wall", ["z"] = 12, ["meta"] = { ["inventory"] = {  }, ["fields"] = { ["infotext"] = "<--- enclos / culture de champignons ", ["text"] = "<--- enclos / culture de champignons\
\
\
\
\
", ["formspec"] = "size[6,4]textarea[0,0;6.5,3;text;;${text}]button_exit[2,3;2,1;ok;Write]background[-0.5,-0.5;7,5;bg_signs_lib.jpg]", ["__signslib_new_format"] = "1" } }, ["param2"] = 1, ["param1"] = 175 }, { ["y"] = 5, ["x"] = 6, ["name"] = "default:leaves", ["z"] = 6, ["meta"] = { ["inventory"] = {  }, ["fields"] = {  } }, ["param2"] = 0, ["param1"] = 173 }, { ["y"] = 5, ["x"] = 6, ["name"] = "default:leaves", ["z"] = 7, ["meta"] = { ["inventory"] = {  }, ["fields"] = {  } }, ["param2"] = 0, ["param1"] = 188 }, { ["y"] = 5, ["x"] = 6, ["name"] = "default:leaves", ["z"] = 8, ["meta"] = { ["inventory"] = {  }, ["fields"] = {  } }, ["param2"] = 0, ["param1"] = 188 }, { ["y"] = 5, ["x"] = 6, ["name"] = "default:papyrus", ["z"] = 11, ["meta"] = { ["inventory"] = {  }, ["fields"] = {  } }, ["param2"] = 0, ["param1"] = 175 }, { ["y"] = 6, ["x"] = 6, ["name"] = "default:leaves", ["z"] = 6, ["meta"] = { ["inventory"] = {  }, ["fields"] = {  } }, ["param2"] = 0, ["param1"] = 157 }, { ["y"] = 6, ["x"] = 6, ["name"] = "default:apple", ["z"] = 7, ["meta"] = { ["inventory"] = {  }, ["fields"] = {  } }, ["param2"] = 0, ["param1"] = 172 }, { ["y"] = 6, ["x"] = 6, ["name"] = "default:apple", ["z"] = 8, ["meta"] = { ["inventory"] = {  }, ["fields"] = {  } }, ["param2"] = 0, ["param1"] = 172 }, { ["y"] = 6, ["x"] = 6, ["name"] = "default:leaves", ["z"] = 9, ["meta"] = { ["inventory"] = {  }, ["fields"] = {  } }, ["param2"] = 0, ["param1"] = 189 }, { ["y"] = 7, ["x"] = 6, ["name"] = "default:leaves", ["z"] = 6, ["meta"] = { ["inventory"] = {  }, ["fields"] = {  } }, ["param2"] = 0, ["param1"] = 141 }, { ["y"] = 7, ["x"] = 6, ["name"] = "default:leaves", ["z"] = 7, ["meta"] = { ["inventory"] = {  }, ["fields"] = {  } }, ["param2"] = 0, ["param1"] = 157 }, { ["y"] = 7, ["x"] = 6, ["name"] = "default:leaves", ["z"] = 8, ["meta"] = { ["inventory"] = {  }, ["fields"] = {  } }, ["param2"] = 0, ["param1"] = 156 }, { ["y"] = 7, ["x"] = 6, ["name"] = "default:leaves", ["z"] = 9, ["meta"] = { ["inventory"] = {  }, ["fields"] = {  } }, ["param2"] = 0, ["param1"] = 173 }, { ["y"] = 8, ["x"] = 6, ["name"] = "default:leaves", ["z"] = 8, ["meta"] = { ["inventory"] = {  }, ["fields"] = {  } }, ["param2"] = 0, ["param1"] = 141 }, { ["y"] = 8, ["x"] = 6, ["name"] = "default:leaves", ["z"] = 9, ["meta"] = { ["inventory"] = {  }, ["fields"] = {  } }, ["param2"] = 0, ["param1"] = 157 }, { ["y"] = 0, ["x"] = 7, ["name"] = "default:water_source", ["z"] = 0, ["meta"] = { ["inventory"] = {  }, ["fields"] = {  } }, ["param2"] = 0, ["param1"] = 44 }, { ["y"] = 0, ["x"] = 7, ["name"] = "default:water_source", ["z"] = 1, ["meta"] = { ["inventory"] = {  }, ["fields"] = {  } }, ["param2"] = 240, ["param1"] = 60 }, { ["y"] = 0, ["x"] = 7, ["name"] = "default:water_source", ["z"] = 2, ["meta"] = { ["inventory"] = {  }, ["fields"] = {  } }, ["param2"] = 0, ["param1"] = 76 }, { ["y"] = 0, ["x"] = 7, ["name"] = "default:sand", ["z"] = 3, ["meta"] = { ["inventory"] = {  }, ["fields"] = {  } }, ["param2"] = 0, ["param1"] = 0 }, { ["y"] = 0, ["x"] = 7, ["name"] = "default:sand", ["z"] = 4, ["meta"] = { ["inventory"] = {  }, ["fields"] = {  } }, ["param2"] = 0, ["param1"] = 0 }, { ["y"] = 0, ["x"] = 7, ["name"] = "default:sand", ["z"] = 5, ["meta"] = { ["inventory"] = {  }, ["fields"] = {  } }, ["param2"] = 0, ["param1"] = 0 }, { ["y"] = 0, ["x"] = 7, ["name"] = "default:sand", ["z"] = 6, ["meta"] = { ["inventory"] = {  }, ["fields"] = {  } }, ["param2"] = 0, ["param1"] = 0 }, { ["y"] = 0, ["x"] = 7, ["name"] = "default:sand", ["z"] = 7, ["meta"] = { ["inventory"] = {  }, ["fields"] = {  } }, ["param2"] = 0, ["param1"] = 0 }, { ["y"] = 0, ["x"] = 7, ["name"] = "default:sand", ["z"] = 8, ["meta"] = { ["inventory"] = {  }, ["fields"] = {  } }, ["param2"] = 0, ["param1"] = 0 }, { ["y"] = 0, ["x"] = 7, ["name"] = "default:sand", ["z"] = 9, ["meta"] = { ["inventory"] = {  }, ["fields"] = {  } }, ["param2"] = 0, ["param1"] = 0 }, { ["y"] = 0, ["x"] = 7, ["name"] = "default:sand", ["z"] = 10, ["meta"] = { ["inventory"] = {  }, ["fields"] = {  } }, ["param2"] = 0, ["param1"] = 0 }, { ["y"] = 0, ["x"] = 7, ["name"] = "default:sand", ["z"] = 11, ["meta"] = { ["inventory"] = {  }, ["fields"] = {  } }, ["param2"] = 0, ["param1"] = 0 }, { ["y"] = 0, ["x"] = 7, ["name"] = "default:sand", ["z"] = 12, ["meta"] = { ["inventory"] = {  }, ["fields"] = {  } }, ["param2"] = 0, ["param1"] = 0 }, { ["y"] = 0, ["x"] = 7, ["name"] = "default:sand", ["z"] = 13, ["meta"] = { ["inventory"] = {  }, ["fields"] = {  } }, ["param2"] = 0, ["param1"] = 0 }, { ["y"] = 0, ["x"] = 7, ["name"] = "default:water_source", ["z"] = 14, ["meta"] = { ["inventory"] = {  }, ["fields"] = {  } }, ["param2"] = 0, ["param1"] = 7 }, { ["y"] = 0, ["x"] = 7, ["name"] = "default:water_source", ["z"] = 15, ["meta"] = { ["inventory"] = {  }, ["fields"] = {  } }, ["param2"] = 0, ["param1"] = 8 }, { ["y"] = 0, ["x"] = 7, ["name"] = "default:water_source", ["z"] = 16, ["meta"] = { ["inventory"] = {  }, ["fields"] = {  } }, ["param2"] = 0, ["param1"] = 9 }, { ["y"] = 0, ["x"] = 7, ["name"] = "default:water_source", ["z"] = 17, ["meta"] = { ["inventory"] = {  }, ["fields"] = {  } }, ["param2"] = 0, ["param1"] = 10 }, { ["y"] = 0, ["x"] = 7, ["name"] = "default:water_source", ["z"] = 18, ["meta"] = { ["inventory"] = {  }, ["fields"] = {  } }, ["param2"] = 0, ["param1"] = 11 }, { ["y"] = 0, ["x"] = 7, ["name"] = "default:water_source", ["z"] = 19, ["meta"] = { ["inventory"] = {  }, ["fields"] = {  } }, ["param2"] = 0, ["param1"] = 12 }, { ["y"] = 1, ["x"] = 7, ["name"] = "default:water_source", ["z"] = 0, ["meta"] = { ["inventory"] = {  }, ["fields"] = {  } }, ["param2"] = 0, ["param1"] = 61 }, { ["y"] = 1, ["x"] = 7, ["name"] = "default:water_source", ["z"] = 1, ["meta"] = { ["inventory"] = {  }, ["fields"] = {  } }, ["param2"] = 0, ["param1"] = 77 }, { ["y"] = 1, ["x"] = 7, ["name"] = "default:water_source", ["z"] = 2, ["meta"] = { ["inventory"] = {  }, ["fields"] = {  } }, ["param2"] = 240, ["param1"] = 93 }, { ["y"] = 1, ["x"] = 7, ["name"] = "default:water_source", ["z"] = 3, ["meta"] = { ["inventory"] = {  }, ["fields"] = {  } }, ["param2"] = 0, ["param1"] = 109 }, { ["y"] = 1, ["x"] = 7, ["name"] = "default:water_source", ["z"] = 4, ["meta"] = { ["inventory"] = {  }, ["fields"] = {  } }, ["param2"] = 0, ["param1"] = 125 }, { ["y"] = 1, ["x"] = 7, ["name"] = "default:water_source", ["z"] = 5, ["meta"] = { ["inventory"] = {  }, ["fields"] = {  } }, ["param2"] = 240, ["param1"] = 108 }, { ["y"] = 1, ["x"] = 7, ["name"] = "default:water_source", ["z"] = 6, ["meta"] = { ["inventory"] = {  }, ["fields"] = {  } }, ["param2"] = 240, ["param1"] = 91 }, { ["y"] = 1, ["x"] = 7, ["name"] = "default:water_source", ["z"] = 7, ["meta"] = { ["inventory"] = {  }, ["fields"] = {  } }, ["param2"] = 240, ["param1"] = 74 }, { ["y"] = 1, ["x"] = 7, ["name"] = "default:water_source", ["z"] = 8, ["meta"] = { ["inventory"] = {  }, ["fields"] = {  } }, ["param2"] = 240, ["param1"] = 57 }, { ["y"] = 1, ["x"] = 7, ["name"] = "default:sandstone", ["z"] = 9, ["meta"] = { ["inventory"] = {  }, ["fields"] = {  } }, ["param2"] = 0, ["param1"] = 0 }, { ["y"] = 1, ["x"] = 7, ["name"] = "default:water_source", ["z"] = 10, ["meta"] = { ["inventory"] = {  }, ["fields"] = {  } }, ["param2"] = 240, ["param1"] = 5 }, { ["y"] = 1, ["x"] = 7, ["name"] = "default:water_source", ["z"] = 11, ["meta"] = { ["inventory"] = {  }, ["fields"] = {  } }, ["param2"] = 240, ["param1"] = 6 }, { ["y"] = 1, ["x"] = 7, ["name"] = "default:water_source", ["z"] = 12, ["meta"] = { ["inventory"] = {  }, ["fields"] = {  } }, ["param2"] = 240, ["param1"] = 7 }, { ["y"] = 1, ["x"] = 7, ["name"] = "default:dirt_with_grass", ["z"] = 13, ["meta"] = { ["inventory"] = {  }, ["fields"] = {  } }, ["param2"] = 0, ["param1"] = 0 }, { ["y"] = 1, ["x"] = 7, ["name"] = "default:dirt_with_grass", ["z"] = 14, ["meta"] = { ["inventory"] = {  }, ["fields"] = {  } }, ["param2"] = 0, ["param1"] = 0 }, { ["y"] = 1, ["x"] = 7, ["name"] = "default:dirt_with_grass", ["z"] = 15, ["meta"] = { ["inventory"] = {  }, ["fields"] = {  } }, ["param2"] = 0, ["param1"] = 0 }, { ["y"] = 1, ["x"] = 7, ["name"] = "default:dirt_with_grass", ["z"] = 16, ["meta"] = { ["inventory"] = {  }, ["fields"] = {  } }, ["param2"] = 0, ["param1"] = 0 }, { ["y"] = 1, ["x"] = 7, ["name"] = "default:dirt_with_grass", ["z"] = 17, ["meta"] = { ["inventory"] = {  }, ["fields"] = {  } }, ["param2"] = 0, ["param1"] = 0 }, { ["y"] = 1, ["x"] = 7, ["name"] = "default:dirt_with_grass", ["z"] = 18, ["meta"] = { ["inventory"] = {  }, ["fields"] = {  } }, ["param2"] = 0, ["param1"] = 0 }, { ["y"] = 1, ["x"] = 7, ["name"] = "default:water_source", ["z"] = 19, ["meta"] = { ["inventory"] = {  }, ["fields"] = {  } }, ["param2"] = 0, ["param1"] = 13 }, { ["y"] = 2, ["x"] = 7, ["name"] = "default:wood", ["z"] = 5, ["meta"] = { ["inventory"] = {  }, ["fields"] = {  } }, ["param2"] = 0, ["param1"] = 0 }, { ["y"] = 2, ["x"] = 7, ["name"] = "default:wood", ["z"] = 6, ["meta"] = { ["inventory"] = {  }, ["fields"] = {  } }, ["param2"] = 0, ["param1"] = 0 }, { ["y"] = 2, ["x"] = 7, ["name"] = "default:wood", ["z"] = 7, ["meta"] = { ["inventory"] = {  }, ["fields"] = {  } }, ["param2"] = 0, ["param1"] = 0 }, { ["y"] = 2, ["x"] = 7, ["name"] = "default:wood", ["z"] = 8, ["meta"] = { ["inventory"] = {  }, ["fields"] = {  } }, ["param2"] = 0, ["param1"] = 0 }, { ["y"] = 2, ["x"] = 7, ["name"] = "doors:door_wood_b_2", ["z"] = 9, ["meta"] = { ["inventory"] = {  }, ["fields"] = {  } }, ["param2"] = 2, ["param1"] = 205 }, { ["y"] = 2, ["x"] = 7, ["name"] = "default:wood", ["z"] = 10, ["meta"] = { ["inventory"] = {  }, ["fields"] = {  } }, ["param2"] = 0, ["param1"] = 0 }, { ["y"] = 2, ["x"] = 7, ["name"] = "default:wood", ["z"] = 11, ["meta"] = { ["inventory"] = {  }, ["fields"] = {  } }, ["param2"] = 0, ["param1"] = 0 }, { ["y"] = 2, ["x"] = 7, ["name"] = "default:wood", ["z"] = 12, ["meta"] = { ["inventory"] = {  }, ["fields"] = {  } }, ["param2"] = 0, ["param1"] = 0 }, { ["y"] = 2, ["x"] = 7, ["name"] = "default:glass", ["z"] = 13, ["meta"] = { ["inventory"] = {  }, ["fields"] = {  } }, ["param2"] = 0, ["param1"] = 111 }, { ["y"] = 2, ["x"] = 7, ["name"] = "default:glass", ["z"] = 14, ["meta"] = { ["inventory"] = {  }, ["fields"] = {  } }, ["param2"] = 0, ["param1"] = 95 }, { ["y"] = 2, ["x"] = 7, ["name"] = "doors:door_wood_b_1", ["z"] = 15, ["meta"] = { ["inventory"] = {  }, ["fields"] = {  } }, ["param2"] = 3, ["param1"] = 77 }, { ["y"] = 2, ["x"] = 7, ["name"] = "doors:door_wood_b_2", ["z"] = 16, ["meta"] = { ["inventory"] = {  }, ["fields"] = {  } }, ["param2"] = 3, ["param1"] = 61 }, { ["y"] = 2, ["x"] = 7, ["name"] = "default:glass", ["z"] = 17, ["meta"] = { ["inventory"] = {  }, ["fields"] = {  } }, ["param2"] = 0, ["param1"] = 47 }, { ["y"] = 2, ["x"] = 7, ["name"] = "default:glass", ["z"] = 18, ["meta"] = { ["inventory"] = {  }, ["fields"] = {  } }, ["param2"] = 0, ["param1"] = 31 }, { ["y"] = 3, ["x"] = 7, ["name"] = "default:wood", ["z"] = 5, ["meta"] = { ["inventory"] = {  }, ["fields"] = {  } }, ["param2"] = 0, ["param1"] = 0 }, { ["y"] = 3, ["x"] = 7, ["name"] = "default:wood", ["z"] = 6, ["meta"] = { ["inventory"] = {  }, ["fields"] = {  } }, ["param2"] = 0, ["param1"] = 0 }, { ["y"] = 3, ["x"] = 7, ["name"] = "default:wood", ["z"] = 7, ["meta"] = { ["inventory"] = {  }, ["fields"] = {  } }, ["param2"] = 0, ["param1"] = 0 }, { ["y"] = 3, ["x"] = 7, ["name"] = "default:wood", ["z"] = 8, ["meta"] = { ["inventory"] = {  }, ["fields"] = {  } }, ["param2"] = 0, ["param1"] = 0 }, { ["y"] = 3, ["x"] = 7, ["name"] = "doors:door_wood_t_2", ["z"] = 9, ["meta"] = { ["inventory"] = {  }, ["fields"] = {  } }, ["param2"] = 2, ["param1"] = 221 }, { ["y"] = 3, ["x"] = 7, ["name"] = "default:wood", ["z"] = 10, ["meta"] = { ["inventory"] = {  }, ["fields"] = {  } }, ["param2"] = 0, ["param1"] = 0 }, { ["y"] = 3, ["x"] = 7, ["name"] = "default:wood", ["z"] = 11, ["meta"] = { ["inventory"] = {  }, ["fields"] = {  } }, ["param2"] = 0, ["param1"] = 0 }, { ["y"] = 3, ["x"] = 7, ["name"] = "default:wood", ["z"] = 12, ["meta"] = { ["inventory"] = {  }, ["fields"] = {  } }, ["param2"] = 0, ["param1"] = 0 }, { ["y"] = 3, ["x"] = 7, ["name"] = "default:glass", ["z"] = 13, ["meta"] = { ["inventory"] = {  }, ["fields"] = {  } }, ["param2"] = 0, ["param1"] = 127 }, { ["y"] = 3, ["x"] = 7, ["name"] = "default:glass", ["z"] = 14, ["meta"] = { ["inventory"] = {  }, ["fields"] = {  } }, ["param2"] = 0, ["param1"] = 111 }, { ["y"] = 3, ["x"] = 7, ["name"] = "doors:door_wood_t_1", ["z"] = 15, ["meta"] = { ["inventory"] = {  }, ["fields"] = {  } }, ["param2"] = 3, ["param1"] = 93 }, { ["y"] = 3, ["x"] = 7, ["name"] = "doors:door_wood_t_2", ["z"] = 16, ["meta"] = { ["inventory"] = {  }, ["fields"] = {  } }, ["param2"] = 3, ["param1"] = 77 }, { ["y"] = 3, ["x"] = 7, ["name"] = "default:glass", ["z"] = 17, ["meta"] = { ["inventory"] = {  }, ["fields"] = {  } }, ["param2"] = 0, ["param1"] = 63 }, { ["y"] = 3, ["x"] = 7, ["name"] = "default:glass", ["z"] = 18, ["meta"] = { ["inventory"] = {  }, ["fields"] = {  } }, ["param2"] = 0, ["param1"] = 47 }, { ["y"] = 4, ["x"] = 7, ["name"] = "default:wood", ["z"] = 5, ["meta"] = { ["inventory"] = {  }, ["fields"] = {  } }, ["param2"] = 0, ["param1"] = 0 }, { ["y"] = 4, ["x"] = 7, ["name"] = "default:wood", ["z"] = 6, ["meta"] = { ["inventory"] = {  }, ["fields"] = {  } }, ["param2"] = 0, ["param1"] = 0 }, { ["y"] = 4, ["x"] = 7, ["name"] = "default:wood", ["z"] = 7, ["meta"] = { ["inventory"] = {  }, ["fields"] = {  } }, ["param2"] = 0, ["param1"] = 0 }, { ["y"] = 4, ["x"] = 7, ["name"] = "default:wood", ["z"] = 8, ["meta"] = { ["inventory"] = {  }, ["fields"] = {  } }, ["param2"] = 0, ["param1"] = 0 }, { ["y"] = 4, ["x"] = 7, ["name"] = "default:nyancat", ["z"] = 9, ["meta"] = { ["inventory"] = {  }, ["fields"] = {  } }, ["param2"] = 1, ["param1"] = 0 }, { ["y"] = 4, ["x"] = 7, ["name"] = "default:wood", ["z"] = 10, ["meta"] = { ["inventory"] = {  }, ["fields"] = {  } }, ["param2"] = 0, ["param1"] = 0 }, { ["y"] = 4, ["x"] = 7, ["name"] = "default:wood", ["z"] = 11, ["meta"] = { ["inventory"] = {  }, ["fields"] = {  } }, ["param2"] = 0, ["param1"] = 0 }, { ["y"] = 4, ["x"] = 7, ["name"] = "default:wood", ["z"] = 12, ["meta"] = { ["inventory"] = {  }, ["fields"] = {  } }, ["param2"] = 0, ["param1"] = 0 }, { ["y"] = 4, ["x"] = 7, ["name"] = "default:glass", ["z"] = 13, ["meta"] = { ["inventory"] = {  }, ["fields"] = {  } }, ["param2"] = 0, ["param1"] = 143 }, { ["y"] = 4, ["x"] = 7, ["name"] = "default:glass", ["z"] = 14, ["meta"] = { ["inventory"] = {  }, ["fields"] = {  } }, ["param2"] = 0, ["param1"] = 127 }, { ["y"] = 4, ["x"] = 7, ["name"] = "default:glass", ["z"] = 15, ["meta"] = { ["inventory"] = {  }, ["fields"] = {  } }, ["param2"] = 0, ["param1"] = 111 }, { ["y"] = 4, ["x"] = 7, ["name"] = "default:glass", ["z"] = 16, ["meta"] = { ["inventory"] = {  }, ["fields"] = {  } }, ["param2"] = 0, ["param1"] = 95 }, { ["y"] = 4, ["x"] = 7, ["name"] = "default:glass", ["z"] = 17, ["meta"] = { ["inventory"] = {  }, ["fields"] = {  } }, ["param2"] = 0, ["param1"] = 79 }, { ["y"] = 4, ["x"] = 7, ["name"] = "default:glass", ["z"] = 18, ["meta"] = { ["inventory"] = {  }, ["fields"] = {  } }, ["param2"] = 0, ["param1"] = 63 }, { ["y"] = 5, ["x"] = 7, ["name"] = "default:glass", ["z"] = 2, ["meta"] = { ["inventory"] = {  }, ["fields"] = {  } }, ["param2"] = 0, ["param1"] = 95 }, { ["y"] = 5, ["x"] = 7, ["name"] = "default:glass", ["z"] = 3, ["meta"] = { ["inventory"] = {  }, ["fields"] = {  } }, ["param2"] = 0, ["param1"] = 111 }, { ["y"] = 5, ["x"] = 7, ["name"] = "default:glass", ["z"] = 4, ["meta"] = { ["inventory"] = {  }, ["fields"] = {  } }, ["param2"] = 0, ["param1"] = 127 }, { ["y"] = 5, ["x"] = 7, ["name"] = "default:wood", ["z"] = 5, ["meta"] = { ["inventory"] = {  }, ["fields"] = {  } }, ["param2"] = 0, ["param1"] = 0 }, { ["y"] = 5, ["x"] = 7, ["name"] = "default:wood", ["z"] = 6, ["meta"] = { ["inventory"] = {  }, ["fields"] = {  } }, ["param2"] = 0, ["param1"] = 0 }, { ["y"] = 5, ["x"] = 7, ["name"] = "default:wood", ["z"] = 7, ["meta"] = { ["inventory"] = {  }, ["fields"] = {  } }, ["param2"] = 0, ["param1"] = 0 }, { ["y"] = 5, ["x"] = 7, ["name"] = "default:wood", ["z"] = 8, ["meta"] = { ["inventory"] = {  }, ["fields"] = {  } }, ["param2"] = 0, ["param1"] = 0 }, { ["y"] = 5, ["x"] = 7, ["name"] = "default:wood", ["z"] = 9, ["meta"] = { ["inventory"] = {  }, ["fields"] = {  } }, ["param2"] = 0, ["param1"] = 0 }, { ["y"] = 5, ["x"] = 7, ["name"] = "default:wood", ["z"] = 10, ["meta"] = { ["inventory"] = {  }, ["fields"] = {  } }, ["param2"] = 0, ["param1"] = 0 }, { ["y"] = 5, ["x"] = 7, ["name"] = "default:wood", ["z"] = 11, ["meta"] = { ["inventory"] = {  }, ["fields"] = {  } }, ["param2"] = 0, ["param1"] = 0 }, { ["y"] = 5, ["x"] = 7, ["name"] = "default:wood", ["z"] = 12, ["meta"] = { ["inventory"] = {  }, ["fields"] = {  } }, ["param2"] = 0, ["param1"] = 0 }, { ["y"] = 6, ["x"] = 7, ["name"] = "fences:fence_wood_2", ["z"] = 2, ["meta"] = { ["inventory"] = {  }, ["fields"] = {  } }, ["param2"] = 0, ["param1"] = 79 }, { ["y"] = 6, ["x"] = 7, ["name"] = "fences:fence_wood_3", ["z"] = 3, ["meta"] = { ["inventory"] = {  }, ["fields"] = {  } }, ["param2"] = 0, ["param1"] = 95 }, { ["y"] = 6, ["x"] = 7, ["name"] = "fences:fence_wood_1", ["z"] = 4, ["meta"] = { ["inventory"] = {  }, ["fields"] = {  } }, ["param2"] = 0, ["param1"] = 111 }, { ["y"] = 6, ["x"] = 7, ["name"] = "default:leaves", ["z"] = 7, ["meta"] = { ["inventory"] = {  }, ["fields"] = {  } }, ["param2"] = 0, ["param1"] = 157 }, { ["y"] = 6, ["x"] = 7, ["name"] = "default:leaves", ["z"] = 8, ["meta"] = { ["inventory"] = {  }, ["fields"] = {  } }, ["param2"] = 0, ["param1"] = 157 }, { ["y"] = 6, ["x"] = 7, ["name"] = "default:leaves", ["z"] = 9, ["meta"] = { ["inventory"] = {  }, ["fields"] = {  } }, ["param2"] = 0, ["param1"] = 173 }, { ["y"] = 7, ["x"] = 7, ["name"] = "default:leaves", ["z"] = 7, ["meta"] = { ["inventory"] = {  }, ["fields"] = {  } }, ["param2"] = 0, ["param1"] = 141 }, { ["y"] = 7, ["x"] = 7, ["name"] = "default:leaves", ["z"] = 8, ["meta"] = { ["inventory"] = {  }, ["fields"] = {  } }, ["param2"] = 0, ["param1"] = 141 }, { ["y"] = 7, ["x"] = 7, ["name"] = "default:leaves", ["z"] = 9, ["meta"] = { ["inventory"] = {  }, ["fields"] = {  } }, ["param2"] = 0, ["param1"] = 157 }, { ["y"] = 0, ["x"] = 8, ["name"] = "default:water_source", ["z"] = 0, ["meta"] = { ["inventory"] = {  }, ["fields"] = {  } }, ["param2"] = 0, ["param1"] = 28 }, { ["y"] = 0, ["x"] = 8, ["name"] = "default:water_source", ["z"] = 1, ["meta"] = { ["inventory"] = {  }, ["fields"] = {  } }, ["param2"] = 0, ["param1"] = 44 }, { ["y"] = 0, ["x"] = 8, ["name"] = "default:water_source", ["z"] = 2, ["meta"] = { ["inventory"] = {  }, ["fields"] = {  } }, ["param2"] = 0, ["param1"] = 59 }, { ["y"] = 0, ["x"] = 8, ["name"] = "default:sand", ["z"] = 3, ["meta"] = { ["inventory"] = {  }, ["fields"] = {  } }, ["param2"] = 0, ["param1"] = 0 }, { ["y"] = 0, ["x"] = 8, ["name"] = "default:sand", ["z"] = 4, ["meta"] = { ["inventory"] = {  }, ["fields"] = {  } }, ["param2"] = 0, ["param1"] = 0 }, { ["y"] = 0, ["x"] = 8, ["name"] = "default:water_source", ["z"] = 5, ["meta"] = { ["inventory"] = {  }, ["fields"] = {  } }, ["param2"] = 240, ["param1"] = 75 }, { ["y"] = 0, ["x"] = 8, ["name"] = "default:water_source", ["z"] = 6, ["meta"] = { ["inventory"] = {  }, ["fields"] = {  } }, ["param2"] = 240, ["param1"] = 58 }, { ["y"] = 0, ["x"] = 8, ["name"] = "default:water_source", ["z"] = 7, ["meta"] = { ["inventory"] = {  }, ["fields"] = {  } }, ["param2"] = 240, ["param1"] = 41 }, { ["y"] = 0, ["x"] = 8, ["name"] = "default:water_source", ["z"] = 8, ["meta"] = { ["inventory"] = {  }, ["fields"] = {  } }, ["param2"] = 240, ["param1"] = 24 }, { ["y"] = 0, ["x"] = 8, ["name"] = "default:water_source", ["z"] = 9, ["meta"] = { ["inventory"] = {  }, ["fields"] = {  } }, ["param2"] = 240, ["param1"] = 7 }, { ["y"] = 0, ["x"] = 8, ["name"] = "default:water_source", ["z"] = 10, ["meta"] = { ["inventory"] = {  }, ["fields"] = {  } }, ["param2"] = 240, ["param1"] = 7 }, { ["y"] = 0, ["x"] = 8, ["name"] = "default:water_source", ["z"] = 11, ["meta"] = { ["inventory"] = {  }, ["fields"] = {  } }, ["param2"] = 240, ["param1"] = 7 }, { ["y"] = 0, ["x"] = 8, ["name"] = "default:water_source", ["z"] = 12, ["meta"] = { ["inventory"] = {  }, ["fields"] = {  } }, ["param2"] = 240, ["param1"] = 7 }, { ["y"] = 0, ["x"] = 8, ["name"] = "default:water_source", ["z"] = 13, ["meta"] = { ["inventory"] = {  }, ["fields"] = {  } }, ["param2"] = 0, ["param1"] = 6 }, { ["y"] = 0, ["x"] = 8, ["name"] = "default:water_source", ["z"] = 14, ["meta"] = { ["inventory"] = {  }, ["fields"] = {  } }, ["param2"] = 0, ["param1"] = 7 }, { ["y"] = 0, ["x"] = 8, ["name"] = "default:water_source", ["z"] = 15, ["meta"] = { ["inventory"] = {  }, ["fields"] = {  } }, ["param2"] = 0, ["param1"] = 8 }, { ["y"] = 0, ["x"] = 8, ["name"] = "default:water_source", ["z"] = 16, ["meta"] = { ["inventory"] = {  }, ["fields"] = {  } }, ["param2"] = 0, ["param1"] = 9 }, { ["y"] = 0, ["x"] = 8, ["name"] = "default:water_source", ["z"] = 17, ["meta"] = { ["inventory"] = {  }, ["fields"] = {  } }, ["param2"] = 0, ["param1"] = 10 }, { ["y"] = 0, ["x"] = 8, ["name"] = "default:water_source", ["z"] = 18, ["meta"] = { ["inventory"] = {  }, ["fields"] = {  } }, ["param2"] = 0, ["param1"] = 11 }, { ["y"] = 0, ["x"] = 8, ["name"] = "default:water_source", ["z"] = 19, ["meta"] = { ["inventory"] = {  }, ["fields"] = {  } }, ["param2"] = 0, ["param1"] = 12 }, { ["y"] = 1, ["x"] = 8, ["name"] = "default:water_source", ["z"] = 0, ["meta"] = { ["inventory"] = {  }, ["fields"] = {  } }, ["param2"] = 0, ["param1"] = 45 }, { ["y"] = 1, ["x"] = 8, ["name"] = "default:water_source", ["z"] = 1, ["meta"] = { ["inventory"] = {  }, ["fields"] = {  } }, ["param2"] = 0, ["param1"] = 61 }, { ["y"] = 1, ["x"] = 8, ["name"] = "default:water_source", ["z"] = 2, ["meta"] = { ["inventory"] = {  }, ["fields"] = {  } }, ["param2"] = 0, ["param1"] = 76 }, { ["y"] = 1, ["x"] = 8, ["name"] = "default:water_source", ["z"] = 3, ["meta"] = { ["inventory"] = {  }, ["fields"] = {  } }, ["param2"] = 0, ["param1"] = 93 }, { ["y"] = 1, ["x"] = 8, ["name"] = "default:water_source", ["z"] = 4, ["meta"] = { ["inventory"] = {  }, ["fields"] = {  } }, ["param2"] = 0, ["param1"] = 109 }, { ["y"] = 1, ["x"] = 8, ["name"] = "default:water_source", ["z"] = 5, ["meta"] = { ["inventory"] = {  }, ["fields"] = {  } }, ["param2"] = 240, ["param1"] = 92 }, { ["y"] = 1, ["x"] = 8, ["name"] = "default:sandstone", ["z"] = 6, ["meta"] = { ["inventory"] = {  }, ["fields"] = {  } }, ["param2"] = 0, ["param1"] = 0 }, { ["y"] = 1, ["x"] = 8, ["name"] = "default:sandstone", ["z"] = 7, ["meta"] = { ["inventory"] = {  }, ["fields"] = {  } }, ["param2"] = 0, ["param1"] = 0 }, { ["y"] = 1, ["x"] = 8, ["name"] = "default:sandstone", ["z"] = 8, ["meta"] = { ["inventory"] = {  }, ["fields"] = {  } }, ["param2"] = 0, ["param1"] = 0 }, { ["y"] = 1, ["x"] = 8, ["name"] = "default:sandstone", ["z"] = 9, ["meta"] = { ["inventory"] = {  }, ["fields"] = {  } }, ["param2"] = 0, ["param1"] = 0 }, { ["y"] = 1, ["x"] = 8, ["name"] = "default:sandstone", ["z"] = 10, ["meta"] = { ["inventory"] = {  }, ["fields"] = {  } }, ["param2"] = 0, ["param1"] = 0 }, { ["y"] = 1, ["x"] = 8, ["name"] = "default:sandstone", ["z"] = 11, ["meta"] = { ["inventory"] = {  }, ["fields"] = {  } }, ["param2"] = 0, ["param1"] = 0 }, { ["y"] = 1, ["x"] = 8, ["name"] = "default:water_source", ["z"] = 12, ["meta"] = { ["inventory"] = {  }, ["fields"] = {  } }, ["param2"] = 240, ["param1"] = 8 }, { ["y"] = 1, ["x"] = 8, ["name"] = "default:dirt_with_grass", ["z"] = 13, ["meta"] = { ["inventory"] = {  }, ["fields"] = {  } }, ["param2"] = 0, ["param1"] = 0 }, { ["y"] = 1, ["x"] = 8, ["name"] = "default:dirt_with_grass", ["z"] = 14, ["meta"] = { ["inventory"] = {  }, ["fields"] = {  } }, ["param2"] = 0, ["param1"] = 0 }, { ["y"] = 1, ["x"] = 8, ["name"] = "default:dirt_with_grass", ["z"] = 15, ["meta"] = { ["inventory"] = {  }, ["fields"] = {  } }, ["param2"] = 0, ["param1"] = 0 }, { ["y"] = 1, ["x"] = 8, ["name"] = "default:dirt_with_grass", ["z"] = 16, ["meta"] = { ["inventory"] = {  }, ["fields"] = {  } }, ["param2"] = 0, ["param1"] = 0 }, { ["y"] = 1, ["x"] = 8, ["name"] = "default:dirt_with_grass", ["z"] = 17, ["meta"] = { ["inventory"] = {  }, ["fields"] = {  } }, ["param2"] = 0, ["param1"] = 0 }, { ["y"] = 1, ["x"] = 8, ["name"] = "default:dirt_with_grass", ["z"] = 18, ["meta"] = { ["inventory"] = {  }, ["fields"] = {  } }, ["param2"] = 0, ["param1"] = 0 }, { ["y"] = 1, ["x"] = 8, ["name"] = "default:water_source", ["z"] = 19, ["meta"] = { ["inventory"] = {  }, ["fields"] = {  } }, ["param2"] = 0, ["param1"] = 13 }, { ["y"] = 2, ["x"] = 8, ["name"] = "default:wood", ["z"] = 5, ["meta"] = { ["inventory"] = {  }, ["fields"] = {  } }, ["param2"] = 0, ["param1"] = 0 }, { ["y"] = 2, ["x"] = 8, ["name"] = "default:chest_locked", ["z"] = 6, ["meta"] = { ["inventory"] = { ["main"] = { "", "", "", "bushes:strawberry_bush", "bushes:blueberry_bush", "", "farming:tomato 22", "", "farming_plus:carrot_item 11", "farming:rhubarb 18", "farming:potato 23", "farming:cotton 2", "", "default:apple 14", "default:sapling 36", "", "", "", "", "", "", "bushes:raspberry_bush 2", "", "farming:pumpkin 5", "", "farming:seed_wheat", "", "", "", "", "", "" } }, ["fields"] = { ["owner"] = "lapotte", ["infotext"] = "Locked Chest (owned by lapotte)", ["formspec"] = "size[8,9]listcolors[#606060AA;#808080;#101010;#202020;#FFF]list[nodemeta:-10,2,-53;main;0,0.3;8,4;]list[current_player;main;0,4.85;8,4;]image[0,4.85;1,1;gui_hb_bg.png]image[1,4.85;1,1;gui_hb_bg.png]image[2,4.85;1,1;gui_hb_bg.png]image[3,4.85;1,1;gui_hb_bg.png]image[4,4.85;1,1;gui_hb_bg.png]image[5,4.85;1,1;gui_hb_bg.png]image[6,4.85;1,1;gui_hb_bg.png]image[7,4.85;1,1;gui_hb_bg.png]image[0,5.85;1,1;gui_hb_bg.png]image[1,5.85;1,1;gui_hb_bg.png]image[2,5.85;1,1;gui_hb_bg.png]image[3,5.85;1,1;gui_hb_bg.png]image[4,5.85;1,1;gui_hb_bg.png]image[5,5.85;1,1;gui_hb_bg.png]image[6,5.85;1,1;gui_hb_bg.png]image[7,5.85;1,1;gui_hb_bg.png]" } }, ["param2"] = 3, ["param1"] = 0 }, { ["y"] = 2, ["x"] = 8, ["name"] = "default:furnace", ["z"] = 7, ["meta"] = { ["inventory"] = { ["dst"] = { "", "", "", "" }, ["fuel"] = { "default:coal_lump 76" }, ["src"] = { "" } }, ["fields"] = { ["src_totaltime"] = "0", ["src_time"] = "0", ["fuel_totaltime"] = "40", ["infotext"] = "Furnace is empty", ["formspec"] = "size[8,8.5]listcolors[#606060AA;#808080;#101010;#202020;#FFF]list[current_name;src;2.75, 0.5;1,1;]list[current_name;fuel;2.75,2.5;1,1;]image[2.75,1.5;1,1;default_furnace_fire_bg.png]image[3.75,1.5;1,1;gui_furnace_arrow_bg.png^[transformR270]list[current_name;dst;4.75, 0.96;2,2;]list[current_player;main;0,4.25;8,4;]image[0,4.25;1,1;gui_hb_bg.png]image[1,4.25;1,1;gui_hb_bg.png]image[2,4.25;1,1;gui_hb_bg.png]image[3,4.25;1,1;gui_hb_bg.png]image[4,4.25;1,1;gui_hb_bg.png]image[5,4.25;1,1;gui_hb_bg.png]image[6,4.25;1,1;gui_hb_bg.png]image[7,4.25;1,1;gui_hb_bg.png]image[0,5.25;1,1;gui_hb_bg.png]image[1,5.25;1,1;gui_hb_bg.png]image[2,5.25;1,1;gui_hb_bg.png]image[3,5.25;1,1;gui_hb_bg.png]image[4,5.25;1,1;gui_hb_bg.png]image[5,5.25;1,1;gui_hb_bg.png]image[6,5.25;1,1;gui_hb_bg.png]image[7,5.25;1,1;gui_hb_bg.png]", ["fuel_time"] = "40" } }, ["param2"] = 3, ["param1"] = 0 }, { ["y"] = 2, ["x"] = 8, ["name"] = "homedecor:flower_pot_terracotta", ["z"] = 8, ["meta"] = { ["inventory"] = {  }, ["fields"] = {  } }, ["param2"] = 3, ["param1"] = 173 }, { ["y"] = 2, ["x"] = 8, ["name"] = "default:chest_locked", ["z"] = 11, ["meta"] = { ["inventory"] = { ["main"] = { "homedecor:roof_tile_terracotta 7", "flowers:rose", "dryplants:reedmace_sapling", "trunks:twig_1", "flowers:dandelion_yellow", "default:desert_cobble 4", "mobs:meat_raw 11", "mobs:meat_raw 8", "moretrees:apple_blossoms", "default:nyancat_rainbow 5", "default:glass", "default:sign_wall", "default:cobble 96", "default:ladder 2", "dye:white", "food:rainbow_juice 98", "vessels:drinking_glass 13", "default:junglegrass 7", "default:paper 4", "flowers:viola 2", "farming:wheat 5", "moreores:tin_ingot 39", "default:shovel_wood 1 46824", "default:stick 30", "maptools:copper_coin 542", "moreblocks:slab_wood 6", "mobs:chicken_raw 3", "ferns:horsetail_04", "default:torch 3", "default:sand 14", "mobs:meat_raw 11", "default:cobble 34" } }, ["fields"] = { ["owner"] = "lapotte", ["infotext"] = "Locked Chest (owned by lapotte)", ["formspec"] = "size[8,9]listcolors[#606060AA;#808080;#101010;#202020;#FFF]list[nodemeta:-10,2,-48;main;0,0.3;8,4;]list[current_player;main;0,4.85;8,4;]image[0,4.85;1,1;gui_hb_bg.png]image[1,4.85;1,1;gui_hb_bg.png]image[2,4.85;1,1;gui_hb_bg.png]image[3,4.85;1,1;gui_hb_bg.png]image[4,4.85;1,1;gui_hb_bg.png]image[5,4.85;1,1;gui_hb_bg.png]image[6,4.85;1,1;gui_hb_bg.png]image[7,4.85;1,1;gui_hb_bg.png]image[0,5.85;1,1;gui_hb_bg.png]image[1,5.85;1,1;gui_hb_bg.png]image[2,5.85;1,1;gui_hb_bg.png]image[3,5.85;1,1;gui_hb_bg.png]image[4,5.85;1,1;gui_hb_bg.png]image[5,5.85;1,1;gui_hb_bg.png]image[6,5.85;1,1;gui_hb_bg.png]image[7,5.85;1,1;gui_hb_bg.png]" } }, ["param2"] = 0, ["param1"] = 0 }, { ["y"] = 2, ["x"] = 8, ["name"] = "default:wood", ["z"] = 12, ["meta"] = { ["inventory"] = {  }, ["fields"] = {  } }, ["param2"] = 0, ["param1"] = 0 }, { ["y"] = 2, ["x"] = 8, ["name"] = "default:glass", ["z"] = 18, ["meta"] = { ["inventory"] = {  }, ["fields"] = {  } }, ["param2"] = 0, ["param1"] = 15 }, { ["y"] = 3, ["x"] = 8, ["name"] = "default:wood", ["z"] = 5, ["meta"] = { ["inventory"] = {  }, ["fields"] = {  } }, ["param2"] = 0, ["param1"] = 0 }, { ["y"] = 3, ["x"] = 8, ["name"] = "flowers:tulip", ["z"] = 8, ["meta"] = { ["inventory"] = {  }, ["fields"] = {  } }, ["param2"] = 0, ["param1"] = 189 }, { ["y"] = 3, ["x"] = 8, ["name"] = "default:chest", ["z"] = 11, ["meta"] = { ["inventory"] = { ["main"] = { "bucket:bucket_empty", "default:gravel", "moreores:silver_ingot 12", "default:torch", "default:copper_ingot 13", "default:dirt 2", "default:cobble 99", "farming:wheat 3", "default:glass 6", "default:wood 2", "mobs:chicken_raw 13", "default:dirt", "default:wood 6", "mobs:meat_raw 27", "default:cobble 99", "markers:stone", "dye:yellow 2", "dye:dark_green", "dye:blue", "building_blocks:terrycloth_towel", "default:sword_stone 1 39792", "farming:hoe_wood 1 40662", "", "dye:red", "default:axe_stone 1 61064", "dye:white 3", "default:desert_cobble 4", "default:sandstone", "markers:mark 7", "default:sign_wall", "moreblocks:jungle_stick", "fences:fence_wood 48" } }, ["fields"] = { ["formspec"] = "size[8,9]listcolors[#606060AA;#808080;#101010;#202020;#FFF]list[current_name;main;0,0.3;8,4;]list[current_player;main;0,4.85;8,4;]image[0,4.85;1,1;gui_hb_bg.png]image[1,4.85;1,1;gui_hb_bg.png]image[2,4.85;1,1;gui_hb_bg.png]image[3,4.85;1,1;gui_hb_bg.png]image[4,4.85;1,1;gui_hb_bg.png]image[5,4.85;1,1;gui_hb_bg.png]image[6,4.85;1,1;gui_hb_bg.png]image[7,4.85;1,1;gui_hb_bg.png]image[0,5.85;1,1;gui_hb_bg.png]image[1,5.85;1,1;gui_hb_bg.png]image[2,5.85;1,1;gui_hb_bg.png]image[3,5.85;1,1;gui_hb_bg.png]image[4,5.85;1,1;gui_hb_bg.png]image[5,5.85;1,1;gui_hb_bg.png]image[6,5.85;1,1;gui_hb_bg.png]image[7,5.85;1,1;gui_hb_bg.png]", ["infotext"] = "Chest" } }, ["param2"] = 0, ["param1"] = 0 }, { ["y"] = 3, ["x"] = 8, ["name"] = "default:wood", ["z"] = 12, ["meta"] = { ["inventory"] = {  }, ["fields"] = {  } }, ["param2"] = 0, ["param1"] = 0 }, { ["y"] = 3, ["x"] = 8, ["name"] = "default:glass", ["z"] = 18, ["meta"] = { ["inventory"] = {  }, ["fields"] = {  } }, ["param2"] = 0, ["param1"] = 31 }, { ["y"] = 4, ["x"] = 8, ["name"] = "default:wood", ["z"] = 5, ["meta"] = { ["inventory"] = {  }, ["fields"] = {  } }, ["param2"] = 0, ["param1"] = 0 }, { ["y"] = 4, ["x"] = 8, ["name"] = "default:ladder", ["z"] = 6, ["meta"] = { ["inventory"] = {  }, ["fields"] = {  } }, ["param2"] = 3, ["param1"] = 175 }, { ["y"] = 4, ["x"] = 8, ["name"] = "homedecor:painting_13", ["z"] = 8, ["meta"] = { ["inventory"] = {  }, ["fields"] = {  } }, ["param2"] = 3, ["param1"] = 205 }, { ["y"] = 4, ["x"] = 8, ["name"] = "paintings:green", ["z"] = 9, ["meta"] = { ["inventory"] = {  }, ["fields"] = {  } }, ["param2"] = 3, ["param1"] = 223 }, { ["y"] = 4, ["x"] = 8, ["name"] = "default:bookshelf", ["z"] = 11, ["meta"] = { ["inventory"] = { ["books"] = { "default:book", "", "", "", "", "", "", "", "", "", "", "", "", "", "", "" } }, ["fields"] = { ["formspec"] = "size[8,7;]listcolors[#606060AA;#808080;#101010;#202020;#FFF]list[context;books;0, 0.3;8,2;]list[current_player;main;0,2.85;8,4;]image[0,2.85;1,1;gui_hb_bg.png]image[1,2.85;1,1;gui_hb_bg.png]image[2,2.85;1,1;gui_hb_bg.png]image[3,2.85;1,1;gui_hb_bg.png]image[4,2.85;1,1;gui_hb_bg.png]image[5,2.85;1,1;gui_hb_bg.png]image[6,2.85;1,1;gui_hb_bg.png]image[7,2.85;1,1;gui_hb_bg.png]image[0,3.85;1,1;gui_hb_bg.png]image[1,3.85;1,1;gui_hb_bg.png]image[2,3.85;1,1;gui_hb_bg.png]image[3,3.85;1,1;gui_hb_bg.png]image[4,3.85;1,1;gui_hb_bg.png]image[5,3.85;1,1;gui_hb_bg.png]image[6,3.85;1,1;gui_hb_bg.png]image[7,3.85;1,1;gui_hb_bg.png]" } }, ["param2"] = 0, ["param1"] = 189 }, { ["y"] = 4, ["x"] = 8, ["name"] = "default:wood", ["z"] = 12, ["meta"] = { ["inventory"] = {  }, ["fields"] = {  } }, ["param2"] = 0, ["param1"] = 0 }, { ["y"] = 4, ["x"] = 8, ["name"] = "default:glass", ["z"] = 13, ["meta"] = { ["inventory"] = {  }, ["fields"] = {  } }, ["param2"] = 0, ["param1"] = 127 }, { ["y"] = 4, ["x"] = 8, ["name"] = "default:glass", ["z"] = 14, ["meta"] = { ["inventory"] = {  }, ["fields"] = {  } }, ["param2"] = 0, ["param1"] = 111 }, { ["y"] = 4, ["x"] = 8, ["name"] = "default:glass", ["z"] = 15, ["meta"] = { ["inventory"] = {  }, ["fields"] = {  } }, ["param2"] = 0, ["param1"] = 95 }, { ["y"] = 4, ["x"] = 8, ["name"] = "default:glass", ["z"] = 16, ["meta"] = { ["inventory"] = {  }, ["fields"] = {  } }, ["param2"] = 0, ["param1"] = 79 }, { ["y"] = 4, ["x"] = 8, ["name"] = "default:glass", ["z"] = 17, ["meta"] = { ["inventory"] = {  }, ["fields"] = {  } }, ["param2"] = 0, ["param1"] = 63 }, { ["y"] = 4, ["x"] = 8, ["name"] = "default:glass", ["z"] = 18, ["meta"] = { ["inventory"] = {  }, ["fields"] = {  } }, ["param2"] = 0, ["param1"] = 47 }, { ["y"] = 5, ["x"] = 8, ["name"] = "default:glass", ["z"] = 2, ["meta"] = { ["inventory"] = {  }, ["fields"] = {  } }, ["param2"] = 0, ["param1"] = 77 }, { ["y"] = 5, ["x"] = 8, ["name"] = "default:glass", ["z"] = 3, ["meta"] = { ["inventory"] = {  }, ["fields"] = {  } }, ["param2"] = 0, ["param1"] = 95 }, { ["y"] = 5, ["x"] = 8, ["name"] = "default:glass", ["z"] = 4, ["meta"] = { ["inventory"] = {  }, ["fields"] = {  } }, ["param2"] = 0, ["param1"] = 111 }, { ["y"] = 5, ["x"] = 8, ["name"] = "default:wood", ["z"] = 5, ["meta"] = { ["inventory"] = {  }, ["fields"] = {  } }, ["param2"] = 0, ["param1"] = 0 }, { ["y"] = 5, ["x"] = 8, ["name"] = "default:ladder", ["z"] = 6, ["meta"] = { ["inventory"] = {  }, ["fields"] = {  } }, ["param2"] = 3, ["param1"] = 159 }, { ["y"] = 5, ["x"] = 8, ["name"] = "default:wood", ["z"] = 12, ["meta"] = { ["inventory"] = {  }, ["fields"] = {  } }, ["param2"] = 0, ["param1"] = 0 }, { ["y"] = 6, ["x"] = 8, ["name"] = "seacoral:coralmagenta", ["z"] = 2, ["meta"] = { ["inventory"] = {  }, ["fields"] = {  } }, ["param2"] = 0, ["param1"] = 77 }, { ["y"] = 6, ["x"] = 8, ["name"] = "default:glass", ["z"] = 7, ["meta"] = { ["inventory"] = {  }, ["fields"] = {  } }, ["param2"] = 0, ["param1"] = 159 }, { ["y"] = 6, ["x"] = 8, ["name"] = "default:glass", ["z"] = 8, ["meta"] = { ["inventory"] = {  }, ["fields"] = {  } }, ["param2"] = 0, ["param1"] = 175 }, { ["y"] = 6, ["x"] = 8, ["name"] = "default:glass", ["z"] = 9, ["meta"] = { ["inventory"] = {  }, ["fields"] = {  } }, ["param2"] = 0, ["param1"] = 191 }, { ["y"] = 6, ["x"] = 8, ["name"] = "default:glass", ["z"] = 10, ["meta"] = { ["inventory"] = {  }, ["fields"] = {  } }, ["param2"] = 0, ["param1"] = 175 }, { ["y"] = 6, ["x"] = 8, ["name"] = "default:glass", ["z"] = 11, ["meta"] = { ["inventory"] = {  }, ["fields"] = {  } }, ["param2"] = 0, ["param1"] = 159 }, { ["y"] = 0, ["x"] = 9, ["name"] = "default:water_source", ["z"] = 0, ["meta"] = { ["inventory"] = {  }, ["fields"] = {  } }, ["param2"] = 0, ["param1"] = 12 }, { ["y"] = 0, ["x"] = 9, ["name"] = "default:water_source", ["z"] = 1, ["meta"] = { ["inventory"] = {  }, ["fields"] = {  } }, ["param2"] = 0, ["param1"] = 28 }, { ["y"] = 0, ["x"] = 9, ["name"] = "default:sand", ["z"] = 2, ["meta"] = { ["inventory"] = {  }, ["fields"] = {  } }, ["param2"] = 0, ["param1"] = 0 }, { ["y"] = 0, ["x"] = 9, ["name"] = "default:sand", ["z"] = 3, ["meta"] = { ["inventory"] = {  }, ["fields"] = {  } }, ["param2"] = 0, ["param1"] = 0 }, { ["y"] = 0, ["x"] = 9, ["name"] = "default:sand", ["z"] = 4, ["meta"] = { ["inventory"] = {  }, ["fields"] = {  } }, ["param2"] = 0, ["param1"] = 0 }, { ["y"] = 0, ["x"] = 9, ["name"] = "default:water_source", ["z"] = 5, ["meta"] = { ["inventory"] = {  }, ["fields"] = {  } }, ["param2"] = 240, ["param1"] = 59 }, { ["y"] = 0, ["x"] = 9, ["name"] = "default:water_source", ["z"] = 6, ["meta"] = { ["inventory"] = {  }, ["fields"] = {  } }, ["param2"] = 240, ["param1"] = 42 }, { ["y"] = 0, ["x"] = 9, ["name"] = "default:water_source", ["z"] = 7, ["meta"] = { ["inventory"] = {  }, ["fields"] = {  } }, ["param2"] = 240, ["param1"] = 25 }, { ["y"] = 0, ["x"] = 9, ["name"] = "default:water_source", ["z"] = 8, ["meta"] = { ["inventory"] = {  }, ["fields"] = {  } }, ["param2"] = 240, ["param1"] = 8 }, { ["y"] = 0, ["x"] = 9, ["name"] = "default:water_source", ["z"] = 9, ["meta"] = { ["inventory"] = {  }, ["fields"] = {  } }, ["param2"] = 240, ["param1"] = 8 }, { ["y"] = 0, ["x"] = 9, ["name"] = "default:water_source", ["z"] = 10, ["meta"] = { ["inventory"] = {  }, ["fields"] = {  } }, ["param2"] = 240, ["param1"] = 8 }, { ["y"] = 0, ["x"] = 9, ["name"] = "default:water_source", ["z"] = 11, ["meta"] = { ["inventory"] = {  }, ["fields"] = {  } }, ["param2"] = 0, ["param1"] = 8 }, { ["y"] = 0, ["x"] = 9, ["name"] = "default:water_source", ["z"] = 12, ["meta"] = { ["inventory"] = {  }, ["fields"] = {  } }, ["param2"] = 0, ["param1"] = 8 }, { ["y"] = 0, ["x"] = 9, ["name"] = "default:water_source", ["z"] = 13, ["meta"] = { ["inventory"] = {  }, ["fields"] = {  } }, ["param2"] = 0, ["param1"] = 7 }, { ["y"] = 0, ["x"] = 9, ["name"] = "default:water_source", ["z"] = 14, ["meta"] = { ["inventory"] = {  }, ["fields"] = {  } }, ["param2"] = 0, ["param1"] = 7 }, { ["y"] = 0, ["x"] = 9, ["name"] = "default:water_source", ["z"] = 15, ["meta"] = { ["inventory"] = {  }, ["fields"] = {  } }, ["param2"] = 0, ["param1"] = 8 }, { ["y"] = 0, ["x"] = 9, ["name"] = "default:water_source", ["z"] = 16, ["meta"] = { ["inventory"] = {  }, ["fields"] = {  } }, ["param2"] = 0, ["param1"] = 9 }, { ["y"] = 0, ["x"] = 9, ["name"] = "default:water_source", ["z"] = 17, ["meta"] = { ["inventory"] = {  }, ["fields"] = {  } }, ["param2"] = 0, ["param1"] = 10 }, { ["y"] = 0, ["x"] = 9, ["name"] = "default:water_source", ["z"] = 18, ["meta"] = { ["inventory"] = {  }, ["fields"] = {  } }, ["param2"] = 0, ["param1"] = 11 }, { ["y"] = 0, ["x"] = 9, ["name"] = "default:water_source", ["z"] = 19, ["meta"] = { ["inventory"] = {  }, ["fields"] = {  } }, ["param2"] = 0, ["param1"] = 12 }, { ["y"] = 1, ["x"] = 9, ["name"] = "default:water_source", ["z"] = 0, ["meta"] = { ["inventory"] = {  }, ["fields"] = {  } }, ["param2"] = 0, ["param1"] = 29 }, { ["y"] = 1, ["x"] = 9, ["name"] = "default:water_source", ["z"] = 1, ["meta"] = { ["inventory"] = {  }, ["fields"] = {  } }, ["param2"] = 0, ["param1"] = 45 }, { ["y"] = 1, ["x"] = 9, ["name"] = "default:water_source", ["z"] = 2, ["meta"] = { ["inventory"] = {  }, ["fields"] = {  } }, ["param2"] = 0, ["param1"] = 60 }, { ["y"] = 1, ["x"] = 9, ["name"] = "default:water_source", ["z"] = 3, ["meta"] = { ["inventory"] = {  }, ["fields"] = {  } }, ["param2"] = 0, ["param1"] = 76 },