return { { ["y"] = 0, ["x"] = 0, ["name"] = "default:water_source", ["z"] = 0, ["meta"] = { ["inventory"] = {  }, ["fields"] = {  } }, ["param2"] = 240, ["param1"] = 10 }, { ["y"] = 0, ["x"] = 0, ["name"] = "default:water_source", ["z"] = 1, ["meta"] = { ["inventory"] = {  }, ["fields"] = {  } }, ["param2"] = 240, ["param1"] = 26 }, { ["y"] = 0, ["x"] = 0, ["name"] = "default:water_source", ["z"] = 2, ["meta"] = { ["inventory"] = {  }, ["fields"] = {  } }, ["param2"] = 240, ["param1"] = 42 }, { ["y"] = 0, ["x"] = 0, ["name"] = "default:water_source", ["z"] = 3, ["meta"] = { ["inventory"] = {  }, ["fields"] = {  } }, ["param2"] = 240, ["param1"] = 26 }, { ["y"] = 0, ["x"] = 0, ["name"] = "default:water_source", ["z"] = 4, ["meta"] = { ["inventory"] = {  }, ["fields"] = {  } }, ["param2"] = 240, ["param1"] = 26 }, { ["y"] = 0, ["x"] = 0, ["name"] = "default:stone", ["z"] = 5, ["meta"] = { ["inventory"] = {  }, ["fields"] = {  } }, ["param2"] = 0, ["param1"] = 0 }, { ["y"] = 0, ["x"] = 0, ["name"] = "default:stone", ["z"] = 6, ["meta"] = { ["inventory"] = {  }, ["fields"] = {  } }, ["param2"] = 0, ["param1"] = 0 }, { ["y"] = 0, ["x"] = 0, ["name"] = "default:stone", ["z"] = 7, ["meta"] = { ["inventory"] = {  }, ["fields"] = {  } }, ["param2"] = 0, ["param1"] = 0 }, { ["y"] = 0, ["x"] = 0, ["name"] = "default:stone", ["z"] = 8, ["meta"] = { ["inventory"] = {  }, ["fields"] = {  } }, ["param2"] = 0, ["param1"] = 0 }, { ["y"] = 1, ["x"] = 0, ["name"] = "default:water_source", ["z"] = 0, ["meta"] = { ["inventory"] = {  }, ["fields"] = {  } }, ["param2"] = 0, ["param1"] = 27 }, { ["y"] = 1, ["x"] = 0, ["name"] = "default:water_source", ["z"] = 1, ["meta"] = { ["inventory"] = {  }, ["fields"] = {  } }, ["param2"] = 240, ["param1"] = 43 }, { ["y"] = 1, ["x"] = 0, ["name"] = "default:water_source", ["z"] = 2, ["meta"] = { ["inventory"] = {  }, ["fields"] = {  } }, ["param2"] = 240, ["param1"] = 59 }, { ["y"] = 1, ["x"] = 0, ["name"] = "default:water_source", ["z"] = 3, ["meta"] = { ["inventory"] = {  }, ["fields"] = {  } }, ["param2"] = 240, ["param1"] = 43 }, { ["y"] = 1, ["x"] = 0, ["name"] = "default:water_source", ["z"] = 4, ["meta"] = { ["inventory"] = {  }, ["fields"] = {  } }, ["param2"] = 240, ["param1"] = 43 }, { ["y"] = 1, ["x"] = 0, ["name"] = "default:sand", ["z"] = 5, ["meta"] = { ["inventory"] = {  }, ["fields"] = {  } }, ["param2"] = 0, ["param1"] = 0 }, { ["y"] = 1, ["x"] = 0, ["name"] = "default:stone", ["z"] = 6, ["meta"] = { ["inventory"] = {  }, ["fields"] = {  } }, ["param2"] = 0, ["param1"] = 0 }, { ["y"] = 1, ["x"] = 0, ["name"] = "default:stone", ["z"] = 7, ["meta"] = { ["inventory"] = {  }, ["fields"] = {  } }, ["param2"] = 0, ["param1"] = 0 }, { ["y"] = 1, ["x"] = 0, ["name"] = "default:stone", ["z"] = 8, ["meta"] = { ["inventory"] = {  }, ["fields"] = {  } }, ["param2"] = 0, ["param1"] = 0 }, { ["y"] = 2, ["x"] = 0, ["name"] = "default:water_source", ["z"] = 0, ["meta"] = { ["inventory"] = {  }, ["fields"] = {  } }, ["param2"] = 0, ["param1"] = 44 }, { ["y"] = 2, ["x"] = 0, ["name"] = "default:water_source", ["z"] = 1, ["meta"] = { ["inventory"] = {  }, ["fields"] = {  } }, ["param2"] = 0, ["param1"] = 60 }, { ["y"] = 2, ["x"] = 0, ["name"] = "default:water_source", ["z"] = 2, ["meta"] = { ["inventory"] = {  }, ["fields"] = {  } }, ["param2"] = 0, ["param1"] = 76 }, { ["y"] = 2, ["x"] = 0, ["name"] = "default:water_source", ["z"] = 3, ["meta"] = { ["inventory"] = {  }, ["fields"] = {  } }, ["param2"] = 240, ["param1"] = 60 }, { ["y"] = 2, ["x"] = 0, ["name"] = "default:water_source", ["z"] = 4, ["meta"] = { ["inventory"] = {  }, ["fields"] = {  } }, ["param2"] = 240, ["param1"] = 60 }, { ["y"] = 2, ["x"] = 0, ["name"] = "default:water_source", ["z"] = 5, ["meta"] = { ["inventory"] = {  }, ["fields"] = {  } }, ["param2"] = 240, ["param1"] = 76 }, { ["y"] = 2, ["x"] = 0, ["name"] = "default:water_source", ["z"] = 6, ["meta"] = { ["inventory"] = {  }, ["fields"] = {  } }, ["param2"] = 240, ["param1"] = 92 }, { ["y"] = 2, ["x"] = 0, ["name"] = "default:water_source", ["z"] = 7, ["meta"] = { ["inventory"] = {  }, ["fields"] = {  } }, ["param2"] = 240, ["param1"] = 108 }, { ["y"] = 2, ["x"] = 0, ["name"] = "default:water_source", ["z"] = 8, ["meta"] = { ["inventory"] = {  }, ["fields"] = {  } }, ["param2"] = 240, ["param1"] = 124 }, { ["y"] = 3, ["x"] = 0, ["name"] = "default:water_source", ["z"] = 0, ["meta"] = { ["inventory"] = {  }, ["fields"] = {  } }, ["param2"] = 0, ["param1"] = 61 }, { ["y"] = 3, ["x"] = 0, ["name"] = "default:water_source", ["z"] = 1, ["meta"] = { ["inventory"] = {  }, ["fields"] = {  } }, ["param2"] = 0, ["param1"] = 77 }, { ["y"] = 3, ["x"] = 0, ["name"] = "default:water_source", ["z"] = 2, ["meta"] = { ["inventory"] = {  }, ["fields"] = {  } }, ["param2"] = 0, ["param1"] = 93 }, { ["y"] = 3, ["x"] = 0, ["name"] = "default:water_source", ["z"] = 3, ["meta"] = { ["inventory"] = {  }, ["fields"] = {  } }, ["param2"] = 0, ["param1"] = 77 }, { ["y"] = 3, ["x"] = 0, ["name"] = "default:water_source", ["z"] = 4, ["meta"] = { ["inventory"] = {  }, ["fields"] = {  } }, ["param2"] = 0, ["param1"] = 77 }, { ["y"] = 3, ["x"] = 0, ["name"] = "default:water_source", ["z"] = 5, ["meta"] = { ["inventory"] = {  }, ["fields"] = {  } }, ["param2"] = 0, ["param1"] = 93 }, { ["y"] = 3, ["x"] = 0, ["name"] = "default:water_source", ["z"] = 6, ["meta"] = { ["inventory"] = {  }, ["fields"] = {  } }, ["param2"] = 240, ["param1"] = 109 }, { ["y"] = 3, ["x"] = 0, ["name"] = "default:water_source", ["z"] = 7, ["meta"] = { ["inventory"] = {  }, ["fields"] = {  } }, ["param2"] = 240, ["param1"] = 125 }, { ["y"] = 3, ["x"] = 0, ["name"] = "default:water_source", ["z"] = 8, ["meta"] = { ["inventory"] = {  }, ["fields"] = {  } }, ["param2"] = 240, ["param1"] = 141 }, { ["y"] = 4, ["x"] = 0, ["name"] = "flowers:waterlily_s3", ["z"] = 5, ["meta"] = { ["inventory"] = {  }, ["fields"] = {  } }, ["param2"] = 1, ["param1"] = 111 }, { ["y"] = 0, ["x"] = 1, ["name"] = "default:water_source", ["z"] = 0, ["meta"] = { ["inventory"] = {  }, ["fields"] = {  } }, ["param2"] = 240, ["param1"] = 26 }, { ["y"] = 0, ["x"] = 1, ["name"] = "default:water_source", ["z"] = 1, ["meta"] = { ["inventory"] = {  }, ["fields"] = {  } }, ["param2"] = 240, ["param1"] = 42 }, { ["y"] = 0, ["x"] = 1, ["name"] = "default:water_source", ["z"] = 2, ["meta"] = { ["inventory"] = {  }, ["fields"] = {  } }, ["param2"] = 240, ["param1"] = 58 }, { ["y"] = 0, ["x"] = 1, ["name"] = "default:water_source", ["z"] = 3, ["meta"] = { ["inventory"] = {  }, ["fields"] = {  } }, ["param2"] = 240, ["param1"] = 42 }, { ["y"] = 0, ["x"] = 1, ["name"] = "default:water_source", ["z"] = 4, ["meta"] = { ["inventory"] = {  }, ["fields"] = {  } }, ["param2"] = 240, ["param1"] = 26 }, { ["y"] = 0, ["x"] = 1, ["name"] = "default:stone", ["z"] = 5, ["meta"] = { ["inventory"] = {  }, ["fields"] = {  } }, ["param2"] = 0, ["param1"] = 0 }, { ["y"] = 0, ["x"] = 1, ["name"] = "default:stone", ["z"] = 6, ["meta"] = { ["inventory"] = {  }, ["fields"] = {  } }, ["param2"] = 0, ["param1"] = 0 }, { ["y"] = 0, ["x"] = 1, ["name"] = "default:stone", ["z"] = 7, ["meta"] = { ["inventory"] = {  }, ["fields"] = {  } }, ["param2"] = 0, ["param1"] = 0 }, { ["y"] = 0, ["x"] = 1, ["name"] = "default:stone", ["z"] = 8, ["meta"] = { ["inventory"] = {  }, ["fields"] = {  } }, ["param2"] = 0, ["param1"] = 0 }, { ["y"] = 1, ["x"] = 1, ["name"] = "default:water_source", ["z"] = 0, ["meta"] = { ["inventory"] = {  }, ["fields"] = {  } }, ["param2"] = 0, ["param1"] = 43 }, { ["y"] = 1, ["x"] = 1, ["name"] = "default:water_source", ["z"] = 1, ["meta"] = { ["inventory"] = {  }, ["fields"] = {  } }, ["param2"] = 240, ["param1"] = 59 }, { ["y"] = 1, ["x"] = 1, ["name"] = "default:water_source", ["z"] = 2, ["meta"] = { ["inventory"] = {  }, ["fields"] = {  } }, ["param2"] = 240, ["param1"] = 75 }, { ["y"] = 1, ["x"] = 1, ["name"] = "default:water_source", ["z"] = 3, ["meta"] = { ["inventory"] = {  }, ["fields"] = {  } }, ["param2"] = 240, ["param1"] = 59 }, { ["y"] = 1, ["x"] = 1, ["name"] = "default:water_source", ["z"] = 4, ["meta"] = { ["inventory"] = {  }, ["fields"] = {  } }, ["param2"] = 240, ["param1"] = 43 }, { ["y"] = 1, ["x"] = 1, ["name"] = "default:sand", ["z"] = 5, ["meta"] = { ["inventory"] = {  }, ["fields"] = {  } }, ["param2"] = 0, ["param1"] = 0 }, { ["y"] = 1, ["x"] = 1, ["name"] = "default:stone", ["z"] = 6, ["meta"] = { ["inventory"] = {  }, ["fields"] = {  } }, ["param2"] = 0, ["param1"] = 0 }, { ["y"] = 1, ["x"] = 1, ["name"] = "default:stone", ["z"] = 7, ["meta"] = { ["inventory"] = {  }, ["fields"] = {  } }, ["param2"] = 0, ["param1"] = 0 }, { ["y"] = 1, ["x"] = 1, ["name"] = "default:stone", ["z"] = 8, ["meta"] = { ["inventory"] = {  }, ["fields"] = {  } }, ["param2"] = 0, ["param1"] = 0 }, { ["y"] = 2, ["x"] = 1, ["name"] = "default:water_source", ["z"] = 0, ["meta"] = { ["inventory"] = {  }, ["fields"] = {  } }, ["param2"] = 0, ["param1"] = 60 }, { ["y"] = 2, ["x"] = 1, ["name"] = "default:water_source", ["z"] = 1, ["meta"] = { ["inventory"] = {  }, ["fields"] = {  } }, ["param2"] = 0, ["param1"] = 76 }, { ["y"] = 2, ["x"] = 1, ["name"] = "default:water_source", ["z"] = 2, ["meta"] = { ["inventory"] = {  }, ["fields"] = {  } }, ["param2"] = 0, ["param1"] = 92 }, { ["y"] = 2, ["x"] = 1, ["name"] = "default:water_source", ["z"] = 3, ["meta"] = { ["inventory"] = {  }, ["fields"] = {  } }, ["param2"] = 240, ["param1"] = 76 }, { ["y"] = 2, ["x"] = 1, ["name"] = "default:water_source", ["z"] = 4, ["meta"] = { ["inventory"] = {  }, ["fields"] = {  } }, ["param2"] = 240, ["param1"] = 60 }, { ["y"] = 2, ["x"] = 1, ["name"] = "default:water_source", ["z"] = 5, ["meta"] = { ["inventory"] = {  }, ["fields"] = {  } }, ["param2"] = 240, ["param1"] = 60 }, { ["y"] = 2, ["x"] = 1, ["name"] = "default:water_source", ["z"] = 6, ["meta"] = { ["inventory"] = {  }, ["fields"] = {  } }, ["param2"] = 240, ["param1"] = 76 }, { ["y"] = 2, ["x"] = 1, ["name"] = "default:water_source", ["z"] = 7, ["meta"] = { ["inventory"] = {  }, ["fields"] = {  } }, ["param2"] = 240, ["param1"] = 92 }, { ["y"] = 2, ["x"] = 1, ["name"] = "default:water_source", ["z"] = 8, ["meta"] = { ["inventory"] = {  }, ["fields"] = {  } }, ["param2"] = 240, ["param1"] = 108 }, { ["y"] = 3, ["x"] = 1, ["name"] = "default:water_source", ["z"] = 0, ["meta"] = { ["inventory"] = {  }, ["fields"] = {  } }, ["param2"] = 0, ["param1"] = 77 }, { ["y"] = 3, ["x"] = 1, ["name"] = "default:water_source", ["z"] = 1, ["meta"] = { ["inventory"] = {  }, ["fields"] = {  } }, ["param2"] = 0, ["param1"] = 93 }, { ["y"] = 3, ["x"] = 1, ["name"] = "default:water_source", ["z"] = 2, ["meta"] = { ["inventory"] = {  }, ["fields"] = {  } }, ["param2"] = 0, ["param1"] = 109 }, { ["y"] = 3, ["x"] = 1, ["name"] = "default:water_source", ["z"] = 3, ["meta"] = { ["inventory"] = {  }, ["fields"] = {  } }, ["param2"] = 0, ["param1"] = 93 }, { ["y"] = 3, ["x"] = 1, ["name"] = "default:water_source", ["z"] = 4, ["meta"] = { ["inventory"] = {  }, ["fields"] = {  } }, ["param2"] = 0, ["param1"] = 77 }, { ["y"] = 3, ["x"] = 1, ["name"] = "default:water_source", ["z"] = 5, ["meta"] = { ["inventory"] = {  }, ["fields"] = {  } }, ["param2"] = 0, ["param1"] = 77 }, { ["y"] = 3, ["x"] = 1, ["name"] = "default:water_source", ["z"] = 6, ["meta"] = { ["inventory"] = {  }, ["fields"] = {  } }, ["param2"] = 240, ["param1"] = 93 }, { ["y"] = 3, ["x"] = 1, ["name"] = "default:water_source", ["z"] = 7, ["meta"] = { ["inventory"] = {  }, ["fields"] = {  } }, ["param2"] = 240, ["param1"] = 109 }, { ["y"] = 3, ["x"] = 1, ["name"] = "default:water_source", ["z"] = 8, ["meta"] = { ["inventory"] = {  }, ["fields"] = {  } }, ["param2"] = 240, ["param1"] = 125 }, { ["y"] = 0, ["x"] = 2, ["name"] = "default:water_source", ["z"] = 0, ["meta"] = { ["inventory"] = {  }, ["fields"] = {  } }, ["param2"] = 240, ["param1"] = 42 }, { ["y"] = 0, ["x"] = 2, ["name"] = "default:water_source", ["z"] = 1, ["meta"] = { ["inventory"] = {  }, ["fields"] = {  } }, ["param2"] = 240, ["param1"] = 58 }, { ["y"] = 0, ["x"] = 2, ["name"] = "default:water_source", ["z"] = 2, ["meta"] = { ["inventory"] = {  }, ["fields"] = {  } }, ["param2"] = 240, ["param1"] = 41 }, { ["y"] = 0, ["x"] = 2, ["name"] = "default:water_source", ["z"] = 3, ["meta"] = { ["inventory"] = {  }, ["fields"] = {  } }, ["param2"] = 240, ["param1"] = 25 }, { ["y"] = 0, ["x"] = 2, ["name"] = "default:water_source", ["z"] = 4, ["meta"] = { ["inventory"] = {  }, ["fields"] = {  } }, ["param2"] = 240, ["param1"] = 9 }, { ["y"] = 0, ["x"] = 2, ["name"] = "default:stone", ["z"] = 5, ["meta"] = { ["inventory"] = {  }, ["fields"] = {  } }, ["param2"] = 0, ["param1"] = 0 }, { ["y"] = 0, ["x"] = 2, ["name"] = "default:dirt", ["z"] = 6, ["meta"] = { ["inventory"] = {  }, ["fields"] = {  } }, ["param2"] = 0, ["param1"] = 0 }, { ["y"] = 0, ["x"] = 2, ["name"] = "default:dirt", ["z"] = 7, ["meta"] = { ["inventory"] = {  }, ["fields"] = {  } }, ["param2"] = 0, ["param1"] = 0 }, { ["y"] = 0, ["x"] = 2, ["name"] = "default:dirt", ["z"] = 8, ["meta"] = { ["inventory"] = {  }, ["fields"] = {  } }, ["param2"] = 0, ["param1"] = 0 }, { ["y"] = 1, ["x"] = 2, ["name"] = "default:water_source", ["z"] = 0, ["meta"] = { ["inventory"] = {  }, ["fields"] = {  } }, ["param2"] = 0, ["param1"] = 59 }, { ["y"] = 1, ["x"] = 2, ["name"] = "default:water_source", ["z"] = 1, ["meta"] = { ["inventory"] = {  }, ["fields"] = {  } }, ["param2"] = 240, ["param1"] = 75 }, { ["y"] = 1, ["x"] = 2, ["name"] = "default:water_source", ["z"] = 2, ["meta"] = { ["inventory"] = {  }, ["fields"] = {  } }, ["param2"] = 240, ["param1"] = 58 }, { ["y"] = 1, ["x"] = 2, ["name"] = "default:water_source", ["z"] = 3, ["meta"] = { ["inventory"] = {  }, ["fields"] = {  } }, ["param2"] = 240, ["param1"] = 42 }, { ["y"] = 1, ["x"] = 2, ["name"] = "default:water_source", ["z"] = 4, ["meta"] = { ["inventory"] = {  }, ["fields"] = {  } }, ["param2"] = 240, ["param1"] = 26 }, { ["y"] = 1, ["x"] = 2, ["name"] = "default:stone", ["z"] = 5, ["meta"] = { ["inventory"] = {  }, ["fields"] = {  } }, ["param2"] = 0, ["param1"] = 0 }, { ["y"] = 1, ["x"] = 2, ["name"] = "default:dirt", ["z"] = 6, ["meta"] = { ["inventory"] = {  }, ["fields"] = {  } }, ["param2"] = 0, ["param1"] = 0 }, { ["y"] = 1, ["x"] = 2, ["name"] = "default:water_source", ["z"] = 7, ["meta"] = { ["inventory"] = {  }, ["fields"] = {  } }, ["param2"] = 240, ["param1"] = 58 }, { ["y"] = 1, ["x"] = 2, ["name"] = "maptools:sand", ["z"] = 8, ["meta"] = { ["inventory"] = {  }, ["fields"] = {  } }, ["param2"] = 0, ["param1"] = 0 }, { ["y"] = 2, ["x"] = 2, ["name"] = "default:water_source", ["z"] = 0, ["meta"] = { ["inventory"] = {  }, ["fields"] = {  } }, ["param2"] = 0, ["param1"] = 76 }, { ["y"] = 2, ["x"] = 2, ["name"] = "default:water_source", ["z"] = 1, ["meta"] = { ["inventory"] = {  }, ["fields"] = {  } }, ["param2"] = 0, ["param1"] = 92 }, { ["y"] = 2, ["x"] = 2, ["name"] = "default:water_source", ["z"] = 2, ["meta"] = { ["inventory"] = {  }, ["fields"] = {  } }, ["param2"] = 0, ["param1"] = 75 }, { ["y"] = 2, ["x"] = 2, ["name"] = "default:water_source", ["z"] = 3, ["meta"] = { ["inventory"] = {  }, ["fields"] = {  } }, ["param2"] = 240, ["param1"] = 59 }, { ["y"] = 2, ["x"] = 2, ["name"] = "default:water_source", ["z"] = 4, ["meta"] = { ["inventory"] = {  }, ["fields"] = {  } }, ["param2"] = 240, ["param1"] = 43 }, { ["y"] = 2, ["x"] = 2, ["name"] = "default:water_source", ["z"] = 5, ["meta"] = { ["inventory"] = {  }, ["fields"] = {  } }, ["param2"] = 240, ["param1"] = 43 }, { ["y"] = 2, ["x"] = 2, ["name"] = "default:water_source", ["z"] = 6, ["meta"] = { ["inventory"] = {  }, ["fields"] = {  } }, ["param2"] = 240, ["param1"] = 59 }, { ["y"] = 2, ["x"] = 2, ["name"] = "default:water_source", ["z"] = 7, ["meta"] = { ["inventory"] = {  }, ["fields"] = {  } }, ["param2"] = 240, ["param1"] = 75 }, { ["y"] = 2, ["x"] = 2, ["name"] = "default:water_source", ["z"] = 8, ["meta"] = { ["inventory"] = {  }, ["fields"] = {  } }, ["param2"] = 240, ["param1"] = 91 }, { ["y"] = 3, ["x"] = 2, ["name"] = "default:water_source", ["z"] = 0, ["meta"] = { ["inventory"] = {  }, ["fields"] = {  } }, ["param2"] = 0, ["param1"] = 93 }, { ["y"] = 3, ["x"] = 2, ["name"] = "default:water_source", ["z"] = 1, ["meta"] = { ["inventory"] = {  }, ["fields"] = {  } }, ["param2"] = 0, ["param1"] = 109 }, { ["y"] = 3, ["x"] = 2, ["name"] = "default:water_source", ["z"] = 2, ["meta"] = { ["inventory"] = {  }, ["fields"] = {  } }, ["param2"] = 0, ["param1"] = 92 }, { ["y"] = 3, ["x"] = 2, ["name"] = "default:water_source", ["z"] = 3, ["meta"] = { ["inventory"] = {  }, ["fields"] = {  } }, ["param2"] = 0, ["param1"] = 76 }, { ["y"] = 3, ["x"] = 2, ["name"] = "default:water_source", ["z"] = 4, ["meta"] = { ["inventory"] = {  }, ["fields"] = {  } }, ["param2"] = 0, ["param1"] = 60 }, { ["y"] = 3, ["x"] = 2, ["name"] = "default:water_source", ["z"] = 5, ["meta"] = { ["inventory"] = {  }, ["fields"] = {  } }, ["param2"] = 240, ["param1"] = 60 }, { ["y"] = 3, ["x"] = 2, ["name"] = "default:water_source", ["z"] = 6, ["meta"] = { ["inventory"] = {  }, ["fields"] = {  } }, ["param2"] = 240, ["param1"] = 76 }, { ["y"] = 3, ["x"] = 2, ["name"] = "default:water_source", ["z"] = 7, ["meta"] = { ["inventory"] = {  }, ["fields"] = {  } }, ["param2"] = 240, ["param1"] = 92 }, { ["y"] = 3, ["x"] = 2, ["name"] = "default:water_source", ["z"] = 8, ["meta"] = { ["inventory"] = {  }, ["fields"] = {  } }, ["param2"] = 240, ["param1"] = 108 }, { ["y"] = 4, ["x"] = 2, ["name"] = "moretrees:palm_planks", ["z"] = 2, ["meta"] = { ["inventory"] = {  }, ["fields"] = {  } }, ["param2"] = 0, ["param1"] = 0 }, { ["y"] = 4, ["x"] = 2, ["name"] = "moretrees:palm_planks", ["z"] = 3, ["meta"] = { ["inventory"] = {  }, ["fields"] = {  } }, ["param2"] = 0, ["param1"] = 0 }, { ["y"] = 4, ["x"] = 2, ["name"] = "moretrees:palm_planks", ["z"] = 4, ["meta"] = { ["inventory"] = {  }, ["fields"] = {  } }, ["param2"] = 0, ["param1"] = 0 }, { ["y"] = 4, ["x"] = 2, ["name"] = "moretrees:palm_planks", ["z"] = 5, ["meta"] = { ["inventory"] = {  }, ["fields"] = {  } }, ["param2"] = 0, ["param1"] = 0 }, { ["y"] = 4, ["x"] = 2, ["name"] = "moretrees:palm_planks", ["z"] = 6, ["meta"] = { ["inventory"] = {  }, ["fields"] = {  } }, ["param2"] = 0, ["param1"] = 0 }, { ["y"] = 4, ["x"] = 2, ["name"] = "moretrees:palm_planks", ["z"] = 7, ["meta"] = { ["inventory"] = {  }, ["fields"] = {  } }, ["param2"] = 0, ["param1"] = 0 }, { ["y"] = 4, ["x"] = 2, ["name"] = "moretrees:palm_planks", ["z"] = 8, ["meta"] = { ["inventory"] = {  }, ["fields"] = {  } }, ["param2"] = 0, ["param1"] = 0 }, { ["y"] = 0, ["x"] = 3, ["name"] = "default:water_source", ["z"] = 0, ["meta"] = { ["inventory"] = {  }, ["fields"] = {  } }, ["param2"] = 240, ["param1"] = 58 }, { ["y"] = 0, ["x"] = 3, ["name"] = "default:water_source", ["z"] = 1, ["meta"] = { ["inventory"] = {  }, ["fields"] = {  } }, ["param2"] = 240, ["param1"] = 74 }, { ["y"] = 0, ["x"] = 3, ["name"] = "default:water_source", ["z"] = 2, ["meta"] = { ["inventory"] = {  }, ["fields"] = {  } }, ["param2"] = 240, ["param1"] = 57 }, { ["y"] = 0, ["x"] = 3, ["name"] = "default:water_source", ["z"] = 3, ["meta"] = { ["inventory"] = {  }, ["fields"] = {  } }, ["param2"] = 240, ["param1"] = 40 }, { ["y"] = 0, ["x"] = 3, ["name"] = "default:water_source", ["z"] = 4, ["meta"] = { ["inventory"] = {  }, ["fields"] = {  } }, ["param2"] = 240, ["param1"] = 24 }, { ["y"] = 0, ["x"] = 3, ["name"] = "default:stone", ["z"] = 5, ["meta"] = { ["inventory"] = {  }, ["fields"] = {  } }, ["param2"] = 0, ["param1"] = 0 }, { ["y"] = 0, ["x"] = 3, ["name"] = "default:dirt", ["z"] = 6, ["meta"] = { ["inventory"] = {  }, ["fields"] = {  } }, ["param2"] = 0, ["param1"] = 0 }, { ["y"] = 0, ["x"] = 3, ["name"] = "default:dirt", ["z"] = 7, ["meta"] = { ["inventory"] = {  }, ["fields"] = {  } }, ["param2"] = 0, ["param1"] = 0 }, { ["y"] = 0, ["x"] = 3, ["name"] = "default:dirt", ["z"] = 8, ["meta"] = { ["inventory"] = {  }, ["fields"] = {  } }, ["param2"] = 0, ["param1"] = 0 }, { ["y"] = 1, ["x"] = 3, ["name"] = "default:water_source", ["z"] = 0, ["meta"] = { ["inventory"] = {  }, ["fields"] = {  } }, ["param2"] = 0, ["param1"] = 75 }, { ["y"] = 1, ["x"] = 3, ["name"] = "default:water_source", ["z"] = 1, ["meta"] = { ["inventory"] = {  }, ["fields"] = {  } }, ["param2"] = 240, ["param1"] = 91 }, { ["y"] = 1, ["x"] = 3, ["name"] = "default:water_source", ["z"] = 2, ["meta"] = { ["inventory"] = {  }, ["fields"] = {  } }, ["param2"] = 240, ["param1"] = 74 }, { ["y"] = 1, ["x"] = 3, ["name"] = "default:water_source", ["z"] = 3, ["meta"] = { ["inventory"] = {  }, ["fields"] = {  } }, ["param2"] = 240, ["param1"] = 57 }, { ["y"] = 1, ["x"] = 3, ["name"] = "default:water_source", ["z"] = 4, ["meta"] = { ["inventory"] = {  }, ["fields"] = {  } }, ["param2"] = 240, ["param1"] = 41 }, { ["y"] = 1, ["x"] = 3, ["name"] = "default:water_source", ["z"] = 5, ["meta"] = { ["inventory"] = {  }, ["fields"] = {  } }, ["param2"] = 240, ["param1"] = 25 }, { ["y"] = 1, ["x"] = 3, ["name"] = "default:water_source", ["z"] = 6, ["meta"] = { ["inventory"] = {  }, ["fields"] = {  } }, ["param2"] = 240, ["param1"] = 25 }, { ["y"] = 1, ["x"] = 3, ["name"] = "default:water_source", ["z"] = 7, ["meta"] = { ["inventory"] = {  }, ["fields"] = {  } }, ["param2"] = 240, ["param1"] = 41 }, { ["y"] = 1, ["x"] = 3, ["name"] = "maptools:sand", ["z"] = 8, ["meta"] = { ["inventory"] = {  }, ["fields"] = {  } }, ["param2"] = 0, ["param1"] = 0 }, { ["y"] = 2, ["x"] = 3, ["name"] = "default:water_source", ["z"] = 0, ["meta"] = { ["inventory"] = {  }, ["fields"] = {  } }, ["param2"] = 0, ["param1"] = 92 }, { ["y"] = 2, ["x"] = 3, ["name"] = "default:water_source", ["z"] = 1, ["meta"] = { ["inventory"] = {  }, ["fields"] = {  } }, ["param2"] = 0, ["param1"] = 108 }, { ["y"] = 2, ["x"] = 3, ["name"] = "default:water_source", ["z"] = 2, ["meta"] = { ["inventory"] = {  }, ["fields"] = {  } }, ["param2"] = 0, ["param1"] = 91 }, { ["y"] = 2, ["x"] = 3, ["name"] = "default:water_source", ["z"] = 3, ["meta"] = { ["inventory"] = {  }, ["fields"] = {  } }, ["param2"] = 240, ["param1"] = 74 }, { ["y"] = 2, ["x"] = 3, ["name"] = "default:water_source", ["z"] = 4, ["meta"] = { ["inventory"] = {  }, ["fields"] = {  } }, ["param2"] = 240, ["param1"] = 58 }, { ["y"] = 2, ["x"] = 3, ["name"] = "default:water_source", ["z"] = 5, ["meta"] = { ["inventory"] = {  }, ["fields"] = {  } }, ["param2"] = 240, ["param1"] = 42 }, { ["y"] = 2, ["x"] = 3, ["name"] = "default:water_source", ["z"] = 6, ["meta"] = { ["inventory"] = {  }, ["fields"] = {  } }, ["param2"] = 240, ["param1"] = 42 }, { ["y"] = 2, ["x"] = 3, ["name"] = "default:water_source", ["z"] = 7, ["meta"] = { ["inventory"] = {  }, ["fields"] = {  } }, ["param2"] = 240, ["param1"] = 58 }, { ["y"] = 2, ["x"] = 3, ["name"] = "default:water_source", ["z"] = 8, ["meta"] = { ["inventory"] = {  }, ["fields"] = {  } }, ["param2"] = 240, ["param1"] = 74 }, { ["y"] = 3, ["x"] = 3, ["name"] = "default:water_source", ["z"] = 0, ["meta"] = { ["inventory"] = {  }, ["fields"] = {  } }, ["param2"] = 0, ["param1"] = 109 }, { ["y"] = 3, ["x"] = 3, ["name"] = "default:water_source", ["z"] = 1, ["meta"] = { ["inventory"] = {  }, ["fields"] = {  } }, ["param2"] = 0, ["param1"] = 125 }, { ["y"] = 3, ["x"] = 3, ["name"] = "default:water_source", ["z"] = 2, ["meta"] = { ["inventory"] = {  }, ["fields"] = {  } }, ["param2"] = 240, ["param1"] = 108 }, { ["y"] = 3, ["x"] = 3, ["name"] = "moretrees:palm_planks", ["z"] = 3, ["meta"] = { ["inventory"] = {  }, ["fields"] = {  } }, ["param2"] = 0, ["param1"] = 0 }, { ["y"] = 3, ["x"] = 3, ["name"] = "moretrees:palm_planks", ["z"] = 4, ["meta"] = { ["inventory"] = {  }, ["fields"] = {  } }, ["param2"] = 0, ["param1"] = 0 }, { ["y"] = 3, ["x"] = 3, ["name"] = "moretrees:palm_planks", ["z"] = 5, ["meta"] = { ["inventory"] = {  }, ["fields"] = {  } }, ["param2"] = 0, ["param1"] = 0 }, { ["y"] = 3, ["x"] = 3, ["name"] = "moretrees:palm_planks", ["z"] = 6, ["meta"] = { ["inventory"] = {  }, ["fields"] = {  } }, ["param2"] = 0, ["param1"] = 0 }, { ["y"] = 3, ["x"] = 3, ["name"] = "moretrees:palm_planks", ["z"] = 7, ["meta"] = { ["inventory"] = {  }, ["fields"] = {  } }, ["param2"] = 0, ["param1"] = 0 }, { ["y"] = 3, ["x"] = 3, ["name"] = "moretrees:palm_planks", ["z"] = 8, ["meta"] = { ["inventory"] = {  }, ["fields"] = {  } }, ["param2"] = 0, ["param1"] = 0 }, { ["y"] = 4, ["x"] = 3, ["name"] = "moretrees:palm_planks", ["z"] = 2, ["meta"] = { ["inventory"] = {  }, ["fields"] = {  } }, ["param2"] = 0, ["param1"] = 0 }, { ["y"] = 4, ["x"] = 3, ["name"] = "moretrees:palm_planks", ["z"] = 8, ["meta"] = { ["inventory"] = {  }, ["fields"] = {  } }, ["param2"] = 0, ["param1"] = 0 }, { ["y"] = 0, ["x"] = 4, ["name"] = "default:water_source", ["z"] = 0, ["meta"] = { ["inventory"] = {  }, ["fields"] = {  } }, ["param2"] = 240, ["param1"] = 74 }, { ["y"] = 0, ["x"] = 4, ["name"] = "default:water_source", ["z"] = 1, ["meta"] = { ["inventory"] = {  }, ["fields"] = {  } }, ["param2"] = 240, ["param1"] = 90 }, { ["y"] = 0, ["x"] = 4, ["name"] = "default:water_source", ["z"] = 2, ["meta"] = { ["inventory"] = {  }, ["fields"] = {  } }, ["param2"] = 240, ["param1"] = 73 }, { ["y"] = 0, ["x"] = 4, ["name"] = "default:water_source", ["z"] = 3, ["meta"] = { ["inventory"] = {  }, ["fields"] = {  } }, ["param2"] = 240, ["param1"] = 56 }, { ["y"] = 0, ["x"] = 4, ["name"] = "default:water_source", ["z"] = 4, ["meta"] = { ["inventory"] = {  }, ["fields"] = {  } }, ["param2"] = 240, ["param1"] = 39 }, { ["y"] = 0, ["x"] = 4, ["name"] = "default:water_source", ["z"] = 5, ["meta"] = { ["inventory"] = {  }, ["fields"] = {  } }, ["param2"] = 240, ["param1"] = 23 }, { ["y"] = 0, ["x"] = 4, ["name"] = "default:water_source", ["z"] = 6, ["meta"] = { ["inventory"] = {  }, ["fields"] = {  } }, ["param2"] = 240, ["param1"] = 7 }, { ["y"] = 0, ["x"] = 4, ["name"] = "default:water_source", ["z"] = 7, ["meta"] = { ["inventory"] = {  }, ["fields"] = {  } }, ["param2"] = 240, ["param1"] = 7 }, { ["y"] = 0, ["x"] = 4, ["name"] = "maptools:sand", ["z"] = 8, ["meta"] = { ["inventory"] = {  }, ["fields"] = {  } }, ["param2"] = 0, ["param1"] = 0 }, { ["y"] = 1, ["x"] = 4, ["name"] = "default:water_source", ["z"] = 0, ["meta"] = { ["inventory"] = {  }, ["fields"] = {  } }, ["param2"] = 0, ["param1"] = 91 }, { ["y"] = 1, ["x"] = 4, ["name"] = "default:water_source", ["z"] = 1, ["meta"] = { ["inventory"] = {  }, ["fields"] = {  } }, ["param2"] = 240, ["param1"] = 107 }, { ["y"] = 1, ["x"] = 4, ["name"] = "default:water_source", ["z"] = 2, ["meta"] = { ["inventory"] = {  }, ["fields"] = {  } }, ["param2"] = 240, ["param1"] = 90 }, { ["y"] = 1, ["x"] = 4, ["name"] = "default:water_source", ["z"] = 3, ["meta"] = { ["inventory"] = {  }, ["fields"] = {  } }, ["param2"] = 240, ["param1"] = 73 }, { ["y"] = 1, ["x"] = 4, ["name"] = "default:water_source", ["z"] = 4, ["meta"] = { ["inventory"] = {  }, ["fields"] = {  } }, ["param2"] = 240, ["param1"] = 56 }, { ["y"] = 1, ["x"] = 4, ["name"] = "default:water_source", ["z"] = 5, ["meta"] = { ["inventory"] = {  }, ["fields"] = {  } }, ["param2"] = 240, ["param1"] = 40 }, { ["y"] = 1, ["x"] = 4, ["name"] = "default:water_source", ["z"] = 6, ["meta"] = { ["inventory"] = {  }, ["fields"] = {  } }, ["param2"] = 240, ["param1"] = 24 }, { ["y"] = 1, ["x"] = 4, ["name"] = "default:water_source", ["z"] = 7, ["meta"] = { ["inventory"] = {  }, ["fields"] = {  } }, ["param2"] = 240, ["param1"] = 24 }, { ["y"] = 1, ["x"] = 4, ["name"] = "maptools:sand", ["z"] = 8, ["meta"] = { ["inventory"] = {  }, ["fields"] = {  } }, ["param2"] = 0, ["param1"] = 0 }, { ["y"] = 2, ["x"] = 4, ["name"] = "default:water_source", ["z"] = 0, ["meta"] = { ["inventory"] = {  }, ["fields"] = {  } }, ["param2"] = 0, ["param1"] = 108 }, { ["y"] = 2, ["x"] = 4, ["name"] = "default:water_source", ["z"] = 1, ["meta"] = { ["inventory"] = {  }, ["fields"] = {  } }, ["param2"] = 0, ["param1"] = 124 }, { ["y"] = 2, ["x"] = 4, ["name"] = "default:water_source", ["z"] = 2, ["meta"] = { ["inventory"] = {  }, ["fields"] = {  } }, ["param2"] = 0, ["param1"] = 107 }, { ["y"] = 2, ["x"] = 4, ["name"] = "default:water_source", ["z"] = 3, ["meta"] = { ["inventory"] = {  }, ["fields"] = {  } }, ["param2"] = 240, ["param1"] = 90 }, { ["y"] = 2, ["x"] = 4, ["name"] = "default:water_source", ["z"] = 4, ["meta"] = { ["inventory"] = {  }, ["fields"] = {  } }, ["param2"] = 240, ["param1"] = 73 }, { ["y"] = 2, ["x"] = 4, ["name"] = "default:water_source", ["z"] = 5, ["meta"] = { ["inventory"] = {  }, ["fields"] = {  } }, ["param2"] = 240, ["param1"] = 57 }, { ["y"] = 2, ["x"] = 4, ["name"] = "default:water_source", ["z"] = 6, ["meta"] = { ["inventory"] = {  }, ["fields"] = {  } }, ["param2"] = 240, ["param1"] = 41 }, { ["y"] = 2, ["x"] = 4, ["name"] = "default:water_source", ["z"] = 7, ["meta"] = { ["inventory"] = {  }, ["fields"] = {  } }, ["param2"] = 240, ["param1"] = 41 }, { ["y"] = 2, ["x"] = 4, ["name"] = "default:water_source", ["z"] = 8, ["meta"] = { ["inventory"] = {  }, ["fields"] = {  } }, ["param2"] = 240, ["param1"] = 57 }, { ["y"] = 3, ["x"] = 4, ["name"] = "default:water_source", ["z"] = 0, ["meta"] = { ["inventory"] = {  }, ["fields"] = {  } }, ["param2"] = 0, ["param1"] = 125 }, { ["y"] = 3, ["x"] = 4, ["name"] = "default:water_source", ["z"] = 1, ["meta"] = { ["inventory"] = {  }, ["fields"] = {  } }, ["param2"] = 0, ["param1"] = 141 }, { ["y"] = 3, ["x"] = 4, ["name"] = "default:water_source", ["z"] = 2, ["meta"] = { ["inventory"] = {  }, ["fields"] = {  } }, ["param2"] = 0, ["param1"] = 124 }, { ["y"] = 3, ["x"] = 4, ["name"] = "moretrees:palm_planks", ["z"] = 3, ["meta"] = { ["inventory"] = {  }, ["fields"] = {  } }, ["param2"] = 0, ["param1"] = 0 }, { ["y"] = 3, ["x"] = 4, ["name"] = "moretrees:palm_planks", ["z"] = 4, ["meta"] = { ["inventory"] = {  }, ["fields"] = {  } }, ["param2"] = 0, ["param1"] = 0 }, { ["y"] = 3, ["x"] = 4, ["name"] = "moretrees:palm_planks", ["z"] = 5, ["meta"] = { ["inventory"] = {  }, ["fields"] = {  } }, ["param2"] = 0, ["param1"] = 0 }, { ["y"] = 3, ["x"] = 4, ["name"] = "moretrees:palm_planks", ["z"] = 6, ["meta"] = { ["inventory"] = {  }, ["fields"] = {  } }, ["param2"] = 0, ["param1"] = 0 }, { ["y"] = 3, ["x"] = 4, ["name"] = "moretrees:palm_planks", ["z"] = 7, ["meta"] = { ["inventory"] = {  }, ["fields"] = {  } }, ["param2"] = 0, ["param1"] = 0 }, { ["y"] = 3, ["x"] = 4, ["name"] = "moretrees:palm_planks", ["z"] = 8, ["meta"] = { ["inventory"] = {  }, ["fields"] = {  } }, ["param2"] = 0, ["param1"] = 0 }, { ["y"] = 4, ["x"] = 4, ["name"] = "moretrees:palm_planks", ["z"] = 2, ["meta"] = { ["inventory"] = {  }, ["fields"] = {  } }, ["param2"] = 0, ["param1"] = 0 }, { ["y"] = 4, ["x"] = 4, ["name"] = "moretrees:palm_planks", ["z"] = 4, ["meta"] = { ["inventory"] = {  }, ["fields"] = {  } }, ["param2"] = 0, ["param1"] = 0 }, { ["y"] = 4, ["x"] = 4, ["name"] = "moretrees:palm_planks", ["z"] = 5, ["meta"] = { ["inventory"] = {  }, ["fields"] = {  } }, ["param2"] = 0, ["param1"] = 0 }, { ["y"] = 4, ["x"] = 4, ["name"] = "moretrees:palm_planks", ["z"] = 6, ["meta"] = { ["inventory"] = {  }, ["fields"] = {  } }, ["param2"] = 0, ["param1"] = 0 }, { ["y"] = 4, ["x"] = 4, ["name"] = "moretrees:palm_planks", ["z"] = 7, ["meta"] = { ["inventory"] = {  }, ["fields"] = {  } }, ["param2"] = 0, ["param1"] = 0 }, { ["y"] = 4, ["x"] = 4, ["name"] = "moretrees:palm_planks", ["z"] = 8, ["meta"] = { ["inventory"] = {  }, ["fields"] = {  } }, ["param2"] = 0, ["param1"] = 0 }, { ["y"] = 5, ["x"] = 4, ["name"] = "moretrees:palm_planks", ["z"] = 4, ["meta"] = { ["inventory"] = {  }, ["fields"] = {  } }, ["param2"] = 0, ["param1"] = 0 }, { ["y"] = 5, ["x"] = 4, ["name"] = "moretrees:palm_planks", ["z"] = 5, ["meta"] = { ["inventory"] = {  }, ["fields"] = {  } }, ["param2"] = 0, ["param1"] = 0 }, { ["y"] = 5, ["x"] = 4, ["name"] = "moretrees:palm_planks", ["z"] = 6, ["meta"] = { ["inventory"] = {  }, ["fields"] = {  } }, ["param2"] = 0, ["param1"] = 0 }, { ["y"] = 5, ["x"] = 4, ["name"] = "moretrees:palm_planks", ["z"] = 7, ["meta"] = { ["inventory"] = {  }, ["fields"] = {  } }, ["param2"] = 0, ["param1"] = 0 }, { ["y"] = 5, ["x"] = 4, ["name"] = "moretrees:palm_planks", ["z"] = 8, ["meta"] = { ["inventory"] = {  }, ["fields"] = {  } }, ["param2"] = 0, ["param1"] = 0 }, { ["y"] = 6, ["x"] = 4, ["name"] = "moretrees:palm_planks", ["z"] = 4, ["meta"] = { ["inventory"] = {  }, ["fields"] = {  } }, ["param2"] = 0, ["param1"] = 0 }, { ["y"] = 6, ["x"] = 4, ["name"] = "moretrees:palm_planks", ["z"] = 5, ["meta"] = { ["inventory"] = {  }, ["fields"] = {  } }, ["param2"] = 0, ["param1"] = 0 }, { ["y"] = 6, ["x"] = 4, ["name"] = "moretrees:palm_planks", ["z"] = 6, ["meta"] = { ["inventory"] = {  }, ["fields"] = {  } }, ["param2"] = 0, ["param1"] = 0 }, { ["y"] = 6, ["x"] = 4, ["name"] = "moretrees:palm_planks", ["z"] = 7, ["meta"] = { ["inventory"] = {  }, ["fields"] = {  } }, ["param2"] = 0, ["param1"] = 0 }, { ["y"] = 6, ["x"] = 4, ["name"] = "moretrees:palm_planks", ["z"] = 8, ["meta"] = { ["inventory"] = {  }, ["fields"] = {  } }, ["param2"] = 0, ["param1"] = 0 }, { ["y"] = 7, ["x"] = 4, ["name"] = "moretrees:palm_planks", ["z"] = 4, ["meta"] = { ["inventory"] = {  }, ["fields"] = {  } }, ["param2"] = 0, ["param1"] = 0 }, { ["y"] = 7, ["x"] = 4, ["name"] = "moretrees:palm_planks", ["z"] = 5, ["meta"] = { ["inventory"] = {  }, ["fields"] = {  } }, ["param2"] = 0, ["param1"] = 0 }, { ["y"] = 7, ["x"] = 4, ["name"] = "moretrees:palm_planks", ["z"] = 6, ["meta"] = { ["inventory"] = {  }, ["fields"] = {  } }, ["param2"] = 0, ["param1"] = 0 }, { ["y"] = 7, ["x"] = 4, ["name"] = "moretrees:palm_planks", ["z"] = 7, ["meta"] = { ["inventory"] = {  }, ["fields"] = {  } }, ["param2"] = 0, ["param1"] = 0 }, { ["y"] = 7, ["x"] = 4, ["name"] = "moretrees:palm_planks", ["z"] = 8, ["meta"] = { ["inventory"] = {  }, ["fields"] = {  } }, ["param2"] = 0, ["param1"] = 0 }, { ["y"] = 0, ["x"] = 5, ["name"] = "default:water_source", ["z"] = 0, ["meta"] = { ["inventory"] = {  }, ["fields"] = {  } }, ["param2"] = 240, ["param1"] = 90 }, { ["y"] = 0, ["x"] = 5, ["name"] = "default:water_source", ["z"] = 1, ["meta"] = { ["inventory"] = {  }, ["fields"] = {  } }, ["param2"] = 240, ["param1"] = 106 }, { ["y"] = 0, ["x"] = 5, ["name"] = "default:water_source", ["z"] = 2, ["meta"] = { ["inventory"] = {  }, ["fields"] = {  } }, ["param2"] = 240, ["param1"] = 89 }, { ["y"] = 0, ["x"] = 5, ["name"] = "default:water_source", ["z"] = 3, ["meta"] = { ["inventory"] = {  }, ["fields"] = {  } }, ["param2"] = 240, ["param1"] = 72 }, { ["y"] = 0, ["x"] = 5, ["name"] = "default:water_source", ["z"] = 4, ["meta"] = { ["inventory"] = {  }, ["fields"] = {  } }, ["param2"] = 240, ["param1"] = 55 }, { ["y"] = 0, ["x"] = 5, ["name"] = "default:water_source", ["z"] = 5, ["meta"] = { ["inventory"] = {  }, ["fields"] = {  } }, ["param2"] = 240, ["param1"] = 38 }, { ["y"] = 0, ["x"] = 5, ["name"] = "default:water_source", ["z"] = 6, ["meta"] = { ["inventory"] = {  }, ["fields"] = {  } }, ["param2"] = 240, ["param1"] = 22 }, { ["y"] = 0, ["x"] = 5, ["name"] = "default:water_source", ["z"] = 7, ["meta"] = { ["inventory"] = {  }, ["fields"] = {  } }, ["param2"] = 240, ["param1"] = 6 }, { ["y"] = 0, ["x"] = 5, ["name"] = "maptools:sand", ["z"] = 8, ["meta"] = { ["inventory"] = {  }, ["fields"] = {  } }, ["param2"] = 0, ["param1"] = 0 }, { ["y"] = 1, ["x"] = 5, ["name"] = "default:water_source", ["z"] = 0, ["meta"] = { ["inventory"] = {  }, ["fields"] = {  } }, ["param2"] = 0, ["param1"] = 107 }, { ["y"] = 1, ["x"] = 5, ["name"] = "default:water_source", ["z"] = 1, ["meta"] = { ["inventory"] = {  }, ["fields"] = {  } }, ["param2"] = 240, ["param1"] = 123 }, { ["y"] = 1, ["x"] = 5, ["name"] = "default:water_source", ["z"] = 2, ["meta"] = { ["inventory"] = {  }, ["fields"] = {  } }, ["param2"] = 240, ["param1"] = 106 }, { ["y"] = 1, ["x"] = 5, ["name"] = "default:water_source", ["z"] = 3, ["meta"] = { ["inventory"] = {  }, ["fields"] = {  } }, ["param2"] = 240, ["param1"] = 89 }, { ["y"] = 1, ["x"] = 5, ["name"] = "default:water_source", ["z"] = 4, ["meta"] = { ["inventory"] = {  }, ["fields"] = {  } }, ["param2"] = 240, ["param1"] = 72 }, { ["y"] = 1, ["x"] = 5, ["name"] = "default:water_source", ["z"] = 5, ["meta"] = { ["inventory"] = {  }, ["fields"] = {  } }, ["param2"] = 240, ["param1"] = 55 }, { ["y"] = 1, ["x"] = 5, ["name"] = "default:water_source", ["z"] = 6, ["meta"] = { ["inventory"] = {  }, ["fields"] = {  } }, ["param2"] = 240, ["param1"] = 39 }, { ["y"] = 1, ["x"] = 5, ["name"] = "default:water_source", ["z"] = 7, ["meta"] = { ["inventory"] = {  }, ["fields"] = {  } }, ["param2"] = 240, ["param1"] = 23 }, { ["y"] = 1, ["x"] = 5, ["name"] = "default:water_source", ["z"] = 8, ["meta"] = { ["inventory"] = {  }, ["fields"] = {  } }, ["param2"] = 240, ["param1"] = 24 }, { ["y"] = 2, ["x"] = 5, ["name"] = "default:water_source", ["z"] = 0, ["meta"] = { ["inventory"] = {  }, ["fields"] = {  } }, ["param2"] = 0, ["param1"] = 124 }, { ["y"] = 2, ["x"] = 5, ["name"] = "default:water_source", ["z"] = 1, ["meta"] = { ["inventory"] = {  }, ["fields"] = {  } }, ["param2"] = 0, ["param1"] = 140 }, { ["y"] = 2, ["x"] = 5, ["name"] = "default:water_source", ["z"] = 2, ["meta"] = { ["inventory"] = {  }, ["fields"] = {  } }, ["param2"] = 0, ["param1"] = 123 }, { ["y"] = 2, ["x"] = 5, ["name"] = "default:water_source", ["z"] = 3, ["meta"] = { ["inventory"] = {  }, ["fields"] = {  } }, ["param2"] = 0, ["param1"] = 106 }, { ["y"] = 2, ["x"] = 5, ["name"] = "default:water_source", ["z"] = 4, ["meta"] = { ["inventory"] = {  }, ["fields"] = {  } }, ["param2"] = 0, ["param1"] = 89 }, { ["y"] = 2, ["x"] = 5, ["name"] = "default:water_source", ["z"] = 5, ["meta"] = { ["inventory"] = {  }, ["fields"] = {  } }, ["param2"] = 240, ["param1"] = 72 }, { ["y"] = 2, ["x"] = 5, ["name"] = "default:water_source", ["z"] = 6, ["meta"] = { ["inventory"] = {  }, ["fields"] = {  } }, ["param2"] = 240, ["param1"] = 56 }, { ["y"] = 2, ["x"] = 5, ["name"] = "default:water_source", ["z"] = 7, ["meta"] = { ["inventory"] = {  }, ["fields"] = {  } }, ["param2"] = 240, ["param1"] = 40 }, { ["y"] = 2, ["x"] = 5, ["name"] = "default:water_source", ["z"] = 8, ["meta"] = { ["inventory"] = {  }, ["fields"] = {  } }, ["param2"] = 240, ["param1"] = 41 }, { ["y"] = 3, ["x"] = 5, ["name"] = "default:water_source", ["z"] = 0, ["meta"] = { ["inventory"] = {  }, ["fields"] = {  } }, ["param2"] = 0, ["param1"] = 141 }, { ["y"] = 3, ["x"] = 5, ["name"] = "default:water_source", ["z"] = 1, ["meta"] = { ["inventory"] = {  }, ["fields"] = {  } }, ["param2"] = 0, ["param1"] = 157 }, { ["y"] = 3, ["x"] = 5, ["name"] = "default:water_source", ["z"] = 2, ["meta"] = { ["inventory"] = {  }, ["fields"] = {  } }, ["param2"] = 0, ["param1"] = 140 }, { ["y"] = 3, ["x"] = 5, ["name"] = "moretrees:palm_planks", ["z"] = 3, ["meta"] = { ["inventory"] = {  }, ["fields"] = {  } }, ["param2"] = 0, ["param1"] = 0 }, { ["y"] = 3, ["x"] = 5, ["name"] = "moretrees:palm_planks", ["z"] = 4, ["meta"] = { ["inventory"] = {  }, ["fields"] = {  } }, ["param2"] = 0, ["param1"] = 0 }, { ["y"] = 3, ["x"] = 5, ["name"] = "moretrees:palm_planks", ["z"] = 5, ["meta"] = { ["inventory"] = {  }, ["fields"] = {  } }, ["param2"] = 0, ["param1"] = 0 }, { ["y"] = 3, ["x"] = 5, ["name"] = "moretrees:palm_planks", ["z"] = 6, ["meta"] = { ["inventory"] = {  }, ["fields"] = {  } }, ["param2"] = 0, ["param1"] = 0 }, { ["y"] = 3, ["x"] = 5, ["name"] = "moretrees:palm_planks", ["z"] = 7, ["meta"] = { ["inventory"] = {  }, ["fields"] = {  } }, ["param2"] = 0, ["param1"] = 0 }, { ["y"] = 3, ["x"] = 5, ["name"] = "moretrees:palm_planks", ["z"] = 8, ["meta"] = { ["inventory"] = {  }, ["fields"] = {  } }, ["param2"] = 0, ["param1"] = 0 }, { ["y"] = 4, ["x"] = 5, ["name"] = "moretrees:palm_planks", ["z"] = 2, ["meta"] = { ["inventory"] = {  }, ["fields"] = {  } }, ["param2"] = 0, ["param1"] = 0 }, { ["y"] = 4, ["x"] = 5, ["name"] = "moretrees:palm_planks", ["z"] = 4, ["meta"] = { ["inventory"] = {  }, ["fields"] = {  } }, ["param2"] = 0, ["param1"] = 0 }, { ["y"] = 4, ["x"] = 5, ["name"] = "default:furnace", ["z"] = 5, ["meta"] = { ["inventory"] = { ["dst"] = { "", "", "", "" }, ["src"] = { "" }, ["fuel"] = { "" } }, ["fields"] = { ["src_time"] = "0", ["fuel_totaltime"] = "0", ["infotext"] = "Furnace inactive (Item: Empty; Fuel: Empty)", ["formspec"] = "size[8,8.5]listcolors[#606060AA;#808080;#101010;#202020;#FFF]list[current_name;src;2.75,0.5;1,1;]list[current_name;fuel;2.75,2.5;1,1;]image[2.75,1.5;1,1;default_furnace_fire_bg.png]image[3.75,1.5;1,1;gui_furnace_arrow_bg.png^[transformR270]list[current_name;dst;4.75,0.96;2,2;]list[current_player;main;0,4.25;8,1;]list[current_player;main;0,5.5;8,3;8]image[0,4.25;1,1;gui_hb_bg.png]image[1,4.25;1,1;gui_hb_bg.png]image[2,4.25;1,1;gui_hb_bg.png]image[3,4.25;1,1;gui_hb_bg.png]image[4,4.25;1,1;gui_hb_bg.png]image[5,4.25;1,1;gui_hb_bg.png]image[6,4.25;1,1;gui_hb_bg.png]image[7,4.25;1,1;gui_hb_bg.png]", ["fuel_time"] = "0" } }, ["param2"] = 3, ["param1"] = 0 }, { ["y"] = 4, ["x"] = 5, ["name"] = "default:chest", ["z"] = 6, ["meta"] = { ["inventory"] = { ["main"] = { "mesecons_pressureplates:pressure_plate_stone_off 3", "default:sand", "doors:door_wood", "farming:tomato 10", "farming:corn 16", "trunks:twig_1 2", "ferns:tree_fern_leaves_giant", "trunks:moss 2", "dryplants:juncus", "default:sapling 12", "default:junglegrass 5", "ferns:tree_fern_leaves", "", "", "", "", "", "", "", "", "", "", "", "", "", "", "", "", "", "", "", "" } }, ["fields"] = { ["formspec"] = "size[8,9]listcolors[#606060AA;#808080;#101010;#202020;#FFF]list[current_name;main;0,0.3;8,4;]list[current_player;main;0,4.85;8,4;]image[0,4.85;1,1;gui_hb_bg.png]image[1,4.85;1,1;gui_hb_bg.png]image[2,4.85;1,1;gui_hb_bg.png]image[3,4.85;1,1;gui_hb_bg.png]image[4,4.85;1,1;gui_hb_bg.png]image[5,4.85;1,1;gui_hb_bg.png]image[6,4.85;1,1;gui_hb_bg.png]image[7,4.85;1,1;gui_hb_bg.png]image[0,5.85;1,1;gui_hb_bg.png]image[1,5.85;1,1;gui_hb_bg.png]image[2,5.85;1,1;gui_hb_bg.png]image[3,5.85;1,1;gui_hb_bg.png]image[4,5.85;1,1;gui_hb_bg.png]image[5,5.85;1,1;gui_hb_bg.png]image[6,5.85;1,1;gui_hb_bg.png]image[7,5.85;1,1;gui_hb_bg.png]", ["infotext"] = "Chest" } }, ["param2"] = 3, ["param1"] = 0 }, { ["y"] = 4, ["x"] = 5, ["name"] = "beds:bed_top", ["z"] = 7, ["meta"] = { ["inventory"] = {  }, ["fields"] = {  } }, ["param2"] = 3, ["param1"] = 204 }, { ["y"] = 4, ["x"] = 5, ["name"] = "moretrees:palm_planks", ["z"] = 8, ["meta"] = { ["inventory"] = {  }, ["fields"] = {  } }, ["param2"] = 0, ["param1"] = 0 }, { ["y"] = 5, ["x"] = 5, ["name"] = "moretrees:palm_planks", ["z"] = 4, ["meta"] = { ["inventory"] = {  }, ["fields"] = {  } }, ["param2"] = 0, ["param1"] = 0 }, { ["y"] = 5, ["x"] = 5, ["name"] = "moretrees:palm_planks", ["z"] = 8, ["meta"] = { ["inventory"] = {  }, ["fields"] = {  } }, ["param2"] = 0, ["param1"] = 0 }, { ["y"] = 6, ["x"] = 5, ["name"] = "moretrees:palm_planks", ["z"] = 4, ["meta"] = { ["inventory"] = {  }, ["fields"] = {  } }, ["param2"] = 0, ["param1"] = 0 }, { ["y"] = 6, ["x"] = 5, ["name"] = "default:torch", ["z"] = 5, ["meta"] = { ["inventory"] = {  }, ["fields"] = {  } }, ["param2"] = 3, ["param1"] = 0 }, { ["y"] = 6, ["x"] = 5, ["name"] = "default:torch", ["z"] = 7, ["meta"] = { ["inventory"] = {  }, ["fields"] = {  } }, ["param2"] = 3, ["param1"] = 0 }, { ["y"] = 6, ["x"] = 5, ["name"] = "moretrees:palm_planks", ["z"] = 8, ["meta"] = { ["inventory"] = {  }, ["fields"] = {  } }, ["param2"] = 0, ["param1"] = 0 }, { ["y"] = 7, ["x"] = 5, ["name"] = "moretrees:palm_planks", ["z"] = 4, ["meta"] = { ["inventory"] = {  }, ["fields"] = {  } }, ["param2"] = 0, ["param1"] = 0 }, { ["y"] = 7, ["x"] = 5, ["name"] = "moretrees:palm_planks", ["z"] = 5, ["meta"] = { ["inventory"] = {  }, ["fields"] = {  } }, ["param2"] = 0, ["param1"] = 0 }, { ["y"] = 7, ["x"] = 5, ["name"] = "moretrees:palm_planks", ["z"] = 6, ["meta"] = { ["inventory"] = {  }, ["fields"] = {  } }, ["param2"] = 0, ["param1"] = 0 }, { ["y"] = 7, ["x"] = 5, ["name"] = "moretrees:palm_planks", ["z"] = 7, ["meta"] = { ["inventory"] = {  }, ["fields"] = {  } }, ["param2"] = 0, ["param1"] = 0 }, { ["y"] = 7, ["x"] = 5, ["name"] = "moretrees:palm_planks", ["z"] = 8, ["meta"] = { ["inventory"] = {  }, ["fields"] = {  } }, ["param2"] = 0, ["param1"] = 0 }, { ["y"] = 0, ["x"] = 6, ["name"] = "default:water_source", ["z"] = 0, ["meta"] = { ["inventory"] = {  }, ["fields"] = {  } }, ["param2"] = 240, ["param1"] = 106 }, { ["y"] = 0, ["x"] = 6, ["name"] = "default:water_source", ["z"] = 1, ["meta"] = { ["inventory"] = {  }, ["fields"] = {  } }, ["param2"] = 240, ["param1"] = 122 }, { ["y"] = 0, ["x"] = 6, ["name"] = "default:water_source", ["z"] = 2, ["meta"] = { ["inventory"] = {  }, ["fields"] = {  } }, ["param2"] = 240, ["param1"] = 105 }, { ["y"] = 0, ["x"] = 6, ["name"] = "default:water_source", ["z"] = 3, ["meta"] = { ["inventory"] = {  }, ["fields"] = {  } }, ["param2"] = 240, ["param1"] = 88 }, { ["y"] = 0, ["x"] = 6, ["name"] = "default:water_source", ["z"] = 4, ["meta"] = { ["inventory"] = {  }, ["fields"] = {  } }, ["param2"] = 240, ["param1"] = 71 }, { ["y"] = 0, ["x"] = 6, ["name"] = "default:water_source", ["z"] = 5, ["meta"] = { ["inventory"] = {  }, ["fields"] = {  } }, ["param2"] = 240, ["param1"] = 54 }, { ["y"] = 0, ["x"] = 6, ["name"] = "default:water_source", ["z"] = 6, ["meta"] = { ["inventory"] = {  }, ["fields"] = {  } }, ["param2"] = 240, ["param1"] = 38 }, { ["y"] = 0, ["x"] = 6, ["name"] = "default:water_source", ["z"] = 7, ["meta"] = { ["inventory"] = {  }, ["fields"] = {  } }, ["param2"] = 240, ["param1"] = 23 }, { ["y"] = 0, ["x"] = 6, ["name"] = "default:water_source", ["z"] = 8, ["meta"] = { ["inventory"] = {  }, ["fields"] = {  } }, ["param2"] = 240, ["param1"] = 8 }, { ["y"] = 1, ["x"] = 6, ["name"] = "default:water_source", ["z"] = 0, ["meta"] = { ["inventory"] = {  }, ["fields"] = {  } }, ["param2"] = 0, ["param1"] = 123 }, { ["y"] = 1, ["x"] = 6, ["name"] = "default:water_source", ["z"] = 1, ["meta"] = { ["inventory"] = {  }, ["fields"] = {  } }, ["param2"] = 0, ["param1"] = 139 }, { ["y"] = 1, ["x"] = 6, ["name"] = "default:water_source", ["z"] = 2, ["meta"] = { ["inventory"] = {  }, ["fields"] = {  } }, ["param2"] = 0, ["param1"] = 122 }, { ["y"] = 1, ["x"] = 6, ["name"] = "default:water_source", ["z"] = 3, ["meta"] = { ["inventory"] = {  }, ["fields"] = {  } }, ["param2"] = 0, ["param1"] = 105 }, { ["y"] = 1, ["x"] = 6, ["name"] = "default:water_source", ["z"] = 4, ["meta"] = { ["inventory"] = {  }, ["fields"] = {  } }, ["param2"] = 0, ["param1"] = 88 }, { ["y"] = 1, ["x"] = 6, ["name"] = "default:water_source", ["z"] = 5, ["meta"] = { ["inventory"] = {  }, ["fields"] = {  } }, ["param2"] = 240, ["param1"] = 71 }, { ["y"] = 1, ["x"] = 6, ["name"] = "default:water_source", ["z"] = 6, ["meta"] = { ["inventory"] = {  }, ["fields"] = {  } }, ["param2"] = 240, ["param1"] = 55 }, { ["y"] = 1, ["x"] = 6, ["name"] = "default:water_source", ["z"] = 7, ["meta"] = { ["inventory"] = {  }, ["fields"] = {  } }, ["param2"] = 240, ["param1"] = 40 }, { ["y"] = 1, ["x"] = 6, ["name"] = "default:water_source", ["z"] = 8, ["meta"] = { ["inventory"] = {  }, ["fields"] = {  } }, ["param2"] = 240, ["param1"] = 25 }, { ["y"] = 2, ["x"] = 6, ["name"] = "default:water_source", ["z"] = 0, ["meta"] = { ["inventory"] = {  }, ["fields"] = {  } }, ["param2"] = 0, ["param1"] = 140 }, { ["y"] = 2, ["x"] = 6, ["name"] = "default:water_source", ["z"] = 1, ["meta"] = { ["inventory"] = {  }, ["fields"] = {  } }, ["param2"] = 0, ["param1"] = 156 }, { ["y"] = 2, ["x"] = 6, ["name"] = "default:water_source", ["z"] = 2, ["meta"] = { ["inventory"] = {  }, ["fields"] = {  } }, ["param2"] = 0, ["param1"] = 139 }, { ["y"] = 2, ["x"] = 6, ["name"] = "default:water_source", ["z"] = 3, ["meta"] = { ["inventory"] = {  }, ["fields"] = {  } }, ["param2"] = 0, ["param1"] = 122 }, { ["y"] = 2, ["x"] = 6, ["name"] = "default:water_source", ["z"] = 4, ["meta"] = { ["inventory"] = {  }, ["fields"] = {  } }, ["param2"] = 0, ["param1"] = 105 }, { ["y"] = 2, ["x"] = 6, ["name"] = "default:water_source", ["z"] = 5, ["meta"] = { ["inventory"] = {  }, ["fields"] = {  } }, ["param2"] = 0, ["param1"] = 88 }, { ["y"] = 2, ["x"] = 6, ["name"] = "default:water_source", ["z"] = 6, ["meta"] = { ["inventory"] = {  }, ["fields"] = {  } }, ["param2"] = 0, ["param1"] = 72 }, { ["y"] = 2, ["x"] = 6, ["name"] = "default:water_source", ["z"] = 7, ["meta"] = { ["inventory"] = {  }, ["fields"] = {  } }, ["param2"] = 240, ["param1"] = 57 }, { ["y"] = 2, ["x"] = 6, ["name"] = "default:water_source", ["z"] = 8, ["meta"] = { ["inventory"] = {  }, ["fields"] = {  } }, ["param2"] = 240, ["param1"] = 42 }, { ["y"] = 3, ["x"] = 6, ["name"] = "default:water_source", ["z"] = 0, ["meta"] = { ["inventory"] = {  }, ["fields"] = {  } }, ["param2"] = 0, ["param1"] = 157 }, { ["y"] = 3, ["x"] = 6, ["name"] = "default:water_source", ["z"] = 1, ["meta"] = { ["inventory"] = {  }, ["fields"] = {  } }, ["param2"] = 0, ["param1"] = 173 }, { ["y"] = 3, ["x"] = 6, ["name"] = "default:water_source", ["z"] = 2, ["meta"] = { ["inventory"] = {  }, ["fields"] = {  } }, ["param2"] = 0, ["param1"] = 156 }, { ["y"] = 3, ["x"] = 6, ["name"] = "moretrees:palm_planks", ["z"] = 3, ["meta"] = { ["inventory"] = {  }, ["fields"] = {  } }, ["param2"] = 0, ["param1"] = 0 }, { ["y"] = 3, ["x"] = 6, ["name"] = "moretrees:palm_planks", ["z"] = 4, ["meta"] = { ["inventory"] = {  }, ["fields"] = {  } }, ["param2"] = 0, ["param1"] = 0 }, { ["y"] = 3, ["x"] = 6, ["name"] = "moretrees:palm_planks", ["z"] = 5, ["meta"] = { ["inventory"] = {  }, ["fields"] = {  } }, ["param2"] = 0, ["param1"] = 0 }, { ["y"] = 3, ["x"] = 6, ["name"] = "moretrees:palm_planks", ["z"] = 6, ["meta"] = { ["inventory"] = {  }, ["fields"] = {  } }, ["param2"] = 0, ["param1"] = 0 }, { ["y"] = 3, ["x"] = 6, ["name"] = "moretrees:palm_planks", ["z"] = 7, ["meta"] = { ["inventory"] = {  }, ["fields"] = {  } }, ["param2"] = 0, ["param1"] = 0 }, { ["y"] = 3, ["x"] = 6, ["name"] = "moretrees:palm_planks", ["z"] = 8, ["meta"] = { ["inventory"] = {  }, ["fields"] = {  } }, ["param2"] = 0, ["param1"] = 0 }, { ["y"] = 4, ["x"] = 6, ["name"] = "moretrees:palm_planks", ["z"] = 2, ["meta"] = { ["inventory"] = {  }, ["fields"] = {  } }, ["param2"] = 0, ["param1"] = 0 }, { ["y"] = 4, ["x"] = 6, ["name"] = "moretrees:palm_planks", ["z"] = 4, ["meta"] = { ["inventory"] = {  }, ["fields"] = {  } }, ["param2"] = 0, ["param1"] = 0 }, { ["y"] = 4, ["x"] = 6, ["name"] = "beds:bed_bottom", ["z"] = 7, ["meta"] = { ["inventory"] = {  }, ["fields"] = {  } }, ["param2"] = 3, ["param1"] = 187 }, { ["y"] = 4, ["x"] = 6, ["name"] = "moretrees:palm_planks", ["z"] = 8, ["meta"] = { ["inventory"] = {  }, ["fields"] = {  } }, ["param2"] = 0, ["param1"] = 0 }, { ["y"] = 5, ["x"] = 6, ["name"] = "moretrees:palm_planks", ["z"] = 4, ["meta"] = { ["inventory"] = {  }, ["fields"] = {  } }, ["param2"] = 0, ["param1"] = 0 }, { ["y"] = 5, ["x"] = 6, ["name"] = "moretrees:palm_planks", ["z"] = 8, ["meta"] = { ["inventory"] = {  }, ["fields"] = {  } }, ["param2"] = 0, ["param1"] = 0 }, { ["y"] = 6, ["x"] = 6, ["name"] = "moretrees:palm_planks", ["z"] = 4, ["meta"] = { ["inventory"] = {  }, ["fields"] = {  } }, ["param2"] = 0, ["param1"] = 0 }, { ["y"] = 6, ["x"] = 6, ["name"] = "moretrees:palm_planks", ["z"] = 8, ["meta"] = { ["inventory"] = {  }, ["fields"] = {  } }, ["param2"] = 0, ["param1"] = 0 }, { ["y"] = 7, ["x"] = 6, ["name"] = "moretrees:palm_planks", ["z"] = 4, ["meta"] = { ["inventory"] = {  }, ["fields"] = {  } }, ["param2"] = 0, ["param1"] = 0 }, { ["y"] = 7, ["x"] = 6, ["name"] = "moretrees:palm_planks", ["z"] = 5, ["meta"] = { ["inventory"] = {  }, ["fields"] = {  } }, ["param2"] = 0, ["param1"] = 0 }, { ["y"] = 7, ["x"] = 6, ["name"] = "moretrees:palm_planks", ["z"] = 6, ["meta"] = { ["inventory"] = {  }, ["fields"] = {  } }, ["param2"] = 0, ["param1"] = 0 }, { ["y"] = 7, ["x"] = 6, ["name"] = "moretrees:palm_planks", ["z"] = 7, ["meta"] = { ["inventory"] = {  }, ["fields"] = {  } }, ["param2"] = 0, ["param1"] = 0 }, { ["y"] = 7, ["x"] = 6, ["name"] = "moretrees:palm_planks", ["z"] = 8, ["meta"] = { ["inventory"] = {  }, ["fields"] = {  } }, ["param2"] = 0, ["param1"] = 0 }, { ["y"] = 0, ["x"] = 7, ["name"] = "default:water_source", ["z"] = 0, ["meta"] = { ["inventory"] = {  }, ["fields"] = {  } }, ["param2"] = 240, ["param1"] = 122 }, { ["y"] = 0, ["x"] = 7, ["name"] = "default:water_source", ["z"] = 1, ["meta"] = { ["inventory"] = {  }, ["fields"] = {  } }, ["param2"] = 0, ["param1"] = 138 }, { ["y"] = 0, ["x"] = 7, ["name"] = "default:water_source", ["z"] = 2, ["meta"] = { ["inventory"] = {  }, ["fields"] = {  } }, ["param2"] = 0, ["param1"] = 121 }, { ["y"] = 0, ["x"] = 7, ["name"] = "default:water_source", ["z"] = 3, ["meta"] = { ["inventory"] = {  }, ["fields"] = {  } }, ["param2"] = 240, ["param1"] = 104 }, { ["y"] = 0, ["x"] = 7, ["name"] = "default:water_source", ["z"] = 4, ["meta"] = { ["inventory"] = {  }, ["fields"] = {  } }, ["param2"] = 240, ["param1"] = 87 }, { ["y"] = 0, ["x"] = 7, ["name"] = "default:water_source", ["z"] = 5, ["meta"] = { ["inventory"] = {  }, ["fields"] = {  } }, ["param2"] = 240, ["param1"] = 70 }, { ["y"] = 0, ["x"] = 7, ["name"] = "default:water_source", ["z"] = 6, ["meta"] = { ["inventory"] = {  }, ["fields"] = {  } }, ["param2"] = 240, ["param1"] = 54 }, { ["y"] = 0, ["x"] = 7, ["name"] = "default:water_source", ["z"] = 7, ["meta"] = { ["inventory"] = {  }, ["fields"] = {  } }, ["param2"] = 240, ["param1"] = 39 }, { ["y"] = 0, ["x"] = 7, ["name"] = "default:water_source", ["z"] = 8, ["meta"] = { ["inventory"] = {  }, ["fields"] = {  } }, ["param2"] = 240, ["param1"] = 24 }, { ["y"] = 1, ["x"] = 7, ["name"] = "default:water_source", ["z"] = 0, ["meta"] = { ["inventory"] = {  }, ["fields"] = {  } }, ["param2"] = 0, ["param1"] = 139 }, { ["y"] = 1, ["x"] = 7, ["name"] = "default:water_source", ["z"] = 1, ["meta"] = { ["inventory"] = {  }, ["fields"] = {  } }, ["param2"] = 0, ["param1"] = 155 }, { ["y"] = 1, ["x"] = 7, ["name"] = "default:water_source", ["z"] = 2, ["meta"] = { ["inventory"] = {  }, ["fields"] = {  } }, ["param2"] = 0, ["param1"] = 138 }, { ["y"] = 1, ["x"] = 7, ["name"] = "default:water_source", ["z"] = 3, ["meta"] = { ["inventory"] = {  }, ["fields"] = {  } }, ["param2"] = 0, ["param1"] = 121 }, { ["y"] = 1, ["x"] = 7, ["name"] = "default:water_source", ["z"] = 4, ["meta"] = { ["inventory"] = {  }, ["fields"] = {  } }, ["param2"] = 0, ["param1"] = 104 }, { ["y"] = 1, ["x"] = 7, ["name"] = "default:water_source", ["z"] = 5, ["meta"] = { ["inventory"] = {  }, ["fields"] = {  } }, ["param2"] = 240, ["param1"] = 87 }, { ["y"] = 1, ["x"] = 7, ["name"] = "default:water_source", ["z"] = 6, ["meta"] = { ["inventory"] = {  }, ["fields"] = {  } }, ["param2"] = 240, ["param1"] = 71 }, { ["y"] = 1, ["x"] = 7, ["name"] = "default:water_source", ["z"] = 7, ["meta"] = { ["inventory"] = {  }, ["fields"] = {  } }, ["param2"] = 240, ["param1"] = 56 }, { ["y"] = 1, ["x"] = 7, ["name"] = "default:water_source", ["z"] = 8, ["meta"] = { ["inventory"] = {  }, ["fields"] = {  } }, ["param2"] = 240, ["param1"] = 41 }, { ["y"] = 2, ["x"] = 7, ["name"] = "default:water_source", ["z"] = 0, ["meta"] = { ["inventory"] = {  }, ["fields"] = {  } }, ["param2"] = 0, ["param1"] = 156 }, { ["y"] = 2, ["x"] = 7, ["name"] = "default:water_source", ["z"] = 1, ["meta"] = { ["inventory"] = {  }, ["fields"] = {  } }, ["param2"] = 0, ["param1"] = 172 }, { ["y"] = 2, ["x"] = 7, ["name"] = "default:water_source", ["z"] = 2, ["meta"] = { ["inventory"] = {  }, ["fields"] = {  } }, ["param2"] = 0, ["param1"] = 155 }, { ["y"] = 2, ["x"] = 7, ["name"] = "default:water_source", ["z"] = 3, ["meta"] = { ["inventory"] = {  }, ["fields"] = {  } }, ["param2"] = 0, ["param1"] = 138 }, { ["y"] = 2, ["x"] = 7, ["name"] = "default:water_source", ["z"] = 4, ["meta"] = { ["inventory"] = {  }, ["fields"] = {  } }, ["param2"] = 0, ["param1"] = 121 }, { ["y"] = 2, ["x"] = 7, ["name"] = "default:water_source", ["z"] = 5, ["meta"] = { ["inventory"] = {  }, ["fields"] = {  } }, ["param2"] = 0, ["param1"] = 104 }, { ["y"] = 2, ["x"] = 7, ["name"] = "default:water_source", ["z"] = 6, ["meta"] = { ["inventory"] = {  }, ["fields"] = {  } }, ["param2"] = 0, ["param1"] = 88 }, { ["y"] = 2, ["x"] = 7, ["name"] = "default:water_source", ["z"] = 7, ["meta"] = { ["inventory"] = {  }, ["fields"] = {  } }, ["param2"] = 240, ["param1"] = 73 }, { ["y"] = 2, ["x"] = 7, ["name"] = "default:water_source", ["z"] = 8, ["meta"] = { ["inventory"] = {  }, ["fields"] = {  } }, ["param2"] = 240, ["param1"] = 58 }, { ["y"] = 3, ["x"] = 7, ["name"] = "default:water_source", ["z"] = 0, ["meta"] = { ["inventory"] = {  }, ["fields"] = {  } }, ["param2"] = 0, ["param1"] = 173 }, { ["y"] = 3, ["x"] = 7, ["name"] = "default:water_source", ["z"] = 1, ["meta"] = { ["inventory"] = {  }, ["fields"] = {  } }, ["param2"] = 0, ["param1"] = 189 }, { ["y"] = 3, ["x"] = 7, ["name"] = "default:water_source", ["z"] = 2, ["meta"] = { ["inventory"] = {  }, ["fields"] = {  } }, ["param2"] = 240, ["param1"] = 172 }, { ["y"] = 3, ["x"] = 7, ["name"] = "moretrees:palm_planks", ["z"] = 3, ["meta"] = { ["inventory"] = {  }, ["fields"] = {  } }, ["param2"] = 0, ["param1"] = 0 }, { ["y"] = 3, ["x"] = 7, ["name"] = "moretrees:palm_planks", ["z"] = 4, ["meta"] = { ["inventory"] = {  }, ["fields"] = {  } }, ["param2"] = 0, ["param1"] = 0 }, { ["y"] = 3, ["x"] = 7, ["name"] = "moretrees:palm_planks", ["z"] = 5, ["meta"] = { ["inventory"] = {  }, ["fields"] = {  } }, ["param2"] = 0, ["param1"] = 0 }, { ["y"] = 3, ["x"] = 7, ["name"] = "moretrees:palm_planks", ["z"] = 6, ["meta"] = { ["inventory"] = {  }, ["fields"] = {  } }, ["param2"] = 0, ["param1"] = 0 }, { ["y"] = 3, ["x"] = 7, ["name"] = "moretrees:palm_planks", ["z"] = 7, ["meta"] = { ["inventory"] = {  }, ["fields"] = {  } }, ["param2"] = 0, ["param1"] = 0 }, { ["y"] = 3, ["x"] = 7, ["name"] = "moretrees:palm_planks", ["z"] = 8, ["meta"] = { ["inventory"] = {  }, ["fields"] = {  } }, ["param2"] = 0, ["param1"] = 0 }, { ["y"] = 4, ["x"] = 7, ["name"] = "moretrees:palm_planks", ["z"] = 2, ["meta"] = { ["inventory"] = {  }, ["fields"] = {  } }, ["param2"] = 0, ["param1"] = 0 }, { ["y"] = 4, ["x"] = 7, ["name"] = "moretrees:palm_planks", ["z"] = 4, ["meta"] = { ["inventory"] = {  }, ["fields"] = {  } }, ["param2"] = 0, ["param1"] = 0 }, { ["y"] = 4, ["x"] = 7, ["name"] = "moretrees:palm_planks", ["z"] = 8, ["meta"] = { ["inventory"] = {  }, ["fields"] = {  } }, ["param2"] = 0, ["param1"] = 0 }, { ["y"] = 5, ["x"] = 7, ["name"] = "default:torch", ["z"] = 2, ["meta"] = { ["inventory"] = {  }, ["fields"] = {  } }, ["param2"] = 1, ["param1"] = 15 }, { ["y"] = 5, ["x"] = 7, ["name"] = "moretrees:palm_planks", ["z"] = 4, ["meta"] = { ["inventory"] = {  }, ["fields"] = {  } }, ["param2"] = 0, ["param1"] = 0 }, { ["y"] = 5, ["x"] = 7, ["name"] = "moretrees:palm_planks", ["z"] = 8, ["meta"] = { ["inventory"] = {  }, ["fields"] = {  } }, ["param2"] = 0, ["param1"] = 0 }, { ["y"] = 6, ["x"] = 7, ["name"] = "default:torch", ["z"] = 3, ["meta"] = { ["inventory"] = {  }, ["fields"] = {  } }, ["param2"] = 4, ["param1"] = 15 }, { ["y"] = 6, ["x"] = 7, ["name"] = "moretrees:palm_planks", ["z"] = 4, ["meta"] = { ["inventory"] = {  }, ["fields"] = {  } }, ["param2"] = 0, ["param1"] = 0 }, { ["y"] = 6, ["x"] = 7, ["name"] = "moretrees:palm_planks", ["z"] = 8, ["meta"] = { ["inventory"] = {  }, ["fields"] = {  } }, ["param2"] = 0, ["param1"] = 0 }, { ["y"] = 7, ["x"] = 7, ["name"] = "moretrees:palm_planks", ["z"] = 4, ["meta"] = { ["inventory"] = {  }, ["fields"] = {  } }, ["param2"] = 0, ["param1"] = 0 }, { ["y"] = 7, ["x"] = 7, ["name"] = "moretrees:palm_planks", ["z"] = 5, ["meta"] = { ["inventory"] = {  }, ["fields"] = {  } }, ["param2"] = 0, ["param1"] = 0 }, { ["y"] = 7, ["x"] = 7, ["name"] = "moretrees:palm_planks", ["z"] = 6, ["meta"] = { ["inventory"] = {  }, ["fields"] = {  } }, ["param2"] = 0, ["param1"] = 0 }, { ["y"] = 7, ["x"] = 7, ["name"] = "moretrees:palm_planks", ["z"] = 7, ["meta"] = { ["inventory"] = {  }, ["fields"] = {  } }, ["param2"] = 0, ["param1"] = 0 }, { ["y"] = 7, ["x"] = 7, ["name"] = "moretrees:palm_planks", ["z"] = 8, ["meta"] = { ["inventory"] = {  }, ["fields"] = {  } }, ["param2"] = 0, ["param1"] = 0 }, { ["y"] = 0, ["x"] = 8, ["name"] = "default:water_source", ["z"] = 0, ["meta"] = { ["inventory"] = {  }, ["fields"] = {  } }, ["param2"] = 240, ["param1"] = 106 }, { ["y"] = 0, ["x"] = 8, ["name"] = "default:water_source", ["z"] = 1, ["meta"] = { ["inventory"] = {  }, ["fields"] = {  } }, ["param2"] = 0, ["param1"] = 122 }, { ["y"] = 0, ["x"] = 8, ["name"] = "default:water_source", ["z"] = 2, ["meta"] = { ["inventory"] = {  }, ["fields"] = {  } }, ["param2"] = 0, ["param1"] = 105 }, { ["y"] = 0, ["x"] = 8, ["name"] = "default:water_source", ["z"] = 3, ["meta"] = { ["inventory"] = {  }, ["fields"] = {  } }, ["param2"] = 240, ["param1"] = 88 }, { ["y"] = 0, ["x"] = 8, ["name"] = "default:water_source", ["z"] = 4, ["meta"] = { ["inventory"] = {  }, ["fields"] = {  } }, ["param2"] = 240, ["param1"] = 71 }, { ["y"] = 0, ["x"] = 8, ["name"] = "default:water_source", ["z"] = 5, ["meta"] = { ["inventory"] = {  }, ["fields"] = {  } }, ["param2"] = 240, ["param1"] = 54 }, { ["y"] = 0, ["x"] = 8, ["name"] = "default:water_source", ["z"] = 6, ["meta"] = { ["inventory"] = {  }, ["fields"] = {  } }, ["param2"] = 240, ["param1"] = 38 }, { ["y"] = 0, ["x"] = 8, ["name"] = "default:water_source", ["z"] = 7, ["meta"] = { ["inventory"] = {  }, ["fields"] = {  } }, ["param2"] = 240, ["param1"] = 23 }, { ["y"] = 0, ["x"] = 8, ["name"] = "default:water_source", ["z"] = 8, ["meta"] = { ["inventory"] = {  }, ["fields"] = {  } }, ["param2"] = 240, ["param1"] = 8 }, { ["y"] = 1, ["x"] = 8, ["name"] = "default:water_source", ["z"] = 0, ["meta"] = { ["inventory"] = {  }, ["fields"] = {  } }, ["param2"] = 0, ["param1"] = 123 }, { ["y"] = 1, ["x"] = 8, ["name"] = "default:water_source", ["z"] = 1, ["meta"] = { ["inventory"] = {  }, ["fields"] = {  } }, ["param2"] = 0, ["param1"] = 139 }, { ["y"] = 1, ["x"] = 8, ["name"] = "default:water_source", ["z"] = 2, ["meta"] = { ["inventory"] = {  }, ["fields"] = {  } }, ["param2"] = 0, ["param1"] = 122 }, { ["y"] = 1, ["x"] = 8, ["name"] = "default:water_source", ["z"] = 3, ["meta"] = { ["inventory"] = {  }, ["fields"] = {  } }, ["param2"] = 0, ["param1"] = 105 }, { ["y"] = 1, ["x"] = 8, ["name"] = "default:water_source", ["z"] = 4, ["meta"] = { ["inventory"] = {  }, ["fields"] = {  } }, ["param2"] = 0, ["param1"] = 88 }, { ["y"] = 1, ["x"] = 8, ["name"] = "default:water_source", ["z"] = 5, ["meta"] = { ["inventory"] = {  }, ["fields"] = {  } }, ["param2"] = 240, ["param1"] = 71 }, { ["y"] = 1, ["x"] = 8, ["name"] = "default:water_source", ["z"] = 6, ["meta"] = { ["inventory"] = {  }, ["fields"] = {  } }, ["param2"] = 240, ["param1"] = 55 }, { ["y"] = 1, ["x"] = 8, ["name"] = "default:water_source", ["z"] = 7, ["meta"] = { ["inventory"] = {  }, ["fields"] = {  } }, ["param2"] = 240, ["param1"] = 40 }, { ["y"] = 1, ["x"] = 8, ["name"] = "default:water_source", ["z"] = 8, ["meta"] = { ["inventory"] = {  }, ["fields"] = {  } }, ["param2"] = 240, ["param1"] = 25 }, { ["y"] = 2, ["x"] = 8, ["name"] = "default:water_source", ["z"] = 0, ["meta"] = { ["inventory"] = {  }, ["fields"] = {  } }, ["param2"] = 240, ["param1"] = 140 }, { ["y"] = 2, ["x"] = 8, ["name"] = "default:water_source", ["z"] = 1, ["meta"] = { ["inventory"] = {  }, ["fields"] = {  } }, ["param2"] = 240, ["param1"] = 156 }, { ["y"] = 2, ["x"] = 8, ["name"] = "default:water_source", ["z"] = 2, ["meta"] = { ["inventory"] = {  }, ["fields"] = {  } }, ["param2"] = 240, ["param1"] = 139 }, { ["y"] = 2, ["x"] = 8, ["name"] = "default:water_source", ["z"] = 3, ["meta"] = { ["inventory"] = {  }, ["fields"] = {  } }, ["param2"] = 240, ["param1"] = 122 }, { ["y"] = 2, ["x"] = 8, ["name"] = "default:water_source", ["z"] = 4, ["meta"] = { ["inventory"] = {  }, ["fields"] = {  } }, ["param2"] = 240, ["param1"] = 105 }, { ["y"] = 2, ["x"] = 8, ["name"] = "default:water_source", ["z"] = 5, ["meta"] = { ["inventory"] = {  }, ["fields"] = {  } }, ["param2"] = 0, ["param1"] = 88 }, { ["y"] = 2, ["x"] = 8, ["name"] = "default:water_source", ["z"] = 6, ["meta"] = { ["inventory"] = {  }, ["fields"] = {  } }, ["param2"] = 0, ["param1"] = 72 }, { ["y"] = 2, ["x"] = 8, ["name"] = "default:water_source", ["z"] = 7, ["meta"] = { ["inventory"] = {  }, ["fields"] = {  } }, ["param2"] = 240, ["param1"] = 57 }, { ["y"] = 2, ["x"] = 8, ["name"] = "default:water_source", ["z"] = 8, ["meta"] = { ["inventory"] = {  }, ["fields"] = {  } }, ["param2"] = 240, ["param1"] = 42 }, { ["y"] = 3, ["x"] = 8, ["name"] = "default:water_source", ["z"] = 0, ["meta"] = { ["inventory"] = {  }, ["fields"] = {  } }, ["param2"] = 240, ["param1"] = 157 }, { ["y"] = 3, ["x"] = 8, ["name"] = "default:water_source", ["z"] = 1, ["meta"] = { ["inventory"] = {  }, ["fields"] = {  } }, ["param2"] = 240, ["param1"] = 173 }, { ["y"] = 3, ["x"] = 8, ["name"] = "moretrees:palm_planks", ["z"] = 2, ["meta"] = { ["inventory"] = {  }, ["fields"] = {  } }, ["param2"] = 0, ["param1"] = 0 }, { ["y"] = 3, ["x"] = 8, ["name"] = "moretrees:palm_planks", ["z"] = 3, ["meta"] = { ["inventory"] = {  }, ["fields"] = {  } }, ["param2"] = 0, ["param1"] = 0 }, { ["y"] = 3, ["x"] = 8, ["name"] = "moretrees:palm_planks", ["z"] = 4, ["meta"] = { ["inventory"] = {  }, ["fields"] = {  } }, ["param2"] = 0, ["param1"] = 0 }, { ["y"] = 3, ["x"] = 8, ["name"] = "moretrees:palm_planks", ["z"] = 5, ["meta"] = { ["inventory"] = {  }, ["fields"] = {  } }, ["param2"] = 0, ["param1"] = 0 }, { ["y"] = 3, ["x"] = 8, ["name"] = "moretrees:palm_planks", ["z"] = 6, ["meta"] = { ["inventory"] = {  }, ["fields"] = {  } }, ["param2"] = 0, ["param1"] = 0 }, { ["y"] = 3, ["x"] = 8, ["name"] = "moretrees:palm_planks", ["z"] = 7, ["meta"] = { ["inventory"] = {  }, ["fields"] = {  } }, ["param2"] = 0, ["param1"] = 0 }, { ["y"] = 3, ["x"] = 8, ["name"] = "moretrees:palm_planks", ["z"] = 8, ["meta"] = { ["inventory"] = {  }, ["fields"] = {  } }, ["param2"] = 0, ["param1"] = 0 }, { ["y"] = 4, ["x"] = 8, ["name"] = "doors:door_wood_b_1", ["z"] = 4, ["meta"] = { ["inventory"] = {  }, ["fields"] = {  } }, ["param2"] = 0, ["param1"] = 173 }, { ["y"] = 4, ["x"] = 8, ["name"] = "default:chest", ["z"] = 7, ["meta"] = { ["inventory"] = { ["main"] = { "", "", "", "", "", "", "", "", "", "", "", "", "", "", "", "", "", "", "", "", "", "", "", "", "", "", "", "", "", "", "", "" } }, ["fields"] = { ["formspec"] = "size[8,9]listcolors[#606060AA;#808080;#101010;#202020;#FFF]list[current_name;main;0,0.3;8,4;]list[current_player;main;0,4.85;8,4;]image[0,4.85;1,1;gui_hb_bg.png]image[1,4.85;1,1;gui_hb_bg.png]image[2,4.85;1,1;gui_hb_bg.png]image[3,4.85;1,1;gui_hb_bg.png]image[4,4.85;1,1;gui_hb_bg.png]image[5,4.85;1,1;gui_hb_bg.png]image[6,4.85;1,1;gui_hb_bg.png]image[7,4.85;1,1;gui_hb_bg.png]image[0,5.85;1,1;gui_hb_bg.png]image[1,5.85;1,1;gui_hb_bg.png]image[2,5.85;1,1;gui_hb_bg.png]image[3,5.85;1,1;gui_hb_bg.png]image[4,5.85;1,1;gui_hb_bg.png]image[5,5.85;1,1;gui_hb_bg.png]image[6,5.85;1,1;gui_hb_bg.png]image[7,5.85;1,1;gui_hb_bg.png]", ["infotext"] = "Chest" } }, ["param2"] = 1, ["param1"] = 0 }, { ["y"] = 4, ["x"] = 8, ["name"] = "moretrees:palm_planks", ["z"] = 8, ["meta"] = { ["inventory"] = {  }, ["fields"] = {  } }, ["param2"] = 0, ["param1"] = 0 }, { ["y"] = 5, ["x"] = 8, ["name"] = "doors:door_wood_t_1", ["z"] = 4, ["meta"] = { ["inventory"] = {  }, ["fields"] = {  } }, ["param2"] = 0, ["param1"] = 189 }, { ["y"] = 5, ["x"] = 8, ["name"] = "moretrees:palm_planks", ["z"] = 8, ["meta"] = { ["inventory"] = {  }, ["fields"] = {  } }, ["param2"] = 0, ["param1"] = 0 }, { ["y"] = 6, ["x"] = 8, ["name"] = "default:sign_wall", ["z"] = 3, ["meta"] = { ["inventory"] = {  }, ["fields"] = { ["infotext"] = "\
\
Maison maman de julie ", ["text"] = "  \
  \
Maison maman de julie", ["formspec"] = "size[6,4]textarea[0,-0.3;6.5,3;text;;${text}]button_exit[2,3.4;2,1;ok;Write]background[-0.5,-0.5;7,5;bg_signs_lib.jpg]", ["__signslib_new_format"] = "1" } }, ["param2"] = 0, ["param1"] = 223 }, { ["y"] = 6, ["x"] = 8, ["name"] = "moretrees:palm_planks", ["z"] = 4, ["meta"] = { ["inventory"] = {  }, ["fields"] = {  } }, ["param2"] = 0, ["param1"] = 0 }, { ["y"] = 6, ["x"] = 8, ["name"] = "default:torch", ["z"] = 7, ["meta"] = { ["inventory"] = {  }, ["fields"] = {  } }, ["param2"] = 4, ["param1"] = 0 }, { ["y"] = 6, ["x"] = 8, ["name"] = "moretrees:palm_planks", ["z"] = 8, ["meta"] = { ["inventory"] = {  }, ["fields"] = {  } }, ["param2"] = 0, ["param1"] = 0 }, { ["y"] = 7, ["x"] = 8, ["name"] = "moretrees:palm_planks", ["z"] = 4, ["meta"] = { ["inventory"] = {  }, ["fields"] = {  } }, ["param2"] = 0, ["param1"] = 0 }, { ["y"] = 7, ["x"] = 8, ["name"] = "moretrees:palm_planks", ["z"] = 5, ["meta"] = { ["inventory"] = {  }, ["fields"] = {  } }, ["param2"] = 0, ["param1"] = 0 }, { ["y"] = 7, ["x"] = 8, ["name"] = "moretrees:palm_planks", ["z"] = 6, ["meta"] = { ["inventory"] = {  }, ["fields"] = {  } }, ["param2"] = 0, ["param1"] = 0 }, { ["y"] = 7, ["x"] = 8, ["name"] = "moretrees:palm_planks", ["z"] = 7, ["meta"] = { ["inventory"] = {  }, ["fields"] = {  } }, ["param2"] = 0, ["param1"] = 0 }, { ["y"] = 7, ["x"] = 8, ["name"] = "moretrees:palm_planks", ["z"] = 8, ["meta"] = { ["inventory"] = {  }, ["fields"] = {  } }, ["param2"] = 0, ["param1"] = 0 }, { ["y"] = 0, ["x"] = 9, ["name"] = "default:water_source", ["z"] = 0, ["meta"] = { ["inventory"] = {  }, ["fields"] = {  } }, ["param2"] = 240, ["param1"] = 122 }, { ["y"] = 0, ["x"] = 9, ["name"] = "default:water_source", ["z"] = 1, ["meta"] = { ["inventory"] = {  }, ["fields"] = {  } }, ["param2"] = 240, ["param1"] = 138 }, { ["y"] = 0, ["x"] = 9, ["name"] = "default:water_source", ["z"] = 2, ["meta"] = { ["inventory"] = {  }, ["fields"] = {  } }, ["param2"] = 0, ["param1"] = 121 }, { ["y"] = 0, ["x"] = 9, ["name"] = "default:water_source", ["z"] = 3, ["meta"] = { ["inventory"] = {  }, ["fields"] = {  } }, ["param2"] = 240, ["param1"] = 104 }, { ["y"] = 0, ["x"] = 9, ["name"] = "default:water_source", ["z"] = 4, ["meta"] = { ["inventory"] = {  }, ["fields"] = {  } }, ["param2"] = 240, ["param1"] = 87 }, { ["y"] = 0, ["x"] = 9, ["name"] = "default:water_source", ["z"] = 5, ["meta"] = { ["inventory"] = {  }, ["fields"] = {  } }, ["param2"] = 240, ["param1"] = 70 }, { ["y"] = 0, ["x"] = 9, ["name"] = "default:water_source", ["z"] = 6, ["meta"] = { ["inventory"] = {  }, ["fields"] = {  } }, ["param2"] = 240, ["param1"] = 54 }, { ["y"] = 0, ["x"] = 9, ["name"] = "default:water_source", ["z"] = 7, ["meta"] = { ["inventory"] = {  }, ["fields"] = {  } }, ["param2"] = 240, ["param1"] = 39 }, { ["y"] = 0, ["x"] = 9, ["name"] = "default:water_source", ["z"] = 8, ["meta"] = { ["inventory"] = {  }, ["fields"] = {  } }, ["param2"] = 240, ["param1"] = 24 }, { ["y"] = 1, ["x"] = 9, ["name"] = "default:water_source", ["z"] = 0, ["meta"] = { ["inventory"] = {  }, ["fields"] = {  } }, ["param2"] = 0, ["param1"] = 139 }, { ["y"] = 1, ["x"] = 9, ["name"] = "default:water_source", ["z"] = 1, ["meta"] = { ["inventory"] = {  }, ["fields"] = {  } }, ["param2"] = 0, ["param1"] = 155 }, { ["y"] = 1, ["x"] = 9, ["name"] = "default:water_source", ["z"] = 2, ["meta"] = { ["inventory"] = {  }, ["fields"] = {  } }, ["param2"] = 0, ["param1"] = 138 }, { ["y"] = 1, ["x"] = 9, ["name"] = "default:water_source", ["z"] = 3, ["meta"] = { ["inventory"] = {  }, ["fields"] = {  } }, ["param2"] = 0, ["param1"] = 121 }, { ["y"] = 1, ["x"] = 9, ["name"] = "default:water_source", ["z"] = 4, ["meta"] = { ["inventory"] = {  }, ["fields"] = {  } }, ["param2"] = 0, ["param1"] = 104 }, { ["y"] = 1, ["x"] = 9, ["name"] = "default:water_source", ["z"] = 5, ["meta"] = { ["inventory"] = {  }, ["fields"] = {  } }, ["param2"] = 240, ["param1"] = 87 }, { ["y"] = 1, ["x"] = 9, ["name"] = "default:water_source", ["z"] = 6, ["meta"] = { ["inventory"] = {  }, ["fields"] = {  } }, ["param2"] = 240, ["param1"] = 71 }, { ["y"] = 1, ["x"] = 9, ["name"] = "default:water_source", ["z"] = 7, ["meta"] = { ["inventory"] = {  }, ["fields"] = {  } }, ["param2"] = 240, ["param1"] = 56 }, { ["y"] = 1, ["x"] = 9, ["name"] = "default:water_source", ["z"] = 8, ["meta"] = { ["inventory"] = {  }, ["fields"] = {  } }, ["param2"] = 240, ["param1"] = 41 }, { ["y"] = 2, ["x"] = 9, ["name"] = "default:water_source", ["z"] = 0, ["meta"] = { ["inventory"] = {  }, ["fields"] = {  } }, ["param2"] = 240, ["param1"] = 156 }, { ["y"] = 2, ["x"] = 9, ["name"] = "default:water_source", ["z"] = 1, ["meta"] = { ["inventory"] = {  }, ["fields"] = {  } }, ["param2"] = 240, ["param1"] = 172 }, { ["y"] = 2, ["x"] = 9, ["name"] = "default:water_source", ["z"] = 2, ["meta"] = { ["inventory"] = {  }, ["fields"] = {  } }, ["param2"] = 240, ["param1"] = 155 }, { ["y"] = 2, ["x"] = 9, ["name"] = "default:water_source", ["z"] = 3, ["meta"] = { ["inventory"] = {  }, ["fields"] = {  } }, ["param2"] = 240, ["param1"] = 138 }, { ["y"] = 2, ["x"] = 9, ["name"] = "default:water_source", ["z"] = 4, ["meta"] = { ["inventory"] = {  }, ["fields"] = {  } }, ["param2"] = 240, ["param1"] = 121 }, { ["y"] = 2, ["x"] = 9, ["name"] = "default:water_source", ["z"] = 5, ["meta"] = { ["inventory"] = {  }, ["fields"] = {  } }, ["param2"] = 0, ["param1"] = 104 }, { ["y"] = 2, ["x"] = 9, ["name"] = "default:water_source", ["z"] = 6, ["meta"] = { ["inventory"] = {  }, ["fields"] = {  } }, ["param2"] = 0, ["param1"] = 88 }, { ["y"] = 2, ["x"] = 9, ["name"] = "default:water_source", ["z"] = 7, ["meta"] = { ["inventory"] = {  }, ["fields"] = {  } }, ["param2"] = 240, ["param1"] = 73 }, { ["y"] = 2, ["x"] = 9, ["name"] = "default:water_source", ["z"] = 8, ["meta"] = { ["inventory"] = {  }, ["fields"] = {  } }, ["param2"] = 240, ["param1"] = 58 }, { ["y"] = 3, ["x"] = 9, ["name"] = "default:water_source", ["z"] = 0, ["meta"] = { ["inventory"] = {  }, ["fields"] = {  } }, ["param2"] = 240, ["param1"] = 173 }, { ["y"] = 3, ["x"] = 9, ["name"] = "default:water_source", ["z"] = 1, ["meta"] = { ["inventory"] = {  }, ["fields"] = {  } }, ["param2"] = 240, ["param1"] = 189 }, { ["y"] = 3, ["x"] = 9, ["name"] = "default:water_source", ["z"] = 2, ["meta"] = { ["inventory"] = {  }, ["fields"] = {  } }, ["param2"] = 240, ["param1"] = 172 }, { ["y"] = 3, ["x"] = 9, ["name"] = "moretrees:palm_planks", ["z"] = 3, ["meta"] = { ["inventory"] = {  }, ["fields"] = {  } }, ["param2"] = 0, ["param1"] = 0 }, { ["y"] = 3, ["x"] = 9, ["name"] = "moretrees:palm_planks", ["z"] = 4, ["meta"] = { ["inventory"] = {  }, ["fields"] = {  } }, ["param2"] = 0, ["param1"] = 0 }, { ["y"] = 3, ["x"] = 9, ["name"] = "moretrees:palm_planks", ["z"] = 5, ["meta"] = { ["inventory"] = {  }, ["fields"] = {  } }, ["param2"] = 0, ["param1"] = 0 }, { ["y"] = 3, ["x"] = 9, ["name"] = "moretrees:palm_planks", ["z"] = 6, ["meta"] = { ["inventory"] = {  }, ["fields"] = {  } }, ["param2"] = 0, ["param1"] = 0 }, { ["y"] = 3, ["x"] = 9, ["name"] = "moretrees:palm_planks", ["z"] = 7, ["meta"] = { ["inventory"] = {  }, ["fields"] = {  } }, ["param2"] = 0, ["param1"] = 0 }, { ["y"] = 3, ["x"] = 9, ["name"] = "moretrees:palm_planks", ["z"] = 8, ["meta"] = { ["inventory"] = {  }, ["fields"] = {  } }, ["param2"] = 0, ["param1"] = 0 }, { ["y"] = 4, ["x"] = 9, ["name"] = "moretrees:palm_planks", ["z"] = 2, ["meta"] = { ["inventory"] = {  }, ["fields"] = {  } }, ["param2"] = 0, ["param1"] = 0 }, { ["y"] = 4, ["x"] = 9, ["name"] = "moretrees:palm_planks", ["z"] = 4, ["meta"] = { ["inventory"] = {  }, ["fields"] = {  } }, ["param2"] = 0, ["param1"] = 0 }, { ["y"] = 4, ["x"] = 9, ["name"] = "moretrees:palm_planks", ["z"] = 5, ["meta"] = { ["inventory"] = {  }, ["fields"] = {  } }, ["param2"] = 0, ["param1"] = 0 }, { ["y"] = 4, ["x"] = 9, ["name"] = "moretrees:palm_planks", ["z"] = 6, ["meta"] = { ["inventory"] = {  }, ["fields"] = {  } }, ["param2"] = 0, ["param1"] = 0 }, { ["y"] = 4, ["x"] = 9, ["name"] = "moretrees:palm_planks", ["z"] = 7, ["meta"] = { ["inventory"] = {  }, ["fields"] = {  } }, ["param2"] = 0, ["param1"] = 0 }, { ["y"] = 4, ["x"] = 9, ["name"] = "moretrees:palm_planks", ["z"] = 8, ["meta"] = { ["inventory"] = {  }, ["fields"] = {  } }, ["param2"] = 0, ["param1"] = 0 }, { ["y"] = 5, ["x"] = 9, ["name"] = "default:torch", ["z"] = 2, ["meta"] = { ["inventory"] = {  }, ["fields"] = {  } }, ["param2"] = 1, ["param1"] = 15 }, { ["y"] = 5, ["x"] = 9, ["name"] = "moretrees:palm_planks", ["z"] = 4, ["meta"] = { ["inventory"] = {  }, ["fields"] = {  } }, ["param2"] = 0, ["param1"] = 0 }, { ["y"] = 5, ["x"] = 9, ["name"] = "moretrees:palm_planks", ["z"] = 5, ["meta"] = { ["inventory"] = {  }, ["fields"] = {  } }, ["param2"] = 0, ["param1"] = 0 }, { ["y"] = 5, ["x"] = 9, ["name"] = "moretrees:palm_planks", ["z"] = 6, ["meta"] = { ["inventory"] = {  }, ["fields"] = {  } }, ["param2"] = 0, ["param1"] = 0 }, { ["y"] = 5, ["x"] = 9, ["name"] = "moretrees:palm_planks", ["z"] = 7, ["meta"] = { ["inventory"] = {  }, ["fields"] = {  } }, ["param2"] = 0, ["param1"] = 0 }, { ["y"] = 5, ["x"] = 9, ["name"] = "moretrees:palm_planks", ["z"] = 8, ["meta"] = { ["inventory"] = {  }, ["fields"] = {  } }, ["param2"] = 0, ["param1"] = 0 }, { ["y"] = 6, ["x"] = 9, ["name"] = "default:torch", ["z"] = 3, ["meta"] = { ["inventory"] = {  }, ["fields"] = {  } }, ["param2"] = 4, ["param1"] = 15 }, { ["y"] = 6, ["x"] = 9, ["name"] = "moretrees:palm_planks", ["z"] = 4, ["meta"] = { ["inventory"] = {  }, ["fields"] = {  } }, ["param2"] = 0, ["param1"] = 0 }, { ["y"] = 6, ["x"] = 9, ["name"] = "moretrees:palm_planks", ["z"] = 5, ["meta"] = { ["inventory"] = {  }, ["fields"] = {  } }, ["param2"] = 0, ["param1"] = 0 }, { ["y"] = 6, ["x"] = 9, ["name"] = "moretrees:palm_planks", ["z"] = 6, ["meta"] = { ["inventory"] = {  }, ["fields"] = {  } }, ["param2"] = 0, ["param1"] = 0 }, { ["y"] = 6, ["x"] = 9, ["name"] = "moretrees:palm_planks", ["z"] = 7, ["meta"] = { ["inventory"] = {  }, ["fields"] = {  } }, ["param2"] = 0, ["param1"] = 0 }, { ["y"] = 6, ["x"] = 9, ["name"] = "moretrees:palm_planks", ["z"] = 8, ["meta"] = { ["inventory"] = {  }, ["fields"] = {  } }, ["param2"] = 0, ["param1"] = 0 }, { ["y"] = 7, ["x"] = 9, ["name"] = "moretrees:palm_planks", ["z"] = 4, ["meta"] = { ["inventory"] = {  }, ["fields"] = {  } }, ["param2"] = 0, ["param1"] = 0 }, { ["y"] = 7, ["x"] = 9, ["name"] = "moretrees:palm_planks", ["z"] = 5, ["meta"] = { ["inventory"] = {  }, ["fields"] = {  } }, ["param2"] = 0, ["param1"] = 0 }, { ["y"] = 7, ["x"] = 9, ["name"] = "moretrees:palm_planks", ["z"] = 6, ["meta"] = { ["inventory"] = {  }, ["fields"] = {  } }, ["param2"] = 0, ["param1"] = 0 }, { ["y"] = 7, ["x"] = 9, ["name"] = "moretrees:palm_planks", ["z"] = 7, ["meta"] = { ["inventory"] = {  }, ["fields"] = {  } }, ["param2"] = 0, ["param1"] = 0 }, { ["y"] = 7, ["x"] = 9, ["name"] = "moretrees:palm_planks", ["z"] = 8, ["meta"] = { ["inventory"] = {  }, ["fields"] = {  } }, ["param2"] = 0, ["param1"] = 0 }, { ["y"] = 0, ["x"] = 10, ["name"] = "default:water_source", ["z"] = 0, ["meta"] = { ["inventory"] = {  }, ["fields"] = {  } }, ["param2"] = 240, ["param1"] = 106 }, { ["y"] = 0, ["x"] = 10, ["name"] = "default:water_source", ["z"] = 1, ["meta"] = { ["inventory"] = {  }, ["fields"] = {  } }, ["param2"] = 240, ["param1"] = 122 }, { ["y"] = 0, ["x"] = 10, ["name"] = "default:water_source", ["z"] = 2, ["meta"] = { ["inventory"] = {  }, ["fields"] = {  } }, ["param2"] = 0, ["param1"] = 105 }, { ["y"] = 0, ["x"] = 10, ["name"] = "default:water_source", ["z"] = 3, ["meta"] = { ["inventory"] = {  }, ["fields"] = {  } }, ["param2"] = 240, ["param1"] = 88 }, { ["y"] = 0, ["x"] = 10, ["name"] = "default:water_source", ["z"] = 4, ["meta"] = { ["inventory"] = {  }, ["fields"] = {  } }, ["param2"] = 240, ["param1"] = 72 }, { ["y"] = 0, ["x"] = 10, ["name"] = "default:water_source", ["z"] = 5, ["meta"] = { ["inventory"] = {  }, ["fields"] = {  } }, ["param2"] = 240, ["param1"] = 55 }, { ["y"] = 0, ["x"] = 10, ["name"] = "default:water_source", ["z"] = 6, ["meta"] = { ["inventory"] = {  }, ["fields"] = {  } }, ["param2"] = 240, ["param1"] = 39 }, { ["y"] = 0, ["x"] = 10, ["name"] = "default:water_source", ["z"] = 7, ["meta"] = { ["inventory"] = {  }, ["fields"] = {  } }, ["param2"] = 240, ["param1"] = 23 }, { ["y"] = 0, ["x"] = 10, ["name"] = "default:water_source", ["z"] = 8, ["meta"] = { ["inventory"] = {  }, ["fields"] = {  } }, ["param2"] = 240, ["param1"] = 8 }, { ["y"] = 1, ["x"] = 10, ["name"] = "default:water_source", ["z"] = 0, ["meta"] = { ["inventory"] = {  }, ["fields"] = {  } }, ["param2"] = 240, ["param1"] = 123 }, { ["y"] = 1, ["x"] = 10, ["name"] = "default:water_source", ["z"] = 1, ["meta"] = { ["inventory"] = {  }, ["fields"] = {  } }, ["param2"] = 240, ["param1"] = 139 }, { ["y"] = 1, ["x"] = 10, ["name"] = "default:water_source", ["z"] = 2, ["meta"] = { ["inventory"] = {  }, ["fields"] = {  } }, ["param2"] = 0, ["param1"] = 122 }, { ["y"] = 1, ["x"] = 10, ["name"] = "default:water_source", ["z"] = 3, ["meta"] = { ["inventory"] = {  }, ["fields"] = {  } }, ["param2"] = 0, ["param1"] = 105 }, { ["y"] = 1, ["x"] = 10, ["name"] = "default:water_source", ["z"] = 4, ["meta"] = { ["inventory"] = {  }, ["fields"] = {  } }, ["param2"] = 0, ["param1"] = 89 }, { ["y"] = 1, ["x"] = 10, ["name"] = "default:water_source", ["z"] = 5, ["meta"] = { ["inventory"] = {  }, ["fields"] = {  } }, ["param2"] = 0, ["param1"] = 72 }, { ["y"] = 1, ["x"] = 10, ["name"] = "default:water_source", ["z"] = 6, ["meta"] = { ["inventory"] = {  }, ["fields"] = {  } }, ["param2"] = 240, ["param1"] = 56 }, { ["y"] = 1, ["x"] = 10, ["name"] = "default:water_source", ["z"] = 7, ["meta"] = { ["inventory"] = {  }, ["fields"] = {  } }, ["param2"] = 240, ["param1"] = 40 }, { ["y"] = 1, ["x"] = 10, ["name"] = "default:water_source", ["z"] = 8, ["meta"] = { ["inventory"] = {  }, ["fields"] = {  } }, ["param2"] = 240, ["param1"] = 25 }, { ["y"] = 2, ["x"] = 10, ["name"] = "default:water_source", ["z"] = 0, ["meta"] = { ["inventory"] = {  }, ["fields"] = {  } }, ["param2"] = 240, ["param1"] = 140 }, { ["y"] = 2, ["x"] = 10, ["name"] = "default:water_source", ["z"] = 1, ["meta"] = { ["inventory"] = {  }, ["fields"] = {  } }, ["param2"] = 240, ["param1"] = 156 }, { ["y"] = 2, ["x"] = 10, ["name"] = "default:water_source", ["z"] = 2, ["meta"] = { ["inventory"] = {  }, ["fields"] = {  } }, ["param2"] = 240, ["param1"] = 139 }, { ["y"] = 2, ["x"] = 10, ["name"] = "default:water_source", ["z"] = 3, ["meta"] = { ["inventory"] = {  }, ["fields"] = {  } }, ["param2"] = 240, ["param1"] = 122 }, { ["y"] = 2, ["x"] = 10, ["name"] = "default:water_source", ["z"] = 4, ["meta"] = { ["inventory"] = {  }, ["fields"] = {  } }, ["param2"] = 240, ["param1"] = 106 }, { ["y"] = 2, ["x"] = 10, ["name"] = "default:water_source", ["z"] = 5, ["meta"] = { ["inventory"] = {  }, ["fields"] = {  } }, ["param2"] = 0, ["param1"] = 89 }, { ["y"] = 2, ["x"] = 10, ["name"] = "default:water_source", ["z"] = 6, ["meta"] = { ["inventory"] = {  }, ["fields"] = {  } }, ["param2"] = 240, ["param1"] = 73 }, { ["y"] = 2, ["x"] = 10, ["name"] = "default:water_source", ["z"] = 7, ["meta"] = { ["inventory"] = {  }, ["fields"] = {  } }, ["param2"] = 240, ["param1"] = 57 }, { ["y"] = 2, ["x"] = 10, ["name"] = "default:water_source", ["z"] = 8, ["meta"] = { ["inventory"] = {  }, ["fields"] = {  } }, ["param2"] = 240, ["param1"] = 42 }, { ["y"] = 3, ["x"] = 10, ["name"] = "default:water_source", ["z"] = 0, ["meta"] = { ["inventory"] = {  }, ["fields"] = {  } }, ["param2"] = 240, ["param1"] = 157 }, { ["y"] = 3, ["x"] = 10, ["name"] = "default:water_source", ["z"] = 1, ["meta"] = { ["inventory"] = {  }, ["fields"] = {  } }, ["param2"] = 240, ["param1"] = 173 }, { ["y"] = 3, ["x"] = 10, ["name"] = "default:water_source", ["z"] = 2, ["meta"] = { ["inventory"] = {  }, ["fields"] = {  } }, ["param2"] = 240, ["param1"] = 156 }, { ["y"] = 3, ["x"] = 10, ["name"] = "moretrees:palm_planks", ["z"] = 3, ["meta"] = { ["inventory"] = {  }, ["fields"] = {  } }, ["param2"] = 0, ["param1"] = 0 }, { ["y"] = 3, ["x"] = 10, ["name"] = "moretrees:palm_planks", ["z"] = 4, ["meta"] = { ["inventory"] = {  }, ["fields"] = {  } }, ["param2"] = 0, ["param1"] = 0 }, { ["y"] = 3, ["x"] = 10, ["name"] = "moretrees:palm_planks", ["z"] = 5, ["meta"] = { ["inventory"] = {  }, ["fields"] = {  } }, ["param2"] = 0, ["param1"] = 0 }, { ["y"] = 3, ["x"] = 10, ["name"] = "moretrees:palm_planks", ["z"] = 6, ["meta"] = { ["inventory"] = {  }, ["fields"] = {  } }, ["param2"] = 0, ["param1"] = 0 }, { ["y"] = 3, ["x"] = 10, ["name"] = "moretrees:palm_planks", ["z"] = 7, ["meta"] = { ["inventory"] = {  }, ["fields"] = {  } }, ["param2"] = 0, ["param1"] = 0 }, { ["y"] = 3, ["x"] = 10, ["name"] = "default:water_source", ["z"] = 8, ["meta"] = { ["inventory"] = {  }, ["fields"] = {  } }, ["param2"] = 240, ["param1"] = 59 }, { ["y"] = 4, ["x"] = 10, ["name"] = "moretrees:palm_planks", ["z"] = 2, ["meta"] = { ["inventory"] = {  }, ["fields"] = {  } }, ["param2"] = 0, ["param1"] = 0 }, { ["y"] = 4, ["x"] = 10, ["name"] = "moretrees:palm_planks", ["z"] = 8, ["meta"] = { ["inventory"] = {  }, ["fields"] = {  } }, ["param2"] = 0, ["param1"] = 0 }, { ["y"] = 0, ["x"] = 11, ["name"] = "default:water_source", ["z"] = 0, ["meta"] = { ["inventory"] = {  }, ["fields"] = {  } }, ["param2"] = 240, ["param1"] = 90 }, { ["y"] = 0, ["x"] = 11, ["name"] = "default:water_source", ["z"] = 1, ["meta"] = { ["inventory"] = {  }, ["fields"] = {  } }, ["param2"] = 240, ["param1"] = 106 }, { ["y"] = 0, ["x"] = 11, ["name"] = "default:water_source", ["z"] = 2, ["meta"] = { ["inventory"] = {  }, ["fields"] = {  } }, ["param2"] = 0, ["param1"] = 89 }, { ["y"] = 0, ["x"] = 11, ["name"] = "default:water_source", ["z"] = 3, ["meta"] = { ["inventory"] = {  }, ["fields"] = {  } }, ["param2"] = 240, ["param1"] = 73 }, { ["y"] = 0, ["x"] = 11, ["name"] = "default:water_source", ["z"] = 4, ["meta"] = { ["inventory"] = {  }, ["fields"] = {  } }, ["param2"] = 240, ["param1"] = 57 }, { ["y"] = 0, ["x"] = 11, ["name"] = "default:water_source", ["z"] = 5, ["meta"] = { ["inventory"] = {  }, ["fields"] = {  } }, ["param2"] = 240, ["param1"] = 40 }, { ["y"] = 0, ["x"] = 11, ["name"] = "default:water_source", ["z"] = 6, ["meta"] = { ["inventory"] = {  }, ["fields"] = {  } }, ["param2"] = 240, ["param1"] = 24 }, { ["y"] = 0, ["x"] = 11, ["name"] = "default:water_source", ["z"] = 7, ["meta"] = { ["inventory"] = {  }, ["fields"] = {  } }, ["param2"] = 240, ["param1"] = 8 }, { ["y"] = 0, ["x"] = 11, ["name"] = "default:water_source", ["z"] = 8, ["meta"] = { ["inventory"] = {  }, ["fields"] = {  } }, ["param2"] = 240, ["param1"] = 8 }, { ["y"] = 1, ["x"] = 11, ["name"] = "default:water_source", ["z"] = 0, ["meta"] = { ["inventory"] = {  }, ["fields"] = {  } }, ["param2"] = 0, ["param1"] = 107 }, { ["y"] = 1, ["x"] = 11, ["name"] = "default:water_source", ["z"] = 1, ["meta"] = { ["inventory"] = {  }, ["fields"] = {  } }, ["param2"] = 240, ["param1"] = 123 }, { ["y"] = 1, ["x"] = 11, ["name"] = "default:water_source", ["z"] = 2, ["meta"] = { ["inventory"] = {  }, ["fields"] = {  } }, ["param2"] = 0, ["param1"] = 106 }, { ["y"] = 1, ["x"] = 11, ["name"] = "default:water_source", ["z"] = 3, ["meta"] = { ["inventory"] = {  }, ["fields"] = {  } }, ["param2"] = 0, ["param1"] = 90 }, { ["y"] = 1, ["x"] = 11, ["name"] = "default:water_source", ["z"] = 4, ["meta"] = { ["inventory"] = {  }, ["fields"] = {  } }, ["param2"] = 0, ["param1"] = 74 }, { ["y"] = 1, ["x"] = 11, ["name"] = "default:water_source", ["z"] = 5, ["meta"] = { ["inventory"] = {  }, ["fields"] = {  } }, ["param2"] = 0, ["param1"] = 57 }, { ["y"] = 1, ["x"] = 11, ["name"] = "default:water_source", ["z"] = 6, ["meta"] = { ["inventory"] = {  }, ["fields"] = {  } }, ["param2"] = 240, ["param1"] = 41 }, { ["y"] = 1, ["x"] = 11, ["name"] = "default:water_source", ["z"] = 7, ["meta"] = { ["inventory"] = {  }, ["fields"] = {  } }, ["param2"] = 240, ["param1"] = 25 }, { ["y"] = 1, ["x"] = 11, ["name"] = "default:water_source", ["z"] = 8, ["meta"] = { ["inventory"] = {  }, ["fields"] = {  } }, ["param2"] = 240, ["param1"] = 9 }, { ["y"] = 2, ["x"] = 11, ["name"] = "default:water_source", ["z"] = 0, ["meta"] = { ["inventory"] = {  }, ["fields"] = {  } }, ["param2"] = 240, ["param1"] = 124 }, { ["y"] = 2, ["x"] = 11, ["name"] = "default:water_source", ["z"] = 1, ["meta"] = { ["inventory"] = {  }, ["fields"] = {  } }, ["param2"] = 240, ["param1"] = 140 }, { ["y"] = 2, ["x"] = 11, ["name"] = "default:water_source", ["z"] = 2, ["meta"] = { ["inventory"] = {  }, ["fields"] = {  } }, ["param2"] = 240, ["param1"] = 123 }, { ["y"] = 2, ["x"] = 11, ["name"] = "default:water_source", ["z"] = 3, ["meta"] = { ["inventory"] = {  }, ["fields"] = {  } }, ["param2"] = 240, ["param1"] = 107 }, { ["y"] = 2, ["x"] = 11, ["name"] = "default:water_source", ["z"] = 4, ["meta"] = { ["inventory"] = {  }, ["fields"] = {  } }, ["param2"] = 240, ["param1"] = 91 }, { ["y"] = 2, ["x"] = 11, ["name"] = "default:water_source", ["z"] = 5, ["meta"] = { ["inventory"] = {  }, ["fields"] = {  } }, ["param2"] = 0, ["param1"] = 74 }, { ["y"] = 2, ["x"] = 11, ["name"] = "default:water_source", ["z"] = 6, ["meta"] = { ["inventory"] = {  }, ["fields"] = {  } }, ["param2"] = 240, ["param1"] = 58 }, { ["y"] = 2, ["x"] = 11, ["name"] = "default:water_source", ["z"] = 7, ["meta"] = { ["inventory"] = {  }, ["fields"] = {  } }, ["param2"] = 240, ["param1"] = 42 }, { ["y"] = 2, ["x"] = 11, ["name"] = "default:water_source", ["z"] = 8, ["meta"] = { ["inventory"] = {  }, ["fields"] = {  } }, ["param2"] = 240, ["param1"] = 26 }, { ["y"] = 3, ["x"] = 11, ["name"] = "default:water_source", ["z"] = 0, ["meta"] = { ["inventory"] = {  }, ["fields"] = {  } }, ["param2"] = 240, ["param1"] = 141 }, { ["y"] = 3, ["x"] = 11, ["name"] = "default:water_source", ["z"] = 1, ["meta"] = { ["inventory"] = {  }, ["fields"] = {  } }, ["param2"] = 240, ["param1"] = 157 }, { ["y"] = 3, ["x"] = 11, ["name"] = "default:water_source", ["z"] = 2, ["meta"] = { ["inventory"] = {  }, ["fields"] = {  } }, ["param2"] = 240, ["param1"] = 140 }, { ["y"] = 3, ["x"] = 11, ["name"] = "default:water_source", ["z"] = 3, ["meta"] = { ["inventory"] = {  }, ["fields"] = {  } }, ["param2"] = 240, ["param1"] = 124 }, { ["y"] = 3, ["x"] = 11, ["name"] = "default:water_source", ["z"] = 4, ["meta"] = { ["inventory"] = {  }, ["fields"] = {  } }, ["param2"] = 240, ["param1"] = 108 }, { ["y"] = 3, ["x"] = 11, ["name"] = "default:water_source", ["z"] = 5, ["meta"] = { ["inventory"] = {  }, ["fields"] = {  } }, ["param2"] = 240, ["param1"] = 91 }, { ["y"] = 3, ["x"] = 11, ["name"] = "default:water_source", ["z"] = 6, ["meta"] = { ["inventory"] = {  }, ["fields"] = {  } }, ["param2"] = 240, ["param1"] = 75 }, { ["y"] = 3, ["x"] = 11, ["name"] = "default:water_source", ["z"] = 7, ["meta"] = { ["inventory"] = {  }, ["fields"] = {  } }, ["param2"] = 240, ["param1"] = 59 }, { ["y"] = 3, ["x"] = 11, ["name"] = "default:water_source", ["z"] = 8, ["meta"] = { ["inventory"] = {  }, ["fields"] = {  } }, ["param2"] = 240, ["param1"] = 43 }, { ["y"] = 4, ["x"] = 11, ["name"] = "moretrees:palm_planks", ["z"] = 2, ["meta"] = { ["inventory"] = {  }, ["fields"] = {  } }, ["param2"] = 0, ["param1"] = 0 }, { ["y"] = 4, ["x"] = 11, ["name"] = "moretrees:palm_planks", ["z"] = 3, ["meta"] = { ["inventory"] = {  }, ["fields"] = {  } }, ["param2"] = 0, ["param1"] = 0 }, { ["y"] = 4, ["x"] = 11, ["name"] = "moretrees:palm_planks", ["z"] = 4, ["meta"] = { ["inventory"] = {  }, ["fields"] = {  } }, ["param2"] = 0, ["param1"] = 0 }, { ["y"] = 4, ["x"] = 11, ["name"] = "moretrees:palm_planks", ["z"] = 5, ["meta"] = { ["inventory"] = {  }, ["fields"] = {  } }, ["param2"] = 0, ["param1"] = 0 }, { ["y"] = 4, ["x"] = 11, ["name"] = "moretrees:palm_planks", ["z"] = 6, ["meta"] = { ["inventory"] = {  }, ["fields"] = {  } }, ["param2"] = 0, ["param1"] = 0 }, { ["y"] = 4, ["x"] = 11, ["name"] = "moretrees:palm_planks", ["z"] = 7, ["meta"] = { ["inventory"] = {  }, ["fields"] = {  } }, ["param2"] = 0, ["param1"] = 0 }, { ["y"] = 4, ["x"] = 11, ["name"] = "moretrees:palm_planks", ["z"] = 8, ["meta"] = { ["inventory"] = {  }, ["fields"] = {  } }, ["param2"] = 0, ["param1"] = 0 }, { ["y"] = 0, ["x"] = 12, ["name"] = "default:water_source", ["z"] = 0, ["meta"] = { ["inventory"] = {  }, ["fields"] = {  } }, ["param2"] = 240, ["param1"] = 74 }, { ["y"] = 0, ["x"] = 12, ["name"] = "default:water_source", ["z"] = 1, ["meta"] = { ["inventory"] = {  }, ["fields"] = {  } }, ["param2"] = 240, ["param1"] = 90 }, { ["y"] = 0, ["x"] = 12, ["name"] = "default:water_source", ["z"] = 2, ["meta"] = { ["inventory"] = {  }, ["fields"] = {  } }, ["param2"] = 240, ["param1"] = 106 }, { ["y"] = 0, ["x"] = 12, ["name"] = "default:water_source", ["z"] = 3, ["meta"] = { ["inventory"] = {  }, ["fields"] = {  } }, ["param2"] = 0, ["param1"] = 90 }, { ["y"] = 0, ["x"] = 12, ["name"] = "default:water_source", ["z"] = 4, ["meta"] = { ["inventory"] = {  }, ["fields"] = {  } }, ["param2"] = 240, ["param1"] = 74 }, { ["y"] = 0, ["x"] = 12, ["name"] = "default:water_source", ["z"] = 5, ["meta"] = { ["inventory"] = {  }, ["fields"] = {  } }, ["param2"] = 240, ["param1"] = 57 }, { ["y"] = 0, ["x"] = 12, ["name"] = "default:water_source", ["z"] = 6, ["meta"] = { ["inventory"] = {  }, ["fields"] = {  } }, ["param2"] = 240, ["param1"] = 41 }, { ["y"] = 0, ["x"] = 12, ["name"] = "default:water_source", ["z"] = 7, ["meta"] = { ["inventory"] = {  }, ["fields"] = {  } }, ["param2"] = 240, ["param1"] = 25 }, { ["y"] = 0, ["x"] = 12, ["name"] = "default:water_source", ["z"] = 8, ["meta"] = { ["inventory"] = {  }, ["fields"] = {  } }, ["param2"] = 240, ["param1"] = 9 }, { ["y"] = 1, ["x"] = 12, ["name"] = "default:water_source", ["z"] = 0, ["meta"] = { ["inventory"] = {  }, ["fields"] = {  } }, ["param2"] = 0, ["param1"] = 91 }, { ["y"] = 1, ["x"] = 12, ["name"] = "default:water_source", ["z"] = 1, ["meta"] = { ["inventory"] = {  }, ["fields"] = {  } }, ["param2"] = 0, ["param1"] = 107 }, { ["y"] = 1, ["x"] = 12, ["name"] = "default:water_source", ["z"] = 2, ["meta"] = { ["inventory"] = {  }, ["fields"] = {  } }, ["param2"] = 240, ["param1"] = 123 }, { ["y"] = 1, ["x"] = 12, ["name"] = "default:water_source", ["z"] = 3, ["meta"] = { ["inventory"] = {  }, ["fields"] = {  } }, ["param2"] = 0, ["param1"] = 107 }, { ["y"] = 1, ["x"] = 12, ["name"] = "default:water_source", ["z"] = 4, ["meta"] = { ["inventory"] = {  }, ["fields"] = {  } }, ["param2"] = 0, ["param1"] = 91 }, { ["y"] = 1, ["x"] = 12, ["name"] = "default:water_source", ["z"] = 5, ["meta"] = { ["inventory"] = {  }, ["fields"] = {  } }, ["param2"] = 0, ["param1"] = 74 }, { ["y"] = 1, ["x"] = 12, ["name"] = "default:water_source", ["z"] = 6, ["meta"] = { ["inventory"] = {  }, ["fields"] = {  } }, ["param2"] = 0, ["param1"] = 58 }, { ["y"] = 1, ["x"] = 12, ["name"] = "default:water_source", ["z"] = 7, ["meta"] = { ["inventory"] = {  }, ["fields"] = {  } }, ["param2"] = 240, ["param1"] = 42 }, { ["y"] = 1, ["x"] = 12, ["name"] = "default:water_source", ["z"] = 8, ["meta"] = { ["inventory"] = {  }, ["fields"] = {  } }, ["param2"] = 240, ["param1"] = 26 }, { ["y"] = 2, ["x"] = 12, ["name"] = "default:water_source", ["z"] = 0, ["meta"] = { ["inventory"] = {  }, ["fields"] = {  } }, ["param2"] = 240, ["param1"] = 108 }, { ["y"] = 2, ["x"] = 12, ["name"] = "default:water_source", ["z"] = 1, ["meta"] = { ["inventory"] = {  }, ["fields"] = {  } }, ["param2"] = 240, ["param1"] = 124 }, { ["y"] = 2, ["x"] = 12, ["name"] = "default:water_source", ["z"] = 2, ["meta"] = { ["inventory"] = {  }, ["fields"] = {  } }, ["param2"] = 240, ["param1"] = 140 }, { ["y"] = 2, ["x"] = 12, ["name"] = "default:water_source", ["z"] = 3, ["meta"] = { ["inventory"] = {  }, ["fields"] = {  } }, ["param2"] = 240, ["param1"] = 124 }, { ["y"] = 2, ["x"] = 12, ["name"] = "default:water_source", ["z"] = 4, ["meta"] = { ["inventory"] = {  }, ["fields"] = {  } }, ["param2"] = 240, ["param1"] = 108 }, { ["y"] = 2, ["x"] = 12, ["name"] = "default:water_source", ["z"] = 5, ["meta"] = { ["inventory"] = {  }, ["fields"] = {  } }, ["param2"] = 0, ["param1"] = 91 }, { ["y"] = 2, ["x"] = 12, ["name"] = "default:water_source", ["z"] = 6, ["meta"] = { ["inventory"] = {  }, ["fields"] = {  } }, ["param2"] = 0, ["param1"] = 75 }, { ["y"] = 2, ["x"] = 12, ["name"] = "default:water_source", ["z"] = 7, ["meta"] = { ["inventory"] = {  }, ["fields"] = {  } }, ["param2"] = 240, ["param1"] = 59 }, { ["y"] = 2, ["x"] = 12, ["name"] = "default:water_source", ["z"] = 8, ["meta"] = { ["inventory"] = {  }, ["fields"] = {  } }, ["param2"] = 240, ["param1"] = 43 }, { ["y"] = 3, ["x"] = 12, ["name"] = "default:water_source", ["z"] = 0, ["meta"] = { ["inventory"] = {  }, ["fields"] = {  } }, ["param2"] = 240, ["param1"] = 125 }, { ["y"] = 3, ["x"] = 12, ["name"] = "default:water_source", ["z"] = 1, ["meta"] = { ["inventory"] = {  }, ["fields"] = {  } }, ["param2"] = 240, ["param1"] = 141 }, { ["y"] = 3, ["x"] = 12, ["name"] = "default:water_source", ["z"] = 2, ["meta"] = { ["inventory"] = {  }, ["fields"] = {  } }, ["param2"] = 240, ["param1"] = 157 }, { ["y"] = 3, ["x"] = 12, ["name"] = "default:water_source", ["z"] = 3, ["meta"] = { ["inventory"] = {  }, ["fields"] = {  } }, ["param2"] = 240, ["param1"] = 141 }, { ["y"] = 3, ["x"] = 12, ["name"] = "default:water_source", ["z"] = 4, ["meta"] = { ["inventory"] = {  }, ["fields"] = {  } }, ["param2"] = 240, ["param1"] = 125 }, { ["y"] = 3, ["x"] = 12, ["name"] = "default:water_source", ["z"] = 5, ["meta"] = { ["inventory"] = {  }, ["fields"] = {  } }, ["param2"] = 0, ["param1"] = 108 }, { ["y"] = 3, ["x"] = 12, ["name"] = "default:water_source", ["z"] = 6, ["meta"] = { ["inventory"] = {  }, ["fields"] = {  } }, ["param2"] = 0, ["param1"] = 92 }, { ["y"] = 3, ["x"] = 12, ["name"] = "default:water_source", ["z"] = 7, ["meta"] = { ["inventory"] = {  }, ["fields"] = {  } }, ["param2"] = 240, ["param1"] = 76 }, { ["y"] = 3, ["x"] = 12, ["name"] = "default:water_source", ["z"] = 8, ["meta"] = { ["inventory"] = {  }, ["fields"] = {  } }, ["param2"] = 240, ["param1"] = 60 }, { ["y"] = 4, ["x"] = 12, ["name"] = "default:water_flowing", ["z"] = 5, ["meta"] = { ["inventory"] = {  }, ["fields"] = {  } }, ["param2"] = 0, ["param1"] = 125 }, { ["y"] = 4, ["x"] = 12, ["name"] = "default:water_flowing", ["z"] = 6, ["meta"] = { ["inventory"] = {  }, ["fields"] = {  } }, ["param2"] = 1, ["param1"] = 109 }, { ["y"] = 4, ["x"] = 12, ["name"] = "default:water_flowing", ["z"] = 7, ["meta"] = { ["inventory"] = {  }, ["fields"] = {  } }, ["param2"] = 2, ["param1"] = 93 }, { ["y"] = 4, ["x"] = 12, ["name"] = "default:water_flowing", ["z"] = 8, ["meta"] = { ["inventory"] = {  }, ["fields"] = {  } }, ["param2"] = 3, ["param1"] = 77 } }