return { { ["x"] = 0, ["y"] = 0, ["z"] = 0, ["name"] = "nether:netherrack_black" }, { ["x"] = 0, ["y"] = 0, ["z"] = 1, ["name"] = "nether:netherrack_black" }, { ["x"] = 0, ["y"] = 0, ["z"] = 2, ["name"] = "nether:netherrack_black" }, { ["x"] = 0, ["y"] = 0, ["z"] = 3, ["name"] = "nether:netherrack_black" }, { ["x"] = 0, ["y"] = 0, ["z"] = 4, ["name"] = "nether:netherrack_black" }, { ["x"] = 0, ["y"] = 1, ["z"] = 0, ["name"] = "nether:netherrack_brick_blue" }, { ["x"] = 0, ["y"] = 1, ["z"] = 4, ["name"] = "nether:netherrack_brick_blue" }, { ["x"] = 0, ["y"] = 2, ["z"] = 0, ["name"] = "nether:netherrack_brick_blue" }, { ["x"] = 0, ["y"] = 2, ["z"] = 4, ["name"] = "nether:netherrack_brick_blue" }, { ["x"] = 0, ["y"] = 3, ["z"] = 0, ["name"] = "nether:netherrack_brick_blue" }, { ["x"] = 0, ["y"] = 3, ["z"] = 4, ["name"] = "nether:netherrack_brick_blue" }, { ["x"] = 0, ["y"] = 4, ["z"] = 0, ["name"] = "nether:wood_empty" }, { ["x"] = 0, ["y"] = 4, ["z"] = 1, ["name"] = "nether:wood_empty" }, { ["x"] = 0, ["y"] = 4, ["z"] = 2, ["name"] = "nether:wood_empty" }, { ["x"] = 0, ["y"] = 4, ["z"] = 3, ["name"] = "nether:wood_empty" }, { ["x"] = 0, ["y"] = 4, ["z"] = 4, ["name"] = "nether:wood_empty" }, { ["x"] = 1, ["y"] = 0, ["z"] = 0, ["name"] = "nether:netherrack_black" }, { ["x"] = 1, ["y"] = 0, ["z"] = 1, ["name"] = "nether:netherrack" }, { ["x"] = 1, ["y"] = 0, ["z"] = 2, ["name"] = "nether:netherrack" }, { ["x"] = 1, ["y"] = 0, ["z"] = 3, ["name"] = "nether:netherrack" }, { ["x"] = 1, ["y"] = 0, ["z"] = 4, ["name"] = "nether:netherrack_black" }, { ["x"] = 1, ["y"] = 3, ["param1"] = 12, ["z"] = 1, ["name"] = "nether:apple" }, { ["x"] = 1, ["y"] = 3, ["param1"] = 12, ["z"] = 3, ["name"] = "nether:apple" }, { ["x"] = 1, ["y"] = 4, ["z"] = 0, ["name"] = "nether:wood_empty" }, { ["x"] = 1, ["y"] = 4, ["z"] = 1, ["name"] = "nether:blood_cooked" }, { ["x"] = 1, ["y"] = 4, ["z"] = 2, ["name"] = "nether:blood_cooked" }, { ["x"] = 1, ["y"] = 4, ["z"] = 3, ["name"] = "nether:blood_cooked" }, { ["x"] = 1, ["y"] = 4, ["z"] = 4, ["name"] = "nether:wood_empty" }, { ["x"] = 1, ["y"] = 5, ["z"] = 1, ["name"] = "nether:wood_empty" }, { ["x"] = 1, ["y"] = 5, ["z"] = 2, ["name"] = "nether:wood_empty" }, { ["x"] = 1, ["y"] = 5, ["z"] = 3, ["name"] = "nether:wood_empty" }, { ["x"] = 2, ["y"] = 0, ["z"] = 0, ["name"] = "nether:netherrack_black" }, { ["x"] = 2, ["y"] = 0, ["z"] = 1, ["name"] = "nether:netherrack" }, { ["x"] = 2, ["y"] = 0, ["z"] = 2, ["name"] = "nether:white" }, { ["x"] = 2, ["y"] = 0, ["z"] = 3, ["name"] = "nether:netherrack" }, { ["x"] = 2, ["y"] = 0, ["z"] = 4, ["name"] = "nether:netherrack_black" }, { ["x"] = 2, ["y"] = 4, ["z"] = 0, ["name"] = "nether:wood_empty" }, { ["x"] = 2, ["y"] = 4, ["z"] = 1, ["name"] = "nether:blood_cooked" }, { ["x"] = 2, ["y"] = 4, ["z"] = 2, ["name"] = "nether:white" }, { ["x"] = 2, ["y"] = 4, ["z"] = 3, ["name"] = "nether:blood_cooked" }, { ["x"] = 2, ["y"] = 4, ["z"] = 4, ["name"] = "nether:wood_empty" }, { ["x"] = 2, ["y"] = 5, ["z"] = 1, ["name"] = "nether:wood_empty" }, { ["x"] = 2, ["y"] = 5, ["z"] = 2, ["name"] = "nether:wood_empty" }, { ["x"] = 2, ["y"] = 5, ["z"] = 3, ["name"] = "nether:wood_empty" }, { ["x"] = 3, ["y"] = 0, ["z"] = 0, ["name"] = "nether:netherrack_black" }, { ["x"] = 3, ["y"] = 0, ["z"] = 1, ["name"] = "nether:netherrack" }, { ["x"] = 3, ["y"] = 0, ["z"] = 2, ["name"] = "nether:netherrack" }, { ["x"] = 3, ["y"] = 0, ["z"] = 3, ["name"] = "nether:netherrack" }, { ["x"] = 3, ["y"] = 0, ["z"] = 4, ["name"] = "nether:netherrack_black" }, { ["x"] = 3, ["y"] = 3, ["param1"] = 12, ["z"] = 1, ["name"] = "nether:apple" }, { ["x"] = 3, ["y"] = 3, ["param1"] = 12, ["z"] = 3, ["name"] = "nether:apple" }, { ["x"] = 3, ["y"] = 4, ["z"] = 0, ["name"] = "nether:wood_empty" }, { ["x"] = 3, ["y"] = 4, ["z"] = 1, ["name"] = "nether:blood_cooked" }, { ["x"] = 3, ["y"] = 4, ["z"] = 2, ["name"] = "nether:blood_cooked" }, { ["x"] = 3, ["y"] = 4, ["z"] = 3, ["name"] = "nether:blood_cooked" }, { ["x"] = 3, ["y"] = 4, ["z"] = 4, ["name"] = "nether:wood_empty" }, { ["x"] = 3, ["y"] = 5, ["z"] = 1, ["name"] = "nether:wood_empty" }, { ["x"] = 3, ["y"] = 5, ["z"] = 2, ["name"] = "nether:wood_empty" }, { ["x"] = 3, ["y"] = 5, ["z"] = 3, ["name"] = "nether:wood_empty" }, { ["x"] = 4, ["y"] = 0, ["z"] = 0, ["name"] = "nether:netherrack_black" }, { ["x"] = 4, ["y"] = 0, ["z"] = 1, ["name"] = "nether:netherrack_black" }, { ["x"] = 4, ["y"] = 0, ["z"] = 2, ["name"] = "nether:netherrack_black" }, { ["x"] = 4, ["y"] = 0, ["z"] = 3, ["name"] = "nether:netherrack_black" }, { ["x"] = 4, ["y"] = 0, ["z"] = 4, ["name"] = "nether:netherrack_black" }, { ["x"] = 4, ["y"] = 1, ["z"] = 0, ["name"] = "nether:netherrack_brick_blue" }, { ["x"] = 4, ["y"] = 1, ["z"] = 4, ["name"] = "nether:netherrack_brick_blue" }, { ["x"] = 4, ["y"] = 2, ["z"] = 0, ["name"] = "nether:netherrack_brick_blue" }, { ["x"] = 4, ["y"] = 2, ["z"] = 4, ["name"] = "nether:netherrack_brick_blue" }, { ["x"] = 4, ["y"] = 3, ["z"] = 0, ["name"] = "nether:netherrack_brick_blue" }, { ["x"] = 4, ["y"] = 3, ["z"] = 4, ["name"] = "nether:netherrack_brick_blue" }, { ["x"] = 4, ["y"] = 4, ["z"] = 0, ["name"] = "nether:wood_empty" }, { ["x"] = 4, ["y"] = 4, ["z"] = 1, ["name"] = "nether:wood_empty" }, { ["x"] = 4, ["y"] = 4, ["z"] = 2, ["name"] = "nether:wood_empty" }, { ["x"] = 4, ["y"] = 4, ["z"] = 3, ["name"] = "nether:wood_empty" }, { ["x"] = 4, ["y"] = 4, ["z"] = 4, ["name"] = "nether:wood_empty" } }
