5:return {{["y"] = 2, ["x"] = 0, ["name"] = "nether:netherrack", ["z"] = 0, ["meta"] = {["inventory"] = {}, ["fields"] = {}}}, {["y"] = 2, ["x"] = 0, ["name"] = "nether:netherrack", ["z"] = 1, ["meta"] = {["inventory"] = {}, ["fields"] = {}}}, {["y"] = 2, ["x"] = 0, ["name"] = "nether:netherrack", ["z"] = 2, ["meta"] = {["inventory"] = {}, ["fields"] = {}}}, {["y"] = 2, ["x"] = 0, ["name"] = "nether:netherrack", ["z"] = 3, ["meta"] = {["inventory"] = {}, ["fields"] = {}}}, {["y"] = 2, ["x"] = 0, ["name"] = "nether:netherrack", ["z"] = 4, ["meta"] = {["inventory"] = {}, ["fields"] = {}}}, {["y"] = 2, ["x"] = 0, ["name"] = "nether:netherrack", ["z"] = 5, ["meta"] = {["inventory"] = {}, ["fields"] = {}}}, {["y"] = 2, ["x"] = 0, ["name"] = "nether:netherrack", ["z"] = 6, ["meta"] = {["inventory"] = {}, ["fields"] = {}}}, {["y"] = 2, ["x"] = 0, ["name"] = "nether:netherrack", ["z"] = 7, ["meta"] = {["inventory"] = {}, ["fields"] = {}}}, {["y"] = 2, ["x"] = 0, ["name"] = "nether:netherrack", ["z"] = 8, ["meta"] = {["inventory"] = {}, ["fields"] = {}}}, {["y"] = 2, ["x"] = 0, ["name"] = "nether:netherrack", ["z"] = 9, ["meta"] = {["inventory"] = {}, ["fields"] = {}}}, {["y"] = 2, ["x"] = 0, ["name"] = "nether:netherrack", ["z"] = 10, ["meta"] = {["inventory"] = {}, ["fields"] = {}}}, {["y"] = 3, ["x"] = 0, ["name"] = "stairs:stair_nether_blood_top", ["z"] = 4, ["meta"] = {["inventory"] = {}, ["fields"] = {}}, ["param2"] = 1, ["param1"] = 153}, {["y"] = 3, ["x"] = 0, ["name"] = "stairs:stair_nether_blood_top", ["z"] = 5, ["meta"] = {["inventory"] = {}, ["fields"] = {}}, ["param2"] = 1, ["param1"] = 136}, {["y"] = 3, ["x"] = 0, ["name"] = "stairs:stair_nether_blood_top", ["z"] = 6, ["meta"] = {["inventory"] = {}, ["fields"] = {}}, ["param2"] = 1, ["param1"] = 153}, {["y"] = 2, ["x"] = 1, ["name"] = "nether:netherrack", ["z"] = 0, ["meta"] = {["inventory"] = {}, ["fields"] = {}}}, {["y"] = 2, ["x"] = 1, ["name"] = "nether:netherrack", ["z"] = 1, ["meta"] = {["inventory"] = {}, ["fields"] = {}}}, {["y"] = 2, ["x"] = 1, ["name"] = "nether:netherrack", ["z"] = 2, ["meta"] = {["inventory"] = {}, ["fields"] = {}}}, {["y"] = 2, ["x"] = 1, ["name"] = "nether:netherrack", ["z"] = 3, ["meta"] = {["inventory"] = {}, ["fields"] = {}}}, {["y"] = 2, ["x"] = 1, ["name"] = "nether:netherrack", ["z"] = 4, ["meta"] = {["inventory"] = {}, ["fields"] = {}}}, {["y"] = 2, ["x"] = 1, ["name"] = "nether:netherrack", ["z"] = 5, ["meta"] = {["inventory"] = {}, ["fields"] = {}}}, {["y"] = 2, ["x"] = 1, ["name"] = "nether:netherrack", ["z"] = 6, ["meta"] = {["inventory"] = {}, ["fields"] = {}}}, {["y"] = 2, ["x"] = 1, ["name"] = "nether:netherrack", ["z"] = 7, ["meta"] = {["inventory"] = {}, ["fields"] = {}}}, {["y"] = 2, ["x"] = 1, ["name"] = "nether:netherrack", ["z"] = 8, ["meta"] = {["inventory"] = {}, ["fields"] = {}}}, {["y"] = 2, ["x"] = 1, ["name"] = "nether:netherrack", ["z"] = 9, ["meta"] = {["inventory"] = {}, ["fields"] = {}}}, {["y"] = 2, ["x"] = 1, ["name"] = "nether:netherrack", ["z"] = 10, ["meta"] = {["inventory"] = {}, ["fields"] = {}}}, {["y"] = 3, ["x"] = 1, ["name"] = "nether:netherrack", ["z"] = 2, ["meta"] = {["inventory"] = {}, ["fields"] = {}}}, {["y"] = 3, ["x"] = 1, ["name"] = "nether:netherrack", ["z"] = 3, ["meta"] = {["inventory"] = {}, ["fields"] = {}}}, {["y"] = 3, ["x"] = 1, ["name"] = "nether:netherrack", ["z"] = 4, ["meta"] = {["inventory"] = {}, ["fields"] = {}}}, {["y"] = 3, ["x"] = 1, ["name"] = "nether:netherrack", ["z"] = 5, ["meta"] = {["inventory"] = {}, ["fields"] = {}}}, {["y"] = 3, ["x"] = 1, ["name"] = "nether:netherrack", ["z"] = 6, ["meta"] = {["inventory"] = {}, ["fields"] = {}}}, {["y"] = 3, ["x"] = 1, ["name"] = "nether:netherrack", ["z"] = 7, ["meta"] = {["inventory"] = {}, ["fields"] = {}}}, {["y"] = 3, ["x"] = 1, ["name"] = "nether:netherrack", ["z"] = 8, ["meta"] = {["inventory"] = {}, ["fields"] = {}}}, {["y"] = 4, ["x"] = 1, ["name"] = "stairs:stair_nether_blood_top", ["z"] = 4, ["meta"] = {["inventory"] = {}, ["fields"] = {}}, ["param2"] = 1, ["param1"] = 187}, {["y"] = 4, ["x"] = 1, ["name"] = "stairs:stair_nether_blood_top", ["z"] = 5, ["meta"] = {["inventory"] = {}, ["fields"] = {}}, ["param2"] = 1, ["param1"] = 170}, {["y"] = 4, ["x"] = 1, ["name"] = "stairs:stair_nether_blood_top", ["z"] = 6, ["meta"] = {["inventory"] = {}, ["fields"] = {}}, ["param2"] = 1, ["param1"] = 187}, {["y"] = 2, ["x"] = 2, ["name"] = "nether:netherrack", ["z"] = 0, ["meta"] = {["inventory"] = {}, ["fields"] = {}}}, {["y"] = 2, ["x"] = 2, ["name"] = "nether:netherrack", ["z"] = 1, ["meta"] = {["inventory"] = {}, ["fields"] = {}}}, {["y"] = 2, ["x"] = 2, ["name"] = "nether:netherrack", ["z"] = 2, ["meta"] = {["inventory"] = {}, ["fields"] = {}}}, {["y"] = 2, ["x"] = 2, ["name"] = "nether:netherrack", ["z"] = 3, ["meta"] = {["inventory"] = {}, ["fields"] = {}}}, {["y"] = 2, ["x"] = 2, ["name"] = "nether:netherrack", ["z"] = 4, ["meta"] = {["inventory"] = {}, ["fields"] = {}}}, {["y"] = 2, ["x"] = 2, ["name"] = "nether:netherrack", ["z"] = 5, ["meta"] = {["inventory"] = {}, ["fields"] = {}}}, {["y"] = 2, ["x"] = 2, ["name"] = "nether:netherrack", ["z"] = 6, ["meta"] = {["inventory"] = {}, ["fields"] = {}}}, {["y"] = 2, ["x"] = 2, ["name"] = "nether:netherrack", ["z"] = 7, ["meta"] = {["inventory"] = {}, ["fields"] = {}}}, {["y"] = 2, ["x"] = 2, ["name"] = "nether:netherrack", ["z"] = 8, ["meta"] = {["inventory"] = {}, ["fields"] = {}}}, {["y"] = 2, ["x"] = 2, ["name"] = "nether:netherrack", ["z"] = 9, ["meta"] = {["inventory"] = {}, ["fields"] = {}}}, {["y"] = 2, ["x"] = 2, ["name"] = "nether:netherrack", ["z"] = 10, ["meta"] = {["inventory"] = {}, ["fields"] = {}}}, {["y"] = 3, ["x"] = 2, ["name"] = "nether:netherrack", ["z"] = 1, ["meta"] = {["inventory"] = {}, ["fields"] = {}}}, {["y"] = 3, ["x"] = 2, ["name"] = "nether:netherrack", ["z"] = 2, ["meta"] = {["inventory"] = {}, ["fields"] = {}}}, {["y"] = 3, ["x"] = 2, ["name"] = "nether:netherrack", ["z"] = 3, ["meta"] = {["inventory"] = {}, ["fields"] = {}}}, {["y"] = 3, ["x"] = 2, ["name"] = "nether:netherrack", ["z"] = 4, ["meta"] = {["inventory"] = {}, ["fields"] = {}}}, {["y"] = 3, ["x"] = 2, ["name"] = "nether:netherrack", ["z"] = 5, ["meta"] = {["inventory"] = {}, ["fields"] = {}}}, {["y"] = 3, ["x"] = 2, ["name"] = "nether:netherrack", ["z"] = 6, ["meta"] = {["inventory"] = {}, ["fields"] = {}}}, {["y"] = 3, ["x"] = 2, ["name"] = "nether:netherrack", ["z"] = 7, ["meta"] = {["inventory"] = {}, ["fields"] = {}}}, {["y"] = 3, ["x"] = 2, ["name"] = "nether:netherrack", ["z"] = 8, ["meta"] = {["inventory"] = {}, ["fields"] = {}}}, {["y"] = 3, ["x"] = 2, ["name"] = "nether:netherrack", ["z"] = 9, ["meta"] = {["inventory"] = {}, ["fields"] = {}}}, {["y"] = 4, ["x"] = 2, ["name"] = "glow:stone", ["z"] = 2, ["meta"] = {["inventory"] = {}, ["fields"] = {}}}, {["y"] = 4, ["x"] = 2, ["name"] = "nether:netherrack", ["z"] = 3, ["meta"] = {["inventory"] = {}, ["fields"] = {}}}, {["y"] = 4, ["x"] = 2, ["name"] = "nether:netherrack", ["z"] = 4, ["meta"] = {["inventory"] = {}, ["fields"] = {}}}, {["y"] = 4, ["x"] = 2, ["name"] = "nether:netherrack", ["z"] = 5, ["meta"] = {["inventory"] = {}, ["fields"] = {}}}, {["y"] = 4, ["x"] = 2, ["name"] = "nether:netherrack", ["z"] = 6, ["meta"] = {["inventory"] = {}, ["fields"] = {}}}, {["y"] = 4, ["x"] = 2, ["name"] = "nether:netherrack", ["z"] = 7, ["meta"] = {["inventory"] = {}, ["fields"] = {}}}, {["y"] = 4, ["x"] = 2, ["name"] = "glow:stone", ["z"] = 8, ["meta"] = {["inventory"] = {}, ["fields"] = {}}}, {["y"] = 5, ["x"] = 2, ["name"] = "stairs:stair_nether_blood_top", ["z"] = 4, ["meta"] = {["inventory"] = {}, ["fields"] = {}}, ["param2"] = 1, ["param1"] = 187}, {["y"] = 5, ["x"] = 2, ["name"] = "stairs:stair_nether_blood_top", ["z"] = 5, ["meta"] = {["inventory"] = {}, ["fields"] = {}}, ["param2"] = 1, ["param1"] = 170}, {["y"] = 5, ["x"] = 2, ["name"] = "stairs:stair_nether_blood_top", ["z"] = 6, ["meta"] = {["inventory"] = {}, ["fields"] = {}}, ["param2"] = 1, ["param1"] = 187}, {["y"] = 2, ["x"] = 3, ["name"] = "nether:netherrack", ["z"] = 0, ["meta"] = {["inventory"] = {}, ["fields"] = {}}}, {["y"] = 2, ["x"] = 3, ["name"] = "nether:netherrack", ["z"] = 1, ["meta"] = {["inventory"] = {}, ["fields"] = {}}}, {["y"] = 2, ["x"] = 3, ["name"] = "nether:netherrack", ["z"] = 2, ["meta"] = {["inventory"] = {}, ["fields"] = {}}}, {["y"] = 2, ["x"] = 3, ["name"] = "nether:netherrack", ["z"] = 3, ["meta"] = {["inventory"] = {}, ["fields"] = {}}}, {["y"] = 2, ["x"] = 3, ["name"] = "nether:netherrack", ["z"] = 4, ["meta"] = {["inventory"] = {}, ["fields"] = {}}}, {["y"] = 2, ["x"] = 3, ["name"] = "nether:netherrack", ["z"] = 5, ["meta"] = {["inventory"] = {}, ["fields"] = {}}}, {["y"] = 2, ["x"] = 3, ["name"] = "nether:netherrack", ["z"] = 6, ["meta"] = {["inventory"] = {}, ["fields"] = {}}}, {["y"] = 2, ["x"] = 3, ["name"] = "nether:netherrack", ["z"] = 7, ["meta"] = {["inventory"] = {}, ["fields"] = {}}}, {["y"] = 2, ["x"] = 3, ["name"] = "nether:netherrack", ["z"] = 8, ["meta"] = {["inventory"] = {}, ["fields"] = {}}}, {["y"] = 2, ["x"] = 3, ["name"] = "nether:netherrack", ["z"] = 9, ["meta"] = {["inventory"] = {}, ["fields"] = {}}}, {["y"] = 2, ["x"] = 3, ["name"] = "nether:netherrack", ["z"] = 10, ["meta"] = {["inventory"] = {}, ["fields"] = {}}}, {["y"] = 3, ["x"] = 3, ["name"] = "nether:netherrack", ["z"] = 1, ["meta"] = {["inventory"] = {}, ["fields"] = {}}}, {["y"] = 3, ["x"] = 3, ["name"] = "nether:netherrack", ["z"] = 2, ["meta"] = {["inventory"] = {}, ["fields"] = {}}}, {["y"] = 3, ["x"] = 3, ["name"] = "nether:netherrack", ["z"] = 3, ["meta"] = {["inventory"] = {}, ["fields"] = {}}}, {["y"] = 3, ["x"] = 3, ["name"] = "nether:netherrack", ["z"] = 4, ["meta"] = {["inventory"] = {}, ["fields"] = {}}}, {["y"] = 3, ["x"] = 3, ["name"] = "nether:netherrack", ["z"] = 5, ["meta"] = {["inventory"] = {}, ["fields"] = {}}}, {["y"] = 3, ["x"] = 3, ["name"] = "nether:netherrack", ["z"] = 6, ["meta"] = {["inventory"] = {}, ["fields"] = {}}}, {["y"] = 3, ["x"] = 3, ["name"] = "nether:netherrack", ["z"] = 7, ["meta"] = {["inventory"] = {}, ["fields"] = {}}}, {["y"] = 3, ["x"] = 3, ["name"] = "nether:netherrack", ["z"] = 8, ["meta"] = {["inventory"] = {}, ["fields"] = {}}}, {["y"] = 3, ["x"] = 3, ["name"] = "nether:netherrack", ["z"] = 9, ["meta"] = {["inventory"] = {}, ["fields"] = {}}}, {["y"] = 3, ["x"] = 3, ["name"] = "default:chest", ["z"] = 10, ["meta"] = {["inventory"] = {["main"] = {"nether:apple 3", "", "nether:fruit_no_leaf", "nether:netherrack_black 42", "mobs:meat_raw 5", "", "", "", "nether:apple 2", "nether:apple", "default:torch 3", "", "nether:netherrack 47", "", "nether:netherrack_tiled 5", "", "nether:apple 2", "nether:apple", "", "", "nether:netherrack 94", "", "", "", "nether:apple 2", "", "", "", "", "", "", ""}}, ["fields"] = {["formspec"] = "size[8,9]listcolors[#606060AA;#808080;#101010;#202020;#FFF]list[current_name;main;0,0.3;8,4;]list[current_player;main;0,4.85;8,4;]image[0,4.85;1,1;gui_hb_bg.png]image[1,4.85;1,1;gui_hb_bg.png]image[2,4.85;1,1;gui_hb_bg.png]image[3,4.85;1,1;gui_hb_bg.png]image[4,4.85;1,1;gui_hb_bg.png]image[5,4.85;1,1;gui_hb_bg.png]image[6,4.85;1,1;gui_hb_bg.png]image[7,4.85;1,1;gui_hb_bg.png]image[0,5.85;1,1;gui_hb_bg.png]image[1,5.85;1,1;gui_hb_bg.png]image[2,5.85;1,1;gui_hb_bg.png]image[3,5.85;1,1;gui_hb_bg.png]image[4,5.85;1,1;gui_hb_bg.png]image[5,5.85;1,1;gui_hb_bg.png]image[6,5.85;1,1;gui_hb_bg.png]image[7,5.85;1,1;gui_hb_bg.png]", ["infotext"] = "Chest"}}, ["param2"] = 2}, {["y"] = 4, ["x"] = 3, ["name"] = "nether:netherrack", ["z"] = 2, ["meta"] = {["inventory"] = {}, ["fields"] = {}}}, {["y"] = 4, ["x"] = 3, ["name"] = "nether:netherrack", ["z"] = 3, ["meta"] = {["inventory"] = {}, ["fields"] = {}}}, {["y"] = 4, ["x"] = 3, ["name"] = "nether:netherrack", ["z"] = 4, ["meta"] = {["inventory"] = {}, ["fields"] = {}}}, {["y"] = 4, ["x"] = 3, ["name"] = "nether:netherrack", ["z"] = 5, ["meta"] = {["inventory"] = {}, ["fields"] = {}}}, {["y"] = 4, ["x"] = 3, ["name"] = "nether:netherrack", ["z"] = 6, ["meta"] = {["inventory"] = {}, ["fields"] = {}}}, {["y"] = 4, ["x"] = 3, ["name"] = "nether:netherrack", ["z"] = 7, ["meta"] = {["inventory"] = {}, ["fields"] = {}}}, {["y"] = 4, ["x"] = 3, ["name"] = "nether:netherrack", ["z"] = 8, ["meta"] = {["inventory"] = {}, ["fields"] = {}}}, {["y"] = 5, ["x"] = 3, ["name"] = "nether:netherrack_black", ["z"] = 3, ["meta"] = {["inventory"] = {}, ["fields"] = {}}}, {["y"] = 5, ["x"] = 3, ["name"] = "nether:netherrack_black", ["z"] = 4, ["meta"] = {["inventory"] = {}, ["fields"] = {}}}, {["y"] = 5, ["x"] = 3, ["name"] = "nether:netherrack_black", ["z"] = 5, ["meta"] = {["inventory"] = {}, ["fields"] = {}}}, {["y"] = 5, ["x"] = 3, ["name"] = "nether:netherrack_black", ["z"] = 6, ["meta"] = {["inventory"] = {}, ["fields"] = {}}}, {["y"] = 5, ["x"] = 3, ["name"] = "nether:netherrack_black", ["z"] = 7, ["meta"] = {["inventory"] = {}, ["fields"] = {}}}, {["y"] = 6, ["x"] = 3, ["name"] = "nether:netherrack_brick_blue", ["z"] = 3, ["meta"] = {["inventory"] = {}, ["fields"] = {}}}, {["y"] = 6, ["x"] = 3, ["name"] = "nether:netherrack_brick_blue", ["z"] = 7, ["meta"] = {["inventory"] = {}, ["fields"] = {}}}, {["y"] = 7, ["x"] = 3, ["name"] = "nether:netherrack_brick_blue", ["z"] = 3, ["meta"] = {["inventory"] = {}, ["fields"] = {}}}, {["y"] = 7, ["x"] = 3, ["name"] = "nether:netherrack_brick_blue", ["z"] = 7, ["meta"] = {["inventory"] = {}, ["fields"] = {}}}, {["y"] = 8, ["x"] = 3, ["name"] = "nether:netherrack_brick_blue", ["z"] = 3, ["meta"] = {["inventory"] = {}, ["fields"] = {}}}, {["y"] = 8, ["x"] = 3, ["name"] = "nether:netherrack_brick_blue", ["z"] = 7, ["meta"] = {["inventory"] = {}, ["fields"] = {}}}, {["y"] = 9, ["x"] = 3, ["name"] = "nether:wood_empty", ["z"] = 3, ["meta"] = {["inventory"] = {}, ["fields"] = {}}}, {["y"] = 9, ["x"] = 3, ["name"] = "nether:wood_empty", ["z"] = 4, ["meta"] = {["inventory"] = {}, ["fields"] = {}}}, {["y"] = 9, ["x"] = 3, ["name"] = "nether:wood_empty", ["z"] = 5, ["meta"] = {["inventory"] = {}, ["fields"] = {}}}, {["y"] = 9, ["x"] = 3, ["name"] = "nether:wood_empty", ["z"] = 6, ["meta"] = {["inventory"] = {}, ["fields"] = {}}}, {["y"] = 9, ["x"] = 3, ["name"] = "nether:wood_empty", ["z"] = 7, ["meta"] = {["inventory"] = {}, ["fields"] = {}}}, {["y"] = 2, ["x"] = 4, ["name"] = "nether:netherrack", ["z"] = 0, ["meta"] = {["inventory"] = {}, ["fields"] = {}}}, {["y"] = 2, ["x"] = 4, ["name"] = "nether:netherrack", ["z"] = 1, ["meta"] = {["inventory"] = {}, ["fields"] = {}}}, {["y"] = 2, ["x"] = 4, ["name"] = "nether:netherrack", ["z"] = 2, ["meta"] = {["inventory"] = {}, ["fields"] = {}}}, {["y"] = 2, ["x"] = 4, ["name"] = "nether:netherrack", ["z"] = 3, ["meta"] = {["inventory"] = {}, ["fields"] = {}}}, {["y"] = 2, ["x"] = 4, ["name"] = "nether:netherrack", ["z"] = 4, ["meta"] = {["inventory"] = {}, ["fields"] = {}}}, {["y"] = 2, ["x"] = 4, ["name"] = "nether:netherrack", ["z"] = 5, ["meta"] = {["inventory"] = {}, ["fields"] = {}}}, {["y"] = 2, ["x"] = 4, ["name"] = "nether:netherrack", ["z"] = 6, ["meta"] = {["inventory"] = {}, ["fields"] = {}}}, {["y"] = 2, ["x"] = 4, ["name"] = "nether:netherrack", ["z"] = 7, ["meta"] = {["inventory"] = {}, ["fields"] = {}}}, {["y"] = 2, ["x"] = 4, ["name"] = "nether:netherrack", ["z"] = 8, ["meta"] = {["inventory"] = {}, ["fields"] = {}}}, {["y"] = 2, ["x"] = 4, ["name"] = "nether:netherrack", ["z"] = 9, ["meta"] = {["inventory"] = {}, ["fields"] = {}}}, {["y"] = 2, ["x"] = 4, ["name"] = "nether:netherrack", ["z"] = 10, ["meta"] = {["inventory"] = {}, ["fields"] = {}}}, {["y"] = 3, ["x"] = 4, ["name"] = "stairs:stair_nether_blood_top", ["z"] = 0, ["meta"] = {["inventory"] = {}, ["fields"] = {}}, ["param1"] = 153}, {["y"] = 3, ["x"] = 4, ["name"] = "nether:netherrack", ["z"] = 1, ["meta"] = {["inventory"] = {}, ["fields"] = {}}}, {["y"] = 3, ["x"] = 4, ["name"] = "nether:netherrack", ["z"] = 2, ["meta"] = {["inventory"] = {}, ["fields"] = {}}}, {["y"] = 3, ["x"] = 4, ["name"] = "nether:netherrack", ["z"] = 3, ["meta"] = {["inventory"] = {}, ["fields"] = {}}}, {["y"] = 3, ["x"] = 4, ["name"] = "nether:netherrack", ["z"] = 4, ["meta"] = {["inventory"] = {}, ["fields"] = {}}}, {["y"] = 3, ["x"] = 4, ["name"] = "nether:netherrack", ["z"] = 5, ["meta"] = {["inventory"] = {}, ["fields"] = {}}}, {["y"] = 3, ["x"] = 4, ["name"] = "nether:netherrack", ["z"] = 6, ["meta"] = {["inventory"] = {}, ["fields"] = {}}}, {["y"] = 3, ["x"] = 4, ["name"] = "nether:netherrack", ["z"] = 7, ["meta"] = {["inventory"] = {}, ["fields"] = {}}}, {["y"] = 3, ["x"] = 4, ["name"] = "nether:netherrack", ["z"] = 8, ["meta"] = {["inventory"] = {}, ["fields"] = {}}}, {["y"] = 3, ["x"] = 4, ["name"] = "nether:netherrack", ["z"] = 9, ["meta"] = {["inventory"] = {}, ["fields"] = {}}}, {["y"] = 3, ["x"] = 4, ["name"] = "stairs:stair_nether_blood_top", ["z"] = 10, ["meta"] = {["inventory"] = {}, ["fields"] = {}}, ["param2"] = 2, ["param1"] = 153}, {["y"] = 4, ["x"] = 4, ["name"] = "stairs:stair_nether_blood_top", ["z"] = 1, ["meta"] = {["inventory"] = {}, ["fields"] = {}}, ["param1"] = 187}, {["y"] = 4, ["x"] = 4, ["name"] = "nether:netherrack", ["z"] = 2, ["meta"] = {["inventory"] = {}, ["fields"] = {}}}, {["y"] = 4, ["x"] = 4, ["name"] = "nether:netherrack", ["z"] = 3, ["meta"] = {["inventory"] = {}, ["fields"] = {}}}, {["y"] = 4, ["x"] = 4, ["name"] = "nether:netherrack", ["z"] = 4, ["meta"] = {["inventory"] = {}, ["fields"] = {}}}, {["y"] = 4, ["x"] = 4, ["name"] = "nether:netherrack", ["z"] = 5, ["meta"] = {["inventory"] = {}, ["fields"] = {}}}, {["y"] = 4, ["x"] = 4, ["name"] = "nether:netherrack", ["z"] = 6, ["meta"] = {["inventory"] = {}, ["fields"] = {}}}, {["y"] = 4, ["x"] = 4, ["name"] = "nether:netherrack", ["z"] = 7, ["meta"] = {["inventory"] = {}, ["fields"] = {}}}, {["y"] = 4, ["x"] = 4, ["name"] = "nether:netherrack", ["z"] = 8, ["meta"] = {["inventory"] = {}, ["fields"] = {}}}, {["y"] = 4, ["x"] = 4, ["name"] = "stairs:stair_nether_blood_top", ["z"] = 9, ["meta"] = {["inventory"] = {}, ["fields"] = {}}, ["param2"] = 2, ["param1"] = 187}, {["y"] = 5, ["x"] = 4, ["name"] = "stairs:stair_nether_blood_top", ["z"] = 2, ["meta"] = {["inventory"] = {}, ["fields"] = {}}, ["param1"] = 187}, {["y"] = 5, ["x"] = 4, ["name"] = "nether:netherrack_black", ["z"] = 3, ["meta"] = {["inventory"] = {}, ["fields"] = {}}}, {["y"] = 5, ["x"] = 4, ["name"] = "nether:netherrack", ["z"] = 4, ["meta"] = {["inventory"] = {}, ["fields"] = {}}}, {["y"] = 5, ["x"] = 4, ["name"] = "nether:netherrack", ["z"] = 5, ["meta"] = {["inventory"] = {}, ["fields"] = {}}}, {["y"] = 5, ["x"] = 4, ["name"] = "nether:netherrack", ["z"] = 6, ["meta"] = {["inventory"] = {}, ["fields"] = {}}}, {["y"] = 5, ["x"] = 4, ["name"] = "nether:netherrack_black", ["z"] = 7, ["meta"] = {["inventory"] = {}, ["fields"] = {}}}, {["y"] = 5, ["x"] = 4, ["name"] = "stairs:stair_nether_blood_top", ["z"] = 8, ["meta"] = {["inventory"] = {}, ["fields"] = {}}, ["param2"] = 2, ["param1"] = 187}, {["y"] = 8, ["x"] = 4, ["name"] = "nether:apple", ["z"] = 4, ["meta"] = {["inventory"] = {}, ["fields"] = {}}, ["param1"] = 102}, {["y"] = 8, ["x"] = 4, ["name"] = "nether:apple", ["z"] = 6, ["meta"] = {["inventory"] = {}, ["fields"] = {}}, ["param1"] = 102}, {["y"] = 9, ["x"] = 4, ["name"] = "nether:wood_empty", ["z"] = 3, ["meta"] = {["inventory"] = {}, ["fields"] = {}}}, {["y"] = 9, ["x"] = 4, ["name"] = "nether:blood_cooked", ["z"] = 4, ["meta"] = {["inventory"] = {}, ["fields"] = {}}}, {["y"] = 9, ["x"] = 4, ["name"] = "nether:blood_cooked", ["z"] = 5, ["meta"] = {["inventory"] = {}, ["fields"] = {}}}, {["y"] = 9, ["x"] = 4, ["name"] = "nether:blood_cooked", ["z"] = 6, ["meta"] = {["inventory"] = {}, ["fields"] = {}}}, {["y"] = 9, ["x"] = 4, ["name"] = "nether:wood_empty", ["z"] = 7, ["meta"] = {["inventory"] = {}, ["fields"] = {}}}, {["y"] = 10, ["x"] = 4, ["name"] = "nether:wood_empty", ["z"] = 4, ["meta"] = {["inventory"] = {}, ["fields"] = {}}}, {["y"] = 10, ["x"] = 4, ["name"] = "nether:wood_empty", ["z"] = 5, ["meta"] = {["inventory"] = {}, ["fields"] = {}}}, {["y"] = 10, ["x"] = 4, ["name"] = "nether:wood_empty", ["z"] = 6, ["meta"] = {["inventory"] = {}, ["fields"] = {}}}, {["y"] = 2, ["x"] = 5, ["name"] = "nether:netherrack", ["z"] = 0, ["meta"] = {["inventory"] = {}, ["fields"] = {}}}, {["y"] = 2, ["x"] = 5, ["name"] = "nether:netherrack", ["z"] = 1, ["meta"] = {["inventory"] = {}, ["fields"] = {}}}, {["y"] = 2, ["x"] = 5, ["name"] = "nether:netherrack", ["z"] = 2, ["meta"] = {["inventory"] = {}, ["fields"] = {}}}, {["y"] = 2, ["x"] = 5, ["name"] = "nether:netherrack", ["z"] = 3, ["meta"] = {["inventory"] = {}, ["fields"] = {}}}, {["y"] = 2, ["x"] = 5, ["name"] = "nether:netherrack", ["z"] = 4, ["meta"] = {["inventory"] = {}, ["fields"] = {}}}, {["y"] = 2, ["x"] = 5, ["name"] = "nether:netherrack", ["z"] = 5, ["meta"] = {["inventory"] = {}, ["fields"] = {}}}, {["y"] = 2, ["x"] = 5, ["name"] = "nether:netherrack", ["z"] = 6, ["meta"] = {["inventory"] = {}, ["fields"] = {}}}, {["y"] = 2, ["x"] = 5, ["name"] = "nether:netherrack", ["z"] = 7, ["meta"] = {["inventory"] = {}, ["fields"] = {}}}, {["y"] = 2, ["x"] = 5, ["name"] = "nether:netherrack", ["z"] = 8, ["meta"] = {["inventory"] = {}, ["fields"] = {}}}, {["y"] = 2, ["x"] = 5, ["name"] = "nether:netherrack", ["z"] = 9, ["meta"] = {["inventory"] = {}, ["fields"] = {}}}, {["y"] = 2, ["x"] = 5, ["name"] = "nether:netherrack", ["z"] = 10, ["meta"] = {["inventory"] = {}, ["fields"] = {}}}, {["y"] = 3, ["x"] = 5, ["name"] = "stairs:stair_nether_blood_top", ["z"] = 0, ["meta"] = {["inventory"] = {}, ["fields"] = {}}, ["param1"] = 136}, {["y"] = 3, ["x"] = 5, ["name"] = "nether:netherrack", ["z"] = 1, ["meta"] = {["inventory"] = {}, ["fields"] = {}}}, {["y"] = 3, ["x"] = 5, ["name"] = "nether:netherrack", ["z"] = 2, ["meta"] = {["inventory"] = {}, ["fields"] = {}}}, {["y"] = 3, ["x"] = 5, ["name"] = "nether:netherrack", ["z"] = 3, ["meta"] = {["inventory"] = {}, ["fields"] = {}}}, {["y"] = 3, ["x"] = 5, ["name"] = "nether:netherrack", ["z"] = 4, ["meta"] = {["inventory"] = {}, ["fields"] = {}}}, {["y"] = 3, ["x"] = 5, ["name"] = "nether:netherrack", ["z"] = 5, ["meta"] = {["inventory"] = {}, ["fields"] = {}}}, {["y"] = 3, ["x"] = 5, ["name"] = "nether:netherrack", ["z"] = 6, ["meta"] = {["inventory"] = {}, ["fields"] = {}}}, {["y"] = 3, ["x"] = 5, ["name"] = "nether:netherrack", ["z"] = 7, ["meta"] = {["inventory"] = {}, ["fields"] = {}}}, {["y"] = 3, ["x"] = 5, ["name"] = "nether:netherrack", ["z"] = 8, ["meta"] = {["inventory"] = {}, ["fields"] = {}}}, {["y"] = 3, ["x"] = 5, ["name"] = "nether:netherrack", ["z"] = 9, ["meta"] = {["inventory"] = {}, ["fields"] = {}}}, {["y"] = 3, ["x"] = 5, ["name"] = "stairs:stair_nether_blood_top", ["z"] = 10, ["meta"] = {["inventory"] = {}, ["fields"] = {}}, ["param2"] = 2, ["param1"] = 136}, {["y"] = 4, ["x"] = 5, ["name"] = "stairs:stair_nether_blood_top", ["z"] = 1, ["meta"] = {["inventory"] = {}, ["fields"] = {}}, ["param1"] = 170}, {["y"] = 4, ["x"] = 5, ["name"] = "nether:netherrack", ["z"] = 2, ["meta"] = {["inventory"] = {}, ["fields"] = {}}}, {["y"] = 4, ["x"] = 5, ["name"] = "nether:netherrack", ["z"] = 3, ["meta"] = {["inventory"] = {}, ["fields"] = {}}}, {["y"] = 4, ["x"] = 5, ["name"] = "nether:netherrack", ["z"] = 4, ["meta"] = {["inventory"] = {}, ["fields"] = {}}}, {["y"] = 4, ["x"] = 5, ["name"] = "nether:netherrack", ["z"] = 5, ["meta"] = {["inventory"] = {}, ["fields"] = {}}}, {["y"] = 4, ["x"] = 5, ["name"] = "nether:netherrack", ["z"] = 6, ["meta"] = {["inventory"] = {}, ["fields"] = {}}}, {["y"] = 4, ["x"] = 5, ["name"] = "nether:netherrack", ["z"] = 7, ["meta"] = {["inventory"] = {}, ["fields"] = {}}}, {["y"] = 4, ["x"] = 5, ["name"] = "nether:netherrack", ["z"] = 8, ["meta"] = {["inventory"] = {}, ["fields"] = {}}}, {["y"] = 4, ["x"] = 5, ["name"] = "stairs:stair_nether_blood_top", ["z"] = 9, ["meta"] = {["inventory"] = {}, ["fields"] = {}}, ["param2"] = 2, ["param1"] = 170}, {["y"] = 5, ["x"] = 5, ["name"] = "stairs:stair_nether_blood_top", ["z"] = 2, ["meta"] = {["inventory"] = {}, ["fields"] = {}}, ["param1"] = 170}, {["y"] = 5, ["x"] = 5, ["name"] = "nether:netherrack_black", ["z"] = 3, ["meta"] = {["inventory"] = {}, ["fields"] = {}}}, {["y"] = 5, ["x"] = 5, ["name"] = "nether:netherrack", ["z"] = 4, ["meta"] = {["inventory"] = {}, ["fields"] = {}}}, {["y"] = 5, ["x"] = 5, ["name"] = "nether:white", ["z"] = 5, ["meta"] = {["inventory"] = {}, ["fields"] = {}}}, {["y"] = 5, ["x"] = 5, ["name"] = "nether:netherrack", ["z"] = 6, ["meta"] = {["inventory"] = {}, ["fields"] = {}}}, {["y"] = 5, ["x"] = 5, ["name"] = "nether:netherrack_black", ["z"] = 7, ["meta"] = {["inventory"] = {}, ["fields"] = {}}}, {["y"] = 5, ["x"] = 5, ["name"] = "stairs:stair_nether_blood_top", ["z"] = 8, ["meta"] = {["inventory"] = {}, ["fields"] = {}}, ["param2"] = 2, ["param1"] = 170}, {["y"] = 9, ["x"] = 5, ["name"] = "nether:wood_empty", ["z"] = 3, ["meta"] = {["inventory"] = {}, ["fields"] = {}}}, {["y"] = 9, ["x"] = 5, ["name"] = "nether:blood_cooked", ["z"] = 4, ["meta"] = {["inventory"] = {}, ["fields"] = {}}}, {["y"] = 9, ["x"] = 5, ["name"] = "nether:white", ["z"] = 5, ["meta"] = {["inventory"] = {}, ["fields"] = {}}}, {["y"] = 9, ["x"] = 5, ["name"] = "nether:blood_cooked", ["z"] = 6, ["meta"] = {["inventory"] = {}, ["fields"] = {}}}, {["y"] = 9, ["x"] = 5, ["name"] = "nether:wood_empty", ["z"] = 7, ["meta"] = {["inventory"] = {}, ["fields"] = {}}}, {["y"] = 10, ["x"] = 5, ["name"] = "nether:wood_empty", ["z"] = 4, ["meta"] = {["inventory"] = {}, ["fields"] = {}}}, {["y"] = 10, ["x"] = 5, ["name"] = "nether:wood_empty", ["z"] = 5, ["meta"] = {["inventory"] = {}, ["fields"] = {}}}, {["y"] = 10, ["x"] = 5, ["name"] = "nether:wood_empty", ["z"] = 6, ["meta"] = {["inventory"] = {}, ["fields"] = {}}}, {["y"] = 2, ["x"] = 6, ["name"] = "nether:netherrack", ["z"] = 0, ["meta"] = {["inventory"] = {}, ["fields"] = {}}}, {["y"] = 2, ["x"] = 6, ["name"] = "nether:netherrack", ["z"] = 1, ["meta"] = {["inventory"] = {}, ["fields"] = {}}}, {["y"] = 2, ["x"] = 6, ["name"] = "nether:netherrack", ["z"] = 2, ["meta"] = {["inventory"] = {}, ["fields"] = {}}}, {["y"] = 2, ["x"] = 6, ["name"] = "nether:netherrack", ["z"] = 3, ["meta"] = {["inventory"] = {}, ["fields"] = {}}}, {["y"] = 2, ["x"] = 6, ["name"] = "nether:netherrack", ["z"] = 4, ["meta"] = {["inventory"] = {}, ["fields"] = {}}}, {["y"] = 2, ["x"] = 6, ["name"] = "nether:netherrack", ["z"] = 5, ["meta"] = {["inventory"] = {}, ["fields"] = {}}}, {["y"] = 2, ["x"] = 6, ["name"] = "nether:netherrack", ["z"] = 6, ["meta"] = {["inventory"] = {}, ["fields"] = {}}}, {["y"] = 2, ["x"] = 6, ["name"] = "nether:netherrack", ["z"] = 7, ["meta"] = {["inventory"] = {}, ["fields"] = {}}}, {["y"] = 2, ["x"] = 6, ["name"] = "nether:netherrack", ["z"] = 8, ["meta"] = {["inventory"] = {}, ["fields"] = {}}}, {["y"] = 2, ["x"] = 6, ["name"] = "nether:netherrack", ["z"] = 9, ["meta"] = {["inventory"] = {}, ["fields"] = {}}}, {["y"] = 2, ["x"] = 6, ["name"] = "nether:netherrack", ["z"] = 10, ["meta"] = {["inventory"] = {}, ["fields"] = {}}}, {["y"] = 3, ["x"] = 6, ["name"] = "stairs:stair_nether_blood_top", ["z"] = 0, ["meta"] = {["inventory"] = {}, ["fields"] = {}}, ["param1"] = 153}, {["y"] = 3, ["x"] = 6, ["name"] = "nether:netherrack", ["z"] = 1, ["meta"] = {["inventory"] = {}, ["fields"] = {}}}, {["y"] = 3, ["x"] = 6, ["name"] = "nether:netherrack", ["z"] = 2, ["meta"] = {["inventory"] = {}, ["fields"] = {}}}, {["y"] = 3, ["x"] = 6, ["name"] = "nether:netherrack", ["z"] = 3, ["meta"] = {["inventory"] = {}, ["fields"] = {}}}, {["y"] = 3, ["x"] = 6, ["name"] = "nether:netherrack", ["z"] = 4, ["meta"] = {["inventory"] = {}, ["fields"] = {}}}, {["y"] = 3, ["x"] = 6, ["name"] = "nether:netherrack", ["z"] = 5, ["meta"] = {["inventory"] = {}, ["fields"] = {}}}, {["y"] = 3, ["x"] = 6, ["name"] = "nether:netherrack", ["z"] = 6, ["meta"] = {["inventory"] = {}, ["fields"] = {}}}, {["y"] = 3, ["x"] = 6, ["name"] = "nether:netherrack", ["z"] = 7, ["meta"] = {["inventory"] = {}, ["fields"] = {}}}, {["y"] = 3, ["x"] = 6, ["name"] = "nether:netherrack", ["z"] = 8, ["meta"] = {["inventory"] = {}, ["fields"] = {}}}, {["y"] = 3, ["x"] = 6, ["name"] = "nether:netherrack", ["z"] = 9, ["meta"] = {["inventory"] = {}, ["fields"] = {}}}, {["y"] = 3, ["x"] = 6, ["name"] = "stairs:stair_nether_blood_top", ["z"] = 10, ["meta"] = {["inventory"] = {}, ["fields"] = {}}, ["param2"] = 2, ["param1"] = 153}, {["y"] = 4, ["x"] = 6, ["name"] = "stairs:stair_nether_blood_top", ["z"] = 1, ["meta"] = {["inventory"] = {}, ["fields"] = {}}, ["param1"] = 187}, {["y"] = 4, ["x"] = 6, ["name"] = "nether:netherrack", ["z"] = 2, ["meta"] = {["inventory"] = {}, ["fields"] = {}}}, {["y"] = 4, ["x"] = 6, ["name"] = "nether:netherrack", ["z"] = 3, ["meta"] = {["inventory"] = {}, ["fields"] = {}}}, {["y"] = 4, ["x"] = 6, ["name"] = "nether:netherrack", ["z"] = 4, ["meta"] = {["inventory"] = {}, ["fields"] = {}}}, {["y"] = 4, ["x"] = 6, ["name"] = "nether:netherrack", ["z"] = 5, ["meta"] = {["inventory"] = {}, ["fields"] = {}}}, {["y"] = 4, ["x"] = 6, ["name"] = "nether:netherrack", ["z"] = 6, ["meta"] = {["inventory"] = {}, ["fields"] = {}}}, {["y"] = 4, ["x"] = 6, ["name"] = "nether:netherrack", ["z"] = 7, ["meta"] = {["inventory"] = {}, ["fields"] = {}}}, {["y"] = 4, ["x"] = 6, ["name"] = "nether:netherrack", ["z"] = 8, ["meta"] = {["inventory"] = {}, ["fields"] = {}}}, {["y"] = 4, ["x"] = 6, ["name"] = "stairs:stair_nether_blood_top", ["z"] = 9, ["meta"] = {["inventory"] = {}, ["fields"] = {}}, ["param2"] = 2, ["param1"] = 187}, {["y"] = 5, ["x"] = 6, ["name"] = "stairs:stair_nether_blood_top", ["z"] = 2, ["meta"] = {["inventory"] = {}, ["fields"] = {}}, ["param1"] = 187}, {["y"] = 5, ["x"] = 6, ["name"] = "nether:netherrack_black", ["z"] = 3, ["meta"] = {["inventory"] = {}, ["fields"] = {}}}, {["y"] = 5, ["x"] = 6, ["name"] = "nether:netherrack", ["z"] = 4, ["meta"] = {["inventory"] = {}, ["fields"] = {}}}, {["y"] = 5, ["x"] = 6, ["name"] = "nether:netherrack", ["z"] = 5, ["meta"] = {["inventory"] = {}, ["fields"] = {}}}, {["y"] = 5, ["x"] = 6, ["name"] = "nether:netherrack", ["z"] = 6, ["meta"] = {["inventory"] = {}, ["fields"] = {}}}, {["y"] = 5, ["x"] = 6, ["name"] = "nether:netherrack_black", ["z"] = 7, ["meta"] = {["inventory"] = {}, ["fields"] = {}}}, {["y"] = 5, ["x"] = 6, ["name"] = "stairs:stair_nether_blood_top", ["z"] = 8, ["meta"] = {["inventory"] = {}, ["fields"] = {}}, ["param2"] = 2, ["param1"] = 187}, {["y"] = 8, ["x"] = 6, ["name"] = "nether:apple", ["z"] = 4, ["meta"] = {["inventory"] = {}, ["fields"] = {}}, ["param1"] = 102}, {["y"] = 8, ["x"] = 6, ["name"] = "nether:apple", ["z"] = 6, ["meta"] = {["inventory"] = {}, ["fields"] = {}}, ["param1"] = 102}, {["y"] = 9, ["x"] = 6, ["name"] = "nether:wood_empty", ["z"] = 3, ["meta"] = {["inventory"] = {}, ["fields"] = {}}}, {["y"] = 9, ["x"] = 6, ["name"] = "nether:blood_cooked", ["z"] = 4, ["meta"] = {["inventory"] = {}, ["fields"] = {}}}, {["y"] = 9, ["x"] = 6, ["name"] = "nether:blood_cooked", ["z"] = 5, ["meta"] = {["inventory"] = {}, ["fields"] = {}}}, {["y"] = 9, ["x"] = 6, ["name"] = "nether:blood_cooked", ["z"] = 6, ["meta"] = {["inventory"] = {}, ["fields"] = {}}}, {["y"] = 9, ["x"] = 6, ["name"] = "nether:wood_empty", ["z"] = 7, ["meta"] = {["inventory"] = {}, ["fields"] = {}}}, {["y"] = 10, ["x"] = 6, ["name"] = "nether:wood_empty", ["z"] = 4, ["meta"] = {["inventory"] = {}, ["fields"] = {}}}, {["y"] = 10, ["x"] = 6, ["name"] = "nether:wood_empty", ["z"] = 5, ["meta"] = {["inventory"] = {}, ["fields"] = {}}}, {["y"] = 10, ["x"] = 6, ["name"] = "nether:wood_empty", ["z"] = 6, ["meta"] = {["inventory"] = {}, ["fields"] = {}}}, {["y"] = 2, ["x"] = 7, ["name"] = "nether:netherrack", ["z"] = 0, ["meta"] = {["inventory"] = {}, ["fields"] = {}}}, {["y"] = 2, ["x"] = 7, ["name"] = "nether:netherrack", ["z"] = 1, ["meta"] = {["inventory"] = {}, ["fields"] = {}}}, {["y"] = 2, ["x"] = 7, ["name"] = "nether:netherrack", ["z"] = 2, ["meta"] = {["inventory"] = {}, ["fields"] = {}}}, {["y"] = 2, ["x"] = 7, ["name"] = "nether:netherrack", ["z"] = 3, ["meta"] = {["inventory"] = {}, ["fields"] = {}}}, {["y"] = 2, ["x"] = 7, ["name"] = "nether:netherrack", ["z"] = 4, ["meta"] = {["inventory"] = {}, ["fields"] = {}}}, {["y"] = 2, ["x"] = 7, ["name"] = "nether:netherrack", ["z"] = 5, ["meta"] = {["inventory"] = {}, ["fields"] = {}}}, {["y"] = 2, ["x"] = 7, ["name"] = "nether:netherrack", ["z"] = 6, ["meta"] = {["inventory"] = {}, ["fields"] = {}}}, {["y"] = 2, ["x"] = 7, ["name"] = "nether:netherrack", ["z"] = 7, ["meta"] = {["inventory"] = {}, ["fields"] = {}}}, {["y"] = 2, ["x"] = 7, ["name"] = "nether:netherrack", ["z"] = 8, ["meta"] = {["inventory"] = {}, ["fields"] = {}}}, {["y"] = 2, ["x"] = 7, ["name"] = "nether:netherrack", ["z"] = 9, ["meta"] = {["inventory"] = {}, ["fields"] = {}}}, {["y"] = 2, ["x"] = 7, ["name"] = "nether:netherrack", ["z"] = 10, ["meta"] = {["inventory"] = {}, ["fields"] = {}}}, {["y"] = 3, ["x"] = 7, ["name"] = "nether:netherrack", ["z"] = 1, ["meta"] = {["inventory"] = {}, ["fields"] = {}}}, {["y"] = 3, ["x"] = 7, ["name"] = "nether:netherrack", ["z"] = 2, ["meta"] = {["inventory"] = {}, ["fields"] = {}}}, {["y"] = 3, ["x"] = 7, ["name"] = "nether:netherrack", ["z"] = 3, ["meta"] = {["inventory"] = {}, ["fields"] = {}}}, {["y"] = 3, ["x"] = 7, ["name"] = "nether:netherrack", ["z"] = 4, ["meta"] = {["inventory"] = {}, ["fields"] = {}}}, {["y"] = 3, ["x"] = 7, ["name"] = "nether:netherrack", ["z"] = 5, ["meta"] = {["inventory"] = {}, ["fields"] = {}}}, {["y"] = 3, ["x"] = 7, ["name"] = "nether:netherrack", ["z"] = 6, ["meta"] = {["inventory"] = {}, ["fields"] = {}}}, {["y"] = 3, ["x"] = 7, ["name"] = "nether:netherrack", ["z"] = 7, ["meta"] = {["inventory"] = {}, ["fields"] = {}}}, {["y"] = 3, ["x"] = 7, ["name"] = "nether:netherrack", ["z"] = 8, ["meta"] = {["inventory"] = {}, ["fields"] = {}}}, {["y"] = 3, ["x"] = 7, ["name"] = "nether:netherrack", ["z"] = 9, ["meta"] = {["inventory"] = {}, ["fields"] = {}}}, {["y"] = 4, ["x"] = 7, ["name"] = "nether:netherrack", ["z"] = 2, ["meta"] = {["inventory"] = {}, ["fields"] = {}}}, {["y"] = 4, ["x"] = 7, ["name"] = "nether:netherrack", ["z"] = 3, ["meta"] = {["inventory"] = {}, ["fields"] = {}}}, {["y"] = 4, ["x"] = 7, ["name"] = "nether:netherrack", ["z"] = 4, ["meta"] = {["inventory"] = {}, ["fields"] = {}}}, {["y"] = 4, ["x"] = 7, ["name"] = "nether:netherrack", ["z"] = 5, ["meta"] = {["inventory"] = {}, ["fields"] = {}}}, {["y"] = 4, ["x"] = 7, ["name"] = "nether:netherrack", ["z"] = 6, ["meta"] = {["inventory"] = {}, ["fields"] = {}}}, {["y"] = 4, ["x"] = 7, ["name"] = "nether:netherrack", ["z"] = 7, ["meta"] = {["inventory"] = {}, ["fields"] = {}}}, {["y"] = 4, ["x"] = 7, ["name"] = "nether:netherrack", ["z"] = 8, ["meta"] = {["inventory"] = {}, ["fields"] = {}}}, {["y"] = 5, ["x"] = 7, ["name"] = "nether:netherrack_black", ["z"] = 3, ["meta"] = {["inventory"] = {}, ["fields"] = {}}}, {["y"] = 5, ["x"] = 7, ["name"] = "nether:netherrack_black", ["z"] = 4, ["meta"] = {["inventory"] = {}, ["fields"] = {}}}, {["y"] = 5, ["x"] = 7, ["name"] = "nether:netherrack_black", ["z"] = 5, ["meta"] = {["inventory"] = {}, ["fields"] = {}}}, {["y"] = 5, ["x"] = 7, ["name"] = "nether:netherrack_black", ["z"] = 6, ["meta"] = {["inventory"] = {}, ["fields"] = {}}}, {["y"] = 5, ["x"] = 7, ["name"] = "nether:netherrack_black", ["z"] = 7, ["meta"] = {["inventory"] = {}, ["fields"] = {}}}, {["y"] = 6, ["x"] = 7, ["name"] = "nether:netherrack_brick_blue", ["z"] = 3, ["meta"] = {["inventory"] = {}, ["fields"] = {}}}, {["y"] = 6, ["x"] = 7, ["name"] = "nether:netherrack_brick_blue", ["z"] = 7, ["meta"] = {["inventory"] = {}, ["fields"] = {}}}, {["y"] = 7, ["x"] = 7, ["name"] = "nether:netherrack_brick_blue", ["z"] = 3, ["meta"] = {["inventory"] = {}, ["fields"] = {}}}, {["y"] = 7, ["x"] = 7, ["name"] = "nether:netherrack_brick_blue", ["z"] = 7, ["meta"] = {["inventory"] = {}, ["fields"] = {}}}, {["y"] = 8, ["x"] = 7, ["name"] = "nether:netherrack_brick_blue", ["z"] = 3, ["meta"] = {["inventory"] = {}, ["fields"] = {}}}, {["y"] = 8, ["x"] = 7, ["name"] = "nether:netherrack_brick_blue", ["z"] = 7, ["meta"] = {["inventory"] = {}, ["fields"] = {}}}, {["y"] = 9, ["x"] = 7, ["name"] = "nether:wood_empty", ["z"] = 3, ["meta"] = {["inventory"] = {}, ["fields"] = {}}}, {["y"] = 9, ["x"] = 7, ["name"] = "nether:wood_empty", ["z"] = 4, ["meta"] = {["inventory"] = {}, ["fields"] = {}}}, {["y"] = 9, ["x"] = 7, ["name"] = "nether:wood_empty", ["z"] = 5, ["meta"] = {["inventory"] = {}, ["fields"] = {}}}, {["y"] = 9, ["x"] = 7, ["name"] = "nether:wood_empty", ["z"] = 6, ["meta"] = {["inventory"] = {}, ["fields"] = {}}}, {["y"] = 9, ["x"] = 7, ["name"] = "nether:wood_empty", ["z"] = 7, ["meta"] = {["inventory"] = {}, ["fields"] = {}}}, {["y"] = 2, ["x"] = 8, ["name"] = "nether:netherrack", ["z"] = 0, ["meta"] = {["inventory"] = {}, ["fields"] = {}}}, {["y"] = 2, ["x"] = 8, ["name"] = "nether:netherrack", ["z"] = 1, ["meta"] = {["inventory"] = {}, ["fields"] = {}}}, {["y"] = 2, ["x"] = 8, ["name"] = "nether:netherrack", ["z"] = 2, ["meta"] = {["inventory"] = {}, ["fields"] = {}}}, {["y"] = 2, ["x"] = 8, ["name"] = "nether:netherrack", ["z"] = 3, ["meta"] = {["inventory"] = {}, ["fields"] = {}}}, {["y"] = 2, ["x"] = 8, ["name"] = "nether:netherrack", ["z"] = 4, ["meta"] = {["inventory"] = {}, ["fields"] = {}}}, {["y"] = 2, ["x"] = 8, ["name"] = "nether:netherrack", ["z"] = 5, ["meta"] = {["inventory"] = {}, ["fields"] = {}}}, {["y"] = 2, ["x"] = 8, ["name"] = "nether:netherrack", ["z"] = 6, ["meta"] = {["inventory"] = {}, ["fields"] = {}}}, {["y"] = 2, ["x"] = 8, ["name"] = "nether:netherrack", ["z"] = 7, ["meta"] = {["inventory"] = {}, ["fields"] = {}}}, {["y"] = 2, ["x"] = 8, ["name"] = "nether:netherrack", ["z"] = 8, ["meta"] = {["inventory"] = {}, ["fields"] = {}}}, {["y"] = 2, ["x"] = 8, ["name"] = "nether:netherrack", ["z"] = 9, ["meta"] = {["inventory"] = {}, ["fields"] = {}}}, {["y"] = 2, ["x"] = 8, ["name"] = "nether:netherrack", ["z"] = 10, ["meta"] = {["inventory"] = {}, ["fields"] = {}}}, {["y"] = 3, ["x"] = 8, ["name"] = "nether:netherrack", ["z"] = 1, ["meta"] = {["inventory"] = {}, ["fields"] = {}}}, {["y"] = 3, ["x"] = 8, ["name"] = "nether:netherrack", ["z"] = 2, ["meta"] = {["inventory"] = {}, ["fields"] = {}}}, {["y"] = 3, ["x"] = 8, ["name"] = "nether:netherrack", ["z"] = 3, ["meta"] = {["inventory"] = {}, ["fields"] = {}}}, {["y"] = 3, ["x"] = 8, ["name"] = "nether:netherrack", ["z"] = 4, ["meta"] = {["inventory"] = {}, ["fields"] = {}}}, {["y"] = 3, ["x"] = 8, ["name"] = "nether:netherrack", ["z"] = 5, ["meta"] = {["inventory"] = {}, ["fields"] = {}}}, {["y"] = 3, ["x"] = 8, ["name"] = "nether:netherrack", ["z"] = 6, ["meta"] = {["inventory"] = {}, ["fields"] = {}}}, {["y"] = 3, ["x"] = 8, ["name"] = "nether:netherrack", ["z"] = 7, ["meta"] = {["inventory"] = {}, ["fields"] = {}}}, {["y"] = 3, ["x"] = 8, ["name"] = "nether:netherrack", ["z"] = 8, ["meta"] = {["inventory"] = {}, ["fields"] = {}}}, {["y"] = 4, ["x"] = 8, ["name"] = "glow:stone", ["z"] = 2, ["meta"] = {["inventory"] = {}, ["fields"] = {}}}, {["y"] = 4, ["x"] = 8, ["name"] = "nether:netherrack", ["z"] = 3, ["meta"] = {["inventory"] = {}, ["fields"] = {}}}, {["y"] = 4, ["x"] = 8, ["name"] = "nether:netherrack", ["z"] = 4, ["meta"] = {["inventory"] = {}, ["fields"] = {}}}, {["y"] = 4, ["x"] = 8, ["name"] = "nether:netherrack", ["z"] = 5, ["meta"] = {["inventory"] = {}, ["fields"] = {}}}, {["y"] = 4, ["x"] = 8, ["name"] = "nether:netherrack", ["z"] = 6, ["meta"] = {["inventory"] = {}, ["fields"] = {}}}, {["y"] = 4, ["x"] = 8, ["name"] = "nether:netherrack", ["z"] = 7, ["meta"] = {["inventory"] = {}, ["fields"] = {}}}, {["y"] = 4, ["x"] = 8, ["name"] = "glow:stone", ["z"] = 8, ["meta"] = {["inventory"] = {}, ["fields"] = {}}}, {["y"] = 5, ["x"] = 8, ["name"] = "stairs:stair_nether_blood_top", ["z"] = 4, ["meta"] = {["inventory"] = {}, ["fields"] = {}}, ["param2"] = 3, ["param1"] = 187}, {["y"] = 5, ["x"] = 8, ["name"] = "stairs:stair_nether_blood_top", ["z"] = 5, ["meta"] = {["inventory"] = {}, ["fields"] = {}}, ["param2"] = 3, ["param1"] = 170}, {["y"] = 5, ["x"] = 8, ["name"] = "stairs:stair_nether_blood_top", ["z"] = 6, ["meta"] = {["inventory"] = {}, ["fields"] = {}}, ["param2"] = 3, ["param1"] = 187}, {["y"] = 0, ["x"] = 9, ["name"] = "nether:netherrack", ["z"] = 4, ["meta"] = {["inventory"] = {}, ["fields"] = {}}}, {["y"] = 1, ["x"] = 9, ["name"] = "nether:netherrack", ["z"] = 4, ["meta"] = {["inventory"] = {}, ["fields"] = {}}}, {["y"] = 2, ["x"] = 9, ["name"] = "nether:netherrack", ["z"] = 0, ["meta"] = {["inventory"] = {}, ["fields"] = {}}}, {["y"] = 2, ["x"] = 9, ["name"] = "nether:netherrack", ["z"] = 1, ["meta"] = {["inventory"] = {}, ["fields"] = {}}}, {["y"] = 2, ["x"] = 9, ["name"] = "nether:netherrack", ["z"] = 2, ["meta"] = {["inventory"] = {}, ["fields"] = {}}}, {["y"] = 2, ["x"] = 9, ["name"] = "nether:netherrack", ["z"] = 3, ["meta"] = {["inventory"] = {}, ["fields"] = {}}}, {["y"] = 2, ["x"] = 9, ["name"] = "nether:netherrack", ["z"] = 4, ["meta"] = {["inventory"] = {}, ["fields"] = {}}}, {["y"] = 2, ["x"] = 9, ["name"] = "nether:netherrack", ["z"] = 5, ["meta"] = {["inventory"] = {}, ["fields"] = {}}}, {["y"] = 2, ["x"] = 9, ["name"] = "nether:netherrack", ["z"] = 6, ["meta"] = {["inventory"] = {}, ["fields"] = {}}}, {["y"] = 2, ["x"] = 9, ["name"] = "nether:netherrack", ["z"] = 7, ["meta"] = {["inventory"] = {}, ["fields"] = {}}}, {["y"] = 2, ["x"] = 9, ["name"] = "nether:netherrack", ["z"] = 8, ["meta"] = {["inventory"] = {}, ["fields"] = {}}}, {["y"] = 2, ["x"] = 9, ["name"] = "nether:netherrack", ["z"] = 9, ["meta"] = {["inventory"] = {}, ["fields"] = {}}}, {["y"] = 2, ["x"] = 9, ["name"] = "nether:netherrack", ["z"] = 10, ["meta"] = {["inventory"] = {}, ["fields"] = {}}}, {["y"] = 3, ["x"] = 9, ["name"] = "nether:netherrack", ["z"] = 2, ["meta"] = {["inventory"] = {}, ["fields"] = {}}}, {["y"] = 3, ["x"] = 9, ["name"] = "nether:netherrack", ["z"] = 3, ["meta"] = {["inventory"] = {}, ["fields"] = {}}}, {["y"] = 3, ["x"] = 9, ["name"] = "nether:netherrack", ["z"] = 4, ["meta"] = {["inventory"] = {}, ["fields"] = {}}}, {["y"] = 3, ["x"] = 9, ["name"] = "nether:netherrack", ["z"] = 5, ["meta"] = {["inventory"] = {}, ["fields"] = {}}}, {["y"] = 3, ["x"] = 9, ["name"] = "nether:netherrack", ["z"] = 6, ["meta"] = {["inventory"] = {}, ["fields"] = {}}}, {["y"] = 3, ["x"] = 9, ["name"] = "nether:netherrack", ["z"] = 7, ["meta"] = {["inventory"] = {}, ["fields"] = {}}}, {["y"] = 4, ["x"] = 9, ["name"] = "stairs:stair_nether_blood_top", ["z"] = 4, ["meta"] = {["inventory"] = {}, ["fields"] = {}}, ["param2"] = 3, ["param1"] = 187}, {["y"] = 4, ["x"] = 9, ["name"] = "stairs:stair_nether_blood_top", ["z"] = 5, ["meta"] = {["inventory"] = {}, ["fields"] = {}}, ["param2"] = 3, ["param1"] = 170}, {["y"] = 4, ["x"] = 9, ["name"] = "stairs:stair_nether_blood_top", ["z"] = 6, ["meta"] = {["inventory"] = {}, ["fields"] = {}}, ["param2"] = 3, ["param1"] = 187}, {["y"] = 0, ["x"] = 10, ["name"] = "nether:netherrack", ["z"] = 3, ["meta"] = {["inventory"] = {}, ["fields"] = {}}}, {["y"] = 0, ["x"] = 10, ["name"] = "nether:netherrack", ["z"] = 4, ["meta"] = {["inventory"] = {}, ["fields"] = {}}}, {["y"] = 0, ["x"] = 10, ["name"] = "nether:netherrack", ["z"] = 5, ["meta"] = {["inventory"] = {}, ["fields"] = {}}}, {["y"] = 0, ["x"] = 10, ["name"] = "nether:netherrack", ["z"] = 6, ["meta"] = {["inventory"] = {}, ["fields"] = {}}}, {["y"] = 0, ["x"] = 10, ["name"] = "nether:netherrack", ["z"] = 10, ["meta"] = {["inventory"] = {}, ["fields"] = {}}}, {["y"] = 1, ["x"] = 10, ["name"] = "nether:netherrack", ["z"] = 3, ["meta"] = {["inventory"] = {}, ["fields"] = {}}}, {["y"] = 1, ["x"] = 10, ["name"] = "nether:netherrack", ["z"] = 4, ["meta"] = {["inventory"] = {}, ["fields"] = {}}}, {["y"] = 1, ["x"] = 10, ["name"] = "nether:netherrack", ["z"] = 5, ["meta"] = {["inventory"] = {}, ["fields"] = {}}}, {["y"] = 1, ["x"] = 10, ["name"] = "nether:netherrack", ["z"] = 6, ["meta"] = {["inventory"] = {}, ["fields"] = {}}}, {["y"] = 1, ["x"] = 10, ["name"] = "nether:netherrack", ["z"] = 10, ["meta"] = {["inventory"] = {}, ["fields"] = {}}}, {["y"] = 2, ["x"] = 10, ["name"] = "nether:netherrack", ["z"] = 0, ["meta"] = {["inventory"] = {}, ["fields"] = {}}}, {["y"] = 2, ["x"] = 10, ["name"] = "nether:netherrack", ["z"] = 1, ["meta"] = {["inventory"] = {}, ["fields"] = {}}}, {["y"] = 2, ["x"] = 10, ["name"] = "nether:netherrack", ["z"] = 2, ["meta"] = {["inventory"] = {}, ["fields"] = {}}}, {["y"] = 2, ["x"] = 10, ["name"] = "nether:netherrack", ["z"] = 3, ["meta"] = {["inventory"] = {}, ["fields"] = {}}}, {["y"] = 2, ["x"] = 10, ["name"] = "nether:netherrack", ["z"] = 4, ["meta"] = {["inventory"] = {}, ["fields"] = {}}}, {["y"] = 2, ["x"] = 10, ["name"] = "nether:netherrack", ["z"] = 5, ["meta"] = {["inventory"] = {}, ["fields"] = {}}}, {["y"] = 2, ["x"] = 10, ["name"] = "nether:netherrack", ["z"] = 6, ["meta"] = {["inventory"] = {}, ["fields"] = {}}}, {["y"] = 2, ["x"] = 10, ["name"] = "nether:netherrack", ["z"] = 7, ["meta"] = {["inventory"] = {}, ["fields"] = {}}}, {["y"] = 2, ["x"] = 10, ["name"] = "nether:netherrack", ["z"] = 8, ["meta"] = {["inventory"] = {}, ["fields"] = {}}}, {["y"] = 2, ["x"] = 10, ["name"] = "nether:netherrack", ["z"] = 9, ["meta"] = {["inventory"] = {}, ["fields"] = {}}}, {["y"] = 2, ["x"] = 10, ["name"] = "nether:netherrack", ["z"] = 10, ["meta"] = {["inventory"] = {}, ["fields"] = {}}}, {["y"] = 3, ["x"] = 10, ["name"] = "stairs:stair_nether_blood_top", ["z"] = 4, ["meta"] = {["inventory"] = {}, ["fields"] = {}}, ["param2"] = 3, ["param1"] = 153}, {["y"] = 3, ["x"] = 10, ["name"] = "stairs:stair_nether_blood_top", ["z"] = 5, ["meta"] = {["inventory"] = {}, ["fields"] = {}}, ["param2"] = 3, ["param1"] = 136}, {["y"] = 3, ["x"] = 10, ["name"] = "stairs:stair_nether_blood_top", ["z"] = 6, ["meta"] = {["inventory"] = {}, ["fields"] = {}}, ["param2"] = 3, ["param1"] = 153}}